Workbook

Sheet Contents
A1: PA-07 Precinct-Level Forecast Analysis
A2: Same backtesting and forecasting pipeline as the municipality-level Analysis workbook, run at 408-precinct resolution.
A4: Sheet | B4: What it does | C4: What it tells us
A5: Precinct Vote Data | B5: Real House votes, registration margin, and turnout for 408 precincts, 2018-2024. | C5: The complete precinct-level foundation.
A6: Predictability Ranking | B6: Classifies all 408 precincts Easy/Medium/Hard to predict. | C6: Finer-grained than the municipality version -- individual precincts within the same town can differ sharply.
A7: Magic Precinct | B7: Bellwether search across all 408 precincts. | C7: Lower Saucon precinct 830 (Northampton) is the closest-tracking bellwether.
A8: Beta Coefficients | B8: Each precinct's beta and R-squared against the district index. | C8: Identifies the most reliable precinct-level predictors of the district.
A9: 2024 Backtest | B9: All four methods (naive, trend, beta-adjusted, regression) tested against real 2024 results. | C9: Beta-Adjusted wins again (2.09 pt MAE) -- same ranking as at municipality level.
A10: 2026 Trend / Beta-Adjusted / Regression Forecast | B10: Three independent live 2026 forecasts at precinct resolution. | C10: 48.3% Dem (R), 47.3% Dem (R), 50.9% Dem (D) -- same 2-1 split as municipality level.
A11: Model Comparison | B11: All three forecasts side by side. | C11: Cross-validates the municipality-level conclusion: a Republican-leaning toss-up.
A12: Methodology | B12: Data source, precinct-matching approach, and what's different from the municipality version. | C12: Read this first if you're comparing the two workbooks.

Sheet Precinct Vote Data
A1: Year | B1: County | C1: Municipality | D1: Precinct Code | E1: Dem Votes | F1: Rep Votes | G1: Total Votes | H1: Dem Share % | I1: Reg Margin | J1: Turnout | K1: Presidential Year (dummy)
A2: 2018 | B2: Carbon | C2: BANKS | D2: 10 | E2: 160 | F2: 221 | G2: =E2+F2 -> 381 | H2: =E2/G2 -> 0.41994751 | I2: 0.2701 | J2: 0.5198 | K2: =IF(OR(A2=2020,A2=2024),1,0) -> 0
A3: 2020 | B3: Carbon | C3: BANKS | D3: 10 | E3: 171 | F3: 332 | G3: =E3+F3 -> 503 | H3: =E3/G3 -> 0.33996024 | I3: 0.1914 | J3: 0.6734 | K3: =IF(OR(A3=2020,A3=2024),1,0) -> 1
A4: 2022 | B4: Carbon | C4: BANKS | D4: 10 | E4: 137 | F4: 249 | G4: =E4+F4 -> 386 | H4: =E4/G4 -> 0.35492228 | I4: 0.1235 | J4: 0.5813 | K4: =IF(OR(A4=2020,A4=2024),1,0) -> 0
A5: 2024 | B5: Carbon | C5: BANKS | D5: 10 | E5: 181 | F5: 285 | G5: =E5+F5 -> 466 | H5: =E5/G5 -> 0.38841202 | I5: 0.0554 | J5: 0.7169 | K5: =IF(OR(A5=2020,A5=2024),1,0) -> 1
A6: 2018 | B6: Carbon | C6: BEAVER MEADOWS | D6: 40 | E6: 95 | F6: 192 | G6: =E6+F6 -> 287 | H6: =E6/G6 -> 0.33101045 | I6: 0.0963 | J6: 0.4767 | K6: =IF(OR(A6=2020,A6=2024),1,0) -> 0
A7: 2020 | B7: Carbon | C7: BEAVER MEADOWS | D7: 40 | E7: 100 | F7: 303 | G7: =E7+F7 -> 403 | H7: =E7/G7 -> 0.24813896 | I7: -0.0357 | J7: 0.6542 | K7: =IF(OR(A7=2020,A7=2024),1,0) -> 1
A8: 2022 | B8: Carbon | C8: BEAVER MEADOWS | D8: 40 | E8: 84 | F8: 230 | G8: =E8+F8 -> 314 | H8: =E8/G8 -> 0.26751592 | I8: -0.1336 | J8: 0.5377 | K8: =IF(OR(A8=2020,A8=2024),1,0) -> 0
A9: 2024 | B9: Carbon | C9: BEAVER MEADOWS | D9: 40 | E9: 118 | F9: 300 | G9: =E9+F9 -> 418 | H9: =E9/G9 -> 0.28229665 | I9: -0.2282 | J9: 0.6764 | K9: =IF(OR(A9=2020,A9=2024),1,0) -> 1
A10: 2018 | B10: Carbon | C10: BOWMANSTOWN | D10: 50 | E10: 110 | F10: 175 | G10: =E10+F10 -> 285 | H10: =E10/G10 -> 0.38596491 | I10: -0.0055 | J10: 0.5258 | K10: =IF(OR(A10=2020,A10=2024),1,0) -> 0
A11: 2020 | B11: Carbon | C11: BOWMANSTOWN | D11: 50 | E11: 111 | F11: 317 | G11: =E11+F11 -> 428 | H11: =E11/G11 -> 0.25934579 | I11: -0.1522 | J11: 0.7157 | K11: =IF(OR(A11=2020,A11=2024),1,0) -> 1
A12: 2022 | B12: Carbon | C12: BOWMANSTOWN | D12: 50 | E12: 125 | F12: 223 | G12: =E12+F12 -> 348 | H12: =E12/G12 -> 0.3591954 | I12: -0.1956 | J12: 0.6362 | K12: =IF(OR(A12=2020,A12=2024),1,0) -> 0
A13: 2024 | B13: Carbon | C13: BOWMANSTOWN | D13: 50 | E13: 144 | F13: 310 | G13: =E13+F13 -> 454 | H13: =E13/G13 -> 0.31718062 | I13: -0.1989 | J13: 0.8064 | K13: =IF(OR(A13=2020,A13=2024),1,0) -> 1
... A1633: 2024 | B1633: Northampton | C1633: WIND GAP | D1633: 1360 | E1633: 634 | F1633: 856 | G1633: =E1633+F1633 -> 1490 | H1633: =E1633/G1633 -> 0.42550336 | I1633: -0.0779 | J1633: 0.6992 | K1633: =IF(OR(A1633=2020,A1633=2024),1,0) -> 1

Sheet Predictability Ranking
A1: County | B1: Municipality | C1: Precinct Code | D1: Avg Dem Share | E1: Avg Margin from 50pt | F1: Stdev Dem Share | G1: Party Flips | H1: Predictability
A2: Carbon | B2: BANKS | C2: 10 | D2: =AVERAGE('Precinct Vote Data'!H2:H5) -> 0.37581051 | E2: =AVERAGE(ABS('Precinct Vote Data'!H2-0.5),ABS('Precinct Vote Data'!H3-0.5),ABS('Precinct Vote Data'!H4-0.5),ABS('Precinct Vote Data'!H5-0.5)) -> 0.12418949 | F2: =STDEV('Precinct Vote Data'!H2:H5) -> 0.03572316 | G2: =IF(('Precinct Vote Data'!H2>0.5)<>('Precinct Vote Data'!H3>0.5),1,0)+IF(('Precinct Vote Data'!H3>0.5)<>('Precinct Vote Data'!H4>0.5),1,0)+IF(('Precinct Vote Data'!H4>0.5)<>('Precinct Vote Data'!H5>0.5),1,0) -> 0 | H2: =IF(OR(G2>=1,E2<0.05),"Hard",IF(AND(E2>=0.15,F2<0.05),"Easy","Medium")) -> Medium
A3: Carbon | B3: BEAVER MEADOWS | C3: 40 | D3: =AVERAGE('Precinct Vote Data'!H6:H9) -> 0.2822405 | E3: =AVERAGE(ABS('Precinct Vote Data'!H6-0.5),ABS('Precinct Vote Data'!H7-0.5),ABS('Precinct Vote Data'!H8-0.5),ABS('Precinct Vote Data'!H9-0.5)) -> 0.2177595 | F3: =STDEV('Precinct Vote Data'!H6:H9) -> 0.035394161 | G3: =IF(('Precinct Vote Data'!H6>0.5)<>('Precinct Vote Data'!H7>0.5),1,0)+IF(('Precinct Vote Data'!H7>0.5)<>('Precinct Vote Data'!H8>0.5),1,0)+IF(('Precinct Vote Data'!H8>0.5)<>('Precinct Vote Data'!H9>0.5),1,0) -> 0 | H3: =IF(OR(G3>=1,E3<0.05),"Hard",IF(AND(E3>=0.15,F3<0.05),"Easy","Medium")) -> Easy
A4: Carbon | B4: BOWMANSTOWN | C4: 50 | D4: =AVERAGE('Precinct Vote Data'!H10:H13) -> 0.33042168 | E4: =AVERAGE(ABS('Precinct Vote Data'!H10-0.5),ABS('Precinct Vote Data'!H11-0.5),ABS('Precinct Vote Data'!H12-0.5),ABS('Precinct Vote Data'!H13-0.5)) -> 0.16957832 | F4: =STDEV('Precinct Vote Data'!H10:H13) -> 0.055196875 | G4: =IF(('Precinct Vote Data'!H10>0.5)<>('Precinct Vote Data'!H11>0.5),1,0)+IF(('Precinct Vote Data'!H11>0.5)<>('Precinct Vote Data'!H12>0.5),1,0)+IF(('Precinct Vote Data'!H12>0.5)<>('Precinct Vote Data'!H13>0.5),1,0) -> 0 | H4: =IF(OR(G4>=1,E4<0.05),"Hard",IF(AND(E4>=0.15,F4<0.05),"Easy","Medium")) -> Medium
A5: Carbon | B5: EAST PENN | C5: 60 | D5: =AVERAGE('Precinct Vote Data'!H14:H17) -> 0.27501179 | E5: =AVERAGE(ABS('Precinct Vote Data'!H14-0.5),ABS('Precinct Vote Data'!H15-0.5),ABS('Precinct Vote Data'!H16-0.5),ABS('Precinct Vote Data'!H17-0.5)) -> 0.22498821 | F5: =STDEV('Precinct Vote Data'!H14:H17) -> 0.039856379 | G5: =IF(('Precinct Vote Data'!H14>0.5)<>('Precinct Vote Data'!H15>0.5),1,0)+IF(('Precinct Vote Data'!H15>0.5)<>('Precinct Vote Data'!H16>0.5),1,0)+IF(('Precinct Vote Data'!H16>0.5)<>('Precinct Vote Data'!H17>0.5),1,0) -> 0 | H5: =IF(OR(G5>=1,E5<0.05),"Hard",IF(AND(E5>=0.15,F5<0.05),"Easy","Medium")) -> Easy
A6: Carbon | B6: EAST PENN | C6: 65 | D6: =AVERAGE('Precinct Vote Data'!H18:H21) -> 0.28864468 | E6: =AVERAGE(ABS('Precinct Vote Data'!H18-0.5),ABS('Precinct Vote Data'!H19-0.5),ABS('Precinct Vote Data'!H20-0.5),ABS('Precinct Vote Data'!H21-0.5)) -> 0.21135532 | F6: =STDEV('Precinct Vote Data'!H18:H21) -> 0.037111786 | G6: =IF(('Precinct Vote Data'!H18>0.5)<>('Precinct Vote Data'!H19>0.5),1,0)+IF(('Precinct Vote Data'!H19>0.5)<>('Precinct Vote Data'!H20>0.5),1,0)+IF(('Precinct Vote Data'!H20>0.5)<>('Precinct Vote Data'!H21>0.5),1,0) -> 0 | H6: =IF(OR(G6>=1,E6<0.05),"Hard",IF(AND(E6>=0.15,F6<0.05),"Easy","Medium")) -> Easy
A7: Carbon | B7: EAST SIDE | C7: 70 | D7: =AVERAGE('Precinct Vote Data'!H22:H25) -> 0.37715956 | E7: =AVERAGE(ABS('Precinct Vote Data'!H22-0.5),ABS('Precinct Vote Data'!H23-0.5),ABS('Precinct Vote Data'!H24-0.5),ABS('Precinct Vote Data'!H25-0.5)) -> 0.12284044 | F7: =STDEV('Precinct Vote Data'!H22:H25) -> 0.049708274 | G7: =IF(('Precinct Vote Data'!H22>0.5)<>('Precinct Vote Data'!H23>0.5),1,0)+IF(('Precinct Vote Data'!H23>0.5)<>('Precinct Vote Data'!H24>0.5),1,0)+IF(('Precinct Vote Data'!H24>0.5)<>('Precinct Vote Data'!H25>0.5),1,0) -> 0 | H7: =IF(OR(G7>=1,E7<0.05),"Hard",IF(AND(E7>=0.15,F7<0.05),"Easy","Medium")) -> Medium
A8: Carbon | B8: FRANKLIN | C8: 80 | D8: =AVERAGE('Precinct Vote Data'!H26:H29) -> 0.292641 | E8: =AVERAGE(ABS('Precinct Vote Data'!H26-0.5),ABS('Precinct Vote Data'!H27-0.5),ABS('Precinct Vote Data'!H28-0.5),ABS('Precinct Vote Data'!H29-0.5)) -> 0.207359 | F8: =STDEV('Precinct Vote Data'!H26:H29) -> 0.034966627 | G8: =IF(('Precinct Vote Data'!H26>0.5)<>('Precinct Vote Data'!H27>0.5),1,0)+IF(('Precinct Vote Data'!H27>0.5)<>('Precinct Vote Data'!H28>0.5),1,0)+IF(('Precinct Vote Data'!H28>0.5)<>('Precinct Vote Data'!H29>0.5),1,0) -> 0 | H8: =IF(OR(G8>=1,E8<0.05),"Hard",IF(AND(E8>=0.15,F8<0.05),"Easy","Medium")) -> Easy
A9: Carbon | B9: FRANKLIN | C9: 90 | D9: =AVERAGE('Precinct Vote Data'!H30:H33) -> 0.29734916 | E9: =AVERAGE(ABS('Precinct Vote Data'!H30-0.5),ABS('Precinct Vote Data'!H31-0.5),ABS('Precinct Vote Data'!H32-0.5),ABS('Precinct Vote Data'!H33-0.5)) -> 0.20265084 | F9: =STDEV('Precinct Vote Data'!H30:H33) -> 0.032831768 | G9: =IF(('Precinct Vote Data'!H30>0.5)<>('Precinct Vote Data'!H31>0.5),1,0)+IF(('Precinct Vote Data'!H31>0.5)<>('Precinct Vote Data'!H32>0.5),1,0)+IF(('Precinct Vote Data'!H32>0.5)<>('Precinct Vote Data'!H33>0.5),1,0) -> 0 | H9: =IF(OR(G9>=1,E9<0.05),"Hard",IF(AND(E9>=0.15,F9<0.05),"Easy","Medium")) -> Easy
A10: Carbon | B10: FRANKLIN | C10: 100 | D10: =AVERAGE('Precinct Vote Data'!H34:H37) -> 0.26630748 | E10: =AVERAGE(ABS('Precinct Vote Data'!H34-0.5),ABS('Precinct Vote Data'!H35-0.5),ABS('Precinct Vote Data'!H36-0.5),ABS('Precinct Vote Data'!H37-0.5)) -> 0.23369252 | F10: =STDEV('Precinct Vote Data'!H34:H37) -> 0.019400766 | G10: =IF(('Precinct Vote Data'!H34>0.5)<>('Precinct Vote Data'!H35>0.5),1,0)+IF(('Precinct Vote Data'!H35>0.5)<>('Precinct Vote Data'!H36>0.5),1,0)+IF(('Precinct Vote Data'!H36>0.5)<>('Precinct Vote Data'!H37>0.5),1,0) -> 0 | H10: =IF(OR(G10>=1,E10<0.05),"Hard",IF(AND(E10>=0.15,F10<0.05),"Easy","Medium")) -> Easy
A11: Carbon | B11: JIM THORPE | C11: 110 | D11: =AVERAGE('Precinct Vote Data'!H38:H41) -> 0.46600686 | E11: =AVERAGE(ABS('Precinct Vote Data'!H38-0.5),ABS('Precinct Vote Data'!H39-0.5),ABS('Precinct Vote Data'!H40-0.5),ABS('Precinct Vote Data'!H41-0.5)) -> 0.056493142 | F11: =STDEV('Precinct Vote Data'!H38:H41) -> 0.05405963 | G11: =IF(('Precinct Vote Data'!H38>0.5)<>('Precinct Vote Data'!H39>0.5),1,0)+IF(('Precinct Vote Data'!H39>0.5)<>('Precinct Vote Data'!H40>0.5),1,0)+IF(('Precinct Vote Data'!H40>0.5)<>('Precinct Vote Data'!H41>0.5),1,0) -> 1 | H11: =IF(OR(G11>=1,E11<0.05),"Hard",IF(AND(E11>=0.15,F11<0.05),"Easy","Medium")) -> Hard
A12: Carbon | B12: JIM THORPE | C12: 120 | D12: =AVERAGE('Precinct Vote Data'!H42:H45) -> 0.42099009 | E12: =AVERAGE(ABS('Precinct Vote Data'!H42-0.5),ABS('Precinct Vote Data'!H43-0.5),ABS('Precinct Vote Data'!H44-0.5),ABS('Precinct Vote Data'!H45-0.5)) -> 0.079009906 | F12: =STDEV('Precinct Vote Data'!H42:H45) -> 0.033581835 | G12: =IF(('Precinct Vote Data'!H42>0.5)<>('Precinct Vote Data'!H43>0.5),1,0)+IF(('Precinct Vote Data'!H43>0.5)<>('Precinct Vote Data'!H44>0.5),1,0)+IF(('Precinct Vote Data'!H44>0.5)<>('Precinct Vote Data'!H45>0.5),1,0) -> 0 | H12: =IF(OR(G12>=1,E12<0.05),"Hard",IF(AND(E12>=0.15,F12<0.05),"Easy","Medium")) -> Medium
A13: Carbon | B13: JIM THORPE | C13: 130 | D13: =AVERAGE('Precinct Vote Data'!H46:H49) -> 0.40338453 | E13: =AVERAGE(ABS('Precinct Vote Data'!H46-0.5),ABS('Precinct Vote Data'!H47-0.5),ABS('Precinct Vote Data'!H48-0.5),ABS('Precinct Vote Data'!H49-0.5)) -> 0.096615473 | F13: =STDEV('Precinct Vote Data'!H46:H49) -> 0.038485824 | G13: =IF(('Precinct Vote Data'!H46>0.5)<>('Precinct Vote Data'!H47>0.5),1,0)+IF(('Precinct Vote Data'!H47>0.5)<>('Precinct Vote Data'!H48>0.5),1,0)+IF(('Precinct Vote Data'!H48>0.5)<>('Precinct Vote Data'!H49>0.5),1,0) -> 0 | H13: =IF(OR(G13>=1,E13<0.05),"Hard",IF(AND(E13>=0.15,F13<0.05),"Easy","Medium")) -> Medium
A14: Carbon | B14: JIM THORPE | C14: 140 | D14: =AVERAGE('Precinct Vote Data'!H50:H53) -> 0.54653352 | E14: =AVERAGE(ABS('Precinct Vote Data'!H50-0.5),ABS('Precinct Vote Data'!H51-0.5),ABS('Precinct Vote Data'!H52-0.5),ABS('Precinct Vote Data'!H53-0.5)) -> 0.04653352 | F14: =STDEV('Precinct Vote Data'!H50:H53) -> 0.035931947 | G14: =IF(('Precinct Vote Data'!H50>0.5)<>('Precinct Vote Data'!H51>0.5),1,0)+IF(('Precinct Vote Data'!H51>0.5)<>('Precinct Vote Data'!H52>0.5),1,0)+IF(('Precinct Vote Data'!H52>0.5)<>('Precinct Vote Data'!H53>0.5),1,0) -> 0 | H14: =IF(OR(G14>=1,E14<0.05),"Hard",IF(AND(E14>=0.15,F14<0.05),"Easy","Medium")) -> Hard
A15: Carbon | B15: JIM THORPE | C15: 150 | D15: =AVERAGE('Precinct Vote Data'!H54:H57) -> 0.44873174 | E15: =AVERAGE(ABS('Precinct Vote Data'!H54-0.5),ABS('Precinct Vote Data'!H55-0.5),ABS('Precinct Vote Data'!H56-0.5),ABS('Precinct Vote Data'!H57-0.5)) -> 0.051268256 | F15: =STDEV('Precinct Vote Data'!H54:H57) -> 0.037467409 | G15: =IF(('Precinct Vote Data'!H54>0.5)<>('Precinct Vote Data'!H55>0.5),1,0)+IF(('Precinct Vote Data'!H55>0.5)<>('Precinct Vote Data'!H56>0.5),1,0)+IF(('Precinct Vote Data'!H56>0.5)<>('Precinct Vote Data'!H57>0.5),1,0) -> 0 | H15: =IF(OR(G15>=1,E15<0.05),"Hard",IF(AND(E15>=0.15,F15<0.05),"Easy","Medium")) -> Medium
A16: Carbon | B16: KIDDER | C16: 160 | D16: =AVERAGE('Precinct Vote Data'!H58:H61) -> 0.35838641 | E16: =AVERAGE(ABS('Precinct Vote Data'!H58-0.5),ABS('Precinct Vote Data'!H59-0.5),ABS('Precinct Vote Data'!H60-0.5),ABS('Precinct Vote Data'!H61-0.5)) -> 0.14161359 | F16: =STDEV('Precinct Vote Data'!H58:H61) -> 0.028047845 | G16: =IF(('Precinct Vote Data'!H58>0.5)<>('Precinct Vote Data'!H59>0.5),1,0)+IF(('Precinct Vote Data'!H59>0.5)<>('Precinct Vote Data'!H60>0.5),1,0)+IF(('Precinct Vote Data'!H60>0.5)<>('Precinct Vote Data'!H61>0.5),1,0) -> 0 | H16: =IF(OR(G16>=1,E16<0.05),"Hard",IF(AND(E16>=0.15,F16<0.05),"Easy","Medium")) -> Medium
A17: Carbon | B17: KIDDER | C17: 170 | D17: =AVERAGE('Precinct Vote Data'!H62:H65) -> 0.31837026 | E17: =AVERAGE(ABS('Precinct Vote Data'!H62-0.5),ABS('Precinct Vote Data'!H63-0.5),ABS('Precinct Vote Data'!H64-0.5),ABS('Precinct Vote Data'!H65-0.5)) -> 0.18162974 | F17: =STDEV('Precinct Vote Data'!H62:H65) -> 0.015918706 | G17: =IF(('Precinct Vote Data'!H62>0.5)<>('Precinct Vote Data'!H63>0.5),1,0)+IF(('Precinct Vote Data'!H63>0.5)<>('Precinct Vote Data'!H64>0.5),1,0)+IF(('Precinct Vote Data'!H64>0.5)<>('Precinct Vote Data'!H65>0.5),1,0) -> 0 | H17: =IF(OR(G17>=1,E17<0.05),"Hard",IF(AND(E17>=0.15,F17<0.05),"Easy","Medium")) -> Easy
A18: Carbon | B18: LANSFORD | C18: 180 | D18: =AVERAGE('Precinct Vote Data'!H66:H69) -> 0.42556737 | E18: =AVERAGE(ABS('Precinct Vote Data'!H66-0.5),ABS('Precinct Vote Data'!H67-0.5),ABS('Precinct Vote Data'!H68-0.5),ABS('Precinct Vote Data'!H69-0.5)) -> 0.074432633 | F18: =STDEV('Precinct Vote Data'!H66:H69) -> 0.050432877 | G18: =IF(('Precinct Vote Data'!H66>0.5)<>('Precinct Vote Data'!H67>0.5),1,0)+IF(('Precinct Vote Data'!H67>0.5)<>('Precinct Vote Data'!H68>0.5),1,0)+IF(('Precinct Vote Data'!H68>0.5)<>('Precinct Vote Data'!H69>0.5),1,0) -> 0 | H18: =IF(OR(G18>=1,E18<0.05),"Hard",IF(AND(E18>=0.15,F18<0.05),"Easy","Medium")) -> Medium
A19: Carbon | B19: LANSFORD | C19: 190 | D19: =AVERAGE('Precinct Vote Data'!H70:H73) -> 0.4247605 | E19: =AVERAGE(ABS('Precinct Vote Data'!H70-0.5),ABS('Precinct Vote Data'!H71-0.5),ABS('Precinct Vote Data'!H72-0.5),ABS('Precinct Vote Data'!H73-0.5)) -> 0.075239504 | F19: =STDEV('Precinct Vote Data'!H70:H73) -> 0.035088902 | G19: =IF(('Precinct Vote Data'!H70>0.5)<>('Precinct Vote Data'!H71>0.5),1,0)+IF(('Precinct Vote Data'!H71>0.5)<>('Precinct Vote Data'!H72>0.5),1,0)+IF(('Precinct Vote Data'!H72>0.5)<>('Precinct Vote Data'!H73>0.5),1,0) -> 0 | H19: =IF(OR(G19>=1,E19<0.05),"Hard",IF(AND(E19>=0.15,F19<0.05),"Easy","Medium")) -> Medium
A20: Carbon | B20: LANSFORD | C20: 200 | D20: =AVERAGE('Precinct Vote Data'!H74:H77) -> 0.45485201 | E20: =AVERAGE(ABS('Precinct Vote Data'!H74-0.5),ABS('Precinct Vote Data'!H75-0.5),ABS('Precinct Vote Data'!H76-0.5),ABS('Precinct Vote Data'!H77-0.5)) -> 0.050753375 | F20: =STDEV('Precinct Vote Data'!H74:H77) -> 0.045002565 | G20: =IF(('Precinct Vote Data'!H74>0.5)<>('Precinct Vote Data'!H75>0.5),1,0)+IF(('Precinct Vote Data'!H75>0.5)<>('Precinct Vote Data'!H76>0.5),1,0)+IF(('Precinct Vote Data'!H76>0.5)<>('Precinct Vote Data'!H77>0.5),1,0) -> 1 | H20: =IF(OR(G20>=1,E20<0.05),"Hard",IF(AND(E20>=0.15,F20<0.05),"Easy","Medium")) -> Hard
A21: Carbon | B21: LAUSANNE | C21: 210 | D21: =AVERAGE('Precinct Vote Data'!H78:H81) -> 0.30063256 | E21: =AVERAGE(ABS('Precinct Vote Data'!H78-0.5),ABS('Precinct Vote Data'!H79-0.5),ABS('Precinct Vote Data'!H80-0.5),ABS('Precinct Vote Data'!H81-0.5)) -> 0.19936744 | F21: =STDEV('Precinct Vote Data'!H78:H81) -> 0.028779368 | G21: =IF(('Precinct Vote Data'!H78>0.5)<>('Precinct Vote Data'!H79>0.5),1,0)+IF(('Precinct Vote Data'!H79>0.5)<>('Precinct Vote Data'!H80>0.5),1,0)+IF(('Precinct Vote Data'!H80>0.5)<>('Precinct Vote Data'!H81>0.5),1,0) -> 0 | H21: =IF(OR(G21>=1,E21<0.05),"Hard",IF(AND(E21>=0.15,F21<0.05),"Easy","Medium")) -> Easy
A22: Carbon | B22: LEHIGH | C22: 220 | D22: =AVERAGE('Precinct Vote Data'!H82:H85) -> 0.20363956 | E22: =AVERAGE(ABS('Precinct Vote Data'!H82-0.5),ABS('Precinct Vote Data'!H83-0.5),ABS('Precinct Vote Data'!H84-0.5),ABS('Precinct Vote Data'!H85-0.5)) -> 0.29636044 | F22: =STDEV('Precinct Vote Data'!H82:H85) -> 0.013232881 | G22: =IF(('Precinct Vote Data'!H82>0.5)<>('Precinct Vote Data'!H83>0.5),1,0)+IF(('Precinct Vote Data'!H83>0.5)<>('Precinct Vote Data'!H84>0.5),1,0)+IF(('Precinct Vote Data'!H84>0.5)<>('Precinct Vote Data'!H85>0.5),1,0) -> 0 | H22: =IF(OR(G22>=1,E22<0.05),"Hard",IF(AND(E22>=0.15,F22<0.05),"Easy","Medium")) -> Easy
A23: Carbon | B23: LEHIGHTON | C23: 230 | D23: =AVERAGE('Precinct Vote Data'!H86:H89) -> 0.40762005 | E23: =AVERAGE(ABS('Precinct Vote Data'!H86-0.5),ABS('Precinct Vote Data'!H87-0.5),ABS('Precinct Vote Data'!H88-0.5),ABS('Precinct Vote Data'!H89-0.5)) -> 0.092379952 | F23: =STDEV('Precinct Vote Data'!H86:H89) -> 0.035394332 | G23: =IF(('Precinct Vote Data'!H86>0.5)<>('Precinct Vote Data'!H87>0.5),1,0)+IF(('Precinct Vote Data'!H87>0.5)<>('Precinct Vote Data'!H88>0.5),1,0)+IF(('Precinct Vote Data'!H88>0.5)<>('Precinct Vote Data'!H89>0.5),1,0) -> 0 | H23: =IF(OR(G23>=1,E23<0.05),"Hard",IF(AND(E23>=0.15,F23<0.05),"Easy","Medium")) -> Medium
A24: Carbon | B24: LEHIGHTON | C24: 240 | D24: =AVERAGE('Precinct Vote Data'!H90:H93) -> 0.42278506 | E24: =AVERAGE(ABS('Precinct Vote Data'!H90-0.5),ABS('Precinct Vote Data'!H91-0.5),ABS('Precinct Vote Data'!H92-0.5),ABS('Precinct Vote Data'!H93-0.5)) -> 0.077214943 | F24: =STDEV('Precinct Vote Data'!H90:H93) -> 0.03620214 | G24: =IF(('Precinct Vote Data'!H90>0.5)<>('Precinct Vote Data'!H91>0.5),1,0)+IF(('Precinct Vote Data'!H91>0.5)<>('Precinct Vote Data'!H92>0.5),1,0)+IF(('Precinct Vote Data'!H92>0.5)<>('Precinct Vote Data'!H93>0.5),1,0) -> 0 | H24: =IF(OR(G24>=1,E24<0.05),"Hard",IF(AND(E24>=0.15,F24<0.05),"Easy","Medium")) -> Medium
A25: Carbon | B25: LEHIGHTON | C25: 250 | D25: =AVERAGE('Precinct Vote Data'!H94:H97) -> 0.41496775 | E25: =AVERAGE(ABS('Precinct Vote Data'!H94-0.5),ABS('Precinct Vote Data'!H95-0.5),ABS('Precinct Vote Data'!H96-0.5),ABS('Precinct Vote Data'!H97-0.5)) -> 0.085032246 | F25: =STDEV('Precinct Vote Data'!H94:H97) -> 0.059509219 | G25: =IF(('Precinct Vote Data'!H94>0.5)<>('Precinct Vote Data'!H95>0.5),1,0)+IF(('Precinct Vote Data'!H95>0.5)<>('Precinct Vote Data'!H96>0.5),1,0)+IF(('Precinct Vote Data'!H96>0.5)<>('Precinct Vote Data'!H97>0.5),1,0) -> 0 | H25: =IF(OR(G25>=1,E25<0.05),"Hard",IF(AND(E25>=0.15,F25<0.05),"Easy","Medium")) -> Medium
A26: Carbon | B26: LOWER TOWAMENSING | C26: 260 | D26: =AVERAGE('Precinct Vote Data'!H98:H101) -> 0.30488811 | E26: =AVERAGE(ABS('Precinct Vote Data'!H98-0.5),ABS('Precinct Vote Data'!H99-0.5),ABS('Precinct Vote Data'!H100-0.5),ABS('Precinct Vote Data'!H101-0.5)) -> 0.19511189 | F26: =STDEV('Precinct Vote Data'!H98:H101) -> 0.036997345 | G26: =IF(('Precinct Vote Data'!H98>0.5)<>('Precinct Vote Data'!H99>0.5),1,0)+IF(('Precinct Vote Data'!H99>0.5)<>('Precinct Vote Data'!H100>0.5),1,0)+IF(('Precinct Vote Data'!H100>0.5)<>('Precinct Vote Data'!H101>0.5),1,0) -> 0 | H26: =IF(OR(G26>=1,E26<0.05),"Hard",IF(AND(E26>=0.15,F26<0.05),"Easy","Medium")) -> Easy
A27: Carbon | B27: LOWER TOWAMENSING | C27: 265 | D27: =AVERAGE('Precinct Vote Data'!H102:H105) -> 0.33554407 | E27: =AVERAGE(ABS('Precinct Vote Data'!H102-0.5),ABS('Precinct Vote Data'!H103-0.5),ABS('Precinct Vote Data'!H104-0.5),ABS('Precinct Vote Data'!H105-0.5)) -> 0.16445593 | F27: =STDEV('Precinct Vote Data'!H102:H105) -> 0.038473542 | G27: =IF(('Precinct Vote Data'!H102>0.5)<>('Precinct Vote Data'!H103>0.5),1,0)+IF(('Precinct Vote Data'!H103>0.5)<>('Precinct Vote Data'!H104>0.5),1,0)+IF(('Precinct Vote Data'!H104>0.5)<>('Precinct Vote Data'!H105>0.5),1,0) -> 0 | H27: =IF(OR(G27>=1,E27<0.05),"Hard",IF(AND(E27>=0.15,F27<0.05),"Easy","Medium")) -> Easy
A28: Carbon | B28: MAHONING | C28: 270 | D28: =AVERAGE('Precinct Vote Data'!H106:H109) -> 0.31500467 | E28: =AVERAGE(ABS('Precinct Vote Data'!H106-0.5),ABS('Precinct Vote Data'!H107-0.5),ABS('Precinct Vote Data'!H108-0.5),ABS('Precinct Vote Data'!H109-0.5)) -> 0.18499533 | F28: =STDEV('Precinct Vote Data'!H106:H109) -> 0.034907117 | G28: =IF(('Precinct Vote Data'!H106>0.5)<>('Precinct Vote Data'!H107>0.5),1,0)+IF(('Precinct Vote Data'!H107>0.5)<>('Precinct Vote Data'!H108>0.5),1,0)+IF(('Precinct Vote Data'!H108>0.5)<>('Precinct Vote Data'!H109>0.5),1,0) -> 0 | H28: =IF(OR(G28>=1,E28<0.05),"Hard",IF(AND(E28>=0.15,F28<0.05),"Easy","Medium")) -> Easy
A29: Carbon | B29: MAHONING | C29: 280 | D29: =AVERAGE('Precinct Vote Data'!H110:H113) -> 0.2590415 | E29: =AVERAGE(ABS('Precinct Vote Data'!H110-0.5),ABS('Precinct Vote Data'!H111-0.5),ABS('Precinct Vote Data'!H112-0.5),ABS('Precinct Vote Data'!H113-0.5)) -> 0.2409585 | F29: =STDEV('Precinct Vote Data'!H110:H113) -> 0.030673218 | G29: =IF(('Precinct Vote Data'!H110>0.5)<>('Precinct Vote Data'!H111>0.5),1,0)+IF(('Precinct Vote Data'!H111>0.5)<>('Precinct Vote Data'!H112>0.5),1,0)+IF(('Precinct Vote Data'!H112>0.5)<>('Precinct Vote Data'!H113>0.5),1,0) -> 0 | H29: =IF(OR(G29>=1,E29<0.05),"Hard",IF(AND(E29>=0.15,F29<0.05),"Easy","Medium")) -> Easy
A30: Carbon | B30: MAHONING | C30: 290 | D30: =AVERAGE('Precinct Vote Data'!H114:H117) -> 0.31601973 | E30: =AVERAGE(ABS('Precinct Vote Data'!H114-0.5),ABS('Precinct Vote Data'!H115-0.5),ABS('Precinct Vote Data'!H116-0.5),ABS('Precinct Vote Data'!H117-0.5)) -> 0.18398027 | F30: =STDEV('Precinct Vote Data'!H114:H117) -> 0.039120462 | G30: =IF(('Precinct Vote Data'!H114>0.5)<>('Precinct Vote Data'!H115>0.5),1,0)+IF(('Precinct Vote Data'!H115>0.5)<>('Precinct Vote Data'!H116>0.5),1,0)+IF(('Precinct Vote Data'!H116>0.5)<>('Precinct Vote Data'!H117>0.5),1,0) -> 0 | H30: =IF(OR(G30>=1,E30<0.05),"Hard",IF(AND(E30>=0.15,F30<0.05),"Easy","Medium")) -> Easy
A31: Carbon | B31: NESQUEHONING | C31: 300 | D31: =AVERAGE('Precinct Vote Data'!H118:H121) -> 0.41967903 | E31: =AVERAGE(ABS('Precinct Vote Data'!H118-0.5),ABS('Precinct Vote Data'!H119-0.5),ABS('Precinct Vote Data'!H120-0.5),ABS('Precinct Vote Data'!H121-0.5)) -> 0.080320971 | F31: =STDEV('Precinct Vote Data'!H118:H121) -> 0.045687054 | G31: =IF(('Precinct Vote Data'!H118>0.5)<>('Precinct Vote Data'!H119>0.5),1,0)+IF(('Precinct Vote Data'!H119>0.5)<>('Precinct Vote Data'!H120>0.5),1,0)+IF(('Precinct Vote Data'!H120>0.5)<>('Precinct Vote Data'!H121>0.5),1,0) -> 0 | H31: =IF(OR(G31>=1,E31<0.05),"Hard",IF(AND(E31>=0.15,F31<0.05),"Easy","Medium")) -> Medium
A32: Carbon | B32: NESQUEHONING | C32: 310 | D32: =AVERAGE('Precinct Vote Data'!H122:H125) -> 0.40443313 | E32: =AVERAGE(ABS('Precinct Vote Data'!H122-0.5),ABS('Precinct Vote Data'!H123-0.5),ABS('Precinct Vote Data'!H124-0.5),ABS('Precinct Vote Data'!H125-0.5)) -> 0.09556687 | F32: =STDEV('Precinct Vote Data'!H122:H125) -> 0.050456204 | G32: =IF(('Precinct Vote Data'!H122>0.5)<>('Precinct Vote Data'!H123>0.5),1,0)+IF(('Precinct Vote Data'!H123>0.5)<>('Precinct Vote Data'!H124>0.5),1,0)+IF(('Precinct Vote Data'!H124>0.5)<>('Precinct Vote Data'!H125>0.5),1,0) -> 0 | H32: =IF(OR(G32>=1,E32<0.05),"Hard",IF(AND(E32>=0.15,F32<0.05),"Easy","Medium")) -> Medium
A33: Carbon | B33: PACKER | C33: 320 | D33: =AVERAGE('Precinct Vote Data'!H126:H129) -> 0.19690165 | E33: =AVERAGE(ABS('Precinct Vote Data'!H126-0.5),ABS('Precinct Vote Data'!H127-0.5),ABS('Precinct Vote Data'!H128-0.5),ABS('Precinct Vote Data'!H129-0.5)) -> 0.30309835 | F33: =STDEV('Precinct Vote Data'!H126:H129) -> 0.027807505 | G33: =IF(('Precinct Vote Data'!H126>0.5)<>('Precinct Vote Data'!H127>0.5),1,0)+IF(('Precinct Vote Data'!H127>0.5)<>('Precinct Vote Data'!H128>0.5),1,0)+IF(('Precinct Vote Data'!H128>0.5)<>('Precinct Vote Data'!H129>0.5),1,0) -> 0 | H33: =IF(OR(G33>=1,E33<0.05),"Hard",IF(AND(E33>=0.15,F33<0.05),"Easy","Medium")) -> Easy
A34: Carbon | B34: PALMERTON | C34: 330 | D34: =AVERAGE('Precinct Vote Data'!H130:H133) -> 0.34568518 | E34: =AVERAGE(ABS('Precinct Vote Data'!H130-0.5),ABS('Precinct Vote Data'!H131-0.5),ABS('Precinct Vote Data'!H132-0.5),ABS('Precinct Vote Data'!H133-0.5)) -> 0.15431482 | F34: =STDEV('Precinct Vote Data'!H130:H133) -> 0.022816524 | G34: =IF(('Precinct Vote Data'!H130>0.5)<>('Precinct Vote Data'!H131>0.5),1,0)+IF(('Precinct Vote Data'!H131>0.5)<>('Precinct Vote Data'!H132>0.5),1,0)+IF(('Precinct Vote Data'!H132>0.5)<>('Precinct Vote Data'!H133>0.5),1,0) -> 0 | H34: =IF(OR(G34>=1,E34<0.05),"Hard",IF(AND(E34>=0.15,F34<0.05),"Easy","Medium")) -> Easy
A35: Carbon | B35: PALMERTON | C35: 340 | D35: =AVERAGE('Precinct Vote Data'!H134:H137) -> 0.40385025 | E35: =AVERAGE(ABS('Precinct Vote Data'!H134-0.5),ABS('Precinct Vote Data'!H135-0.5),ABS('Precinct Vote Data'!H136-0.5),ABS('Precinct Vote Data'!H137-0.5)) -> 0.09614975 | F35: =STDEV('Precinct Vote Data'!H134:H137) -> 0.037702045 | G35: =IF(('Precinct Vote Data'!H134>0.5)<>('Precinct Vote Data'!H135>0.5),1,0)+IF(('Precinct Vote Data'!H135>0.5)<>('Precinct Vote Data'!H136>0.5),1,0)+IF(('Precinct Vote Data'!H136>0.5)<>('Precinct Vote Data'!H137>0.5),1,0) -> 0 | H35: =IF(OR(G35>=1,E35<0.05),"Hard",IF(AND(E35>=0.15,F35<0.05),"Easy","Medium")) -> Medium
A36: Carbon | B36: PALMERTON | C36: 350 | D36: =AVERAGE('Precinct Vote Data'!H138:H141) -> 0.34836005 | E36: =AVERAGE(ABS('Precinct Vote Data'!H138-0.5),ABS('Precinct Vote Data'!H139-0.5),ABS('Precinct Vote Data'!H140-0.5),ABS('Precinct Vote Data'!H141-0.5)) -> 0.15163995 | F36: =STDEV('Precinct Vote Data'!H138:H141) -> 0.03399888 | G36: =IF(('Precinct Vote Data'!H138>0.5)<>('Precinct Vote Data'!H139>0.5),1,0)+IF(('Precinct Vote Data'!H139>0.5)<>('Precinct Vote Data'!H140>0.5),1,0)+IF(('Precinct Vote Data'!H140>0.5)<>('Precinct Vote Data'!H141>0.5),1,0) -> 0 | H36: =IF(OR(G36>=1,E36<0.05),"Hard",IF(AND(E36>=0.15,F36<0.05),"Easy","Medium")) -> Easy
A37: Carbon | B37: PARRYVILLE | C37: 360 | D37: =AVERAGE('Precinct Vote Data'!H142:H145) -> 0.28623541 | E37: =AVERAGE(ABS('Precinct Vote Data'!H142-0.5),ABS('Precinct Vote Data'!H143-0.5),ABS('Precinct Vote Data'!H144-0.5),ABS('Precinct Vote Data'!H145-0.5)) -> 0.21376459 | F37: =STDEV('Precinct Vote Data'!H142:H145) -> 0.038872197 | G37: =IF(('Precinct Vote Data'!H142>0.5)<>('Precinct Vote Data'!H143>0.5),1,0)+IF(('Precinct Vote Data'!H143>0.5)<>('Precinct Vote Data'!H144>0.5),1,0)+IF(('Precinct Vote Data'!H144>0.5)<>('Precinct Vote Data'!H145>0.5),1,0) -> 0 | H37: =IF(OR(G37>=1,E37<0.05),"Hard",IF(AND(E37>=0.15,F37<0.05),"Easy","Medium")) -> Easy
A38: Carbon | B38: PENN FOREST | C38: 370 | D38: =AVERAGE('Precinct Vote Data'!H146:H149) -> 0.36158908 | E38: =AVERAGE(ABS('Precinct Vote Data'!H146-0.5),ABS('Precinct Vote Data'!H147-0.5),ABS('Precinct Vote Data'!H148-0.5),ABS('Precinct Vote Data'!H149-0.5)) -> 0.13841092 | F38: =STDEV('Precinct Vote Data'!H146:H149) -> 0.019860904 | G38: =IF(('Precinct Vote Data'!H146>0.5)<>('Precinct Vote Data'!H147>0.5),1,0)+IF(('Precinct Vote Data'!H147>0.5)<>('Precinct Vote Data'!H148>0.5),1,0)+IF(('Precinct Vote Data'!H148>0.5)<>('Precinct Vote Data'!H149>0.5),1,0) -> 0 | H38: =IF(OR(G38>=1,E38<0.05),"Hard",IF(AND(E38>=0.15,F38<0.05),"Easy","Medium")) -> Medium
A39: Carbon | B39: PENN FOREST | C39: 373 | D39: =AVERAGE('Precinct Vote Data'!H150:H153) -> 0.33280241 | E39: =AVERAGE(ABS('Precinct Vote Data'!H150-0.5),ABS('Precinct Vote Data'!H151-0.5),ABS('Precinct Vote Data'!H152-0.5),ABS('Precinct Vote Data'!H153-0.5)) -> 0.16719759 | F39: =STDEV('Precinct Vote Data'!H150:H153) -> 0.03582395 | G39: =IF(('Precinct Vote Data'!H150>0.5)<>('Precinct Vote Data'!H151>0.5),1,0)+IF(('Precinct Vote Data'!H151>0.5)<>('Precinct Vote Data'!H152>0.5),1,0)+IF(('Precinct Vote Data'!H152>0.5)<>('Precinct Vote Data'!H153>0.5),1,0) -> 0 | H39: =IF(OR(G39>=1,E39<0.05),"Hard",IF(AND(E39>=0.15,F39<0.05),"Easy","Medium")) -> Easy
A40: Carbon | B40: PENN FOREST | C40: 375 | D40: =AVERAGE('Precinct Vote Data'!H154:H157) -> 0.40495123 | E40: =AVERAGE(ABS('Precinct Vote Data'!H154-0.5),ABS('Precinct Vote Data'!H155-0.5),ABS('Precinct Vote Data'!H156-0.5),ABS('Precinct Vote Data'!H157-0.5)) -> 0.095048767 | F40: =STDEV('Precinct Vote Data'!H154:H157) -> 0.027871526 | G40: =IF(('Precinct Vote Data'!H154>0.5)<>('Precinct Vote Data'!H155>0.5),1,0)+IF(('Precinct Vote Data'!H155>0.5)<>('Precinct Vote Data'!H156>0.5),1,0)+IF(('Precinct Vote Data'!H156>0.5)<>('Precinct Vote Data'!H157>0.5),1,0) -> 0 | H40: =IF(OR(G40>=1,E40<0.05),"Hard",IF(AND(E40>=0.15,F40<0.05),"Easy","Medium")) -> Medium
...

Sheet Magic Precinct
A1: Bellwether Search (408 Precincts)
A3: District-wide result by year
A4: Year | B4: District Dem Votes | C4: District Rep Votes | D4: District Dem Share | E4: District Winner
A5: 2018 | B5: =SUMIF('Precinct Vote Data'!$A:$A,A5,'Precinct Vote Data'!$E:$E) -> 164979 | C5: =SUMIF('Precinct Vote Data'!$A:$A,A5,'Precinct Vote Data'!$F:$F) -> 140498 | D5: =B5/(B5+C5) -> 0.54007012 | E5: =IF(D5>0.5,"D","R") -> D
A6: 2020 | B6: =SUMIF('Precinct Vote Data'!$A:$A,A6,'Precinct Vote Data'!$E:$E) -> 227949 | C6: =SUMIF('Precinct Vote Data'!$A:$A,A6,'Precinct Vote Data'!$F:$F) -> 221629 | D6: =B6/(B6+C6) -> 0.50702881 | E6: =IF(D6>0.5,"D","R") -> D
A7: 2022 | B7: =SUMIF('Precinct Vote Data'!$A:$A,A7,'Precinct Vote Data'!$E:$E) -> 175346 | C7: =SUMIF('Precinct Vote Data'!$A:$A,A7,'Precinct Vote Data'!$F:$F) -> 164738 | D7: =B7/(B7+C7) -> 0.51559615 | E7: =IF(D7>0.5,"D","R") -> D
A8: 2024 | B8: =SUMIF('Precinct Vote Data'!$A:$A,A8,'Precinct Vote Data'!$E:$E) -> 232003 | C8: =SUMIF('Precinct Vote Data'!$A:$A,A8,'Precinct Vote Data'!$F:$F) -> 229952 | D8: =B8/(B8+C8) -> 0.50221991 | E8: =IF(D8>0.5,"D","R") -> D
A11: Per-precinct bellwether test
A12: County | B12: Municipality | C12: Precinct Code | D12: Match 2018 | E12: Match 2020 | F12: Match 2022 | G12: Match 2024 | H12: Total Matches (/4) | I12: Avg Point Gap vs District | J12: Magic Precinct? | K12: (h)
A13: Carbon | B13: BANKS | C13: 10 | D13: =IF(IF('Precinct Vote Data'!H2>0.5,"D","R")=$E$5,1,0) -> 0 | E13: =IF(IF('Precinct Vote Data'!H3>0.5,"D","R")=$E$6,1,0) -> 0 | F13: =IF(IF('Precinct Vote Data'!H4>0.5,"D","R")=$E$7,1,0) -> 0 | G13: =IF(IF('Precinct Vote Data'!H5>0.5,"D","R")=$E$8,1,0) -> 0 | H13: =SUM(D13:G13) -> 0 | I13: =AVERAGE(ABS('Precinct Vote Data'!H2-$D$5),ABS('Precinct Vote Data'!H3-$D$6),ABS('Precinct Vote Data'!H4-$D$7),ABS('Precinct Vote Data'!H5-$D$8)) -> 0.14041824 | J13: =IF(AND(H13=4,I13=MIN(K13:K420)),"<< MAGIC PRECINCT","") | K13: =IF(H13=4,I13,"")
A14: Carbon | B14: BEAVER MEADOWS | C14: 40 | D14: =IF(IF('Precinct Vote Data'!H6>0.5,"D","R")=$E$5,1,0) -> 0 | E14: =IF(IF('Precinct Vote Data'!H7>0.5,"D","R")=$E$6,1,0) -> 0 | F14: =IF(IF('Precinct Vote Data'!H8>0.5,"D","R")=$E$7,1,0) -> 0 | G14: =IF(IF('Precinct Vote Data'!H9>0.5,"D","R")=$E$8,1,0) -> 0 | H14: =SUM(D14:G14) -> 0 | I14: =AVERAGE(ABS('Precinct Vote Data'!H6-$D$5),ABS('Precinct Vote Data'!H7-$D$6),ABS('Precinct Vote Data'!H8-$D$7),ABS('Precinct Vote Data'!H9-$D$8)) -> 0.23398825 | J14: =IF(AND(H14=4,I14=MIN(K13:K420)),"<< MAGIC PRECINCT","") | K14: =IF(H14=4,I14,"")
A15: Carbon | B15: BOWMANSTOWN | C15: 50 | D15: =IF(IF('Precinct Vote Data'!H10>0.5,"D","R")=$E$5,1,0) -> 0 | E15: =IF(IF('Precinct Vote Data'!H11>0.5,"D","R")=$E$6,1,0) -> 0 | F15: =IF(IF('Precinct Vote Data'!H12>0.5,"D","R")=$E$7,1,0) -> 0 | G15: =IF(IF('Precinct Vote Data'!H13>0.5,"D","R")=$E$8,1,0) -> 0 | H15: =SUM(D15:G15) -> 0 | I15: =AVERAGE(ABS('Precinct Vote Data'!H10-$D$5),ABS('Precinct Vote Data'!H11-$D$6),ABS('Precinct Vote Data'!H12-$D$7),ABS('Precinct Vote Data'!H13-$D$8)) -> 0.18580707 | J15: =IF(AND(H15=4,I15=MIN(K13:K420)),"<< MAGIC PRECINCT","") | K15: =IF(H15=4,I15,"")
A16: Carbon | B16: EAST PENN | C16: 60 | D16: =IF(IF('Precinct Vote Data'!H14>0.5,"D","R")=$E$5,1,0) -> 0 | E16: =IF(IF('Precinct Vote Data'!H15>0.5,"D","R")=$E$6,1,0) -> 0 | F16: =IF(IF('Precinct Vote Data'!H16>0.5,"D","R")=$E$7,1,0) -> 0 | G16: =IF(IF('Precinct Vote Data'!H17>0.5,"D","R")=$E$8,1,0) -> 0 | H16: =SUM(D16:G16) -> 0 | I16: =AVERAGE(ABS('Precinct Vote Data'!H14-$D$5),ABS('Precinct Vote Data'!H15-$D$6),ABS('Precinct Vote Data'!H16-$D$7),ABS('Precinct Vote Data'!H17-$D$8)) -> 0.24121696 | J16: =IF(AND(H16=4,I16=MIN(K13:K420)),"<< MAGIC PRECINCT","") | K16: =IF(H16=4,I16,"")
A17: Carbon | B17: EAST PENN | C17: 65 | D17: =IF(IF('Precinct Vote Data'!H18>0.5,"D","R")=$E$5,1,0) -> 0 | E17: =IF(IF('Precinct Vote Data'!H19>0.5,"D","R")=$E$6,1,0) -> 0 | F17: =IF(IF('Precinct Vote Data'!H20>0.5,"D","R")=$E$7,1,0) -> 0 | G17: =IF(IF('Precinct Vote Data'!H21>0.5,"D","R")=$E$8,1,0) -> 0 | H17: =SUM(D17:G17) -> 0 | I17: =AVERAGE(ABS('Precinct Vote Data'!H18-$D$5),ABS('Precinct Vote Data'!H19-$D$6),ABS('Precinct Vote Data'!H20-$D$7),ABS('Precinct Vote Data'!H21-$D$8)) -> 0.22758407 | J17: =IF(AND(H17=4,I17=MIN(K13:K420)),"<< MAGIC PRECINCT","") | K17: =IF(H17=4,I17,"")
A18: Carbon | B18: EAST SIDE | C18: 70 | D18: =IF(IF('Precinct Vote Data'!H22>0.5,"D","R")=$E$5,1,0) -> 0 | E18: =IF(IF('Precinct Vote Data'!H23>0.5,"D","R")=$E$6,1,0) -> 0 | F18: =IF(IF('Precinct Vote Data'!H24>0.5,"D","R")=$E$7,1,0) -> 0 | G18: =IF(IF('Precinct Vote Data'!H25>0.5,"D","R")=$E$8,1,0) -> 0 | H18: =SUM(D18:G18) -> 0 | I18: =AVERAGE(ABS('Precinct Vote Data'!H22-$D$5),ABS('Precinct Vote Data'!H23-$D$6),ABS('Precinct Vote Data'!H24-$D$7),ABS('Precinct Vote Data'!H25-$D$8)) -> 0.13906919 | J18: =IF(AND(H18=4,I18=MIN(K13:K420)),"<< MAGIC PRECINCT","") | K18: =IF(H18=4,I18,"")
A19: Carbon | B19: FRANKLIN | C19: 80 | D19: =IF(IF('Precinct Vote Data'!H26>0.5,"D","R")=$E$5,1,0) -> 0 | E19: =IF(IF('Precinct Vote Data'!H27>0.5,"D","R")=$E$6,1,0) -> 0 | F19: =IF(IF('Precinct Vote Data'!H28>0.5,"D","R")=$E$7,1,0) -> 0 | G19: =IF(IF('Precinct Vote Data'!H29>0.5,"D","R")=$E$8,1,0) -> 0 | H19: =SUM(D19:G19) -> 0 | I19: =AVERAGE(ABS('Precinct Vote Data'!H26-$D$5),ABS('Precinct Vote Data'!H27-$D$6),ABS('Precinct Vote Data'!H28-$D$7),ABS('Precinct Vote Data'!H29-$D$8)) -> 0.22358774 | J19: =IF(AND(H19=4,I19=MIN(K13:K420)),"<< MAGIC PRECINCT","") | K19: =IF(H19=4,I19,"")
A20: Carbon | B20: FRANKLIN | C20: 90 | D20: =IF(IF('Precinct Vote Data'!H30>0.5,"D","R")=$E$5,1,0) -> 0 | E20: =IF(IF('Precinct Vote Data'!H31>0.5,"D","R")=$E$6,1,0) -> 0 | F20: =IF(IF('Precinct Vote Data'!H32>0.5,"D","R")=$E$7,1,0) -> 0 | G20: =IF(IF('Precinct Vote Data'!H33>0.5,"D","R")=$E$8,1,0) -> 0 | H20: =SUM(D20:G20) -> 0 | I20: =AVERAGE(ABS('Precinct Vote Data'!H30-$D$5),ABS('Precinct Vote Data'!H31-$D$6),ABS('Precinct Vote Data'!H32-$D$7),ABS('Precinct Vote Data'!H33-$D$8)) -> 0.21887958 | J20: =IF(AND(H20=4,I20=MIN(K13:K420)),"<< MAGIC PRECINCT","") | K20: =IF(H20=4,I20,"")
A21: Carbon | B21: FRANKLIN | C21: 100 | D21: =IF(IF('Precinct Vote Data'!H34>0.5,"D","R")=$E$5,1,0) -> 0 | E21: =IF(IF('Precinct Vote Data'!H35>0.5,"D","R")=$E$6,1,0) -> 0 | F21: =IF(IF('Precinct Vote Data'!H36>0.5,"D","R")=$E$7,1,0) -> 0 | G21: =IF(IF('Precinct Vote Data'!H37>0.5,"D","R")=$E$8,1,0) -> 0 | H21: =SUM(D21:G21) -> 0 | I21: =AVERAGE(ABS('Precinct Vote Data'!H34-$D$5),ABS('Precinct Vote Data'!H35-$D$6),ABS('Precinct Vote Data'!H36-$D$7),ABS('Precinct Vote Data'!H37-$D$8)) -> 0.24992126 | J21: =IF(AND(H21=4,I21=MIN(K13:K420)),"<< MAGIC PRECINCT","") | K21: =IF(H21=4,I21,"")
A22: Carbon | B22: JIM THORPE | C22: 110 | D22: =IF(IF('Precinct Vote Data'!H38>0.5,"D","R")=$E$5,1,0) -> 1 | E22: =IF(IF('Precinct Vote Data'!H39>0.5,"D","R")=$E$6,1,0) -> 0 | F22: =IF(IF('Precinct Vote Data'!H40>0.5,"D","R")=$E$7,1,0) -> 0 | G22: =IF(IF('Precinct Vote Data'!H41>0.5,"D","R")=$E$8,1,0) -> 0 | H22: =SUM(D22:G22) -> 1 | I22: =AVERAGE(ABS('Precinct Vote Data'!H38-$D$5),ABS('Precinct Vote Data'!H39-$D$6),ABS('Precinct Vote Data'!H40-$D$7),ABS('Precinct Vote Data'!H41-$D$8)) -> 0.052686831 | J22: =IF(AND(H22=4,I22=MIN(K13:K420)),"<< MAGIC PRECINCT","") | K22: =IF(H22=4,I22,"")
A23: Carbon | B23: JIM THORPE | C23: 120 | D23: =IF(IF('Precinct Vote Data'!H42>0.5,"D","R")=$E$5,1,0) -> 0 | E23: =IF(IF('Precinct Vote Data'!H43>0.5,"D","R")=$E$6,1,0) -> 0 | F23: =IF(IF('Precinct Vote Data'!H44>0.5,"D","R")=$E$7,1,0) -> 0 | G23: =IF(IF('Precinct Vote Data'!H45>0.5,"D","R")=$E$8,1,0) -> 0 | H23: =SUM(D23:G23) -> 0 | I23: =AVERAGE(ABS('Precinct Vote Data'!H42-$D$5),ABS('Precinct Vote Data'!H43-$D$6),ABS('Precinct Vote Data'!H44-$D$7),ABS('Precinct Vote Data'!H45-$D$8)) -> 0.095238655 | J23: =IF(AND(H23=4,I23=MIN(K13:K420)),"<< MAGIC PRECINCT","") | K23: =IF(H23=4,I23,"")
A24: Carbon | B24: JIM THORPE | C24: 130 | D24: =IF(IF('Precinct Vote Data'!H46>0.5,"D","R")=$E$5,1,0) -> 0 | E24: =IF(IF('Precinct Vote Data'!H47>0.5,"D","R")=$E$6,1,0) -> 0 | F24: =IF(IF('Precinct Vote Data'!H48>0.5,"D","R")=$E$7,1,0) -> 0 | G24: =IF(IF('Precinct Vote Data'!H49>0.5,"D","R")=$E$8,1,0) -> 0 | H24: =SUM(D24:G24) -> 0 | I24: =AVERAGE(ABS('Precinct Vote Data'!H46-$D$5),ABS('Precinct Vote Data'!H47-$D$6),ABS('Precinct Vote Data'!H48-$D$7),ABS('Precinct Vote Data'!H49-$D$8)) -> 0.11284422 | J24: =IF(AND(H24=4,I24=MIN(K13:K420)),"<< MAGIC PRECINCT","") | K24: =IF(H24=4,I24,"")
A25: Carbon | B25: JIM THORPE | C25: 140 | D25: =IF(IF('Precinct Vote Data'!H50>0.5,"D","R")=$E$5,1,0) -> 1 | E25: =IF(IF('Precinct Vote Data'!H51>0.5,"D","R")=$E$6,1,0) -> 1 | F25: =IF(IF('Precinct Vote Data'!H52>0.5,"D","R")=$E$7,1,0) -> 1 | G25: =IF(IF('Precinct Vote Data'!H53>0.5,"D","R")=$E$8,1,0) -> 1 | H25: =SUM(D25:G25) -> 4 | I25: =AVERAGE(ABS('Precinct Vote Data'!H50-$D$5),ABS('Precinct Vote Data'!H51-$D$6),ABS('Precinct Vote Data'!H52-$D$7),ABS('Precinct Vote Data'!H53-$D$8)) -> 0.030304772 | J25: =IF(AND(H25=4,I25=MIN(K13:K420)),"<< MAGIC PRECINCT","") | K25: =IF(H25=4,I25,"") -> 0.030304772
A26: Carbon | B26: JIM THORPE | C26: 150 | D26: =IF(IF('Precinct Vote Data'!H54>0.5,"D","R")=$E$5,1,0) -> 0 | E26: =IF(IF('Precinct Vote Data'!H55>0.5,"D","R")=$E$6,1,0) -> 0 | F26: =IF(IF('Precinct Vote Data'!H56>0.5,"D","R")=$E$7,1,0) -> 0 | G26: =IF(IF('Precinct Vote Data'!H57>0.5,"D","R")=$E$8,1,0) -> 0 | H26: =SUM(D26:G26) -> 0 | I26: =AVERAGE(ABS('Precinct Vote Data'!H54-$D$5),ABS('Precinct Vote Data'!H55-$D$6),ABS('Precinct Vote Data'!H56-$D$7),ABS('Precinct Vote Data'!H57-$D$8)) -> 0.067497004 | J26: =IF(AND(H26=4,I26=MIN(K13:K420)),"<< MAGIC PRECINCT","") | K26: =IF(H26=4,I26,"")
A27: Carbon | B27: KIDDER | C27: 160 | D27: =IF(IF('Precinct Vote Data'!H58>0.5,"D","R")=$E$5,1,0) -> 0 | E27: =IF(IF('Precinct Vote Data'!H59>0.5,"D","R")=$E$6,1,0) -> 0 | F27: =IF(IF('Precinct Vote Data'!H60>0.5,"D","R")=$E$7,1,0) -> 0 | G27: =IF(IF('Precinct Vote Data'!H61>0.5,"D","R")=$E$8,1,0) -> 0 | H27: =SUM(D27:G27) -> 0 | I27: =AVERAGE(ABS('Precinct Vote Data'!H58-$D$5),ABS('Precinct Vote Data'!H59-$D$6),ABS('Precinct Vote Data'!H60-$D$7),ABS('Precinct Vote Data'!H61-$D$8)) -> 0.15784233 | J27: =IF(AND(H27=4,I27=MIN(K13:K420)),"<< MAGIC PRECINCT","") | K27: =IF(H27=4,I27,"")
A28: Carbon | B28: KIDDER | C28: 170 | D28: =IF(IF('Precinct Vote Data'!H62>0.5,"D","R")=$E$5,1,0) -> 0 | E28: =IF(IF('Precinct Vote Data'!H63>0.5,"D","R")=$E$6,1,0) -> 0 | F28: =IF(IF('Precinct Vote Data'!H64>0.5,"D","R")=$E$7,1,0) -> 0 | G28: =IF(IF('Precinct Vote Data'!H65>0.5,"D","R")=$E$8,1,0) -> 0 | H28: =SUM(D28:G28) -> 0 | I28: =AVERAGE(ABS('Precinct Vote Data'!H62-$D$5),ABS('Precinct Vote Data'!H63-$D$6),ABS('Precinct Vote Data'!H64-$D$7),ABS('Precinct Vote Data'!H65-$D$8)) -> 0.19785849 | J28: =IF(AND(H28=4,I28=MIN(K13:K420)),"<< MAGIC PRECINCT","") | K28: =IF(H28=4,I28,"")
A29: Carbon | B29: LANSFORD | C29: 180 | D29: =IF(IF('Precinct Vote Data'!H66>0.5,"D","R")=$E$5,1,0) -> 0 | E29: =IF(IF('Precinct Vote Data'!H67>0.5,"D","R")=$E$6,1,0) -> 0 | F29: =IF(IF('Precinct Vote Data'!H68>0.5,"D","R")=$E$7,1,0) -> 0 | G29: =IF(IF('Precinct Vote Data'!H69>0.5,"D","R")=$E$8,1,0) -> 0 | H29: =SUM(D29:G29) -> 0 | I29: =AVERAGE(ABS('Precinct Vote Data'!H66-$D$5),ABS('Precinct Vote Data'!H67-$D$6),ABS('Precinct Vote Data'!H68-$D$7),ABS('Precinct Vote Data'!H69-$D$8)) -> 0.090661381 | J29: =IF(AND(H29=4,I29=MIN(K13:K420)),"<< MAGIC PRECINCT","") | K29: =IF(H29=4,I29,"")
A30: Carbon | B30: LANSFORD | C30: 190 | D30: =IF(IF('Precinct Vote Data'!H70>0.5,"D","R")=$E$5,1,0) -> 0 | E30: =IF(IF('Precinct Vote Data'!H71>0.5,"D","R")=$E$6,1,0) -> 0 | F30: =IF(IF('Precinct Vote Data'!H72>0.5,"D","R")=$E$7,1,0) -> 0 | G30: =IF(IF('Precinct Vote Data'!H73>0.5,"D","R")=$E$8,1,0) -> 0 | H30: =SUM(D30:G30) -> 0 | I30: =AVERAGE(ABS('Precinct Vote Data'!H70-$D$5),ABS('Precinct Vote Data'!H71-$D$6),ABS('Precinct Vote Data'!H72-$D$7),ABS('Precinct Vote Data'!H73-$D$8)) -> 0.091468252 | J30: =IF(AND(H30=4,I30=MIN(K13:K420)),"<< MAGIC PRECINCT","") | K30: =IF(H30=4,I30,"")
A31: Carbon | B31: LANSFORD | C31: 200 | D31: =IF(IF('Precinct Vote Data'!H74>0.5,"D","R")=$E$5,1,0) -> 1 | E31: =IF(IF('Precinct Vote Data'!H75>0.5,"D","R")=$E$6,1,0) -> 0 | F31: =IF(IF('Precinct Vote Data'!H76>0.5,"D","R")=$E$7,1,0) -> 0 | G31: =IF(IF('Precinct Vote Data'!H77>0.5,"D","R")=$E$8,1,0) -> 0 | H31: =SUM(D31:G31) -> 1 | I31: =AVERAGE(ABS('Precinct Vote Data'!H74-$D$5),ABS('Precinct Vote Data'!H75-$D$6),ABS('Precinct Vote Data'!H76-$D$7),ABS('Precinct Vote Data'!H77-$D$8)) -> 0.061376743 | J31: =IF(AND(H31=4,I31=MIN(K13:K420)),"<< MAGIC PRECINCT","") | K31: =IF(H31=4,I31,"")
A32: Carbon | B32: LAUSANNE | C32: 210 | D32: =IF(IF('Precinct Vote Data'!H78>0.5,"D","R")=$E$5,1,0) -> 0 | E32: =IF(IF('Precinct Vote Data'!H79>0.5,"D","R")=$E$6,1,0) -> 0 | F32: =IF(IF('Precinct Vote Data'!H80>0.5,"D","R")=$E$7,1,0) -> 0 | G32: =IF(IF('Precinct Vote Data'!H81>0.5,"D","R")=$E$8,1,0) -> 0 | H32: =SUM(D32:G32) -> 0 | I32: =AVERAGE(ABS('Precinct Vote Data'!H78-$D$5),ABS('Precinct Vote Data'!H79-$D$6),ABS('Precinct Vote Data'!H80-$D$7),ABS('Precinct Vote Data'!H81-$D$8)) -> 0.21559619 | J32: =IF(AND(H32=4,I32=MIN(K13:K420)),"<< MAGIC PRECINCT","") | K32: =IF(H32=4,I32,"")
A33: Carbon | B33: LEHIGH | C33: 220 | D33: =IF(IF('Precinct Vote Data'!H82>0.5,"D","R")=$E$5,1,0) -> 0 | E33: =IF(IF('Precinct Vote Data'!H83>0.5,"D","R")=$E$6,1,0) -> 0 | F33: =IF(IF('Precinct Vote Data'!H84>0.5,"D","R")=$E$7,1,0) -> 0 | G33: =IF(IF('Precinct Vote Data'!H85>0.5,"D","R")=$E$8,1,0) -> 0 | H33: =SUM(D33:G33) -> 0 | I33: =AVERAGE(ABS('Precinct Vote Data'!H82-$D$5),ABS('Precinct Vote Data'!H83-$D$6),ABS('Precinct Vote Data'!H84-$D$7),ABS('Precinct Vote Data'!H85-$D$8)) -> 0.31258919 | J33: =IF(AND(H33=4,I33=MIN(K13:K420)),"<< MAGIC PRECINCT","") | K33: =IF(H33=4,I33,"")
A34: Carbon | B34: LEHIGHTON | C34: 230 | D34: =IF(IF('Precinct Vote Data'!H86>0.5,"D","R")=$E$5,1,0) -> 0 | E34: =IF(IF('Precinct Vote Data'!H87>0.5,"D","R")=$E$6,1,0) -> 0 | F34: =IF(IF('Precinct Vote Data'!H88>0.5,"D","R")=$E$7,1,0) -> 0 | G34: =IF(IF('Precinct Vote Data'!H89>0.5,"D","R")=$E$8,1,0) -> 0 | H34: =SUM(D34:G34) -> 0 | I34: =AVERAGE(ABS('Precinct Vote Data'!H86-$D$5),ABS('Precinct Vote Data'!H87-$D$6),ABS('Precinct Vote Data'!H88-$D$7),ABS('Precinct Vote Data'!H89-$D$8)) -> 0.1086087 | J34: =IF(AND(H34=4,I34=MIN(K13:K420)),"<< MAGIC PRECINCT","") | K34: =IF(H34=4,I34,"")
A35: Carbon | B35: LEHIGHTON | C35: 240 | D35: =IF(IF('Precinct Vote Data'!H90>0.5,"D","R")=$E$5,1,0) -> 0 | E35: =IF(IF('Precinct Vote Data'!H91>0.5,"D","R")=$E$6,1,0) -> 0 | F35: =IF(IF('Precinct Vote Data'!H92>0.5,"D","R")=$E$7,1,0) -> 0 | G35: =IF(IF('Precinct Vote Data'!H93>0.5,"D","R")=$E$8,1,0) -> 0 | H35: =SUM(D35:G35) -> 0 | I35: =AVERAGE(ABS('Precinct Vote Data'!H90-$D$5),ABS('Precinct Vote Data'!H91-$D$6),ABS('Precinct Vote Data'!H92-$D$7),ABS('Precinct Vote Data'!H93-$D$8)) -> 0.093443691 | J35: =IF(AND(H35=4,I35=MIN(K13:K420)),"<< MAGIC PRECINCT","") | K35: =IF(H35=4,I35,"")
A36: Carbon | B36: LEHIGHTON | C36: 250 | D36: =IF(IF('Precinct Vote Data'!H94>0.5,"D","R")=$E$5,1,0) -> 0 | E36: =IF(IF('Precinct Vote Data'!H95>0.5,"D","R")=$E$6,1,0) -> 0 | F36: =IF(IF('Precinct Vote Data'!H96>0.5,"D","R")=$E$7,1,0) -> 0 | G36: =IF(IF('Precinct Vote Data'!H97>0.5,"D","R")=$E$8,1,0) -> 0 | H36: =SUM(D36:G36) -> 0 | I36: =AVERAGE(ABS('Precinct Vote Data'!H94-$D$5),ABS('Precinct Vote Data'!H95-$D$6),ABS('Precinct Vote Data'!H96-$D$7),ABS('Precinct Vote Data'!H97-$D$8)) -> 0.10126099 | J36: =IF(AND(H36=4,I36=MIN(K13:K420)),"<< MAGIC PRECINCT","") | K36: =IF(H36=4,I36,"")
A37: Carbon | B37: LOWER TOWAMENSING | C37: 260 | D37: =IF(IF('Precinct Vote Data'!H98>0.5,"D","R")=$E$5,1,0) -> 0 | E37: =IF(IF('Precinct Vote Data'!H99>0.5,"D","R")=$E$6,1,0) -> 0 | F37: =IF(IF('Precinct Vote Data'!H100>0.5,"D","R")=$E$7,1,0) -> 0 | G37: =IF(IF('Precinct Vote Data'!H101>0.5,"D","R")=$E$8,1,0) -> 0 | H37: =SUM(D37:G37) -> 0 | I37: =AVERAGE(ABS('Precinct Vote Data'!H98-$D$5),ABS('Precinct Vote Data'!H99-$D$6),ABS('Precinct Vote Data'!H100-$D$7),ABS('Precinct Vote Data'!H101-$D$8)) -> 0.21134064 | J37: =IF(AND(H37=4,I37=MIN(K13:K420)),"<< MAGIC PRECINCT","") | K37: =IF(H37=4,I37,"")
A38: Carbon | B38: LOWER TOWAMENSING | C38: 265 | D38: =IF(IF('Precinct Vote Data'!H102>0.5,"D","R")=$E$5,1,0) -> 0 | E38: =IF(IF('Precinct Vote Data'!H103>0.5,"D","R")=$E$6,1,0) -> 0 | F38: =IF(IF('Precinct Vote Data'!H104>0.5,"D","R")=$E$7,1,0) -> 0 | G38: =IF(IF('Precinct Vote Data'!H105>0.5,"D","R")=$E$8,1,0) -> 0 | H38: =SUM(D38:G38) -> 0 | I38: =AVERAGE(ABS('Precinct Vote Data'!H102-$D$5),ABS('Precinct Vote Data'!H103-$D$6),ABS('Precinct Vote Data'!H104-$D$7),ABS('Precinct Vote Data'!H105-$D$8)) -> 0.18068467 | J38: =IF(AND(H38=4,I38=MIN(K13:K420)),"<< MAGIC PRECINCT","") | K38: =IF(H38=4,I38,"")
A39: Carbon | B39: MAHONING | C39: 270 | D39: =IF(IF('Precinct Vote Data'!H106>0.5,"D","R")=$E$5,1,0) -> 0 | E39: =IF(IF('Precinct Vote Data'!H107>0.5,"D","R")=$E$6,1,0) -> 0 | F39: =IF(IF('Precinct Vote Data'!H108>0.5,"D","R")=$E$7,1,0) -> 0 | G39: =IF(IF('Precinct Vote Data'!H109>0.5,"D","R")=$E$8,1,0) -> 0 | H39: =SUM(D39:G39) -> 0 | I39: =AVERAGE(ABS('Precinct Vote Data'!H106-$D$5),ABS('Precinct Vote Data'!H107-$D$6),ABS('Precinct Vote Data'!H108-$D$7),ABS('Precinct Vote Data'!H109-$D$8)) -> 0.20122407 | J39: =IF(AND(H39=4,I39=MIN(K13:K420)),"<< MAGIC PRECINCT","") | K39: =IF(H39=4,I39,"")
A40: Carbon | B40: MAHONING | C40: 280 | D40: =IF(IF('Precinct Vote Data'!H110>0.5,"D","R")=$E$5,1,0) -> 0 | E40: =IF(IF('Precinct Vote Data'!H111>0.5,"D","R")=$E$6,1,0) -> 0 | F40: =IF(IF('Precinct Vote Data'!H112>0.5,"D","R")=$E$7,1,0) -> 0 | G40: =IF(IF('Precinct Vote Data'!H113>0.5,"D","R")=$E$8,1,0) -> 0 | H40: =SUM(D40:G40) -> 0 | I40: =AVERAGE(ABS('Precinct Vote Data'!H110-$D$5),ABS('Precinct Vote Data'!H111-$D$6),ABS('Precinct Vote Data'!H112-$D$7),ABS('Precinct Vote Data'!H113-$D$8)) -> 0.25718725 | J40: =IF(AND(H40=4,I40=MIN(K13:K420)),"<< MAGIC PRECINCT","") | K40: =IF(H40=4,I40,"")
A41: Carbon | B41: MAHONING | C41: 290 | D41: =IF(IF('Precinct Vote Data'!H114>0.5,"D","R")=$E$5,1,0) -> 0 | E41: =IF(IF('Precinct Vote Data'!H115>0.5,"D","R")=$E$6,1,0) -> 0 | F41: =IF(IF('Precinct Vote Data'!H116>0.5,"D","R")=$E$7,1,0) -> 0 | G41: =IF(IF('Precinct Vote Data'!H117>0.5,"D","R")=$E$8,1,0) -> 0 | H41: =SUM(D41:G41) -> 0 | I41: =AVERAGE(ABS('Precinct Vote Data'!H114-$D$5),ABS('Precinct Vote Data'!H115-$D$6),ABS('Precinct Vote Data'!H116-$D$7),ABS('Precinct Vote Data'!H117-$D$8)) -> 0.20020902 | J41: =IF(AND(H41=4,I41=MIN(K13:K420)),"<< MAGIC PRECINCT","") | K41: =IF(H41=4,I41,"")
A42: Carbon | B42: NESQUEHONING | C42: 300 | D42: =IF(IF('Precinct Vote Data'!H118>0.5,"D","R")=$E$5,1,0) -> 0 | E42: =IF(IF('Precinct Vote Data'!H119>0.5,"D","R")=$E$6,1,0) -> 0 | F42: =IF(IF('Precinct Vote Data'!H120>0.5,"D","R")=$E$7,1,0) -> 0 | G42: =IF(IF('Precinct Vote Data'!H121>0.5,"D","R")=$E$8,1,0) -> 0 | H42: =SUM(D42:G42) -> 0 | I42: =AVERAGE(ABS('Precinct Vote Data'!H118-$D$5),ABS('Precinct Vote Data'!H119-$D$6),ABS('Precinct Vote Data'!H120-$D$7),ABS('Precinct Vote Data'!H121-$D$8)) -> 0.09654972 | J42: =IF(AND(H42=4,I42=MIN(K13:K420)),"<< MAGIC PRECINCT","") | K42: =IF(H42=4,I42,"")
A43: Carbon | B43: NESQUEHONING | C43: 310 | D43: =IF(IF('Precinct Vote Data'!H122>0.5,"D","R")=$E$5,1,0) -> 0 | E43: =IF(IF('Precinct Vote Data'!H123>0.5,"D","R")=$E$6,1,0) -> 0 | F43: =IF(IF('Precinct Vote Data'!H124>0.5,"D","R")=$E$7,1,0) -> 0 | G43: =IF(IF('Precinct Vote Data'!H125>0.5,"D","R")=$E$8,1,0) -> 0 | H43: =SUM(D43:G43) -> 0 | I43: =AVERAGE(ABS('Precinct Vote Data'!H122-$D$5),ABS('Precinct Vote Data'!H123-$D$6),ABS('Precinct Vote Data'!H124-$D$7),ABS('Precinct Vote Data'!H125-$D$8)) -> 0.11179562 | J43: =IF(AND(H43=4,I43=MIN(K13:K420)),"<< MAGIC PRECINCT","") | K43: =IF(H43=4,I43,"")
...

Sheet Beta Coefficients
A1: Precinct Beta vs. the Combined District (408 Precincts)
A3: 2018 | B3: 2020 | C3: 2022 | D3: 2024
A4: ='Magic Precinct'!D5 -> 0.54007012 | B4: ='Magic Precinct'!D6 -> 0.50702881 | C4: ='Magic Precinct'!D7 -> 0.51559615 | D4: ='Magic Precinct'!D8 -> 0.50221991
A6: County | B6: Municipality | C6: Precinct Code | D6: Beta | E6: R-squared | F6: Deviation from 1.0 | G6: Avg Dem Share | H6: Selected (Top 30 fit) | N6: (h) score | O6: (h) rank | Q6: (h) key
A7: Carbon | B7: BANKS | C7: 10 | D7: =SLOPE(J7:M7,$A$4:$D$4) -> 1.434379 | E7: =RSQ(J7:M7,$A$4:$D$4) -> 0.45663706 | F7: =ABS(D7-1) -> 0.43437901 | G7: =AVERAGE(J7:M7) -> 0.37581051 | H7: =IF(O7<=30,"YES","") | J7: ='Precinct Vote Data'!H2 -> 0.41994751 | K7: ='Precinct Vote Data'!H3 -> 0.33996024 | L7: ='Precinct Vote Data'!H4 -> 0.35492228 | M7: ='Precinct Vote Data'!H5 -> 0.38841202 | N7: =F7+(1-E7) -> 0.97774196 | O7: =RANK(N7,$N$7:$N$414,1) -> 185 | Q7: =A7&"|"&B7&"|"&C7 -> Carbon|BANKS|10
A8: Carbon | B8: BEAVER MEADOWS | C8: 40 | D8: =SLOPE(J8:M8,$A$4:$D$4) -> 1.7476841 | E8: =RSQ(J8:M8,$A$4:$D$4) -> 0.6905668 | F8: =ABS(D8-1) -> 0.74768411 | G8: =AVERAGE(J8:M8) -> 0.2822405 | H8: =IF(O8<=30,"YES","") | J8: ='Precinct Vote Data'!H6 -> 0.33101045 | K8: ='Precinct Vote Data'!H7 -> 0.24813896 | L8: ='Precinct Vote Data'!H8 -> 0.26751592 | M8: ='Precinct Vote Data'!H9 -> 0.28229665 | N8: =F8+(1-E8) -> 1.0571173 | O8: =RANK(N8,$N$7:$N$414,1) -> 201 | Q8: =A8&"|"&B8&"|"&C8 -> Carbon|BEAVER MEADOWS|40
A9: Carbon | B9: BOWMANSTOWN | C9: 50 | D9: =SLOPE(J9:M9,$A$4:$D$4) -> 2.5249104 | E9: =RSQ(J9:M9,$A$4:$D$4) -> 0.59266055 | F9: =ABS(D9-1) -> 1.5249104 | G9: =AVERAGE(J9:M9) -> 0.33042168 | H9: =IF(O9<=30,"YES","") | J9: ='Precinct Vote Data'!H10 -> 0.38596491 | K9: ='Precinct Vote Data'!H11 -> 0.25934579 | L9: ='Precinct Vote Data'!H12 -> 0.3591954 | M9: ='Precinct Vote Data'!H13 -> 0.31718062 | N9: =F9+(1-E9) -> 1.9322499 | O9: =RANK(N9,$N$7:$N$414,1) -> 340 | Q9: =A9&"|"&B9&"|"&C9 -> Carbon|BOWMANSTOWN|50
A10: Carbon | B10: EAST PENN | C10: 60 | D10: =SLOPE(J10:M10,$A$4:$D$4) -> 2.3564244 | E10: =RSQ(J10:M10,$A$4:$D$4) -> 0.9900438 | F10: =ABS(D10-1) -> 1.3564244 | G10: =AVERAGE(J10:M10) -> 0.27501179 | H10: =IF(O10<=30,"YES","") | J10: ='Precinct Vote Data'!H14 -> 0.3295082 | K10: ='Precinct Vote Data'!H15 -> 0.25031928 | L10: ='Precinct Vote Data'!H16 -> 0.27936963 | M10: ='Precinct Vote Data'!H17 -> 0.24085006 | N10: =F10+(1-E10) -> 1.3663806 | O10: =RANK(N10,$N$7:$N$414,1) -> 259 | Q10: =A10&"|"&B10&"|"&C10 -> Carbon|EAST PENN|60
A11: Carbon | B11: EAST PENN | C11: 65 | D11: =SLOPE(J11:M11,$A$4:$D$4) -> 1.9489051 | E11: =RSQ(J11:M11,$A$4:$D$4) -> 0.78108942 | F11: =ABS(D11-1) -> 0.94890515 | G11: =AVERAGE(J11:M11) -> 0.28864468 | H11: =IF(O11<=30,"YES","") | J11: ='Precinct Vote Data'!H18 -> 0.33532934 | K11: ='Precinct Vote Data'!H19 -> 0.24650572 | L11: ='Precinct Vote Data'!H20 -> 0.29549249 | M11: ='Precinct Vote Data'!H21 -> 0.27725118 | N11: =F11+(1-E11) -> 1.1678157 | O11: =RANK(N11,$N$7:$N$414,1) -> 222 | Q11: =A11&"|"&B11&"|"&C11 -> Carbon|EAST PENN|65
A12: Carbon | B12: EAST SIDE | C12: 70 | D12: =SLOPE(J12:M12,$A$4:$D$4) -> 2.5216573 | E12: =RSQ(J12:M12,$A$4:$D$4) -> 0.72888298 | F12: =ABS(D12-1) -> 1.5216573 | G12: =AVERAGE(J12:M12) -> 0.37715956 | H12: =IF(O12<=30,"YES","") | J12: ='Precinct Vote Data'!H22 -> 0.44155844 | K12: ='Precinct Vote Data'!H23 -> 0.38842975 | L12: ='Precinct Vote Data'!H24 -> 0.35106383 | M12: ='Precinct Vote Data'!H25 -> 0.32758621 | N12: =F12+(1-E12) -> 1.7927743 | O12: =RANK(N12,$N$7:$N$414,1) -> 325 | Q12: =A12&"|"&B12&"|"&C12 -> Carbon|EAST SIDE|70
A13: Carbon | B13: FRANKLIN | C13: 80 | D13: =SLOPE(J13:M13,$A$4:$D$4) -> 2.0682974 | E13: =RSQ(J13:M13,$A$4:$D$4) -> 0.99097232 | F13: =ABS(D13-1) -> 1.0682974 | G13: =AVERAGE(J13:M13) -> 0.292641 | H13: =IF(O13<=30,"YES","") | J13: ='Precinct Vote Data'!H26 -> 0.34196891 | K13: ='Precinct Vote Data'!H27 -> 0.2689769 | L13: ='Precinct Vote Data'!H28 -> 0.29295154 | M13: ='Precinct Vote Data'!H29 -> 0.26666667 | N13: =F13+(1-E13) -> 1.077325 | O13: =RANK(N13,$N$7:$N$414,1) -> 204 | Q13: =A13&"|"&B13&"|"&C13 -> Carbon|FRANKLIN|80
A14: Carbon | B14: FRANKLIN | C14: 90 | D14: =SLOPE(J14:M14,$A$4:$D$4) -> 1.7670326 | E14: =RSQ(J14:M14,$A$4:$D$4) -> 0.82043398 | F14: =ABS(D14-1) -> 0.76703261 | G14: =AVERAGE(J14:M14) -> 0.29734916 | H14: =IF(O14<=30,"YES","") | J14: ='Precinct Vote Data'!H30 -> 0.34122563 | K14: ='Precinct Vote Data'!H31 -> 0.26248776 | L14: ='Precinct Vote Data'!H32 -> 0.29797378 | M14: ='Precinct Vote Data'!H33 -> 0.2877095 | N14: =F14+(1-E14) -> 0.94659863 | O14: =RANK(N14,$N$7:$N$414,1) -> 181 | Q14: =A14&"|"&B14&"|"&C14 -> Carbon|FRANKLIN|90
A15: Carbon | B15: FRANKLIN | C15: 100 | D15: =SLOPE(J15:M15,$A$4:$D$4) -> 0.7729713 | E15: =RSQ(J15:M15,$A$4:$D$4) -> 0.44960595 | F15: =ABS(D15-1) -> 0.2270287 | G15: =AVERAGE(J15:M15) -> 0.26630748 | H15: =IF(O15<=30,"YES","") | J15: ='Precinct Vote Data'!H34 -> 0.28700361 | K15: ='Precinct Vote Data'!H35 -> 0.24038462 | L15: ='Precinct Vote Data'!H36 -> 0.26616541 | M15: ='Precinct Vote Data'!H37 -> 0.2716763 | N15: =F15+(1-E15) -> 0.77742274 | O15: =RANK(N15,$N$7:$N$414,1) -> 153 | Q15: =A15&"|"&B15&"|"&C15 -> Carbon|FRANKLIN|100
A16: Carbon | B16: JIM THORPE | C16: 110 | D16: =SLOPE(J16:M16,$A$4:$D$4) -> 3.1041996 | E16: =RSQ(J16:M16,$A$4:$D$4) -> 0.93389102 | F16: =ABS(D16-1) -> 2.1041996 | G16: =AVERAGE(J16:M16) -> 0.46600686 | H16: =IF(O16<=30,"YES","") | J16: ='Precinct Vote Data'!H38 -> 0.545 | K16: ='Precinct Vote Data'!H39 -> 0.42463235 | L16: ='Precinct Vote Data'!H40 -> 0.45454545 | M16: ='Precinct Vote Data'!H41 -> 0.43984962 | N16: =F16+(1-E16) -> 2.1703086 | O16: =RANK(N16,$N$7:$N$414,1) -> 373 | Q16: =A16&"|"&B16&"|"&C16 -> Carbon|JIM THORPE|110
A17: Carbon | B17: JIM THORPE | C17: 120 | D17: =SLOPE(J17:M17,$A$4:$D$4) -> 0.7192759 | E17: =RSQ(J17:M17,$A$4:$D$4) -> 0.12993473 | F17: =ABS(D17-1) -> 0.2807241 | G17: =AVERAGE(J17:M17) -> 0.42099009 | H17: =IF(O17<=30,"YES","") | J17: ='Precinct Vote Data'!H42 -> 0.4296875 | K17: ='Precinct Vote Data'!H43 -> 0.37692308 | L17: ='Precinct Vote Data'!H44 -> 0.45791246 | M17: ='Precinct Vote Data'!H45 -> 0.41943734 | N17: =F17+(1-E17) -> 1.1507894 | O17: =RANK(N17,$N$7:$N$414,1) -> 220 | Q17: =A17&"|"&B17&"|"&C17 -> Carbon|JIM THORPE|120
A18: Carbon | B18: JIM THORPE | C18: 130 | D18: =SLOPE(J18:M18,$A$4:$D$4) -> 2.2150066 | E18: =RSQ(J18:M18,$A$4:$D$4) -> 0.93819159 | F18: =ABS(D18-1) -> 1.2150066 | G18: =AVERAGE(J18:M18) -> 0.40338453 | H18: =IF(O18<=30,"YES","") | J18: ='Precinct Vote Data'!H46 -> 0.46071429 | K18: ='Precinct Vote Data'!H47 -> 0.37964237 | L18: ='Precinct Vote Data'!H48 -> 0.3904 | M18: ='Precinct Vote Data'!H49 -> 0.38278146 | N18: =F18+(1-E18) -> 1.276815 | O18: =RANK(N18,$N$7:$N$414,1) -> 245 | Q18: =A18&"|"&B18&"|"&C18 -> Carbon|JIM THORPE|130
A19: Carbon | B19: JIM THORPE | C19: 140 | D19: =SLOPE(J19:M19,$A$4:$D$4) -> 1.9519208 | E19: =RSQ(J19:M19,$A$4:$D$4) -> 0.83580685 | F19: =ABS(D19-1) -> 0.95192077 | G19: =AVERAGE(J19:M19) -> 0.54653352 | H19: =IF(O19<=30,"YES","") | J19: ='Precinct Vote Data'!H50 -> 0.58590308 | K19: ='Precinct Vote Data'!H51 -> 0.52666667 | L19: ='Precinct Vote Data'!H52 -> 0.56626506 | M19: ='Precinct Vote Data'!H53 -> 0.50729927 | N19: =F19+(1-E19) -> 1.1161139 | O19: =RANK(N19,$N$7:$N$414,1) -> 212 | Q19: =A19&"|"&B19&"|"&C19 -> Carbon|JIM THORPE|140
A20: Carbon | B20: JIM THORPE | C20: 150 | D20: =SLOPE(J20:M20,$A$4:$D$4) -> 0.98972831 | E20: =RSQ(J20:M20,$A$4:$D$4) -> 0.19763676 | F20: =ABS(D20-1) -> 0.010271687 | G20: =AVERAGE(J20:M20) -> 0.44873174 | H20: =IF(O20<=30,"YES","") | J20: ='Precinct Vote Data'!H54 -> 0.46172249 | K20: ='Precinct Vote Data'!H55 -> 0.4025974 | L20: ='Precinct Vote Data'!H56 -> 0.49142857 | M20: ='Precinct Vote Data'!H57 -> 0.43917851 | N20: =F20+(1-E20) -> 0.81263493 | O20: =RANK(N20,$N$7:$N$414,1) -> 158 | Q20: =A20&"|"&B20&"|"&C20 -> Carbon|JIM THORPE|150
A21: Carbon | B21: KIDDER | C21: 160 | D21: =SLOPE(J21:M21,$A$4:$D$4) -> 0.93113236 | E21: =RSQ(J21:M21,$A$4:$D$4) -> 0.31215256 | F21: =ABS(D21-1) -> 0.068867644 | G21: =AVERAGE(J21:M21) -> 0.35838641 | H21: =IF(O21<=30,"YES","") | J21: ='Precinct Vote Data'!H58 -> 0.38497653 | K21: ='Precinct Vote Data'!H59 -> 0.32026144 | L21: ='Precinct Vote Data'!H60 -> 0.356 | M21: ='Precinct Vote Data'!H61 -> 0.37230769 | N21: =F21+(1-E21) -> 0.75671509 | O21: =RANK(N21,$N$7:$N$414,1) -> 149 | Q21: =A21&"|"&B21&"|"&C21 -> Carbon|KIDDER|160
A22: Carbon | B22: KIDDER | C22: 170 | D22: =SLOPE(J22:M22,$A$4:$D$4) -> 0.7441175 | E22: =RSQ(J22:M22,$A$4:$D$4) -> 0.61888586 | F22: =ABS(D22-1) -> 0.2558825 | G22: =AVERAGE(J22:M22) -> 0.31837026 | H22: =IF(O22<=30,"YES","") | J22: ='Precinct Vote Data'!H62 -> 0.33697632 | K22: ='Precinct Vote Data'!H63 -> 0.29811321 | L22: ='Precinct Vote Data'!H64 -> 0.32027257 | M22: ='Precinct Vote Data'!H65 -> 0.31811895 | N22: =F22+(1-E22) -> 0.63699665 | O22: =RANK(N22,$N$7:$N$414,1) -> 112 | Q22: =A22&"|"&B22&"|"&C22 -> Carbon|KIDDER|170
A23: Carbon | B23: LANSFORD | C23: 180 | D23: =SLOPE(J23:M23,$A$4:$D$4) -> 2.6886966 | E23: =RSQ(J23:M23,$A$4:$D$4) -> 0.80500609 | F23: =ABS(D23-1) -> 1.6886966 | G23: =AVERAGE(J23:M23) -> 0.42556737 | H23: =IF(O23<=30,"YES","") | J23: ='Precinct Vote Data'!H66 -> 0.49761905 | K23: ='Precinct Vote Data'!H67 -> 0.42307692 | L23: ='Precinct Vote Data'!H68 -> 0.39337474 | M23: ='Precinct Vote Data'!H69 -> 0.38819876 | N23: =F23+(1-E23) -> 1.8836905 | O23: =RANK(N23,$N$7:$N$414,1) -> 335 | Q23: =A23&"|"&B23&"|"&C23 -> Carbon|LANSFORD|180
A24: Carbon | B24: LANSFORD | C24: 190 | D24: =SLOPE(J24:M24,$A$4:$D$4) -> 2.0736805 | E24: =RSQ(J24:M24,$A$4:$D$4) -> 0.98920698 | F24: =ABS(D24-1) -> 1.0736805 | G24: =AVERAGE(J24:M24) -> 0.4247605 | H24: =IF(O24<=30,"YES","") | J24: ='Precinct Vote Data'!H70 -> 0.47311828 | K24: ='Precinct Vote Data'!H71 -> 0.40963855 | L24: ='Precinct Vote Data'!H72 -> 0.42508711 | M24: ='Precinct Vote Data'!H73 -> 0.39119804 | N24: =F24+(1-E24) -> 1.0844735 | O24: =RANK(N24,$N$7:$N$414,1) -> 205 | Q24: =A24&"|"&B24&"|"&C24 -> Carbon|LANSFORD|190
