Workbook

Sheet Contents
A1: PA-07 Forecast Workbook v3 — Complete, Corrected Data
A2: Companion file: PA07_Data.xlsx holds House Vote Data and Registration & ACS Data on their own for easy review. This workbook keeps its own copies of those same sheets so every formula here works standalone.
A4: Sheet | B4: What it does | C4: What it tells us
A5: House Vote Data | B5: Real certified House + Governor votes for all 89 municipalities, 2018-2024, plus a Presidential Year dummy. | C5: The complete, verified core of the dataset -- no more estimation layer.
A6: Registration & ACS Data | B6: Registration lean and % bachelor's degree per municipality-year, plus registrants (used as population weight). | C6: Supporting data for the regression and representative-sample analyses.
A7: District History Note | B7: Documents the real boundary changes (Carbon pre-2022, Monroe post-2022) and the corrected 2020 result. | C7: Read this first -- it explains why this version's numbers differ from an earlier version.
A8: Predictability Ranking | B8: Classifies all 89 municipalities Easy/Medium/Hard to predict. | C8: Where more data/effort would change the forecast, across the full real district.
A9: Magic Municipality | B9: Bellwether search across all 89 municipalities. | C9: Salisbury (Lehigh) is the new closest-tracking bellwether.
A10: Beta Coefficients | B10: Each municipality's beta and R-squared against the self-computed, complete district index. | C10: Identifies the 30 towns that behave most like a scaled-down mirror of the district.
A11: Governor-House Correlation | B11: Correlates Governor vs. House Dem Share, 2018 and 2022, across all 89 municipalities. | C11: r = 0.99 -- consistent with earlier findings.
A12: 2024 Backtest | B12: Naive, trend, and beta-adjusted methods tested against real 2024 results. | C12: Beta-adjusted now wins (1.81 pt MAE); naive is worst.
A13: Regression Analysis | B13: Documents the multi-variable regression and explains why it now performs worst of the three forecasting methods. | C13: A genuinely useful negative result -- more complexity isn't automatically better.
A14: Kiley - 2026 Trend Forecast / Beta-Adjusted Forecast / Regression Forecast | B14: Three independent live 2026 forecasts. | C14: 47.7% Dem (R), 46.8% Dem (R), and 50.6% Dem (D) respectively -- two of three lean Republican.
A15: Model Comparison | B15: All three 2026 forecasts side by side with backtested accuracy. | C15: The real takeaway: this is a Republican-leaning toss-up, not a confident call either way.
... A17: Methodology | B17: Documents every method, data source, and correction made in this version. | C17: Start here if you want the full picture before diving into any one sheet.

Sheet House Vote Data
A1: Year | B1: Municipality | C1: County | D1: Dem Votes | E1: Rep Votes | F1: Total Votes | G1: Dem Share % | H1: Governor Dem Votes | I1: Governor Rep Votes | J1: Governor Total | K1: Governor Dem Share | L1: Presidential Year (dummy)
A2: 2018 | B2: Banks Township | C2: Carbon | D2: 160 | E2: 221 | F2: =D2+E2 -> 381 | G2: =D2/F2 -> 0.41994751 | H2: 174 | I2: 208 | J2: =IF(OR(H2="",H2=0),"",H2+I2) -> 382 | K2: =IF(J2="","",H2/J2) -> 0.45549738 | L2: =IF(OR(A2=2020,A2=2024),1,0) -> 0
A3: 2020 | B3: Banks Township | C3: Carbon | D3: 171 | E3: 332 | F3: =D3+E3 -> 503 | G3: =D3/F3 -> 0.33996024 | J3: =IF(OR(H3="",H3=0),"",H3+I3) | K3: =IF(J3="","",H3/J3) | L3: =IF(OR(A3=2020,A3=2024),1,0) -> 1
A4: 2022 | B4: Banks Township | C4: Carbon | D4: 137 | E4: 249 | F4: =D4+E4 -> 386 | G4: =D4/F4 -> 0.35492228 | H4: 151 | I4: 227 | J4: =IF(OR(H4="",H4=0),"",H4+I4) -> 378 | K4: =IF(J4="","",H4/J4) -> 0.3994709 | L4: =IF(OR(A4=2020,A4=2024),1,0) -> 0
A5: 2024 | B5: Banks Township | C5: Carbon | D5: 181 | E5: 285 | F5: =D5+E5 -> 466 | G5: =D5/F5 -> 0.38841202 | J5: =IF(OR(H5="",H5=0),"",H5+I5) | K5: =IF(J5="","",H5/J5) | L5: =IF(OR(A5=2020,A5=2024),1,0) -> 1
A6: 2018 | B6: Beaver Meadows Borough | C6: Carbon | D6: 95 | E6: 192 | F6: =D6+E6 -> 287 | G6: =D6/F6 -> 0.33101045 | H6: 112 | I6: 168 | J6: =IF(OR(H6="",H6=0),"",H6+I6) -> 280 | K6: =IF(J6="","",H6/J6) -> 0.4 | L6: =IF(OR(A6=2020,A6=2024),1,0) -> 0
A7: 2020 | B7: Beaver Meadows Borough | C7: Carbon | D7: 100 | E7: 303 | F7: =D7+E7 -> 403 | G7: =D7/F7 -> 0.24813896 | J7: =IF(OR(H7="",H7=0),"",H7+I7) | K7: =IF(J7="","",H7/J7) | L7: =IF(OR(A7=2020,A7=2024),1,0) -> 1
A8: 2022 | B8: Beaver Meadows Borough | C8: Carbon | D8: 84 | E8: 230 | F8: =D8+E8 -> 314 | G8: =D8/F8 -> 0.26751592 | H8: 108 | I8: 196 | J8: =IF(OR(H8="",H8=0),"",H8+I8) -> 304 | K8: =IF(J8="","",H8/J8) -> 0.35526316 | L8: =IF(OR(A8=2020,A8=2024),1,0) -> 0
A9: 2024 | B9: Beaver Meadows Borough | C9: Carbon | D9: 118 | E9: 300 | F9: =D9+E9 -> 418 | G9: =D9/F9 -> 0.28229665 | J9: =IF(OR(H9="",H9=0),"",H9+I9) | K9: =IF(J9="","",H9/J9) | L9: =IF(OR(A9=2020,A9=2024),1,0) -> 1
A10: 2018 | B10: Bowmanstown Borough | C10: Carbon | D10: 110 | E10: 175 | F10: =D10+E10 -> 285 | G10: =D10/F10 -> 0.38596491 | H10: 121 | I10: 160 | J10: =IF(OR(H10="",H10=0),"",H10+I10) -> 281 | K10: =IF(J10="","",H10/J10) -> 0.43060498 | L10: =IF(OR(A10=2020,A10=2024),1,0) -> 0
A11: 2020 | B11: Bowmanstown Borough | C11: Carbon | D11: 111 | E11: 317 | F11: =D11+E11 -> 428 | G11: =D11/F11 -> 0.25934579 | J11: =IF(OR(H11="",H11=0),"",H11+I11) | K11: =IF(J11="","",H11/J11) | L11: =IF(OR(A11=2020,A11=2024),1,0) -> 1
A12: 2022 | B12: Bowmanstown Borough | C12: Carbon | D12: 125 | E12: 223 | F12: =D12+E12 -> 348 | G12: =D12/F12 -> 0.3591954 | H12: 145 | I12: 199 | J12: =IF(OR(H12="",H12=0),"",H12+I12) -> 344 | K12: =IF(J12="","",H12/J12) -> 0.42151163 | L12: =IF(OR(A12=2020,A12=2024),1,0) -> 0
A13: 2024 | B13: Bowmanstown Borough | C13: Carbon | D13: 144 | E13: 310 | F13: =D13+E13 -> 454 | G13: =D13/F13 -> 0.31718062 | J13: =IF(OR(H13="",H13=0),"",H13+I13) | K13: =IF(J13="","",H13/J13) | L13: =IF(OR(A13=2020,A13=2024),1,0) -> 1
A14: 2018 | B14: East Penn Township | C14: Carbon | D14: 369 | E14: 742 | F14: =D14+E14 -> 1111 | G14: =D14/F14 -> 0.33213321 | H14: 443 | I14: 665 | J14: =IF(OR(H14="",H14=0),"",H14+I14) -> 1108 | K14: =IF(J14="","",H14/J14) -> 0.39981949 | L14: =IF(OR(A14=2020,A14=2024),1,0) -> 0
A15: 2020 | B15: East Penn Township | C15: Carbon | D15: 390 | E15: 1180 | F15: =D15+E15 -> 1570 | G15: =D15/F15 -> 0.24840764 | J15: =IF(OR(H15="",H15=0),"",H15+I15) | K15: =IF(J15="","",H15/J15) | L15: =IF(OR(A15=2020,A15=2024),1,0) -> 1
A16: 2022 | B16: East Penn Township | C16: Carbon | D16: 372 | E16: 925 | F16: =D16+E16 -> 1297 | G16: =D16/F16 -> 0.28681573 | H16: 449 | I16: 830 | J16: =IF(OR(H16="",H16=0),"",H16+I16) -> 1279 | K16: =IF(J16="","",H16/J16) -> 0.35105551 | L16: =IF(OR(A16=2020,A16=2024),1,0) -> 0
A17: 2024 | B17: East Penn Township | C17: Carbon | D17: 438 | E17: 1253 | F17: =D17+E17 -> 1691 | G17: =D17/F17 -> 0.25901833 | J17: =IF(OR(H17="",H17=0),"",H17+I17) | K17: =IF(J17="","",H17/J17) | L17: =IF(OR(A17=2020,A17=2024),1,0) -> 1
A18: 2018 | B18: East Side Borough | C18: Carbon | D18: 34 | E18: 43 | F18: =D18+E18 -> 77 | G18: =D18/F18 -> 0.44155844 | H18: 36 | I18: 40 | J18: =IF(OR(H18="",H18=0),"",H18+I18) -> 76 | K18: =IF(J18="","",H18/J18) -> 0.47368421 | L18: =IF(OR(A18=2020,A18=2024),1,0) -> 0
A19: 2020 | B19: East Side Borough | C19: Carbon | D19: 47 | E19: 74 | F19: =D19+E19 -> 121 | G19: =D19/F19 -> 0.38842975 | J19: =IF(OR(H19="",H19=0),"",H19+I19) | K19: =IF(J19="","",H19/J19) | L19: =IF(OR(A19=2020,A19=2024),1,0) -> 1
A20: 2022 | B20: East Side Borough | C20: Carbon | D20: 33 | E20: 61 | F20: =D20+E20 -> 94 | G20: =D20/F20 -> 0.35106383 | H20: 38 | I20: 52 | J20: =IF(OR(H20="",H20=0),"",H20+I20) -> 90 | K20: =IF(J20="","",H20/J20) -> 0.42222222 | L20: =IF(OR(A20=2020,A20=2024),1,0) -> 0
A21: 2024 | B21: East Side Borough | C21: Carbon | D21: 38 | E21: 78 | F21: =D21+E21 -> 116 | G21: =D21/F21 -> 0.32758621 | J21: =IF(OR(H21="",H21=0),"",H21+I21) | K21: =IF(J21="","",H21/J21) | L21: =IF(OR(A21=2020,A21=2024),1,0) -> 1
A22: 2018 | B22: Franklin Township | C22: Carbon | D22: 536 | E22: 1122 | F22: =D22+E22 -> 1658 | G22: =D22/F22 -> 0.32328106 | H22: 581 | I22: 1055 | J22: =IF(OR(H22="",H22=0),"",H22+I22) -> 1636 | K22: =IF(J22="","",H22/J22) -> 0.35513447 | L22: =IF(OR(A22=2020,A22=2024),1,0) -> 0
A23: 2020 | B23: Franklin Township | C23: Carbon | D23: 631 | E23: 1828 | F23: =D23+E23 -> 2459 | G23: =D23/F23 -> 0.25660838 | J23: =IF(OR(H23="",H23=0),"",H23+I23) | K23: =IF(J23="","",H23/J23) | L23: =IF(OR(A23=2020,A23=2024),1,0) -> 1
A24: 2022 | B24: Franklin Township | C24: Carbon | D24: 560 | E24: 1398 | F24: =D24+E24 -> 1958 | G24: =D24/F24 -> 0.28600613 | H24: 680 | I24: 1232 | J24: =IF(OR(H24="",H24=0),"",H24+I24) -> 1912 | K24: =IF(J24="","",H24/J24) -> 0.35564854 | L24: =IF(OR(A24=2020,A24=2024),1,0) -> 0
A25: 2024 | B25: Franklin Township | C25: Carbon | D25: 708 | E25: 1846 | F25: =D25+E25 -> 2554 | G25: =D25/F25 -> 0.27721222 | J25: =IF(OR(H25="",H25=0),"",H25+I25) | K25: =IF(J25="","",H25/J25) | L25: =IF(OR(A25=2020,A25=2024),1,0) -> 1
A26: 2018 | B26: Jim Thorpe Borough | C26: Carbon | D26: 912 | E26: 949 | F26: =D26+E26 -> 1861 | G26: =D26/F26 -> 0.49005911 | H26: 971 | I26: 862 | J26: =IF(OR(H26="",H26=0),"",H26+I26) -> 1833 | K26: =IF(J26="","",H26/J26) -> 0.52973268 | L26: =IF(OR(A26=2020,A26=2024),1,0) -> 0
A27: 2020 | B27: Jim Thorpe Borough | C27: Carbon | D27: 1060 | E27: 1517 | F27: =D27+E27 -> 2577 | G27: =D27/F27 -> 0.41133101 | J27: =IF(OR(H27="",H27=0),"",H27+I27) | K27: =IF(J27="","",H27/J27) | L27: =IF(OR(A27=2020,A27=2024),1,0) -> 1
A28: 2022 | B28: Jim Thorpe Borough | C28: Carbon | D28: 979 | E28: 1157 | F28: =D28+E28 -> 2136 | G28: =D28/F28 -> 0.45833333 | H28: 1107 | I28: 992 | J28: =IF(OR(H28="",H28=0),"",H28+I28) -> 2099 | K28: =IF(J28="","",H28/J28) -> 0.527394 | L28: =IF(OR(A28=2020,A28=2024),1,0) -> 0
A29: 2024 | B29: Jim Thorpe Borough | C29: Carbon | D29: 1104 | E29: 1481 | F29: =D29+E29 -> 2585 | G29: =D29/F29 -> 0.4270793 | J29: =IF(OR(H29="",H29=0),"",H29+I29) | K29: =IF(J29="","",H29/J29) | L29: =IF(OR(A29=2020,A29=2024),1,0) -> 1
A30: 2018 | B30: Kidder Township | C30: Carbon | D30: 267 | E30: 495 | F30: =D30+E30 -> 762 | G30: =D30/F30 -> 0.3503937 | H30: 303 | I30: 453 | J30: =IF(OR(H30="",H30=0),"",H30+I30) -> 756 | K30: =IF(J30="","",H30/J30) -> 0.40079365 | L30: =IF(OR(A30=2020,A30=2024),1,0) -> 0
A31: 2020 | B31: Kidder Township | C31: Carbon | D31: 335 | E31: 766 | F31: =D31+E31 -> 1101 | G31: =D31/F31 -> 0.30426885 | J31: =IF(OR(H31="",H31=0),"",H31+I31) | K31: =IF(J31="","",H31/J31) | L31: =IF(OR(A31=2020,A31=2024),1,0) -> 1
A32: 2022 | B32: Kidder Township | C32: Carbon | D32: 277 | E32: 560 | F32: =D32+E32 -> 837 | G32: =D32/F32 -> 0.33094385 | H32: 347 | I32: 482 | J32: =IF(OR(H32="",H32=0),"",H32+I32) -> 829 | K32: =IF(J32="","",H32/J32) -> 0.4185766 | L32: =IF(OR(A32=2020,A32=2024),1,0) -> 0
A33: 2024 | B33: Kidder Township | C33: Carbon | D33: 351 | E33: 697 | F33: =D33+E33 -> 1048 | G33: =D33/F33 -> 0.33492366 | J33: =IF(OR(H33="",H33=0),"",H33+I33) | K33: =IF(J33="","",H33/J33) | L33: =IF(OR(A33=2020,A33=2024),1,0) -> 1
A34: 2018 | B34: Lansford Borough | C34: Carbon | D34: 455 | E34: 467 | F34: =D34+E34 -> 922 | G34: =D34/F34 -> 0.49349241 | H34: 482 | I34: 429 | J34: =IF(OR(H34="",H34=0),"",H34+I34) -> 911 | K34: =IF(J34="","",H34/J34) -> 0.52908891 | L34: =IF(OR(A34=2020,A34=2024),1,0) -> 0
A35: 2020 | B35: Lansford Borough | C35: Carbon | D35: 614 | E35: 846 | F35: =D35+E35 -> 1460 | G35: =D35/F35 -> 0.42054795 | J35: =IF(OR(H35="",H35=0),"",H35+I35) | K35: =IF(J35="","",H35/J35) | L35: =IF(OR(A35=2020,A35=2024),1,0) -> 1
A36: 2022 | B36: Lansford Borough | C36: Carbon | D36: 420 | E36: 580 | F36: =D36+E36 -> 1000 | G36: =D36/F36 -> 0.42 | H36: 493 | I36: 506 | J36: =IF(OR(H36="",H36=0),"",H36+I36) -> 999 | K36: =IF(J36="","",H36/J36) -> 0.49349349 | L36: =IF(OR(A36=2020,A36=2024),1,0) -> 0
A37: 2024 | B37: Lansford Borough | C37: Carbon | D37: 575 | E37: 880 | F37: =D37+E37 -> 1455 | G37: =D37/F37 -> 0.395189 | J37: =IF(OR(H37="",H37=0),"",H37+I37) | K37: =IF(J37="","",H37/J37) | L37: =IF(OR(A37=2020,A37=2024),1,0) -> 1
A38: 2018 | B38: Lausanne Township | C38: Carbon | D38: 29 | E38: 59 | F38: =D38+E38 -> 88 | G38: =D38/F38 -> 0.32954545 | H38: 33 | I38: 58 | J38: =IF(OR(H38="",H38=0),"",H38+I38) -> 91 | K38: =IF(J38="","",H38/J38) -> 0.36263736 | L38: =IF(OR(A38=2020,A38=2024),1,0) -> 0
A39: 2020 | B39: Lausanne Township | C39: Carbon | D39: 42 | E39: 99 | F39: =D39+E39 -> 141 | G39: =D39/F39 -> 0.29787234 | J39: =IF(OR(H39="",H39=0),"",H39+I39) | K39: =IF(J39="","",H39/J39) | L39: =IF(OR(A39=2020,A39=2024),1,0) -> 1
A40: 2022 | B40: Lausanne Township | C40: Carbon | D40: 36 | E40: 79 | F40: =D40+E40 -> 115 | G40: =D40/F40 -> 0.31304348 | H40: 45 | I40: 70 | J40: =IF(OR(H40="",H40=0),"",H40+I40) -> 115 | K40: =IF(J40="","",H40/J40) -> 0.39130435 | L40: =IF(OR(A40=2020,A40=2024),1,0) -> 0
...

Sheet Registration & ACS Data
A1: Year | B1: Municipality | C1: County | D1: Reg D-minus-R | E1: % Bachelor's Degree (ACS) | F1: Registrants
A2: 2018 | B2: Banks Township | C2: Carbon | D2: 0.2701 | E2: 0.07 | F2: 733
A3: 2020 | B3: Banks Township | C3: Carbon | D3: 0.1914 | E3: 0.08 | F3: 747
A4: 2022 | B4: Banks Township | C4: Carbon | D4: 0.1235 | E4: 0.08 | F4: 664
A5: 2024 | B5: Banks Township | C5: Carbon | D5: 0.0554 | E5: 0.08 | F5: 650
A6: 2018 | B6: Beaver Meadows Borough | C6: Carbon | D6: 0.0963 | E6: 0.11 | F6: 602
A7: 2020 | B7: Beaver Meadows Borough | C7: Carbon | D7: -0.0357 | E7: 0.12 | F7: 616
A8: 2022 | B8: Beaver Meadows Borough | C8: Carbon | D8: -0.1336 | E8: 0.14 | F8: 584
A9: 2024 | B9: Beaver Meadows Borough | C9: Carbon | D9: -0.2282 | E9: 0.11 | F9: 618
A10: 2018 | B10: Bowmanstown Borough | C10: Carbon | D10: -0.0055 | E10: 0.11 | F10: 542
A11: 2020 | B11: Bowmanstown Borough | C11: Carbon | D11: -0.1522 | E11: 0.25 | F11: 598
A12: 2022 | B12: Bowmanstown Borough | C12: Carbon | D12: -0.1956 | E12: 0.25 | F12: 547
A13: 2024 | B13: Bowmanstown Borough | C13: Carbon | D13: -0.1989 | E13: 0.25 | F13: 563
... A201: 2024 | B201: Polk Township | C201: Monroe | D201: -0.2038 | E201: 0.19 | F201: 5678
A202: 2018 | B202: Ross Township | C202: Monroe | D202: 0 | E202: 0.15
A203: 2020 | B203: Ross Township | C203: Monroe | D203: 0 | E203: 0.26
A204: 2022 | B204: Ross Township | C204: Monroe | D204: -0.1891 | E204: 0.31 | F204: 1777
A205: 2024 | B205: Ross Township | C205: Monroe | D205: -0.239 | E205: 0.31 | F205: 1916
A206: 2018 | B206: Allen | C206: Northampton | D206: -0.0243 | E206: 0.35 | F206: 3711
A207: 2020 | B207: Allen | C207: Northampton | D207: -0.0328 | E207: 0.4 | F207: 4114
A208: 2022 | B208: Allen | C208: Northampton | D208: -0.0478 | E208: 0.36 | F208: 4139
A209: 2024 | B209: Allen | C209: Northampton | D209: -0.0833 | E209: 0.31 | F209: 4300
A210: 2018 | B210: Bangor | C210: Northampton | D210: 0.0243 | E210: 0.15 | F210: 3171
A211: 2020 | B211: Bangor | C211: Northampton | D211: -0.0213 | E211: 0.16 | F211: 3382
A212: 2022 | B212: Bangor | C212: Northampton | D212: -0.0543 | E212: 0.18 | F212: 3370
A213: 2024 | B213: Bangor | C213: Northampton | D213: -0.1008 | E213: 0.23 | F213: 3424
A214: 2018 | B214: Bath | C214: Northampton | D214: 0.0444 | E214: 0.18 | F214: 1599
A215: 2020 | B215: Bath | C215: Northampton | D215: 0.0107 | E215: 0.19 | F215: 1770
... A357: 2024 | B357: Wind Gap | C357: Northampton | D357: -0.0779 | E357: 0.25 | F357: 2131

Sheet District History Note
A1: What Changed: PA-07's Real Boundaries and Corrected History
A3: Full geography, real votes | B3: This workbook is built on Municipal_Data.xlsx's 'Master Data' tab, which has certified House votes for all 89 municipalities across Carbon, Lehigh, Northampton, and Monroe (3 townships: Eldred, Polk, Ross). The earlier version of this workbook had to ESTIMATE Carbon from registration data and had NO Monroe data at all -- that entire workaround is no longer needed.
A4: Carbon and Monroe's real district history | B4: The source data documents that PA-07's boundaries actually changed over time: Carbon wasn't part of PA-07 before 2022, and most of Monroe County left the district after 2022, leaving just the 3 townships tracked here. This workbook uses each town's own vote history as the best available signal for how it behaves in the CURRENT district, consistent with how earlier versions handled similarly-situated historical data.
A5: 2020 result corrected | B5: Earlier versions of this analysis (built on a different reference source) showed the Democrat winning the 2020 House race district-wide. The certified returns in this file show the OPPOSITE: the Republican won 2020 by about 2,600 votes (196,320 to 193,719). This changes the district's real historical pattern to Democrat-Republican-Democrat-Republican across 2018-2024, alternating every cycle -- not a steady Democratic-leaning trend as earlier analysis suggested.
A6: Ross Township's split | B6: Ross Township, Monroe County, is split across two congressional districts. Registration figures use the 'USC 7' (US Congressional District 7) portion specifically, verified against Master Data's certified vote totals for Ross to confirm the correct split was used.

Sheet Predictability Ranking
A1: Municipality | B1: County | C1: Avg Dem Share | D1: Avg Margin from 50pt | E1: Stdev Dem Share | F1: Party Flips | G1: Predictability
A2: Banks Township | B2: Carbon | C2: =AVERAGE('House Vote Data'!G2:G5) -> 0.37581051 | D2: =AVERAGE(ABS('House Vote Data'!G2-0.5),ABS('House Vote Data'!G3-0.5),ABS('House Vote Data'!G4-0.5),ABS('House Vote Data'!G5-0.5)) -> 0.12418949 | E2: =STDEV('House Vote Data'!G2:G5) -> 0.03572316 | F2: =IF(('House Vote Data'!G2>0.5)<>('House Vote Data'!G3>0.5),1,0)+IF(('House Vote Data'!G3>0.5)<>('House Vote Data'!G4>0.5),1,0)+IF(('House Vote Data'!G4>0.5)<>('House Vote Data'!G5>0.5),1,0) -> 0 | G2: =IF(OR(F2>=1,D2<0.05),"Hard",IF(AND(D2>=0.15,E2<0.05),"Easy","Medium")) -> Medium
A3: Beaver Meadows Borough | B3: Carbon | C3: =AVERAGE('House Vote Data'!G6:G9) -> 0.2822405 | D3: =AVERAGE(ABS('House Vote Data'!G6-0.5),ABS('House Vote Data'!G7-0.5),ABS('House Vote Data'!G8-0.5),ABS('House Vote Data'!G9-0.5)) -> 0.2177595 | E3: =STDEV('House Vote Data'!G6:G9) -> 0.035394161 | F3: =IF(('House Vote Data'!G6>0.5)<>('House Vote Data'!G7>0.5),1,0)+IF(('House Vote Data'!G7>0.5)<>('House Vote Data'!G8>0.5),1,0)+IF(('House Vote Data'!G8>0.5)<>('House Vote Data'!G9>0.5),1,0) -> 0 | G3: =IF(OR(F3>=1,D3<0.05),"Hard",IF(AND(D3>=0.15,E3<0.05),"Easy","Medium")) -> Easy
A4: Bowmanstown Borough | B4: Carbon | C4: =AVERAGE('House Vote Data'!G10:G13) -> 0.33042168 | D4: =AVERAGE(ABS('House Vote Data'!G10-0.5),ABS('House Vote Data'!G11-0.5),ABS('House Vote Data'!G12-0.5),ABS('House Vote Data'!G13-0.5)) -> 0.16957832 | E4: =STDEV('House Vote Data'!G10:G13) -> 0.055196875 | F4: =IF(('House Vote Data'!G10>0.5)<>('House Vote Data'!G11>0.5),1,0)+IF(('House Vote Data'!G11>0.5)<>('House Vote Data'!G12>0.5),1,0)+IF(('House Vote Data'!G12>0.5)<>('House Vote Data'!G13>0.5),1,0) -> 0 | G4: =IF(OR(F4>=1,D4<0.05),"Hard",IF(AND(D4>=0.15,E4<0.05),"Easy","Medium")) -> Medium
A5: East Penn Township | B5: Carbon | C5: =AVERAGE('House Vote Data'!G14:G17) -> 0.28159373 | D5: =AVERAGE(ABS('House Vote Data'!G14-0.5),ABS('House Vote Data'!G15-0.5),ABS('House Vote Data'!G16-0.5),ABS('House Vote Data'!G17-0.5)) -> 0.21840627 | E5: =STDEV('House Vote Data'!G14:G17) -> 0.037383033 | F5: =IF(('House Vote Data'!G14>0.5)<>('House Vote Data'!G15>0.5),1,0)+IF(('House Vote Data'!G15>0.5)<>('House Vote Data'!G16>0.5),1,0)+IF(('House Vote Data'!G16>0.5)<>('House Vote Data'!G17>0.5),1,0) -> 0 | G5: =IF(OR(F5>=1,D5<0.05),"Hard",IF(AND(D5>=0.15,E5<0.05),"Easy","Medium")) -> Easy
A6: East Side Borough | B6: Carbon | C6: =AVERAGE('House Vote Data'!G18:G21) -> 0.37715956 | D6: =AVERAGE(ABS('House Vote Data'!G18-0.5),ABS('House Vote Data'!G19-0.5),ABS('House Vote Data'!G20-0.5),ABS('House Vote Data'!G21-0.5)) -> 0.12284044 | E6: =STDEV('House Vote Data'!G18:G21) -> 0.049708274 | F6: =IF(('House Vote Data'!G18>0.5)<>('House Vote Data'!G19>0.5),1,0)+IF(('House Vote Data'!G19>0.5)<>('House Vote Data'!G20>0.5),1,0)+IF(('House Vote Data'!G20>0.5)<>('House Vote Data'!G21>0.5),1,0) -> 0 | G6: =IF(OR(F6>=1,D6<0.05),"Hard",IF(AND(D6>=0.15,E6<0.05),"Easy","Medium")) -> Medium
A7: Franklin Township | B7: Carbon | C7: =AVERAGE('House Vote Data'!G22:G25) -> 0.28577695 | D7: =AVERAGE(ABS('House Vote Data'!G22-0.5),ABS('House Vote Data'!G23-0.5),ABS('House Vote Data'!G24-0.5),ABS('House Vote Data'!G25-0.5)) -> 0.21422305 | E7: =STDEV('House Vote Data'!G22:G25) -> 0.027873352 | F7: =IF(('House Vote Data'!G22>0.5)<>('House Vote Data'!G23>0.5),1,0)+IF(('House Vote Data'!G23>0.5)<>('House Vote Data'!G24>0.5),1,0)+IF(('House Vote Data'!G24>0.5)<>('House Vote Data'!G25>0.5),1,0) -> 0 | G7: =IF(OR(F7>=1,D7<0.05),"Hard",IF(AND(D7>=0.15,E7<0.05),"Easy","Medium")) -> Easy
A8: Jim Thorpe Borough | B8: Carbon | C8: =AVERAGE('House Vote Data'!G26:G29) -> 0.44670069 | D8: =AVERAGE(ABS('House Vote Data'!G26-0.5),ABS('House Vote Data'!G27-0.5),ABS('House Vote Data'!G28-0.5),ABS('House Vote Data'!G29-0.5)) -> 0.053299312 | E8: =STDEV('House Vote Data'!G26:G29) -> 0.034886885 | F8: =IF(('House Vote Data'!G26>0.5)<>('House Vote Data'!G27>0.5),1,0)+IF(('House Vote Data'!G27>0.5)<>('House Vote Data'!G28>0.5),1,0)+IF(('House Vote Data'!G28>0.5)<>('House Vote Data'!G29>0.5),1,0) -> 0 | G8: =IF(OR(F8>=1,D8<0.05),"Hard",IF(AND(D8>=0.15,E8<0.05),"Easy","Medium")) -> Medium
A9: Kidder Township | B9: Carbon | C9: =AVERAGE('House Vote Data'!G30:G33) -> 0.33013251 | D9: =AVERAGE(ABS('House Vote Data'!G30-0.5),ABS('House Vote Data'!G31-0.5),ABS('House Vote Data'!G32-0.5),ABS('House Vote Data'!G33-0.5)) -> 0.16986749 | E9: =STDEV('House Vote Data'!G30:G33) -> 0.019175143 | F9: =IF(('House Vote Data'!G30>0.5)<>('House Vote Data'!G31>0.5),1,0)+IF(('House Vote Data'!G31>0.5)<>('House Vote Data'!G32>0.5),1,0)+IF(('House Vote Data'!G32>0.5)<>('House Vote Data'!G33>0.5),1,0) -> 0 | G9: =IF(OR(F9>=1,D9<0.05),"Hard",IF(AND(D9>=0.15,E9<0.05),"Easy","Medium")) -> Easy
A10: Lansford Borough | B10: Carbon | C10: =AVERAGE('House Vote Data'!G34:G37) -> 0.43230734 | D10: =AVERAGE(ABS('House Vote Data'!G34-0.5),ABS('House Vote Data'!G35-0.5),ABS('House Vote Data'!G36-0.5),ABS('House Vote Data'!G37-0.5)) -> 0.067692661 | E10: =STDEV('House Vote Data'!G34:G37) -> 0.042470136 | F10: =IF(('House Vote Data'!G34>0.5)<>('House Vote Data'!G35>0.5),1,0)+IF(('House Vote Data'!G35>0.5)<>('House Vote Data'!G36>0.5),1,0)+IF(('House Vote Data'!G36>0.5)<>('House Vote Data'!G37>0.5),1,0) -> 0 | G10: =IF(OR(F10>=1,D10<0.05),"Hard",IF(AND(D10>=0.15,E10<0.05),"Easy","Medium")) -> Medium
A11: Lausanne Township | B11: Carbon | C11: =AVERAGE('House Vote Data'!G38:G41) -> 0.30063256 | D11: =AVERAGE(ABS('House Vote Data'!G38-0.5),ABS('House Vote Data'!G39-0.5),ABS('House Vote Data'!G40-0.5),ABS('House Vote Data'!G41-0.5)) -> 0.19936744 | E11: =STDEV('House Vote Data'!G38:G41) -> 0.028779368 | F11: =IF(('House Vote Data'!G38>0.5)<>('House Vote Data'!G39>0.5),1,0)+IF(('House Vote Data'!G39>0.5)<>('House Vote Data'!G40>0.5),1,0)+IF(('House Vote Data'!G40>0.5)<>('House Vote Data'!G41>0.5),1,0) -> 0 | G11: =IF(OR(F11>=1,D11<0.05),"Hard",IF(AND(D11>=0.15,E11<0.05),"Easy","Medium")) -> Easy
A12: Lehigh Township | B12: Carbon | C12: =AVERAGE('House Vote Data'!G42:G45) -> 0.20363956 | D12: =AVERAGE(ABS('House Vote Data'!G42-0.5),ABS('House Vote Data'!G43-0.5),ABS('House Vote Data'!G44-0.5),ABS('House Vote Data'!G45-0.5)) -> 0.29636044 | E12: =STDEV('House Vote Data'!G42:G45) -> 0.013232881 | F12: =IF(('House Vote Data'!G42>0.5)<>('House Vote Data'!G43>0.5),1,0)+IF(('House Vote Data'!G43>0.5)<>('House Vote Data'!G44>0.5),1,0)+IF(('House Vote Data'!G44>0.5)<>('House Vote Data'!G45>0.5),1,0) -> 0 | G12: =IF(OR(F12>=1,D12<0.05),"Hard",IF(AND(D12>=0.15,E12<0.05),"Easy","Medium")) -> Easy
A13: Lehighton Borough | B13: Carbon | C13: =AVERAGE('House Vote Data'!G46:G49) -> 0.41480817 | D13: =AVERAGE(ABS('House Vote Data'!G46-0.5),ABS('House Vote Data'!G47-0.5),ABS('House Vote Data'!G48-0.5),ABS('House Vote Data'!G49-0.5)) -> 0.08519183 | E13: =STDEV('House Vote Data'!G46:G49) -> 0.041897109 | F13: =IF(('House Vote Data'!G46>0.5)<>('House Vote Data'!G47>0.5),1,0)+IF(('House Vote Data'!G47>0.5)<>('House Vote Data'!G48>0.5),1,0)+IF(('House Vote Data'!G48>0.5)<>('House Vote Data'!G49>0.5),1,0) -> 0 | G13: =IF(OR(F13>=1,D13<0.05),"Hard",IF(AND(D13>=0.15,E13<0.05),"Easy","Medium")) -> Medium
A14: Lower Towamensing Township | B14: Carbon | C14: =AVERAGE('House Vote Data'!G50:G53) -> 0.31740532 | D14: =AVERAGE(ABS('House Vote Data'!G50-0.5),ABS('House Vote Data'!G51-0.5),ABS('House Vote Data'!G52-0.5),ABS('House Vote Data'!G53-0.5)) -> 0.18259468 | E14: =STDEV('House Vote Data'!G50:G53) -> 0.037605004 | F14: =IF(('House Vote Data'!G50>0.5)<>('House Vote Data'!G51>0.5),1,0)+IF(('House Vote Data'!G51>0.5)<>('House Vote Data'!G52>0.5),1,0)+IF(('House Vote Data'!G52>0.5)<>('House Vote Data'!G53>0.5),1,0) -> 0 | G14: =IF(OR(F14>=1,D14<0.05),"Hard",IF(AND(D14>=0.15,E14<0.05),"Easy","Medium")) -> Easy
A15: Mahoning Township | B15: Carbon | C15: =AVERAGE('House Vote Data'!G54:G57) -> 0.30267631 | D15: =AVERAGE(ABS('House Vote Data'!G54-0.5),ABS('House Vote Data'!G55-0.5),ABS('House Vote Data'!G56-0.5),ABS('House Vote Data'!G57-0.5)) -> 0.19732369 | E15: =STDEV('House Vote Data'!G54:G57) -> 0.034308045 | F15: =IF(('House Vote Data'!G54>0.5)<>('House Vote Data'!G55>0.5),1,0)+IF(('House Vote Data'!G55>0.5)<>('House Vote Data'!G56>0.5),1,0)+IF(('House Vote Data'!G56>0.5)<>('House Vote Data'!G57>0.5),1,0) -> 0 | G15: =IF(OR(F15>=1,D15<0.05),"Hard",IF(AND(D15>=0.15,E15<0.05),"Easy","Medium")) -> Easy
A16: Nesquehoning Borough | B16: Carbon | C16: =AVERAGE('House Vote Data'!G58:G61) -> 0.41160581 | D16: =AVERAGE(ABS('House Vote Data'!G58-0.5),ABS('House Vote Data'!G59-0.5),ABS('House Vote Data'!G60-0.5),ABS('House Vote Data'!G61-0.5)) -> 0.088394185 | E16: =STDEV('House Vote Data'!G58:G61) -> 0.046607143 | F16: =IF(('House Vote Data'!G58>0.5)<>('House Vote Data'!G59>0.5),1,0)+IF(('House Vote Data'!G59>0.5)<>('House Vote Data'!G60>0.5),1,0)+IF(('House Vote Data'!G60>0.5)<>('House Vote Data'!G61>0.5),1,0) -> 0 | G16: =IF(OR(F16>=1,D16<0.05),"Hard",IF(AND(D16>=0.15,E16<0.05),"Easy","Medium")) -> Medium
A17: Packer Township | B17: Carbon | C17: =AVERAGE('House Vote Data'!G62:G65) -> 0.19690165 | D17: =AVERAGE(ABS('House Vote Data'!G62-0.5),ABS('House Vote Data'!G63-0.5),ABS('House Vote Data'!G64-0.5),ABS('House Vote Data'!G65-0.5)) -> 0.30309835 | E17: =STDEV('House Vote Data'!G62:G65) -> 0.027807505 | F17: =IF(('House Vote Data'!G62>0.5)<>('House Vote Data'!G63>0.5),1,0)+IF(('House Vote Data'!G63>0.5)<>('House Vote Data'!G64>0.5),1,0)+IF(('House Vote Data'!G64>0.5)<>('House Vote Data'!G65>0.5),1,0) -> 0 | G17: =IF(OR(F17>=1,D17<0.05),"Hard",IF(AND(D17>=0.15,E17<0.05),"Easy","Medium")) -> Easy
A18: Palmerton Borough | B18: Carbon | C18: =AVERAGE('House Vote Data'!G66:G69) -> 0.37477636 | D18: =AVERAGE(ABS('House Vote Data'!G66-0.5),ABS('House Vote Data'!G67-0.5),ABS('House Vote Data'!G68-0.5),ABS('House Vote Data'!G69-0.5)) -> 0.12522364 | E18: =STDEV('House Vote Data'!G66:G69) -> 0.031509508 | F18: =IF(('House Vote Data'!G66>0.5)<>('House Vote Data'!G67>0.5),1,0)+IF(('House Vote Data'!G67>0.5)<>('House Vote Data'!G68>0.5),1,0)+IF(('House Vote Data'!G68>0.5)<>('House Vote Data'!G69>0.5),1,0) -> 0 | G18: =IF(OR(F18>=1,D18<0.05),"Hard",IF(AND(D18>=0.15,E18<0.05),"Easy","Medium")) -> Medium
A19: Parryville Borough | B19: Carbon | C19: =AVERAGE('House Vote Data'!G70:G73) -> 0.28623541 | D19: =AVERAGE(ABS('House Vote Data'!G70-0.5),ABS('House Vote Data'!G71-0.5),ABS('House Vote Data'!G72-0.5),ABS('House Vote Data'!G73-0.5)) -> 0.21376459 | E19: =STDEV('House Vote Data'!G70:G73) -> 0.038872197 | F19: =IF(('House Vote Data'!G70>0.5)<>('House Vote Data'!G71>0.5),1,0)+IF(('House Vote Data'!G71>0.5)<>('House Vote Data'!G72>0.5),1,0)+IF(('House Vote Data'!G72>0.5)<>('House Vote Data'!G73>0.5),1,0) -> 0 | G19: =IF(OR(F19>=1,D19<0.05),"Hard",IF(AND(D19>=0.15,E19<0.05),"Easy","Medium")) -> Easy
A20: Penn Forest Township | B20: Carbon | C20: =AVERAGE('House Vote Data'!G74:G77) -> 0.37408937 | D20: =AVERAGE(ABS('House Vote Data'!G74-0.5),ABS('House Vote Data'!G75-0.5),ABS('House Vote Data'!G76-0.5),ABS('House Vote Data'!G77-0.5)) -> 0.12591063 | E20: =STDEV('House Vote Data'!G74:G77) -> 0.025105534 | F20: =IF(('House Vote Data'!G74>0.5)<>('House Vote Data'!G75>0.5),1,0)+IF(('House Vote Data'!G75>0.5)<>('House Vote Data'!G76>0.5),1,0)+IF(('House Vote Data'!G76>0.5)<>('House Vote Data'!G77>0.5),1,0) -> 0 | G20: =IF(OR(F20>=1,D20<0.05),"Hard",IF(AND(D20>=0.15,E20<0.05),"Easy","Medium")) -> Medium
A21: Summit Hill Borough | B21: Carbon | C21: =AVERAGE('House Vote Data'!G78:G81) -> 0.44481437 | D21: =AVERAGE(ABS('House Vote Data'!G78-0.5),ABS('House Vote Data'!G79-0.5),ABS('House Vote Data'!G80-0.5),ABS('House Vote Data'!G81-0.5)) -> 0.057826478 | E21: =STDEV('House Vote Data'!G78:G81) -> 0.044899897 | F21: =IF(('House Vote Data'!G78>0.5)<>('House Vote Data'!G79>0.5),1,0)+IF(('House Vote Data'!G79>0.5)<>('House Vote Data'!G80>0.5),1,0)+IF(('House Vote Data'!G80>0.5)<>('House Vote Data'!G81>0.5),1,0) -> 1 | G21: =IF(OR(F21>=1,D21<0.05),"Hard",IF(AND(D21>=0.15,E21<0.05),"Easy","Medium")) -> Hard
A22: Towamensing Township | B22: Carbon | C22: =AVERAGE('House Vote Data'!G82:G85) -> 0.30278832 | D22: =AVERAGE(ABS('House Vote Data'!G82-0.5),ABS('House Vote Data'!G83-0.5),ABS('House Vote Data'!G84-0.5),ABS('House Vote Data'!G85-0.5)) -> 0.19721168 | E22: =STDEV('House Vote Data'!G82:G85) -> 0.032653512 | F22: =IF(('House Vote Data'!G82>0.5)<>('House Vote Data'!G83>0.5),1,0)+IF(('House Vote Data'!G83>0.5)<>('House Vote Data'!G84>0.5),1,0)+IF(('House Vote Data'!G84>0.5)<>('House Vote Data'!G85>0.5),1,0) -> 0 | G22: =IF(OR(F22>=1,D22<0.05),"Hard",IF(AND(D22>=0.15,E22<0.05),"Easy","Medium")) -> Easy
A23: Weatherly Borough | B23: Carbon | C23: =AVERAGE('House Vote Data'!G86:G89) -> 0.28781785 | D23: =AVERAGE(ABS('House Vote Data'!G86-0.5),ABS('House Vote Data'!G87-0.5),ABS('House Vote Data'!G88-0.5),ABS('House Vote Data'!G89-0.5)) -> 0.21218215 | E23: =STDEV('House Vote Data'!G86:G89) -> 0.025862681 | F23: =IF(('House Vote Data'!G86>0.5)<>('House Vote Data'!G87>0.5),1,0)+IF(('House Vote Data'!G87>0.5)<>('House Vote Data'!G88>0.5),1,0)+IF(('House Vote Data'!G88>0.5)<>('House Vote Data'!G89>0.5),1,0) -> 0 | G23: =IF(OR(F23>=1,D23<0.05),"Hard",IF(AND(D23>=0.15,E23<0.05),"Easy","Medium")) -> Easy
A24: Weissport Borough | B24: Carbon | C24: =AVERAGE('House Vote Data'!G90:G93) -> 0.43281527 | D24: =AVERAGE(ABS('House Vote Data'!G90-0.5),ABS('House Vote Data'!G91-0.5),ABS('House Vote Data'!G92-0.5),ABS('House Vote Data'!G93-0.5)) -> 0.072286776 | E24: =STDEV('House Vote Data'!G90:G93) -> 0.066873161 | F24: =IF(('House Vote Data'!G90>0.5)<>('House Vote Data'!G91>0.5),1,0)+IF(('House Vote Data'!G91>0.5)<>('House Vote Data'!G92>0.5),1,0)+IF(('House Vote Data'!G92>0.5)<>('House Vote Data'!G93>0.5),1,0) -> 1 | G24: =IF(OR(F24>=1,D24<0.05),"Hard",IF(AND(D24>=0.15,E24<0.05),"Easy","Medium")) -> Hard
A25: Alburtis | B25: Lehigh | C25: =AVERAGE('House Vote Data'!G94:G97) -> 0.48055533 | D25: =AVERAGE(ABS('House Vote Data'!G94-0.5),ABS('House Vote Data'!G95-0.5),ABS('House Vote Data'!G96-0.5),ABS('House Vote Data'!G97-0.5)) -> 0.033398155 | E25: =STDEV('House Vote Data'!G94:G97) -> 0.037191436 | F25: =IF(('House Vote Data'!G94>0.5)<>('House Vote Data'!G95>0.5),1,0)+IF(('House Vote Data'!G95>0.5)<>('House Vote Data'!G96>0.5),1,0)+IF(('House Vote Data'!G96>0.5)<>('House Vote Data'!G97>0.5),1,0) -> 1 | G25: =IF(OR(F25>=1,D25<0.05),"Hard",IF(AND(D25>=0.15,E25<0.05),"Easy","Medium")) -> Hard
A26: Allentown | B26: Lehigh | C26: =AVERAGE('House Vote Data'!G98:G101) -> 0.68530365 | D26: =AVERAGE(ABS('House Vote Data'!G98-0.5),ABS('House Vote Data'!G99-0.5),ABS('House Vote Data'!G100-0.5),ABS('House Vote Data'!G101-0.5)) -> 0.18530365 | E26: =STDEV('House Vote Data'!G98:G101) -> 0.034903769 | F26: =IF(('House Vote Data'!G98>0.5)<>('House Vote Data'!G99>0.5),1,0)+IF(('House Vote Data'!G99>0.5)<>('House Vote Data'!G100>0.5),1,0)+IF(('House Vote Data'!G100>0.5)<>('House Vote Data'!G101>0.5),1,0) -> 0 | G26: =IF(OR(F26>=1,D26<0.05),"Hard",IF(AND(D26>=0.15,E26<0.05),"Easy","Medium")) -> Easy
A27: Bethlehem | B27: Lehigh | C27: =AVERAGE('House Vote Data'!G102:G105) -> 0.64818892 | D27: =AVERAGE(ABS('House Vote Data'!G102-0.5),ABS('House Vote Data'!G103-0.5),ABS('House Vote Data'!G104-0.5),ABS('House Vote Data'!G105-0.5)) -> 0.14818892 | E27: =STDEV('House Vote Data'!G102:G105) -> 0.019520993 | F27: =IF(('House Vote Data'!G102>0.5)<>('House Vote Data'!G103>0.5),1,0)+IF(('House Vote Data'!G103>0.5)<>('House Vote Data'!G104>0.5),1,0)+IF(('House Vote Data'!G104>0.5)<>('House Vote Data'!G105>0.5),1,0) -> 0 | G27: =IF(OR(F27>=1,D27<0.05),"Hard",IF(AND(D27>=0.15,E27<0.05),"Easy","Medium")) -> Medium
A28: Catasauqua | B28: Lehigh | C28: =AVERAGE('House Vote Data'!G106:G109) -> 0.53597179 | D28: =AVERAGE(ABS('House Vote Data'!G106-0.5),ABS('House Vote Data'!G107-0.5),ABS('House Vote Data'!G108-0.5),ABS('House Vote Data'!G109-0.5)) -> 0.035971789 | E28: =STDEV('House Vote Data'!G106:G109) -> 0.032126268 | F28: =IF(('House Vote Data'!G106>0.5)<>('House Vote Data'!G107>0.5),1,0)+IF(('House Vote Data'!G107>0.5)<>('House Vote Data'!G108>0.5),1,0)+IF(('House Vote Data'!G108>0.5)<>('House Vote Data'!G109>0.5),1,0) -> 0 | G28: =IF(OR(F28>=1,D28<0.05),"Hard",IF(AND(D28>=0.15,E28<0.05),"Easy","Medium")) -> Hard
A29: Coopersburg | B29: Lehigh | C29: =AVERAGE('House Vote Data'!G110:G113) -> 0.49821301 | D29: =AVERAGE(ABS('House Vote Data'!G110-0.5),ABS('House Vote Data'!G111-0.5),ABS('House Vote Data'!G112-0.5),ABS('House Vote Data'!G113-0.5)) -> 0.023970082 | E29: =STDEV('House Vote Data'!G110:G113) -> 0.029696521 | F29: =IF(('House Vote Data'!G110>0.5)<>('House Vote Data'!G111>0.5),1,0)+IF(('House Vote Data'!G111>0.5)<>('House Vote Data'!G112>0.5),1,0)+IF(('House Vote Data'!G112>0.5)<>('House Vote Data'!G113>0.5),1,0) -> 3 | G29: =IF(OR(F29>=1,D29<0.05),"Hard",IF(AND(D29>=0.15,E29<0.05),"Easy","Medium")) -> Hard
A30: Coplay | B30: Lehigh | C30: =AVERAGE('House Vote Data'!G114:G117) -> 0.52425916 | D30: =AVERAGE(ABS('House Vote Data'!G114-0.5),ABS('House Vote Data'!G115-0.5),ABS('House Vote Data'!G116-0.5),ABS('House Vote Data'!G117-0.5)) -> 0.024259156 | E30: =STDEV('House Vote Data'!G114:G117) -> 0.029052692 | F30: =IF(('House Vote Data'!G114>0.5)<>('House Vote Data'!G115>0.5),1,0)+IF(('House Vote Data'!G115>0.5)<>('House Vote Data'!G116>0.5),1,0)+IF(('House Vote Data'!G116>0.5)<>('House Vote Data'!G117>0.5),1,0) -> 0 | G30: =IF(OR(F30>=1,D30<0.05),"Hard",IF(AND(D30>=0.15,E30<0.05),"Easy","Medium")) -> Hard
A31: Emmaus | B31: Lehigh | C31: =AVERAGE('House Vote Data'!G118:G121) -> 0.5418223 | D31: =AVERAGE(ABS('House Vote Data'!G118-0.5),ABS('House Vote Data'!G119-0.5),ABS('House Vote Data'!G120-0.5),ABS('House Vote Data'!G121-0.5)) -> 0.041822301 | E31: =STDEV('House Vote Data'!G118:G121) -> 0.016634844 | F31: =IF(('House Vote Data'!G118>0.5)<>('House Vote Data'!G119>0.5),1,0)+IF(('House Vote Data'!G119>0.5)<>('House Vote Data'!G120>0.5),1,0)+IF(('House Vote Data'!G120>0.5)<>('House Vote Data'!G121>0.5),1,0) -> 0 | G31: =IF(OR(F31>=1,D31<0.05),"Hard",IF(AND(D31>=0.15,E31<0.05),"Easy","Medium")) -> Hard
A32: Fountain Hill | B32: Lehigh | C32: =AVERAGE('House Vote Data'!G122:G125) -> 0.67539829 | D32: =AVERAGE(ABS('House Vote Data'!G122-0.5),ABS('House Vote Data'!G123-0.5),ABS('House Vote Data'!G124-0.5),ABS('House Vote Data'!G125-0.5)) -> 0.17539829 | E32: =STDEV('House Vote Data'!G122:G125) -> 0.024967888 | F32: =IF(('House Vote Data'!G122>0.5)<>('House Vote Data'!G123>0.5),1,0)+IF(('House Vote Data'!G123>0.5)<>('House Vote Data'!G124>0.5),1,0)+IF(('House Vote Data'!G124>0.5)<>('House Vote Data'!G125>0.5),1,0) -> 0 | G32: =IF(OR(F32>=1,D32<0.05),"Hard",IF(AND(D32>=0.15,E32<0.05),"Easy","Medium")) -> Easy
A33: Hanover | B33: Lehigh | C33: =AVERAGE('House Vote Data'!G126:G129) -> 0.5660929 | D33: =AVERAGE(ABS('House Vote Data'!G126-0.5),ABS('House Vote Data'!G127-0.5),ABS('House Vote Data'!G128-0.5),ABS('House Vote Data'!G129-0.5)) -> 0.066092901 | E33: =STDEV('House Vote Data'!G126:G129) -> 0.02605666 | F33: =IF(('House Vote Data'!G126>0.5)<>('House Vote Data'!G127>0.5),1,0)+IF(('House Vote Data'!G127>0.5)<>('House Vote Data'!G128>0.5),1,0)+IF(('House Vote Data'!G128>0.5)<>('House Vote Data'!G129>0.5),1,0) -> 0 | G33: =IF(OR(F33>=1,D33<0.05),"Hard",IF(AND(D33>=0.15,E33<0.05),"Easy","Medium")) -> Medium
A34: Heidelberg | B34: Lehigh | C34: =AVERAGE('House Vote Data'!G130:G133) -> 0.32939124 | D34: =AVERAGE(ABS('House Vote Data'!G130-0.5),ABS('House Vote Data'!G131-0.5),ABS('House Vote Data'!G132-0.5),ABS('House Vote Data'!G133-0.5)) -> 0.17060876 | E34: =STDEV('House Vote Data'!G130:G133) -> 0.024213045 | F34: =IF(('House Vote Data'!G130>0.5)<>('House Vote Data'!G131>0.5),1,0)+IF(('House Vote Data'!G131>0.5)<>('House Vote Data'!G132>0.5),1,0)+IF(('House Vote Data'!G132>0.5)<>('House Vote Data'!G133>0.5),1,0) -> 0 | G34: =IF(OR(F34>=1,D34<0.05),"Hard",IF(AND(D34>=0.15,E34<0.05),"Easy","Medium")) -> Easy
A35: Lower Macungie | B35: Lehigh | C35: =AVERAGE('House Vote Data'!G134:G137) -> 0.50687503 | D35: =AVERAGE(ABS('House Vote Data'!G134-0.5),ABS('House Vote Data'!G135-0.5),ABS('House Vote Data'!G136-0.5),ABS('House Vote Data'!G137-0.5)) -> 0.012005704 | E35: =STDEV('House Vote Data'!G134:G137) -> 0.014471563 | F35: =IF(('House Vote Data'!G134>0.5)<>('House Vote Data'!G135>0.5),1,0)+IF(('House Vote Data'!G135>0.5)<>('House Vote Data'!G136>0.5),1,0)+IF(('House Vote Data'!G136>0.5)<>('House Vote Data'!G137>0.5),1,0) -> 3 | G35: =IF(OR(F35>=1,D35<0.05),"Hard",IF(AND(D35>=0.15,E35<0.05),"Easy","Medium")) -> Hard
A36: Lower Milford | B36: Lehigh | C36: =AVERAGE('House Vote Data'!G138:G141) -> 0.38515093 | D36: =AVERAGE(ABS('House Vote Data'!G138-0.5),ABS('House Vote Data'!G139-0.5),ABS('House Vote Data'!G140-0.5),ABS('House Vote Data'!G141-0.5)) -> 0.11484907 | E36: =STDEV('House Vote Data'!G138:G141) -> 0.014478893 | F36: =IF(('House Vote Data'!G138>0.5)<>('House Vote Data'!G139>0.5),1,0)+IF(('House Vote Data'!G139>0.5)<>('House Vote Data'!G140>0.5),1,0)+IF(('House Vote Data'!G140>0.5)<>('House Vote Data'!G141>0.5),1,0) -> 0 | G36: =IF(OR(F36>=1,D36<0.05),"Hard",IF(AND(D36>=0.15,E36<0.05),"Easy","Medium")) -> Medium
A37: Lowhill | B37: Lehigh | C37: =AVERAGE('House Vote Data'!G142:G145) -> 0.36615963 | D37: =AVERAGE(ABS('House Vote Data'!G142-0.5),ABS('House Vote Data'!G143-0.5),ABS('House Vote Data'!G144-0.5),ABS('House Vote Data'!G145-0.5)) -> 0.13384037 | E37: =STDEV('House Vote Data'!G142:G145) -> 0.011622044 | F37: =IF(('House Vote Data'!G142>0.5)<>('House Vote Data'!G143>0.5),1,0)+IF(('House Vote Data'!G143>0.5)<>('House Vote Data'!G144>0.5),1,0)+IF(('House Vote Data'!G144>0.5)<>('House Vote Data'!G145>0.5),1,0) -> 0 | G37: =IF(OR(F37>=1,D37<0.05),"Hard",IF(AND(D37>=0.15,E37<0.05),"Easy","Medium")) -> Medium
A38: Lynn | B38: Lehigh | C38: =AVERAGE('House Vote Data'!G146:G149) -> 0.32638322 | D38: =AVERAGE(ABS('House Vote Data'!G146-0.5),ABS('House Vote Data'!G147-0.5),ABS('House Vote Data'!G148-0.5),ABS('House Vote Data'!G149-0.5)) -> 0.17361678 | E38: =STDEV('House Vote Data'!G146:G149) -> 0.01024726 | F38: =IF(('House Vote Data'!G146>0.5)<>('House Vote Data'!G147>0.5),1,0)+IF(('House Vote Data'!G147>0.5)<>('House Vote Data'!G148>0.5),1,0)+IF(('House Vote Data'!G148>0.5)<>('House Vote Data'!G149>0.5),1,0) -> 0 | G38: =IF(OR(F38>=1,D38<0.05),"Hard",IF(AND(D38>=0.15,E38<0.05),"Easy","Medium")) -> Easy
A39: Macungie | B39: Lehigh | C39: =AVERAGE('House Vote Data'!G150:G153) -> 0.54112577 | D39: =AVERAGE(ABS('House Vote Data'!G150-0.5),ABS('House Vote Data'!G151-0.5),ABS('House Vote Data'!G152-0.5),ABS('House Vote Data'!G153-0.5)) -> 0.04112577 | E39: =STDEV('House Vote Data'!G150:G153) -> 0.01152065 | F39: =IF(('House Vote Data'!G150>0.5)<>('House Vote Data'!G151>0.5),1,0)+IF(('House Vote Data'!G151>0.5)<>('House Vote Data'!G152>0.5),1,0)+IF(('House Vote Data'!G152>0.5)<>('House Vote Data'!G153>0.5),1,0) -> 0 | G39: =IF(OR(F39>=1,D39<0.05),"Hard",IF(AND(D39>=0.15,E39<0.05),"Easy","Medium")) -> Hard
A40: North Whitehall | B40: Lehigh | C40: =AVERAGE('House Vote Data'!G154:G157) -> 0.41138663 | D40: =AVERAGE(ABS('House Vote Data'!G154-0.5),ABS('House Vote Data'!G155-0.5),ABS('House Vote Data'!G156-0.5),ABS('House Vote Data'!G157-0.5)) -> 0.088613373 | E40: =STDEV('House Vote Data'!G154:G157) -> 0.010867674 | F40: =IF(('House Vote Data'!G154>0.5)<>('House Vote Data'!G155>0.5),1,0)+IF(('House Vote Data'!G155>0.5)<>('House Vote Data'!G156>0.5),1,0)+IF(('House Vote Data'!G156>0.5)<>('House Vote Data'!G157>0.5),1,0) -> 0 | G40: =IF(OR(F40>=1,D40<0.05),"Hard",IF(AND(D40>=0.15,E40<0.05),"Easy","Medium")) -> Medium
...

Sheet Magic Municipality
A1: Bellwether Search (89 Municipalities, Complete Real Data)
A3: District-wide result by year
A4: Year | B4: District Dem Votes | C4: District Rep Votes | D4: District Dem Share | E4: District Winner
A5: 2018 | B5: =SUMIF('House Vote Data'!$A:$A,A5,'House Vote Data'!$D:$D) -> 140419 | C5: =SUMIF('House Vote Data'!$A:$A,A5,'House Vote Data'!$E:$E) -> 122895 | D5: =B5/(B5+C5) -> 0.53327586 | E5: =IF(D5>0.5,"D","R") -> D
A6: 2020 | B6: =SUMIF('House Vote Data'!$A:$A,A6,'House Vote Data'!$D:$D) -> 193719 | C6: =SUMIF('House Vote Data'!$A:$A,A6,'House Vote Data'!$E:$E) -> 196320 | D6: =B6/(B6+C6) -> 0.49666572 | E6: =IF(D6>0.5,"D","R") -> R
A7: 2022 | B7: =SUMIF('House Vote Data'!$A:$A,A7,'House Vote Data'!$D:$D) -> 151364 | C7: =SUMIF('House Vote Data'!$A:$A,A7,'House Vote Data'!$E:$E) -> 145527 | D7: =B7/(B7+C7) -> 0.50983021 | E7: =IF(D7>0.5,"D","R") -> D
A8: 2024 | B8: =SUMIF('House Vote Data'!$A:$A,A8,'House Vote Data'!$D:$D) -> 199626 | C8: =SUMIF('House Vote Data'!$A:$A,A8,'House Vote Data'!$E:$E) -> 203688 | D8: =B8/(B8+C8) -> 0.49496422 | E8: =IF(D8>0.5,"D","R") -> R
A11: Per-municipality bellwether test
A12: Municipality | B12: County | C12: Match 2018 | D12: Match 2020 | E12: Match 2022 | F12: Match 2024 | G12: Total Matches (/4) | H12: Avg Point Gap vs District | I12: Magic Municipality? | J12: (helper)
A13: Banks Township | B13: Carbon | C13: =IF(IF('House Vote Data'!G2>0.5,"D","R")=$E$5,1,0) -> 0 | D13: =IF(IF('House Vote Data'!G3>0.5,"D","R")=$E$6,1,0) -> 1 | E13: =IF(IF('House Vote Data'!G4>0.5,"D","R")=$E$7,1,0) -> 0 | F13: =IF(IF('House Vote Data'!G5>0.5,"D","R")=$E$8,1,0) -> 1 | G13: =SUM(C13:F13) -> 2 | H13: =AVERAGE(ABS('House Vote Data'!G2-$D$5),ABS('House Vote Data'!G3-$D$6),ABS('House Vote Data'!G4-$D$7),ABS('House Vote Data'!G5-$D$8)) -> 0.13287349 | I13: =IF(AND(G13=4,H13=MIN(J13:J101)),"<< MAGIC MUNICIPALITY","") | J13: =IF(G13=4,H13,"")
A14: Beaver Meadows Borough | B14: Carbon | C14: =IF(IF('House Vote Data'!G6>0.5,"D","R")=$E$5,1,0) -> 0 | D14: =IF(IF('House Vote Data'!G7>0.5,"D","R")=$E$6,1,0) -> 1 | E14: =IF(IF('House Vote Data'!G8>0.5,"D","R")=$E$7,1,0) -> 0 | F14: =IF(IF('House Vote Data'!G9>0.5,"D","R")=$E$8,1,0) -> 1 | G14: =SUM(C14:F14) -> 2 | H14: =AVERAGE(ABS('House Vote Data'!G6-$D$5),ABS('House Vote Data'!G7-$D$6),ABS('House Vote Data'!G8-$D$7),ABS('House Vote Data'!G9-$D$8)) -> 0.22644351 | I14: =IF(AND(G14=4,H14=MIN(J13:J101)),"<< MAGIC MUNICIPALITY","") | J14: =IF(G14=4,H14,"")
A15: Bowmanstown Borough | B15: Carbon | C15: =IF(IF('House Vote Data'!G10>0.5,"D","R")=$E$5,1,0) -> 0 | D15: =IF(IF('House Vote Data'!G11>0.5,"D","R")=$E$6,1,0) -> 1 | E15: =IF(IF('House Vote Data'!G12>0.5,"D","R")=$E$7,1,0) -> 0 | F15: =IF(IF('House Vote Data'!G13>0.5,"D","R")=$E$8,1,0) -> 1 | G15: =SUM(C15:F15) -> 2 | H15: =AVERAGE(ABS('House Vote Data'!G10-$D$5),ABS('House Vote Data'!G11-$D$6),ABS('House Vote Data'!G12-$D$7),ABS('House Vote Data'!G13-$D$8)) -> 0.17826232 | I15: =IF(AND(G15=4,H15=MIN(J13:J101)),"<< MAGIC MUNICIPALITY","") | J15: =IF(G15=4,H15,"")
A16: East Penn Township | B16: Carbon | C16: =IF(IF('House Vote Data'!G14>0.5,"D","R")=$E$5,1,0) -> 0 | D16: =IF(IF('House Vote Data'!G15>0.5,"D","R")=$E$6,1,0) -> 1 | E16: =IF(IF('House Vote Data'!G16>0.5,"D","R")=$E$7,1,0) -> 0 | F16: =IF(IF('House Vote Data'!G17>0.5,"D","R")=$E$8,1,0) -> 1 | G16: =SUM(C16:F16) -> 2 | H16: =AVERAGE(ABS('House Vote Data'!G14-$D$5),ABS('House Vote Data'!G15-$D$6),ABS('House Vote Data'!G16-$D$7),ABS('House Vote Data'!G17-$D$8)) -> 0.22709027 | I16: =IF(AND(G16=4,H16=MIN(J13:J101)),"<< MAGIC MUNICIPALITY","") | J16: =IF(G16=4,H16,"")
A17: East Side Borough | B17: Carbon | C17: =IF(IF('House Vote Data'!G18>0.5,"D","R")=$E$5,1,0) -> 0 | D17: =IF(IF('House Vote Data'!G19>0.5,"D","R")=$E$6,1,0) -> 1 | E17: =IF(IF('House Vote Data'!G20>0.5,"D","R")=$E$7,1,0) -> 0 | F17: =IF(IF('House Vote Data'!G21>0.5,"D","R")=$E$8,1,0) -> 1 | G17: =SUM(C17:F17) -> 2 | H17: =AVERAGE(ABS('House Vote Data'!G18-$D$5),ABS('House Vote Data'!G19-$D$6),ABS('House Vote Data'!G20-$D$7),ABS('House Vote Data'!G21-$D$8)) -> 0.13152444 | I17: =IF(AND(G17=4,H17=MIN(J13:J101)),"<< MAGIC MUNICIPALITY","") | J17: =IF(G17=4,H17,"")
A18: Franklin Township | B18: Carbon | C18: =IF(IF('House Vote Data'!G22>0.5,"D","R")=$E$5,1,0) -> 0 | D18: =IF(IF('House Vote Data'!G23>0.5,"D","R")=$E$6,1,0) -> 1 | E18: =IF(IF('House Vote Data'!G24>0.5,"D","R")=$E$7,1,0) -> 0 | F18: =IF(IF('House Vote Data'!G25>0.5,"D","R")=$E$8,1,0) -> 1 | G18: =SUM(C18:F18) -> 2 | H18: =AVERAGE(ABS('House Vote Data'!G22-$D$5),ABS('House Vote Data'!G23-$D$6),ABS('House Vote Data'!G24-$D$7),ABS('House Vote Data'!G25-$D$8)) -> 0.22290706 | I18: =IF(AND(G18=4,H18=MIN(J13:J101)),"<< MAGIC MUNICIPALITY","") | J18: =IF(G18=4,H18,"")
A19: Jim Thorpe Borough | B19: Carbon | C19: =IF(IF('House Vote Data'!G26>0.5,"D","R")=$E$5,1,0) -> 0 | D19: =IF(IF('House Vote Data'!G27>0.5,"D","R")=$E$6,1,0) -> 1 | E19: =IF(IF('House Vote Data'!G28>0.5,"D","R")=$E$7,1,0) -> 0 | F19: =IF(IF('House Vote Data'!G29>0.5,"D","R")=$E$8,1,0) -> 1 | G19: =SUM(C19:F19) -> 2 | H19: =AVERAGE(ABS('House Vote Data'!G26-$D$5),ABS('House Vote Data'!G27-$D$6),ABS('House Vote Data'!G28-$D$7),ABS('House Vote Data'!G29-$D$8)) -> 0.061983314 | I19: =IF(AND(G19=4,H19=MIN(J13:J101)),"<< MAGIC MUNICIPALITY","") | J19: =IF(G19=4,H19,"")
A20: Kidder Township | B20: Carbon | C20: =IF(IF('House Vote Data'!G30>0.5,"D","R")=$E$5,1,0) -> 0 | D20: =IF(IF('House Vote Data'!G31>0.5,"D","R")=$E$6,1,0) -> 1 | E20: =IF(IF('House Vote Data'!G32>0.5,"D","R")=$E$7,1,0) -> 0 | F20: =IF(IF('House Vote Data'!G33>0.5,"D","R")=$E$8,1,0) -> 1 | G20: =SUM(C20:F20) -> 2 | H20: =AVERAGE(ABS('House Vote Data'!G30-$D$5),ABS('House Vote Data'!G31-$D$6),ABS('House Vote Data'!G32-$D$7),ABS('House Vote Data'!G33-$D$8)) -> 0.17855149 | I20: =IF(AND(G20=4,H20=MIN(J13:J101)),"<< MAGIC MUNICIPALITY","") | J20: =IF(G20=4,H20,"")
A21: Lansford Borough | B21: Carbon | C21: =IF(IF('House Vote Data'!G34>0.5,"D","R")=$E$5,1,0) -> 0 | D21: =IF(IF('House Vote Data'!G35>0.5,"D","R")=$E$6,1,0) -> 1 | E21: =IF(IF('House Vote Data'!G36>0.5,"D","R")=$E$7,1,0) -> 0 | F21: =IF(IF('House Vote Data'!G37>0.5,"D","R")=$E$8,1,0) -> 1 | G21: =SUM(C21:F21) -> 2 | H21: =AVERAGE(ABS('House Vote Data'!G34-$D$5),ABS('House Vote Data'!G35-$D$6),ABS('House Vote Data'!G36-$D$7),ABS('House Vote Data'!G37-$D$8)) -> 0.076376663 | I21: =IF(AND(G21=4,H21=MIN(J13:J101)),"<< MAGIC MUNICIPALITY","") | J21: =IF(G21=4,H21,"")
A22: Lausanne Township | B22: Carbon | C22: =IF(IF('House Vote Data'!G38>0.5,"D","R")=$E$5,1,0) -> 0 | D22: =IF(IF('House Vote Data'!G39>0.5,"D","R")=$E$6,1,0) -> 1 | E22: =IF(IF('House Vote Data'!G40>0.5,"D","R")=$E$7,1,0) -> 0 | F22: =IF(IF('House Vote Data'!G41>0.5,"D","R")=$E$8,1,0) -> 1 | G22: =SUM(C22:F22) -> 2 | H22: =AVERAGE(ABS('House Vote Data'!G38-$D$5),ABS('House Vote Data'!G39-$D$6),ABS('House Vote Data'!G40-$D$7),ABS('House Vote Data'!G41-$D$8)) -> 0.20805144 | I22: =IF(AND(G22=4,H22=MIN(J13:J101)),"<< MAGIC MUNICIPALITY","") | J22: =IF(G22=4,H22,"")
A23: Lehigh Township | B23: Carbon | C23: =IF(IF('House Vote Data'!G42>0.5,"D","R")=$E$5,1,0) -> 0 | D23: =IF(IF('House Vote Data'!G43>0.5,"D","R")=$E$6,1,0) -> 1 | E23: =IF(IF('House Vote Data'!G44>0.5,"D","R")=$E$7,1,0) -> 0 | F23: =IF(IF('House Vote Data'!G45>0.5,"D","R")=$E$8,1,0) -> 1 | G23: =SUM(C23:F23) -> 2 | H23: =AVERAGE(ABS('House Vote Data'!G42-$D$5),ABS('House Vote Data'!G43-$D$6),ABS('House Vote Data'!G44-$D$7),ABS('House Vote Data'!G45-$D$8)) -> 0.30504444 | I23: =IF(AND(G23=4,H23=MIN(J13:J101)),"<< MAGIC MUNICIPALITY","") | J23: =IF(G23=4,H23,"")
A24: Lehighton Borough | B24: Carbon | C24: =IF(IF('House Vote Data'!G46>0.5,"D","R")=$E$5,1,0) -> 0 | D24: =IF(IF('House Vote Data'!G47>0.5,"D","R")=$E$6,1,0) -> 1 | E24: =IF(IF('House Vote Data'!G48>0.5,"D","R")=$E$7,1,0) -> 0 | F24: =IF(IF('House Vote Data'!G49>0.5,"D","R")=$E$8,1,0) -> 1 | G24: =SUM(C24:F24) -> 2 | H24: =AVERAGE(ABS('House Vote Data'!G46-$D$5),ABS('House Vote Data'!G47-$D$6),ABS('House Vote Data'!G48-$D$7),ABS('House Vote Data'!G49-$D$8)) -> 0.093875832 | I24: =IF(AND(G24=4,H24=MIN(J13:J101)),"<< MAGIC MUNICIPALITY","") | J24: =IF(G24=4,H24,"")
A25: Lower Towamensing Township | B25: Carbon | C25: =IF(IF('House Vote Data'!G50>0.5,"D","R")=$E$5,1,0) -> 0 | D25: =IF(IF('House Vote Data'!G51>0.5,"D","R")=$E$6,1,0) -> 1 | E25: =IF(IF('House Vote Data'!G52>0.5,"D","R")=$E$7,1,0) -> 0 | F25: =IF(IF('House Vote Data'!G53>0.5,"D","R")=$E$8,1,0) -> 1 | G25: =SUM(C25:F25) -> 2 | H25: =AVERAGE(ABS('House Vote Data'!G50-$D$5),ABS('House Vote Data'!G51-$D$6),ABS('House Vote Data'!G52-$D$7),ABS('House Vote Data'!G53-$D$8)) -> 0.19127868 | I25: =IF(AND(G25=4,H25=MIN(J13:J101)),"<< MAGIC MUNICIPALITY","") | J25: =IF(G25=4,H25,"")
A26: Mahoning Township | B26: Carbon | C26: =IF(IF('House Vote Data'!G54>0.5,"D","R")=$E$5,1,0) -> 0 | D26: =IF(IF('House Vote Data'!G55>0.5,"D","R")=$E$6,1,0) -> 1 | E26: =IF(IF('House Vote Data'!G56>0.5,"D","R")=$E$7,1,0) -> 0 | F26: =IF(IF('House Vote Data'!G57>0.5,"D","R")=$E$8,1,0) -> 1 | G26: =SUM(C26:F26) -> 2 | H26: =AVERAGE(ABS('House Vote Data'!G54-$D$5),ABS('House Vote Data'!G55-$D$6),ABS('House Vote Data'!G56-$D$7),ABS('House Vote Data'!G57-$D$8)) -> 0.20600769 | I26: =IF(AND(G26=4,H26=MIN(J13:J101)),"<< MAGIC MUNICIPALITY","") | J26: =IF(G26=4,H26,"")
A27: Nesquehoning Borough | B27: Carbon | C27: =IF(IF('House Vote Data'!G58>0.5,"D","R")=$E$5,1,0) -> 0 | D27: =IF(IF('House Vote Data'!G59>0.5,"D","R")=$E$6,1,0) -> 1 | E27: =IF(IF('House Vote Data'!G60>0.5,"D","R")=$E$7,1,0) -> 0 | F27: =IF(IF('House Vote Data'!G61>0.5,"D","R")=$E$8,1,0) -> 1 | G27: =SUM(C27:F27) -> 2 | H27: =AVERAGE(ABS('House Vote Data'!G58-$D$5),ABS('House Vote Data'!G59-$D$6),ABS('House Vote Data'!G60-$D$7),ABS('House Vote Data'!G61-$D$8)) -> 0.097078187 | I27: =IF(AND(G27=4,H27=MIN(J13:J101)),"<< MAGIC MUNICIPALITY","") | J27: =IF(G27=4,H27,"")
A28: Packer Township | B28: Carbon | C28: =IF(IF('House Vote Data'!G62>0.5,"D","R")=$E$5,1,0) -> 0 | D28: =IF(IF('House Vote Data'!G63>0.5,"D","R")=$E$6,1,0) -> 1 | E28: =IF(IF('House Vote Data'!G64>0.5,"D","R")=$E$7,1,0) -> 0 | F28: =IF(IF('House Vote Data'!G65>0.5,"D","R")=$E$8,1,0) -> 1 | G28: =SUM(C28:F28) -> 2 | H28: =AVERAGE(ABS('House Vote Data'!G62-$D$5),ABS('House Vote Data'!G63-$D$6),ABS('House Vote Data'!G64-$D$7),ABS('House Vote Data'!G65-$D$8)) -> 0.31178235 | I28: =IF(AND(G28=4,H28=MIN(J13:J101)),"<< MAGIC MUNICIPALITY","") | J28: =IF(G28=4,H28,"")
A29: Palmerton Borough | B29: Carbon | C29: =IF(IF('House Vote Data'!G66>0.5,"D","R")=$E$5,1,0) -> 0 | D29: =IF(IF('House Vote Data'!G67>0.5,"D","R")=$E$6,1,0) -> 1 | E29: =IF(IF('House Vote Data'!G68>0.5,"D","R")=$E$7,1,0) -> 0 | F29: =IF(IF('House Vote Data'!G69>0.5,"D","R")=$E$8,1,0) -> 1 | G29: =SUM(C29:F29) -> 2 | H29: =AVERAGE(ABS('House Vote Data'!G66-$D$5),ABS('House Vote Data'!G67-$D$6),ABS('House Vote Data'!G68-$D$7),ABS('House Vote Data'!G69-$D$8)) -> 0.13390764 | I29: =IF(AND(G29=4,H29=MIN(J13:J101)),"<< MAGIC MUNICIPALITY","") | J29: =IF(G29=4,H29,"")
A30: Parryville Borough | B30: Carbon | C30: =IF(IF('House Vote Data'!G70>0.5,"D","R")=$E$5,1,0) -> 0 | D30: =IF(IF('House Vote Data'!G71>0.5,"D","R")=$E$6,1,0) -> 1 | E30: =IF(IF('House Vote Data'!G72>0.5,"D","R")=$E$7,1,0) -> 0 | F30: =IF(IF('House Vote Data'!G73>0.5,"D","R")=$E$8,1,0) -> 1 | G30: =SUM(C30:F30) -> 2 | H30: =AVERAGE(ABS('House Vote Data'!G70-$D$5),ABS('House Vote Data'!G71-$D$6),ABS('House Vote Data'!G72-$D$7),ABS('House Vote Data'!G73-$D$8)) -> 0.22244859 | I30: =IF(AND(G30=4,H30=MIN(J13:J101)),"<< MAGIC MUNICIPALITY","") | J30: =IF(G30=4,H30,"")
A31: Penn Forest Township | B31: Carbon | C31: =IF(IF('House Vote Data'!G74>0.5,"D","R")=$E$5,1,0) -> 0 | D31: =IF(IF('House Vote Data'!G75>0.5,"D","R")=$E$6,1,0) -> 1 | E31: =IF(IF('House Vote Data'!G76>0.5,"D","R")=$E$7,1,0) -> 0 | F31: =IF(IF('House Vote Data'!G77>0.5,"D","R")=$E$8,1,0) -> 1 | G31: =SUM(C31:F31) -> 2 | H31: =AVERAGE(ABS('House Vote Data'!G74-$D$5),ABS('House Vote Data'!G75-$D$6),ABS('House Vote Data'!G76-$D$7),ABS('House Vote Data'!G77-$D$8)) -> 0.13459463 | I31: =IF(AND(G31=4,H31=MIN(J13:J101)),"<< MAGIC MUNICIPALITY","") | J31: =IF(G31=4,H31,"")
A32: Summit Hill Borough | B32: Carbon | C32: =IF(IF('House Vote Data'!G78>0.5,"D","R")=$E$5,1,0) -> 1 | D32: =IF(IF('House Vote Data'!G79>0.5,"D","R")=$E$6,1,0) -> 1 | E32: =IF(IF('House Vote Data'!G80>0.5,"D","R")=$E$7,1,0) -> 0 | F32: =IF(IF('House Vote Data'!G81>0.5,"D","R")=$E$8,1,0) -> 1 | G32: =SUM(C32:F32) -> 3 | H32: =AVERAGE(ABS('House Vote Data'!G78-$D$5),ABS('House Vote Data'!G79-$D$6),ABS('House Vote Data'!G80-$D$7),ABS('House Vote Data'!G81-$D$8)) -> 0.063869634 | I32: =IF(AND(G32=4,H32=MIN(J13:J101)),"<< MAGIC MUNICIPALITY","") | J32: =IF(G32=4,H32,"")
A33: Towamensing Township | B33: Carbon | C33: =IF(IF('House Vote Data'!G82>0.5,"D","R")=$E$5,1,0) -> 0 | D33: =IF(IF('House Vote Data'!G83>0.5,"D","R")=$E$6,1,0) -> 1 | E33: =IF(IF('House Vote Data'!G84>0.5,"D","R")=$E$7,1,0) -> 0 | F33: =IF(IF('House Vote Data'!G85>0.5,"D","R")=$E$8,1,0) -> 1 | G33: =SUM(C33:F33) -> 2 | H33: =AVERAGE(ABS('House Vote Data'!G82-$D$5),ABS('House Vote Data'!G83-$D$6),ABS('House Vote Data'!G84-$D$7),ABS('House Vote Data'!G85-$D$8)) -> 0.20589569 | I33: =IF(AND(G33=4,H33=MIN(J13:J101)),"<< MAGIC MUNICIPALITY","") | J33: =IF(G33=4,H33,"")
A34: Weatherly Borough | B34: Carbon | C34: =IF(IF('House Vote Data'!G86>0.5,"D","R")=$E$5,1,0) -> 0 | D34: =IF(IF('House Vote Data'!G87>0.5,"D","R")=$E$6,1,0) -> 1 | E34: =IF(IF('House Vote Data'!G88>0.5,"D","R")=$E$7,1,0) -> 0 | F34: =IF(IF('House Vote Data'!G89>0.5,"D","R")=$E$8,1,0) -> 1 | G34: =SUM(C34:F34) -> 2 | H34: =AVERAGE(ABS('House Vote Data'!G86-$D$5),ABS('House Vote Data'!G87-$D$6),ABS('House Vote Data'!G88-$D$7),ABS('House Vote Data'!G89-$D$8)) -> 0.22086615 | I34: =IF(AND(G34=4,H34=MIN(J13:J101)),"<< MAGIC MUNICIPALITY","") | J34: =IF(G34=4,H34,"")
A35: Weissport Borough | B35: Carbon | C35: =IF(IF('House Vote Data'!G90>0.5,"D","R")=$E$5,1,0) -> 1 | D35: =IF(IF('House Vote Data'!G91>0.5,"D","R")=$E$6,1,0) -> 1 | E35: =IF(IF('House Vote Data'!G92>0.5,"D","R")=$E$7,1,0) -> 0 | F35: =IF(IF('House Vote Data'!G93>0.5,"D","R")=$E$8,1,0) -> 1 | G35: =SUM(C35:F35) -> 3 | H35: =AVERAGE(ABS('House Vote Data'!G90-$D$5),ABS('House Vote Data'!G91-$D$6),ABS('House Vote Data'!G92-$D$7),ABS('House Vote Data'!G93-$D$8)) -> 0.075868737 | I35: =IF(AND(G35=4,H35=MIN(J13:J101)),"<< MAGIC MUNICIPALITY","") | J35: =IF(G35=4,H35,"")
A36: Alburtis | B36: Lehigh | C36: =IF(IF('House Vote Data'!G94>0.5,"D","R")=$E$5,1,0) -> 1 | D36: =IF(IF('House Vote Data'!G95>0.5,"D","R")=$E$6,1,0) -> 1 | E36: =IF(IF('House Vote Data'!G96>0.5,"D","R")=$E$7,1,0) -> 0 | F36: =IF(IF('House Vote Data'!G97>0.5,"D","R")=$E$8,1,0) -> 1 | G36: =SUM(C36:F36) -> 3 | H36: =AVERAGE(ABS('House Vote Data'!G94-$D$5),ABS('House Vote Data'!G95-$D$6),ABS('House Vote Data'!G96-$D$7),ABS('House Vote Data'!G97-$D$8)) -> 0.028128668 | I36: =IF(AND(G36=4,H36=MIN(J13:J101)),"<< MAGIC MUNICIPALITY","") | J36: =IF(G36=4,H36,"")
A37: Allentown | B37: Lehigh | C37: =IF(IF('House Vote Data'!G98>0.5,"D","R")=$E$5,1,0) -> 1 | D37: =IF(IF('House Vote Data'!G99>0.5,"D","R")=$E$6,1,0) -> 0 | E37: =IF(IF('House Vote Data'!G100>0.5,"D","R")=$E$7,1,0) -> 1 | F37: =IF(IF('House Vote Data'!G101>0.5,"D","R")=$E$8,1,0) -> 0 | G37: =SUM(C37:F37) -> 2 | H37: =AVERAGE(ABS('House Vote Data'!G98-$D$5),ABS('House Vote Data'!G99-$D$6),ABS('House Vote Data'!G100-$D$7),ABS('House Vote Data'!G101-$D$8)) -> 0.17661965 | I37: =IF(AND(G37=4,H37=MIN(J13:J101)),"<< MAGIC MUNICIPALITY","") | J37: =IF(G37=4,H37,"")
A38: Bethlehem | B38: Lehigh | C38: =IF(IF('House Vote Data'!G102>0.5,"D","R")=$E$5,1,0) -> 1 | D38: =IF(IF('House Vote Data'!G103>0.5,"D","R")=$E$6,1,0) -> 0 | E38: =IF(IF('House Vote Data'!G104>0.5,"D","R")=$E$7,1,0) -> 1 | F38: =IF(IF('House Vote Data'!G105>0.5,"D","R")=$E$8,1,0) -> 0 | G38: =SUM(C38:F38) -> 2 | H38: =AVERAGE(ABS('House Vote Data'!G102-$D$5),ABS('House Vote Data'!G103-$D$6),ABS('House Vote Data'!G104-$D$7),ABS('House Vote Data'!G105-$D$8)) -> 0.13950492 | I38: =IF(AND(G38=4,H38=MIN(J13:J101)),"<< MAGIC MUNICIPALITY","") | J38: =IF(G38=4,H38,"")
A39: Catasauqua | B39: Lehigh | C39: =IF(IF('House Vote Data'!G106>0.5,"D","R")=$E$5,1,0) -> 1 | D39: =IF(IF('House Vote Data'!G107>0.5,"D","R")=$E$6,1,0) -> 0 | E39: =IF(IF('House Vote Data'!G108>0.5,"D","R")=$E$7,1,0) -> 1 | F39: =IF(IF('House Vote Data'!G109>0.5,"D","R")=$E$8,1,0) -> 0 | G39: =SUM(C39:F39) -> 2 | H39: =AVERAGE(ABS('House Vote Data'!G106-$D$5),ABS('House Vote Data'!G107-$D$6),ABS('House Vote Data'!G108-$D$7),ABS('House Vote Data'!G109-$D$8)) -> 0.027287787 | I39: =IF(AND(G39=4,H39=MIN(J13:J101)),"<< MAGIC MUNICIPALITY","") | J39: =IF(G39=4,H39,"")
A40: Coopersburg | B40: Lehigh | C40: =IF(IF('House Vote Data'!G110>0.5,"D","R")=$E$5,1,0) -> 1 | D40: =IF(IF('House Vote Data'!G111>0.5,"D","R")=$E$6,1,0) -> 1 | E40: =IF(IF('House Vote Data'!G112>0.5,"D","R")=$E$7,1,0) -> 1 | F40: =IF(IF('House Vote Data'!G113>0.5,"D","R")=$E$8,1,0) -> 1 | G40: =SUM(C40:F40) -> 4 | H40: =AVERAGE(ABS('House Vote Data'!G110-$D$5),ABS('House Vote Data'!G111-$D$6),ABS('House Vote Data'!G112-$D$7),ABS('House Vote Data'!G113-$D$8)) -> 0.011299172 | I40: =IF(AND(G40=4,H40=MIN(J13:J101)),"<< MAGIC MUNICIPALITY","") | J40: =IF(G40=4,H40,"") -> 0.011299172
A41: Coplay | B41: Lehigh | C41: =IF(IF('House Vote Data'!G114>0.5,"D","R")=$E$5,1,0) -> 1 | D41: =IF(IF('House Vote Data'!G115>0.5,"D","R")=$E$6,1,0) -> 0 | E41: =IF(IF('House Vote Data'!G116>0.5,"D","R")=$E$7,1,0) -> 1 | F41: =IF(IF('House Vote Data'!G117>0.5,"D","R")=$E$8,1,0) -> 0 | G41: =SUM(C41:F41) -> 2 | H41: =AVERAGE(ABS('House Vote Data'!G114-$D$5),ABS('House Vote Data'!G115-$D$6),ABS('House Vote Data'!G116-$D$7),ABS('House Vote Data'!G117-$D$8)) -> 0.015575154 | I41: =IF(AND(G41=4,H41=MIN(J13:J101)),"<< MAGIC MUNICIPALITY","") | J41: =IF(G41=4,H41,"")
A42: Emmaus | B42: Lehigh | C42: =IF(IF('House Vote Data'!G118>0.5,"D","R")=$E$5,1,0) -> 1 | D42: =IF(IF('House Vote Data'!G119>0.5,"D","R")=$E$6,1,0) -> 0 | E42: =IF(IF('House Vote Data'!G120>0.5,"D","R")=$E$7,1,0) -> 1 | F42: =IF(IF('House Vote Data'!G121>0.5,"D","R")=$E$8,1,0) -> 0 | G42: =SUM(C42:F42) -> 2 | H42: =AVERAGE(ABS('House Vote Data'!G118-$D$5),ABS('House Vote Data'!G119-$D$6),ABS('House Vote Data'!G120-$D$7),ABS('House Vote Data'!G121-$D$8)) -> 0.033138299 | I42: =IF(AND(G42=4,H42=MIN(J13:J101)),"<< MAGIC MUNICIPALITY","") | J42: =IF(G42=4,H42,"")
