Workbook

Sheet Read Me
A1: PA-07 U.S. House Mail-Ballot Data — Combined Workbook
A4: Year | B4: Mail Requests | C4: Mail Returned | D4: Mail Recorded | E4: Dem. House Votes | F4: Rep. House Votes | G4: Dem. Candidate Mail Votes | H4: Rep. Candidate Mail Votes
A5: 2020 | B5: ='Voting County Summary'!D9 -> 193736 | C5: ='Voting County Summary'!F9 -> 172024 | D5: ='Voting County Summary'!G9 -> n.a. | E5: ='Voting County Summary'!K9 -> 195462 | F5: ='Voting County Summary'!M9 -> 181368 | G5: ='Voting County Summary'!R9 -> 122135 | H5: ='Voting County Summary'!S9 -> 44777
A6: 2022 | B6: ='Voting County Summary'!D16 -> 87296 | C6: ='Voting County Summary'!F16 -> 78087 | D6: ='Voting County Summary'!G16 -> n.a. | E6: ='Voting County Summary'!K16 -> 151364 | F6: ='Voting County Summary'!M16 -> 145527 | G6: ='Voting County Summary'!R16 -> 60736 | H6: ='Voting County Summary'!S16 -> 16382
A7: 2024 | B7: ='Voting County Summary'!D23 -> 142884 | C7: ='Voting County Summary'!F23 -> 128928 | D7: ='Voting County Summary'!G23 -> 127494 | E7: ='Voting County Summary'!K23 -> 199626 | F7: ='Voting County Summary'!M23 -> 203688 | G7: ='Voting County Summary'!R23 -> 80909 | H7: ='Voting County Summary'!S23 -> 44560

Sheet Voting County Summary
A1: PA-07 U.S. House — Voting County Summary
A2: All-method House vote totals are separate from candidate mail votes. Returned and recorded mail-ballot ratios are shown separately where available.
A4: Year | B4: County / PA-07 Portion | C4: Request Definition | D4: Mail Requests | E4: Ballots Issued | F4: Mail Returned | G4: Mail Recorded | H4: Returned / Requests | I4: Recorded / Requests | J4: Dem. Candidate | K4: Dem. Votes — All Methods | L4: Rep. Candidate | M4: Rep. Votes — All Methods | N4: Two-Party House Total | O4: Dem. Two-Party Share | P4: Returned / House Total | Q4: Recorded / House Total | R4: Dem. Candidate Mail Votes | S4: Rep. Candidate Mail Votes | T4: Two-Candidate Mail Total
A5: 2020 | B5: Carbon (2020 PA-09) | C5: All request records | D5: 10954 | E5: 10872 | F5: 9299 | G5: n.a. | H5: =F5/D5 -> 0.84891364 | J5: Gary Wegman | K5: 10768 | L5: Dan Meuser | M5: 22227 | N5: 32995 | O5: =IFERROR(K5/N5,"") -> 0.32635248 | P5: =IFERROR(F5/N5,"") -> 0.28183058 | R5: 4926 | S5: 2682 | T5: =IF(AND(ISNUMBER(R5),ISNUMBER(S5)),R5+S5,"") -> 7608
A6: 2020 | B6: Lehigh | C6: All request records | D6: 87328 | E6: 86807 | F6: 77097 | G6: n.a. | H6: =F6/D6 -> 0.88284399 | I6: =IF(ISNUMBER(G6),IFERROR(G6/D6,""),"") | J6: Susan Wild | K6: 96835 | L6: Lisa Scheller | M6: 85219 | N6: =K6+M6 -> 182054 | O6: =IFERROR(K6/N6,"") -> 0.53190262 | P6: =IFERROR(F6/N6,"") -> 0.42348424 | Q6: =IF(ISNUMBER(G6),IFERROR(G6/N6,""),"") | R6: 56508 | S6: 19111 | T6: =IF(AND(ISNUMBER(R6),ISNUMBER(S6)),R6+S6,"") -> 75619
A7: 2020 | B7: Monroe — PA-07 portion | C7: All request records | D7: 12694 | E7: 12663 | F7: 11745 | G7: n.a. | H7: =F7/D7 -> 0.92524027 | I7: =IF(ISNUMBER(G7),IFERROR(G7/D7,""),"") | J7: Susan Wild | K7: 15527 | L7: Lisa Scheller | M7: 12527 | N7: =K7+M7 -> 28054 | O7: =IFERROR(K7/N7,"") -> 0.55346831 | P7: =IFERROR(F7/N7,"") -> 0.41865688 | Q7: =IF(ISNUMBER(G7),IFERROR(G7/N7,""),"") | R7: 8454 | S7: 2715 | T7: =IF(AND(ISNUMBER(R7),ISNUMBER(S7)),R7+S7,"") -> 11169
A8: 2020 | B8: Northampton | C8: All request records | D8: 82760 | E8: 82750 | F8: 73883 | G8: n.a. | H8: =F8/D8 -> 0.89273804 | I8: =IF(ISNUMBER(G8),IFERROR(G8/D8,""),"") | J8: Susan Wild | K8: 83100 | L8: Lisa Scheller | M8: 83622 | N8: =K8+M8 -> 166722 | O8: =IFERROR(K8/N8,"") -> 0.49843452 | P8: =IFERROR(F8/N8,"") -> 0.44315087 | Q8: =IF(ISNUMBER(G8),IFERROR(G8/N8,""),"") | R8: 52247 | S8: 20269 | T8: =IF(AND(ISNUMBER(R8),ISNUMBER(S8)),R8+S8,"") -> 72516
A9: 2020 | B9: PA-07 TOTAL | C9: All request records | D9: 193736 | E9: 193092 | F9: 172024 | G9: n.a. | H9: =F9/D9 -> 0.88792997 | I9: =IF(ISNUMBER(G9),IFERROR(G9/D9,""),"") | J9: Susan Wild | K9: 195462 | L9: Lisa Scheller | M9: 181368 | N9: =K9+M9 -> 376830 | O9: =IFERROR(K9/N9,"") -> 0.51870074 | P9: =IFERROR(F9/N9,"") -> 0.45650293 | Q9: =IF(ISNUMBER(G9),IFERROR(G9/N9,""),"") | R9: 122135 | S9: 44777 | T9: =IF(AND(ISNUMBER(R9),ISNUMBER(S9)),R9+S9,"") -> 166912
A12: 2022 | B12: Carbon | C12: All request records | D12: 5313 | E12: 5284 | F12: 4813 | G12: n.a. | H12: =F12/D12 -> 0.90589121 | I12: =IF(ISNUMBER(G12),IFERROR(G12/D12,""),"") | J12: Susan Wild | K12: 9189 | L12: Lisa Scheller | M12: 16844 | N12: =K12+M12 -> 26033 | O12: =IFERROR(K12/N12,"") -> 0.35297507 | P12: =IFERROR(F12/N12,"") -> 0.18488073 | Q12: =IF(ISNUMBER(G12),IFERROR(G12/N12,""),"") | R12: 3296 | S12: 1449 | T12: =IF(AND(ISNUMBER(R12),ISNUMBER(S12)),R12+S12,"") -> 4745
A13: 2022 | B13: Lehigh | C13: All request records | D13: 40849 | E13: 40698 | F13: 35734 | G13: n.a. | H13: =F13/D13 -> 0.87478274 | I13: =IF(ISNUMBER(G13),IFERROR(G13/D13,""),"") | J13: Susan Wild | K13: 73756 | L13: Lisa Scheller | M13: 62343 | N13: =K13+M13 -> 136099 | O13: =IFERROR(K13/N13,"") -> 0.54192904 | P13: =IFERROR(F13/N13,"") -> 0.26255887 | Q13: =IF(ISNUMBER(G13),IFERROR(G13/N13,""),"") | R13: 28362 | S13: 6995 | T13: =IF(AND(ISNUMBER(R13),ISNUMBER(S13)),R13+S13,"") -> 35357
A14: 2022 | B14: Monroe — PA-07 portion | C14: All request records | D14: 1122 | E14: 1121 | F14: 1014 | G14: n.a. | H14: =F14/D14 -> 0.90374332 | I14: =IF(ISNUMBER(G14),IFERROR(G14/D14,""),"") | J14: Susan Wild | K14: 1762 | L14: Lisa Scheller | M14: 3540 | N14: =K14+M14 -> 5302 | O14: =IFERROR(K14/N14,"") -> 0.33232742 | P14: =IFERROR(F14/N14,"") -> 0.19124859 | Q14: =IF(ISNUMBER(G14),IFERROR(G14/N14,""),"") | R14: 726 | S14: 256 | T14: =IF(AND(ISNUMBER(R14),ISNUMBER(S14)),R14+S14,"") -> 982
A15: 2022 | B15: Northampton | C15: All request records | D15: 40012 | E15: 39922 | F15: 36526 | G15: n.a. | H15: =F15/D15 -> 0.91287614 | I15: =IF(ISNUMBER(G15),IFERROR(G15/D15,""),"") | J15: Susan Wild | K15: 66657 | L15: Lisa Scheller | M15: 62800 | N15: =K15+M15 -> 129457 | O15: =IFERROR(K15/N15,"") -> 0.51489684 | P15: =IFERROR(F15/N15,"") -> 0.28214774 | Q15: =IF(ISNUMBER(G15),IFERROR(G15/N15,""),"") | R15: 28352 | S15: 7682 | T15: =IF(AND(ISNUMBER(R15),ISNUMBER(S15)),R15+S15,"") -> 36034
A16: 2022 | B16: PA-07 TOTAL | C16: All request records | D16: 87296 | E16: 87025 | F16: 78087 | G16: n.a. | H16: =F16/D16 -> 0.89450834 | I16: =IF(ISNUMBER(G16),IFERROR(G16/D16,""),"") | J16: Susan Wild | K16: 151364 | L16: Lisa Scheller | M16: 145527 | N16: =K16+M16 -> 296891 | O16: =IFERROR(K16/N16,"") -> 0.50983021 | P16: =IFERROR(F16/N16,"") -> 0.26301572 | Q16: =IF(ISNUMBER(G16),IFERROR(G16/N16,""),"") | R16: 60736 | S16: 16382 | T16: =IF(AND(ISNUMBER(R16),ISNUMBER(S16)),R16+S16,"") -> 77118
A19: 2024 | B19: Carbon | C19: Approved requests | D19: 8705 | E19: 8641 | F19: 7349 | G19: 7313 | H19: =F19/D19 -> 0.84422746 | I19: =IF(ISNUMBER(G19),IFERROR(G19/D19,""),"") -> 0.8400919 | J19: Susan Wild | K19: 11614 | L19: Ryan Mackenzie | M19: 22813 | N19: =K19+M19 -> 34427 | O19: =IFERROR(K19/N19,"") -> 0.3373515 | P19: =IFERROR(F19/N19,"") -> 0.21346617 | Q19: =IF(ISNUMBER(G19),IFERROR(G19/N19,""),"") -> 0.21242048 | R19: 4022 | S19: 3130 | T19: =IF(AND(ISNUMBER(R19),ISNUMBER(S19)),R19+S19,"") -> 7152
A20: 2024 | B20: Lehigh | C20: Approved requests | D20: 65504 | E20: 65166 | F20: 58514 | G20: 57757 | H20: =F20/D20 -> 0.89328896 | I20: =IF(ISNUMBER(G20),IFERROR(G20/D20,""),"") -> 0.88173241 | J20: Susan Wild | K20: 98017 | L20: Ryan Mackenzie | M20: 89350 | N20: =K20+M20 -> 187367 | O20: =IFERROR(K20/N20,"") -> 0.52312841 | P20: =IFERROR(F20/N20,"") -> 0.31229619 | Q20: =IF(ISNUMBER(G20),IFERROR(G20/N20,""),"") -> 0.30825599 | R20: 37662 | S20: 19173 | T20: =IF(AND(ISNUMBER(R20),ISNUMBER(S20)),R20+S20,"") -> 56835
A21: 2024 | B21: Monroe — PA-07 portion | C21: Approved requests | D21: 2236 | E21: 2236 | F21: 2043 | G21: 2032 | H21: =F21/D21 -> 0.91368515 | I21: =IF(ISNUMBER(G21),IFERROR(G21/D21,""),"") -> 0.90876565 | J21: Susan Wild | K21: 2406 | L21: Ryan Mackenzie | M21: 5015 | N21: =K21+M21 -> 7421 | O21: =IFERROR(K21/N21,"") -> 0.32421507 | P21: =IFERROR(F21/N21,"") -> 0.27529982 | Q21: =IF(ISNUMBER(G21),IFERROR(G21/N21,""),"") -> 0.27381754 | R21: 1087 | S21: 908 | T21: =IF(AND(ISNUMBER(R21),ISNUMBER(S21)),R21+S21,"") -> 1995
A22: 2024 | B22: Northampton | C22: Approved requests | D22: 66439 | E22: 66098 | F22: 61022 | G22: 60392 | H22: =F22/D22 -> 0.91846656 | I22: =IF(ISNUMBER(G22),IFERROR(G22/D22,""),"") -> 0.90898418 | J22: Susan Wild | K22: 87589 | L22: Ryan Mackenzie | M22: 86510 | N22: =K22+M22 -> 174099 | O22: =IFERROR(K22/N22,"") -> 0.50309881 | P22: =IFERROR(F22/N22,"") -> 0.35050173 | Q22: =IF(ISNUMBER(G22),IFERROR(G22/N22,""),"") -> 0.3468831 | R22: 38138 | S22: 21349 | T22: =IF(AND(ISNUMBER(R22),ISNUMBER(S22)),R22+S22,"") -> 59487
A23: 2024 | B23: PA-07 TOTAL | C23: Approved requests | D23: 142884 | E23: 142141 | F23: 128928 | G23: 127494 | H23: =F23/D23 -> 0.90232636 | I23: =IF(ISNUMBER(G23),IFERROR(G23/D23,""),"") -> 0.89229025 | J23: Susan Wild | K23: 199626 | L23: Ryan Mackenzie | M23: 203688 | N23: =K23+M23 -> 403314 | O23: =IFERROR(K23/N23,"") -> 0.49496422 | P23: =IFERROR(F23/N23,"") -> 0.31967152 | Q23: =IF(ISNUMBER(G23),IFERROR(G23/N23,""),"") -> 0.31611598 | R23: 80909 | S23: 44560 | T23: =IF(AND(ISNUMBER(R23),ISNUMBER(S23)),R23+S23,"") -> 125469

Sheet Party Mail Ballots
A1: PA-07 Mail Ballots by Registered Party
A2: Registered party describes the voter registration in the request file. It does not identify which U.S. House candidate the voter selected.
A4: Year | B4: County / PA-07 Portion | C4: Registered Party | D4: Mail Requests | E4: Ballots Issued | F4: Mail Returned | G4: Mail Recorded | H4: Returned / Requests | I4: Recorded / Requests
A5: 2020 | B5: Carbon (2020 PA-09) | C5: Democratic | D5: 6241 | E5: 6209 | F5: 5589 | G5: n.a. | H5: 0.896
A6: 2020 | B6: Carbon (2020 PA-09) | C6: Republican | D6: 3445 | E6: 3421 | F6: 2696 | G6: n.a. | H6: 0.783
A7: 2020 | B7: Carbon (2020 PA-09) | C7: Other / No affiliation | D7: 1268 | E7: 1242 | F7: 1014 | G7: n.a. | H7: 0.8
A8: 2020 | B8: Lehigh | C8: Democratic | D8: 53589 | E8: 53299 | F8: 48487 | G8: n.a. | H8: 0.90479389
A9: 2020 | B9: Lehigh | C9: Republican | D9: 21386 | E9: 21243 | F9: 17863 | G9: n.a. | H9: 0.83526606
A10: 2020 | B10: Lehigh | C10: Other / No affiliation | D10: 12353 | E10: 12265 | F10: 10747 | G10: n.a. | H10: 0.8699911
A11: 2020 | B11: Monroe — PA-07 portion | C11: Democratic | D11: 8042 | E11: 8026 | F11: 7560 | G11: n.a. | H11: 0.94006466
A12: 2020 | B12: Monroe — PA-07 portion | C12: Republican | D12: 2766 | E12: 2758 | F12: 2487 | G12: n.a. | H12: 0.89913232
A13: 2020 | B13: Monroe — PA-07 portion | C13: Other / No affiliation | D13: 1886 | E13: 1879 | F13: 1698 | G13: n.a. | H13: 0.90031813
A14: 2020 | B14: Northampton | C14: Democratic | D14: 49522 | E14: 49518 | F14: 45426 | G14: n.a. | H14: 0.91728929
A15: 2020 | B15: Northampton | C15: Republican | D15: 20618 | E15: 20618 | F15: 17382 | G15: n.a. | H15: 0.84304976
A16: 2020 | B16: Northampton | C16: Other / No affiliation | D16: 12620 | E16: 12614 | F16: 11075 | G16: n.a. | H16: 0.87757528
A17: 2020 | B17: PA-07 TOTAL | C17: All parties | D17: 193736 | E17: 193092 | F17: 172024 | G17: n.a. | H17: 0.87216667
A19: Year | B19: County / PA-07 Portion | C19: Registered Party | D19: Mail Requests | E19: Ballots Issued | F19: Mail Returned | G19: Mail Recorded | H19: Returned / Requests | I19: Recorded / Requests
A20: 2022 | B20: Carbon | C20: Democratic | D20: 3393 | E20: 3374 | F20: 3089 | G20: n.a. | H20: 0.91040377
A21: 2022 | B21: Carbon | C21: Republican | D21: 1420 | E21: 1415 | F21: 1298 | G21: n.a. | H21: 0.91408451
A22: 2022 | B22: Carbon | C22: Other / No affiliation | D22: 500 | E22: 495 | F22: 426 | G22: n.a. | H22: 0.852
A23: 2022 | B23: Lehigh | C23: Democratic | D23: 27526 | E23: 27407 | F23: 24265 | G23: n.a. | H23: 0.88153019
A24: 2022 | B24: Lehigh | C24: Republican | D24: 8580 | E24: 8556 | F24: 7557 | G24: n.a. | H24: 0.88076923
A25: 2022 | B25: Lehigh | C25: Other / No affiliation | D25: 4743 | E25: 4735 | F25: 3912 | G25: n.a. | H25: 0.82479443
A26: 2022 | B26: Monroe — PA-07 portion | C26: Democratic | D26: 721 | E26: 720 | F26: 659 | G26: n.a. | H26: 0.91400832
A27: 2022 | B27: Monroe — PA-07 portion | C27: Republican | D27: 267 | E27: 267 | F27: 245 | G27: n.a. | H27: 0.917603
A28: 2022 | B28: Monroe — PA-07 portion | C28: Other / No affiliation | D28: 134 | E28: 134 | F28: 110 | G28: n.a. | H28: 0.82089552
A29: 2022 | B29: Northampton | C29: Democratic | D29: 26711 | E29: 26652 | F29: 24624 | G29: n.a. | H29: 0.9218674
A30: 2022 | B30: Northampton | C30: Republican | D30: 8212 | E30: 8191 | F30: 7451 | G30: n.a. | H30: 0.90733074
A31: 2022 | B31: Northampton | C31: Other / No affiliation | D31: 5089 | E31: 5079 | F31: 4451 | G31: n.a. | H31: 0.87463156
A32: 2022 | B32: PA-07 TOTAL | C32: All parties | D32: 87296 | E32: 87025 | F32: 78087 | G32: n.a. | H32: 0.89450834
A34: Year | B34: County / PA-07 Portion | C34: Registered Party | D34: Mail Requests | E34: Ballots Issued | F34: Mail Returned | G34: Mail Recorded | H34: Returned / Requests | I34: Recorded / Requests
A35: 2024 | B35: Carbon | C35: Democratic | D35: 4070 | E35: 4041 | F35: 3596 | G35: 3581 | H35: 0.88353808 | I35: 0.87985258
A36: 2024 | B36: Carbon | C36: Republican | D36: 3551 | E36: 3526 | F36: 2890 | G36: 2876 | H36: 0.81385525 | I36: 0.8099127
A37: 2024 | B37: Carbon | C37: Other / No affiliation | D37: 1084 | E37: 1074 | F37: 863 | G37: 856 | H37: 0.79612546 | I37: 0.7896679
A38: 2024 | B38: Lehigh | C38: Democratic | D38: 35142 | E38: 34938 | F38: 31806 | G38: 31432 | H38: 0.90507086 | I38: 0.89442832
A39: 2024 | B39: Lehigh | C39: Republican | D39: 20668 | E39: 20579 | F39: 18467 | G39: 18202 | H39: 0.89350687 | I39: 0.88068512
A40: 2024 | B40: Lehigh | C40: Other / No affiliation | D40: 9694 | E40: 9649 | F40: 8241 | G40: 8123 | H40: 0.85011347 | I40: 0.83794099
A41: 2024 | B41: Monroe — PA-07 portion | C41: Democratic | D41: 1012 | E41: 1012 | F41: 941 | G41: 939 | H41: 0.9298419 | I41: 0.92786561
A42: 2024 | B42: Monroe — PA-07 portion | C42: Republican | D42: 898 | E42: 898 | F42: 814 | G42: 809 | H42: 0.9064588 | I42: 0.90089087
A43: 2024 | B43: Monroe — PA-07 portion | C43: Other / No affiliation | D43: 326 | E43: 326 | F43: 288 | G43: 284 | H43: 0.88343558 | I43: 0.87116564
...

Sheet Candidate Mail Votes
A1: PA-07 U.S. House — Candidate Mail Votes
A2: These are U.S. House candidate votes reported in county mail categories. They are not ballot requests, return counts, or party-registration counts.
A4: Year | B4: County / PA-07 Portion | C4: Democratic candidate | D4: Democratic Mail Votes | E4: Republican Candidate | F4: Republican Mail Votes | G4: Two-Candidate Mail Total | H4: Status / Scope
A5: 2020 | B5: Carbon (2020 PA-09) | C5: Gary Wegman | D5: 4926 | E5: Dan Meuser | F5: 2682 | G5: 7608
A6: 2020 | B6: Lehigh | C6: Susan Wild | D6: 56508 | E6: Lisa Scheller | F6: 18935 | G6: 75247 | H6: PA official returns: Mail
A7: 2020 | B7: Monroe — PA-07 portion | C7: Susan Wild | D7: 8454 | E7: Lisa Scheller | F7: 2738 | G7: 11258 | H7: PA official returns: Mail
A8: 2020 | B8: Northampton | C8: Susan Wild | D8: 52247 | E8: Lisa Scheller | F8: 20269 | G8: 72516 | H8: PA official returns: Mail
A9: 2020 | B9: PA-07 TOTAL | C9: Susan Wild/Gary Wegman | D9: 117079 | E9: Lisa Scheller | F9: 41942 | G9: 159021 | H9: PA official returns: Mail total
A11: 2022 | B11: Carbon | C11: Susan Wild | D11: 3296 | E11: Lisa Scheller | F11: 1449 | G11: 4745 | H11: County report: Mail-In
A12: 2022 | B12: Lehigh | C12: Susan Wild | D12: 28362 | E12: Lisa Scheller | F12: 6995 | G12: 35357 | H12: Official CSV: Mail Ballots Votes
A13: 2022 | B13: Monroe — PA-07 portion | C13: Susan Wild | D13: 726 | E13: Lisa Scheller | F13: 256 | G13: 982 | H13: Mail-In/Absentee; PA-07 portion only
A14: 2022 | B14: Northampton | C14: Susan Wild | D14: 28352 | E14: Lisa Scheller | F14: 7682 | G14: 36034 | H14: Official report: Mail Votes
A15: 2022 | B15: PA-07 TOTAL | C15: Susan Wild | D15: 60736 | E15: Lisa Scheller | F15: 16382 | G15: 77118 | H15: Two named candidates; excludes write-ins
A17: 2024 | B17: Carbon | C17: Susan Wild | D17: 4022 | E17: Ryan Mackenzie | F17: 3130 | G17: 7152 | H17: County report: Mail-In
A18: 2024 | B18: Lehigh | C18: Susan Wild | D18: 37662 | E18: Ryan Mackenzie | F18: 19173 | G18: 56835 | H18: Official CSV: Mail Ballots Votes
A19: 2024 | B19: Monroe — PA-07 portion | C19: Susan Wild | D19: 1087 | E19: Ryan Mackenzie | F19: 908 | G19: 1995 | H19: Mail-In/Absentee; PA-07 portion only
... A21: 2024 | B21: PA-07 TOTAL | C21: Susan Wild | D21: 80909 | E21: Ryan Mackenzie | F21: 44560 | G21: 125469 | H21: Two named candidates; excludes write-ins

Sheet Notes for myself
A1: The Two Workbooks
A3: Area | B3: Workbook 1 | C3: Workbook 2 | D3: Combined Treatment
A4: County request / issued / returned data | B4: Yes | C4: Yes | D4: Kept once in Master County Summary.
A5: 2024 recorded-ballot counts | B5: Yes | C5: Yes | D5: Kept once; separate Recorded / Requests and Recorded / House ratios.
A6: All-method U.S. House candidate totals | B6: Yes | C6: Yes | D6: Kept once in Master County Summary.
A7: Party-level mail request / return breakdown | B7: No | C7: Yes | D7: Preserved in Party Mail Ballots.
A8: Actual U.S. House candidate mail votes | B8: No | C8: Yes | D8: Preserved in Candidate Mail Votes and linked into Master County Summary.
A9: Source codes and county report links | B9: Limited | C9: Yes | D9: Preserved in Sources & Notes.
A10: Year-by-year simplified presentation | B10: Yes | C10: No | D10: Replaced by one filterable Master County Summary plus yearly totals on Read Me.
A11: 2024 mail-share definition | B11: Returned ÷ House total | C11: Recorded ÷ House total | D11: Both are retained as separate columns.
A12: 2020 district candidate mail total | B12: Not included | C12: Not finalized | D12: Preserved as not finalized; county figures remain visible.
A14: Automated overlap check
A15: Shared county rows checked | B15: 11
A16: Requests/issued/returned/recorded + all-method House totals matched | B16: Yes
