Workbook

Sheet Contents
A1: PA-07 Forecast Workbook v2 — Rebuilt on Complete Voter File Data
A2: Companion file: PA07_Data.xlsx holds the raw source tables (House Vote Data, Carbon Estimates, Combined District Data, Model Inputs, Carbon 2026 Registration) on their own for easy review. This workbook keeps its own copies of those same sheets so every formula here still works standalone -- edit data in one place only if you want the two to stay in sync.
A4: Sheet | B4: What it does | C4: What it tells us
A5: House Vote Data (Actual) | B5: Real House + Governor vote counts for the 63 Lehigh+Northampton municipalities, 2018-2024 (4 cycles, no invalid 2016). | C5: The verified core of the dataset.
A6: Carbon County Estimates | B6: Estimated House vote counts for Carbon's 23 municipalities, derived from registration lean calibrated against Lehigh+Northampton's actual registration-to-vote relationship. | C6: Fills in the single biggest geography gap from the prior workbook, with a documented, validated method.
A7: Carbon 2026 Registration | B7: Raw Aug-2026 registration snapshot and historical ballot counts for Carbon, used to build the 2026 forecast. | C7: Supporting data for the forecast sheet.
A8: Combined District Data | B8: Merges actual (63 towns) + estimated (23 Carbon towns) into one 86-municipality table, flagged by source. | C8: The single source every downstream analysis sheet reads from.
A9: Geography Validation | B9: Compares the combined actual+estimated district total to the true PA-07 totals (from the prior external reference) for every year. | C9: CRITICAL: shows the Carbon estimate closes the gap from 20,000-42,000 missing votes/year down to just a few thousand (Monroe's residual).
A10: Predictability Ranking | B10: Classifies all 86 municipalities Easy/Medium/Hard to predict. | C10: Where more data/effort would change the forecast, now across the full reportable district.
A11: Kiley - 2026 Vote Forecast | B11: Trend-based forecast for Lehigh+Northampton + calibration-based forecast for Carbon, summed to a district total. | C11: MAJOR UPDATE: district flips to 49.4% Dem / Republican win, vs. the old 54.7% Dem estimate -- Carbon's inclusion changes the outcome.
A12: Magic Municipality | B12: Bellwether search across all 86 municipalities. | C12: Coplay is now the closest-tracking bellwether (updated from Catasauqua in the prior version).
A13: Beta Coefficients | B13: Each municipality's beta and R-squared against the self-computed combined-district index. | C13: No longer needs an external 'true' reference -- the district index is now built from data this workbook owns.
A14: Governor-House Correlation | B14: Correlates Governor vs. House Dem Share, Lehigh+Northampton, 2018 and 2022. | C14: r = 0.99 -- consistent with the prior finding; still no ticket-splitting to speak of.
A15: 2024 Backtest | B15: Reruns the trend method on 2018-2022 only, checks against real 2024, compares to a naive 'assume 2022 repeats' baseline. | C15: UPDATED FINDING: with 2016 no longer contaminating the trend, the trend model now performs about even with the naive baseline (2.17 vs 2.25 pts MAE), not clearly worse as before.
... A22: Model Comparison | B22: All three 2026 forecasts (trend, beta-adjusted, regression) side by side with their backtested accuracy. | C22: The real takeaway: methods span a 2.4-point range and split 2-1 on the winner -- this is a genuine toss-up, not a confident call.

Sheet House Vote Data (Actual)
A1: Year | B1: Municipality | C1: County | D1: Dem Votes | E1: Rep Votes | F1: Other Votes | G1: Total Votes | H1: Dem Share % | I1: Governor Dem Votes | J1: Governor Rep Votes | K1: Governor Total Votes | L1: Governor Dem Share | M1: Presidential Year (dummy)
A2: 2018 | B2: Alburtis | C2: Lehigh | D2: 454 | E2: 406 | F2: 36 | G2: =D2+E2+F2 -> 896 | H2: =D2/G2 -> 0.50669643 | I2: 519 | J2: 356 | K2: =I2+J2 -> 875 | L2: =IF(K2=0,"",I2/K2) -> 0.59314286 | M2: =IF(OR(A2=2020,A2=2024),1,0) -> 0
A3: 2020 | B3: Alburtis | C3: Lehigh | D3: 644 | E3: 735 | F3: 0 | G3: =D3+E3+F3 -> 1379 | H3: =D3/G3 -> 0.46700508 | I3: 0 | J3: 0 | K3: =I3+J3 -> 0 | L3: =IF(K3=0,"",I3/K3) | M3: =IF(OR(A3=2020,A3=2024),1,0) -> 1
A4: 2022 | B4: Alburtis | C4: Lehigh | D4: 494 | E4: 519 | F4: 0 | G4: =D4+E4+F4 -> 1013 | H4: =D4/G4 -> 0.48766041 | I4: 539 | J4: 447 | K4: =I4+J4 -> 986 | L4: =IF(K4=0,"",I4/K4) -> 0.54665314 | M4: =IF(OR(A4=2020,A4=2024),1,0) -> 0
A5: 2024 | B5: Alburtis | C5: Lehigh | D5: 601 | E5: 766 | F5: 0 | G5: =D5+E5+F5 -> 1367 | H5: =D5/G5 -> 0.43964887 | I5: 0 | J5: 0 | K5: =I5+J5 -> 0 | L5: =IF(K5=0,"",I5/K5) | M5: =IF(OR(A5=2020,A5=2024),1,0) -> 1
A6: 2018 | B6: Allentown | C6: Lehigh | D6: 19919 | E6: 7341 | F6: 773 | G6: =D6+E6+F6 -> 28033 | H6: =D6/G6 -> 0.71055542 | I6: 21066 | J6: 6512 | K6: =I6+J6 -> 27578 | L6: =IF(K6=0,"",I6/K6) -> 0.76386975 | M6: =IF(OR(A6=2020,A6=2024),1,0) -> 0
A7: 2020 | B7: Allentown | C7: Lehigh | D7: 27952 | E7: 12938 | F7: 0 | G7: =D7+E7+F7 -> 40890 | H7: =D7/G7 -> 0.68359012 | I7: 0 | J7: 0 | K7: =I7+J7 -> 0 | L7: =IF(K7=0,"",I7/K7) | M7: =IF(OR(A7=2020,A7=2024),1,0) -> 1
A8: 2022 | B8: Allentown | C8: Lehigh | D8: 16965 | E8: 7936 | F8: 0 | G8: =D8+E8+F8 -> 24901 | H8: =D8/G8 -> 0.68129794 | I8: 17605 | J8: 6760 | K8: =I8+J8 -> 24365 | L8: =IF(K8=0,"",I8/K8) -> 0.72255284 | M8: =IF(OR(A8=2020,A8=2024),1,0) -> 0
A9: 2024 | B9: Allentown | C9: Lehigh | D9: 26568 | E9: 14583 | F9: 0 | G9: =D9+E9+F9 -> 41151 | H9: =D9/G9 -> 0.64562222 | I9: 0 | J9: 0 | K9: =I9+J9 -> 0 | L9: =IF(K9=0,"",I9/K9) | M9: =IF(OR(A9=2020,A9=2024),1,0) -> 1
A10: 2018 | B10: Bethlehem | C10: Lehigh | D10: 4700 | E10: 2300 | F10: 378 | G10: =D10+E10+F10 -> 7378 | H10: =D10/G10 -> 0.63702901 | I10: 5072 | J10: 2132 | K10: =I10+J10 -> 7204 | L10: =IF(K10=0,"",I10/K10) -> 0.7040533 | M10: =IF(OR(A10=2020,A10=2024),1,0) -> 0
A11: 2020 | B11: Bethlehem | C11: Lehigh | D11: 6475 | E11: 3784 | F11: 0 | G11: =D11+E11+F11 -> 10259 | H11: =D11/G11 -> 0.63115313 | I11: 0 | J11: 0 | K11: =I11+J11 -> 0 | L11: =IF(K11=0,"",I11/K11) | M11: =IF(OR(A11=2020,A11=2024),1,0) -> 1
A12: 2022 | B12: Bethlehem | C12: Lehigh | D12: 5186 | E12: 2705 | F12: 0 | G12: =D12+E12+F12 -> 7891 | H12: =D12/G12 -> 0.65720441 | I12: 5445 | J12: 2279 | K12: =I12+J12 -> 7724 | L12: =IF(K12=0,"",I12/K12) -> 0.70494562 | M12: =IF(OR(A12=2020,A12=2024),1,0) -> 0
A13: 2024 | B13: Bethlehem | C13: Lehigh | D13: 6612 | E13: 3834 | F13: 0 | G13: =D13+E13+F13 -> 10446 | H13: =D13/G13 -> 0.63296956 | I13: 0 | J13: 0 | K13: =I13+J13 -> 0 | L13: =IF(K13=0,"",I13/K13) | M13: =IF(OR(A13=2020,A13=2024),1,0) -> 1
... A253: 2024 | B253: Wind Gap | C253: Northampton | D253: 634 | E253: 856 | F253: 0 | G253: =D253+E253+F253 -> 1490 | H253: =D253/G253 -> 0.42550336 | I253: 0 | J253: 0 | K253: =I253+J253 -> 0 | L253: =IF(K253=0,"",I253/K253) | M253: =IF(OR(A253=2020,A253=2024),1,0) -> 1

Sheet Carbon County Estimates
A1: Carbon County has no directly reported House vote counts in the source file. These figures are ESTIMATED from each municipality's voter-registration lean (Reg D minus Reg R), calibrated against the actual registration-to-vote relationship observed in Lehigh+Northampton municipalities each year (see Geography Validation sheet for the calibration and its accuracy).
A3: Year | B3: Municipality | C3: County | D3: Reg D-R (registration lean) | E3: Estimated Dem Votes | F3: Estimated Rep Votes | G3: Estimated Total Votes | H3: Estimated Dem Share %
A4: 2018 | B4: Banks Township | C4: Carbon | D4: 0.0544 | E4: 157 | F4: 133 | G4: =E4+F4 -> 290 | H4: =E4/G4 -> 0.54137931
A5: 2020 | B5: Banks Township | C5: Carbon | D5: 0.0544 | E5: 206 | F5: 192 | G5: =E5+F5 -> 398 | H5: =E5/G5 -> 0.51758794
A6: 2022 | B6: Banks Township | C6: Carbon | D6: 0.0544 | E6: 181 | F6: 155 | G6: =E6+F6 -> 336 | H6: =E6/G6 -> 0.53869048
A7: 2024 | B7: Banks Township | C7: Carbon | D7: 0.0544 | E7: 235 | F7: 220 | G7: =E7+F7 -> 455 | H7: =E7/G7 -> 0.51648352
A8: 2018 | B8: Beaver Meadows Borough | C8: Carbon | D8: -0.2367 | E8: 84 | F8: 131 | G8: =E8+F8 -> 215 | H8: =E8/G8 -> 0.39069767
A9: 2020 | B9: Beaver Meadows Borough | C9: Carbon | D9: -0.2367 | E9: 116 | F9: 203 | G9: =E9+F9 -> 319 | H9: =E9/G9 -> 0.36363636
A10: 2022 | B10: Beaver Meadows Borough | C10: Carbon | D10: -0.2367 | E10: 109 | F10: 168 | G10: =E10+F10 -> 277 | H10: =E10/G10 -> 0.39350181
A11: 2024 | B11: Beaver Meadows Borough | C11: Carbon | D11: -0.2367 | E11: 152 | F11: 255 | G11: =E11+F11 -> 407 | H11: =E11/G11 -> 0.37346437
A12: 2018 | B12: Bowmanstown Borough | C12: Carbon | D12: -0.2708 | E12: 90 | F12: 152 | G12: =E12+F12 -> 242 | H12: =E12/G12 -> 0.37190083
A13: 2020 | B13: Bowmanstown Borough | C13: Carbon | D13: -0.2708 | E13: 122 | F13: 231 | G13: =E13+F13 -> 353 | H13: =E13/G13 -> 0.34560907
A14: 2022 | B14: Bowmanstown Borough | C14: Carbon | D14: -0.2708 | E14: 120 | F14: 200 | G14: =E14+F14 -> 320 | H14: =E14/G14 -> 0.375
A15: 2024 | B15: Bowmanstown Borough | C15: Carbon | D15: -0.2708 | E15: 158 | F15: 285 | G15: =E15+F15 -> 443 | H15: =E15/G15 -> 0.35665914
... A95: 2024 | B95: Weissport Borough | C95: Carbon | D95: -0.177 | E95: 64 | F95: 95 | G95: =E95+F95 -> 159 | H95: =E95/G95 -> 0.40251572

Sheet Geography Validation
A1: Closing the Geography Gap: Carbon County Estimate vs. True Totals
A2: Method: for each year, fit a simple linear model (actual Dem vote share ~ registration D-minus-R) using the 63 Lehigh+Northampton municipalities where we have BOTH real votes and registration data. Apply that same model to Carbon County's registration lean to estimate its vote share, since Carbon's actual House vote counts aren't in the source file. Monroe County's 3 townships remain fully unaccounted for (no votes or registration data available anywhere in the source) -- the small residual gap below is entirely Monroe.
A4: Year | B4: Calibration (slope, intercept, R²) | C4: Estimated District Total (Actual LN + Estimated Carbon) | D4: True District Total | E4: Remaining Gap (Monroe only) | F4: Estimated vs True Dem Share
A5: 2018 | B5: slope=0.5165, intercept=0.5124, R²=0.937 | C5: =SUMIF('House Vote Data (Actual)'!A2:A253,A5,'House Vote Data (Actual)'!D2:D253)+SUMIF('House Vote Data (Actual)'!A2:A253,A5,'House Vote Data (Actual)'!E2:E253)+SUMIF('House Vote Data (Actual)'!A2:A253,A5,'House Vote Data (Actual)'!F2:F253)+SUMIF('Carbon County Estimates'!A4:A95,A5,'Carbon County Estimates'!E4:E95)+SUMIF('Carbon County Estimates'!A4:A95,A5,'Carbon County Estimates'!F4:F95) -> 260862 | D5: 263261 | E5: =D5-C5 -> 2399 | F5: =(SUMIF('House Vote Data (Actual)'!A2:A253,A5,'House Vote Data (Actual)'!D2:D253)+SUMIF('Carbon County Estimates'!A4:A95,A5,'Carbon County Estimates'!E4:E95))/C5 -> 0.5228205
A6: 2020 | B6: slope=0.5286, intercept=0.4879, R²=0.936 | C6: =SUMIF('House Vote Data (Actual)'!A2:A253,A6,'House Vote Data (Actual)'!D2:D253)+SUMIF('House Vote Data (Actual)'!A2:A253,A6,'House Vote Data (Actual)'!E2:E253)+SUMIF('House Vote Data (Actual)'!A2:A253,A6,'House Vote Data (Actual)'!F2:F253)+SUMIF('Carbon County Estimates'!A4:A95,A6,'Carbon County Estimates'!E4:E95)+SUMIF('Carbon County Estimates'!A4:A95,A6,'Carbon County Estimates'!F4:F95) -> 376092 | D6: 376882 | E6: =D6-C6 -> 790 | F6: =(SUMIF('House Vote Data (Actual)'!A2:A253,A6,'House Vote Data (Actual)'!D2:D253)+SUMIF('Carbon County Estimates'!A4:A95,A6,'Carbon County Estimates'!E4:E95))/C6 -> 0.50536039
A7: 2022 | B7: slope=0.4989, intercept=0.5112, R²=0.934 | C7: =SUMIF('House Vote Data (Actual)'!A2:A253,A7,'House Vote Data (Actual)'!D2:D253)+SUMIF('House Vote Data (Actual)'!A2:A253,A7,'House Vote Data (Actual)'!E2:E253)+SUMIF('House Vote Data (Actual)'!A2:A253,A7,'House Vote Data (Actual)'!F2:F253)+SUMIF('Carbon County Estimates'!A4:A95,A7,'Carbon County Estimates'!E4:E95)+SUMIF('Carbon County Estimates'!A4:A95,A7,'Carbon County Estimates'!F4:F95) -> 289186 | D7: 296891 | E7: =D7-C7 -> 7705 | F7: =(SUMIF('House Vote Data (Actual)'!A2:A253,A7,'House Vote Data (Actual)'!D2:D253)+SUMIF('Carbon County Estimates'!A4:A95,A7,'Carbon County Estimates'!E4:E95))/C7 -> 0.51824086
A8: 2024 | B8: slope=0.4899, intercept=0.489, R²=0.939 | C8: =SUMIF('House Vote Data (Actual)'!A2:A253,A8,'House Vote Data (Actual)'!D2:D253)+SUMIF('House Vote Data (Actual)'!A2:A253,A8,'House Vote Data (Actual)'!E2:E253)+SUMIF('House Vote Data (Actual)'!A2:A253,A8,'House Vote Data (Actual)'!F2:F253)+SUMIF('Carbon County Estimates'!A4:A95,A8,'Carbon County Estimates'!E4:E95)+SUMIF('Carbon County Estimates'!A4:A95,A8,'Carbon County Estimates'!F4:F95) -> 394740 | D8: 403314 | E8: =D8-C8 -> 8574 | F8: =(SUMIF('House Vote Data (Actual)'!A2:A253,A8,'House Vote Data (Actual)'!D2:D253)+SUMIF('Carbon County Estimates'!A4:A95,A8,'Carbon County Estimates'!E4:E95))/C8 -> 0.50230785
A10: Compare: before this estimate, our old Lehigh+Northampton-only totals were missing 20,000-42,000 votes per year (see prior 'Geography Gap Check' analysis). The registration-based Carbon estimate closes that down to just Monroe's residual (a few thousand votes from only 3 small townships) -- a real, validated improvement in district coverage.

Sheet Combined District Data
A1: Merges actual Lehigh+Northampton votes with estimated Carbon County votes into one 86-municipality table (all Combined District analyses -- Predictability, Magic Municipality, Beta, Forecast -- read from here). Monroe County's 3 townships are not included (no data available). 'Source' flags whether each row is Actual or Estimated.
A3: Year | B3: Municipality | C3: County | D3: Source | E3: Dem Votes | F3: Rep Votes | G3: Total Votes | H3: Dem Share %
A4: 2018 | B4: Alburtis | C4: Lehigh | D4: Actual | E4: ='House Vote Data (Actual)'!D2 -> 454 | F4: ='House Vote Data (Actual)'!E2 -> 406 | G4: ='House Vote Data (Actual)'!G2 -> 896 | H4: =E4/G4 -> 0.50669643
A5: 2020 | B5: Alburtis | C5: Lehigh | D5: Actual | E5: ='House Vote Data (Actual)'!D3 -> 644 | F5: ='House Vote Data (Actual)'!E3 -> 735 | G5: ='House Vote Data (Actual)'!G3 -> 1379 | H5: =E5/G5 -> 0.46700508
A6: 2022 | B6: Alburtis | C6: Lehigh | D6: Actual | E6: ='House Vote Data (Actual)'!D4 -> 494 | F6: ='House Vote Data (Actual)'!E4 -> 519 | G6: ='House Vote Data (Actual)'!G4 -> 1013 | H6: =E6/G6 -> 0.48766041
A7: 2024 | B7: Alburtis | C7: Lehigh | D7: Actual | E7: ='House Vote Data (Actual)'!D5 -> 601 | F7: ='House Vote Data (Actual)'!E5 -> 766 | G7: ='House Vote Data (Actual)'!G5 -> 1367 | H7: =E7/G7 -> 0.43964887
A8: 2018 | B8: Allentown | C8: Lehigh | D8: Actual | E8: ='House Vote Data (Actual)'!D6 -> 19919 | F8: ='House Vote Data (Actual)'!E6 -> 7341 | G8: ='House Vote Data (Actual)'!G6 -> 28033 | H8: =E8/G8 -> 0.71055542
A9: 2020 | B9: Allentown | C9: Lehigh | D9: Actual | E9: ='House Vote Data (Actual)'!D7 -> 27952 | F9: ='House Vote Data (Actual)'!E7 -> 12938 | G9: ='House Vote Data (Actual)'!G7 -> 40890 | H9: =E9/G9 -> 0.68359012
A10: 2022 | B10: Allentown | C10: Lehigh | D10: Actual | E10: ='House Vote Data (Actual)'!D8 -> 16965 | F10: ='House Vote Data (Actual)'!E8 -> 7936 | G10: ='House Vote Data (Actual)'!G8 -> 24901 | H10: =E10/G10 -> 0.68129794
A11: 2024 | B11: Allentown | C11: Lehigh | D11: Actual | E11: ='House Vote Data (Actual)'!D9 -> 26568 | F11: ='House Vote Data (Actual)'!E9 -> 14583 | G11: ='House Vote Data (Actual)'!G9 -> 41151 | H11: =E11/G11 -> 0.64562222
A12: 2018 | B12: Bethlehem | C12: Lehigh | D12: Actual | E12: ='House Vote Data (Actual)'!D10 -> 4700 | F12: ='House Vote Data (Actual)'!E10 -> 2300 | G12: ='House Vote Data (Actual)'!G10 -> 7378 | H12: =E12/G12 -> 0.63702901
A13: 2020 | B13: Bethlehem | C13: Lehigh | D13: Actual | E13: ='House Vote Data (Actual)'!D11 -> 6475 | F13: ='House Vote Data (Actual)'!E11 -> 3784 | G13: ='House Vote Data (Actual)'!G11 -> 10259 | H13: =E13/G13 -> 0.63115313
A14: 2022 | B14: Bethlehem | C14: Lehigh | D14: Actual | E14: ='House Vote Data (Actual)'!D12 -> 5186 | F14: ='House Vote Data (Actual)'!E12 -> 2705 | G14: ='House Vote Data (Actual)'!G12 -> 7891 | H14: =E14/G14 -> 0.65720441
A15: 2024 | B15: Bethlehem | C15: Lehigh | D15: Actual | E15: ='House Vote Data (Actual)'!D13 -> 6612 | F15: ='House Vote Data (Actual)'!E13 -> 3834 | G15: ='House Vote Data (Actual)'!G13 -> 10446 | H15: =E15/G15 -> 0.63296956
... A255: 2024 | B255: Wind Gap | C255: Northampton | D255: Actual | E255: ='House Vote Data (Actual)'!D253 -> 634 | F255: ='House Vote Data (Actual)'!E253 -> 856 | G255: ='House Vote Data (Actual)'!G253 -> 1490 | H255: =E255/G255 -> 0.42550336
A256: 2018 | B256: Banks Township | C256: Carbon | D256: Estimated | E256: ='Carbon County Estimates'!E4 -> 157 | F256: ='Carbon County Estimates'!F4 -> 133 | G256: ='Carbon County Estimates'!G4 -> 290 | H256: =E256/G256 -> 0.54137931
A257: 2020 | B257: Banks Township | C257: Carbon | D257: Estimated | E257: ='Carbon County Estimates'!E5 -> 206 | F257: ='Carbon County Estimates'!F5 -> 192 | G257: ='Carbon County Estimates'!G5 -> 398 | H257: =E257/G257 -> 0.51758794
A258: 2022 | B258: Banks Township | C258: Carbon | D258: Estimated | E258: ='Carbon County Estimates'!E6 -> 181 | F258: ='Carbon County Estimates'!F6 -> 155 | G258: ='Carbon County Estimates'!G6 -> 336 | H258: =E258/G258 -> 0.53869048
A259: 2024 | B259: Banks Township | C259: Carbon | D259: Estimated | E259: ='Carbon County Estimates'!E7 -> 235 | F259: ='Carbon County Estimates'!F7 -> 220 | G259: ='Carbon County Estimates'!G7 -> 455 | H259: =E259/G259 -> 0.51648352
A260: 2018 | B260: Beaver Meadows Borough | C260: Carbon | D260: Estimated | E260: ='Carbon County Estimates'!E8 -> 84 | F260: ='Carbon County Estimates'!F8 -> 131 | G260: ='Carbon County Estimates'!G8 -> 215 | H260: =E260/G260 -> 0.39069767
A261: 2020 | B261: Beaver Meadows Borough | C261: Carbon | D261: Estimated | E261: ='Carbon County Estimates'!E9 -> 116 | F261: ='Carbon County Estimates'!F9 -> 203 | G261: ='Carbon County Estimates'!G9 -> 319 | H261: =E261/G261 -> 0.36363636
A262: 2022 | B262: Beaver Meadows Borough | C262: Carbon | D262: Estimated | E262: ='Carbon County Estimates'!E10 -> 109 | F262: ='Carbon County Estimates'!F10 -> 168 | G262: ='Carbon County Estimates'!G10 -> 277 | H262: =E262/G262 -> 0.39350181
A263: 2024 | B263: Beaver Meadows Borough | C263: Carbon | D263: Estimated | E263: ='Carbon County Estimates'!E11 -> 152 | F263: ='Carbon County Estimates'!F11 -> 255 | G263: ='Carbon County Estimates'!G11 -> 407 | H263: =E263/G263 -> 0.37346437
A264: 2018 | B264: Bowmanstown Borough | C264: Carbon | D264: Estimated | E264: ='Carbon County Estimates'!E12 -> 90 | F264: ='Carbon County Estimates'!F12 -> 152 | G264: ='Carbon County Estimates'!G12 -> 242 | H264: =E264/G264 -> 0.37190083
A265: 2020 | B265: Bowmanstown Borough | C265: Carbon | D265: Estimated | E265: ='Carbon County Estimates'!E13 -> 122 | F265: ='Carbon County Estimates'!F13 -> 231 | G265: ='Carbon County Estimates'!G13 -> 353 | H265: =E265/G265 -> 0.34560907
A266: 2022 | B266: Bowmanstown Borough | C266: Carbon | D266: Estimated | E266: ='Carbon County Estimates'!E14 -> 120 | F266: ='Carbon County Estimates'!F14 -> 200 | G266: ='Carbon County Estimates'!G14 -> 320 | H266: =E266/G266 -> 0.375
A267: 2024 | B267: Bowmanstown Borough | C267: Carbon | D267: Estimated | E267: ='Carbon County Estimates'!E15 -> 158 | F267: ='Carbon County Estimates'!F15 -> 285 | G267: ='Carbon County Estimates'!G15 -> 443 | H267: =E267/G267 -> 0.35665914
... A347: 2024 | B347: Weissport Borough | C347: Carbon | D347: Estimated | E347: ='Carbon County Estimates'!E95 -> 64 | F347: ='Carbon County Estimates'!F95 -> 95 | G347: ='Carbon County Estimates'!G95 -> 159 | H347: =E347/G347 -> 0.40251572

Sheet Predictability Ranking
A1: Same methodology as before (margin from 50%, cycle-to-cycle volatility, party flips), now run on all 86 municipalities -- 63 with actual votes, 23 Carbon estimates. Estimated rows are flagged so you can weight confidence accordingly.
A3: Municipality | B3: County | C3: Source | D3: Avg Dem Share | E3: Avg Margin from 50pt | F3: Stdev Dem Share | G3: Party Flips | H3: Predictability
A4: Alburtis | B4: Lehigh | C4: Actual | D4: =AVERAGE('Combined District Data'!H4:H7) -> 0.4752527 | E4: =AVERAGE(ABS('Combined District Data'!H4-0.5),ABS('Combined District Data'!H5-0.5),ABS('Combined District Data'!H6-0.5),ABS('Combined District Data'!H7-0.5)) -> 0.028095518 | F4: =STDEV('Combined District Data'!H4:H7) -> 0.028742047 | G4: =IF(('Combined District Data'!H4>0.5)<>('Combined District Data'!H5>0.5),1,0)+IF(('Combined District Data'!H5>0.5)<>('Combined District Data'!H6>0.5),1,0)+IF(('Combined District Data'!H6>0.5)<>('Combined District Data'!H7>0.5),1,0) -> 1 | H4: =IF(OR(G4>=1,E4<0.05),"Hard",IF(AND(E4>=0.15,F4<0.05),"Easy","Medium")) -> Hard
A5: Allentown | B5: Lehigh | C5: Actual | D5: =AVERAGE('Combined District Data'!H8:H11) -> 0.68026642 | E5: =AVERAGE(ABS('Combined District Data'!H8-0.5),ABS('Combined District Data'!H9-0.5),ABS('Combined District Data'!H10-0.5),ABS('Combined District Data'!H11-0.5)) -> 0.18026642 | F5: =STDEV('Combined District Data'!H8:H11) -> 0.026644292 | G5: =IF(('Combined District Data'!H8>0.5)<>('Combined District Data'!H9>0.5),1,0)+IF(('Combined District Data'!H9>0.5)<>('Combined District Data'!H10>0.5),1,0)+IF(('Combined District Data'!H10>0.5)<>('Combined District Data'!H11>0.5),1,0) -> 0 | H5: =IF(OR(G5>=1,E5<0.05),"Hard",IF(AND(E5>=0.15,F5<0.05),"Easy","Medium")) -> Easy
A6: Bethlehem | B6: Lehigh | C6: Actual | D6: =AVERAGE('Combined District Data'!H12:H15) -> 0.63958903 | E6: =AVERAGE(ABS('Combined District Data'!H12-0.5),ABS('Combined District Data'!H13-0.5),ABS('Combined District Data'!H14-0.5),ABS('Combined District Data'!H15-0.5)) -> 0.13958903 | F6: =STDEV('Combined District Data'!H12:H15) -> 0.011997737 | G6: =IF(('Combined District Data'!H12>0.5)<>('Combined District Data'!H13>0.5),1,0)+IF(('Combined District Data'!H13>0.5)<>('Combined District Data'!H14>0.5),1,0)+IF(('Combined District Data'!H14>0.5)<>('Combined District Data'!H15>0.5),1,0) -> 0 | H6: =IF(OR(G6>=1,E6<0.05),"Hard",IF(AND(E6>=0.15,F6<0.05),"Easy","Medium")) -> Medium
A7: Catasauqua | B7: Lehigh | C7: Actual | D7: =AVERAGE('Combined District Data'!H16:H19) -> 0.52878358 | E7: =AVERAGE(ABS('Combined District Data'!H16-0.5),ABS('Combined District Data'!H17-0.5),ABS('Combined District Data'!H18-0.5),ABS('Combined District Data'!H19-0.5)) -> 0.028783579 | F7: =STDEV('Combined District Data'!H16:H19) -> 0.019532203 | G7: =IF(('Combined District Data'!H16>0.5)<>('Combined District Data'!H17>0.5),1,0)+IF(('Combined District Data'!H17>0.5)<>('Combined District Data'!H18>0.5),1,0)+IF(('Combined District Data'!H18>0.5)<>('Combined District Data'!H19>0.5),1,0) -> 0 | H7: =IF(OR(G7>=1,E7<0.05),"Hard",IF(AND(E7>=0.15,F7<0.05),"Easy","Medium")) -> Hard
A8: Coopersburg | B8: Lehigh | C8: Actual | D8: =AVERAGE('Combined District Data'!H20:H23) -> 0.49209189 | E8: =AVERAGE(ABS('Combined District Data'!H20-0.5),ABS('Combined District Data'!H21-0.5),ABS('Combined District Data'!H22-0.5),ABS('Combined District Data'!H23-0.5)) -> 0.017848967 | F8: =STDEV('Combined District Data'!H20:H23) -> 0.020793961 | G8: =IF(('Combined District Data'!H20>0.5)<>('Combined District Data'!H21>0.5),1,0)+IF(('Combined District Data'!H21>0.5)<>('Combined District Data'!H22>0.5),1,0)+IF(('Combined District Data'!H22>0.5)<>('Combined District Data'!H23>0.5),1,0) -> 3 | H8: =IF(OR(G8>=1,E8<0.05),"Hard",IF(AND(E8>=0.15,F8<0.05),"Easy","Medium")) -> Hard
A9: Coplay | B9: Lehigh | C9: Actual | D9: =AVERAGE('Combined District Data'!H24:H27) -> 0.51808912 | E9: =AVERAGE(ABS('Combined District Data'!H24-0.5),ABS('Combined District Data'!H25-0.5),ABS('Combined District Data'!H26-0.5),ABS('Combined District Data'!H27-0.5)) -> 0.018089117 | F9: =STDEV('Combined District Data'!H24:H27) -> 0.019500534 | G9: =IF(('Combined District Data'!H24>0.5)<>('Combined District Data'!H25>0.5),1,0)+IF(('Combined District Data'!H25>0.5)<>('Combined District Data'!H26>0.5),1,0)+IF(('Combined District Data'!H26>0.5)<>('Combined District Data'!H27>0.5),1,0) -> 0 | H9: =IF(OR(G9>=1,E9<0.05),"Hard",IF(AND(E9>=0.15,F9<0.05),"Easy","Medium")) -> Hard
A10: Emmaus | B10: Lehigh | C10: Actual | D10: =AVERAGE('Combined District Data'!H28:H31) -> 0.53633123 | E10: =AVERAGE(ABS('Combined District Data'!H28-0.5),ABS('Combined District Data'!H29-0.5),ABS('Combined District Data'!H30-0.5),ABS('Combined District Data'!H31-0.5)) -> 0.036331226 | F10: =STDEV('Combined District Data'!H28:H31) -> 0.014515116 | G10: =IF(('Combined District Data'!H28>0.5)<>('Combined District Data'!H29>0.5),1,0)+IF(('Combined District Data'!H29>0.5)<>('Combined District Data'!H30>0.5),1,0)+IF(('Combined District Data'!H30>0.5)<>('Combined District Data'!H31>0.5),1,0) -> 0 | H10: =IF(OR(G10>=1,E10<0.05),"Hard",IF(AND(E10>=0.15,F10<0.05),"Easy","Medium")) -> Hard
A11: Fountain Hill | B11: Lehigh | C11: Actual | D11: =AVERAGE('Combined District Data'!H32:H35) -> 0.66696978 | E11: =AVERAGE(ABS('Combined District Data'!H32-0.5),ABS('Combined District Data'!H33-0.5),ABS('Combined District Data'!H34-0.5),ABS('Combined District Data'!H35-0.5)) -> 0.16696978 | F11: =STDEV('Combined District Data'!H32:H35) -> 0.019214597 | G11: =IF(('Combined District Data'!H32>0.5)<>('Combined District Data'!H33>0.5),1,0)+IF(('Combined District Data'!H33>0.5)<>('Combined District Data'!H34>0.5),1,0)+IF(('Combined District Data'!H34>0.5)<>('Combined District Data'!H35>0.5),1,0) -> 0 | H11: =IF(OR(G11>=1,E11<0.05),"Hard",IF(AND(E11>=0.15,F11<0.05),"Easy","Medium")) -> Easy
A12: Hanover | B12: Lehigh | C12: Actual | D12: =AVERAGE('Combined District Data'!H36:H39) -> 0.56282592 | E12: =AVERAGE(ABS('Combined District Data'!H36-0.5),ABS('Combined District Data'!H37-0.5),ABS('Combined District Data'!H38-0.5),ABS('Combined District Data'!H39-0.5)) -> 0.062825918 | F12: =STDEV('Combined District Data'!H36:H39) -> 0.021154049 | G12: =IF(('Combined District Data'!H36>0.5)<>('Combined District Data'!H37>0.5),1,0)+IF(('Combined District Data'!H37>0.5)<>('Combined District Data'!H38>0.5),1,0)+IF(('Combined District Data'!H38>0.5)<>('Combined District Data'!H39>0.5),1,0) -> 0 | H12: =IF(OR(G12>=1,E12<0.05),"Hard",IF(AND(E12>=0.15,F12<0.05),"Easy","Medium")) -> Medium
A13: Heidelberg | B13: Lehigh | C13: Actual | D13: =AVERAGE('Combined District Data'!H40:H43) -> 0.32608704 | E13: =AVERAGE(ABS('Combined District Data'!H40-0.5),ABS('Combined District Data'!H41-0.5),ABS('Combined District Data'!H42-0.5),ABS('Combined District Data'!H43-0.5)) -> 0.17391296 | F13: =STDEV('Combined District Data'!H40:H43) -> 0.018403682 | G13: =IF(('Combined District Data'!H40>0.5)<>('Combined District Data'!H41>0.5),1,0)+IF(('Combined District Data'!H41>0.5)<>('Combined District Data'!H42>0.5),1,0)+IF(('Combined District Data'!H42>0.5)<>('Combined District Data'!H43>0.5),1,0) -> 0 | H13: =IF(OR(G13>=1,E13<0.05),"Hard",IF(AND(E13>=0.15,F13<0.05),"Easy","Medium")) -> Easy
A14: Lower Macungie | B14: Lehigh | C14: Actual | D14: =AVERAGE('Combined District Data'!H44:H47) -> 0.50330098 | E14: =AVERAGE(ABS('Combined District Data'!H44-0.5),ABS('Combined District Data'!H45-0.5),ABS('Combined District Data'!H46-0.5),ABS('Combined District Data'!H47-0.5)) -> 0.0086560224 | F14: =STDEV('Combined District Data'!H44:H47) -> 0.013930849 | G14: =IF(('Combined District Data'!H44>0.5)<>('Combined District Data'!H45>0.5),1,0)+IF(('Combined District Data'!H45>0.5)<>('Combined District Data'!H46>0.5),1,0)+IF(('Combined District Data'!H46>0.5)<>('Combined District Data'!H47>0.5),1,0) -> 2 | H14: =IF(OR(G14>=1,E14<0.05),"Hard",IF(AND(E14>=0.15,F14<0.05),"Easy","Medium")) -> Hard
A15: Lower Milford | B15: Lehigh | C15: Actual | D15: =AVERAGE('Combined District Data'!H48:H51) -> 0.38263416 | E15: =AVERAGE(ABS('Combined District Data'!H48-0.5),ABS('Combined District Data'!H49-0.5),ABS('Combined District Data'!H50-0.5),ABS('Combined District Data'!H51-0.5)) -> 0.11736584 | F15: =STDEV('Combined District Data'!H48:H51) -> 0.01206084 | G15: =IF(('Combined District Data'!H48>0.5)<>('Combined District Data'!H49>0.5),1,0)+IF(('Combined District Data'!H49>0.5)<>('Combined District Data'!H50>0.5),1,0)+IF(('Combined District Data'!H50>0.5)<>('Combined District Data'!H51>0.5),1,0) -> 0 | H15: =IF(OR(G15>=1,E15<0.05),"Hard",IF(AND(E15>=0.15,F15<0.05),"Easy","Medium")) -> Medium
A16: Lowhill | B16: Lehigh | C16: Actual | D16: =AVERAGE('Combined District Data'!H52:H55) -> 0.36298972 | E16: =AVERAGE(ABS('Combined District Data'!H52-0.5),ABS('Combined District Data'!H53-0.5),ABS('Combined District Data'!H54-0.5),ABS('Combined District Data'!H55-0.5)) -> 0.13701028 | F16: =STDEV('Combined District Data'!H52:H55) -> 0.0092741158 | G16: =IF(('Combined District Data'!H52>0.5)<>('Combined District Data'!H53>0.5),1,0)+IF(('Combined District Data'!H53>0.5)<>('Combined District Data'!H54>0.5),1,0)+IF(('Combined District Data'!H54>0.5)<>('Combined District Data'!H55>0.5),1,0) -> 0 | H16: =IF(OR(G16>=1,E16<0.05),"Hard",IF(AND(E16>=0.15,F16<0.05),"Easy","Medium")) -> Medium
A17: Lynn | B17: Lehigh | C17: Actual | D17: =AVERAGE('Combined District Data'!H56:H59) -> 0.32354375 | E17: =AVERAGE(ABS('Combined District Data'!H56-0.5),ABS('Combined District Data'!H57-0.5),ABS('Combined District Data'!H58-0.5),ABS('Combined District Data'!H59-0.5)) -> 0.17645625 | F17: =STDEV('Combined District Data'!H56:H59) -> 0.008182438 | G17: =IF(('Combined District Data'!H56>0.5)<>('Combined District Data'!H57>0.5),1,0)+IF(('Combined District Data'!H57>0.5)<>('Combined District Data'!H58>0.5),1,0)+IF(('Combined District Data'!H58>0.5)<>('Combined District Data'!H59>0.5),1,0) -> 0 | H17: =IF(OR(G17>=1,E17<0.05),"Hard",IF(AND(E17>=0.15,F17<0.05),"Easy","Medium")) -> Easy
A18: Macungie | B18: Lehigh | C18: Actual | D18: =AVERAGE('Combined District Data'!H60:H63) -> 0.5370044 | E18: =AVERAGE(ABS('Combined District Data'!H60-0.5),ABS('Combined District Data'!H61-0.5),ABS('Combined District Data'!H62-0.5),ABS('Combined District Data'!H63-0.5)) -> 0.037004395 | F18: =STDEV('Combined District Data'!H60:H63) -> 0.013838035 | G18: =IF(('Combined District Data'!H60>0.5)<>('Combined District Data'!H61>0.5),1,0)+IF(('Combined District Data'!H61>0.5)<>('Combined District Data'!H62>0.5),1,0)+IF(('Combined District Data'!H62>0.5)<>('Combined District Data'!H63>0.5),1,0) -> 0 | H18: =IF(OR(G18>=1,E18<0.05),"Hard",IF(AND(E18>=0.15,F18<0.05),"Easy","Medium")) -> Hard
A19: North Whitehall | B19: Lehigh | C19: Actual | D19: =AVERAGE('Combined District Data'!H64:H67) -> 0.40760578 | E19: =AVERAGE(ABS('Combined District Data'!H64-0.5),ABS('Combined District Data'!H65-0.5),ABS('Combined District Data'!H66-0.5),ABS('Combined District Data'!H67-0.5)) -> 0.092394223 | F19: =STDEV('Combined District Data'!H64:H67) -> 0.0097365715 | G19: =IF(('Combined District Data'!H64>0.5)<>('Combined District Data'!H65>0.5),1,0)+IF(('Combined District Data'!H65>0.5)<>('Combined District Data'!H66>0.5),1,0)+IF(('Combined District Data'!H66>0.5)<>('Combined District Data'!H67>0.5),1,0) -> 0 | H19: =IF(OR(G19>=1,E19<0.05),"Hard",IF(AND(E19>=0.15,F19<0.05),"Easy","Medium")) -> Medium
A20: Salisbury | B20: Lehigh | C20: Actual | D20: =AVERAGE('Combined District Data'!H68:H71) -> 0.49733365 | E20: =AVERAGE(ABS('Combined District Data'!H68-0.5),ABS('Combined District Data'!H69-0.5),ABS('Combined District Data'!H70-0.5),ABS('Combined District Data'!H71-0.5)) -> 0.0069848204 | F20: =STDEV('Combined District Data'!H68:H71) -> 0.0075513108 | G20: =IF(('Combined District Data'!H68>0.5)<>('Combined District Data'!H69>0.5),1,0)+IF(('Combined District Data'!H69>0.5)<>('Combined District Data'!H70>0.5),1,0)+IF(('Combined District Data'!H70>0.5)<>('Combined District Data'!H71>0.5),1,0) -> 2 | H20: =IF(OR(G20>=1,E20<0.05),"Hard",IF(AND(E20>=0.15,F20<0.05),"Easy","Medium")) -> Hard
A21: Slatington | B21: Lehigh | C21: Actual | D21: =AVERAGE('Combined District Data'!H72:H75) -> 0.424841 | E21: =AVERAGE(ABS('Combined District Data'!H72-0.5),ABS('Combined District Data'!H73-0.5),ABS('Combined District Data'!H74-0.5),ABS('Combined District Data'!H75-0.5)) -> 0.075159001 | F21: =STDEV('Combined District Data'!H72:H75) -> 0.027655711 | G21: =IF(('Combined District Data'!H72>0.5)<>('Combined District Data'!H73>0.5),1,0)+IF(('Combined District Data'!H73>0.5)<>('Combined District Data'!H74>0.5),1,0)+IF(('Combined District Data'!H74>0.5)<>('Combined District Data'!H75>0.5),1,0) -> 0 | H21: =IF(OR(G21>=1,E21<0.05),"Hard",IF(AND(E21>=0.15,F21<0.05),"Easy","Medium")) -> Medium
A22: South Whitehall | B22: Lehigh | C22: Actual | D22: =AVERAGE('Combined District Data'!H76:H79) -> 0.54503236 | E22: =AVERAGE(ABS('Combined District Data'!H76-0.5),ABS('Combined District Data'!H77-0.5),ABS('Combined District Data'!H78-0.5),ABS('Combined District Data'!H79-0.5)) -> 0.045032358 | F22: =STDEV('Combined District Data'!H76:H79) -> 0.014390127 | G22: =IF(('Combined District Data'!H76>0.5)<>('Combined District Data'!H77>0.5),1,0)+IF(('Combined District Data'!H77>0.5)<>('Combined District Data'!H78>0.5),1,0)+IF(('Combined District Data'!H78>0.5)<>('Combined District Data'!H79>0.5),1,0) -> 0 | H22: =IF(OR(G22>=1,E22<0.05),"Hard",IF(AND(E22>=0.15,F22<0.05),"Easy","Medium")) -> Hard
A23: Upper Macungie | B23: Lehigh | C23: Actual | D23: =AVERAGE('Combined District Data'!H80:H83) -> 0.52003115 | E23: =AVERAGE(ABS('Combined District Data'!H80-0.5),ABS('Combined District Data'!H81-0.5),ABS('Combined District Data'!H82-0.5),ABS('Combined District Data'!H83-0.5)) -> 0.020031155 | F23: =STDEV('Combined District Data'!H80:H83) -> 0.0090523443 | G23: =IF(('Combined District Data'!H80>0.5)<>('Combined District Data'!H81>0.5),1,0)+IF(('Combined District Data'!H81>0.5)<>('Combined District Data'!H82>0.5),1,0)+IF(('Combined District Data'!H82>0.5)<>('Combined District Data'!H83>0.5),1,0) -> 0 | H23: =IF(OR(G23>=1,E23<0.05),"Hard",IF(AND(E23>=0.15,F23<0.05),"Easy","Medium")) -> Hard
A24: Upper Milford | B24: Lehigh | C24: Actual | D24: =AVERAGE('Combined District Data'!H84:H87) -> 0.43966475 | E24: =AVERAGE(ABS('Combined District Data'!H84-0.5),ABS('Combined District Data'!H85-0.5),ABS('Combined District Data'!H86-0.5),ABS('Combined District Data'!H87-0.5)) -> 0.06033525 | F24: =STDEV('Combined District Data'!H84:H87) -> 0.011353998 | G24: =IF(('Combined District Data'!H84>0.5)<>('Combined District Data'!H85>0.5),1,0)+IF(('Combined District Data'!H85>0.5)<>('Combined District Data'!H86>0.5),1,0)+IF(('Combined District Data'!H86>0.5)<>('Combined District Data'!H87>0.5),1,0) -> 0 | H24: =IF(OR(G24>=1,E24<0.05),"Hard",IF(AND(E24>=0.15,F24<0.05),"Easy","Medium")) -> Medium
A25: Upper Saucon | B25: Lehigh | C25: Actual | D25: =AVERAGE('Combined District Data'!H88:H91) -> 0.48386045 | E25: =AVERAGE(ABS('Combined District Data'!H88-0.5),ABS('Combined District Data'!H89-0.5),ABS('Combined District Data'!H90-0.5),ABS('Combined District Data'!H91-0.5)) -> 0.017193676 | F25: =STDEV('Combined District Data'!H88:H91) -> 0.014841905 | G25: =IF(('Combined District Data'!H88>0.5)<>('Combined District Data'!H89>0.5),1,0)+IF(('Combined District Data'!H89>0.5)<>('Combined District Data'!H90>0.5),1,0)+IF(('Combined District Data'!H90>0.5)<>('Combined District Data'!H91>0.5),1,0) -> 2 | H25: =IF(OR(G25>=1,E25<0.05),"Hard",IF(AND(E25>=0.15,F25<0.05),"Easy","Medium")) -> Hard
A26: Washington | B26: Lehigh | C26: Actual | D26: =AVERAGE('Combined District Data'!H92:H95) -> 0.33473717 | E26: =AVERAGE(ABS('Combined District Data'!H92-0.5),ABS('Combined District Data'!H93-0.5),ABS('Combined District Data'!H94-0.5),ABS('Combined District Data'!H95-0.5)) -> 0.16526283 | F26: =STDEV('Combined District Data'!H92:H95) -> 0.014497891 | G26: =IF(('Combined District Data'!H92>0.5)<>('Combined District Data'!H93>0.5),1,0)+IF(('Combined District Data'!H93>0.5)<>('Combined District Data'!H94>0.5),1,0)+IF(('Combined District Data'!H94>0.5)<>('Combined District Data'!H95>0.5),1,0) -> 0 | H26: =IF(OR(G26>=1,E26<0.05),"Hard",IF(AND(E26>=0.15,F26<0.05),"Easy","Medium")) -> Easy
A27: Weisenberg | B27: Lehigh | C27: Actual | D27: =AVERAGE('Combined District Data'!H96:H99) -> 0.3464918 | E27: =AVERAGE(ABS('Combined District Data'!H96-0.5),ABS('Combined District Data'!H97-0.5),ABS('Combined District Data'!H98-0.5),ABS('Combined District Data'!H99-0.5)) -> 0.1535082 | F27: =STDEV('Combined District Data'!H96:H99) -> 0.013486092 | G27: =IF(('Combined District Data'!H96>0.5)<>('Combined District Data'!H97>0.5),1,0)+IF(('Combined District Data'!H97>0.5)<>('Combined District Data'!H98>0.5),1,0)+IF(('Combined District Data'!H98>0.5)<>('Combined District Data'!H99>0.5),1,0) -> 0 | H27: =IF(OR(G27>=1,E27<0.05),"Hard",IF(AND(E27>=0.15,F27<0.05),"Easy","Medium")) -> Easy
A28: Whitehall | B28: Lehigh | C28: Actual | D28: =AVERAGE('Combined District Data'!H100:H103) -> 0.52770789 | E28: =AVERAGE(ABS('Combined District Data'!H100-0.5),ABS('Combined District Data'!H101-0.5),ABS('Combined District Data'!H102-0.5),ABS('Combined District Data'!H103-0.5)) -> 0.027707894 | F28: =STDEV('Combined District Data'!H100:H103) -> 0.011717288 | G28: =IF(('Combined District Data'!H100>0.5)<>('Combined District Data'!H101>0.5),1,0)+IF(('Combined District Data'!H101>0.5)<>('Combined District Data'!H102>0.5),1,0)+IF(('Combined District Data'!H102>0.5)<>('Combined District Data'!H103>0.5),1,0) -> 0 | H28: =IF(OR(G28>=1,E28<0.05),"Hard",IF(AND(E28>=0.15,F28<0.05),"Easy","Medium")) -> Hard
A29: Allen | B29: Northampton | C29: Actual | D29: =AVERAGE('Combined District Data'!H104:H107) -> 0.4327543 | E29: =AVERAGE(ABS('Combined District Data'!H104-0.5),ABS('Combined District Data'!H105-0.5),ABS('Combined District Data'!H106-0.5),ABS('Combined District Data'!H107-0.5)) -> 0.067245698 | F29: =STDEV('Combined District Data'!H104:H107) -> 0.013636598 | G29: =IF(('Combined District Data'!H104>0.5)<>('Combined District Data'!H105>0.5),1,0)+IF(('Combined District Data'!H105>0.5)<>('Combined District Data'!H106>0.5),1,0)+IF(('Combined District Data'!H106>0.5)<>('Combined District Data'!H107>0.5),1,0) -> 0 | H29: =IF(OR(G29>=1,E29<0.05),"Hard",IF(AND(E29>=0.15,F29<0.05),"Easy","Medium")) -> Medium
A30: Bangor | B30: Northampton | C30: Actual | D30: =AVERAGE('Combined District Data'!H108:H111) -> 0.43283697 | E30: =AVERAGE(ABS('Combined District Data'!H108-0.5),ABS('Combined District Data'!H109-0.5),ABS('Combined District Data'!H110-0.5),ABS('Combined District Data'!H111-0.5)) -> 0.067163029 | F30: =STDEV('Combined District Data'!H108:H111) -> 0.021721023 | G30: =IF(('Combined District Data'!H108>0.5)<>('Combined District Data'!H109>0.5),1,0)+IF(('Combined District Data'!H109>0.5)<>('Combined District Data'!H110>0.5),1,0)+IF(('Combined District Data'!H110>0.5)<>('Combined District Data'!H111>0.5),1,0) -> 0 | H30: =IF(OR(G30>=1,E30<0.05),"Hard",IF(AND(E30>=0.15,F30<0.05),"Easy","Medium")) -> Medium
A31: Bath | B31: Northampton | C31: Actual | D31: =AVERAGE('Combined District Data'!H112:H115) -> 0.4583611 | E31: =AVERAGE(ABS('Combined District Data'!H112-0.5),ABS('Combined District Data'!H113-0.5),ABS('Combined District Data'!H114-0.5),ABS('Combined District Data'!H115-0.5)) -> 0.041638902 | F31: =STDEV('Combined District Data'!H112:H115) -> 0.0042595571 | G31: =IF(('Combined District Data'!H112>0.5)<>('Combined District Data'!H113>0.5),1,0)+IF(('Combined District Data'!H113>0.5)<>('Combined District Data'!H114>0.5),1,0)+IF(('Combined District Data'!H114>0.5)<>('Combined District Data'!H115>0.5),1,0) -> 0 | H31: =IF(OR(G31>=1,E31<0.05),"Hard",IF(AND(E31>=0.15,F31<0.05),"Easy","Medium")) -> Hard
A32: Bethlehem | B32: Northampton | C32: Actual | D32: =AVERAGE('Combined District Data'!H116:H119) -> 0.6784395 | E32: =AVERAGE(ABS('Combined District Data'!H116-0.5),ABS('Combined District Data'!H117-0.5),ABS('Combined District Data'!H118-0.5),ABS('Combined District Data'!H119-0.5)) -> 0.1784395 | F32: =STDEV('Combined District Data'!H116:H119) -> 0.0094557579 | G32: =IF(('Combined District Data'!H116>0.5)<>('Combined District Data'!H117>0.5),1,0)+IF(('Combined District Data'!H117>0.5)<>('Combined District Data'!H118>0.5),1,0)+IF(('Combined District Data'!H118>0.5)<>('Combined District Data'!H119>0.5),1,0) -> 0 | H32: =IF(OR(G32>=1,E32<0.05),"Hard",IF(AND(E32>=0.15,F32<0.05),"Easy","Medium")) -> Easy
A33: Bethlehem Township | B33: Northampton | C33: Actual | D33: =AVERAGE('Combined District Data'!H120:H123) -> 0.53552415 | E33: =AVERAGE(ABS('Combined District Data'!H120-0.5),ABS('Combined District Data'!H121-0.5),ABS('Combined District Data'!H122-0.5),ABS('Combined District Data'!H123-0.5)) -> 0.035524149 | F33: =STDEV('Combined District Data'!H120:H123) -> 0.0073642727 | G33: =IF(('Combined District Data'!H120>0.5)<>('Combined District Data'!H121>0.5),1,0)+IF(('Combined District Data'!H121>0.5)<>('Combined District Data'!H122>0.5),1,0)+IF(('Combined District Data'!H122>0.5)<>('Combined District Data'!H123>0.5),1,0) -> 0 | H33: =IF(OR(G33>=1,E33<0.05),"Hard",IF(AND(E33>=0.15,F33<0.05),"Easy","Medium")) -> Hard
A34: Bushkill | B34: Northampton | C34: Actual | D34: =AVERAGE('Combined District Data'!H124:H127) -> 0.38151885 | E34: =AVERAGE(ABS('Combined District Data'!H124-0.5),ABS('Combined District Data'!H125-0.5),ABS('Combined District Data'!H126-0.5),ABS('Combined District Data'!H127-0.5)) -> 0.11848115 | F34: =STDEV('Combined District Data'!H124:H127) -> 0.011176034 | G34: =IF(('Combined District Data'!H124>0.5)<>('Combined District Data'!H125>0.5),1,0)+IF(('Combined District Data'!H125>0.5)<>('Combined District Data'!H126>0.5),1,0)+IF(('Combined District Data'!H126>0.5)<>('Combined District Data'!H127>0.5),1,0) -> 0 | H34: =IF(OR(G34>=1,E34<0.05),"Hard",IF(AND(E34>=0.15,F34<0.05),"Easy","Medium")) -> Medium
A35: Chapman | B35: Northampton | C35: Actual | D35: =AVERAGE('Combined District Data'!H128:H131) -> 0.36273986 | E35: =AVERAGE(ABS('Combined District Data'!H128-0.5),ABS('Combined District Data'!H129-0.5),ABS('Combined District Data'!H130-0.5),ABS('Combined District Data'!H131-0.5)) -> 0.13726014 | F35: =STDEV('Combined District Data'!H128:H131) -> 0.050475047 | G35: =IF(('Combined District Data'!H128>0.5)<>('Combined District Data'!H129>0.5),1,0)+IF(('Combined District Data'!H129>0.5)<>('Combined District Data'!H130>0.5),1,0)+IF(('Combined District Data'!H130>0.5)<>('Combined District Data'!H131>0.5),1,0) -> 0 | H35: =IF(OR(G35>=1,E35<0.05),"Hard",IF(AND(E35>=0.15,F35<0.05),"Easy","Medium")) -> Medium
A36: East Allen | B36: Northampton | C36: Actual | D36: =AVERAGE('Combined District Data'!H132:H135) -> 0.42015114 | E36: =AVERAGE(ABS('Combined District Data'!H132-0.5),ABS('Combined District Data'!H133-0.5),ABS('Combined District Data'!H134-0.5),ABS('Combined District Data'!H135-0.5)) -> 0.079848862 | F36: =STDEV('Combined District Data'!H132:H135) -> 0.018509198 | G36: =IF(('Combined District Data'!H132>0.5)<>('Combined District Data'!H133>0.5),1,0)+IF(('Combined District Data'!H133>0.5)<>('Combined District Data'!H134>0.5),1,0)+IF(('Combined District Data'!H134>0.5)<>('Combined District Data'!H135>0.5),1,0) -> 0 | H36: =IF(OR(G36>=1,E36<0.05),"Hard",IF(AND(E36>=0.15,F36<0.05),"Easy","Medium")) -> Medium
A37: East Bangor | B37: Northampton | C37: Actual | D37: =AVERAGE('Combined District Data'!H136:H139) -> 0.37743937 | E37: =AVERAGE(ABS('Combined District Data'!H136-0.5),ABS('Combined District Data'!H137-0.5),ABS('Combined District Data'!H138-0.5),ABS('Combined District Data'!H139-0.5)) -> 0.12256063 | F37: =STDEV('Combined District Data'!H136:H139) -> 0.033459878 | G37: =IF(('Combined District Data'!H136>0.5)<>('Combined District Data'!H137>0.5),1,0)+IF(('Combined District Data'!H137>0.5)<>('Combined District Data'!H138>0.5),1,0)+IF(('Combined District Data'!H138>0.5)<>('Combined District Data'!H139>0.5),1,0) -> 0 | H37: =IF(OR(G37>=1,E37<0.05),"Hard",IF(AND(E37>=0.15,F37<0.05),"Easy","Medium")) -> Medium
A38: Easton | B38: Northampton | C38: Actual | D38: =AVERAGE('Combined District Data'!H140:H143) -> 0.71897369 | E38: =AVERAGE(ABS('Combined District Data'!H140-0.5),ABS('Combined District Data'!H141-0.5),ABS('Combined District Data'!H142-0.5),ABS('Combined District Data'!H143-0.5)) -> 0.21897369 | F38: =STDEV('Combined District Data'!H140:H143) -> 0.021399452 | G38: =IF(('Combined District Data'!H140>0.5)<>('Combined District Data'!H141>0.5),1,0)+IF(('Combined District Data'!H141>0.5)<>('Combined District Data'!H142>0.5),1,0)+IF(('Combined District Data'!H142>0.5)<>('Combined District Data'!H143>0.5),1,0) -> 0 | H38: =IF(OR(G38>=1,E38<0.05),"Hard",IF(AND(E38>=0.15,F38<0.05),"Easy","Medium")) -> Easy
A39: Forks | B39: Northampton | C39: Actual | D39: =AVERAGE('Combined District Data'!H144:H147) -> 0.5200637 | E39: =AVERAGE(ABS('Combined District Data'!H144-0.5),ABS('Combined District Data'!H145-0.5),ABS('Combined District Data'!H146-0.5),ABS('Combined District Data'!H147-0.5)) -> 0.020063701 | F39: =STDEV('Combined District Data'!H144:H147) -> 0.008007736 | G39: =IF(('Combined District Data'!H144>0.5)<>('Combined District Data'!H145>0.5),1,0)+IF(('Combined District Data'!H145>0.5)<>('Combined District Data'!H146>0.5),1,0)+IF(('Combined District Data'!H146>0.5)<>('Combined District Data'!H147>0.5),1,0) -> 0 | H39: =IF(OR(G39>=1,E39<0.05),"Hard",IF(AND(E39>=0.15,F39<0.05),"Easy","Medium")) -> Hard
A40: Freemansburg | B40: Northampton | C40: Actual | D40: =AVERAGE('Combined District Data'!H148:H151) -> 0.61340818 | E40: =AVERAGE(ABS('Combined District Data'!H148-0.5),ABS('Combined District Data'!H149-0.5),ABS('Combined District Data'!H150-0.5),ABS('Combined District Data'!H151-0.5)) -> 0.11340818 | F40: =STDEV('Combined District Data'!H148:H151) -> 0.022866505 | G40: =IF(('Combined District Data'!H148>0.5)<>('Combined District Data'!H149>0.5),1,0)+IF(('Combined District Data'!H149>0.5)<>('Combined District Data'!H150>0.5),1,0)+IF(('Combined District Data'!H150>0.5)<>('Combined District Data'!H151>0.5),1,0) -> 0 | H40: =IF(OR(G40>=1,E40<0.05),"Hard",IF(AND(E40>=0.15,F40<0.05),"Easy","Medium")) -> Medium
A41: Glendon | B41: Northampton | C41: Actual | D41: =AVERAGE('Combined District Data'!H152:H155) -> 0.54208476 | E41: =AVERAGE(ABS('Combined District Data'!H152-0.5),ABS('Combined District Data'!H153-0.5),ABS('Combined District Data'!H154-0.5),ABS('Combined District Data'!H155-0.5)) -> 0.042084758 | F41: =STDEV('Combined District Data'!H152:H155) -> 0.057099653 | G41: =IF(('Combined District Data'!H152>0.5)<>('Combined District Data'!H153>0.5),1,0)+IF(('Combined District Data'!H153>0.5)<>('Combined District Data'!H154>0.5),1,0)+IF(('Combined District Data'!H154>0.5)<>('Combined District Data'!H155>0.5),1,0) -> 0 | H41: =IF(OR(G41>=1,E41<0.05),"Hard",IF(AND(E41>=0.15,F41<0.05),"Easy","Medium")) -> Hard
...

Sheet Magic Municipality
A1: Bellwether Search (86 Municipalities)
A2: District-wide result now computed directly from the Combined District Data (actual + Carbon estimate), not an external reference. Match = municipality's own winner equals the combined-district winner that year.
A4: District-wide result by year
A5: Year | B5: District Dem Votes | C5: District Rep Votes | D5: District Dem Share | E5: District Winner
A6: 2018 | B6: =SUMIF('Combined District Data'!$A:$A,A6,'Combined District Data'!$E:$E) -> 136384 | C6: =SUMIF('Combined District Data'!$A:$A,A6,'Combined District Data'!$F:$F) -> 116835 | D6: =B6/(B6+C6) -> 0.53860097 | E6: =IF(D6>0.5,"D","R") -> D
A7: 2020 | B7: =SUMIF('Combined District Data'!$A:$A,A7,'Combined District Data'!$E:$E) -> 190062 | C7: =SUMIF('Combined District Data'!$A:$A,A7,'Combined District Data'!$F:$F) -> 186030 | D7: =B7/(B7+C7) -> 0.50536039 | E7: =IF(D7>0.5,"D","R") -> D
A8: 2022 | B8: =SUMIF('Combined District Data'!$A:$A,A8,'Combined District Data'!$E:$E) -> 149868 | C8: =SUMIF('Combined District Data'!$A:$A,A8,'Combined District Data'!$F:$F) -> 139318 | D8: =B8/(B8+C8) -> 0.51824086 | E8: =IF(D8>0.5,"D","R") -> D
A9: 2024 | B9: =SUMIF('Combined District Data'!$A:$A,A9,'Combined District Data'!$E:$E) -> 198281 | C9: =SUMIF('Combined District Data'!$A:$A,A9,'Combined District Data'!$F:$F) -> 196459 | D9: =B9/(B9+C9) -> 0.50230785 | E9: =IF(D9>0.5,"D","R") -> D
A12: Per-municipality bellwether test
A13: Municipality | B13: County | C13: Source | D13: Match 2018 | E13: Match 2020 | F13: Match 2022 | G13: Match 2024 | H13: Total Matches (/4) | I13: Avg Point Gap vs District | J13: Magic Municipality? | K13: (helper)
A14: Alburtis | B14: Lehigh | C14: Actual | D14: =IF(IF('Combined District Data'!H4>0.5,"D","R")=$E$6,1,0) -> 1 | E14: =IF(IF('Combined District Data'!H5>0.5,"D","R")=$E$7,1,0) -> 0 | F14: =IF(IF('Combined District Data'!H6>0.5,"D","R")=$E$8,1,0) -> 0 | G14: =IF(IF('Combined District Data'!H7>0.5,"D","R")=$E$9,1,0) -> 0 | H14: =SUM(D14:G14) -> 1 | I14: =AVERAGE(ABS('Combined District Data'!H4-$D$6),ABS('Combined District Data'!H5-$D$7),ABS('Combined District Data'!H6-$D$8),ABS('Combined District Data'!H7-$D$9)) -> 0.040874821 | J14: =IF(AND(H14=4,I14=MIN(K14:K99)),"<< MAGIC MUNICIPALITY","") | K14: =IF(H14=4,I14,"")
A15: Allentown | B15: Lehigh | C15: Actual | D15: =IF(IF('Combined District Data'!H8>0.5,"D","R")=$E$6,1,0) -> 1 | E15: =IF(IF('Combined District Data'!H9>0.5,"D","R")=$E$7,1,0) -> 1 | F15: =IF(IF('Combined District Data'!H10>0.5,"D","R")=$E$8,1,0) -> 1 | G15: =IF(IF('Combined District Data'!H11>0.5,"D","R")=$E$9,1,0) -> 1 | H15: =SUM(D15:G15) -> 4 | I15: =AVERAGE(ABS('Combined District Data'!H8-$D$6),ABS('Combined District Data'!H9-$D$7),ABS('Combined District Data'!H10-$D$8),ABS('Combined District Data'!H11-$D$9)) -> 0.16413891 | J15: =IF(AND(H15=4,I15=MIN(K14:K99)),"<< MAGIC MUNICIPALITY","") | K15: =IF(H15=4,I15,"") -> 0.16413891
A16: Bethlehem | B16: Lehigh | C16: Actual | D16: =IF(IF('Combined District Data'!H12>0.5,"D","R")=$E$6,1,0) -> 1 | E16: =IF(IF('Combined District Data'!H13>0.5,"D","R")=$E$7,1,0) -> 1 | F16: =IF(IF('Combined District Data'!H14>0.5,"D","R")=$E$8,1,0) -> 1 | G16: =IF(IF('Combined District Data'!H15>0.5,"D","R")=$E$9,1,0) -> 1 | H16: =SUM(D16:G16) -> 4 | I16: =AVERAGE(ABS('Combined District Data'!H12-$D$6),ABS('Combined District Data'!H13-$D$7),ABS('Combined District Data'!H14-$D$8),ABS('Combined District Data'!H15-$D$9)) -> 0.12346151 | J16: =IF(AND(H16=4,I16=MIN(K14:K99)),"<< MAGIC MUNICIPALITY","") | K16: =IF(H16=4,I16,"") -> 0.12346151
A17: Catasauqua | B17: Lehigh | C17: Actual | D17: =IF(IF('Combined District Data'!H16>0.5,"D","R")=$E$6,1,0) -> 1 | E17: =IF(IF('Combined District Data'!H17>0.5,"D","R")=$E$7,1,0) -> 1 | F17: =IF(IF('Combined District Data'!H18>0.5,"D","R")=$E$8,1,0) -> 1 | G17: =IF(IF('Combined District Data'!H19>0.5,"D","R")=$E$9,1,0) -> 1 | H17: =SUM(D17:G17) -> 4 | I17: =AVERAGE(ABS('Combined District Data'!H16-$D$6),ABS('Combined District Data'!H17-$D$7),ABS('Combined District Data'!H18-$D$8),ABS('Combined District Data'!H19-$D$9)) -> 0.012656062 | J17: =IF(AND(H17=4,I17=MIN(K14:K99)),"<< MAGIC MUNICIPALITY","") | K17: =IF(H17=4,I17,"") -> 0.012656062
A18: Coopersburg | B18: Lehigh | C18: Actual | D18: =IF(IF('Combined District Data'!H20>0.5,"D","R")=$E$6,1,0) -> 1 | E18: =IF(IF('Combined District Data'!H21>0.5,"D","R")=$E$7,1,0) -> 0 | F18: =IF(IF('Combined District Data'!H22>0.5,"D","R")=$E$8,1,0) -> 1 | G18: =IF(IF('Combined District Data'!H23>0.5,"D","R")=$E$9,1,0) -> 0 | H18: =SUM(D18:G18) -> 2 | I18: =AVERAGE(ABS('Combined District Data'!H20-$D$6),ABS('Combined District Data'!H21-$D$7),ABS('Combined District Data'!H22-$D$8),ABS('Combined District Data'!H23-$D$9)) -> 0.024035622 | J18: =IF(AND(H18=4,I18=MIN(K14:K99)),"<< MAGIC MUNICIPALITY","") | K18: =IF(H18=4,I18,"")
A19: Coplay | B19: Lehigh | C19: Actual | D19: =IF(IF('Combined District Data'!H24>0.5,"D","R")=$E$6,1,0) -> 1 | E19: =IF(IF('Combined District Data'!H25>0.5,"D","R")=$E$7,1,0) -> 1 | F19: =IF(IF('Combined District Data'!H26>0.5,"D","R")=$E$8,1,0) -> 1 | G19: =IF(IF('Combined District Data'!H27>0.5,"D","R")=$E$9,1,0) -> 1 | H19: =SUM(D19:G19) -> 4 | I19: =AVERAGE(ABS('Combined District Data'!H24-$D$6),ABS('Combined District Data'!H25-$D$7),ABS('Combined District Data'!H26-$D$8),ABS('Combined District Data'!H27-$D$9)) -> 0.0053019358 | J19: =IF(AND(H19=4,I19=MIN(K14:K99)),"<< MAGIC MUNICIPALITY","") -> << MAGIC MUNICIPALITY | K19: =IF(H19=4,I19,"") -> 0.0053019358
A20: Emmaus | B20: Lehigh | C20: Actual | D20: =IF(IF('Combined District Data'!H28>0.5,"D","R")=$E$6,1,0) -> 1 | E20: =IF(IF('Combined District Data'!H29>0.5,"D","R")=$E$7,1,0) -> 1 | F20: =IF(IF('Combined District Data'!H30>0.5,"D","R")=$E$8,1,0) -> 1 | G20: =IF(IF('Combined District Data'!H31>0.5,"D","R")=$E$9,1,0) -> 1 | H20: =SUM(D20:G20) -> 4 | I20: =AVERAGE(ABS('Combined District Data'!H28-$D$6),ABS('Combined District Data'!H29-$D$7),ABS('Combined District Data'!H30-$D$8),ABS('Combined District Data'!H31-$D$9)) -> 0.023202226 | J20: =IF(AND(H20=4,I20=MIN(K14:K99)),"<< MAGIC MUNICIPALITY","") | K20: =IF(H20=4,I20,"") -> 0.023202226
A21: Fountain Hill | B21: Lehigh | C21: Actual | D21: =IF(IF('Combined District Data'!H32>0.5,"D","R")=$E$6,1,0) -> 1 | E21: =IF(IF('Combined District Data'!H33>0.5,"D","R")=$E$7,1,0) -> 1 | F21: =IF(IF('Combined District Data'!H34>0.5,"D","R")=$E$8,1,0) -> 1 | G21: =IF(IF('Combined District Data'!H35>0.5,"D","R")=$E$9,1,0) -> 1 | H21: =SUM(D21:G21) -> 4 | I21: =AVERAGE(ABS('Combined District Data'!H32-$D$6),ABS('Combined District Data'!H33-$D$7),ABS('Combined District Data'!H34-$D$8),ABS('Combined District Data'!H35-$D$9)) -> 0.15084226 | J21: =IF(AND(H21=4,I21=MIN(K14:K99)),"<< MAGIC MUNICIPALITY","") | K21: =IF(H21=4,I21,"") -> 0.15084226
A22: Hanover | B22: Lehigh | C22: Actual | D22: =IF(IF('Combined District Data'!H36>0.5,"D","R")=$E$6,1,0) -> 1 | E22: =IF(IF('Combined District Data'!H37>0.5,"D","R")=$E$7,1,0) -> 1 | F22: =IF(IF('Combined District Data'!H38>0.5,"D","R")=$E$8,1,0) -> 1 | G22: =IF(IF('Combined District Data'!H39>0.5,"D","R")=$E$9,1,0) -> 1 | H22: =SUM(D22:G22) -> 4 | I22: =AVERAGE(ABS('Combined District Data'!H36-$D$6),ABS('Combined District Data'!H37-$D$7),ABS('Combined District Data'!H38-$D$8),ABS('Combined District Data'!H39-$D$9)) -> 0.046698401 | J22: =IF(AND(H22=4,I22=MIN(K14:K99)),"<< MAGIC MUNICIPALITY","") | K22: =IF(H22=4,I22,"") -> 0.046698401
A23: Heidelberg | B23: Lehigh | C23: Actual | D23: =IF(IF('Combined District Data'!H40>0.5,"D","R")=$E$6,1,0) -> 0 | E23: =IF(IF('Combined District Data'!H41>0.5,"D","R")=$E$7,1,0) -> 0 | F23: =IF(IF('Combined District Data'!H42>0.5,"D","R")=$E$8,1,0) -> 0 | G23: =IF(IF('Combined District Data'!H43>0.5,"D","R")=$E$9,1,0) -> 0 | H23: =SUM(D23:G23) -> 0 | I23: =AVERAGE(ABS('Combined District Data'!H40-$D$6),ABS('Combined District Data'!H41-$D$7),ABS('Combined District Data'!H42-$D$8),ABS('Combined District Data'!H43-$D$9)) -> 0.19004048 | J23: =IF(AND(H23=4,I23=MIN(K14:K99)),"<< MAGIC MUNICIPALITY","") | K23: =IF(H23=4,I23,"")
A24: Lower Macungie | B24: Lehigh | C24: Actual | D24: =IF(IF('Combined District Data'!H44>0.5,"D","R")=$E$6,1,0) -> 0 | E24: =IF(IF('Combined District Data'!H45>0.5,"D","R")=$E$7,1,0) -> 0 | F24: =IF(IF('Combined District Data'!H46>0.5,"D","R")=$E$8,1,0) -> 1 | G24: =IF(IF('Combined District Data'!H47>0.5,"D","R")=$E$9,1,0) -> 0 | H24: =SUM(D24:G24) -> 1 | I24: =AVERAGE(ABS('Combined District Data'!H44-$D$6),ABS('Combined District Data'!H45-$D$7),ABS('Combined District Data'!H46-$D$8),ABS('Combined District Data'!H47-$D$9)) -> 0.015663112 | J24: =IF(AND(H24=4,I24=MIN(K14:K99)),"<< MAGIC MUNICIPALITY","") | K24: =IF(H24=4,I24,"")
A25: Lower Milford | B25: Lehigh | C25: Actual | D25: =IF(IF('Combined District Data'!H48>0.5,"D","R")=$E$6,1,0) -> 0 | E25: =IF(IF('Combined District Data'!H49>0.5,"D","R")=$E$7,1,0) -> 0 | F25: =IF(IF('Combined District Data'!H50>0.5,"D","R")=$E$8,1,0) -> 0 | G25: =IF(IF('Combined District Data'!H51>0.5,"D","R")=$E$9,1,0) -> 0 | H25: =SUM(D25:G25) -> 0 | I25: =AVERAGE(ABS('Combined District Data'!H48-$D$6),ABS('Combined District Data'!H49-$D$7),ABS('Combined District Data'!H50-$D$8),ABS('Combined District Data'!H51-$D$9)) -> 0.13349335 | J25: =IF(AND(H25=4,I25=MIN(K14:K99)),"<< MAGIC MUNICIPALITY","") | K25: =IF(H25=4,I25,"")
A26: Lowhill | B26: Lehigh | C26: Actual | D26: =IF(IF('Combined District Data'!H52>0.5,"D","R")=$E$6,1,0) -> 0 | E26: =IF(IF('Combined District Data'!H53>0.5,"D","R")=$E$7,1,0) -> 0 | F26: =IF(IF('Combined District Data'!H54>0.5,"D","R")=$E$8,1,0) -> 0 | G26: =IF(IF('Combined District Data'!H55>0.5,"D","R")=$E$9,1,0) -> 0 | H26: =SUM(D26:G26) -> 0 | I26: =AVERAGE(ABS('Combined District Data'!H52-$D$6),ABS('Combined District Data'!H53-$D$7),ABS('Combined District Data'!H54-$D$8),ABS('Combined District Data'!H55-$D$9)) -> 0.15313779 | J26: =IF(AND(H26=4,I26=MIN(K14:K99)),"<< MAGIC MUNICIPALITY","") | K26: =IF(H26=4,I26,"")
A27: Lynn | B27: Lehigh | C27: Actual | D27: =IF(IF('Combined District Data'!H56>0.5,"D","R")=$E$6,1,0) -> 0 | E27: =IF(IF('Combined District Data'!H57>0.5,"D","R")=$E$7,1,0) -> 0 | F27: =IF(IF('Combined District Data'!H58>0.5,"D","R")=$E$8,1,0) -> 0 | G27: =IF(IF('Combined District Data'!H59>0.5,"D","R")=$E$9,1,0) -> 0 | H27: =SUM(D27:G27) -> 0 | I27: =AVERAGE(ABS('Combined District Data'!H56-$D$6),ABS('Combined District Data'!H57-$D$7),ABS('Combined District Data'!H58-$D$8),ABS('Combined District Data'!H59-$D$9)) -> 0.19258376 | J27: =IF(AND(H27=4,I27=MIN(K14:K99)),"<< MAGIC MUNICIPALITY","") | K27: =IF(H27=4,I27,"")
A28: Macungie | B28: Lehigh | C28: Actual | D28: =IF(IF('Combined District Data'!H60>0.5,"D","R")=$E$6,1,0) -> 1 | E28: =IF(IF('Combined District Data'!H61>0.5,"D","R")=$E$7,1,0) -> 1 | F28: =IF(IF('Combined District Data'!H62>0.5,"D","R")=$E$8,1,0) -> 1 | G28: =IF(IF('Combined District Data'!H63>0.5,"D","R")=$E$9,1,0) -> 1 | H28: =SUM(D28:G28) -> 4 | I28: =AVERAGE(ABS('Combined District Data'!H60-$D$6),ABS('Combined District Data'!H61-$D$7),ABS('Combined District Data'!H62-$D$8),ABS('Combined District Data'!H63-$D$9)) -> 0.027439722 | J28: =IF(AND(H28=4,I28=MIN(K14:K99)),"<< MAGIC MUNICIPALITY","") | K28: =IF(H28=4,I28,"") -> 0.027439722
A29: North Whitehall | B29: Lehigh | C29: Actual | D29: =IF(IF('Combined District Data'!H64>0.5,"D","R")=$E$6,1,0) -> 0 | E29: =IF(IF('Combined District Data'!H65>0.5,"D","R")=$E$7,1,0) -> 0 | F29: =IF(IF('Combined District Data'!H66>0.5,"D","R")=$E$8,1,0) -> 0 | G29: =IF(IF('Combined District Data'!H67>0.5,"D","R")=$E$9,1,0) -> 0 | H29: =SUM(D29:G29) -> 0 | I29: =AVERAGE(ABS('Combined District Data'!H64-$D$6),ABS('Combined District Data'!H65-$D$7),ABS('Combined District Data'!H66-$D$8),ABS('Combined District Data'!H67-$D$9)) -> 0.10852174 | J29: =IF(AND(H29=4,I29=MIN(K14:K99)),"<< MAGIC MUNICIPALITY","") | K29: =IF(H29=4,I29,"")
A30: Salisbury | B30: Lehigh | C30: Actual | D30: =IF(IF('Combined District Data'!H68>0.5,"D","R")=$E$6,1,0) -> 0 | E30: =IF(IF('Combined District Data'!H69>0.5,"D","R")=$E$7,1,0) -> 0 | F30: =IF(IF('Combined District Data'!H70>0.5,"D","R")=$E$8,1,0) -> 1 | G30: =IF(IF('Combined District Data'!H71>0.5,"D","R")=$E$9,1,0) -> 0 | H30: =SUM(D30:G30) -> 1 | I30: =AVERAGE(ABS('Combined District Data'!H68-$D$6),ABS('Combined District Data'!H69-$D$7),ABS('Combined District Data'!H70-$D$8),ABS('Combined District Data'!H71-$D$9)) -> 0.01879387 | J30: =IF(AND(H30=4,I30=MIN(K14:K99)),"<< MAGIC MUNICIPALITY","") | K30: =IF(H30=4,I30,"")
A31: Slatington | B31: Lehigh | C31: Actual | D31: =IF(IF('Combined District Data'!H72>0.5,"D","R")=$E$6,1,0) -> 0 | E31: =IF(IF('Combined District Data'!H73>0.5,"D","R")=$E$7,1,0) -> 0 | F31: =IF(IF('Combined District Data'!H74>0.5,"D","R")=$E$8,1,0) -> 0 | G31: =IF(IF('Combined District Data'!H75>0.5,"D","R")=$E$9,1,0) -> 0 | H31: =SUM(D31:G31) -> 0 | I31: =AVERAGE(ABS('Combined District Data'!H72-$D$6),ABS('Combined District Data'!H73-$D$7),ABS('Combined District Data'!H74-$D$8),ABS('Combined District Data'!H75-$D$9)) -> 0.091286518 | J31: =IF(AND(H31=4,I31=MIN(K14:K99)),"<< MAGIC MUNICIPALITY","") | K31: =IF(H31=4,I31,"")
