Workbook

Sheet Summary
A1: PA-07 2026 General Forecast — Mail-Ballot Model
A2: Bob Brooks (D) vs. Rep. Ryan Mackenzie (R) · built on the v0.5 random-forest backtest · as of 2026-10-01
A4: Central forecast (live — recalculates from Assumptions) | D4: Signal-scope comparison (central case, static)
A5: Brooks votes | B5: =SUM('Municipal Forecast'!L5:L93) -> 160197.05 | D5: No primary signal | E5: 0.48657035
A6: Total votes | B6: =SUM('Municipal Forecast'!L5:M93) -> 323501.29 | D6: Mail voters only (prior run) | E6: 0.48865998
A7: Mackenzie votes | B7: =SUM('Municipal Forecast'!M5:M93) -> 163304.23 | D7: All party voters (this run) | E7: 0.49519757
A8: Brooks share | B8: =B5/B6 -> 0.49519757
A9: Mackenzie share | B9: =B7/B6 -> 0.50480243
A10: Margin (Brooks − Mackenzie, pts) | B10: =(B8-B9)*100 -> -0.96048518
A11: Swing vs 2024 Wild share (pts) | B11: =(B8-SUMPRODUCT('Municipal Forecast'!E5:E93,'Municipal Forecast'!D5:D93)/SUM('Municipal Forecast'!E5:E93))*100 -> 0.023335269
A13: Mail component (live)
A14: Projected mail ballots | B14: ='Mail Projection'!C20 -> 90356.874
A15: Brooks mail votes | B15: ='Mail Projection'!C21 -> 59381.862
A16: Mackenzie mail votes | B16: ='Mail Projection'!C22 -> 30975.011
A17: Brooks mail margin | B17: ='Mail Projection'!C23 -> 28406.851
A18: Brooks share of mail | B18: ='Mail Projection'!C24 -> 0.65719253
A19: Mail share of all votes | B19: ='Mail Projection'!C25 -> 0.27930916
A20: Mackenzie share of in-person/drop-off votes needed to hold seat | B20: =(B6/2-'Mail Projection'!C22)/(B6-'Mail Projection'!C20) -> 0.56092115
A21: Modeled Mackenzie share of non-mail votes | B21: =(B7-'Mail Projection'!C22)/(B6-'Mail Projection'!C20) -> 0.56758479
A23: Uncertainty — 20,000-run Monte Carlo (static values from Python run)
A24: P(Brooks wins) | B24: 0.4388 | C24: Draws all levers across their ranges (Assumptions col C) plus a ±3.0-pt (1 SD) district environment shock and municipal noise sized from backtest residuals.
A25: P(Mackenzie wins) | B25: 0.5612
A26: Brooks share — 10th pct | B26: 0.45601679
A27: Brooks share — median | B27: 0.49541507
A28: Brooks share — 90th pct | B28: 0.53377179
A30: Sensitivity — one lever at a time, others at central (static)
A31: Lever | B31: Low setting | C31: Brooks share | D31: High setting | E31: Brooks share
A32: GOP mail-habit retention | B32: 0 | C32: 0.49519757 | D32: 1 | E32: 0.49519757
A33: Mail-signal elasticity | B33: 0.25 | C33: 0.49014451 | D33: 1 | E33: 0.501044
A34: Midterm turnout factor | B34: 0.76 | C34: 0.49519757 | D34: 0.86 | E34: 0.49519757
A35: Weight on RF backtest | B35: 0.3 | C35: 0.49857256 | D35: 0.7 | E35: 0.49182131
A36: Unaffiliated → Brooks | B36: 0.5 | C36: 0.49513587 | D36: 0.62 | E36: 0.49525934
A37: Dem loyalty | B37: 0.9 | C37: 0.49491964 | D37: 0.95 | E37: 0.49537228
A38: GOP loyalty | B38: 0.88 | C38: 0.49484344 | D38: 0.94 | E38: 0.49552677
A41: Backtest calibration (2024, RF v0.5)
A42: District error, predicted − actual (pts) | B42: -1.5789769
A43: Vote-weighted municipal RMSE (pts) | B43: 2.0786072
A44: Municipal residual SD after removing bias (pts) | B44: 1.248672
A46: Key caveats
A47: • No national midterm-environment term: the central case assumes a neutral year. Historically the president’s party loses ground in midterms; add that via the env shock if you want a lean.
...

Sheet SHAP Ranking
A1: SHAP Ranking — Drivers of Brooks Vote Share
A2: TreeSHAP on a random-forest surrogate fit to 4,000 model runs (held-out R² = 0.998). Blue values come from the Python run; share columns are formulas.
A4: Rank | B4: Assumption | C4: Mean |SHAP| (pts) | D4: Share of total | E4: Share excl. environment | F4: Direction (corr. of value with SHAP)
A5: 1 | B5: National environment shock (±3 pt) | C5: 2.4192792 | D5: =C5/SUM($C$5:$C$12) -> 0.86758086 | E5: n/a | F5: 0.99958802
A6: 2 | B6: Primary-signal elasticity | C6: 0.24269508 | D6: =C6/SUM($C$5:$C$12) -> 0.087033199 | E6: =C6/(SUM($C$5:$C$12)-$C$5) -> 0.65725541 | F6: 0.98410105
A7: 3 | B7: Weight on RF backtest vs 2024 | C7: 0.11961049 | D7: =C7/SUM($C$5:$C$12) -> 0.042893675 | E7: =C7/(SUM($C$5:$C$12)-$C$5) -> 0.32392351 | F7: -0.97213414
A8: 4 | B8: GOP loyalty | C8: 0.002604448 | D8: =C8/SUM($C$5:$C$12) -> 0.00093398448 | E8: =C8/(SUM($C$5:$C$12)-$C$5) -> 0.0070532436 | F8: 0.62461433
A9: 5 | B9: Midterm turnout factor | C9: 0.0013131896 | D9: =C9/SUM($C$5:$C$12) -> 0.00047092463 | E9: =C9/(SUM($C$5:$C$12)-$C$5) -> 0.0035563183 | F9: 0.23221287
A10: 6 | B10: Dem loyalty | C10: 0.0011819468 | D10: =C10/SUM($C$5:$C$12) -> 0.00042385948 | E10: =C10/(SUM($C$5:$C$12)-$C$5) -> 0.0032008928 | F10: 0.65763399
A11: 7 | B11: Unaffiliated → Brooks | C11: 0.0011015107 | D11: =C11/SUM($C$5:$C$12) -> 0.00039501419 | E11: =C11/(SUM($C$5:$C$12)-$C$5) -> 0.0029830595 | F11: 0.53280889
A12: 8 | B12: GOP mail-habit retention | C12: 0.00074868679 | D12: =C12/SUM($C$5:$C$12) -> 0.00026848755 | E12: =C12/(SUM($C$5:$C$12)-$C$5) -> 0.0020275584 | F12: -0.067113872
A14: Positive direction = higher setting pushes toward Brooks. Environment shock is the national swing the model does not predict, only allows for.
A16: Primary mail signal — exact Shapley split (central case)
B17: Component | C17: Contribution (pts) | D17: Share of signal
B18: GOP mail returns down 5.2% | C18: 0.58436145 | D18: =C18/SUM($C$18:$C$20) -> 0.67734617
B19: Dem mail returns up 2.6% | C19: 0.26993883 | D19: =C19/SUM($C$18:$C$20) -> 0.31289201
B20: County offsets | C20: 0.0084217388 | D20: =C20/SUM($C$18:$C$20) -> 0.009761822
B21: Total signal | C21: =SUM(C18:C20) -> 0.86272202
B22: Check: all-voter share − no-signal share (pts) | C22: 0.86272202

Sheet Assumptions
A1: PA-07 2026 General — Mail-Ballot Forecast: Assumptions
A2: Blue = input you can change (yellow = key scenario lever). Everything on other tabs recalculates from these.
A4: Midterm turnout factor (2026 total ÷ 2024 total) | B4: 0.81 | C4: Assumption. 2022 PA-07 House turnout ran roughly 80–82% of 2024; Monte Carlo range 76–86%.
A5: Weight on random-forest backtest share (vs. 2024 actual) | B5: 0.5 | C5: RF trained on 2018–2022 (two midterms) carries midterm structure; 2024 actual is the latest result. MC range 30–70%.
A6: GOP mail-habit retention (alpha) | B6: 0.5 | C6: 0 = mail electorate reverts to 2022 mix (D-heavy); 1 = each party keeps its 2024 mail share, falling only by the turnout factor. MC range 0–100%.
A7: Elasticity: general mail turnout to primary mail-return change | B7: 0.6 | C7: How much of the 2024→2026 primary return change carries into the general. MC range 0.25–1.0.
A8: Dem-registered mail voters → Brooks | B8: 0.93 | C8: Assumed party loyalty. MC range 90–95%.
A9: GOP-registered mail voters → Mackenzie | B9: 0.91 | C9: Assumed party loyalty. MC range 88–94%.
A10: Unaffiliated mail voters → Brooks | B10: 0.56 | C10: Assumed. MC range 50–62%.
A11: Primary-signal scope (1 = all party voters, 0 = mail voters only) | B11: 1 | C11: 1 treats the 2026 primary mail-return change as a base-enthusiasm signal for every registrant of that party; 0 limits it to projected mail voters.
A12: Midterm mail ratio by party (2022 returned ÷ 2024 returned, PA-07)
A13: Democratic | B13: 0.76818785 | C13: Source: PA07_House_mail-ballot_2020_2022_2024 (user file). GOP mail use more than doubled from 2022 to 2024.
A14: Republican | B14: 0.39599483
A15: Other / No affiliation | B15: 0.47815808
A17: 2026 primary mail-return signal (returned, % change vs 2024 primary)
A18: Democratic | B18: 0.026 | C18: Source: PA07_primary_mail_ballot_requests_2024_2026 (user file). D returns +2.6%, R −5.2%.
A19: Republican | B19: -0.052
A20: Other / No affiliation | B20: 0 | C20: Set to 0: closed primary, so unaffiliated requests are mostly declined and say nothing about the general.
A22: County offset (county return change minus district +0.3%)
A23: Carbon | B23: -0.057
A24: Lehigh | B24: -0.035
A25: Monroe | B25: 0.085
A26: Northampton | B26: 0.04

Sheet Mail Projection
A1: 2026 General Mail-Ballot Projection by County and Registered Party
A2: Registered party ≠ vote choice; candidate columns apply the loyalty assumptions.
A4: County | B4: Party | C4: 2024 mail recorded | D4: Midterm mail ratio | E4: 2026 mail (habit-adjusted) | F4: Primary signal (party + county) | G4: 2026 mail (signal-adjusted) | H4: Net new mail voters vs. habit | I4: Share to Brooks | J4: Brooks mail votes | K4: Mackenzie mail votes | L4: Net new → Brooks | M4: Net new → Mackenzie | N4: All-voter party electorate
A5: Carbon | B5: Democratic | C5: 3581 | D5: =Assumptions!$B$13 -> 0.76818785 | E5: =C5*(D5+Assumptions!$B$6*(Assumptions!$B$4-D5)) -> 2825.7454 | F5: =Assumptions!$B$18+Assumptions!$B$23 -> -0.031 | G5: =E5*(1+Assumptions!$B$7*F5) -> 2773.1865 | H5: =IF(Assumptions!$B$11=1,N5,E5)*Assumptions!$B$7*F5 -> -112.76169 | I5: =Assumptions!$B$8 -> 0.93 | J5: =G5*I5 -> 2579.0634 | K5: =G5*(1-I5) -> 194.12305 | L5: =H5*I5 -> -104.86837 | M5: =H5*(1-I5) -> -7.893318 | N5: {=INDEX($F$36:$F$39,MATCH(A5,$A$36:$A$39,0))} -> 6062.4562
A6: Carbon | B6: Republican | C6: 2876 | D6: =Assumptions!$B$14 -> 0.39599483 | E6: =C6*(D6+Assumptions!$B$6*(Assumptions!$B$4-D6)) -> 1734.2206 | F6: =Assumptions!$B$19+Assumptions!$B$23 -> -0.109 | G6: =E6*(1+Assumptions!$B$7*F6) -> 1620.8025 | H6: =IF(Assumptions!$B$11=1,N6,E6)*Assumptions!$B$7*F6 -> -1213.7796 | I6: =1-Assumptions!$B$9 -> 0.09 | J6: =G6*I6 -> 145.87223 | K6: =G6*(1-I6) -> 1474.9303 | L6: =H6*I6 -> -109.24017 | M6: =H6*(1-I6) -> -1104.5395 | N6: {=INDEX($G$36:$G$39,MATCH(A6,$A$36:$A$39,0))} -> 18559.322
A7: Carbon | B7: Other / No affiliation | C7: 856 | D7: =Assumptions!$B$15 -> 0.47815808 | E7: =C7*(D7+Assumptions!$B$6*(Assumptions!$B$4-D7)) -> 551.33166 | F7: =Assumptions!$B$20 -> 0 | G7: =E7*(1+Assumptions!$B$7*F7) -> 551.33166 | H7: =IF(Assumptions!$B$11=1,N7,E7)*Assumptions!$B$7*F7 -> 0 | I7: =Assumptions!$B$10 -> 0.56 | J7: =G7*I7 -> 308.74573 | K7: =G7*(1-I7) -> 242.58593 | L7: =H7*I7 -> 0 | M7: =H7*(1-I7) -> 0 | N7: {=INDEX($E$36:$E$39,MATCH(A7,$A$36:$A$39,0))} -> 3264.092
A8: Lehigh | B8: Democratic | C8: 31432 | D8: =Assumptions!$B$13 -> 0.76818785 | E8: =C8*(D8+Assumptions!$B$6*(Assumptions!$B$4-D8)) -> 24802.8 | F8: =Assumptions!$B$18+Assumptions!$B$24 -> -0.009 | G8: =E8*(1+Assumptions!$B$7*F8) -> 24668.865 | H8: =IF(Assumptions!$B$11=1,N8,E8)*Assumptions!$B$7*F8 -> -351.59563 | I8: =Assumptions!$B$8 -> 0.93 | J8: =G8*I8 -> 22942.045 | K8: =G8*(1-I8) -> 1726.8206 | L8: =H8*I8 -> -326.98393 | M8: =H8*(1-I8) -> -24.611694 | N8: {=INDEX($F$36:$F$39,MATCH(A8,$A$36:$A$39,0))} -> 65110.301
A9: Lehigh | B9: Republican | C9: 18202 | D9: =Assumptions!$B$14 -> 0.39599483 | E9: =C9*(D9+Assumptions!$B$6*(Assumptions!$B$4-D9)) -> 10975.759 | F9: =Assumptions!$B$19+Assumptions!$B$24 -> -0.087 | G9: =E9*(1+Assumptions!$B$7*F9) -> 10402.824 | H9: =IF(Assumptions!$B$11=1,N9,E9)*Assumptions!$B$7*F9 -> -3409.3007 | I9: =1-Assumptions!$B$9 -> 0.09 | J9: =G9*I9 -> 936.25419 | K9: =G9*(1-I9) -> 9466.5702 | L9: =H9*I9 -> -306.83706 | M9: =H9*(1-I9) -> -3102.4636 | N9: {=INDEX($G$36:$G$39,MATCH(A9,$A$36:$A$39,0))} -> 65312.274
A10: Lehigh | B10: Other / No affiliation | C10: 8123 | D10: =Assumptions!$B$15 -> 0.47815808 | E10: =C10*(D10+Assumptions!$B$6*(Assumptions!$B$4-D10)) -> 5231.854 | F10: =Assumptions!$B$20 -> 0 | G10: =E10*(1+Assumptions!$B$7*F10) -> 5231.854 | H10: =IF(Assumptions!$B$11=1,N10,E10)*Assumptions!$B$7*F10 -> 0 | I10: =Assumptions!$B$10 -> 0.56 | J10: =G10*I10 -> 2929.8383 | K10: =G10*(1-I10) -> 2302.0158 | L10: =H10*I10 -> 0 | M10: =H10*(1-I10) -> 0 | N10: {=INDEX($E$36:$E$39,MATCH(A10,$A$36:$A$39,0))} -> 21344.695
A11: Monroe | B11: Democratic | C11: 939 | D11: =Assumptions!$B$13 -> 0.76818785 | E11: =C11*(D11+Assumptions!$B$6*(Assumptions!$B$4-D11)) -> 740.9592 | F11: =Assumptions!$B$18+Assumptions!$B$25 -> 0.111 | G11: =E11*(1+Assumptions!$B$7*F11) -> 790.30708 | H11: =IF(Assumptions!$B$11=1,N11,E11)*Assumptions!$B$7*F11 -> 73.147608 | I11: =Assumptions!$B$8 -> 0.93 | J11: =G11*I11 -> 734.98558 | K11: =G11*(1-I11) -> 55.321496 | L11: =H11*I11 -> 68.027276 | M11: =H11*(1-I11) -> 5.1203326 | N11: {=INDEX($F$36:$F$39,MATCH(A11,$A$36:$A$39,0))} -> 1098.3124
A12: Monroe | B12: Republican | C12: 809 | D12: =Assumptions!$B$14 -> 0.39599483 | E12: =C12*(D12+Assumptions!$B$6*(Assumptions!$B$4-D12)) -> 487.82491 | F12: =Assumptions!$B$19+Assumptions!$B$25 -> 0.033 | G12: =E12*(1+Assumptions!$B$7*F12) -> 497.48384 | H12: =IF(Assumptions!$B$11=1,N12,E12)*Assumptions!$B$7*F12 -> 80.637007 | I12: =1-Assumptions!$B$9 -> 0.09 | J12: =G12*I12 -> 44.773546 | K12: =G12*(1-I12) -> 452.7103 | L12: =H12*I12 -> 7.2573306 | M12: =H12*(1-I12) -> 73.379676 | N12: {=INDEX($G$36:$G$39,MATCH(A12,$A$36:$A$39,0))} -> 4072.5761
A13: Monroe | B13: Other / No affiliation | C13: 284 | D13: =Assumptions!$B$15 -> 0.47815808 | E13: =C13*(D13+Assumptions!$B$6*(Assumptions!$B$4-D13)) -> 182.91845 | F13: =Assumptions!$B$20 -> 0 | G13: =E13*(1+Assumptions!$B$7*F13) -> 182.91845 | H13: =IF(Assumptions!$B$11=1,N13,E13)*Assumptions!$B$7*F13 -> 0 | I13: =Assumptions!$B$10 -> 0.56 | J13: =G13*I13 -> 102.43433 | K13: =G13*(1-I13) -> 80.484117 | L13: =H13*I13 -> 0 | M13: =H13*(1-I13) -> 0 | N13: {=INDEX($E$36:$E$39,MATCH(A13,$A$36:$A$39,0))} -> 840.12148
A14: Northampton | B14: Democratic | C14: 31892 | D14: =Assumptions!$B$13 -> 0.76818785 | E14: =C14*(D14+Assumptions!$B$6*(Assumptions!$B$4-D14)) -> 25165.784 | F14: =Assumptions!$B$18+Assumptions!$B$26 -> 0.066 | G14: =E14*(1+Assumptions!$B$7*F14) -> 26162.349 | H14: =IF(Assumptions!$B$11=1,N14,E14)*Assumptions!$B$7*F14 -> 2210.9856 | I14: =Assumptions!$B$8 -> 0.93 | J14: =G14*I14 -> 24330.984 | K14: =G14*(1-I14) -> 1831.3644 | L14: =H14*I14 -> 2056.2166 | M14: =H14*(1-I14) -> 154.76899 | N14: {=INDEX($F$36:$F$39,MATCH(A14,$A$36:$A$39,0))} -> 55832.969
A15: Northampton | B15: Republican | C15: 19402 | D15: =Assumptions!$B$14 -> 0.39599483 | E15: =C15*(D15+Assumptions!$B$6*(Assumptions!$B$4-D15)) -> 11699.356 | F15: =Assumptions!$B$19+Assumptions!$B$26 -> -0.012 | G15: =E15*(1+Assumptions!$B$7*F15) -> 11615.121 | H15: =IF(Assumptions!$B$11=1,N15,E15)*Assumptions!$B$7*F15 -> -460.38713 | I15: =1-Assumptions!$B$9 -> 0.09 | J15: =G15*I15 -> 1045.3608 | K15: =G15*(1-I15) -> 10569.76 | L15: =H15*I15 -> -41.434842 | M15: =H15*(1-I15) -> -418.95229 | N15: {=INDEX($G$36:$G$39,MATCH(A15,$A$36:$A$39,0))} -> 63942.658
A16: Northampton | B16: Other / No affiliation | C16: 9098 | D16: =Assumptions!$B$15 -> 0.47815808 | E16: =C16*(D16+Assumptions!$B$6*(Assumptions!$B$4-D16)) -> 5859.8311 | F16: =Assumptions!$B$20 -> 0 | G16: =E16*(1+Assumptions!$B$7*F16) -> 5859.8311 | H16: =IF(Assumptions!$B$11=1,N16,E16)*Assumptions!$B$7*F16 -> 0 | I16: =Assumptions!$B$10 -> 0.56 | J16: =G16*I16 -> 3281.5054 | K16: =G16*(1-I16) -> 2578.3257 | L16: =H16*I16 -> 0 | M16: =H16*(1-I16) -> 0 | N16: {=INDEX($E$36:$E$39,MATCH(A16,$A$36:$A$39,0))} -> 21244.564
A17: PA-07 TOTAL | C17: =SUM(C5:C16) -> 127494 | E17: =SUM(E5:E16) -> 90258.384 | G17: =SUM(G5:G16) -> 90356.874 | H17: =SUM(H5:H16) -> -3183.0546 | J17: =SUM(J5:J16) -> 59381.862 | K17: =SUM(K5:K16) -> 30975.011 | L17: =SUM(L5:L16) -> 1242.1368 | M17: =SUM(M5:M16) -> -4425.1914
A19: Mail margin summary
A20: Projected 2026 mail ballots | C20: =G17 -> 90356.874
A21: Brooks mail votes | C21: =J17 -> 59381.862
A22: Mackenzie mail votes | C22: =K17 -> 30975.011
A23: Brooks mail margin | C23: =J17-K17 -> 28406.851
A24: Brooks share of mail | C24: =J17/G17 -> 0.65719253
A25: Mail share of all 2026 votes | C25: =G17/Summary!B6 -> 0.27930916
A27: County mail-signal adjustment (feeds Municipal tab)
A28: County | B28: Net new → Brooks | C28: Net new → Mackenzie
A29: Carbon | B29: =SUMIF($A$5:$A$16,A29,$L$5:$L$16) -> -214.10854 | C29: =SUMIF($A$5:$A$16,A29,$M$5:$M$16) -> -1112.4328
A30: Lehigh | B30: =SUMIF($A$5:$A$16,A30,$L$5:$L$16) -> -633.821 | C30: =SUMIF($A$5:$A$16,A30,$M$5:$M$16) -> -3127.0753
A31: Monroe | B31: =SUMIF($A$5:$A$16,A31,$L$5:$L$16) -> 75.284606 | C31: =SUMIF($A$5:$A$16,A31,$M$5:$M$16) -> 78.500009
A32: Northampton | B32: =SUMIF($A$5:$A$16,A32,$L$5:$L$16) -> 2014.7817 | C32: =SUMIF($A$5:$A$16,A32,$M$5:$M$16) -> -264.1833
A34: All-voter party electorate by county (baseline votes; unaffiliated share proxied by 2024 mail mix; D/R solved from loyalty rates)
A35: County | B35: Baseline Brooks | C35: Baseline Mackenzie | D35: Unaffiliated share | E35: Unaffiliated voters | F35: Dem voters | G35: GOP voters
A36: Carbon | B36: =SUMIF('Municipal Forecast'!$A$5:$A$93,A36,'Municipal Forecast'!$H$5:$H$93) -> 9136.3147 | C36: =SUMIF('Municipal Forecast'!$A$5:$A$93,A36,'Municipal Forecast'!$I$5:$I$93) -> 18749.555 | D36: =C7/SUM(C5:C7) -> 0.11705183 | E36: =D36*(B36+C36) -> 3264.092 | F36: =(Assumptions!$B$9*(B36-Assumptions!$B$10*E36)-(1-Assumptions!$B$9)*(C36-(1-Assumptions!$B$10)*E36))/(Assumptions!$B$8*Assumptions!$B$9-(1-Assumptions!$B$9)*(1-Assumptions!$B$8)) -> 6062.4562 | G36: =(Assumptions!$B$8*(C36-(1-Assumptions!$B$10)*E36)-(1-Assumptions!$B$8)*(B36-Assumptions!$B$10*E36))/(Assumptions!$B$8*Assumptions!$B$9-(1-Assumptions!$B$9)*(1-Assumptions!$B$8)) -> 18559.322
A37: Lehigh | B37: =SUMIF('Municipal Forecast'!$A$5:$A$93,A37,'Municipal Forecast'!$H$5:$H$93) -> 78383.714 | C37: =SUMIF('Municipal Forecast'!$A$5:$A$93,A37,'Municipal Forecast'!$I$5:$I$93) -> 73383.556 | D37: =C10/SUM(C8:C10) -> 0.14064096 | E37: =D37*(B37+C37) -> 21344.695 | F37: =(Assumptions!$B$9*(B37-Assumptions!$B$10*E37)-(1-Assumptions!$B$9)*(C37-(1-Assumptions!$B$10)*E37))/(Assumptions!$B$8*Assumptions!$B$9-(1-Assumptions!$B$9)*(1-Assumptions!$B$8)) -> 65110.301 | G37: =(Assumptions!$B$8*(C37-(1-Assumptions!$B$10)*E37)-(1-Assumptions!$B$8)*(B37-Assumptions!$B$10*E37))/(Assumptions!$B$8*Assumptions!$B$9-(1-Assumptions!$B$9)*(1-Assumptions!$B$8)) -> 65312.274
A38: Monroe | B38: =SUMIF('Municipal Forecast'!$A$5:$A$93,A38,'Municipal Forecast'!$H$5:$H$93) -> 1858.4304 | C38: =SUMIF('Municipal Forecast'!$A$5:$A$93,A38,'Municipal Forecast'!$I$5:$I$93) -> 4152.5796 | D38: =C13/SUM(C11:C13) -> 0.13976378 | E38: =D38*(B38+C38) -> 840.12148 | F38: =(Assumptions!$B$9*(B38-Assumptions!$B$10*E38)-(1-Assumptions!$B$9)*(C38-(1-Assumptions!$B$10)*E38))/(Assumptions!$B$8*Assumptions!$B$9-(1-Assumptions!$B$9)*(1-Assumptions!$B$8)) -> 1098.3124 | G38: =(Assumptions!$B$8*(C38-(1-Assumptions!$B$10)*E38)-(1-Assumptions!$B$8)*(B38-Assumptions!$B$10*E38))/(Assumptions!$B$8*Assumptions!$B$9-(1-Assumptions!$B$9)*(1-Assumptions!$B$8)) -> 4072.5761
A39: Northampton | B39: =SUMIF('Municipal Forecast'!$A$5:$A$93,A39,'Municipal Forecast'!$H$5:$H$93) -> 69576.456 | C39: =SUMIF('Municipal Forecast'!$A$5:$A$93,A39,'Municipal Forecast'!$I$5:$I$93) -> 71443.734 | D39: =C16/SUM(C14:C16) -> 0.15064909 | E39: =D39*(B39+C39) -> 21244.564 | F39: =(Assumptions!$B$9*(B39-Assumptions!$B$10*E39)-(1-Assumptions!$B$9)*(C39-(1-Assumptions!$B$10)*E39))/(Assumptions!$B$8*Assumptions!$B$9-(1-Assumptions!$B$9)*(1-Assumptions!$B$8)) -> 55832.969 | G39: =(Assumptions!$B$8*(C39-(1-Assumptions!$B$10)*E39)-(1-Assumptions!$B$8)*(B39-Assumptions!$B$10*E39))/(Assumptions!$B$8*Assumptions!$B$9-(1-Assumptions!$B$9)*(1-Assumptions!$B$8)) -> 63942.658

Sheet Municipal Forecast
A1: PA-07 2026 Municipal Forecast — Brooks (D) vs. Mackenzie (R)
A2: Baseline = RF backtest share blended with 2024 actual, scaled to midterm turnout, then adjusted by the county mail-return signal. P10/P90 and win odds from 20,000 Monte Carlo runs (static values).
A4: County | B4: Municipality | C4: RF backtest D share | D4: 2024 actual D share | E4: 2024 actual votes | F4: Baseline D share | G4: 2026 total votes | H4: Baseline Brooks | I4: Baseline Mackenzie | J4: Mail adj. Brooks | K4: Mail adj. Mackenzie | L4: Brooks 2026 | M4: Mackenzie 2026 | N4: Brooks share | O4: Swing vs 2024 (pts) | P4: Brooks share P10 | Q4: Brooks share P90 | R4: P(Brooks carries)
A5: Carbon | B5: BANKS TOWNSHIP | C5: 0.31278539 | D5: 0.38841202 | E5: 466 | F5: =Assumptions!$B$5*C5+(1-Assumptions!$B$5)*D5 -> 0.3505987 | G5: =E5*Assumptions!$B$4 -> 377.46 | H5: =G5*F5 -> 132.33699 | I5: =G5-H5 -> 245.12301 | J5: {=INDEX('Mail Projection'!$B$29:$B$32,MATCH(A5,'Mail Projection'!$A$29:$A$32,0))*H5/SUMIF($A$5:$A$93,A5,$H$5:$H$93)} -> -3.1013028 | K5: {=INDEX('Mail Projection'!$C$29:$C$32,MATCH(A5,'Mail Projection'!$A$29:$A$32,0))*I5/SUMIF($A$5:$A$93,A5,$I$5:$I$93)} -> -14.543432 | L5: =H5+J5 -> 129.23568 | M5: =I5+K5 -> 230.57958 | N5: =L5/(L5+M5) -> 0.35917232 | O5: =(N5-D5)*100 -> -2.9239697 | P5: 0.31713734 | Q5: 0.4007788 | R5: 0
A6: Carbon | B6: BEAVER MEADOWS BOROUGH | C6: 0.23267327 | D6: 0.28229665 | E6: 418 | F6: =Assumptions!$B$5*C6+(1-Assumptions!$B$5)*D6 -> 0.25748496 | G6: =E6*Assumptions!$B$4 -> 338.58 | H6: =G6*F6 -> 87.179257 | I6: =G6-H6 -> 251.40074 | J6: {=INDEX('Mail Projection'!$B$29:$B$32,MATCH(A6,'Mail Projection'!$A$29:$A$32,0))*H6/SUMIF($A$5:$A$93,A6,$H$5:$H$93)} -> -2.0430364 | K6: {=INDEX('Mail Projection'!$C$29:$C$32,MATCH(A6,'Mail Projection'!$A$29:$A$32,0))*I6/SUMIF($A$5:$A$93,A6,$I$5:$I$93)} -> -14.915897 | L6: =H6+J6 -> 85.136221 | M6: =I6+K6 -> 236.48485 | N6: =L6/(L6+M6) -> 0.26470972 | O6: =(N6-D6)*100 -> -1.7586935 | P6: 0.22362277 | Q6: 0.30589493 | R6: 0
A7: Carbon | B7: BOWMANSTOWN BOROUGH | C7: 0.32009926 | D7: 0.31718062 | E7: 454 | F7: =Assumptions!$B$5*C7+(1-Assumptions!$B$5)*D7 -> 0.31863994 | G7: =E7*Assumptions!$B$4 -> 367.74 | H7: =G7*F7 -> 117.17665 | I7: =G7-H7 -> 250.56335 | J7: {=INDEX('Mail Projection'!$B$29:$B$32,MATCH(A7,'Mail Projection'!$A$29:$A$32,0))*H7/SUMIF($A$5:$A$93,A7,$H$5:$H$93)} -> -2.746022 | K7: {=INDEX('Mail Projection'!$C$29:$C$32,MATCH(A7,'Mail Projection'!$A$29:$A$32,0))*I7/SUMIF($A$5:$A$93,A7,$I$5:$I$93)} -> -14.866213 | L7: =H7+J7 -> 114.43063 | M7: =I7+K7 -> 235.69714 | N7: =L7/(L7+M7) -> 0.32682535 | O7: =(N7-D7)*100 -> 0.96447301 | P7: 0.28562829 | Q7: 0.36721287 | R7: 0
A8: Carbon | B8: EAST PENN TOWNSHIP | C8: 0.25015873 | D8: 0.25901833 | E8: 1691 | F8: =Assumptions!$B$5*C8+(1-Assumptions!$B$5)*D8 -> 0.25458853 | G8: =E8*Assumptions!$B$4 -> 1369.71 | H8: =G8*F8 -> 348.71246 | I8: =G8-H8 -> 1020.9975 | J8: {=INDEX('Mail Projection'!$B$29:$B$32,MATCH(A8,'Mail Projection'!$A$29:$A$32,0))*H8/SUMIF($A$5:$A$93,A8,$H$5:$H$93)} -> -8.1720382 | K8: {=INDEX('Mail Projection'!$C$29:$C$32,MATCH(A8,'Mail Projection'!$A$29:$A$32,0))*I8/SUMIF($A$5:$A$93,A8,$I$5:$I$93)} -> -60.576965 | L8: =H8+J8 -> 340.54042 | M8: =I8+K8 -> 960.42058 | N8: =L8/(L8+M8) -> 0.26176067 | O8: =(N8-D8)*100 -> 0.27423351 | P8: 0.22092848 | Q8: 0.30204368 | R8: 0
A9: Carbon | B9: EAST SIDE BOROUGH | C9: 0.32142857 | D9: 0.32758621 | E9: 116 | F9: =Assumptions!$B$5*C9+(1-Assumptions!$B$5)*D9 -> 0.32450739 | G9: =E9*Assumptions!$B$4 -> 93.96 | H9: =G9*F9 -> 30.490714 | I9: =G9-H9 -> 63.469286 | J9: {=INDEX('Mail Projection'!$B$29:$B$32,MATCH(A9,'Mail Projection'!$A$29:$A$32,0))*H9/SUMIF($A$5:$A$93,A9,$H$5:$H$93)} -> -0.71454655 | K9: {=INDEX('Mail Projection'!$C$29:$C$32,MATCH(A9,'Mail Projection'!$A$29:$A$32,0))*I9/SUMIF($A$5:$A$93,A9,$I$5:$I$93)} -> -3.7657061 | L9: =H9+J9 -> 29.776168 | M9: =I9+K9 -> 59.70358 | N9: =L9/(L9+M9) -> 0.33276991 | O9: =(N9-D9)*100 -> 0.51837061 | P9: 0.29224911 | Q9: 0.37281296 | R9: 0
A10: Carbon | B10: FRANKLIN TOWNSHIP | C10: 0.25236334 | D10: 0.27721222 | E10: 2554 | F10: =Assumptions!$B$5*C10+(1-Assumptions!$B$5)*D10 -> 0.26478778 | G10: =E10*Assumptions!$B$4 -> 2068.74 | H10: =G10*F10 -> 547.77707 | I10: =G10-H10 -> 1520.9629 | J10: {=INDEX('Mail Projection'!$B$29:$B$32,MATCH(A10,'Mail Projection'!$A$29:$A$32,0))*H10/SUMIF($A$5:$A$93,A10,$H$5:$H$93)} -> -12.837096 | K10: {=INDEX('Mail Projection'!$C$29:$C$32,MATCH(A10,'Mail Projection'!$A$29:$A$32,0))*I10/SUMIF($A$5:$A$93,A10,$I$5:$I$93)} -> -90.24049 | L10: =H10+J10 -> 534.93997 | M10: =I10+K10 -> 1430.7224 | N10: =L10/(L10+M10) -> 0.27214234 | O10: =(N10-D10)*100 -> -0.50698758 | P10: 0.23160542 | Q10: 0.3124161 | R10: 0
A11: Carbon | B11: JIM THORPE BOROUGH | C11: 0.42268041 | D11: 0.4270793 | E11: 2585 | F11: =Assumptions!$B$5*C11+(1-Assumptions!$B$5)*D11 -> 0.42487986 | G11: =E11*Assumptions!$B$4 -> 2093.85 | H11: =G11*F11 -> 889.63469 | I11: =G11-H11 -> 1204.2153 | J11: {=INDEX('Mail Projection'!$B$29:$B$32,MATCH(A11,'Mail Projection'!$A$29:$A$32,0))*H11/SUMIF($A$5:$A$93,A11,$H$5:$H$93)} -> -20.848492 | K11: {=INDEX('Mail Projection'!$C$29:$C$32,MATCH(A11,'Mail Projection'!$A$29:$A$32,0))*I11/SUMIF($A$5:$A$93,A11,$I$5:$I$93)} -> -71.447487 | L11: =H11+J11 -> 868.7862 | M11: =I11+K11 -> 1132.7678 | N11: =L11/(L11+M11) -> 0.43405583 | O11: =(N11-D11)*100 -> 0.69765298 | P11: 0.39342147 | Q11: 0.47458145 | R11: 0.0154
A12: Carbon | B12: KIDDER TOWNSHIP | C12: 0.29411765 | D12: 0.33492366 | E12: 1048 | F12: =Assumptions!$B$5*C12+(1-Assumptions!$B$5)*D12 -> 0.31452066 | G12: =E12*Assumptions!$B$4 -> 848.88 | H12: =G12*F12 -> 266.99029 | I12: =G12-H12 -> 581.88971 | J12: {=INDEX('Mail Projection'!$B$29:$B$32,MATCH(A12,'Mail Projection'!$A$29:$A$32,0))*H12/SUMIF($A$5:$A$93,A12,$H$5:$H$93)} -> -6.2568883 | K12: {=INDEX('Mail Projection'!$C$29:$C$32,MATCH(A12,'Mail Projection'!$A$29:$A$32,0))*I12/SUMIF($A$5:$A$93,A12,$I$5:$I$93)} -> -34.524189 | L12: =H12+J12 -> 260.73341 | M12: =I12+K12 -> 547.36552 | N12: =L12/(L12+M12) -> 0.32265036 | O12: =(N12-D12)*100 -> -1.2273307 | P12: 0.28171008 | Q12: 0.36332809 | R12: 0
A13: Carbon | B13: LANSFORD BOROUGH | C13: 0.39417614 | D13: 0.395189 | E13: 1455 | F13: =Assumptions!$B$5*C13+(1-Assumptions!$B$5)*D13 -> 0.39468257 | G13: =E13*Assumptions!$B$4 -> 1178.55 | H13: =G13*F13 -> 465.15314 | I13: =G13-H13 -> 713.39686 | J13: {=INDEX('Mail Projection'!$B$29:$B$32,MATCH(A13,'Mail Projection'!$A$29:$A$32,0))*H13/SUMIF($A$5:$A$93,A13,$H$5:$H$93)} -> -10.900813 | K13: {=INDEX('Mail Projection'!$C$29:$C$32,MATCH(A13,'Mail Projection'!$A$29:$A$32,0))*I13/SUMIF($A$5:$A$93,A13,$I$5:$I$93)} -> -42.326661 | L13: =H13+J13 -> 454.25233 | M13: =I13+K13 -> 671.0702 | N13: =L13/(L13+M13) -> 0.40366412 | O13: =(N13-D13)*100 -> 0.84751187 | P13: 0.3629792 | Q13: 0.44402706 | R13: 0.0012
A14: Carbon | B14: LAUSANNE TOWNSHIP | C14: 0.27338129 | D14: 0.26206897 | E14: 145 | F14: =Assumptions!$B$5*C14+(1-Assumptions!$B$5)*D14 -> 0.26772513 | G14: =E14*Assumptions!$B$4 -> 117.45 | H14: =G14*F14 -> 31.444317 | I14: =G14-H14 -> 86.005683 | J14: {=INDEX('Mail Projection'!$B$29:$B$32,MATCH(A14,'Mail Projection'!$A$29:$A$32,0))*H14/SUMIF($A$5:$A$93,A14,$H$5:$H$93)} -> -0.73689412 | K14: {=INDEX('Mail Projection'!$C$29:$C$32,MATCH(A14,'Mail Projection'!$A$29:$A$32,0))*I14/SUMIF($A$5:$A$93,A14,$I$5:$I$93)} -> -5.1028167 | L14: =H14+J14 -> 30.707422 | M14: =I14+K14 -> 80.902867 | N14: =L14/(L14+M14) -> 0.27513075 | O14: =(N14-D14)*100 -> 1.3061783 | P14: 0.23460079 | Q14: 0.3157097 | R14: 0
A15: Carbon | B15: LEHIGH TOWNSHIP | C15: 0.18939394 | D15: 0.21167883 | E15: 274 | F15: =Assumptions!$B$5*C15+(1-Assumptions!$B$5)*D15 -> 0.20053639 | G15: =E15*Assumptions!$B$4 -> 221.94 | H15: =G15*F15 -> 44.507045 | I15: =G15-H15 -> 177.43295 | J15: {=INDEX('Mail Projection'!$B$29:$B$32,MATCH(A15,'Mail Projection'!$A$29:$A$32,0))*H15/SUMIF($A$5:$A$93,A15,$H$5:$H$93)} -> -1.0430177 | K15: {=INDEX('Mail Projection'!$C$29:$C$32,MATCH(A15,'Mail Projection'!$A$29:$A$32,0))*I15/SUMIF($A$5:$A$93,A15,$I$5:$I$93)} -> -10.527302 | L15: =H15+J15 -> 43.464028 | M15: =I15+K15 -> 166.90565 | N15: =L15/(L15+M15) -> 0.20660785 | O15: =(N15-D15)*100 -> -0.507098 | P15: 0.16628965 | Q15: 0.24705913 | R15: 0
A16: Carbon | B16: LEHIGHTON BOROUGH | C16: 0.39840989 | D16: 0.38847737 | E16: 2430 | F16: =Assumptions!$B$5*C16+(1-Assumptions!$B$5)*D16 -> 0.39344363 | G16: =E16*Assumptions!$B$4 -> 1968.3 | H16: =G16*F16 -> 774.4151 | I16: =G16-H16 -> 1193.8849 | J16: {=INDEX('Mail Projection'!$B$29:$B$32,MATCH(A16,'Mail Projection'!$A$29:$A$32,0))*H16/SUMIF($A$5:$A$93,A16,$H$5:$H$93)} -> -18.148333 | K16: {=INDEX('Mail Projection'!$C$29:$C$32,MATCH(A16,'Mail Projection'!$A$29:$A$32,0))*I16/SUMIF($A$5:$A$93,A16,$I$5:$I$93)} -> -70.834572 | L16: =H16+J16 -> 756.26676 | M16: =I16+K16 -> 1123.0503 | N16: =L16/(L16+M16) -> 0.40241573 | O16: =(N16-D16)*100 -> 1.3938366 | P16: 0.36137435 | Q16: 0.44238607 | R16: 0.0007
... A93: Northampton | B93: WIND GAP BORO | C93: 0.41939712 | D93: 0.42550336 | E93: 1490 | F93: =Assumptions!$B$5*C93+(1-Assumptions!$B$5)*D93 -> 0.42245024 | G93: =E93*Assumptions!$B$4 -> 1206.9 | H93: =G93*F93 -> 509.85519 | I93: =G93-H93 -> 697.04481 | J93: {=INDEX('Mail Projection'!$B$29:$B$32,MATCH(A93,'Mail Projection'!$A$29:$A$32,0))*H93/SUMIF($A$5:$A$93,A93,$H$5:$H$93)} -> 14.764289 | K93: {=INDEX('Mail Projection'!$C$29:$C$32,MATCH(A93,'Mail Projection'!$A$29:$A$32,0))*I93/SUMIF($A$5:$A$93,A93,$I$5:$I$93)} -> -2.5775192 | L93: =H93+J93 -> 524.61948 | M93: =I93+K93 -> 694.46729 | N93: =L93/(L93+M93) -> 0.4303381 | O93: =(N93-D93)*100 -> 0.48347402 | P93: 0.3900468 | Q93: 0.47044141 | R93: 0.01145
