Workbook

Sheet Scenario & Comparison
A1: PA-07 2026 House Forecast — Municipal Level: three results-only random-forest forecasts
A2: Candidates: Brooks | Mackenzie | Change the yellow cell to set the district-wide Brooks share; all three forecasts update. Turnout = 2022 House votes in every row.
A3: A, B and C weight the same random-forest inputs differently using SHAP (see How Forecasts Are Weighted). Each is backtested on 2024 with its own weights; those errors are the error terms.
A5: SCENARIO
A6: District-wide Brooks share of the two-party vote (input) | C6: =AVERAGE(C10,C12) -> 0.52816948 | D6: ← default: average of the 2018 and 2022 midterms in today’s district
A8: Past House results in today’s district | C8: Democratic share | D8: Democratic votes | E8: Republican votes
A9: (certified precinct returns; Carbon and Polk 2018/2020 excluded — they voted in PA-09/PA-08)
A10: 2018 General | C10: =D10/(D10+E10) -> 0.54737325 | D10: 126510 | E10: 104612
A11: 2020 General | C11: =D11/(D11+E11) -> 0.51437081 | D11: 176154 | E11: 166311
A12: 2022 General | C12: =D12/(D12+E12) -> 0.50896572 | D12: 149243 | E12: 143985
A13: 2024 General | C13: =D13/(D13+E13) -> 0.49424813 | D13: 196561 | E13: 201136
A15: DISTRICT TOTALS BY FORECAST (live from each forecast tab)
A16: Forecast | B16: Weighting | C16: Brooks votes | D16: Mackenzie votes | E16: Total votes (2022 turnout) | F16: Brooks share | G16: Error term (± pts) | H16: Brooks share range | I16: Error term, Brooks votes (±)
A17: Forecast A | B17: Full random forest | C17: ='2026 Forecast A'!D8 -> 156807 | D17: ='2026 Forecast A'!E8 -> 140084 | E17: ='2026 Forecast A'!F8 -> 296891 | F17: ='2026 Forecast A'!G8 -> 0.52816353 | G17: ='2026 Forecast A'!J8 -> 1.9409982 | H17: =TEXT('2026 Forecast A'!K8,"0.0%")&" – "&TEXT('2026 Forecast A'!L8,"0.0%") -> 50.9% – 54.8% | I17: ='2026 Forecast A'!M8 -> 5763
A18: Forecast B | B18: SHAP-selected forest | C18: ='2026 Forecast B'!D8 -> 156809 | D18: ='2026 Forecast B'!E8 -> 140082 | E18: ='2026 Forecast B'!F8 -> 296891 | F18: ='2026 Forecast B'!G8 -> 0.52817027 | G18: ='2026 Forecast B'!J8 -> 1.9402291 | H18: =TEXT('2026 Forecast B'!K8,"0.0%")&" – "&TEXT('2026 Forecast B'!L8,"0.0%") -> 50.9% – 54.8% | I18: ='2026 Forecast B'!M8 -> 5760
A19: Forecast C | B19: SHAP family-reweighted forest | C19: ='2026 Forecast C'!D8 -> 156805 | D19: ='2026 Forecast C'!E8 -> 140086 | E19: ='2026 Forecast C'!F8 -> 296891 | F19: ='2026 Forecast C'!G8 -> 0.5281568 | G19: ='2026 Forecast C'!J8 -> 1.9412546 | H19: =TEXT('2026 Forecast C'!K8,"0.0%")&" – "&TEXT('2026 Forecast C'!L8,"0.0%") -> 50.9% – 54.8% | I19: ='2026 Forecast C'!M8 -> 5763
A21: ERROR TERMS — 2024 BACKTEST OF EACH FORECAST (same weights as the forecast)
A22: Forecast | B22: Rows scored | C22: Avg miss per row, Dem share (pts) | D22: RMS miss per row, Dem share (pts) | E22: District-wide miss (pts) | F22: Pattern RMS miss (pts) | G22: Rows within 3 pts | H22: Avg miss per row, Dem votes | I22: Votes cast miss (turnout rule)
A23: Forecast A | B23: ='2024 Backtest A'!F103 -> 89 | C23: ='2024 Backtest A'!F97 -> 2.4493156 | D23: ='2024 Backtest A'!F98 -> 2.9050972 | E23: ='2024 Backtest A'!F99 -> 1.9409982 | F23: ='2024 Backtest A'!F100 -> 1.809898 | G23: ='2024 Backtest A'!F102 -> 0.70786517 | H23: ='2024 Backtest A'!F95 -> 84.921348 | I23: ='2024 Backtest A'!F101 -> -0.032914801
A24: Forecast B | B24: ='2024 Backtest B'!F103 -> 89 | C24: ='2024 Backtest B'!F97 -> 2.5350963 | D24: ='2024 Backtest B'!F98 -> 3.0499315 | E24: ='2024 Backtest B'!F99 -> 1.9402291 | F24: ='2024 Backtest B'!F100 -> 1.9868101 | G24: ='2024 Backtest B'!F102 -> 0.68539326 | H24: ='2024 Backtest B'!F95 -> 81.674157 | I24: ='2024 Backtest B'!F101 -> -0.032914801
A25: Forecast C | B25: ='2024 Backtest C'!F103 -> 89 | C25: ='2024 Backtest C'!F97 -> 1.8166194 | D25: ='2024 Backtest C'!F98 -> 2.3124552 | E25: ='2024 Backtest C'!F99 -> 1.9412546 | F25: ='2024 Backtest C'!F100 -> 1.8991208 | G25: ='2024 Backtest C'!F102 -> 0.79775281 | H25: ='2024 Backtest C'!F95 -> 93.921348 | I25: ='2024 Backtest C'!F101 -> -0.032914801
A26: District-wide miss comes from the level rule (last same-type election), so it is nearly identical for all three; the pattern miss is what separates them. The votes-cast miss shows how far "same turnout as the last same-type election" was off in 2024.
A28: MUNICIPALITY COMPARISON (Brooks share by forecast, live)
A29: County | B29: Municipality | C29: Area | D29: Forecast A | E29: Forecast B | F29: Forecast C | G29: Spread (max − min, pts) | H29: Error term A (± pts) | I29: Error term B (± pts) | J29: Error term C (± pts) | K29: Votes cast (2022) | L29: Calls agree?
A30: ='2026 Forecast A'!A12 -> Carbon | B30: ='2026 Forecast A'!B12 -> BANKS TOWNSHIP | C30: ='2026 Forecast A'!C12 -> (whole municipality) | D30: ='2026 Forecast A'!G12 -> 0.42227979 | E30: ='2026 Forecast B'!G12 -> 0.42746114 | F30: ='2026 Forecast C'!G12 -> 0.42746114 | G30: =(MAX(D30:F30)-MIN(D30:F30))*100 -> 0.51813472 | H30: ='2026 Forecast A'!J12 -> 2.5271346 | I30: ='2026 Forecast B'!J12 -> 2.7059882 | J30: ='2026 Forecast C'!J12 -> 2.3992519 | K30: ='2026 Forecast A'!F12 -> 386 | L30: =IF(OR(AND(D30>0.5,E30>0.5,F30>0.5),AND(D30<0.5,E30<0.5,F30<0.5)),"Yes","No — toss-up") -> Yes
A31: ='2026 Forecast A'!A13 -> Carbon | B31: ='2026 Forecast A'!B13 -> BEAVER MEADOWS BOROUGH | C31: ='2026 Forecast A'!C13 -> (whole municipality) | D31: ='2026 Forecast A'!G13 -> 0.32165605 | E31: ='2026 Forecast B'!G13 -> 0.32484076 | F31: ='2026 Forecast C'!G13 -> 0.31210191 | G31: =(MAX(D31:F31)-MIN(D31:F31))*100 -> 1.2738854 | H31: ='2026 Forecast A'!J13 -> 2.5271346 | I31: ='2026 Forecast B'!J13 -> 2.7059882 | J31: ='2026 Forecast C'!J13 -> 2.3992519 | K31: ='2026 Forecast A'!F13 -> 314 | L31: =IF(OR(AND(D31>0.5,E31>0.5,F31>0.5),AND(D31<0.5,E31<0.5,F31<0.5)),"Yes","No — toss-up") -> Yes
A32: ='2026 Forecast A'!A14 -> Carbon | B32: ='2026 Forecast A'!B14 -> BOWMANSTOWN BOROUGH | C32: ='2026 Forecast A'!C14 -> (whole municipality) | D32: ='2026 Forecast A'!G14 -> 0.36494253 | E32: ='2026 Forecast B'!G14 -> 0.36781609 | F32: ='2026 Forecast C'!G14 -> 0.35344828 | G32: =(MAX(D32:F32)-MIN(D32:F32))*100 -> 1.4367816 | H32: ='2026 Forecast A'!J14 -> 2.5271346 | I32: ='2026 Forecast B'!J14 -> 2.7059882 | J32: ='2026 Forecast C'!J14 -> 2.3992519 | K32: ='2026 Forecast A'!F14 -> 348 | L32: =IF(OR(AND(D32>0.5,E32>0.5,F32>0.5),AND(D32<0.5,E32<0.5,F32<0.5)),"Yes","No — toss-up") -> Yes
A33: ='2026 Forecast A'!A15 -> Carbon | B33: ='2026 Forecast A'!B15 -> EAST PENN TOWNSHIP | C33: ='2026 Forecast A'!C15 -> (whole municipality) | D33: ='2026 Forecast A'!G15 -> 0.31148805 | E33: ='2026 Forecast B'!G15 -> 0.3153431 | F33: ='2026 Forecast C'!G15 -> 0.29606785 | G33: =(MAX(D33:F33)-MIN(D33:F33))*100 -> 1.9275251 | H33: ='2026 Forecast A'!J15 -> 2.5271346 | I33: ='2026 Forecast B'!J15 -> 2.7059882 | J33: ='2026 Forecast C'!J15 -> 2.3992519 | K33: ='2026 Forecast A'!F15 -> 1297 | L33: =IF(OR(AND(D33>0.5,E33>0.5,F33>0.5),AND(D33<0.5,E33<0.5,F33<0.5)),"Yes","No — toss-up") -> Yes
A34: ='2026 Forecast A'!A16 -> Carbon | B34: ='2026 Forecast A'!B16 -> EAST SIDE BOROUGH | C34: ='2026 Forecast A'!C16 -> (whole municipality) | D34: ='2026 Forecast A'!G16 -> 0.38297872 | E34: ='2026 Forecast B'!G16 -> 0.38297872 | F34: ='2026 Forecast C'!G16 -> 0.37234043 | G34: =(MAX(D34:F34)-MIN(D34:F34))*100 -> 1.0638298 | H34: ='2026 Forecast A'!J16 -> 2.5271346 | I34: ='2026 Forecast B'!J16 -> 2.7059882 | J34: ='2026 Forecast C'!J16 -> 2.3992519 | K34: ='2026 Forecast A'!F16 -> 94 | L34: =IF(OR(AND(D34>0.5,E34>0.5,F34>0.5),AND(D34<0.5,E34<0.5,F34<0.5)),"Yes","No — toss-up") -> Yes
A35: ='2026 Forecast A'!A17 -> Carbon | B35: ='2026 Forecast A'!B17 -> FRANKLIN TOWNSHIP | C35: ='2026 Forecast A'!C17 -> (whole municipality) | D35: ='2026 Forecast A'!G17 -> 0.32226762 | E35: ='2026 Forecast B'!G17 -> 0.31971399 | F35: ='2026 Forecast C'!G17 -> 0.30898876 | G35: =(MAX(D35:F35)-MIN(D35:F35))*100 -> 1.3278856 | H35: ='2026 Forecast A'!J17 -> 1.487633 | I35: ='2026 Forecast B'!J17 -> 1.7997491 | J35: ='2026 Forecast C'!J17 -> 1.3223778 | K35: ='2026 Forecast A'!F17 -> 1958 | L35: =IF(OR(AND(D35>0.5,E35>0.5,F35>0.5),AND(D35<0.5,E35<0.5,F35<0.5)),"Yes","No — toss-up") -> Yes
A36: ='2026 Forecast A'!A18 -> Carbon | B36: ='2026 Forecast A'!B18 -> JIM THORPE BOROUGH | C36: ='2026 Forecast A'!C18 -> (whole municipality) | D36: ='2026 Forecast A'!G18 -> 0.48127341 | E36: ='2026 Forecast B'!G18 -> 0.48174157 | F36: ='2026 Forecast C'!G18 -> 0.47705993 | G36: =(MAX(D36:F36)-MIN(D36:F36))*100 -> 0.46816479 | H36: ='2026 Forecast A'!J18 -> 1.487633 | I36: ='2026 Forecast B'!J18 -> 1.7997491 | J36: ='2026 Forecast C'!J18 -> 1.3223778 | K36: ='2026 Forecast A'!F18 -> 2136 | L36: =IF(OR(AND(D36>0.5,E36>0.5,F36>0.5),AND(D36<0.5,E36<0.5,F36<0.5)),"Yes","No — toss-up") -> Yes
A37: ='2026 Forecast A'!A19 -> Carbon | B37: ='2026 Forecast A'!B19 -> KIDDER TOWNSHIP | C37: ='2026 Forecast A'!C19 -> (whole municipality) | D37: ='2026 Forecast A'!G19 -> 0.37156511 | E37: ='2026 Forecast B'!G19 -> 0.3739546 | F37: ='2026 Forecast C'!G19 -> 0.35603345 | G37: =(MAX(D37:F37)-MIN(D37:F37))*100 -> 1.7921147 | H37: ='2026 Forecast A'!J19 -> 2.5271346 | I37: ='2026 Forecast B'!J19 -> 2.7059882 | J37: ='2026 Forecast C'!J19 -> 2.3992519 | K37: ='2026 Forecast A'!F19 -> 837 | L37: =IF(OR(AND(D37>0.5,E37>0.5,F37>0.5),AND(D37<0.5,E37<0.5,F37<0.5)),"Yes","No — toss-up") -> Yes
A38: ='2026 Forecast A'!A20 -> Carbon | B38: ='2026 Forecast A'!B20 -> LANSFORD BOROUGH | C38: ='2026 Forecast A'!C20 -> (whole municipality) | D38: ='2026 Forecast A'!G20 -> 0.438 | E38: ='2026 Forecast B'!G20 -> 0.446 | F38: ='2026 Forecast C'!G20 -> 0.44 | G38: =(MAX(D38:F38)-MIN(D38:F38))*100 -> 0.8 | H38: ='2026 Forecast A'!J20 -> 2.5271346 | I38: ='2026 Forecast B'!J20 -> 2.7059882 | J38: ='2026 Forecast C'!J20 -> 2.3992519 | K38: ='2026 Forecast A'!F20 -> 1000 | L38: =IF(OR(AND(D38>0.5,E38>0.5,F38>0.5),AND(D38<0.5,E38<0.5,F38<0.5)),"Yes","No — toss-up") -> Yes
A39: ='2026 Forecast A'!A21 -> Carbon | B39: ='2026 Forecast A'!B21 -> LAUSANNE TOWNSHIP | C39: ='2026 Forecast A'!C21 -> (whole municipality) | D39: ='2026 Forecast A'!G21 -> 0.32173913 | E39: ='2026 Forecast B'!G21 -> 0.32173913 | F39: ='2026 Forecast C'!G21 -> 0.30434783 | G39: =(MAX(D39:F39)-MIN(D39:F39))*100 -> 1.7391304 | H39: ='2026 Forecast A'!J21 -> 2.5271346 | I39: ='2026 Forecast B'!J21 -> 2.7059882 | J39: ='2026 Forecast C'!J21 -> 2.3992519 | K39: ='2026 Forecast A'!F21 -> 115 | L39: =IF(OR(AND(D39>0.5,E39>0.5,F39>0.5),AND(D39<0.5,E39<0.5,F39<0.5)),"Yes","No — toss-up") -> Yes
A40: ='2026 Forecast A'!A22 -> Carbon | B40: ='2026 Forecast A'!B22 -> LEHIGH TOWNSHIP | C40: ='2026 Forecast A'!C22 -> (whole municipality) | D40: ='2026 Forecast A'!G22 -> 0.24481328 | E40: ='2026 Forecast B'!G22 -> 0.25311203 | F40: ='2026 Forecast C'!G22 -> 0.21576763 | G40: =(MAX(D40:F40)-MIN(D40:F40))*100 -> 3.7344398 | H40: ='2026 Forecast A'!J22 -> 2.5271346 | I40: ='2026 Forecast B'!J22 -> 2.7059882 | J40: ='2026 Forecast C'!J22 -> 2.3992519 | K40: ='2026 Forecast A'!F22 -> 241 | L40: =IF(OR(AND(D40>0.5,E40>0.5,F40>0.5),AND(D40<0.5,E40<0.5,F40<0.5)),"Yes","No — toss-up") -> Yes
A41: ='2026 Forecast A'!A23 -> Carbon | B41: ='2026 Forecast A'!B23 -> LEHIGHTON BOROUGH | C41: ='2026 Forecast A'!C23 -> (whole municipality) | D41: ='2026 Forecast A'!G23 -> 0.43731254 | E41: ='2026 Forecast B'!G23 -> 0.44211158 | F41: ='2026 Forecast C'!G23 -> 0.42891422 | G41: =(MAX(D41:F41)-MIN(D41:F41))*100 -> 1.3197361 | H41: ='2026 Forecast A'!J23 -> 1.487633 | I41: ='2026 Forecast B'!J23 -> 1.7997491 | J41: ='2026 Forecast C'!J23 -> 1.3223778 | K41: ='2026 Forecast A'!F23 -> 1667 | L41: =IF(OR(AND(D41>0.5,E41>0.5,F41>0.5),AND(D41<0.5,E41<0.5,F41<0.5)),"Yes","No — toss-up") -> Yes
... A118: ='2026 Forecast A'!A100 -> Northampton | B118: ='2026 Forecast A'!B100 -> WIND GAP | C118: ='2026 Forecast A'!C100 -> (whole municipality) | D118: ='2026 Forecast A'!G100 -> 0.46940639 | E118: ='2026 Forecast B'!G100 -> 0.46757991 | F118: ='2026 Forecast C'!G100 -> 0.46118721 | G118: =(MAX(D118:F118)-MIN(D118:F118))*100 -> 0.82191781 | H118: ='2026 Forecast A'!J100 -> 2.5271346 | I118: ='2026 Forecast B'!J100 -> 2.7059882 | J118: ='2026 Forecast C'!J100 -> 2.3992519 | K118: ='2026 Forecast A'!F100 -> 1095 | L118: =IF(OR(AND(D118>0.5,E118>0.5,F118>0.5),AND(D118<0.5,E118<0.5,F118<0.5)),"Yes","No — toss-up") -> Yes

Sheet 2026 Forecast A
A1: PA-07 2026 House Forecast — Municipal-Level Predictions (Forecast A: full random forest)
A2: Candidates: Brooks | Mackenzie | District totals (yellow) are formulas over the municipality rows.
A3: Only the results are modelled. Votes cast in each row = that row’s 2022 House votes (turnout similar to 2022). Brooks votes = 2022 votes × forecast Brooks share. Change the district scenario on the Scenario & Comparison tab.
A4: Model / scenario | B4: Random forest on results — Forecast A (Full random forest), municipality model; turnout = 2022 | C4: As-of date | D4: 46300 | E4: Prepared by | F4: Max | G4: Version | H4: v2.0 (results only)
A5: District Brooks share (scenario) | B5: ='Scenario & Comparison'!$C$6 -> 0.52816948 | C5: Uniform shift applied | D5: =B5-SUMPRODUCT(P12:P100,Q12:Q100)/SUM(Q12:Q100)/100 -> 0.44128518 | E5: 2024 backtest district miss (pts) | F5: 1.9409982
A6: DISTRICT TOTALS (auto-sum — do not type over)
A7: Geography | B7: (muni) | C7: (area) | D7: Brooks votes | E7: Mackenzie votes | F7: Total votes | G7: Brooks share | H7: Mackenzie share | I7: Notes | J7: Error term: Brooks share (± pts) | K7: Brooks share, low | L7: Brooks share, high | M7: Error term: Brooks votes (± votes)
A8: PA-07 District | B8: (all municipalities) | D8: =SUM(D12:D100) -> 156807 | E8: =SUM(E12:E100) -> 140084 | F8: =D8+E8 -> 296891 | G8: =IF(F8=0,"",D8/F8) -> 0.52816353 | H8: =IF(F8=0,"",E8/F8) -> 0.47183647 | I8: Headline forecast for the briefing | J8: 1.9409982 | K8: =G8-J8/100 -> 0.50875355 | L8: =G8+J8/100 -> 0.54757352 | M8: =ROUND(F8*J8/100,0) -> 5763
A9: Error terms: each row = ±1 root-mean-square miss of this forecast in its 2024 backtest for places of similar size, after removing the district-wide miss. District row = the district-wide miss. Turnout is held at 2022, so no turnout error is included.
A10: MUNICIPALITY DETAIL | P10: MODEL INPUTS (from the random forest — do not edit)
A11: County | B11: Municipality | C11: Area | D11: Brooks votes | E11: Mackenzie votes | F11: Total votes | G11: Brooks share | H11: Mackenzie share | I11: Notes / source method | J11: Error term: Brooks share (± pts) | K11: Brooks share, low | L11: Brooks share, high | M11: Error term: Brooks votes (± votes) | P11: Model lean vs district (pts) | Q11: Votes cast (2022 House votes) | R11: Forecast Brooks share (unrounded) | S11: Size group (backtest error band)
A12: Carbon | B12: BANKS TOWNSHIP | C12: (whole municipality) | D12: =ROUND(Q12*R12,0) -> 163 | E12: =ROUND(Q12,0)-D12 -> 223 | F12: =IF(COUNTA(D12:E12)=0,"",SUM(D12:E12)) -> 386 | G12: =IF(OR(F12="",F12=0),"",D12/F12) -> 0.42227979 | H12: =IF(OR(F12="",F12=0),"",E12/F12) -> 0.57772021 | I12: random forest (results only) | J12: 2.5271346 | K12: =IF(G12="","",MAX(0,G12-J12/100)) -> 0.39700845 | L12: =IF(G12="","",MIN(1,G12+J12/100)) -> 0.44755114 | M12: =IF(F12="","",ROUND(F12*J12/100,0)) -> 10 | P12: -1.949499 | Q12: 386 | R12: =MAX(0,MIN(1,P12/100+$D$5)) -> 0.42179019 | S12: Small
A13: Carbon | B13: BEAVER MEADOWS BOROUGH | C13: (whole municipality) | D13: =ROUND(Q13*R13,0) -> 101 | E13: =ROUND(Q13,0)-D13 -> 213 | F13: =IF(COUNTA(D13:E13)=0,"",SUM(D13:E13)) -> 314 | G13: =IF(OR(F13="",F13=0),"",D13/F13) -> 0.32165605 | H13: =IF(OR(F13="",F13=0),"",E13/F13) -> 0.67834395 | I13: random forest (results only) | J13: 2.5271346 | K13: =IF(G13="","",MAX(0,G13-J13/100)) -> 0.29638471 | L13: =IF(G13="","",MIN(1,G13+J13/100)) -> 0.3469274 | M13: =IF(F13="","",ROUND(F13*J13/100,0)) -> 8 | P13: -11.904994 | Q13: 314 | R13: =MAX(0,MIN(1,P13/100+$D$5)) -> 0.32223525 | S13: Small
A14: Carbon | B14: BOWMANSTOWN BOROUGH | C14: (whole municipality) | D14: =ROUND(Q14*R14,0) -> 127 | E14: =ROUND(Q14,0)-D14 -> 221 | F14: =IF(COUNTA(D14:E14)=0,"",SUM(D14:E14)) -> 348 | G14: =IF(OR(F14="",F14=0),"",D14/F14) -> 0.36494253 | H14: =IF(OR(F14="",F14=0),"",E14/F14) -> 0.63505747 | I14: random forest (results only) | J14: 2.5271346 | K14: =IF(G14="","",MAX(0,G14-J14/100)) -> 0.33967118 | L14: =IF(G14="","",MIN(1,G14+J14/100)) -> 0.39021387 | M14: =IF(F14="","",ROUND(F14*J14/100,0)) -> 9 | P14: -7.5856383 | Q14: 348 | R14: =MAX(0,MIN(1,P14/100+$D$5)) -> 0.3654288 | S14: Small
A15: Carbon | B15: EAST PENN TOWNSHIP | C15: (whole municipality) | D15: =ROUND(Q15*R15,0) -> 404 | E15: =ROUND(Q15,0)-D15 -> 893 | F15: =IF(COUNTA(D15:E15)=0,"",SUM(D15:E15)) -> 1297 | G15: =IF(OR(F15="",F15=0),"",D15/F15) -> 0.31148805 | H15: =IF(OR(F15="",F15=0),"",E15/F15) -> 0.68851195 | I15: random forest (results only) | J15: 2.5271346 | K15: =IF(G15="","",MAX(0,G15-J15/100)) -> 0.2862167 | L15: =IF(G15="","",MIN(1,G15+J15/100)) -> 0.3367594 | M15: =IF(F15="","",ROUND(F15*J15/100,0)) -> 33 | P15: -12.972555 | Q15: 1297 | R15: =MAX(0,MIN(1,P15/100+$D$5)) -> 0.31155963 | S15: Small
A16: Carbon | B16: EAST SIDE BOROUGH | C16: (whole municipality) | D16: =ROUND(Q16*R16,0) -> 36 | E16: =ROUND(Q16,0)-D16 -> 58 | F16: =IF(COUNTA(D16:E16)=0,"",SUM(D16:E16)) -> 94 | G16: =IF(OR(F16="",F16=0),"",D16/F16) -> 0.38297872 | H16: =IF(OR(F16="",F16=0),"",E16/F16) -> 0.61702128 | I16: random forest (results only) | J16: 2.5271346 | K16: =IF(G16="","",MAX(0,G16-J16/100)) -> 0.35770738 | L16: =IF(G16="","",MIN(1,G16+J16/100)) -> 0.40825007 | M16: =IF(F16="","",ROUND(F16*J16/100,0)) -> 2 | P16: -5.6796433 | Q16: 94 | R16: =MAX(0,MIN(1,P16/100+$D$5)) -> 0.38448875 | S16: Small
A17: Carbon | B17: FRANKLIN TOWNSHIP | C17: (whole municipality) | D17: =ROUND(Q17*R17,0) -> 631 | E17: =ROUND(Q17,0)-D17 -> 1327 | F17: =IF(COUNTA(D17:E17)=0,"",SUM(D17:E17)) -> 1958 | G17: =IF(OR(F17="",F17=0),"",D17/F17) -> 0.32226762 | H17: =IF(OR(F17="",F17=0),"",E17/F17) -> 0.67773238 | I17: random forest (results only) | J17: 1.487633 | K17: =IF(G17="","",MAX(0,G17-J17/100)) -> 0.30739129 | L17: =IF(G17="","",MIN(1,G17+J17/100)) -> 0.33714395 | M17: =IF(F17="","",ROUND(F17*J17/100,0)) -> 29 | P17: -11.90247 | Q17: 1958 | R17: =MAX(0,MIN(1,P17/100+$D$5)) -> 0.32226049 | S17: Medium
A18: Carbon | B18: JIM THORPE BOROUGH | C18: (whole municipality) | D18: =ROUND(Q18*R18,0) -> 1028 | E18: =ROUND(Q18,0)-D18 -> 1108 | F18: =IF(COUNTA(D18:E18)=0,"",SUM(D18:E18)) -> 2136 | G18: =IF(OR(F18="",F18=0),"",D18/F18) -> 0.48127341 | H18: =IF(OR(F18="",F18=0),"",E18/F18) -> 0.51872659 | I18: random forest (results only) | J18: 1.487633 | K18: =IF(G18="","",MAX(0,G18-J18/100)) -> 0.46639708 | L18: =IF(G18="","",MIN(1,G18+J18/100)) -> 0.49614974 | M18: =IF(F18="","",ROUND(F18*J18/100,0)) -> 32 | P18: 3.9947459 | Q18: 2136 | R18: =MAX(0,MIN(1,P18/100+$D$5)) -> 0.48123264 | S18: Medium
A19: Carbon | B19: KIDDER TOWNSHIP | C19: (whole municipality) | D19: =ROUND(Q19*R19,0) -> 311 | E19: =ROUND(Q19,0)-D19 -> 526 | F19: =IF(COUNTA(D19:E19)=0,"",SUM(D19:E19)) -> 837 | G19: =IF(OR(F19="",F19=0),"",D19/F19) -> 0.37156511 | H19: =IF(OR(F19="",F19=0),"",E19/F19) -> 0.62843489 | I19: random forest (results only) | J19: 2.5271346 | K19: =IF(G19="","",MAX(0,G19-J19/100)) -> 0.34629377 | L19: =IF(G19="","",MIN(1,G19+J19/100)) -> 0.39683646 | M19: =IF(F19="","",ROUND(F19*J19/100,0)) -> 21 | P19: -6.9894018 | Q19: 837 | R19: =MAX(0,MIN(1,P19/100+$D$5)) -> 0.37139117 | S19: Small
A20: Carbon | B20: LANSFORD BOROUGH | C20: (whole municipality) | D20: =ROUND(Q20*R20,0) -> 438 | E20: =ROUND(Q20,0)-D20 -> 562 | F20: =IF(COUNTA(D20:E20)=0,"",SUM(D20:E20)) -> 1000 | G20: =IF(OR(F20="",F20=0),"",D20/F20) -> 0.438 | H20: =IF(OR(F20="",F20=0),"",E20/F20) -> 0.562 | I20: random forest (results only) | J20: 2.5271346 | K20: =IF(G20="","",MAX(0,G20-J20/100)) -> 0.41272865 | L20: =IF(G20="","",MIN(1,G20+J20/100)) -> 0.46327135 | M20: =IF(F20="","",ROUND(F20*J20/100,0)) -> 25 | P20: -0.28059531 | Q20: 1000 | R20: =MAX(0,MIN(1,P20/100+$D$5)) -> 0.43847923 | S20: Small
A21: Carbon | B21: LAUSANNE TOWNSHIP | C21: (whole municipality) | D21: =ROUND(Q21*R21,0) -> 37 | E21: =ROUND(Q21,0)-D21 -> 78 | F21: =IF(COUNTA(D21:E21)=0,"",SUM(D21:E21)) -> 115 | G21: =IF(OR(F21="",F21=0),"",D21/F21) -> 0.32173913 | H21: =IF(OR(F21="",F21=0),"",E21/F21) -> 0.67826087 | I21: random forest (results only) | J21: 2.5271346 | K21: =IF(G21="","",MAX(0,G21-J21/100)) -> 0.29646778 | L21: =IF(G21="","",MIN(1,G21+J21/100)) -> 0.34701048 | M21: =IF(F21="","",ROUND(F21*J21/100,0)) -> 3 | P21: -11.988803 | Q21: 115 | R21: =MAX(0,MIN(1,P21/100+$D$5)) -> 0.32139716 | S21: Small
A22: Carbon | B22: LEHIGH TOWNSHIP | C22: (whole municipality) | D22: =ROUND(Q22*R22,0) -> 59 | E22: =ROUND(Q22,0)-D22 -> 182 | F22: =IF(COUNTA(D22:E22)=0,"",SUM(D22:E22)) -> 241 | G22: =IF(OR(F22="",F22=0),"",D22/F22) -> 0.24481328 | H22: =IF(OR(F22="",F22=0),"",E22/F22) -> 0.75518672 | I22: random forest (results only) | J22: 2.5271346 | K22: =IF(G22="","",MAX(0,G22-J22/100)) -> 0.21954193 | L22: =IF(G22="","",MIN(1,G22+J22/100)) -> 0.27008462 | M22: =IF(F22="","",ROUND(F22*J22/100,0)) -> 6 | P22: -19.804641 | Q22: 241 | R22: =MAX(0,MIN(1,P22/100+$D$5)) -> 0.24323877 | S22: Small
A23: Carbon | B23: LEHIGHTON BOROUGH | C23: (whole municipality) | D23: =ROUND(Q23*R23,0) -> 729 | E23: =ROUND(Q23,0)-D23 -> 938 | F23: =IF(COUNTA(D23:E23)=0,"",SUM(D23:E23)) -> 1667 | G23: =IF(OR(F23="",F23=0),"",D23/F23) -> 0.43731254 | H23: =IF(OR(F23="",F23=0),"",E23/F23) -> 0.56268746 | I23: random forest (results only) | J23: 1.487633 | K23: =IF(G23="","",MAX(0,G23-J23/100)) -> 0.42243621 | L23: =IF(G23="","",MIN(1,G23+J23/100)) -> 0.45218887 | M23: =IF(F23="","",ROUND(F23*J23/100,0)) -> 25 | P23: -0.38575102 | Q23: 1667 | R23: =MAX(0,MIN(1,P23/100+$D$5)) -> 0.43742767 | S23: Medium
... A100: Northampton | B100: WIND GAP | C100: (whole municipality) | D100: =ROUND(Q100*R100,0) -> 514 | E100: =ROUND(Q100,0)-D100 -> 581 | F100: =IF(COUNTA(D100:E100)=0,"",SUM(D100:E100)) -> 1095 | G100: =IF(OR(F100="",F100=0),"",D100/F100) -> 0.46940639 | H100: =IF(OR(F100="",F100=0),"",E100/F100) -> 0.53059361 | I100: random forest (results only) | J100: 2.5271346 | K100: =IF(G100="","",MAX(0,G100-J100/100)) -> 0.44413505 | L100: =IF(G100="","",MIN(1,G100+J100/100)) -> 0.49467774 | M100: =IF(F100="","",ROUND(F100*J100/100,0)) -> 28 | P100: 2.8503602 | Q100: 1095 | R100: =MAX(0,MIN(1,P100/100+$D$5)) -> 0.46978879 | S100: Small

Sheet 2026 Forecast B
A1: PA-07 2026 House Forecast — Municipal-Level Predictions (Forecast B: shap-selected forest)
A2: Candidates: Brooks | Mackenzie | District totals (yellow) are formulas over the municipality rows.
A3: Only the results are modelled. Votes cast in each row = that row’s 2022 House votes (turnout similar to 2022). Brooks votes = 2022 votes × forecast Brooks share. Change the district scenario on the Scenario & Comparison tab.
A4: Model / scenario | B4: Random forest on results — Forecast B (SHAP-selected forest), municipality model; turnout = 2022 | C4: As-of date | D4: 46300 | E4: Prepared by | F4: Max | G4: Version | H4: v2.0 (results only)
A5: District Brooks share (scenario) | B5: ='Scenario & Comparison'!$C$6 -> 0.52816948 | C5: Uniform shift applied | D5: =B5-SUMPRODUCT(P12:P100,Q12:Q100)/SUM(Q12:Q100)/100 -> 0.44626036 | E5: 2024 backtest district miss (pts) | F5: 1.9402291
A6: DISTRICT TOTALS (auto-sum — do not type over)
A7: Geography | B7: (muni) | C7: (area) | D7: Brooks votes | E7: Mackenzie votes | F7: Total votes | G7: Brooks share | H7: Mackenzie share | I7: Notes | J7: Error term: Brooks share (± pts) | K7: Brooks share, low | L7: Brooks share, high | M7: Error term: Brooks votes (± votes)
A8: PA-07 District | B8: (all municipalities) | D8: =SUM(D12:D100) -> 156809 | E8: =SUM(E12:E100) -> 140082 | F8: =D8+E8 -> 296891 | G8: =IF(F8=0,"",D8/F8) -> 0.52817027 | H8: =IF(F8=0,"",E8/F8) -> 0.47182973 | I8: Headline forecast for the briefing | J8: 1.9402291 | K8: =G8-J8/100 -> 0.50876798 | L8: =G8+J8/100 -> 0.54757256 | M8: =ROUND(F8*J8/100,0) -> 5760
A9: Error terms: each row = ±1 root-mean-square miss of this forecast in its 2024 backtest for places of similar size, after removing the district-wide miss. District row = the district-wide miss. Turnout is held at 2022, so no turnout error is included.
A10: MUNICIPALITY DETAIL | P10: MODEL INPUTS (from the random forest — do not edit)
A11: County | B11: Municipality | C11: Area | D11: Brooks votes | E11: Mackenzie votes | F11: Total votes | G11: Brooks share | H11: Mackenzie share | I11: Notes / source method | J11: Error term: Brooks share (± pts) | K11: Brooks share, low | L11: Brooks share, high | M11: Error term: Brooks votes (± votes) | P11: Model lean vs district (pts) | Q11: Votes cast (2022 House votes) | R11: Forecast Brooks share (unrounded) | S11: Size group (backtest error band)
A12: Carbon | B12: BANKS TOWNSHIP | C12: (whole municipality) | D12: =ROUND(Q12*R12,0) -> 165 | E12: =ROUND(Q12,0)-D12 -> 221 | F12: =IF(COUNTA(D12:E12)=0,"",SUM(D12:E12)) -> 386 | G12: =IF(OR(F12="",F12=0),"",D12/F12) -> 0.42746114 | H12: =IF(OR(F12="",F12=0),"",E12/F12) -> 0.57253886 | I12: random forest (results only) | J12: 2.7059882 | K12: =IF(G12="","",MAX(0,G12-J12/100)) -> 0.40040126 | L12: =IF(G12="","",MIN(1,G12+J12/100)) -> 0.45452102 | M12: =IF(F12="","",ROUND(F12*J12/100,0)) -> 10 | P12: -1.8860467 | Q12: 386 | R12: =MAX(0,MIN(1,P12/100+$D$5)) -> 0.42739989 | S12: Small
A13: Carbon | B13: BEAVER MEADOWS BOROUGH | C13: (whole municipality) | D13: =ROUND(Q13*R13,0) -> 102 | E13: =ROUND(Q13,0)-D13 -> 212 | F13: =IF(COUNTA(D13:E13)=0,"",SUM(D13:E13)) -> 314 | G13: =IF(OR(F13="",F13=0),"",D13/F13) -> 0.32484076 | H13: =IF(OR(F13="",F13=0),"",E13/F13) -> 0.67515924 | I13: random forest (results only) | J13: 2.7059882 | K13: =IF(G13="","",MAX(0,G13-J13/100)) -> 0.29778088 | L13: =IF(G13="","",MIN(1,G13+J13/100)) -> 0.35190065 | M13: =IF(F13="","",ROUND(F13*J13/100,0)) -> 8 | P13: -12.121851 | Q13: 314 | R13: =MAX(0,MIN(1,P13/100+$D$5)) -> 0.32504185 | S13: Small
A14: Carbon | B14: BOWMANSTOWN BOROUGH | C14: (whole municipality) | D14: =ROUND(Q14*R14,0) -> 128 | E14: =ROUND(Q14,0)-D14 -> 220 | F14: =IF(COUNTA(D14:E14)=0,"",SUM(D14:E14)) -> 348 | G14: =IF(OR(F14="",F14=0),"",D14/F14) -> 0.36781609 | H14: =IF(OR(F14="",F14=0),"",E14/F14) -> 0.63218391 | I14: random forest (results only) | J14: 2.7059882 | K14: =IF(G14="","",MAX(0,G14-J14/100)) -> 0.34075621 | L14: =IF(G14="","",MIN(1,G14+J14/100)) -> 0.39487597 | M14: =IF(F14="","",ROUND(F14*J14/100,0)) -> 9 | P14: -7.8401932 | Q14: 348 | R14: =MAX(0,MIN(1,P14/100+$D$5)) -> 0.36785843 | S14: Small
A15: Carbon | B15: EAST PENN TOWNSHIP | C15: (whole municipality) | D15: =ROUND(Q15*R15,0) -> 409 | E15: =ROUND(Q15,0)-D15 -> 888 | F15: =IF(COUNTA(D15:E15)=0,"",SUM(D15:E15)) -> 1297 | G15: =IF(OR(F15="",F15=0),"",D15/F15) -> 0.3153431 | H15: =IF(OR(F15="",F15=0),"",E15/F15) -> 0.6846569 | I15: random forest (results only) | J15: 2.7059882 | K15: =IF(G15="","",MAX(0,G15-J15/100)) -> 0.28828322 | L15: =IF(G15="","",MIN(1,G15+J15/100)) -> 0.34240298 | M15: =IF(F15="","",ROUND(F15*J15/100,0)) -> 35 | P15: -13.12717 | Q15: 1297 | R15: =MAX(0,MIN(1,P15/100+$D$5)) -> 0.31498866 | S15: Small
A16: Carbon | B16: EAST SIDE BOROUGH | C16: (whole municipality) | D16: =ROUND(Q16*R16,0) -> 36 | E16: =ROUND(Q16,0)-D16 -> 58 | F16: =IF(COUNTA(D16:E16)=0,"",SUM(D16:E16)) -> 94 | G16: =IF(OR(F16="",F16=0),"",D16/F16) -> 0.38297872 | H16: =IF(OR(F16="",F16=0),"",E16/F16) -> 0.61702128 | I16: random forest (results only) | J16: 2.7059882 | K16: =IF(G16="","",MAX(0,G16-J16/100)) -> 0.35591884 | L16: =IF(G16="","",MIN(1,G16+J16/100)) -> 0.4100386 | M16: =IF(F16="","",ROUND(F16*J16/100,0)) -> 3 | P16: -5.803746 | Q16: 94 | R16: =MAX(0,MIN(1,P16/100+$D$5)) -> 0.3882229 | S16: Small
A17: Carbon | B17: FRANKLIN TOWNSHIP | C17: (whole municipality) | D17: =ROUND(Q17*R17,0) -> 626 | E17: =ROUND(Q17,0)-D17 -> 1332 | F17: =IF(COUNTA(D17:E17)=0,"",SUM(D17:E17)) -> 1958 | G17: =IF(OR(F17="",F17=0),"",D17/F17) -> 0.31971399 | H17: =IF(OR(F17="",F17=0),"",E17/F17) -> 0.68028601 | I17: random forest (results only) | J17: 1.7997491 | K17: =IF(G17="","",MAX(0,G17-J17/100)) -> 0.3017165 | L17: =IF(G17="","",MIN(1,G17+J17/100)) -> 0.33771149 | M17: =IF(F17="","",ROUND(F17*J17/100,0)) -> 35 | P17: -12.649003 | Q17: 1958 | R17: =MAX(0,MIN(1,P17/100+$D$5)) -> 0.31977033 | S17: Medium
A18: Carbon | B18: JIM THORPE BOROUGH | C18: (whole municipality) | D18: =ROUND(Q18*R18,0) -> 1029 | E18: =ROUND(Q18,0)-D18 -> 1107 | F18: =IF(COUNTA(D18:E18)=0,"",SUM(D18:E18)) -> 2136 | G18: =IF(OR(F18="",F18=0),"",D18/F18) -> 0.48174157 | H18: =IF(OR(F18="",F18=0),"",E18/F18) -> 0.51825843 | I18: random forest (results only) | J18: 1.7997491 | K18: =IF(G18="","",MAX(0,G18-J18/100)) -> 0.46374408 | L18: =IF(G18="","",MIN(1,G18+J18/100)) -> 0.49973906 | M18: =IF(F18="","",ROUND(F18*J18/100,0)) -> 38 | P18: 3.5409734 | Q18: 2136 | R18: =MAX(0,MIN(1,P18/100+$D$5)) -> 0.48167009 | S18: Medium
A19: Carbon | B19: KIDDER TOWNSHIP | C19: (whole municipality) | D19: =ROUND(Q19*R19,0) -> 313 | E19: =ROUND(Q19,0)-D19 -> 524 | F19: =IF(COUNTA(D19:E19)=0,"",SUM(D19:E19)) -> 837 | G19: =IF(OR(F19="",F19=0),"",D19/F19) -> 0.3739546 | H19: =IF(OR(F19="",F19=0),"",E19/F19) -> 0.6260454 | I19: random forest (results only) | J19: 2.7059882 | K19: =IF(G19="","",MAX(0,G19-J19/100)) -> 0.34689472 | L19: =IF(G19="","",MIN(1,G19+J19/100)) -> 0.40101448 | M19: =IF(F19="","",ROUND(F19*J19/100,0)) -> 23 | P19: -7.2202183 | Q19: 837 | R19: =MAX(0,MIN(1,P19/100+$D$5)) -> 0.37405818 | S19: Small
A20: Carbon | B20: LANSFORD BOROUGH | C20: (whole municipality) | D20: =ROUND(Q20*R20,0) -> 446 | E20: =ROUND(Q20,0)-D20 -> 554 | F20: =IF(COUNTA(D20:E20)=0,"",SUM(D20:E20)) -> 1000 | G20: =IF(OR(F20="",F20=0),"",D20/F20) -> 0.446 | H20: =IF(OR(F20="",F20=0),"",E20/F20) -> 0.554 | I20: random forest (results only) | J20: 2.7059882 | K20: =IF(G20="","",MAX(0,G20-J20/100)) -> 0.41894012 | L20: =IF(G20="","",MIN(1,G20+J20/100)) -> 0.47305988 | M20: =IF(F20="","",ROUND(F20*J20/100,0)) -> 27 | P20: -0.075770389 | Q20: 1000 | R20: =MAX(0,MIN(1,P20/100+$D$5)) -> 0.44550266 | S20: Small
A21: Carbon | B21: LAUSANNE TOWNSHIP | C21: (whole municipality) | D21: =ROUND(Q21*R21,0) -> 37 | E21: =ROUND(Q21,0)-D21 -> 78 | F21: =IF(COUNTA(D21:E21)=0,"",SUM(D21:E21)) -> 115 | G21: =IF(OR(F21="",F21=0),"",D21/F21) -> 0.32173913 | H21: =IF(OR(F21="",F21=0),"",E21/F21) -> 0.67826087 | I21: random forest (results only) | J21: 2.7059882 | K21: =IF(G21="","",MAX(0,G21-J21/100)) -> 0.29467925 | L21: =IF(G21="","",MIN(1,G21+J21/100)) -> 0.34879901 | M21: =IF(F21="","",ROUND(F21*J21/100,0)) -> 3 | P21: -12.591713 | Q21: 115 | R21: =MAX(0,MIN(1,P21/100+$D$5)) -> 0.32034323 | S21: Small
A22: Carbon | B22: LEHIGH TOWNSHIP | C22: (whole municipality) | D22: =ROUND(Q22*R22,0) -> 61 | E22: =ROUND(Q22,0)-D22 -> 180 | F22: =IF(COUNTA(D22:E22)=0,"",SUM(D22:E22)) -> 241 | G22: =IF(OR(F22="",F22=0),"",D22/F22) -> 0.25311203 | H22: =IF(OR(F22="",F22=0),"",E22/F22) -> 0.74688797 | I22: random forest (results only) | J22: 2.7059882 | K22: =IF(G22="","",MAX(0,G22-J22/100)) -> 0.22605215 | L22: =IF(G22="","",MIN(1,G22+J22/100)) -> 0.28017191 | M22: =IF(F22="","",ROUND(F22*J22/100,0)) -> 7 | P22: -19.324307 | Q22: 241 | R22: =MAX(0,MIN(1,P22/100+$D$5)) -> 0.25301729 | S22: Small
A23: Carbon | B23: LEHIGHTON BOROUGH | C23: (whole municipality) | D23: =ROUND(Q23*R23,0) -> 737 | E23: =ROUND(Q23,0)-D23 -> 930 | F23: =IF(COUNTA(D23:E23)=0,"",SUM(D23:E23)) -> 1667 | G23: =IF(OR(F23="",F23=0),"",D23/F23) -> 0.44211158 | H23: =IF(OR(F23="",F23=0),"",E23/F23) -> 0.55788842 | I23: random forest (results only) | J23: 1.7997491 | K23: =IF(G23="","",MAX(0,G23-J23/100)) -> 0.42411409 | L23: =IF(G23="","",MIN(1,G23+J23/100)) -> 0.46010907 | M23: =IF(F23="","",ROUND(F23*J23/100,0)) -> 30 | P23: -0.38871737 | Q23: 1667 | R23: =MAX(0,MIN(1,P23/100+$D$5)) -> 0.44237319 | S23: Medium
... A100: Northampton | B100: WIND GAP | C100: (whole municipality) | D100: =ROUND(Q100*R100,0) -> 512 | E100: =ROUND(Q100,0)-D100 -> 583 | F100: =IF(COUNTA(D100:E100)=0,"",SUM(D100:E100)) -> 1095 | G100: =IF(OR(F100="",F100=0),"",D100/F100) -> 0.46757991 | H100: =IF(OR(F100="",F100=0),"",E100/F100) -> 0.53242009 | I100: random forest (results only) | J100: 2.7059882 | K100: =IF(G100="","",MAX(0,G100-J100/100)) -> 0.44052003 | L100: =IF(G100="","",MIN(1,G100+J100/100)) -> 0.49463979 | M100: =IF(F100="","",ROUND(F100*J100/100,0)) -> 30 | P100: 2.1114012 | Q100: 1095 | R100: =MAX(0,MIN(1,P100/100+$D$5)) -> 0.46737437 | S100: Small

Sheet 2026 Forecast C
A1: PA-07 2026 House Forecast — Municipal-Level Predictions (Forecast C: shap family-reweighted forest)
A2: Candidates: Brooks | Mackenzie | District totals (yellow) are formulas over the municipality rows.
A3: Only the results are modelled. Votes cast in each row = that row’s 2022 House votes (turnout similar to 2022). Brooks votes = 2022 votes × forecast Brooks share. Change the district scenario on the Scenario & Comparison tab.
A4: Model / scenario | B4: Random forest on results — Forecast C (SHAP family-reweighted forest), municipality model; turnout = 2022 | C4: As-of date | D4: 46300 | E4: Prepared by | F4: Max | G4: Version | H4: v2.0 (results only)
A5: District Brooks share (scenario) | B5: ='Scenario & Comparison'!$C$6 -> 0.52816948 | C5: Uniform shift applied | D5: =B5-SUMPRODUCT(P12:P100,Q12:Q100)/SUM(Q12:Q100)/100 -> 0.4370993 | E5: 2024 backtest district miss (pts) | F5: 1.9412546
A6: DISTRICT TOTALS (auto-sum — do not type over)
A7: Geography | B7: (muni) | C7: (area) | D7: Brooks votes | E7: Mackenzie votes | F7: Total votes | G7: Brooks share | H7: Mackenzie share | I7: Notes | J7: Error term: Brooks share (± pts) | K7: Brooks share, low | L7: Brooks share, high | M7: Error term: Brooks votes (± votes)
A8: PA-07 District | B8: (all municipalities) | D8: =SUM(D12:D100) -> 156805 | E8: =SUM(E12:E100) -> 140086 | F8: =D8+E8 -> 296891 | G8: =IF(F8=0,"",D8/F8) -> 0.5281568 | H8: =IF(F8=0,"",E8/F8) -> 0.4718432 | I8: Headline forecast for the briefing | J8: 1.9412546 | K8: =G8-J8/100 -> 0.50874425 | L8: =G8+J8/100 -> 0.54756934 | M8: =ROUND(F8*J8/100,0) -> 5763
A9: Error terms: each row = ±1 root-mean-square miss of this forecast in its 2024 backtest for places of similar size, after removing the district-wide miss. District row = the district-wide miss. Turnout is held at 2022, so no turnout error is included.
A10: MUNICIPALITY DETAIL | P10: MODEL INPUTS (from the random forest — do not edit)
A11: County | B11: Municipality | C11: Area | D11: Brooks votes | E11: Mackenzie votes | F11: Total votes | G11: Brooks share | H11: Mackenzie share | I11: Notes / source method | J11: Error term: Brooks share (± pts) | K11: Brooks share, low | L11: Brooks share, high | M11: Error term: Brooks votes (± votes) | P11: Model lean vs district (pts) | Q11: Votes cast (2022 House votes) | R11: Forecast Brooks share (unrounded) | S11: Size group (backtest error band)
A12: Carbon | B12: BANKS TOWNSHIP | C12: (whole municipality) | D12: =ROUND(Q12*R12,0) -> 165 | E12: =ROUND(Q12,0)-D12 -> 221 | F12: =IF(COUNTA(D12:E12)=0,"",SUM(D12:E12)) -> 386 | G12: =IF(OR(F12="",F12=0),"",D12/F12) -> 0.42746114 | H12: =IF(OR(F12="",F12=0),"",E12/F12) -> 0.57253886 | I12: random forest (results only) | J12: 2.3992519 | K12: =IF(G12="","",MAX(0,G12-J12/100)) -> 0.40346862 | L12: =IF(G12="","",MIN(1,G12+J12/100)) -> 0.45145366 | M12: =IF(F12="","",ROUND(F12*J12/100,0)) -> 9 | P12: -1.0206213 | Q12: 386 | R12: =MAX(0,MIN(1,P12/100+$D$5)) -> 0.42689309 | S12: Small
A13: Carbon | B13: BEAVER MEADOWS BOROUGH | C13: (whole municipality) | D13: =ROUND(Q13*R13,0) -> 98 | E13: =ROUND(Q13,0)-D13 -> 216 | F13: =IF(COUNTA(D13:E13)=0,"",SUM(D13:E13)) -> 314 | G13: =IF(OR(F13="",F13=0),"",D13/F13) -> 0.31210191 | H13: =IF(OR(F13="",F13=0),"",E13/F13) -> 0.68789809 | I13: random forest (results only) | J13: 2.3992519 | K13: =IF(G13="","",MAX(0,G13-J13/100)) -> 0.28810939 | L13: =IF(G13="","",MIN(1,G13+J13/100)) -> 0.33609443 | M13: =IF(F13="","",ROUND(F13*J13/100,0)) -> 8 | P13: -12.46672 | Q13: 314 | R13: =MAX(0,MIN(1,P13/100+$D$5)) -> 0.3124321 | S13: Small
A14: Carbon | B14: BOWMANSTOWN BOROUGH | C14: (whole municipality) | D14: =ROUND(Q14*R14,0) -> 123 | E14: =ROUND(Q14,0)-D14 -> 225 | F14: =IF(COUNTA(D14:E14)=0,"",SUM(D14:E14)) -> 348 | G14: =IF(OR(F14="",F14=0),"",D14/F14) -> 0.35344828 | H14: =IF(OR(F14="",F14=0),"",E14/F14) -> 0.64655172 | I14: random forest (results only) | J14: 2.3992519 | K14: =IF(G14="","",MAX(0,G14-J14/100)) -> 0.32945576 | L14: =IF(G14="","",MIN(1,G14+J14/100)) -> 0.37744079 | M14: =IF(F14="","",ROUND(F14*J14/100,0)) -> 8 | P14: -8.435158 | Q14: 348 | R14: =MAX(0,MIN(1,P14/100+$D$5)) -> 0.35274772 | S14: Small
A15: Carbon | B15: EAST PENN TOWNSHIP | C15: (whole municipality) | D15: =ROUND(Q15*R15,0) -> 384 | E15: =ROUND(Q15,0)-D15 -> 913 | F15: =IF(COUNTA(D15:E15)=0,"",SUM(D15:E15)) -> 1297 | G15: =IF(OR(F15="",F15=0),"",D15/F15) -> 0.29606785 | H15: =IF(OR(F15="",F15=0),"",E15/F15) -> 0.70393215 | I15: random forest (results only) | J15: 2.3992519 | K15: =IF(G15="","",MAX(0,G15-J15/100)) -> 0.27207533 | L15: =IF(G15="","",MIN(1,G15+J15/100)) -> 0.32006037 | M15: =IF(F15="","",ROUND(F15*J15/100,0)) -> 31 | P15: -14.089405 | Q15: 1297 | R15: =MAX(0,MIN(1,P15/100+$D$5)) -> 0.29620525 | S15: Small
A16: Carbon | B16: EAST SIDE BOROUGH | C16: (whole municipality) | D16: =ROUND(Q16*R16,0) -> 35 | E16: =ROUND(Q16,0)-D16 -> 59 | F16: =IF(COUNTA(D16:E16)=0,"",SUM(D16:E16)) -> 94 | G16: =IF(OR(F16="",F16=0),"",D16/F16) -> 0.37234043 | H16: =IF(OR(F16="",F16=0),"",E16/F16) -> 0.62765957 | I16: random forest (results only) | J16: 2.3992519 | K16: =IF(G16="","",MAX(0,G16-J16/100)) -> 0.34834791 | L16: =IF(G16="","",MIN(1,G16+J16/100)) -> 0.39633294 | M16: =IF(F16="","",ROUND(F16*J16/100,0)) -> 2 | P16: -6.2139642 | Q16: 94 | R16: =MAX(0,MIN(1,P16/100+$D$5)) -> 0.37495966 | S16: Small
A17: Carbon | B17: FRANKLIN TOWNSHIP | C17: (whole municipality) | D17: =ROUND(Q17*R17,0) -> 605 | E17: =ROUND(Q17,0)-D17 -> 1353 | F17: =IF(COUNTA(D17:E17)=0,"",SUM(D17:E17)) -> 1958 | G17: =IF(OR(F17="",F17=0),"",D17/F17) -> 0.30898876 | H17: =IF(OR(F17="",F17=0),"",E17/F17) -> 0.69101124 | I17: random forest (results only) | J17: 1.3223778 | K17: =IF(G17="","",MAX(0,G17-J17/100)) -> 0.29576499 | L17: =IF(G17="","",MIN(1,G17+J17/100)) -> 0.32221254 | M17: =IF(F17="","",ROUND(F17*J17/100,0)) -> 26 | P17: -12.78729 | Q17: 1958 | R17: =MAX(0,MIN(1,P17/100+$D$5)) -> 0.3092264 | S17: Medium
A18: Carbon | B18: JIM THORPE BOROUGH | C18: (whole municipality) | D18: =ROUND(Q18*R18,0) -> 1019 | E18: =ROUND(Q18,0)-D18 -> 1117 | F18: =IF(COUNTA(D18:E18)=0,"",SUM(D18:E18)) -> 2136 | G18: =IF(OR(F18="",F18=0),"",D18/F18) -> 0.47705993 | H18: =IF(OR(F18="",F18=0),"",E18/F18) -> 0.52294007 | I18: random forest (results only) | J18: 1.3223778 | K18: =IF(G18="","",MAX(0,G18-J18/100)) -> 0.46383615 | L18: =IF(G18="","",MIN(1,G18+J18/100)) -> 0.4902837 | M18: =IF(F18="","",ROUND(F18*J18/100,0)) -> 28 | P18: 3.9867001 | Q18: 2136 | R18: =MAX(0,MIN(1,P18/100+$D$5)) -> 0.4769663 | S18: Medium
A19: Carbon | B19: KIDDER TOWNSHIP | C19: (whole municipality) | D19: =ROUND(Q19*R19,0) -> 298 | E19: =ROUND(Q19,0)-D19 -> 539 | F19: =IF(COUNTA(D19:E19)=0,"",SUM(D19:E19)) -> 837 | G19: =IF(OR(F19="",F19=0),"",D19/F19) -> 0.35603345 | H19: =IF(OR(F19="",F19=0),"",E19/F19) -> 0.64396655 | I19: random forest (results only) | J19: 2.3992519 | K19: =IF(G19="","",MAX(0,G19-J19/100)) -> 0.33204093 | L19: =IF(G19="","",MIN(1,G19+J19/100)) -> 0.38002597 | M19: =IF(F19="","",ROUND(F19*J19/100,0)) -> 20 | P19: -8.0871871 | Q19: 837 | R19: =MAX(0,MIN(1,P19/100+$D$5)) -> 0.35622743 | S19: Small
A20: Carbon | B20: LANSFORD BOROUGH | C20: (whole municipality) | D20: =ROUND(Q20*R20,0) -> 440 | E20: =ROUND(Q20,0)-D20 -> 560 | F20: =IF(COUNTA(D20:E20)=0,"",SUM(D20:E20)) -> 1000 | G20: =IF(OR(F20="",F20=0),"",D20/F20) -> 0.44 | H20: =IF(OR(F20="",F20=0),"",E20/F20) -> 0.56 | I20: random forest (results only) | J20: 2.3992519 | K20: =IF(G20="","",MAX(0,G20-J20/100)) -> 0.41600748 | L20: =IF(G20="","",MIN(1,G20+J20/100)) -> 0.46399252 | M20: =IF(F20="","",ROUND(F20*J20/100,0)) -> 24 | P20: 0.30657532 | Q20: 1000 | R20: =MAX(0,MIN(1,P20/100+$D$5)) -> 0.44016505 | S20: Small
A21: Carbon | B21: LAUSANNE TOWNSHIP | C21: (whole municipality) | D21: =ROUND(Q21*R21,0) -> 35 | E21: =ROUND(Q21,0)-D21 -> 80 | F21: =IF(COUNTA(D21:E21)=0,"",SUM(D21:E21)) -> 115 | G21: =IF(OR(F21="",F21=0),"",D21/F21) -> 0.30434783 | H21: =IF(OR(F21="",F21=0),"",E21/F21) -> 0.69565217 | I21: random forest (results only) | J21: 2.3992519 | K21: =IF(G21="","",MAX(0,G21-J21/100)) -> 0.28035531 | L21: =IF(G21="","",MIN(1,G21+J21/100)) -> 0.32834034 | M21: =IF(F21="","",ROUND(F21*J21/100,0)) -> 3 | P21: -13.196146 | Q21: 115 | R21: =MAX(0,MIN(1,P21/100+$D$5)) -> 0.30513784 | S21: Small
A22: Carbon | B22: LEHIGH TOWNSHIP | C22: (whole municipality) | D22: =ROUND(Q22*R22,0) -> 52 | E22: =ROUND(Q22,0)-D22 -> 189 | F22: =IF(COUNTA(D22:E22)=0,"",SUM(D22:E22)) -> 241 | G22: =IF(OR(F22="",F22=0),"",D22/F22) -> 0.21576763 | H22: =IF(OR(F22="",F22=0),"",E22/F22) -> 0.78423237 | I22: random forest (results only) | J22: 2.3992519 | K22: =IF(G22="","",MAX(0,G22-J22/100)) -> 0.19177512 | L22: =IF(G22="","",MIN(1,G22+J22/100)) -> 0.23976015 | M22: =IF(F22="","",ROUND(F22*J22/100,0)) -> 6 | P22: -21.992231 | Q22: 241 | R22: =MAX(0,MIN(1,P22/100+$D$5)) -> 0.21717699 | S22: Small
A23: Carbon | B23: LEHIGHTON BOROUGH | C23: (whole municipality) | D23: =ROUND(Q23*R23,0) -> 715 | E23: =ROUND(Q23,0)-D23 -> 952 | F23: =IF(COUNTA(D23:E23)=0,"",SUM(D23:E23)) -> 1667 | G23: =IF(OR(F23="",F23=0),"",D23/F23) -> 0.42891422 | H23: =IF(OR(F23="",F23=0),"",E23/F23) -> 0.57108578 | I23: random forest (results only) | J23: 1.3223778 | K23: =IF(G23="","",MAX(0,G23-J23/100)) -> 0.41569044 | L23: =IF(G23="","",MIN(1,G23+J23/100)) -> 0.442138 | M23: =IF(F23="","",ROUND(F23*J23/100,0)) -> 22 | P23: -0.79961773 | Q23: 1667 | R23: =MAX(0,MIN(1,P23/100+$D$5)) -> 0.42910312 | S23: Medium
... A100: Northampton | B100: WIND GAP | C100: (whole municipality) | D100: =ROUND(Q100*R100,0) -> 505 | E100: =ROUND(Q100,0)-D100 -> 590 | F100: =IF(COUNTA(D100:E100)=0,"",SUM(D100:E100)) -> 1095 | G100: =IF(OR(F100="",F100=0),"",D100/F100) -> 0.46118721 | H100: =IF(OR(F100="",F100=0),"",E100/F100) -> 0.53881279 | I100: random forest (results only) | J100: 2.3992519 | K100: =IF(G100="","",MAX(0,G100-J100/100)) -> 0.4371947 | L100: =IF(G100="","",MIN(1,G100+J100/100)) -> 0.48517973 | M100: =IF(F100="","",ROUND(F100*J100/100,0)) -> 26 | P100: 2.4519248 | Q100: 1095 | R100: =MAX(0,MIN(1,P100/100+$D$5)) -> 0.46161855 | S100: Small

Sheet How Forecasts Are Weighted
A1: How the three municipality-level forecasts weigh their inputs (SHAP) — results-only random forests
A3: Forecast A — Full random forest.
A4: All 21 candidate inputs go into one random forest that forecasts the Democratic share. Nothing is weighted by hand; SHAP measures what the forest learned. This is the reference.
A5: Forecast B — SHAP-selected forest.
A6: Keeps only inputs whose average |SHAP| beat all 10 random columns in at least 18 of 20 refits and that held at least 2% of Forecast A’s SHAP total (7 of 21 kept), then refits the forest on them. Weight that was spread thinly over weak inputs is concentrated on the strong ones.
A7: Forecast C — SHAP family-reweighted forest.
A8: Keeps Forecast A’s forest but multiplies each input family’s SHAP values by a weight fitted to how well that family predicted elections the forest had not seen (leave-one-election-out, fitted within each election). Families under 3% of SHAP stay at ×1; others are limited to ×0.5–×2 because there are only three training elections.
A9: Backtests.
A10: Each 2024 backtest uses its own forecast’s weighting: A’s full input set, B’s selected inputs, and C’s exact family weights — refit only on 2020 and 2022.
A11: Turnout.
A12: Not modelled in any forecast: votes cast = 2022 House votes for 2026 (2020 votes in the 2024 backtest). All differences between A, B and C come from the results model.
A14: Family share of SHAP value in votes, 2026 forecast rows
A15: Input family | B15: Forecast A | C15: Forecast B | D15: Forecast C | E15: Forecast C weight (×)
A16: Election type | B16: 0.0021988197 | C16: 0 | D16: 0.0020391966 | E16: 1
A17: Historical voter data | B17: 0.78001141 | C17: 0.785036 | D17: 0.65741325 | E17: 0.90879938
A18: Voter registration data | B18: 0.21778977 | C18: 0.214964 | D18: 0.34054755 | E18: 1.6860514
A19: Out-of-fold pattern error before → after Forecast C’s re-weighting: 2.35 → 2.15 points.
A21: Top inputs in each forecast (share of SHAP value in votes)
A22: # | B22: Forecast A | C22: Share | D22: Forecast B | E22: Share | F22: Forecast C | G22: Share
A23: 1 | B23: House lean, last election (t−2) | C23: 0.21034096 | D23: House lean, last election (t−2) | E23: 0.2241668 | F23: House lean, last election (t−2) | G23: 0.17728066
A24: 2 | B24: Top-of-ticket lean, last election (t−2) | C24: 0.18121549 | D24: Top-of-ticket lean, last election (t−2) | E24: 0.21003989 | F24: Registration: R % (voter file) | G24: 0.15722213
A25: 3 | B25: Senate lean, most recent Senate race | C25: 0.15702086 | D25: Senate lean, most recent Senate race | E25: 0.16729992 | F25: Top-of-ticket lean, last election (t−2) | G25: 0.15273298
A26: 4 | B26: Registration: R % (voter file) | C26: 0.10054799 | D26: Registration: R % (voter file) | E26: 0.13518145 | F26: Senate lean, most recent Senate race | G26: 0.13234113
A27: 5 | B27: Electorate last election: R % of ballots | C27: 0.098261315 | D27: Electorate last election: R % of ballots | E27: 0.10076922 | F27: Registration: D % (voter file) | G27: 0.12404933
A28: 6 | B28: Registration: D % (voter file) | C28: 0.079333047 | D28: House lean, last same-type election (t−4) | E28: 0.082760175 | F28: Electorate last election: R % of ballots | G28: 0.082817109
A29: 7 | B29: House lean, last same-type election (t−4) | C29: 0.071846086 | D29: Registration: D % (voter file) | E29: 0.079782551 | F29: House lean, last same-type election (t−4) | G29: 0.06055369
A30: 8 | B30: Turnout, last election (certified) | C30: 0.012989431 | F30: Registrants: female % (known sex) | G30: 0.016341527
A31: 9 | B31: Registrants: female % (known sex) | C31: 0.010450868 | F31: Registered voters (log) | G31: 0.016057673
A32: 10 | B32: Registered voters (log) | C32: 0.010269335 | F32: Turnout, last election (certified) | G32: 0.010947819
A34: Forecast B — random-column test and selection
A35: Input | B35: Beat random columns (of 20) | C35: Share of SHAP in A | D35: Kept in B?
A36: House lean, last election (t−2) | B36: 20 | C36: 0.20573896 | D36: Yes
A37: Top-of-ticket lean, last election (t−2) | B37: 20 | C37: 0.17679046 | D37: Yes
A38: Senate lean, most recent Senate race | B38: 20 | C38: 0.15467014 | D38: Yes
A39: Registration: R % (voter file) | B39: 20 | C39: 0.097076864 | D39: Yes
A40: Electorate last election: R % of ballots | B40: 20 | C40: 0.092382792 | D40: Yes
A41: Registration: D % (voter file) | B41: 20 | C41: 0.078563191 | D41: Yes
A42: House lean, last same-type election (t−4) | B42: 20 | C42: 0.070221666 | D42: Yes
A43: Turnout, last election (certified) | B43: 20 | C43: 0.01602685 | D43: No
A44: Turnout last election: R registrants | B44: 20 | C44: 0.013922063 | D44: No
...

Sheet Feature Ranking A
A1: Rank | B1: Feature | C1: Input family | D1: Share of model | E1: Share within its family | F1: SHAP value in votes | G1: Used to forecast | H1: Significance test result | I1: Variable (short name) | J1: Status in Forecast B
A2: 1 | B2: Democratic percent of the two-party House vote, 2024 (certified municipal results), above or below the district average for that election | C2: Historical voter data | D2: 0.21034096 | E2: 0.26966396 | F2: 173.32166 | G2: Democratic percent of the two-party vote | H2: Beat all 10 random comparison columns in 20 of 20 refits. | I2: House lean, last election (t−2) | J2: Kept in B
A3: 2 | B3: Democratic percent of the two-party vote for President, 2024 (the top race on the ballot), above or below the district average | C3: Historical voter data | D3: 0.18121549 | E3: 0.23232415 | F3: 149.32218 | G3: Democratic percent of the two-party vote | H3: Beat all 10 random comparison columns in 20 of 20 refits. | I3: Top-of-ticket lean, last election (t−2) | J3: Kept in B
A4: 3 | B4: Democratic percent of the two-party U.S. Senate vote, 2024 (most recent Senate race), above or below the district average | C4: Historical voter data | D4: 0.15702086 | E4: 0.20130585 | F4: 129.38572 | G4: Democratic percent of the two-party vote | H4: Beat all 10 random comparison columns in 20 of 20 refits. | I4: Senate lean, most recent Senate race | J4: Kept in B
A5: 4 | B5: Registered Republicans as a percent of all registered voters, 2026 (voter file) | C5: Voter registration data | D5: 0.10054799 | E5: 0.46167452 | F5: 82.85188 | G5: Democratic percent of the two-party vote | H5: Beat all 10 random comparison columns in 20 of 20 refits. | I5: Registration: R % (voter file) | J5: Kept in B
A6: 5 | B6: Registered Republicans as a percent of everyone who voted, 2024 (voter file) | C6: Historical voter data | D6: 0.098261315 | E6: 0.1259742 | F6: 80.967656 | G6: Democratic percent of the two-party vote | H6: Beat all 10 random comparison columns in 20 of 20 refits. | I6: Electorate last election: R % of ballots | J6: Kept in B
A7: 6 | B7: Registered Democrats as a percent of all registered voters, 2026 (voter file) | C7: Voter registration data | D7: 0.079333047 | E7: 0.36426434 | F7: 65.370699 | G7: Democratic percent of the two-party vote | H7: Beat all 10 random comparison columns in 20 of 20 refits. | I7: Registration: D % (voter file) | J7: Kept in B
A8: 7 | B8: Democratic percent of the two-party House vote, 2022 — the last midterm (certified municipal results), above or below the district average | C8: Historical voter data | D8: 0.071846086 | E8: 0.09210902 | F8: 59.201418 | G8: Democratic percent of the two-party vote | H8: Beat all 10 random comparison columns in 20 of 20 refits. | I8: House lean, last same-type election (t−4) | J8: Kept in B
A9: 8 | B9: Ballots cast as a percent of registered voters, 2024 (certified municipal results) | C9: Historical voter data | D9: 0.012989431 | E9: 0.016652872 | F9: 10.703335 | G9: Democratic percent of the two-party vote | H9: Beat all 10 random comparison columns in 20 of 20 refits. | I9: Turnout, last election (certified) | J9: Dropped from B
A10: 9 | B10: Women as a percent of registered voters whose sex is recorded, 2026 (voter file) | C10: Voter registration data | D10: 0.010450868 | E10: 0.047986037 | F10: 8.6115505 | G10: Democratic percent of the two-party vote | H10: Beat all 10 random comparison columns in 18 of 20 refits. | I10: Registrants: female % (known sex) | J10: Dropped from B
A11: 10 | B11: Number of registered voters, 2026, on a log scale (voter file) | C11: Voter registration data | D11: 0.010269335 | E11: 0.047152514 | F11: 8.4619668 | G11: Democratic percent of the two-party vote | H11: Beat all 10 random comparison columns in 20 of 20 refits. | I11: Registered voters (log) | J11: Dropped from B
A12: 11 | B12: Percent of registered Republicans who voted, 2024 (voter file) | C12: Historical voter data | D12: 0.0097518048 | E12: 0.012502131 | F12: 8.0355202 | G12: Democratic percent of the two-party vote | H12: Beat all 10 random comparison columns in 20 of 20 refits. | I12: Turnout last election: R registrants | J12: Dropped from B
A13: 12 | B13: Percent of registered voters in neither major party who voted, 2024 (voter file) | C13: Historical voter data | D13: 0.0092638737 | E13: 0.011876587 | F13: 7.6334633 | G13: Democratic percent of the two-party vote | H13: Beat all 10 random comparison columns in 20 of 20 refits. | I13: Turnout last election: unaffiliated | J13: Dropped from B
... A22: 21 | B22: Election type: 1 for a midterm year (2026), 0 for a presidential year | C22: Election type | D22: 0.0021988197 | E22: 1 | F22: 1.8118349 | G22: Democratic percent of the two-party vote | H22: Beat all 10 random comparison columns in 6 of 20 refits. | I22: Midterm year (1/0) | J22: Dropped from B
B24: Historical voter data, total | C24: Historical voter data | D24: =SUMIF(C2:C22,"Historical voter data",D2:D22) -> 0.78001141 | F24: =SUMIF(C2:C22,"Historical voter data",F2:F22) -> 642.73204
B25: Voter registration data, total | C25: Voter registration data | D25: =SUMIF(C2:C22,"Voter registration data",D2:D22) -> 0.21778977 | F25: =SUMIF(C2:C22,"Voter registration data",F2:F22) -> 179.45951
B26: Election type, total | C26: Election type | D26: =SUMIF(C2:C22,"Election type",D2:D22) -> 0.0021988197 | F26: =SUMIF(C2:C22,"Election type",F2:F22) -> 1.8118349
B27: All features, total | D27: =SUM(D2:D22) -> 1 | F27: =SUM(F2:F22) -> 824.00338
B29: Notes
B30: How to read this table. Each row is one input that this forecast uses, ranked by SHAP value in votes on the 2026 forecast rows.
B31: SHAP value: for one place, the number of votes that one input added to or took away from that place’s forecast, measured from the model’s starting value (the average over the places and years it was trained on). Exact TreeSHAP over every tree.
B32: SHAP value in votes is the average over the 89 municipalities of the votes the input moved, ignoring direction. Brooks votes and Mackenzie votes are counted together (moving 10 votes from Mackenzie to Brooks counts as 20). Votes cast are each place’s 2022 House votes.
B33: Share of model = the input’s SHAP value in votes ÷ the total for all inputs. Share within its family divides by its family’s total instead.
B34: What the model forecasts. One random forest forecasts each place’s Democratic percent of the two-party House vote, above or below the district average for that election. Turnout is not forecast: each place casts the same number of House votes as in 2022. Brooks share = forecast pattern + one uniform shift so the district total equals the scenario.
B35: Forecast A weighting: none imposed. Each input’s weight is exactly what the full forest learned; SHAP shows it after the fact.
B36: Significance test. The full forest was refit 20 times with 10 extra columns of random numbers (5 that change row to row, 5 that keep one value per place). The column counts the refits in which the input’s average |SHAP| on the 2026 rows beat every random column.
B37: Settings: max_features=0.33, min_samples_leaf=1, 500 trees, trained on 243 municipality-elections (2020, 2022, 2024).

Sheet Feature Ranking B
A1: Rank | B1: Feature | C1: Input family | D1: Share of model | E1: Share within its family | F1: SHAP value in votes | G1: Used to forecast | H1: Significance test result | I1: Variable (short name) | J1: Status in Forecast B
A2: 1 | B2: Democratic percent of the two-party House vote, 2024 (certified municipal results), above or below the district average for that election | C2: Historical voter data | D2: 0.2241668 | E2: 0.2855497 | F2: 174.92235 | G2: Democratic percent of the two-party vote | H2: Beat all 10 random comparison columns in 20 of 20 refits. | I2: House lean, last election (t−2) | J2: Kept in B
A3: 2 | B3: Democratic percent of the two-party vote for President, 2024 (the top race on the ballot), above or below the district average | C3: Historical voter data | D3: 0.21003989 | E3: 0.26755446 | F3: 163.89881 | G3: Democratic percent of the two-party vote | H3: Beat all 10 random comparison columns in 20 of 20 refits. | I3: Top-of-ticket lean, last election (t−2) | J3: Kept in B
A4: 3 | B4: Democratic percent of the two-party U.S. Senate vote, 2024 (most recent Senate race), above or below the district average | C4: Historical voter data | D4: 0.16729992 | E4: 0.21311115 | F4: 130.54786 | G4: Democratic percent of the two-party vote | H4: Beat all 10 random comparison columns in 20 of 20 refits. | I4: Senate lean, most recent Senate race | J4: Kept in B
A5: 4 | B5: Registered Republicans as a percent of all registered voters, 2026 (voter file) | C5: Voter registration data | D5: 0.13518145 | E5: 0.62885622 | F5: 105.4851 | G5: Democratic percent of the two-party vote | H5: Beat all 10 random comparison columns in 20 of 20 refits. | I5: Registration: R % (voter file) | J5: Kept in B
A6: 5 | B6: Registered Republicans as a percent of everyone who voted, 2024 (voter file) | C6: Historical voter data | D6: 0.10076922 | E6: 0.12836255 | F6: 78.632472 | G6: Democratic percent of the two-party vote | H6: Beat all 10 random comparison columns in 20 of 20 refits. | I6: Electorate last election: R % of ballots | J6: Kept in B
A7: 6 | B7: Democratic percent of the two-party House vote, 2022 — the last midterm (certified municipal results), above or below the district average | C7: Historical voter data | D7: 0.082760175 | E7: 0.10542214 | F7: 64.579611 | G7: Democratic percent of the two-party vote | H7: Beat all 10 random comparison columns in 20 of 20 refits. | I7: House lean, last same-type election (t−4) | J7: Kept in B
A8: 7 | B8: Registered Democrats as a percent of all registered voters, 2026 (voter file) | C8: Voter registration data | D8: 0.079782551 | E8: 0.37114378 | F8: 62.256104 | G8: Democratic percent of the two-party vote | H8: Beat all 10 random comparison columns in 20 of 20 refits. | I8: Registration: D % (voter file) | J8: Kept in B
B10: Historical voter data, total | C10: Historical voter data | D10: =SUMIF(C2:C8,"Historical voter data",D2:D8) -> 0.785036 | F10: =SUMIF(C2:C8,"Historical voter data",F2:F8) -> 612.58111
B11: Voter registration data, total | C11: Voter registration data | D11: =SUMIF(C2:C8,"Voter registration data",D2:D8) -> 0.214964 | F11: =SUMIF(C2:C8,"Voter registration data",F2:F8) -> 167.7412
B12: All features, total | D12: =SUM(D2:D8) -> 1 | F12: =SUM(F2:F8) -> 780.32231
B14: Notes
B15: How to read this table. Each row is one input that this forecast uses, ranked by SHAP value in votes on the 2026 forecast rows.
B16: SHAP value: for one place, the number of votes that one input added to or took away from that place’s forecast, measured from the model’s starting value (the average over the places and years it was trained on). Exact TreeSHAP over every tree.
B17: SHAP value in votes is the average over the 89 municipalities of the votes the input moved, ignoring direction. Brooks votes and Mackenzie votes are counted together (moving 10 votes from Mackenzie to Brooks counts as 20). Votes cast are each place’s 2022 House votes.
B18: Share of model = the input’s SHAP value in votes ÷ the total for all inputs. Share within its family divides by its family’s total instead.
B19: What the model forecasts. One random forest forecasts each place’s Democratic percent of the two-party House vote, above or below the district average for that election. Turnout is not forecast: each place casts the same number of House votes as in 2022. Brooks share = forecast pattern + one uniform shift so the district total equals the scenario.
B20: Forecast B weighting: SHAP-selected. Only inputs that beat all 10 random columns in at least 18 of 20 refits AND held at least 2% of Forecast A’s SHAP total were kept; the forest was refit on those inputs alone, so weight that was spread over weak inputs is concentrated on the strong ones.
B21: Significance test. The full forest was refit 20 times with 10 extra columns of random numbers (5 that change row to row, 5 that keep one value per place). The column counts the refits in which the input’s average |SHAP| on the 2026 rows beat every random column.
B22: Settings: max_features=0.33, min_samples_leaf=1, 500 trees, trained on 243 municipality-elections (2020, 2022, 2024).

Sheet Feature Ranking C
