Workbook

Sheet Scenario & Comparison
A1: PA-07 2026 House Forecast — Precinct Level: three results-only random-forest forecasts (fixed baseline)
A2: Candidates: Brooks | Mackenzie | The two yellow cells set the district-wide Brooks share and votes cast; all three forecasts update.
A3: A, B and C weight the same random-forest inputs differently using SHAP (see How Forecasts Are Weighted). Each is backtested on 2024, 2022 and 2020 with its own weights; those misses are the error terms.
A5: SCENARIO INPUTS (defaults are built from the tables below; type over them to run another scenario)
A6: District-wide Brooks share of the two-party vote (input) | C6: =C21 -> 0.49330923 | D6: ← default: feeder-rule baseline (row 21) — 67% 2022 + 33% 2024, adjusted for the registration shift
A7: Turnout multiplier (input; 1.00 = each place keeps its 2022 turnout rate) | C7: 1 | D7: ← votes cast = 2022 turnout rate × 2026 registered voters × this multiplier (row 27)
A9: HOW THE DEFAULTS ARE BUILT (today’s map applied to every year — all municipalities and precincts, as if the district had always included them)
A10: Election | C10: Democratic share | D10: Democratic votes | E10: Republican votes | F10: Registered (state rolls) | G10: Dem share of two-party registration
A11: 2018 General | C11: =D11/(D11+E11) -> 0.53271241 | D11: 138964.36 | E11: 121897.52 | F11: 487006 | G11: 0.56754738
A12: 2020 General | C12: =D12/(D12+E12) -> 0.49604501 | D12: 191745.71 | E12: 194803.3 | F12: 524392 | G12: 0.5561199
A13: 2022 General | C13: =D13/(D13+E13) -> 0.50878429 | D13: 150244 | E13: 145056 | F13: 517457 | G13: 0.54638851
A14: 2024 General | C14: =D14/(D14+E14) -> 0.4940398 | D14: 197775 | E14: 202547 | F14: 542756 | G14: 0.52629318
A15: 2026 Primary rolls | F15: 536459 | G15: 0.5205639
A16: Source: certified precinct House returns and Department of State registration (PA07_Precinct_Data.xlsx). 2018/2020 count Carbon (then PA-09) and Polk (then PA-08) as district results and include an estimate for Ross One, so every year covers the same territory as 2026.
A18: Feeder-weighted Democratic share: 67% × 2022 + 33% × 2024 | C18: =0.67*C13+0.33*C14 -> 0.50391861
A19: Change in Dem share of two-party registration since the feeder elections (pts) | C19: =(G15-(0.67*G13+0.33*G14))*100 -> -1.9193149
A20: Registration-to-vote link (k), measured on precinct changes 2018→2020, 2020→2022, 2022→2024 | C20: 0.55276914 | D20: Within-district slope: precincts whose registration moved 1 pt toward a party moved about this many pts in vote share (national swing removed).
A21: Feeder-rule baseline for 2026 = row 18 + k × row 19 | C21: =C18+C20*C19/100 -> 0.49330923
A22: For comparison — pure feeder share with no registration adjustment (row 18) | C22: =C18 -> 0.50391861
A23: 2022 turnout in today’s district (House votes ÷ registered voters) | C23: 0.57163979
A24: 2026 registered voters (state rolls, summed over precincts) | C24: 538613.35
A25: District check: 2022 turnout × 2026 registered | C25: =C23*C24 -> 307892.82
A26: Rule applied precinct by precinct (each place’s own 2022 turnout × its 2026 registered) and summed | C26: 307102.91 | D26: Each place uses its own 2022 turnout rate, so the summed total differs slightly from the district-level check. Registration: Department of State rolls (2026 primary).
A27: Votes cast used in the forecasts (row 26 × turnout multiplier) | C27: =C26*C7 -> 307102.91
A29: DISTRICT TOTALS BY FORECAST, WITH ERROR TERMS (live from each forecast tab)
A30: Forecast | B30: Weighting | C30: Brooks votes | D30: Mackenzie votes | E30: Total votes | F30: Brooks share | G30: Error term, share (± pts) | H30: Brooks share, 95% range | I30: Error term, votes cast (±) | J30: Error term, Brooks votes (±)
A31: Forecast A | B31: Full random forest | C31: ='2026 Forecast A'!D8 -> 151504 | D31: ='2026 Forecast A'!E8 -> 155596 | E31: ='2026 Forecast A'!F8 -> 307100 | F31: ='2026 Forecast A'!G8 -> 0.49333768 | G31: ='2026 Forecast A'!L8 -> 2.1254091 | H31: =TEXT('2026 Forecast A'!M8,"0.0%")&" – "&TEXT('2026 Forecast A'!N8,"0.0%") -> 45.2% – 53.5% | I31: ='2026 Forecast A'!O8 -> 11264 | J31: ='2026 Forecast A'!P8 -> 8572
A32: Forecast B | B32: SHAP-selected forest | C32: ='2026 Forecast B'!D8 -> 151496 | D32: ='2026 Forecast B'!E8 -> 155604 | E32: ='2026 Forecast B'!F8 -> 307100 | F32: ='2026 Forecast B'!G8 -> 0.49331162 | G32: ='2026 Forecast B'!L8 -> 2.1257089 | H32: =TEXT('2026 Forecast B'!M8,"0.0%")&" – "&TEXT('2026 Forecast B'!N8,"0.0%") -> 45.2% – 53.5% | I32: ='2026 Forecast B'!O8 -> 11264 | J32: ='2026 Forecast B'!P8 -> 8573
A33: Forecast C | B33: SHAP family-reweighted forest | C33: ='2026 Forecast C'!D8 -> 151497 | D33: ='2026 Forecast C'!E8 -> 155603 | E33: ='2026 Forecast C'!F8 -> 307100 | F33: ='2026 Forecast C'!G8 -> 0.49331488 | G33: ='2026 Forecast C'!L8 -> 2.1253506 | H33: =TEXT('2026 Forecast C'!M8,"0.0%")&" – "&TEXT('2026 Forecast C'!N8,"0.0%") -> 45.2% – 53.5% | I33: ='2026 Forecast C'!O8 -> 11264 | J33: ='2026 Forecast C'!P8 -> 8572
A34: District error terms = root-mean-square of the district-wide misses in the 2020, 2022 and 2024 backtests. Place pattern error terms come from the 2022 and 2024 forward backtests.
A36: BACKTESTS FOR EVERY YEAR, WITH ERROR TERMS (same weights as the forecasts; live from each backtest tab)
A37: Forecast | B37: Backtest | C37: District Dem share miss (pts) | D37: Dem votes miss | E37: Rep votes miss | F37: Votes cast miss | G37: Pattern RMS miss per row (pts) | H37: RMS miss per row (pts) | I37: Avg error term set beforehand (± pts) | J37: Actual inside ±1 error term | K37: Actual inside 95% range | L37: Rows within 3 pts
A38: Forecast A | B38: 2024 — forward backtest | C38: ='Backtest 2024 A'!F375 -> 0.080012066 | D38: ='Backtest 2024 A'!F377 -> -0.0036293361 | E38: ='Backtest 2024 A'!F378 -> -0.006813725 | F38: ='Backtest 2024 A'!F379 -> -0.0052450157 | G38: ='Backtest 2024 A'!F376 -> 2.3748436 | H38: ='Backtest 2024 A'!F374 -> 2.3846922 | I38: ='Backtest 2024 A'!F380 -> 3.7849421 | J38: ='Backtest 2024 A'!F381 -> 0.91036415 | K38: ='Backtest 2024 A'!F382 -> 0.99439776 | L38: ='Backtest 2024 A'!F383 -> 0.8627451
A39: Forecast B | B39: 2024 — forward backtest | C39: ='Backtest 2024 B'!F375 -> 0.083312246 | D39: ='Backtest 2024 B'!F377 -> -0.0035626958 | E39: ='Backtest 2024 B'!F378 -> -0.006878428 | F39: ='Backtest 2024 B'!F379 -> -0.0052450157 | G39: ='Backtest 2024 B'!F376 -> 2.1971151 | H39: ='Backtest 2024 B'!F374 -> 2.20691 | I39: ='Backtest 2024 B'!F380 -> 3.7572326 | J39: ='Backtest 2024 B'!F381 -> 0.93557423 | K39: ='Backtest 2024 B'!F382 -> 0.99439776 | L39: ='Backtest 2024 B'!F383 -> 0.86554622
A40: Forecast C | B40: 2024 — forward backtest | C40: ='Backtest 2024 C'!F375 -> 0.080519786 | D40: ='Backtest 2024 C'!F377 -> -0.0036190837 | E40: ='Backtest 2024 C'!F378 -> -0.0068236793 | F40: ='Backtest 2024 C'!F379 -> -0.0052450157 | G40: ='Backtest 2024 C'!F376 -> 2.3538986 | H40: ='Backtest 2024 C'!F374 -> 2.3630282 | I40: ='Backtest 2024 C'!F380 -> 3.7926385 | J40: ='Backtest 2024 C'!F381 -> 0.91596639 | K40: ='Backtest 2024 C'!F382 -> 0.99439776 | L40: ='Backtest 2024 C'!F383 -> 0.8627451
A41: Forecast A | B41: 2022 — forward backtest | C41: ='Backtest 2022 A'!F375 -> -1.8750869 | D41: ='Backtest 2022 A'!F377 -> -0.097820222 | E41: ='Backtest 2022 A'!F378 -> -0.027542019 | F41: ='Backtest 2022 A'!F379 -> -0.063225988 | G41: ='Backtest 2022 A'!F376 -> 2.7049268 | H41: ='Backtest 2022 A'!F374 -> 3.7269094 | I41: ='Backtest 2022 A'!F380 -> 3.4221072 | J41: ='Backtest 2022 A'!F381 -> 0.6162465 | K41: ='Backtest 2022 A'!F382 -> 0.94677871 | L41: ='Backtest 2022 A'!F383 -> 0.54061625
A42: Forecast B | B42: 2022 — forward backtest | C42: ='Backtest 2022 B'!F375 -> -1.8750869 | D42: ='Backtest 2022 B'!F377 -> -0.097820222 | E42: ='Backtest 2022 B'!F378 -> -0.027542019 | F42: ='Backtest 2022 B'!F379 -> -0.063225988 | G42: ='Backtest 2022 B'!F376 -> 2.6088338 | H42: ='Backtest 2022 B'!F374 -> 3.6060818 | I42: ='Backtest 2022 B'!F380 -> 3.3689436 | J42: ='Backtest 2022 B'!F381 -> 0.61904762 | K42: ='Backtest 2022 B'!F382 -> 0.94957983 | L42: ='Backtest 2022 B'!F383 -> 0.56302521
A43: Forecast C | B43: 2022 — forward backtest | C43: ='Backtest 2022 C'!F375 -> -1.8739902 | D43: ='Backtest 2022 C'!F377 -> -0.097799989 | E43: ='Backtest 2022 C'!F378 -> -0.02756289 | F43: ='Backtest 2022 C'!F379 -> -0.063225988 | G43: ='Backtest 2022 C'!F376 -> 2.7428656 | H43: ='Backtest 2022 C'!F374 -> 3.7657533 | I43: ='Backtest 2022 C'!F380 -> 3.4090857 | J43: ='Backtest 2022 C'!F381 -> 0.61344538 | K43: ='Backtest 2022 C'!F382 -> 0.93557423 | L43: ='Backtest 2022 C'!F383 -> 0.54341737
A44: Forecast A | B44: 2020 — hold-out test | C44: ='Backtest 2020 A'!F375 -> 3.1668994 | D44: ='Backtest 2020 A'!F377 -> 0.067757022 | E44: ='Backtest 2020 A'!F378 -> -0.059388119 | F44: ='Backtest 2020 A'!F379 -> 0.0036263082 | G44: ='Backtest 2020 A'!F376 -> 2.855298 | H44: ='Backtest 2020 A'!F374 -> 4.5834772 | I44: ='Backtest 2020 A'!F380 -> 2.795346 | J44: ='Backtest 2020 A'!F381 -> 0.39832869 | K44: ='Backtest 2020 A'!F382 -> 0.74651811 | L44: ='Backtest 2020 A'!F383 -> 0.454039
A45: Forecast B | B45: 2020 — hold-out test | C45: ='Backtest 2020 B'!F375 -> 3.1674177 | D45: ='Backtest 2020 B'!F377 -> 0.067767519 | E45: ='Backtest 2020 B'!F378 -> -0.059398434 | F45: ='Backtest 2020 B'!F379 -> 0.0036263082 | G45: ='Backtest 2020 B'!F376 -> 2.8557623 | H45: ='Backtest 2020 B'!F374 -> 4.654579 | I45: ='Backtest 2020 B'!F380 -> 2.6956713 | J45: ='Backtest 2020 B'!F381 -> 0.36768802 | K45: ='Backtest 2020 B'!F382 -> 0.73259053 | L45: ='Backtest 2020 B'!F383 -> 0.44289694
...

Sheet 2026 Forecast A
A1: PA-07 2026 House Forecast — Precinct-Level Predictions (Forecast A: full random forest)
A2: Candidates: Brooks | Mackenzie | District totals (yellow) are formulas over the precinct rows.
A3: Only the results are modelled (one random forest). Votes cast in each row = its 2022 turnout rate (House votes ÷ registered voters) × its 2026 registered voters. Brooks votes = votes cast × forecast Brooks share. Error terms combine the place’s own pattern error (2022 and 2024 backtests), the district-wide error and turnout error (2020, 2022 and 2024 backtests).
A4: Model / scenario | B4: Random forest on results — Forecast A (Full random forest), precinct model; turnout = 2022 turnout rate × 2026 registered voters | C4: As-of date | D4: 46300 | E4: Prepared by | F4: Max | G4: Version | H4: v9.0 (current map; feeder rule; 27 historical precincts)
A5: District Brooks share (scenario) | B5: ='Scenario & Comparison'!$C$6 -> 0.49330923 | C5: Uniform shift applied | D5: =B5-SUMPRODUCT(R12:R376,S12:S376)/SUM(S12:S376)/100 -> 0.50777762 | E5: Turnout multiplier (1.00 = 2022 turnout) | F5: ='Scenario & Comparison'!$C$7 -> 1
A6: DISTRICT TOTALS (auto-sum — do not type over)
A7: Geography | B7: (muni) | C7: (precinct) | D7: Brooks votes | E7: Mackenzie votes | F7: Total votes | G7: Brooks share | H7: Mackenzie share | I7: Notes | J7: Error term: place pattern (± pts) | K7: Error term: district-wide (± pts) | L7: Error term: total (± pts) | M7: Brooks share, 95% low | N7: Brooks share, 95% high | O7: Error term: votes cast (± votes) | P7: Error term: Brooks votes (± votes)
A8: PA-07 District | B8: (all precincts) | D8: =SUM(D12:D376) -> 151504 | E8: =SUM(E12:E376) -> 155596 | F8: =D8+E8 -> 307100 | G8: =IF(F8=0,"",D8/F8) -> 0.49333768 | H8: =IF(F8=0,"",E8/F8) -> 0.50666232 | I8: Headline forecast for the briefing | J8: 0 | K8: 2.1254091 | L8: =SQRT(J8^2+K8^2) -> 2.1254091 | M8: =G8-1.96*L8/100 -> 0.45167966 | N8: =G8+1.96*L8/100 -> 0.53499569 | O8: =ROUND(F8*0.03668,0) -> 11264 | P8: =ROUND(SQRT((F8*L8/100)^2+(G8*O8)^2),0) -> 8572
A9: Error terms are ±1 standard error: place pattern error by place size (2022 and 2024 forward backtests) plus district-wide and turnout error (2020, 2022 and 2024 backtests). 95% low/high = Brooks share ± 1.96 × total error term.
A10: PRECINCT DETAIL | R10: MODEL INPUTS (from the random forest — do not edit)
A11: County | B11: Municipality | C11: Precinct | D11: Brooks votes | E11: Mackenzie votes | F11: Total votes | G11: Brooks share | H11: Mackenzie share | I11: Notes / source method | J11: Error term: place pattern (± pts) | K11: Error term: district-wide (± pts) | L11: Error term: total (± pts) | M11: Brooks share, 95% low | N11: Brooks share, 95% high | O11: Error term: votes cast (± votes) | P11: Error term: Brooks votes (± votes) | R11: Model lean vs district (pts) | S11: Votes cast = 2022 turnout × 2026 registered | T11: Forecast Brooks share (unrounded) | U11: 2022 turnout (House votes ÷ registered) | V11: 2026 registered voters | W11: Votes-cast error (% of votes) | X11: Size group (backtest error band) | Y11: Registration source
A12: Carbon | B12: BANKS TOWNSHIP | C12: BANKS TOWNSHIP | D12: =ROUND(S12*T12,0) -> 139 | E12: =ROUND(S12,0)-D12 -> 225 | F12: =IF(COUNTA(D12:E12)=0,"",SUM(D12:E12)) -> 364 | G12: =IF(OR(F12="",F12=0),"",D12/F12) -> 0.38186813 | H12: =IF(OR(F12="",F12=0),"",E12/F12) -> 0.61813187 | I12: random forest (results only) | J12: 3.4605219 | K12: =$K$8 -> 2.1254091 | L12: =SQRT(J12^2+K12^2) -> 4.0611052 | M12: =IF(G12="","",MAX(0,G12-1.96*L12/100)) -> 0.30227047 | N12: =IF(G12="","",MIN(1,G12+1.96*L12/100)) -> 0.46146579 | O12: =ROUND(S12*W12,0) -> 53 | P12: =IF(F12="","",ROUND(SQRT((F12*L12/100)^2+(G12*O12)^2),0)) -> 25 | R12: -12.70327 | S12: =U12*V12*$F$5 -> 364.49096 | T12: =MAX(0,MIN(1,R12/100+$D$5)) -> 0.38074492 | U12: 0.5813253 | V12: 627 | W12: 0.14423891 | X12: Small | Y12: state rolls, precinct
A13: Carbon | B13: BEAVER MEADOWS BOROUGH | C13: BEAVER MEADOWS BOROUGH | D13: =ROUND(S13*T13,0) -> 94 | E13: =ROUND(S13,0)-D13 -> 236 | F13: =IF(COUNTA(D13:E13)=0,"",SUM(D13:E13)) -> 330 | G13: =IF(OR(F13="",F13=0),"",D13/F13) -> 0.28484848 | H13: =IF(OR(F13="",F13=0),"",E13/F13) -> 0.71515152 | I13: random forest (results only) | J13: 3.4605219 | K13: =$K$8 -> 2.1254091 | L13: =SQRT(J13^2+K13^2) -> 4.0611052 | M13: =IF(G13="","",MAX(0,G13-1.96*L13/100)) -> 0.20525082 | N13: =IF(G13="","",MIN(1,G13+1.96*L13/100)) -> 0.36444615 | O13: =ROUND(S13*W13,0) -> 48 | P13: =IF(F13="","",ROUND(SQRT((F13*L13/100)^2+(G13*O13)^2),0)) -> 19 | R13: -22.323393 | S13: =U13*V13*$F$5 -> 330.13014 | T13: =MAX(0,MIN(1,R13/100+$D$5)) -> 0.28454369 | U13: 0.53767123 | V13: 614 | W13: 0.14423891 | X13: Small | Y13: state rolls, precinct
A14: Carbon | B14: BOWMANSTOWN BOROUGH | C14: BOWMANSTOWN BOROUGH | D14: =ROUND(S14*T14,0) -> 118 | E14: =ROUND(S14,0)-D14 -> 238 | F14: =IF(COUNTA(D14:E14)=0,"",SUM(D14:E14)) -> 356 | G14: =IF(OR(F14="",F14=0),"",D14/F14) -> 0.33146067 | H14: =IF(OR(F14="",F14=0),"",E14/F14) -> 0.66853933 | I14: random forest (results only) | J14: 3.4605219 | K14: =$K$8 -> 2.1254091 | L14: =SQRT(J14^2+K14^2) -> 4.0611052 | M14: =IF(G14="","",MAX(0,G14-1.96*L14/100)) -> 0.25186301 | N14: =IF(G14="","",MIN(1,G14+1.96*L14/100)) -> 0.41105834 | O14: =ROUND(S14*W14,0) -> 51 | P14: =IF(F14="","",ROUND(SQRT((F14*L14/100)^2+(G14*O14)^2),0)) -> 22 | R14: -17.553778 | S14: =U14*V14*$F$5 -> 355.63437 | T14: =MAX(0,MIN(1,R14/100+$D$5)) -> 0.33223984 | U14: 0.63619744 | V14: 559 | W14: 0.14423891 | X14: Small | Y14: state rolls, precinct
A15: Carbon | B15: EAST PENN TOWNSHIP | C15: EAST PENN TOWNSHIP-NORTH | D15: =ROUND(S15*T15,0) -> 190 | E15: =ROUND(S15,0)-D15 -> 534 | F15: =IF(COUNTA(D15:E15)=0,"",SUM(D15:E15)) -> 724 | G15: =IF(OR(F15="",F15=0),"",D15/F15) -> 0.26243094 | H15: =IF(OR(F15="",F15=0),"",E15/F15) -> 0.73756906 | I15: random forest (results only) | J15: 2.113578 | K15: =$K$8 -> 2.1254091 | L15: =SQRT(J15^2+K15^2) -> 2.9974282 | M15: =IF(G15="","",MAX(0,G15-1.96*L15/100)) -> 0.20368135 | N15: =IF(G15="","",MIN(1,G15+1.96*L15/100)) -> 0.32118053 | O15: =ROUND(S15*W15,0) -> 61 | P15: =IF(F15="","",ROUND(SQRT((F15*L15/100)^2+(G15*O15)^2),0)) -> 27 | R15: -24.536113 | S15: =U15*V15*$F$5 -> 724.37791 | T15: =MAX(0,MIN(1,R15/100+$D$5)) -> 0.26241649 | U15: 0.67635659 | V15: 1071 | W15: 0.084758521 | X15: Medium | Y15: state rolls, precinct
A16: Carbon | B16: EAST PENN TOWNSHIP | C16: EAST PENN TOWNSHIP-SOUTH | D16: =ROUND(S16*T16,0) -> 174 | E16: =ROUND(S16,0)-D16 -> 437 | F16: =IF(COUNTA(D16:E16)=0,"",SUM(D16:E16)) -> 611 | G16: =IF(OR(F16="",F16=0),"",D16/F16) -> 0.28477905 | H16: =IF(OR(F16="",F16=0),"",E16/F16) -> 0.71522095 | I16: random forest (results only) | J16: 2.113578 | K16: =$K$8 -> 2.1254091 | L16: =SQRT(J16^2+K16^2) -> 2.9974282 | M16: =IF(G16="","",MAX(0,G16-1.96*L16/100)) -> 0.22602946 | N16: =IF(G16="","",MIN(1,G16+1.96*L16/100)) -> 0.34352864 | O16: =ROUND(S16*W16,0) -> 52 | P16: =IF(F16="","",ROUND(SQRT((F16*L16/100)^2+(G16*O16)^2),0)) -> 24 | R16: -22.307132 | S16: =U16*V16*$F$5 -> 610.89237 | T16: =MAX(0,MIN(1,R16/100+$D$5)) -> 0.2847063 | U16: 0.62591432 | V16: 976 | W16: 0.084758521 | X16: Medium | Y16: state rolls, precinct
A17: Carbon | B17: EAST SIDE BOROUGH | C17: EAST SIDE BOROUGH | D17: =ROUND(S17*T17,0) -> 32 | E17: =ROUND(S17,0)-D17 -> 61 | F17: =IF(COUNTA(D17:E17)=0,"",SUM(D17:E17)) -> 93 | G17: =IF(OR(F17="",F17=0),"",D17/F17) -> 0.34408602 | H17: =IF(OR(F17="",F17=0),"",E17/F17) -> 0.65591398 | I17: random forest (results only) | J17: 3.4605219 | K17: =$K$8 -> 2.1254091 | L17: =SQRT(J17^2+K17^2) -> 4.0611052 | M17: =IF(G17="","",MAX(0,G17-1.96*L17/100)) -> 0.26448836 | N17: =IF(G17="","",MIN(1,G17+1.96*L17/100)) -> 0.42368368 | O17: =ROUND(S17*W17,0) -> 13 | P17: =IF(F17="","",ROUND(SQRT((F17*L17/100)^2+(G17*O17)^2),0)) -> 6 | R17: -16.918868 | S17: =U17*V17*$F$5 -> 93.426829 | T17: =MAX(0,MIN(1,R17/100+$D$5)) -> 0.33858894 | U17: 0.57317073 | V17: 163 | W17: 0.14423891 | X17: Small | Y17: state rolls, precinct
A18: Carbon | B18: FRANKLIN TOWNSHIP | C18: FRANKLIN TOWNSHIP-HARRITY | D18: =ROUND(S18*T18,0) -> 246 | E18: =ROUND(S18,0)-D18 -> 607 | F18: =IF(COUNTA(D18:E18)=0,"",SUM(D18:E18)) -> 853 | G18: =IF(OR(F18="",F18=0),"",D18/F18) -> 0.2883939 | H18: =IF(OR(F18="",F18=0),"",E18/F18) -> 0.7116061 | I18: random forest (results only) | J18: 2.113578 | K18: =$K$8 -> 2.1254091 | L18: =SQRT(J18^2+K18^2) -> 2.9974282 | M18: =IF(G18="","",MAX(0,G18-1.96*L18/100)) -> 0.22964431 | N18: =IF(G18="","",MIN(1,G18+1.96*L18/100)) -> 0.3471435 | O18: =ROUND(S18*W18,0) -> 72 | P18: =IF(F18="","",ROUND(SQRT((F18*L18/100)^2+(G18*O18)^2),0)) -> 33 | R18: -21.991573 | S18: =U18*V18*$F$5 -> 852.99444 | T18: =MAX(0,MIN(1,R18/100+$D$5)) -> 0.28786189 | U18: 0.66640191 | V18: 1280 | W18: 0.084758521 | X18: Medium | Y18: state rolls, precinct
A19: Carbon | B19: FRANKLIN TOWNSHIP | C19: FRANKLIN TOWNSHIP-IND DIST | D19: =ROUND(S19*T19,0) -> 129 | E19: =ROUND(S19,0)-D19 -> 319 | F19: =IF(COUNTA(D19:E19)=0,"",SUM(D19:E19)) -> 448 | G19: =IF(OR(F19="",F19=0),"",D19/F19) -> 0.28794643 | H19: =IF(OR(F19="",F19=0),"",E19/F19) -> 0.71205357 | I19: random forest (results only) | J19: 3.4605219 | K19: =$K$8 -> 2.1254091 | L19: =SQRT(J19^2+K19^2) -> 4.0611052 | M19: =IF(G19="","",MAX(0,G19-1.96*L19/100)) -> 0.20834877 | N19: =IF(G19="","",MIN(1,G19+1.96*L19/100)) -> 0.36754409 | O19: =ROUND(S19*W19,0) -> 65 | P19: =IF(F19="","",ROUND(SQRT((F19*L19/100)^2+(G19*O19)^2),0)) -> 26 | R19: -22.076343 | S19: =U19*V19*$F$5 -> 447.93932 | T19: =MAX(0,MIN(1,R19/100+$D$5)) -> 0.28701419 | U19: 0.55097087 | V19: 813 | W19: 0.14423891 | X19: Small | Y19: state rolls, precinct
A20: Carbon | B20: FRANKLIN TOWNSHIP | C20: FRANKLIN TOWNSHIP-LONG RUN | D20: =ROUND(S20*T20,0) -> 185 | E20: =ROUND(S20,0)-D20 -> 498 | F20: =IF(COUNTA(D20:E20)=0,"",SUM(D20:E20)) -> 683 | G20: =IF(OR(F20="",F20=0),"",D20/F20) -> 0.27086384 | H20: =IF(OR(F20="",F20=0),"",E20/F20) -> 0.72913616 | I20: random forest (results only) | J20: 2.113578 | K20: =$K$8 -> 2.1254091 | L20: =SQRT(J20^2+K20^2) -> 2.9974282 | M20: =IF(G20="","",MAX(0,G20-1.96*L20/100)) -> 0.21211424 | N20: =IF(G20="","",MIN(1,G20+1.96*L20/100)) -> 0.32961343 | O20: =ROUND(S20*W20,0) -> 58 | P20: =IF(F20="","",ROUND(SQRT((F20*L20/100)^2+(G20*O20)^2),0)) -> 26 | R20: -23.704827 | S20: =U20*V20*$F$5 -> 683.32677 | T20: =MAX(0,MIN(1,R20/100+$D$5)) -> 0.27072935 | U20: 0.65452756 | V20: 1044 | W20: 0.084758521 | X20: Medium | Y20: state rolls, precinct
A21: Carbon | B21: JIM THORPE BOROUGH | C21: JIM THORPE BOROUGH-1ST | D21: =ROUND(S21*T21,0) -> 193 | E21: =ROUND(S21,0)-D21 -> 243 | F21: =IF(COUNTA(D21:E21)=0,"",SUM(D21:E21)) -> 436 | G21: =IF(OR(F21="",F21=0),"",D21/F21) -> 0.44266055 | H21: =IF(OR(F21="",F21=0),"",E21/F21) -> 0.55733945 | I21: random forest (results only) | J21: 3.4605219 | K21: =$K$8 -> 2.1254091 | L21: =SQRT(J21^2+K21^2) -> 4.0611052 | M21: =IF(G21="","",MAX(0,G21-1.96*L21/100)) -> 0.36306289 | N21: =IF(G21="","",MIN(1,G21+1.96*L21/100)) -> 0.52225821 | O21: =ROUND(S21*W21,0) -> 63 | P21: =IF(F21="","",ROUND(SQRT((F21*L21/100)^2+(G21*O21)^2),0)) -> 33 | R21: -6.4390872 | S21: =U21*V21*$F$5 -> 436.24467 | T21: =MAX(0,MIN(1,R21/100+$D$5)) -> 0.44338675 | U21: 0.62588905 | V21: 697 | W21: 0.14423891 | X21: Small | Y21: state rolls, precinct
A22: Carbon | B22: JIM THORPE BOROUGH | C22: JIM THORPE BOROUGH-2ND | D22: =ROUND(S22*T22,0) -> 120 | E22: =ROUND(S22,0)-D22 -> 160 | F22: =IF(COUNTA(D22:E22)=0,"",SUM(D22:E22)) -> 280 | G22: =IF(OR(F22="",F22=0),"",D22/F22) -> 0.42857143 | H22: =IF(OR(F22="",F22=0),"",E22/F22) -> 0.57142857 | I22: random forest (results only) | J22: 3.4605219 | K22: =$K$8 -> 2.1254091 | L22: =SQRT(J22^2+K22^2) -> 4.0611052 | M22: =IF(G22="","",MAX(0,G22-1.96*L22/100)) -> 0.34897377 | N22: =IF(G22="","",MIN(1,G22+1.96*L22/100)) -> 0.50816909 | O22: =ROUND(S22*W22,0) -> 40 | P22: =IF(F22="","",ROUND(SQRT((F22*L22/100)^2+(G22*O22)^2),0)) -> 21 | R22: -7.9782024 | S22: =U22*V22*$F$5 -> 280.5 | T22: =MAX(0,MIN(1,R22/100+$D$5)) -> 0.4279956 | U22: 0.56896552 | V22: 493 | W22: 0.14423891 | X22: Small | Y22: state rolls, precinct
A23: Carbon | B23: JIM THORPE BOROUGH | C23: JIM THORPE BOROUGH-3RD | D23: =ROUND(S23*T23,0) -> 248 | E23: =ROUND(S23,0)-D23 -> 398 | F23: =IF(COUNTA(D23:E23)=0,"",SUM(D23:E23)) -> 646 | G23: =IF(OR(F23="",F23=0),"",D23/F23) -> 0.38390093 | H23: =IF(OR(F23="",F23=0),"",E23/F23) -> 0.61609907 | I23: random forest (results only) | J23: 2.113578 | K23: =$K$8 -> 2.1254091 | L23: =SQRT(J23^2+K23^2) -> 2.9974282 | M23: =IF(G23="","",MAX(0,G23-1.96*L23/100)) -> 0.32515134 | N23: =IF(G23="","",MIN(1,G23+1.96*L23/100)) -> 0.44265052 | O23: =ROUND(S23*W23,0) -> 55 | P23: =IF(F23="","",ROUND(SQRT((F23*L23/100)^2+(G23*O23)^2),0)) -> 29 | R23: -12.405352 | S23: =U23*V23*$F$5 -> 645.69536 | T23: =MAX(0,MIN(1,R23/100+$D$5)) -> 0.3837241 | U23: 0.68984547 | V23: 936 | W23: 0.084758521 | X23: Medium | Y23: state rolls, precinct
... A376: Northampton | B376: WIND GAP | C376: WIND GAP | D376: =ROUND(S376*T376,0) -> 492 | E376: =ROUND(S376,0)-D376 -> 653 | F376: =IF(COUNTA(D376:E376)=0,"",SUM(D376:E376)) -> 1145 | G376: =IF(OR(F376="",F376=0),"",D376/F376) -> 0.42969432 | H376: =IF(OR(F376="",F376=0),"",E376/F376) -> 0.57030568 | I376: random forest (results only) | J376: 1.7315876 | K376: =$K$8 -> 2.1254091 | L376: =SQRT(J376^2+K376^2) -> 2.7414886 | M376: =IF(G376="","",MAX(0,G376-1.96*L376/100)) -> 0.37596115 | N376: =IF(G376="","",MIN(1,G376+1.96*L376/100)) -> 0.4834275 | O376: =ROUND(S376*W376,0) -> 72 | P376: =IF(F376="","",ROUND(SQRT((F376*L376/100)^2+(G376*O376)^2),0)) -> 44 | R376: -7.8074572 | S376: =U376*V376*$F$5 -> 1145.4806 | T376: =MAX(0,MIN(1,R376/100+$D$5)) -> 0.42970305 | U376: 0.53702795 | V376: 2133 | W376: 0.062659809 | X376: Large | Y376: state rolls, precinct

Sheet 2026 Forecast B
A1: PA-07 2026 House Forecast — Precinct-Level Predictions (Forecast B: shap-selected forest)
A2: Candidates: Brooks | Mackenzie | District totals (yellow) are formulas over the precinct rows.
A3: Only the results are modelled (one random forest). Votes cast in each row = its 2022 turnout rate (House votes ÷ registered voters) × its 2026 registered voters. Brooks votes = votes cast × forecast Brooks share. Error terms combine the place’s own pattern error (2022 and 2024 backtests), the district-wide error and turnout error (2020, 2022 and 2024 backtests).
A4: Model / scenario | B4: Random forest on results — Forecast B (SHAP-selected forest), precinct model; turnout = 2022 turnout rate × 2026 registered voters | C4: As-of date | D4: 46300 | E4: Prepared by | F4: Max | G4: Version | H4: v9.0 (current map; feeder rule; 27 historical precincts)
A5: District Brooks share (scenario) | B5: ='Scenario & Comparison'!$C$6 -> 0.49330923 | C5: Uniform shift applied | D5: =B5-SUMPRODUCT(R12:R376,S12:S376)/SUM(S12:S376)/100 -> 0.50969809 | E5: Turnout multiplier (1.00 = 2022 turnout) | F5: ='Scenario & Comparison'!$C$7 -> 1
A6: DISTRICT TOTALS (auto-sum — do not type over)
A7: Geography | B7: (muni) | C7: (precinct) | D7: Brooks votes | E7: Mackenzie votes | F7: Total votes | G7: Brooks share | H7: Mackenzie share | I7: Notes | J7: Error term: place pattern (± pts) | K7: Error term: district-wide (± pts) | L7: Error term: total (± pts) | M7: Brooks share, 95% low | N7: Brooks share, 95% high | O7: Error term: votes cast (± votes) | P7: Error term: Brooks votes (± votes)
A8: PA-07 District | B8: (all precincts) | D8: =SUM(D12:D376) -> 151496 | E8: =SUM(E12:E376) -> 155604 | F8: =D8+E8 -> 307100 | G8: =IF(F8=0,"",D8/F8) -> 0.49331162 | H8: =IF(F8=0,"",E8/F8) -> 0.50668838 | I8: Headline forecast for the briefing | J8: 0 | K8: 2.1257089 | L8: =SQRT(J8^2+K8^2) -> 2.1257089 | M8: =G8-1.96*L8/100 -> 0.45164773 | N8: =G8+1.96*L8/100 -> 0.53497552 | O8: =ROUND(F8*0.03668,0) -> 11264 | P8: =ROUND(SQRT((F8*L8/100)^2+(G8*O8)^2),0) -> 8573
A9: Error terms are ±1 standard error: place pattern error by place size (2022 and 2024 forward backtests) plus district-wide and turnout error (2020, 2022 and 2024 backtests). 95% low/high = Brooks share ± 1.96 × total error term.
A10: PRECINCT DETAIL | R10: MODEL INPUTS (from the random forest — do not edit)
A11: County | B11: Municipality | C11: Precinct | D11: Brooks votes | E11: Mackenzie votes | F11: Total votes | G11: Brooks share | H11: Mackenzie share | I11: Notes / source method | J11: Error term: place pattern (± pts) | K11: Error term: district-wide (± pts) | L11: Error term: total (± pts) | M11: Brooks share, 95% low | N11: Brooks share, 95% high | O11: Error term: votes cast (± votes) | P11: Error term: Brooks votes (± votes) | R11: Model lean vs district (pts) | S11: Votes cast = 2022 turnout × 2026 registered | T11: Forecast Brooks share (unrounded) | U11: 2022 turnout (House votes ÷ registered) | V11: 2026 registered voters | W11: Votes-cast error (% of votes) | X11: Size group (backtest error band) | Y11: Registration source
A12: Carbon | B12: BANKS TOWNSHIP | C12: BANKS TOWNSHIP | D12: =ROUND(S12*T12,0) -> 140 | E12: =ROUND(S12,0)-D12 -> 224 | F12: =IF(COUNTA(D12:E12)=0,"",SUM(D12:E12)) -> 364 | G12: =IF(OR(F12="",F12=0),"",D12/F12) -> 0.38461538 | H12: =IF(OR(F12="",F12=0),"",E12/F12) -> 0.61538462 | I12: random forest (results only) | J12: 3.2717186 | K12: =$K$8 -> 2.1257089 | L12: =SQRT(J12^2+K12^2) -> 3.9016382 | M12: =IF(G12="","",MAX(0,G12-1.96*L12/100)) -> 0.30814328 | N12: =IF(G12="","",MIN(1,G12+1.96*L12/100)) -> 0.46108749 | O12: =ROUND(S12*W12,0) -> 53 | P12: =IF(F12="","",ROUND(SQRT((F12*L12/100)^2+(G12*O12)^2),0)) -> 25 | R12: -12.429052 | S12: =U12*V12*$F$5 -> 364.49096 | T12: =MAX(0,MIN(1,R12/100+$D$5)) -> 0.38540757 | U12: 0.5813253 | V12: 627 | W12: 0.14423891 | X12: Small | Y12: state rolls, precinct
A13: Carbon | B13: BEAVER MEADOWS BOROUGH | C13: BEAVER MEADOWS BOROUGH | D13: =ROUND(S13*T13,0) -> 93 | E13: =ROUND(S13,0)-D13 -> 237 | F13: =IF(COUNTA(D13:E13)=0,"",SUM(D13:E13)) -> 330 | G13: =IF(OR(F13="",F13=0),"",D13/F13) -> 0.28181818 | H13: =IF(OR(F13="",F13=0),"",E13/F13) -> 0.71818182 | I13: random forest (results only) | J13: 3.2717186 | K13: =$K$8 -> 2.1257089 | L13: =SQRT(J13^2+K13^2) -> 3.9016382 | M13: =IF(G13="","",MAX(0,G13-1.96*L13/100)) -> 0.20534607 | N13: =IF(G13="","",MIN(1,G13+1.96*L13/100)) -> 0.35829029 | O13: =ROUND(S13*W13,0) -> 48 | P13: =IF(F13="","",ROUND(SQRT((F13*L13/100)^2+(G13*O13)^2),0)) -> 19 | R13: -22.670385 | S13: =U13*V13*$F$5 -> 330.13014 | T13: =MAX(0,MIN(1,R13/100+$D$5)) -> 0.28299424 | U13: 0.53767123 | V13: 614 | W13: 0.14423891 | X13: Small | Y13: state rolls, precinct
A14: Carbon | B14: BOWMANSTOWN BOROUGH | C14: BOWMANSTOWN BOROUGH | D14: =ROUND(S14*T14,0) -> 122 | E14: =ROUND(S14,0)-D14 -> 234 | F14: =IF(COUNTA(D14:E14)=0,"",SUM(D14:E14)) -> 356 | G14: =IF(OR(F14="",F14=0),"",D14/F14) -> 0.34269663 | H14: =IF(OR(F14="",F14=0),"",E14/F14) -> 0.65730337 | I14: random forest (results only) | J14: 3.2717186 | K14: =$K$8 -> 2.1257089 | L14: =SQRT(J14^2+K14^2) -> 3.9016382 | M14: =IF(G14="","",MAX(0,G14-1.96*L14/100)) -> 0.26622452 | N14: =IF(G14="","",MIN(1,G14+1.96*L14/100)) -> 0.41916874 | O14: =ROUND(S14*W14,0) -> 51 | P14: =IF(F14="","",ROUND(SQRT((F14*L14/100)^2+(G14*O14)^2),0)) -> 22 | R14: -16.763025 | S14: =U14*V14*$F$5 -> 355.63437 | T14: =MAX(0,MIN(1,R14/100+$D$5)) -> 0.34206784 | U14: 0.63619744 | V14: 559 | W14: 0.14423891 | X14: Small | Y14: state rolls, precinct
A15: Carbon | B15: EAST PENN TOWNSHIP | C15: EAST PENN TOWNSHIP-NORTH | D15: =ROUND(S15*T15,0) -> 185 | E15: =ROUND(S15,0)-D15 -> 539 | F15: =IF(COUNTA(D15:E15)=0,"",SUM(D15:E15)) -> 724 | G15: =IF(OR(F15="",F15=0),"",D15/F15) -> 0.25552486 | H15: =IF(OR(F15="",F15=0),"",E15/F15) -> 0.74447514 | I15: random forest (results only) | J15: 1.940776 | K15: =$K$8 -> 2.1257089 | L15: =SQRT(J15^2+K15^2) -> 2.878411 | M15: =IF(G15="","",MAX(0,G15-1.96*L15/100)) -> 0.19910801 | N15: =IF(G15="","",MIN(1,G15+1.96*L15/100)) -> 0.31194172 | O15: =ROUND(S15*W15,0) -> 61 | P15: =IF(F15="","",ROUND(SQRT((F15*L15/100)^2+(G15*O15)^2),0)) -> 26 | R15: -25.405272 | S15: =U15*V15*$F$5 -> 724.37791 | T15: =MAX(0,MIN(1,R15/100+$D$5)) -> 0.25564537 | U15: 0.67635659 | V15: 1071 | W15: 0.084758521 | X15: Medium | Y15: state rolls, precinct
A16: Carbon | B16: EAST PENN TOWNSHIP | C16: EAST PENN TOWNSHIP-SOUTH | D16: =ROUND(S16*T16,0) -> 171 | E16: =ROUND(S16,0)-D16 -> 440 | F16: =IF(COUNTA(D16:E16)=0,"",SUM(D16:E16)) -> 611 | G16: =IF(OR(F16="",F16=0),"",D16/F16) -> 0.27986907 | H16: =IF(OR(F16="",F16=0),"",E16/F16) -> 0.72013093 | I16: random forest (results only) | J16: 1.940776 | K16: =$K$8 -> 2.1257089 | L16: =SQRT(J16^2+K16^2) -> 2.878411 | M16: =IF(G16="","",MAX(0,G16-1.96*L16/100)) -> 0.22345221 | N16: =IF(G16="","",MIN(1,G16+1.96*L16/100)) -> 0.33628592 | O16: =ROUND(S16*W16,0) -> 52 | P16: =IF(F16="","",ROUND(SQRT((F16*L16/100)^2+(G16*O16)^2),0)) -> 23 | R16: -22.969312 | S16: =U16*V16*$F$5 -> 610.89237 | T16: =MAX(0,MIN(1,R16/100+$D$5)) -> 0.28000497 | U16: 0.62591432 | V16: 976 | W16: 0.084758521 | X16: Medium | Y16: state rolls, precinct
A17: Carbon | B17: EAST SIDE BOROUGH | C17: EAST SIDE BOROUGH | D17: =ROUND(S17*T17,0) -> 32 | E17: =ROUND(S17,0)-D17 -> 61 | F17: =IF(COUNTA(D17:E17)=0,"",SUM(D17:E17)) -> 93 | G17: =IF(OR(F17="",F17=0),"",D17/F17) -> 0.34408602 | H17: =IF(OR(F17="",F17=0),"",E17/F17) -> 0.65591398 | I17: random forest (results only) | J17: 3.2717186 | K17: =$K$8 -> 2.1257089 | L17: =SQRT(J17^2+K17^2) -> 3.9016382 | M17: =IF(G17="","",MAX(0,G17-1.96*L17/100)) -> 0.26761391 | N17: =IF(G17="","",MIN(1,G17+1.96*L17/100)) -> 0.42055813 | O17: =ROUND(S17*W17,0) -> 13 | P17: =IF(F17="","",ROUND(SQRT((F17*L17/100)^2+(G17*O17)^2),0)) -> 6 | R17: -17.226 | S17: =U17*V17*$F$5 -> 93.426829 | T17: =MAX(0,MIN(1,R17/100+$D$5)) -> 0.33743809 | U17: 0.57317073 | V17: 163 | W17: 0.14423891 | X17: Small | Y17: state rolls, precinct
A18: Carbon | B18: FRANKLIN TOWNSHIP | C18: FRANKLIN TOWNSHIP-HARRITY | D18: =ROUND(S18*T18,0) -> 244 | E18: =ROUND(S18,0)-D18 -> 609 | F18: =IF(COUNTA(D18:E18)=0,"",SUM(D18:E18)) -> 853 | G18: =IF(OR(F18="",F18=0),"",D18/F18) -> 0.28604924 | H18: =IF(OR(F18="",F18=0),"",E18/F18) -> 0.71395076 | I18: random forest (results only) | J18: 1.940776 | K18: =$K$8 -> 2.1257089 | L18: =SQRT(J18^2+K18^2) -> 2.878411 | M18: =IF(G18="","",MAX(0,G18-1.96*L18/100)) -> 0.22963238 | N18: =IF(G18="","",MIN(1,G18+1.96*L18/100)) -> 0.34246609 | O18: =ROUND(S18*W18,0) -> 72 | P18: =IF(F18="","",ROUND(SQRT((F18*L18/100)^2+(G18*O18)^2),0)) -> 32 | R18: -22.360368 | S18: =U18*V18*$F$5 -> 852.99444 | T18: =MAX(0,MIN(1,R18/100+$D$5)) -> 0.2860944 | U18: 0.66640191 | V18: 1280 | W18: 0.084758521 | X18: Medium | Y18: state rolls, precinct
A19: Carbon | B19: FRANKLIN TOWNSHIP | C19: FRANKLIN TOWNSHIP-IND DIST | D19: =ROUND(S19*T19,0) -> 130 | E19: =ROUND(S19,0)-D19 -> 318 | F19: =IF(COUNTA(D19:E19)=0,"",SUM(D19:E19)) -> 448 | G19: =IF(OR(F19="",F19=0),"",D19/F19) -> 0.29017857 | H19: =IF(OR(F19="",F19=0),"",E19/F19) -> 0.70982143 | I19: random forest (results only) | J19: 3.2717186 | K19: =$K$8 -> 2.1257089 | L19: =SQRT(J19^2+K19^2) -> 3.9016382 | M19: =IF(G19="","",MAX(0,G19-1.96*L19/100)) -> 0.21370646 | N19: =IF(G19="","",MIN(1,G19+1.96*L19/100)) -> 0.36665068 | O19: =ROUND(S19*W19,0) -> 65 | P19: =IF(F19="","",ROUND(SQRT((F19*L19/100)^2+(G19*O19)^2),0)) -> 26 | R19: -21.981537 | S19: =U19*V19*$F$5 -> 447.93932 | T19: =MAX(0,MIN(1,R19/100+$D$5)) -> 0.28988272 | U19: 0.55097087 | V19: 813 | W19: 0.14423891 | X19: Small | Y19: state rolls, precinct
A20: Carbon | B20: FRANKLIN TOWNSHIP | C20: FRANKLIN TOWNSHIP-LONG RUN | D20: =ROUND(S20*T20,0) -> 182 | E20: =ROUND(S20,0)-D20 -> 501 | F20: =IF(COUNTA(D20:E20)=0,"",SUM(D20:E20)) -> 683 | G20: =IF(OR(F20="",F20=0),"",D20/F20) -> 0.26647145 | H20: =IF(OR(F20="",F20=0),"",E20/F20) -> 0.73352855 | I20: random forest (results only) | J20: 1.940776 | K20: =$K$8 -> 2.1257089 | L20: =SQRT(J20^2+K20^2) -> 2.878411 | M20: =IF(G20="","",MAX(0,G20-1.96*L20/100)) -> 0.21005459 | N20: =IF(G20="","",MIN(1,G20+1.96*L20/100)) -> 0.3228883 | O20: =ROUND(S20*W20,0) -> 58 | P20: =IF(F20="","",ROUND(SQRT((F20*L20/100)^2+(G20*O20)^2),0)) -> 25 | R20: -24.291021 | S20: =U20*V20*$F$5 -> 683.32677 | T20: =MAX(0,MIN(1,R20/100+$D$5)) -> 0.26678788 | U20: 0.65452756 | V20: 1044 | W20: 0.084758521 | X20: Medium | Y20: state rolls, precinct
A21: Carbon | B21: JIM THORPE BOROUGH | C21: JIM THORPE BOROUGH-1ST | D21: =ROUND(S21*T21,0) -> 196 | E21: =ROUND(S21,0)-D21 -> 240 | F21: =IF(COUNTA(D21:E21)=0,"",SUM(D21:E21)) -> 436 | G21: =IF(OR(F21="",F21=0),"",D21/F21) -> 0.44954128 | H21: =IF(OR(F21="",F21=0),"",E21/F21) -> 0.55045872 | I21: random forest (results only) | J21: 3.2717186 | K21: =$K$8 -> 2.1257089 | L21: =SQRT(J21^2+K21^2) -> 3.9016382 | M21: =IF(G21="","",MAX(0,G21-1.96*L21/100)) -> 0.37306918 | N21: =IF(G21="","",MIN(1,G21+1.96*L21/100)) -> 0.52601339 | O21: =ROUND(S21*W21,0) -> 63 | P21: =IF(F21="","",ROUND(SQRT((F21*L21/100)^2+(G21*O21)^2),0)) -> 33 | R21: -5.9587258 | S21: =U21*V21*$F$5 -> 436.24467 | T21: =MAX(0,MIN(1,R21/100+$D$5)) -> 0.45011083 | U21: 0.62588905 | V21: 697 | W21: 0.14423891 | X21: Small | Y21: state rolls, precinct
A22: Carbon | B22: JIM THORPE BOROUGH | C22: JIM THORPE BOROUGH-2ND | D22: =ROUND(S22*T22,0) -> 116 | E22: =ROUND(S22,0)-D22 -> 164 | F22: =IF(COUNTA(D22:E22)=0,"",SUM(D22:E22)) -> 280 | G22: =IF(OR(F22="",F22=0),"",D22/F22) -> 0.41428571 | H22: =IF(OR(F22="",F22=0),"",E22/F22) -> 0.58571429 | I22: random forest (results only) | J22: 3.2717186 | K22: =$K$8 -> 2.1257089 | L22: =SQRT(J22^2+K22^2) -> 3.9016382 | M22: =IF(G22="","",MAX(0,G22-1.96*L22/100)) -> 0.33781361 | N22: =IF(G22="","",MIN(1,G22+1.96*L22/100)) -> 0.49075782 | O22: =ROUND(S22*W22,0) -> 40 | P22: =IF(F22="","",ROUND(SQRT((F22*L22/100)^2+(G22*O22)^2),0)) -> 20 | R22: -9.563064 | S22: =U22*V22*$F$5 -> 280.5 | T22: =MAX(0,MIN(1,R22/100+$D$5)) -> 0.41406745 | U22: 0.56896552 | V22: 493 | W22: 0.14423891 | X22: Small | Y22: state rolls, precinct
A23: Carbon | B23: JIM THORPE BOROUGH | C23: JIM THORPE BOROUGH-3RD | D23: =ROUND(S23*T23,0) -> 247 | E23: =ROUND(S23,0)-D23 -> 399 | F23: =IF(COUNTA(D23:E23)=0,"",SUM(D23:E23)) -> 646 | G23: =IF(OR(F23="",F23=0),"",D23/F23) -> 0.38235294 | H23: =IF(OR(F23="",F23=0),"",E23/F23) -> 0.61764706 | I23: random forest (results only) | J23: 1.940776 | K23: =$K$8 -> 2.1257089 | L23: =SQRT(J23^2+K23^2) -> 2.878411 | M23: =IF(G23="","",MAX(0,G23-1.96*L23/100)) -> 0.32593609 | N23: =IF(G23="","",MIN(1,G23+1.96*L23/100)) -> 0.4387698 | O23: =ROUND(S23*W23,0) -> 55 | P23: =IF(F23="","",ROUND(SQRT((F23*L23/100)^2+(G23*O23)^2),0)) -> 28 | R23: -12.698531 | S23: =U23*V23*$F$5 -> 645.69536 | T23: =MAX(0,MIN(1,R23/100+$D$5)) -> 0.38271278 | U23: 0.68984547 | V23: 936 | W23: 0.084758521 | X23: Medium | Y23: state rolls, precinct
... A376: Northampton | B376: WIND GAP | C376: WIND GAP | D376: =ROUND(S376*T376,0) -> 483 | E376: =ROUND(S376,0)-D376 -> 662 | F376: =IF(COUNTA(D376:E376)=0,"",SUM(D376:E376)) -> 1145 | G376: =IF(OR(F376="",F376=0),"",D376/F376) -> 0.42183406 | H376: =IF(OR(F376="",F376=0),"",E376/F376) -> 0.57816594 | I376: random forest (results only) | J376: 1.7575191 | K376: =$K$8 -> 2.1257089 | L376: =SQRT(J376^2+K376^2) -> 2.7581718 | M376: =IF(G376="","",MAX(0,G376-1.96*L376/100)) -> 0.36777389 | N376: =IF(G376="","",MIN(1,G376+1.96*L376/100)) -> 0.47589423 | O376: =ROUND(S376*W376,0) -> 72 | P376: =IF(F376="","",ROUND(SQRT((F376*L376/100)^2+(G376*O376)^2),0)) -> 44 | R376: -8.842218 | S376: =U376*V376*$F$5 -> 1145.4806 | T376: =MAX(0,MIN(1,R376/100+$D$5)) -> 0.42127591 | U376: 0.53702795 | V376: 2133 | W376: 0.062659809 | X376: Large | Y376: state rolls, precinct

Sheet 2026 Forecast C
A1: PA-07 2026 House Forecast — Precinct-Level Predictions (Forecast C: shap family-reweighted forest)
A2: Candidates: Brooks | Mackenzie | District totals (yellow) are formulas over the precinct rows.
A3: Only the results are modelled (one random forest). Votes cast in each row = its 2022 turnout rate (House votes ÷ registered voters) × its 2026 registered voters. Brooks votes = votes cast × forecast Brooks share. Error terms combine the place’s own pattern error (2022 and 2024 backtests), the district-wide error and turnout error (2020, 2022 and 2024 backtests).
A4: Model / scenario | B4: Random forest on results — Forecast C (SHAP family-reweighted forest), precinct model; turnout = 2022 turnout rate × 2026 registered voters | C4: As-of date | D4: 46300 | E4: Prepared by | F4: Max | G4: Version | H4: v9.0 (current map; feeder rule; 27 historical precincts)
A5: District Brooks share (scenario) | B5: ='Scenario & Comparison'!$C$6 -> 0.49330923 | C5: Uniform shift applied | D5: =B5-SUMPRODUCT(R12:R376,S12:S376)/SUM(S12:S376)/100 -> 0.50837086 | E5: Turnout multiplier (1.00 = 2022 turnout) | F5: ='Scenario & Comparison'!$C$7 -> 1
A6: DISTRICT TOTALS (auto-sum — do not type over)
A7: Geography | B7: (muni) | C7: (precinct) | D7: Brooks votes | E7: Mackenzie votes | F7: Total votes | G7: Brooks share | H7: Mackenzie share | I7: Notes | J7: Error term: place pattern (± pts) | K7: Error term: district-wide (± pts) | L7: Error term: total (± pts) | M7: Brooks share, 95% low | N7: Brooks share, 95% high | O7: Error term: votes cast (± votes) | P7: Error term: Brooks votes (± votes)
A8: PA-07 District | B8: (all precincts) | D8: =SUM(D12:D376) -> 151497 | E8: =SUM(E12:E376) -> 155603 | F8: =D8+E8 -> 307100 | G8: =IF(F8=0,"",D8/F8) -> 0.49331488 | H8: =IF(F8=0,"",E8/F8) -> 0.50668512 | I8: Headline forecast for the briefing | J8: 0 | K8: 2.1253506 | L8: =SQRT(J8^2+K8^2) -> 2.1253506 | M8: =G8-1.96*L8/100 -> 0.45165801 | N8: =G8+1.96*L8/100 -> 0.53497175 | O8: =ROUND(F8*0.03668,0) -> 11264 | P8: =ROUND(SQRT((F8*L8/100)^2+(G8*O8)^2),0) -> 8572
A9: Error terms are ±1 standard error: place pattern error by place size (2022 and 2024 forward backtests) plus district-wide and turnout error (2020, 2022 and 2024 backtests). 95% low/high = Brooks share ± 1.96 × total error term.
A10: PRECINCT DETAIL | R10: MODEL INPUTS (from the random forest — do not edit)
A11: County | B11: Municipality | C11: Precinct | D11: Brooks votes | E11: Mackenzie votes | F11: Total votes | G11: Brooks share | H11: Mackenzie share | I11: Notes / source method | J11: Error term: place pattern (± pts) | K11: Error term: district-wide (± pts) | L11: Error term: total (± pts) | M11: Brooks share, 95% low | N11: Brooks share, 95% high | O11: Error term: votes cast (± votes) | P11: Error term: Brooks votes (± votes) | R11: Model lean vs district (pts) | S11: Votes cast = 2022 turnout × 2026 registered | T11: Forecast Brooks share (unrounded) | U11: 2022 turnout (House votes ÷ registered) | V11: 2026 registered voters | W11: Votes-cast error (% of votes) | X11: Size group (backtest error band) | Y11: Registration source
A12: Carbon | B12: BANKS TOWNSHIP | C12: BANKS TOWNSHIP | D12: =ROUND(S12*T12,0) -> 139 | E12: =ROUND(S12,0)-D12 -> 225 | F12: =IF(COUNTA(D12:E12)=0,"",SUM(D12:E12)) -> 364 | G12: =IF(OR(F12="",F12=0),"",D12/F12) -> 0.38186813 | H12: =IF(OR(F12="",F12=0),"",E12/F12) -> 0.61813187 | I12: random forest (results only) | J12: 3.4877482 | K12: =$K$8 -> 2.1253506 | L12: =SQRT(J12^2+K12^2) -> 4.0842995 | M12: =IF(G12="","",MAX(0,G12-1.96*L12/100)) -> 0.30181586 | N12: =IF(G12="","",MIN(1,G12+1.96*L12/100)) -> 0.4619204 | O12: =ROUND(S12*W12,0) -> 53 | P12: =IF(F12="","",ROUND(SQRT((F12*L12/100)^2+(G12*O12)^2),0)) -> 25 | R12: -12.702743 | S12: =U12*V12*$F$5 -> 364.49096 | T12: =MAX(0,MIN(1,R12/100+$D$5)) -> 0.38134343 | U12: 0.5813253 | V12: 627 | W12: 0.14423891 | X12: Small | Y12: state rolls, precinct
A13: Carbon | B13: BEAVER MEADOWS BOROUGH | C13: BEAVER MEADOWS BOROUGH | D13: =ROUND(S13*T13,0) -> 94 | E13: =ROUND(S13,0)-D13 -> 236 | F13: =IF(COUNTA(D13:E13)=0,"",SUM(D13:E13)) -> 330 | G13: =IF(OR(F13="",F13=0),"",D13/F13) -> 0.28484848 | H13: =IF(OR(F13="",F13=0),"",E13/F13) -> 0.71515152 | I13: random forest (results only) | J13: 3.4877482 | K13: =$K$8 -> 2.1253506 | L13: =SQRT(J13^2+K13^2) -> 4.0842995 | M13: =IF(G13="","",MAX(0,G13-1.96*L13/100)) -> 0.20479621 | N13: =IF(G13="","",MIN(1,G13+1.96*L13/100)) -> 0.36490076 | O13: =ROUND(S13*W13,0) -> 48 | P13: =IF(F13="","",ROUND(SQRT((F13*L13/100)^2+(G13*O13)^2),0)) -> 19 | R13: -22.363267 | S13: =U13*V13*$F$5 -> 330.13014 | T13: =MAX(0,MIN(1,R13/100+$D$5)) -> 0.28473819 | U13: 0.53767123 | V13: 614 | W13: 0.14423891 | X13: Small | Y13: state rolls, precinct
A14: Carbon | B14: BOWMANSTOWN BOROUGH | C14: BOWMANSTOWN BOROUGH | D14: =ROUND(S14*T14,0) -> 118 | E14: =ROUND(S14,0)-D14 -> 238 | F14: =IF(COUNTA(D14:E14)=0,"",SUM(D14:E14)) -> 356 | G14: =IF(OR(F14="",F14=0),"",D14/F14) -> 0.33146067 | H14: =IF(OR(F14="",F14=0),"",E14/F14) -> 0.66853933 | I14: random forest (results only) | J14: 3.4877482 | K14: =$K$8 -> 2.1253506 | L14: =SQRT(J14^2+K14^2) -> 4.0842995 | M14: =IF(G14="","",MAX(0,G14-1.96*L14/100)) -> 0.2514084 | N14: =IF(G14="","",MIN(1,G14+1.96*L14/100)) -> 0.41151294 | O14: =ROUND(S14*W14,0) -> 51 | P14: =IF(F14="","",ROUND(SQRT((F14*L14/100)^2+(G14*O14)^2),0)) -> 22 | R14: -17.722549 | S14: =U14*V14*$F$5 -> 355.63437 | T14: =MAX(0,MIN(1,R14/100+$D$5)) -> 0.33114537 | U14: 0.63619744 | V14: 559 | W14: 0.14423891 | X14: Small | Y14: state rolls, precinct
A15: Carbon | B15: EAST PENN TOWNSHIP | C15: EAST PENN TOWNSHIP-NORTH | D15: =ROUND(S15*T15,0) -> 190 | E15: =ROUND(S15,0)-D15 -> 534 | F15: =IF(COUNTA(D15:E15)=0,"",SUM(D15:E15)) -> 724 | G15: =IF(OR(F15="",F15=0),"",D15/F15) -> 0.26243094 | H15: =IF(OR(F15="",F15=0),"",E15/F15) -> 0.73756906 | I15: random forest (results only) | J15: 2.1380818 | K15: =$K$8 -> 2.1253506 | L15: =SQRT(J15^2+K15^2) -> 3.0147154 | M15: =IF(G15="","",MAX(0,G15-1.96*L15/100)) -> 0.20334252 | N15: =IF(G15="","",MIN(1,G15+1.96*L15/100)) -> 0.32151936 | O15: =ROUND(S15*W15,0) -> 61 | P15: =IF(F15="","",ROUND(SQRT((F15*L15/100)^2+(G15*O15)^2),0)) -> 27 | R15: -24.605839 | S15: =U15*V15*$F$5 -> 724.37791 | T15: =MAX(0,MIN(1,R15/100+$D$5)) -> 0.26231247 | U15: 0.67635659 | V15: 1071 | W15: 0.084758521 | X15: Medium | Y15: state rolls, precinct
A16: Carbon | B16: EAST PENN TOWNSHIP | C16: EAST PENN TOWNSHIP-SOUTH | D16: =ROUND(S16*T16,0) -> 174 | E16: =ROUND(S16,0)-D16 -> 437 | F16: =IF(COUNTA(D16:E16)=0,"",SUM(D16:E16)) -> 611 | G16: =IF(OR(F16="",F16=0),"",D16/F16) -> 0.28477905 | H16: =IF(OR(F16="",F16=0),"",E16/F16) -> 0.71522095 | I16: random forest (results only) | J16: 2.1380818 | K16: =$K$8 -> 2.1253506 | L16: =SQRT(J16^2+K16^2) -> 3.0147154 | M16: =IF(G16="","",MAX(0,G16-1.96*L16/100)) -> 0.22569063 | N16: =IF(G16="","",MIN(1,G16+1.96*L16/100)) -> 0.34386747 | O16: =ROUND(S16*W16,0) -> 52 | P16: =IF(F16="","",ROUND(SQRT((F16*L16/100)^2+(G16*O16)^2),0)) -> 24 | R16: -22.284666 | S16: =U16*V16*$F$5 -> 610.89237 | T16: =MAX(0,MIN(1,R16/100+$D$5)) -> 0.2855242 | U16: 0.62591432 | V16: 976 | W16: 0.084758521 | X16: Medium | Y16: state rolls, precinct
A17: Carbon | B17: EAST SIDE BOROUGH | C17: EAST SIDE BOROUGH | D17: =ROUND(S17*T17,0) -> 32 | E17: =ROUND(S17,0)-D17 -> 61 | F17: =IF(COUNTA(D17:E17)=0,"",SUM(D17:E17)) -> 93 | G17: =IF(OR(F17="",F17=0),"",D17/F17) -> 0.34408602 | H17: =IF(OR(F17="",F17=0),"",E17/F17) -> 0.65591398 | I17: random forest (results only) | J17: 3.4877482 | K17: =$K$8 -> 2.1253506 | L17: =SQRT(J17^2+K17^2) -> 4.0842995 | M17: =IF(G17="","",MAX(0,G17-1.96*L17/100)) -> 0.26403375 | N17: =IF(G17="","",MIN(1,G17+1.96*L17/100)) -> 0.42413829 | O17: =ROUND(S17*W17,0) -> 13 | P17: =IF(F17="","",ROUND(SQRT((F17*L17/100)^2+(G17*O17)^2),0)) -> 6 | R17: -17.116424 | S17: =U17*V17*$F$5 -> 93.426829 | T17: =MAX(0,MIN(1,R17/100+$D$5)) -> 0.33720662 | U17: 0.57317073 | V17: 163 | W17: 0.14423891 | X17: Small | Y17: state rolls, precinct
A18: Carbon | B18: FRANKLIN TOWNSHIP | C18: FRANKLIN TOWNSHIP-HARRITY | D18: =ROUND(S18*T18,0) -> 247 | E18: =ROUND(S18,0)-D18 -> 606 | F18: =IF(COUNTA(D18:E18)=0,"",SUM(D18:E18)) -> 853 | G18: =IF(OR(F18="",F18=0),"",D18/F18) -> 0.28956624 | H18: =IF(OR(F18="",F18=0),"",E18/F18) -> 0.71043376 | I18: random forest (results only) | J18: 2.1380818 | K18: =$K$8 -> 2.1253506 | L18: =SQRT(J18^2+K18^2) -> 3.0147154 | M18: =IF(G18="","",MAX(0,G18-1.96*L18/100)) -> 0.23047781 | N18: =IF(G18="","",MIN(1,G18+1.96*L18/100)) -> 0.34865466 | O18: =ROUND(S18*W18,0) -> 72 | P18: =IF(F18="","",ROUND(SQRT((F18*L18/100)^2+(G18*O18)^2),0)) -> 33 | R18: -21.934432 | S18: =U18*V18*$F$5 -> 852.99444 | T18: =MAX(0,MIN(1,R18/100+$D$5)) -> 0.28902654 | U18: 0.66640191 | V18: 1280 | W18: 0.084758521 | X18: Medium | Y18: state rolls, precinct
A19: Carbon | B19: FRANKLIN TOWNSHIP | C19: FRANKLIN TOWNSHIP-IND DIST | D19: =ROUND(S19*T19,0) -> 130 | E19: =ROUND(S19,0)-D19 -> 318 | F19: =IF(COUNTA(D19:E19)=0,"",SUM(D19:E19)) -> 448 | G19: =IF(OR(F19="",F19=0),"",D19/F19) -> 0.29017857 | H19: =IF(OR(F19="",F19=0),"",E19/F19) -> 0.70982143 | I19: random forest (results only) | J19: 3.4877482 | K19: =$K$8 -> 2.1253506 | L19: =SQRT(J19^2+K19^2) -> 4.0842995 | M19: =IF(G19="","",MAX(0,G19-1.96*L19/100)) -> 0.2101263 | N19: =IF(G19="","",MIN(1,G19+1.96*L19/100)) -> 0.37023084 | O19: =ROUND(S19*W19,0) -> 65 | P19: =IF(F19="","",ROUND(SQRT((F19*L19/100)^2+(G19*O19)^2),0)) -> 26 | R19: -21.894475 | S19: =U19*V19*$F$5 -> 447.93932 | T19: =MAX(0,MIN(1,R19/100+$D$5)) -> 0.28942611 | U19: 0.55097087 | V19: 813 | W19: 0.14423891 | X19: Small | Y19: state rolls, precinct
A20: Carbon | B20: FRANKLIN TOWNSHIP | C20: FRANKLIN TOWNSHIP-LONG RUN | D20: =ROUND(S20*T20,0) -> 186 | E20: =ROUND(S20,0)-D20 -> 497 | F20: =IF(COUNTA(D20:E20)=0,"",SUM(D20:E20)) -> 683 | G20: =IF(OR(F20="",F20=0),"",D20/F20) -> 0.27232796 | H20: =IF(OR(F20="",F20=0),"",E20/F20) -> 0.72767204 | I20: random forest (results only) | J20: 2.1380818 | K20: =$K$8 -> 2.1253506 | L20: =SQRT(J20^2+K20^2) -> 3.0147154 | M20: =IF(G20="","",MAX(0,G20-1.96*L20/100)) -> 0.21323954 | N20: =IF(G20="","",MIN(1,G20+1.96*L20/100)) -> 0.33141639 | O20: =ROUND(S20*W20,0) -> 58 | P20: =IF(F20="","",ROUND(SQRT((F20*L20/100)^2+(G20*O20)^2),0)) -> 26 | R20: -23.608117 | S20: =U20*V20*$F$5 -> 683.32677 | T20: =MAX(0,MIN(1,R20/100+$D$5)) -> 0.27228968 | U20: 0.65452756 | V20: 1044 | W20: 0.084758521 | X20: Medium | Y20: state rolls, precinct
A21: Carbon | B21: JIM THORPE BOROUGH | C21: JIM THORPE BOROUGH-1ST | D21: =ROUND(S21*T21,0) -> 193 | E21: =ROUND(S21,0)-D21 -> 243 | F21: =IF(COUNTA(D21:E21)=0,"",SUM(D21:E21)) -> 436 | G21: =IF(OR(F21="",F21=0),"",D21/F21) -> 0.44266055 | H21: =IF(OR(F21="",F21=0),"",E21/F21) -> 0.55733945 | I21: random forest (results only) | J21: 3.4877482 | K21: =$K$8 -> 2.1253506 | L21: =SQRT(J21^2+K21^2) -> 4.0842995 | M21: =IF(G21="","",MAX(0,G21-1.96*L21/100)) -> 0.36260828 | N21: =IF(G21="","",MIN(1,G21+1.96*L21/100)) -> 0.52271282 | O21: =ROUND(S21*W21,0) -> 63 | P21: =IF(F21="","",ROUND(SQRT((F21*L21/100)^2+(G21*O21)^2),0)) -> 33 | R21: -6.5279449 | S21: =U21*V21*$F$5 -> 436.24467 | T21: =MAX(0,MIN(1,R21/100+$D$5)) -> 0.44309141 | U21: 0.62588905 | V21: 697 | W21: 0.14423891 | X21: Small | Y21: state rolls, precinct
A22: Carbon | B22: JIM THORPE BOROUGH | C22: JIM THORPE BOROUGH-2ND | D22: =ROUND(S22*T22,0) -> 119 | E22: =ROUND(S22,0)-D22 -> 161 | F22: =IF(COUNTA(D22:E22)=0,"",SUM(D22:E22)) -> 280 | G22: =IF(OR(F22="",F22=0),"",D22/F22) -> 0.425 | H22: =IF(OR(F22="",F22=0),"",E22/F22) -> 0.575 | I22: random forest (results only) | J22: 3.4877482 | K22: =$K$8 -> 2.1253506 | L22: =SQRT(J22^2+K22^2) -> 4.0842995 | M22: =IF(G22="","",MAX(0,G22-1.96*L22/100)) -> 0.34494773 | N22: =IF(G22="","",MIN(1,G22+1.96*L22/100)) -> 0.50505227 | O22: =ROUND(S22*W22,0) -> 40 | P22: =IF(F22="","",ROUND(SQRT((F22*L22/100)^2+(G22*O22)^2),0)) -> 20 | R22: -8.3228305 | S22: =U22*V22*$F$5 -> 280.5 | T22: =MAX(0,MIN(1,R22/100+$D$5)) -> 0.42514255 | U22: 0.56896552 | V22: 493 | W22: 0.14423891 | X22: Small | Y22: state rolls, precinct
A23: Carbon | B23: JIM THORPE BOROUGH | C23: JIM THORPE BOROUGH-3RD | D23: =ROUND(S23*T23,0) -> 248 | E23: =ROUND(S23,0)-D23 -> 398 | F23: =IF(COUNTA(D23:E23)=0,"",SUM(D23:E23)) -> 646 | G23: =IF(OR(F23="",F23=0),"",D23/F23) -> 0.38390093 | H23: =IF(OR(F23="",F23=0),"",E23/F23) -> 0.61609907 | I23: random forest (results only) | J23: 2.1380818 | K23: =$K$8 -> 2.1253506 | L23: =SQRT(J23^2+K23^2) -> 3.0147154 | M23: =IF(G23="","",MAX(0,G23-1.96*L23/100)) -> 0.32481251 | N23: =IF(G23="","",MIN(1,G23+1.96*L23/100)) -> 0.44298935 | O23: =ROUND(S23*W23,0) -> 55 | P23: =IF(F23="","",ROUND(SQRT((F23*L23/100)^2+(G23*O23)^2),0)) -> 29 | R23: -12.489696 | S23: =U23*V23*$F$5 -> 645.69536 | T23: =MAX(0,MIN(1,R23/100+$D$5)) -> 0.3834739 | U23: 0.68984547 | V23: 936 | W23: 0.084758521 | X23: Medium | Y23: state rolls, precinct
... A376: Northampton | B376: WIND GAP | C376: WIND GAP | D376: =ROUND(S376*T376,0) -> 491 | E376: =ROUND(S376,0)-D376 -> 654 | F376: =IF(COUNTA(D376:E376)=0,"",SUM(D376:E376)) -> 1145 | G376: =IF(OR(F376="",F376=0),"",D376/F376) -> 0.42882096 | H376: =IF(OR(F376="",F376=0),"",E376/F376) -> 0.57117904 | I376: random forest (results only) | J376: 1.7280547 | K376: =$K$8 -> 2.1253506 | L376: =SQRT(J376^2+K376^2) -> 2.7392131 | M376: =IF(G376="","",MAX(0,G376-1.96*L376/100)) -> 0.37513238 | N376: =IF(G376="","",MIN(1,G376+1.96*L376/100)) -> 0.48250954 | O376: =ROUND(S376*W376,0) -> 72 | P376: =IF(F376="","",ROUND(SQRT((F376*L376/100)^2+(G376*O376)^2),0)) -> 44 | R376: -7.9403275 | S376: =U376*V376*$F$5 -> 1145.4806 | T376: =MAX(0,MIN(1,R376/100+$D$5)) -> 0.42896758 | U376: 0.53702795 | V376: 2133 | W376: 0.062659809 | X376: Large | Y376: state rolls, precinct

Sheet How Forecasts Are Weighted
A1: How the three precinct-level forecasts weigh their inputs (SHAP) — results-only random forests
A3: Forecast A — Full random forest.
A4: All 22 candidate inputs go into one random forest that forecasts the Democratic share. Nothing is weighted by hand; SHAP measures what the forest learned. This is the reference.
A5: Forecast B — SHAP-selected forest.
A6: Keeps only inputs whose average |SHAP| beat all 10 random columns in at least 18 of 20 refits and that held at least 2% of Forecast A’s SHAP total (6 of 22 kept), then refits the forest on them. Weight that was spread thinly over weak inputs is concentrated on the strong ones.
A7: Forecast C — SHAP family-reweighted forest.
A8: Keeps Forecast A’s forest but multiplies each input family’s SHAP values by a weight fitted to how well that family predicted elections the forest had not seen (leave-one-election-out, fitted within each election). Families under 3% of SHAP stay at ×1; others are limited to ×0.5–×2 because there are only three training elections.
A9: Backtests.
A10: Each 2024 backtest uses its own forecast’s weighting: A’s full input set, B’s selected inputs, and C’s exact family weights — refit only on 2020 and 2022.
A11: Turnout.
A12: Not modelled in any forecast: votes cast = each place’s 2022 turnout rate × its 2026 registered voters (2020 turnout × 2024 registered in the backtest). All differences between A, B and C come from the results model.
A14: Family share of SHAP value in votes, 2026 forecast rows
A15: Input family | B15: Forecast A | C15: Forecast B | D15: Forecast C | E15: Forecast C weight (×)
A16: Election type | B16: 0.0012803358 | C16: 0 | D16: 0.0012620897 | E16: 1
A17: Geography & municipal context | B17: 0.13387813 | C17: 0.15359271 | D17: 0.14252182 | E17: 1.0799544
A18: Historical voter data | B18: 0.73999289 | C18: 0.69415473 | D18: 0.69968704 | E18: 0.95920171
A19: Voter registration data | B19: 0.12484865 | C19: 0.15225256 | D19: 0.15652905 | E19: 1.271876
A20: Out-of-fold pattern error before → after Forecast C’s re-weighting: 2.58 → 2.57 points.
A22: Top inputs in each forecast (share of SHAP value in votes)
A23: # | B23: Forecast A | C23: Share | D23: Forecast B | E23: Share | F23: Forecast C | G23: Share
A24: 1 | B24: Feeder precinct House lean (district-relative) | C24: 0.54616418 | D24: Feeder precinct House lean (district-relative) | E24: 0.47242082 | F24: Feeder precinct House lean (district-relative) | G24: 0.51641576
A25: 2 | B25: Feeder electorate: R % of ballots | C25: 0.17258011 | D25: Feeder electorate: R % of ballots | E25: 0.22173391 | F25: Feeder electorate: R % of ballots | G25: 0.16318004
A26: 3 | B26: Feeder municipality House lean | C26: 0.1181371 | D26: Feeder municipality House lean | E26: 0.15359271 | F26: Feeder municipality House lean | G26: 0.1257645
A27: 4 | B27: State registration: R % | C27: 0.050769429 | D27: State registration: R % | E27: 0.086611623 | F27: State registration: R % | G27: 0.063652196
A28: 5 | B28: State registration: D % | C28: 0.02255122 | D28: State registration: change in D−R margin since the feeder elections | E28: 0.038347962 | F28: State registration: D % | G28: 0.028273603
A29: 6 | B29: State registration: change in D−R margin since the feeder elections | C29: 0.021644407 | D29: State registration: D % | E29: 0.027292975 | F29: State registration: change in D−R margin since the feeder elections | G29: 0.027136686
A30: 7 | B30: Voter-file party switch gap (voter-file R % − state R %) | C30: 0.0085310098 | F30: Voter-file party switch gap (voter-file R % − state R %) | G30: 0.010695758
A31: 8 | B31: Feeder precinct vs. its municipality (pts) | C31: 0.0084001564 | F31: Feeder precinct vs. its municipality (pts) | G31: 0.0089425033
A32: 9 | B32: Registered voters (log, state) | C32: 0.0067709206 | F32: Registered voters (log, state) | G32: 0.008489045
A33: 10 | B33: Feeder turnout: R registrants | C33: 0.0060976883 | F33: State registration: other % | G33: 0.0061214085
A35: Forecast B — random-column test and selection
A36: Input | B36: Beat random columns (of 20) | C36: Share of SHAP in A | D36: Kept in B?
A37: Feeder precinct House lean (district-relative) | B37: 20 | C37: 0.56027106 | D37: Yes
A38: Feeder electorate: R % of ballots | B38: 20 | C38: 0.17096928 | D38: Yes
A39: Feeder municipality House lean | B39: 20 | C39: 0.11329823 | D39: Yes
A40: State registration: R % | B40: 20 | C40: 0.048067511 | D40: Yes
A41: State registration: change in D−R margin since the feeder elections | B41: 20 | C41: 0.022488904 | D41: Yes
A42: State registration: D % | B42: 20 | C42: 0.020630906 | D42: Yes
A43: Feeder precinct vs. its municipality (pts) | B43: 20 | C43: 0.00797696 | D43: No
A44: Voter-file party switch gap (voter-file R % − state R %) | B44: 20 | C44: 0.0076225312 | D44: No
...

Sheet Feature Ranking A
A1: Rank | B1: Feature | C1: Input family | D1: Share of model | E1: Share within its family | F1: SHAP value in votes | G1: Used to forecast | H1: Significance test result | I1: Variable (short name) | J1: Status in Forecast B
A2: 1 | B2: Precinct’s Democratic percent of the two-party House vote, above or below the district average, from the feeder elections (2026: 67% 2022 + 33% 2024) | C2: Historical voter data | D2: 0.54616418 | E2: 0.73806679 | F2: 100.73477 | G2: Democratic percent of the two-party vote | H2: Beat all 10 random comparison columns in 20 of 20 refits. | I2: Feeder precinct House lean (district-relative) | J2: Kept in B
A3: 2 | B3: Registered Republicans as a percent of everyone who voted, in the feeder elections (voter file) | C3: Historical voter data | D3: 0.17258011 | E3: 0.23321861 | F3: 31.830753 | G3: Democratic percent of the two-party vote | H3: Beat all 10 random comparison columns in 20 of 20 refits. | I3: Feeder electorate: R % of ballots | J3: Kept in B
A4: 3 | B4: The precinct’s municipality’s House lean from the feeder elections | C4: Geography & municipal context | D4: 0.1181371 | E4: 0.88242274 | F4: 21.78926 | G4: Democratic percent of the two-party vote | H4: Beat all 10 random comparison columns in 20 of 20 refits. | I4: Feeder municipality House lean | J4: Kept in B
A5: 4 | B5: Registered Republicans as a percent of all registered voters, as of the election (Department of State) | C5: Voter registration data | D5: 0.050769429 | E5: 0.40664782 | F5: 9.3639362 | G5: Democratic percent of the two-party vote | H5: Beat all 10 random comparison columns in 20 of 20 refits. | I5: State registration: R % | J5: Kept in B
A6: 5 | B6: Registered Democrats as a percent of all registered voters, as of the election (Department of State) | C6: Voter registration data | D6: 0.02255122 | E6: 0.18062847 | F6: 4.1593571 | G6: Democratic percent of the two-party vote | H6: Beat all 10 random comparison columns in 20 of 20 refits. | I6: State registration: D % | J6: Kept in B
A7: 6 | B7: Registered Democrats minus Republicans (percent) now, minus the same in the feeder elections (Department of State) | C7: Voter registration data | D7: 0.021644407 | E7: 0.17336517 | F7: 3.9921041 | G7: Democratic percent of the two-party vote | H7: Beat all 10 random comparison columns in 20 of 20 refits. | I7: State registration: change in D−R margin since the feeder elections | J7: Kept in B
A8: 7 | B8: Republican percent in the voter file minus on the state rolls (a party-switching signal) | C8: Voter registration data | D8: 0.0085310098 | E8: 0.068330816 | F8: 1.5734633 | G8: Democratic percent of the two-party vote | H8: Beat all 10 random comparison columns in 20 of 20 refits. | I8: Voter-file party switch gap (voter-file R % − state R %) | J8: Dropped from B
A9: 8 | B9: Precinct’s feeder House lean minus its municipality’s, in points | C9: Geography & municipal context | D9: 0.0084001564 | E9: 0.062744801 | F9: 1.5493286 | G9: Democratic percent of the two-party vote | H9: Beat all 10 random comparison columns in 20 of 20 refits. | I9: Feeder precinct vs. its municipality (pts) | J9: Dropped from B
A10: 9 | B10: Number of registered voters, log scale (Department of State) | C10: Voter registration data | D10: 0.0067709206 | E10: 0.054233033 | F10: 1.2488316 | G10: Democratic percent of the two-party vote | H10: Beat all 10 random comparison columns in 20 of 20 refits. | I10: Registered voters (log, state) | J10: Dropped from B
A11: 10 | B11: Percent of registered Republicans who voted, in the feeder elections (voter file) | C11: Historical voter data | D11: 0.0060976883 | E11: 0.0082401985 | F11: 1.1246604 | G11: Democratic percent of the two-party vote | H11: Beat all 10 random comparison columns in 20 of 20 refits. | I11: Feeder turnout: R registrants | J11: Dropped from B
