Workbook

Sheet Scenario & Comparison
A1: PA-07 2026 House Forecast — Precinct Level: three forecasts compared
A2: Candidates: Brooks | Mackenzie | Change the yellow cell to set the district-wide Brooks share; all three forecasts and their district totals update.
A3: Forecasts A, B and C use different SHAP-based weightings of the same random-forest inputs (see How Forecasts Are Weighted). Error terms come from each forecast’s own 2024 backtest.
A5: SCENARIO
A6: District-wide Brooks share of the two-party vote (input) | C6: =AVERAGE(C10,C12) -> 0.52816948 | D6: ← default: average of the 2018 and 2022 midterms in today’s district
A8: Past House results in today’s district | C8: Democratic share | D8: Democratic votes | E8: Republican votes
A9: (certified precinct returns; Carbon and Polk 2018/2020 excluded — they voted in PA-09/PA-08)
A10: 2018 General | C10: =D10/(D10+E10) -> 0.54737325 | D10: 126510 | E10: 104612
A11: 2020 General | C11: =D11/(D11+E11) -> 0.51437081 | D11: 176154 | E11: 166311
A12: 2022 General | C12: =D12/(D12+E12) -> 0.50896572 | D12: 149243 | E12: 143985
A13: 2024 General | C13: =D13/(D13+E13) -> 0.49424813 | D13: 196561 | E13: 201136
A15: DISTRICT TOTALS BY FORECAST (live from each forecast tab)
A16: Forecast | B16: Weighting | C16: Brooks votes | D16: Mackenzie votes | E16: Total votes | F16: Brooks share | G16: Error term (± pts) | H16: Brooks share range | I16: Error term, Brooks votes (±)
A17: Forecast A | B17: Full random forest | C17: ='2026 Forecast A'!D8 -> 158256 | D17: ='2026 Forecast A'!E8 -> 141367 | E17: ='2026 Forecast A'!F8 -> 299623 | F17: ='2026 Forecast A'!G8 -> 0.52818375 | G17: ='2026 Forecast A'!J8 -> 2.2311014 | H17: =TEXT('2026 Forecast A'!K8,"0.0%")&" – "&TEXT('2026 Forecast A'!L8,"0.0%") -> 50.6% – 55.0% | I17: ='2026 Forecast A'!N8 -> 8118
A18: Forecast B | B18: SHAP-selected forest | C18: ='2026 Forecast B'!D8 -> 158252 | D18: ='2026 Forecast B'!E8 -> 141371 | E18: ='2026 Forecast B'!F8 -> 299623 | F18: ='2026 Forecast B'!G8 -> 0.5281704 | G18: ='2026 Forecast B'!J8 -> 2.2335886 | H18: =TEXT('2026 Forecast B'!K8,"0.0%")&" – "&TEXT('2026 Forecast B'!L8,"0.0%") -> 50.6% – 55.1% | I18: ='2026 Forecast B'!N8 -> 8124
A19: Forecast C | B19: SHAP family-reweighted forest | C19: ='2026 Forecast C'!D8 -> 158260 | D19: ='2026 Forecast C'!E8 -> 141363 | E19: ='2026 Forecast C'!F8 -> 299623 | F19: ='2026 Forecast C'!G8 -> 0.5281971 | G19: ='2026 Forecast C'!J8 -> 2.2330359 | H19: =TEXT('2026 Forecast C'!K8,"0.0%")&" – "&TEXT('2026 Forecast C'!L8,"0.0%") -> 50.6% – 55.1% | I19: ='2026 Forecast C'!N8 -> 8122
A21: ERROR TERMS — 2024 BACKTEST OF EACH FORECAST
A22: Forecast | B22: Rows scored | C22: Avg miss per row, Dem share (pts) | D22: RMS miss per row, Dem share (pts) | E22: District-wide miss (pts) | F22: Pattern RMS miss (pts) | G22: Total votes cast miss | H22: Avg miss per row, Dem votes | I22: Rows within 3 pts
A23: Forecast A | B23: ='2024 Backtest A'!F384 -> 342 | C23: ='2024 Backtest A'!F378 -> 2.7262324 | D23: ='2024 Backtest A'!F379 -> 3.3438536 | E23: ='2024 Backtest A'!F380 -> 2.2311014 | F23: ='2024 Backtest A'!F381 -> 2.1600589 | G23: ='2024 Backtest A'!F382 -> -0.029072653 | H23: ='2024 Backtest A'!F376 -> 34.152047 | I23: ='2024 Backtest A'!F383 -> 0.62573099
A24: Forecast B | B24: ='2024 Backtest B'!F384 -> 342 | C24: ='2024 Backtest B'!F378 -> 2.8516954 | D24: ='2024 Backtest B'!F379 -> 3.4437264 | E24: ='2024 Backtest B'!F380 -> 2.2335886 | F24: ='2024 Backtest B'!F381 -> 2.274836 | G24: ='2024 Backtest B'!F382 -> -0.029072653 | H24: ='2024 Backtest B'!F376 -> 36.687135 | I24: ='2024 Backtest B'!F383 -> 0.58479532
A25: Forecast C | B25: ='2024 Backtest C'!F384 -> 342 | C25: ='2024 Backtest C'!F378 -> 2.8113842 | D25: ='2024 Backtest C'!F379 -> 3.575552 | E25: ='2024 Backtest C'!F380 -> 2.2330359 | F25: ='2024 Backtest C'!F381 -> 2.4261515 | G25: ='2024 Backtest C'!F382 -> -0.029072653 | H25: ='2024 Backtest C'!F376 -> 34.769006 | I25: ='2024 Backtest C'!F383 -> 0.63157895
A26: District-wide miss is the same for all three because it comes from the level rule (last same-type election), not the forests. The pattern miss is what separates the forecasts; it sets each row’s error term.
A28: PRECINCT COMPARISON (Brooks share by forecast, live)
A29: County | B29: Municipality | C29: Precinct | D29: Forecast A | E29: Forecast B | F29: Forecast C | G29: Spread (max − min, pts) | H29: Error term A (± pts) | I29: Error term B (± pts) | J29: Error term C (± pts) | K29: Projected votes (A) | L29: Calls agree?
A30: ='2026 Forecast A'!A12 -> Carbon | B30: ='2026 Forecast A'!B12 -> BANKS TOWNSHIP | C30: ='2026 Forecast A'!C12 -> BANKS TOWNSHIP | D30: ='2026 Forecast A'!G12 -> 0.44300518 | E30: ='2026 Forecast B'!G12 -> 0.44559585 | F30: ='2026 Forecast C'!G12 -> 0.43782383 | G30: =(MAX(D30:F30)-MIN(D30:F30))*100 -> 0.77720207 | H30: ='2026 Forecast A'!J12 -> 3.0260856 | I30: ='2026 Forecast B'!J12 -> 2.8748004 | J30: ='2026 Forecast C'!J12 -> 3.4531761 | K30: ='2026 Forecast A'!F12 -> 386 | L30: =IF(OR(AND(D30>0.5,E30>0.5,F30>0.5),AND(D30<0.5,E30<0.5,F30<0.5)),"Yes","No — toss-up") -> Yes
A31: ='2026 Forecast A'!A13 -> Carbon | B31: ='2026 Forecast A'!B13 -> BEAVER MEADOWS BOROUGH | C31: ='2026 Forecast A'!C13 -> BEAVER MEADOWS BOROUGH | D31: ='2026 Forecast A'!G13 -> 0.32484076 | E31: ='2026 Forecast B'!G13 -> 0.33121019 | F31: ='2026 Forecast C'!G13 -> 0.31528662 | G31: =(MAX(D31:F31)-MIN(D31:F31))*100 -> 1.5923567 | H31: ='2026 Forecast A'!J13 -> 3.0260856 | I31: ='2026 Forecast B'!J13 -> 2.8748004 | J31: ='2026 Forecast C'!J13 -> 3.4531761 | K31: ='2026 Forecast A'!F13 -> 314 | L31: =IF(OR(AND(D31>0.5,E31>0.5,F31>0.5),AND(D31<0.5,E31<0.5,F31<0.5)),"Yes","No — toss-up") -> Yes
A32: ='2026 Forecast A'!A14 -> Carbon | B32: ='2026 Forecast A'!B14 -> BOWMANSTOWN BOROUGH | C32: ='2026 Forecast A'!C14 -> BOWMANSTOWN BOROUGH | D32: ='2026 Forecast A'!G14 -> 0.3591954 | E32: ='2026 Forecast B'!G14 -> 0.37356322 | F32: ='2026 Forecast C'!G14 -> 0.35344828 | G32: =(MAX(D32:F32)-MIN(D32:F32))*100 -> 2.0114943 | H32: ='2026 Forecast A'!J14 -> 3.0260856 | I32: ='2026 Forecast B'!J14 -> 2.8748004 | J32: ='2026 Forecast C'!J14 -> 3.4531761 | K32: ='2026 Forecast A'!F14 -> 348 | L32: =IF(OR(AND(D32>0.5,E32>0.5,F32>0.5),AND(D32<0.5,E32<0.5,F32<0.5)),"Yes","No — toss-up") -> Yes
A33: ='2026 Forecast A'!A15 -> Carbon | B33: ='2026 Forecast A'!B15 -> EAST PENN TOWNSHIP | C33: ='2026 Forecast A'!C15 -> EAST PENN TOWNSHIP-NORTH | D33: ='2026 Forecast A'!G15 -> 0.29083095 | E33: ='2026 Forecast B'!G15 -> 0.29799427 | F33: ='2026 Forecast C'!G15 -> 0.28223496 | G33: =(MAX(D33:F33)-MIN(D33:F33))*100 -> 1.5759312 | H33: ='2026 Forecast A'!J15 -> 3.0260856 | I33: ='2026 Forecast B'!J15 -> 2.8748004 | J33: ='2026 Forecast C'!J15 -> 3.4531761 | K33: ='2026 Forecast A'!F15 -> 698 | L33: =IF(OR(AND(D33>0.5,E33>0.5,F33>0.5),AND(D33<0.5,E33<0.5,F33<0.5)),"Yes","No — toss-up") -> Yes
A34: ='2026 Forecast A'!A16 -> Carbon | B34: ='2026 Forecast A'!B16 -> EAST PENN TOWNSHIP | C34: ='2026 Forecast A'!C16 -> EAST PENN TOWNSHIP-SOUTH | D34: ='2026 Forecast A'!G16 -> 0.32053422 | E34: ='2026 Forecast B'!G16 -> 0.32053422 | F34: ='2026 Forecast C'!G16 -> 0.31218698 | G34: =(MAX(D34:F34)-MIN(D34:F34))*100 -> 0.83472454 | H34: ='2026 Forecast A'!J16 -> 3.0260856 | I34: ='2026 Forecast B'!J16 -> 2.8748004 | J34: ='2026 Forecast C'!J16 -> 3.4531761 | K34: ='2026 Forecast A'!F16 -> 599 | L34: =IF(OR(AND(D34>0.5,E34>0.5,F34>0.5),AND(D34<0.5,E34<0.5,F34<0.5)),"Yes","No — toss-up") -> Yes
A35: ='2026 Forecast A'!A17 -> Carbon | B35: ='2026 Forecast A'!B17 -> EAST SIDE BOROUGH | C35: ='2026 Forecast A'!C17 -> EAST SIDE BOROUGH | D35: ='2026 Forecast A'!G17 -> 0.38297872 | E35: ='2026 Forecast B'!G17 -> 0.39361702 | F35: ='2026 Forecast C'!G17 -> 0.37234043 | G35: =(MAX(D35:F35)-MIN(D35:F35))*100 -> 2.1276596 | H35: ='2026 Forecast A'!J17 -> 3.0260856 | I35: ='2026 Forecast B'!J17 -> 2.8748004 | J35: ='2026 Forecast C'!J17 -> 3.4531761 | K35: ='2026 Forecast A'!F17 -> 94 | L35: =IF(OR(AND(D35>0.5,E35>0.5,F35>0.5),AND(D35<0.5,E35<0.5,F35<0.5)),"Yes","No — toss-up") -> Yes
A36: ='2026 Forecast A'!A18 -> Carbon | B36: ='2026 Forecast A'!B18 -> FRANKLIN TOWNSHIP | C36: ='2026 Forecast A'!C18 -> FRANKLIN TOWNSHIP-HARRITY | D36: ='2026 Forecast A'!G18 -> 0.32300358 | E36: ='2026 Forecast B'!G18 -> 0.32300358 | F36: ='2026 Forecast C'!G18 -> 0.31346841 | G36: =(MAX(D36:F36)-MIN(D36:F36))*100 -> 0.95351609 | H36: ='2026 Forecast A'!J18 -> 1.8085538 | I36: ='2026 Forecast B'!J18 -> 1.924721 | J36: ='2026 Forecast C'!J18 -> 2.0502504 | K36: ='2026 Forecast A'!F18 -> 839 | L36: =IF(OR(AND(D36>0.5,E36>0.5,F36>0.5),AND(D36<0.5,E36<0.5,F36<0.5)),"Yes","No — toss-up") -> Yes
A37: ='2026 Forecast A'!A19 -> Carbon | B37: ='2026 Forecast A'!B19 -> FRANKLIN TOWNSHIP | C37: ='2026 Forecast A'!C19 -> FRANKLIN TOWNSHIP-IND DIST | D37: ='2026 Forecast A'!G19 -> 0.31277533 | E37: ='2026 Forecast B'!G19 -> 0.31938326 | F37: ='2026 Forecast C'!G19 -> 0.30396476 | G37: =(MAX(D37:F37)-MIN(D37:F37))*100 -> 1.5418502 | H37: ='2026 Forecast A'!J19 -> 3.0260856 | I37: ='2026 Forecast B'!J19 -> 2.8748004 | J37: ='2026 Forecast C'!J19 -> 3.4531761 | K37: ='2026 Forecast A'!F19 -> 454 | L37: =IF(OR(AND(D37>0.5,E37>0.5,F37>0.5),AND(D37<0.5,E37<0.5,F37<0.5)),"Yes","No — toss-up") -> Yes
A38: ='2026 Forecast A'!A20 -> Carbon | B38: ='2026 Forecast A'!B20 -> FRANKLIN TOWNSHIP | C38: ='2026 Forecast A'!C20 -> FRANKLIN TOWNSHIP-LONG RUN | D38: ='2026 Forecast A'!G20 -> 0.3112782 | E38: ='2026 Forecast B'!G20 -> 0.3112782 | F38: ='2026 Forecast C'!G20 -> 0.30225564 | G38: =(MAX(D38:F38)-MIN(D38:F38))*100 -> 0.90225564 | H38: ='2026 Forecast A'!J20 -> 3.0260856 | I38: ='2026 Forecast B'!J20 -> 2.8748004 | J38: ='2026 Forecast C'!J20 -> 3.4531761 | K38: ='2026 Forecast A'!F20 -> 665 | L38: =IF(OR(AND(D38>0.5,E38>0.5,F38>0.5),AND(D38<0.5,E38<0.5,F38<0.5)),"Yes","No — toss-up") -> Yes
A39: ='2026 Forecast A'!A21 -> Carbon | B39: ='2026 Forecast A'!B21 -> JIM THORPE BOROUGH | C39: ='2026 Forecast A'!C21 -> JIM THORPE BOROUGH-1ST | D39: ='2026 Forecast A'!G21 -> 0.49090909 | E39: ='2026 Forecast B'!G21 -> 0.5 | F39: ='2026 Forecast C'!G21 -> 0.48863636 | G39: =(MAX(D39:F39)-MIN(D39:F39))*100 -> 1.1363636 | H39: ='2026 Forecast A'!J21 -> 3.0260856 | I39: ='2026 Forecast B'!J21 -> 2.8748004 | J39: ='2026 Forecast C'!J21 -> 3.4531761 | K39: ='2026 Forecast A'!F21 -> 440 | L39: =IF(OR(AND(D39>0.5,E39>0.5,F39>0.5),AND(D39<0.5,E39<0.5,F39<0.5)),"Yes","No — toss-up") -> No — toss-up
A40: ='2026 Forecast A'!A22 -> Carbon | B40: ='2026 Forecast A'!B22 -> JIM THORPE BOROUGH | C40: ='2026 Forecast A'!C22 -> JIM THORPE BOROUGH-2ND | D40: ='2026 Forecast A'!G22 -> 0.47138047 | E40: ='2026 Forecast B'!G22 -> 0.49158249 | F40: ='2026 Forecast C'!G22 -> 0.47138047 | G40: =(MAX(D40:F40)-MIN(D40:F40))*100 -> 2.020202 | H40: ='2026 Forecast A'!J22 -> 3.0260856 | I40: ='2026 Forecast B'!J22 -> 2.8748004 | J40: ='2026 Forecast C'!J22 -> 3.4531761 | K40: ='2026 Forecast A'!F22 -> 297 | L40: =IF(OR(AND(D40>0.5,E40>0.5,F40>0.5),AND(D40<0.5,E40<0.5,F40<0.5)),"Yes","No — toss-up") -> Yes
A41: ='2026 Forecast A'!A23 -> Carbon | B41: ='2026 Forecast A'!B23 -> JIM THORPE BOROUGH | C41: ='2026 Forecast A'!C23 -> JIM THORPE BOROUGH-3RD | D41: ='2026 Forecast A'!G23 -> 0.4272 | E41: ='2026 Forecast B'!G23 -> 0.432 | F41: ='2026 Forecast C'!G23 -> 0.4224 | G41: =(MAX(D41:F41)-MIN(D41:F41))*100 -> 0.96 | H41: ='2026 Forecast A'!J23 -> 3.0260856 | I41: ='2026 Forecast B'!J23 -> 2.8748004 | J41: ='2026 Forecast C'!J23 -> 3.4531761 | K41: ='2026 Forecast A'!F23 -> 625 | L41: =IF(OR(AND(D41>0.5,E41>0.5,F41>0.5),AND(D41<0.5,E41<0.5,F41<0.5)),"Yes","No — toss-up") -> Yes
... A399: ='2026 Forecast A'!A381 -> Northampton | B399: ='2026 Forecast A'!B381 -> WIND GAP | C399: ='2026 Forecast A'!C381 -> WIND GAP | D399: ='2026 Forecast A'!G381 -> 0.47671233 | E399: ='2026 Forecast B'!G381 -> 0.47488584 | F399: ='2026 Forecast C'!G381 -> 0.47579909 | G399: =(MAX(D399:F399)-MIN(D399:F399))*100 -> 0.1826484 | H399: ='2026 Forecast A'!J381 -> 1.8085538 | I399: ='2026 Forecast B'!J381 -> 1.924721 | J399: ='2026 Forecast C'!J381 -> 2.0502504 | K399: ='2026 Forecast A'!F381 -> 1095 | L399: =IF(OR(AND(D399>0.5,E399>0.5,F399>0.5),AND(D399<0.5,E399<0.5,F399<0.5)),"Yes","No — toss-up") -> Yes

Sheet 2026 Forecast A
A1: PA-07 2026 House Forecast — Precinct-Level Predictions (Forecast A: full random forest)
A2: Candidates: Brooks | Mackenzie | District totals (yellow) are formulas over the precinct rows.
A3: Brooks and Mackenzie votes are formulas: 2022 House votes cast × forecast Brooks share (turnout held at 2022 levels). Change the district scenario on the Scenario & Comparison tab. Error terms come from this forecast’s 2024 backtest.
A4: Model / scenario | B4: Random forest on results only — Forecast A (Full random forest), precinct model; turnout = 2022 | C4: As-of date | D4: 46300 | E4: Prepared by | F4: Max | G4: Version | H4: v1.0
A5: District Brooks share (scenario) | B5: ='Scenario & Comparison'!$C$6 -> 0.52816948 | C5: Uniform shift applied | D5: =B5-SUMPRODUCT(P12:P381,Q12:Q381)/SUM(Q12:Q381)/100 -> 0.5265672 | E5: 2024 backtest district miss (pts) | F5: 2.2311014
A6: DISTRICT TOTALS (auto-sum — do not type over)
A7: Geography | B7: (muni) | C7: (precinct) | D7: Brooks votes | E7: Mackenzie votes | F7: Total votes | G7: Brooks share | H7: Mackenzie share | I7: Notes | J7: Error term: Brooks share (± pts) | K7: Brooks share, low | L7: Brooks share, high | M7: Error term: votes cast (± votes) | N7: Error term: Brooks votes (± votes)
A8: PA-07 District | B8: (all precincts) | D8: =SUM(D12:D381) -> 158256 | E8: =SUM(E12:E381) -> 141367 | F8: =D8+E8 -> 299623 | G8: =IF(F8=0,"",D8/F8) -> 0.52818375 | H8: =IF(F8=0,"",E8/F8) -> 0.47181625 | I8: Headline forecast for the briefing | J8: 2.2311014 | K8: =G8-J8/100 -> 0.50587274 | L8: =G8+J8/100 -> 0.55049476 | M8: =ROUND(F8*0.0291,0) -> 8719 | N8: =ROUND(SQRT((F8*J8/100)^2+(G8*M8)^2),0) -> 8118
A9: Discussion prompt: Precinct and municipal district totals use the same scenario share, so their Brooks share matches by design; vote totals differ slightly because 2022 votes were re-allocated where precinct lines changed.
A10: PRECINCT DETAIL | P10: MODEL INPUTS (from the random forests — do not edit)
A11: County | B11: Municipality | C11: Precinct | D11: Brooks votes | E11: Mackenzie votes | F11: Total votes | G11: Brooks share | H11: Mackenzie share | I11: Notes / source method | J11: Error term: Brooks share (± pts) | K11: Brooks share, low | L11: Brooks share, high | M11: Error term: votes cast (± votes) | N11: Error term: Brooks votes (± votes) | P11: Model lean vs district (pts) | Q11: Votes cast (= 2022 House votes) | R11: Forecast Brooks share (unrounded) | S11: Votes error term (% of votes) | T11: Size group (backtest error band)
A12: Carbon | B12: BANKS TOWNSHIP | C12: BANKS TOWNSHIP | D12: =ROUND(Q12*R12,0) -> 171 | E12: =ROUND(Q12,0)-D12 -> 215 | F12: =IF(COUNTA(D12:E12)=0,"",SUM(D12:E12)) -> 386 | G12: =IF(OR(F12="",F12=0),"",D12/F12) -> 0.44300518 | H12: =IF(OR(F12="",F12=0),"",E12/F12) -> 0.55699482 | I12: random forest | J12: 3.0260856 | K12: =IF(G12="","",MAX(0,G12-J12/100)) -> 0.41274433 | L12: =IF(G12="","",MIN(1,G12+J12/100)) -> 0.47326604 | M12: =ROUND(Q12*S12,0) -> 24 | N12: =ROUND(SQRT((F12*J12/100)^2+(G12*M12)^2),0) -> 16 | P12: -8.3120668 | Q12: 386 | R12: =MAX(0,MIN(1,P12/100+$D$5)) -> 0.44344653 | S12: 0.061040569 | T12: Small
A13: Carbon | B13: BEAVER MEADOWS BOROUGH | C13: BEAVER MEADOWS BOROUGH | D13: =ROUND(Q13*R13,0) -> 102 | E13: =ROUND(Q13,0)-D13 -> 212 | F13: =IF(COUNTA(D13:E13)=0,"",SUM(D13:E13)) -> 314 | G13: =IF(OR(F13="",F13=0),"",D13/F13) -> 0.32484076 | H13: =IF(OR(F13="",F13=0),"",E13/F13) -> 0.67515924 | I13: random forest | J13: 3.0260856 | K13: =IF(G13="","",MAX(0,G13-J13/100)) -> 0.29457991 | L13: =IF(G13="","",MIN(1,G13+J13/100)) -> 0.35510162 | M13: =ROUND(Q13*S13,0) -> 19 | N13: =ROUND(SQRT((F13*J13/100)^2+(G13*M13)^2),0) -> 11 | P13: -20.225366 | Q13: 314 | R13: =MAX(0,MIN(1,P13/100+$D$5)) -> 0.32431355 | S13: 0.061040569 | T13: Small
A14: Carbon | B14: BOWMANSTOWN BOROUGH | C14: BOWMANSTOWN BOROUGH | D14: =ROUND(Q14*R14,0) -> 125 | E14: =ROUND(Q14,0)-D14 -> 223 | F14: =IF(COUNTA(D14:E14)=0,"",SUM(D14:E14)) -> 348 | G14: =IF(OR(F14="",F14=0),"",D14/F14) -> 0.3591954 | H14: =IF(OR(F14="",F14=0),"",E14/F14) -> 0.6408046 | I14: random forest | J14: 3.0260856 | K14: =IF(G14="","",MAX(0,G14-J14/100)) -> 0.32893455 | L14: =IF(G14="","",MIN(1,G14+J14/100)) -> 0.38945626 | M14: =ROUND(Q14*S14,0) -> 21 | N14: =ROUND(SQRT((F14*J14/100)^2+(G14*M14)^2),0) -> 13 | P14: -16.727513 | Q14: 348 | R14: =MAX(0,MIN(1,P14/100+$D$5)) -> 0.35929207 | S14: 0.061040569 | T14: Small
A15: Carbon | B15: EAST PENN TOWNSHIP | C15: EAST PENN TOWNSHIP-NORTH | D15: =ROUND(Q15*R15,0) -> 203 | E15: =ROUND(Q15,0)-D15 -> 495 | F15: =IF(COUNTA(D15:E15)=0,"",SUM(D15:E15)) -> 698 | G15: =IF(OR(F15="",F15=0),"",D15/F15) -> 0.29083095 | H15: =IF(OR(F15="",F15=0),"",E15/F15) -> 0.70916905 | I15: random forest | J15: 3.0260856 | K15: =IF(G15="","",MAX(0,G15-J15/100)) -> 0.26057009 | L15: =IF(G15="","",MIN(1,G15+J15/100)) -> 0.3210918 | M15: =ROUND(Q15*S15,0) -> 43 | N15: =ROUND(SQRT((F15*J15/100)^2+(G15*M15)^2),0) -> 25 | P15: -23.506514 | Q15: 698 | R15: =MAX(0,MIN(1,P15/100+$D$5)) -> 0.29150207 | S15: 0.061040569 | T15: Small
A16: Carbon | B16: EAST PENN TOWNSHIP | C16: EAST PENN TOWNSHIP-SOUTH | D16: =ROUND(Q16*R16,0) -> 192 | E16: =ROUND(Q16,0)-D16 -> 407 | F16: =IF(COUNTA(D16:E16)=0,"",SUM(D16:E16)) -> 599 | G16: =IF(OR(F16="",F16=0),"",D16/F16) -> 0.32053422 | H16: =IF(OR(F16="",F16=0),"",E16/F16) -> 0.67946578 | I16: random forest | J16: 3.0260856 | K16: =IF(G16="","",MAX(0,G16-J16/100)) -> 0.29027337 | L16: =IF(G16="","",MIN(1,G16+J16/100)) -> 0.35079508 | M16: =ROUND(Q16*S16,0) -> 37 | N16: =ROUND(SQRT((F16*J16/100)^2+(G16*M16)^2),0) -> 22 | P16: -20.528255 | Q16: 599 | R16: =MAX(0,MIN(1,P16/100+$D$5)) -> 0.32128465 | S16: 0.061040569 | T16: Small
A17: Carbon | B17: EAST SIDE BOROUGH | C17: EAST SIDE BOROUGH | D17: =ROUND(Q17*R17,0) -> 36 | E17: =ROUND(Q17,0)-D17 -> 58 | F17: =IF(COUNTA(D17:E17)=0,"",SUM(D17:E17)) -> 94 | G17: =IF(OR(F17="",F17=0),"",D17/F17) -> 0.38297872 | H17: =IF(OR(F17="",F17=0),"",E17/F17) -> 0.61702128 | I17: random forest | J17: 3.0260856 | K17: =IF(G17="","",MAX(0,G17-J17/100)) -> 0.35271787 | L17: =IF(G17="","",MIN(1,G17+J17/100)) -> 0.41323958 | M17: =ROUND(Q17*S17,0) -> 6 | N17: =ROUND(SQRT((F17*J17/100)^2+(G17*M17)^2),0) -> 4 | P17: -14.667941 | Q17: 94 | R17: =MAX(0,MIN(1,P17/100+$D$5)) -> 0.37988779 | S17: 0.061040569 | T17: Small
A18: Carbon | B18: FRANKLIN TOWNSHIP | C18: FRANKLIN TOWNSHIP-HARRITY | D18: =ROUND(Q18*R18,0) -> 271 | E18: =ROUND(Q18,0)-D18 -> 568 | F18: =IF(COUNTA(D18:E18)=0,"",SUM(D18:E18)) -> 839 | G18: =IF(OR(F18="",F18=0),"",D18/F18) -> 0.32300358 | H18: =IF(OR(F18="",F18=0),"",E18/F18) -> 0.67699642 | I18: random forest | J18: 1.8085538 | K18: =IF(G18="","",MAX(0,G18-J18/100)) -> 0.30491804 | L18: =IF(G18="","",MIN(1,G18+J18/100)) -> 0.34108911 | M18: =ROUND(Q18*S18,0) -> 42 | N18: =ROUND(SQRT((F18*J18/100)^2+(G18*M18)^2),0) -> 20 | P18: -20.377608 | Q18: 839 | R18: =MAX(0,MIN(1,P18/100+$D$5)) -> 0.32279112 | S18: 0.050032131 | T18: Medium
A19: Carbon | B19: FRANKLIN TOWNSHIP | C19: FRANKLIN TOWNSHIP-IND DIST | D19: =ROUND(Q19*R19,0) -> 142 | E19: =ROUND(Q19,0)-D19 -> 312 | F19: =IF(COUNTA(D19:E19)=0,"",SUM(D19:E19)) -> 454 | G19: =IF(OR(F19="",F19=0),"",D19/F19) -> 0.31277533 | H19: =IF(OR(F19="",F19=0),"",E19/F19) -> 0.68722467 | I19: random forest | J19: 3.0260856 | K19: =IF(G19="","",MAX(0,G19-J19/100)) -> 0.28251447 | L19: =IF(G19="","",MIN(1,G19+J19/100)) -> 0.34303619 | M19: =ROUND(Q19*S19,0) -> 28 | N19: =ROUND(SQRT((F19*J19/100)^2+(G19*M19)^2),0) -> 16 | P19: -21.320992 | Q19: 454 | R19: =MAX(0,MIN(1,P19/100+$D$5)) -> 0.31335728 | S19: 0.061040569 | T19: Small
A20: Carbon | B20: FRANKLIN TOWNSHIP | C20: FRANKLIN TOWNSHIP-LONG RUN | D20: =ROUND(Q20*R20,0) -> 207 | E20: =ROUND(Q20,0)-D20 -> 458 | F20: =IF(COUNTA(D20:E20)=0,"",SUM(D20:E20)) -> 665 | G20: =IF(OR(F20="",F20=0),"",D20/F20) -> 0.3112782 | H20: =IF(OR(F20="",F20=0),"",E20/F20) -> 0.6887218 | I20: random forest | J20: 3.0260856 | K20: =IF(G20="","",MAX(0,G20-J20/100)) -> 0.28101734 | L20: =IF(G20="","",MIN(1,G20+J20/100)) -> 0.34153905 | M20: =ROUND(Q20*S20,0) -> 41 | N20: =ROUND(SQRT((F20*J20/100)^2+(G20*M20)^2),0) -> 24 | P20: -21.529878 | Q20: 665 | R20: =MAX(0,MIN(1,P20/100+$D$5)) -> 0.31126842 | S20: 0.061040569 | T20: Small
A21: Carbon | B21: JIM THORPE BOROUGH | C21: JIM THORPE BOROUGH-1ST | D21: =ROUND(Q21*R21,0) -> 216 | E21: =ROUND(Q21,0)-D21 -> 224 | F21: =IF(COUNTA(D21:E21)=0,"",SUM(D21:E21)) -> 440 | G21: =IF(OR(F21="",F21=0),"",D21/F21) -> 0.49090909 | H21: =IF(OR(F21="",F21=0),"",E21/F21) -> 0.50909091 | I21: random forest | J21: 3.0260856 | K21: =IF(G21="","",MAX(0,G21-J21/100)) -> 0.46064824 | L21: =IF(G21="","",MIN(1,G21+J21/100)) -> 0.52116995 | M21: =ROUND(Q21*S21,0) -> 27 | N21: =ROUND(SQRT((F21*J21/100)^2+(G21*M21)^2),0) -> 19 | P21: -3.6144659 | Q21: 440 | R21: =MAX(0,MIN(1,P21/100+$D$5)) -> 0.49042254 | S21: 0.061040569 | T21: Small
A22: Carbon | B22: JIM THORPE BOROUGH | C22: JIM THORPE BOROUGH-2ND | D22: =ROUND(Q22*R22,0) -> 140 | E22: =ROUND(Q22,0)-D22 -> 157 | F22: =IF(COUNTA(D22:E22)=0,"",SUM(D22:E22)) -> 297 | G22: =IF(OR(F22="",F22=0),"",D22/F22) -> 0.47138047 | H22: =IF(OR(F22="",F22=0),"",E22/F22) -> 0.52861953 | I22: random forest | J22: 3.0260856 | K22: =IF(G22="","",MAX(0,G22-J22/100)) -> 0.44111962 | L22: =IF(G22="","",MIN(1,G22+J22/100)) -> 0.50164133 | M22: =ROUND(Q22*S22,0) -> 18 | N22: =ROUND(SQRT((F22*J22/100)^2+(G22*M22)^2),0) -> 12 | P22: -5.491426 | Q22: 297 | R22: =MAX(0,MIN(1,P22/100+$D$5)) -> 0.47165294 | S22: 0.061040569 | T22: Small
A23: Carbon | B23: JIM THORPE BOROUGH | C23: JIM THORPE BOROUGH-3RD | D23: =ROUND(Q23*R23,0) -> 267 | E23: =ROUND(Q23,0)-D23 -> 358 | F23: =IF(COUNTA(D23:E23)=0,"",SUM(D23:E23)) -> 625 | G23: =IF(OR(F23="",F23=0),"",D23/F23) -> 0.4272 | H23: =IF(OR(F23="",F23=0),"",E23/F23) -> 0.5728 | I23: random forest | J23: 3.0260856 | K23: =IF(G23="","",MAX(0,G23-J23/100)) -> 0.39693914 | L23: =IF(G23="","",MIN(1,G23+J23/100)) -> 0.45746086 | M23: =ROUND(Q23*S23,0) -> 38 | N23: =ROUND(SQRT((F23*J23/100)^2+(G23*M23)^2),0) -> 25 | P23: -9.9574664 | Q23: 625 | R23: =MAX(0,MIN(1,P23/100+$D$5)) -> 0.42699254 | S23: 0.061040569 | T23: Small
... A381: Northampton | B381: WIND GAP | C381: WIND GAP | D381: =ROUND(Q381*R381,0) -> 522 | E381: =ROUND(Q381,0)-D381 -> 573 | F381: =IF(COUNTA(D381:E381)=0,"",SUM(D381:E381)) -> 1095 | G381: =IF(OR(F381="",F381=0),"",D381/F381) -> 0.47671233 | H381: =IF(OR(F381="",F381=0),"",E381/F381) -> 0.52328767 | I381: random forest | J381: 1.8085538 | K381: =IF(G381="","",MAX(0,G381-J381/100)) -> 0.45862679 | L381: =IF(G381="","",MIN(1,G381+J381/100)) -> 0.49479787 | M381: =ROUND(Q381*S381,0) -> 55 | N381: =ROUND(SQRT((F381*J381/100)^2+(G381*M381)^2),0) -> 33 | P381: -4.9958289 | Q381: 1095 | R381: =MAX(0,MIN(1,P381/100+$D$5)) -> 0.47660891 | S381: 0.050032131 | T381: Medium

Sheet 2026 Forecast B
A1: PA-07 2026 House Forecast — Precinct-Level Predictions (Forecast B: shap-selected forest)
A2: Candidates: Brooks | Mackenzie | District totals (yellow) are formulas over the precinct rows.
A3: Brooks and Mackenzie votes are formulas: 2022 House votes cast × forecast Brooks share (turnout held at 2022 levels). Change the district scenario on the Scenario & Comparison tab. Error terms come from this forecast’s 2024 backtest.
A4: Model / scenario | B4: Random forest on results only — Forecast B (SHAP-selected forest), precinct model; turnout = 2022 | C4: As-of date | D4: 46300 | E4: Prepared by | F4: Max | G4: Version | H4: v1.0
A5: District Brooks share (scenario) | B5: ='Scenario & Comparison'!$C$6 -> 0.52816948 | C5: Uniform shift applied | D5: =B5-SUMPRODUCT(P12:P381,Q12:Q381)/SUM(Q12:Q381)/100 -> 0.53575636 | E5: 2024 backtest district miss (pts) | F5: 2.2335886
A6: DISTRICT TOTALS (auto-sum — do not type over)
A7: Geography | B7: (muni) | C7: (precinct) | D7: Brooks votes | E7: Mackenzie votes | F7: Total votes | G7: Brooks share | H7: Mackenzie share | I7: Notes | J7: Error term: Brooks share (± pts) | K7: Brooks share, low | L7: Brooks share, high | M7: Error term: votes cast (± votes) | N7: Error term: Brooks votes (± votes)
A8: PA-07 District | B8: (all precincts) | D8: =SUM(D12:D381) -> 158252 | E8: =SUM(E12:E381) -> 141371 | F8: =D8+E8 -> 299623 | G8: =IF(F8=0,"",D8/F8) -> 0.5281704 | H8: =IF(F8=0,"",E8/F8) -> 0.4718296 | I8: Headline forecast for the briefing | J8: 2.2335886 | K8: =G8-J8/100 -> 0.50583451 | L8: =G8+J8/100 -> 0.55050629 | M8: =ROUND(F8*0.0291,0) -> 8719 | N8: =ROUND(SQRT((F8*J8/100)^2+(G8*M8)^2),0) -> 8124
A9: Discussion prompt: Precinct and municipal district totals use the same scenario share, so their Brooks share matches by design; vote totals differ slightly because 2022 votes were re-allocated where precinct lines changed.
A10: PRECINCT DETAIL | P10: MODEL INPUTS (from the random forests — do not edit)
A11: County | B11: Municipality | C11: Precinct | D11: Brooks votes | E11: Mackenzie votes | F11: Total votes | G11: Brooks share | H11: Mackenzie share | I11: Notes / source method | J11: Error term: Brooks share (± pts) | K11: Brooks share, low | L11: Brooks share, high | M11: Error term: votes cast (± votes) | N11: Error term: Brooks votes (± votes) | P11: Model lean vs district (pts) | Q11: Votes cast (= 2022 House votes) | R11: Forecast Brooks share (unrounded) | S11: Votes error term (% of votes) | T11: Size group (backtest error band)
A12: Carbon | B12: BANKS TOWNSHIP | C12: BANKS TOWNSHIP | D12: =ROUND(Q12*R12,0) -> 172 | E12: =ROUND(Q12,0)-D12 -> 214 | F12: =IF(COUNTA(D12:E12)=0,"",SUM(D12:E12)) -> 386 | G12: =IF(OR(F12="",F12=0),"",D12/F12) -> 0.44559585 | H12: =IF(OR(F12="",F12=0),"",E12/F12) -> 0.55440415 | I12: random forest | J12: 2.8748004 | K12: =IF(G12="","",MAX(0,G12-J12/100)) -> 0.41684785 | L12: =IF(G12="","",MIN(1,G12+J12/100)) -> 0.47434386 | M12: =ROUND(Q12*S12,0) -> 24 | N12: =ROUND(SQRT((F12*J12/100)^2+(G12*M12)^2),0) -> 15 | P12: -9.0537482 | Q12: 386 | R12: =MAX(0,MIN(1,P12/100+$D$5)) -> 0.44521888 | S12: 0.061040569 | T12: Small
A13: Carbon | B13: BEAVER MEADOWS BOROUGH | C13: BEAVER MEADOWS BOROUGH | D13: =ROUND(Q13*R13,0) -> 104 | E13: =ROUND(Q13,0)-D13 -> 210 | F13: =IF(COUNTA(D13:E13)=0,"",SUM(D13:E13)) -> 314 | G13: =IF(OR(F13="",F13=0),"",D13/F13) -> 0.33121019 | H13: =IF(OR(F13="",F13=0),"",E13/F13) -> 0.66878981 | I13: random forest | J13: 2.8748004 | K13: =IF(G13="","",MAX(0,G13-J13/100)) -> 0.30246219 | L13: =IF(G13="","",MIN(1,G13+J13/100)) -> 0.3599582 | M13: =ROUND(Q13*S13,0) -> 19 | N13: =ROUND(SQRT((F13*J13/100)^2+(G13*M13)^2),0) -> 11 | P13: -20.36251 | Q13: 314 | R13: =MAX(0,MIN(1,P13/100+$D$5)) -> 0.33213126 | S13: 0.061040569 | T13: Small
A14: Carbon | B14: BOWMANSTOWN BOROUGH | C14: BOWMANSTOWN BOROUGH | D14: =ROUND(Q14*R14,0) -> 130 | E14: =ROUND(Q14,0)-D14 -> 218 | F14: =IF(COUNTA(D14:E14)=0,"",SUM(D14:E14)) -> 348 | G14: =IF(OR(F14="",F14=0),"",D14/F14) -> 0.37356322 | H14: =IF(OR(F14="",F14=0),"",E14/F14) -> 0.62643678 | I14: random forest | J14: 2.8748004 | K14: =IF(G14="","",MAX(0,G14-J14/100)) -> 0.34481521 | L14: =IF(G14="","",MIN(1,G14+J14/100)) -> 0.40231122 | M14: =ROUND(Q14*S14,0) -> 21 | N14: =ROUND(SQRT((F14*J14/100)^2+(G14*M14)^2),0) -> 13 | P14: -16.116993 | Q14: 348 | R14: =MAX(0,MIN(1,P14/100+$D$5)) -> 0.37458644 | S14: 0.061040569 | T14: Small
A15: Carbon | B15: EAST PENN TOWNSHIP | C15: EAST PENN TOWNSHIP-NORTH | D15: =ROUND(Q15*R15,0) -> 208 | E15: =ROUND(Q15,0)-D15 -> 490 | F15: =IF(COUNTA(D15:E15)=0,"",SUM(D15:E15)) -> 698 | G15: =IF(OR(F15="",F15=0),"",D15/F15) -> 0.29799427 | H15: =IF(OR(F15="",F15=0),"",E15/F15) -> 0.70200573 | I15: random forest | J15: 2.8748004 | K15: =IF(G15="","",MAX(0,G15-J15/100)) -> 0.26924627 | L15: =IF(G15="","",MIN(1,G15+J15/100)) -> 0.32674227 | M15: =ROUND(Q15*S15,0) -> 43 | N15: =ROUND(SQRT((F15*J15/100)^2+(G15*M15)^2),0) -> 24 | P15: -23.742058 | Q15: 698 | R15: =MAX(0,MIN(1,P15/100+$D$5)) -> 0.29833578 | S15: 0.061040569 | T15: Small
A16: Carbon | B16: EAST PENN TOWNSHIP | C16: EAST PENN TOWNSHIP-SOUTH | D16: =ROUND(Q16*R16,0) -> 192 | E16: =ROUND(Q16,0)-D16 -> 407 | F16: =IF(COUNTA(D16:E16)=0,"",SUM(D16:E16)) -> 599 | G16: =IF(OR(F16="",F16=0),"",D16/F16) -> 0.32053422 | H16: =IF(OR(F16="",F16=0),"",E16/F16) -> 0.67946578 | I16: random forest | J16: 2.8748004 | K16: =IF(G16="","",MAX(0,G16-J16/100)) -> 0.29178622 | L16: =IF(G16="","",MIN(1,G16+J16/100)) -> 0.34928223 | M16: =ROUND(Q16*S16,0) -> 37 | N16: =ROUND(SQRT((F16*J16/100)^2+(G16*M16)^2),0) -> 21 | P16: -21.553933 | Q16: 599 | R16: =MAX(0,MIN(1,P16/100+$D$5)) -> 0.32021703 | S16: 0.061040569 | T16: Small
A17: Carbon | B17: EAST SIDE BOROUGH | C17: EAST SIDE BOROUGH | D17: =ROUND(Q17*R17,0) -> 37 | E17: =ROUND(Q17,0)-D17 -> 57 | F17: =IF(COUNTA(D17:E17)=0,"",SUM(D17:E17)) -> 94 | G17: =IF(OR(F17="",F17=0),"",D17/F17) -> 0.39361702 | H17: =IF(OR(F17="",F17=0),"",E17/F17) -> 0.60638298 | I17: random forest | J17: 2.8748004 | K17: =IF(G17="","",MAX(0,G17-J17/100)) -> 0.36486902 | L17: =IF(G17="","",MIN(1,G17+J17/100)) -> 0.42236503 | M17: =ROUND(Q17*S17,0) -> 6 | N17: =ROUND(SQRT((F17*J17/100)^2+(G17*M17)^2),0) -> 4 | P17: -14.644744 | Q17: 94 | R17: =MAX(0,MIN(1,P17/100+$D$5)) -> 0.38930892 | S17: 0.061040569 | T17: Small
A18: Carbon | B18: FRANKLIN TOWNSHIP | C18: FRANKLIN TOWNSHIP-HARRITY | D18: =ROUND(Q18*R18,0) -> 271 | E18: =ROUND(Q18,0)-D18 -> 568 | F18: =IF(COUNTA(D18:E18)=0,"",SUM(D18:E18)) -> 839 | G18: =IF(OR(F18="",F18=0),"",D18/F18) -> 0.32300358 | H18: =IF(OR(F18="",F18=0),"",E18/F18) -> 0.67699642 | I18: random forest | J18: 1.924721 | K18: =IF(G18="","",MAX(0,G18-J18/100)) -> 0.30375637 | L18: =IF(G18="","",MIN(1,G18+J18/100)) -> 0.34225079 | M18: =ROUND(Q18*S18,0) -> 42 | N18: =ROUND(SQRT((F18*J18/100)^2+(G18*M18)^2),0) -> 21 | P18: -21.271718 | Q18: 839 | R18: =MAX(0,MIN(1,P18/100+$D$5)) -> 0.32303918 | S18: 0.050032131 | T18: Medium
A19: Carbon | B19: FRANKLIN TOWNSHIP | C19: FRANKLIN TOWNSHIP-IND DIST | D19: =ROUND(Q19*R19,0) -> 145 | E19: =ROUND(Q19,0)-D19 -> 309 | F19: =IF(COUNTA(D19:E19)=0,"",SUM(D19:E19)) -> 454 | G19: =IF(OR(F19="",F19=0),"",D19/F19) -> 0.31938326 | H19: =IF(OR(F19="",F19=0),"",E19/F19) -> 0.68061674 | I19: random forest | J19: 2.8748004 | K19: =IF(G19="","",MAX(0,G19-J19/100)) -> 0.29063526 | L19: =IF(G19="","",MIN(1,G19+J19/100)) -> 0.34813126 | M19: =ROUND(Q19*S19,0) -> 28 | N19: =ROUND(SQRT((F19*J19/100)^2+(G19*M19)^2),0) -> 16 | P19: -21.572129 | Q19: 454 | R19: =MAX(0,MIN(1,P19/100+$D$5)) -> 0.32003507 | S19: 0.061040569 | T19: Small
A20: Carbon | B20: FRANKLIN TOWNSHIP | C20: FRANKLIN TOWNSHIP-LONG RUN | D20: =ROUND(Q20*R20,0) -> 207 | E20: =ROUND(Q20,0)-D20 -> 458 | F20: =IF(COUNTA(D20:E20)=0,"",SUM(D20:E20)) -> 665 | G20: =IF(OR(F20="",F20=0),"",D20/F20) -> 0.3112782 | H20: =IF(OR(F20="",F20=0),"",E20/F20) -> 0.6887218 | I20: random forest | J20: 2.8748004 | K20: =IF(G20="","",MAX(0,G20-J20/100)) -> 0.28253019 | L20: =IF(G20="","",MIN(1,G20+J20/100)) -> 0.3400262 | M20: =ROUND(Q20*S20,0) -> 41 | N20: =ROUND(SQRT((F20*J20/100)^2+(G20*M20)^2),0) -> 23 | P20: -22.407704 | Q20: 665 | R20: =MAX(0,MIN(1,P20/100+$D$5)) -> 0.31167932 | S20: 0.061040569 | T20: Small
A21: Carbon | B21: JIM THORPE BOROUGH | C21: JIM THORPE BOROUGH-1ST | D21: =ROUND(Q21*R21,0) -> 220 | E21: =ROUND(Q21,0)-D21 -> 220 | F21: =IF(COUNTA(D21:E21)=0,"",SUM(D21:E21)) -> 440 | G21: =IF(OR(F21="",F21=0),"",D21/F21) -> 0.5 | H21: =IF(OR(F21="",F21=0),"",E21/F21) -> 0.5 | I21: random forest | J21: 2.8748004 | K21: =IF(G21="","",MAX(0,G21-J21/100)) -> 0.471252 | L21: =IF(G21="","",MIN(1,G21+J21/100)) -> 0.528748 | M21: =ROUND(Q21*S21,0) -> 27 | N21: =ROUND(SQRT((F21*J21/100)^2+(G21*M21)^2),0) -> 19 | P21: -3.6000118 | Q21: 440 | R21: =MAX(0,MIN(1,P21/100+$D$5)) -> 0.49975624 | S21: 0.061040569 | T21: Small
A22: Carbon | B22: JIM THORPE BOROUGH | C22: JIM THORPE BOROUGH-2ND | D22: =ROUND(Q22*R22,0) -> 146 | E22: =ROUND(Q22,0)-D22 -> 151 | F22: =IF(COUNTA(D22:E22)=0,"",SUM(D22:E22)) -> 297 | G22: =IF(OR(F22="",F22=0),"",D22/F22) -> 0.49158249 | H22: =IF(OR(F22="",F22=0),"",E22/F22) -> 0.50841751 | I22: random forest | J22: 2.8748004 | K22: =IF(G22="","",MAX(0,G22-J22/100)) -> 0.46283449 | L22: =IF(G22="","",MIN(1,G22+J22/100)) -> 0.5203305 | M22: =ROUND(Q22*S22,0) -> 18 | N22: =ROUND(SQRT((F22*J22/100)^2+(G22*M22)^2),0) -> 12 | P22: -4.288818 | Q22: 297 | R22: =MAX(0,MIN(1,P22/100+$D$5)) -> 0.49286818 | S22: 0.061040569 | T22: Small
A23: Carbon | B23: JIM THORPE BOROUGH | C23: JIM THORPE BOROUGH-3RD | D23: =ROUND(Q23*R23,0) -> 270 | E23: =ROUND(Q23,0)-D23 -> 355 | F23: =IF(COUNTA(D23:E23)=0,"",SUM(D23:E23)) -> 625 | G23: =IF(OR(F23="",F23=0),"",D23/F23) -> 0.432 | H23: =IF(OR(F23="",F23=0),"",E23/F23) -> 0.568 | I23: random forest | J23: 2.8748004 | K23: =IF(G23="","",MAX(0,G23-J23/100)) -> 0.403252 | L23: =IF(G23="","",MIN(1,G23+J23/100)) -> 0.460748 | M23: =ROUND(Q23*S23,0) -> 38 | N23: =ROUND(SQRT((F23*J23/100)^2+(G23*M23)^2),0) -> 24 | P23: -10.416499 | Q23: 625 | R23: =MAX(0,MIN(1,P23/100+$D$5)) -> 0.43159137 | S23: 0.061040569 | T23: Small
... A381: Northampton | B381: WIND GAP | C381: WIND GAP | D381: =ROUND(Q381*R381,0) -> 520 | E381: =ROUND(Q381,0)-D381 -> 575 | F381: =IF(COUNTA(D381:E381)=0,"",SUM(D381:E381)) -> 1095 | G381: =IF(OR(F381="",F381=0),"",D381/F381) -> 0.47488584 | H381: =IF(OR(F381="",F381=0),"",E381/F381) -> 0.52511416 | I381: random forest | J381: 1.924721 | K381: =IF(G381="","",MAX(0,G381-J381/100)) -> 0.45563863 | L381: =IF(G381="","",MIN(1,G381+J381/100)) -> 0.49413305 | M381: =ROUND(Q381*S381,0) -> 55 | N381: =ROUND(SQRT((F381*J381/100)^2+(G381*M381)^2),0) -> 34 | P381: -6.1239684 | Q381: 1095 | R381: =MAX(0,MIN(1,P381/100+$D$5)) -> 0.47451668 | S381: 0.050032131 | T381: Medium

Sheet 2026 Forecast C
A1: PA-07 2026 House Forecast — Precinct-Level Predictions (Forecast C: shap family-reweighted forest)
A2: Candidates: Brooks | Mackenzie | District totals (yellow) are formulas over the precinct rows.
A3: Brooks and Mackenzie votes are formulas: 2022 House votes cast × forecast Brooks share (turnout held at 2022 levels). Change the district scenario on the Scenario & Comparison tab. Error terms come from this forecast’s 2024 backtest.
A4: Model / scenario | B4: Random forest on results only — Forecast C (SHAP family-reweighted forest), precinct model; turnout = 2022 | C4: As-of date | D4: 46300 | E4: Prepared by | F4: Max | G4: Version | H4: v1.0
A5: District Brooks share (scenario) | B5: ='Scenario & Comparison'!$C$6 -> 0.52816948 | C5: Uniform shift applied | D5: =B5-SUMPRODUCT(P12:P381,Q12:Q381)/SUM(Q12:Q381)/100 -> 0.52521844 | E5: 2024 backtest district miss (pts) | F5: 2.2330359
A6: DISTRICT TOTALS (auto-sum — do not type over)
A7: Geography | B7: (muni) | C7: (precinct) | D7: Brooks votes | E7: Mackenzie votes | F7: Total votes | G7: Brooks share | H7: Mackenzie share | I7: Notes | J7: Error term: Brooks share (± pts) | K7: Brooks share, low | L7: Brooks share, high | M7: Error term: votes cast (± votes) | N7: Error term: Brooks votes (± votes)
A8: PA-07 District | B8: (all precincts) | D8: =SUM(D12:D381) -> 158260 | E8: =SUM(E12:E381) -> 141363 | F8: =D8+E8 -> 299623 | G8: =IF(F8=0,"",D8/F8) -> 0.5281971 | H8: =IF(F8=0,"",E8/F8) -> 0.4718029 | I8: Headline forecast for the briefing | J8: 2.2330359 | K8: =G8-J8/100 -> 0.50586674 | L8: =G8+J8/100 -> 0.55052746 | M8: =ROUND(F8*0.0291,0) -> 8719 | N8: =ROUND(SQRT((F8*J8/100)^2+(G8*M8)^2),0) -> 8122
A9: Discussion prompt: Precinct and municipal district totals use the same scenario share, so their Brooks share matches by design; vote totals differ slightly because 2022 votes were re-allocated where precinct lines changed.
A10: PRECINCT DETAIL | P10: MODEL INPUTS (from the random forests — do not edit)
A11: County | B11: Municipality | C11: Precinct | D11: Brooks votes | E11: Mackenzie votes | F11: Total votes | G11: Brooks share | H11: Mackenzie share | I11: Notes / source method | J11: Error term: Brooks share (± pts) | K11: Brooks share, low | L11: Brooks share, high | M11: Error term: votes cast (± votes) | N11: Error term: Brooks votes (± votes) | P11: Model lean vs district (pts) | Q11: Votes cast (= 2022 House votes) | R11: Forecast Brooks share (unrounded) | S11: Votes error term (% of votes) | T11: Size group (backtest error band)
A12: Carbon | B12: BANKS TOWNSHIP | C12: BANKS TOWNSHIP | D12: =ROUND(Q12*R12,0) -> 169 | E12: =ROUND(Q12,0)-D12 -> 217 | F12: =IF(COUNTA(D12:E12)=0,"",SUM(D12:E12)) -> 386 | G12: =IF(OR(F12="",F12=0),"",D12/F12) -> 0.43782383 | H12: =IF(OR(F12="",F12=0),"",E12/F12) -> 0.56217617 | I12: random forest | J12: 3.4531761 | K12: =IF(G12="","",MAX(0,G12-J12/100)) -> 0.40329207 | L12: =IF(G12="","",MIN(1,G12+J12/100)) -> 0.4723556 | M12: =ROUND(Q12*S12,0) -> 24 | N12: =ROUND(SQRT((F12*J12/100)^2+(G12*M12)^2),0) -> 17 | P12: -8.8015271 | Q12: 386 | R12: =MAX(0,MIN(1,P12/100+$D$5)) -> 0.43720317 | S12: 0.061040569 | T12: Small
A13: Carbon | B13: BEAVER MEADOWS BOROUGH | C13: BEAVER MEADOWS BOROUGH | D13: =ROUND(Q13*R13,0) -> 99 | E13: =ROUND(Q13,0)-D13 -> 215 | F13: =IF(COUNTA(D13:E13)=0,"",SUM(D13:E13)) -> 314 | G13: =IF(OR(F13="",F13=0),"",D13/F13) -> 0.31528662 | H13: =IF(OR(F13="",F13=0),"",E13/F13) -> 0.68471338 | I13: random forest | J13: 3.4531761 | K13: =IF(G13="","",MAX(0,G13-J13/100)) -> 0.28075486 | L13: =IF(G13="","",MIN(1,G13+J13/100)) -> 0.34981839 | M13: =ROUND(Q13*S13,0) -> 19 | N13: =ROUND(SQRT((F13*J13/100)^2+(G13*M13)^2),0) -> 12 | P13: -21.059919 | Q13: 314 | R13: =MAX(0,MIN(1,P13/100+$D$5)) -> 0.31461925 | S13: 0.061040569 | T13: Small
A14: Carbon | B14: BOWMANSTOWN BOROUGH | C14: BOWMANSTOWN BOROUGH | D14: =ROUND(Q14*R14,0) -> 123 | E14: =ROUND(Q14,0)-D14 -> 225 | F14: =IF(COUNTA(D14:E14)=0,"",SUM(D14:E14)) -> 348 | G14: =IF(OR(F14="",F14=0),"",D14/F14) -> 0.35344828 | H14: =IF(OR(F14="",F14=0),"",E14/F14) -> 0.64655172 | I14: random forest | J14: 3.4531761 | K14: =IF(G14="","",MAX(0,G14-J14/100)) -> 0.31891651 | L14: =IF(G14="","",MIN(1,G14+J14/100)) -> 0.38798004 | M14: =ROUND(Q14*S14,0) -> 21 | N14: =ROUND(SQRT((F14*J14/100)^2+(G14*M14)^2),0) -> 14 | P14: -17.216509 | Q14: 348 | R14: =MAX(0,MIN(1,P14/100+$D$5)) -> 0.35305335 | S14: 0.061040569 | T14: Small
A15: Carbon | B15: EAST PENN TOWNSHIP | C15: EAST PENN TOWNSHIP-NORTH | D15: =ROUND(Q15*R15,0) -> 197 | E15: =ROUND(Q15,0)-D15 -> 501 | F15: =IF(COUNTA(D15:E15)=0,"",SUM(D15:E15)) -> 698 | G15: =IF(OR(F15="",F15=0),"",D15/F15) -> 0.28223496 | H15: =IF(OR(F15="",F15=0),"",E15/F15) -> 0.71776504 | I15: random forest | J15: 3.4531761 | K15: =IF(G15="","",MAX(0,G15-J15/100)) -> 0.2477032 | L15: =IF(G15="","",MIN(1,G15+J15/100)) -> 0.31676672 | M15: =ROUND(Q15*S15,0) -> 43 | N15: =ROUND(SQRT((F15*J15/100)^2+(G15*M15)^2),0) -> 27 | P15: -24.369799 | Q15: 698 | R15: =MAX(0,MIN(1,P15/100+$D$5)) -> 0.28152045 | S15: 0.061040569 | T15: Small
A16: Carbon | B16: EAST PENN TOWNSHIP | C16: EAST PENN TOWNSHIP-SOUTH | D16: =ROUND(Q16*R16,0) -> 187 | E16: =ROUND(Q16,0)-D16 -> 412 | F16: =IF(COUNTA(D16:E16)=0,"",SUM(D16:E16)) -> 599 | G16: =IF(OR(F16="",F16=0),"",D16/F16) -> 0.31218698 | H16: =IF(OR(F16="",F16=0),"",E16/F16) -> 0.68781302 | I16: random forest | J16: 3.4531761 | K16: =IF(G16="","",MAX(0,G16-J16/100)) -> 0.27765522 | L16: =IF(G16="","",MIN(1,G16+J16/100)) -> 0.34671874 | M16: =ROUND(Q16*S16,0) -> 37 | N16: =ROUND(SQRT((F16*J16/100)^2+(G16*M16)^2),0) -> 24 | P16: -21.361117 | Q16: 599 | R16: =MAX(0,MIN(1,P16/100+$D$5)) -> 0.31160727 | S16: 0.061040569 | T16: Small
A17: Carbon | B17: EAST SIDE BOROUGH | C17: EAST SIDE BOROUGH | D17: =ROUND(Q17*R17,0) -> 35 | E17: =ROUND(Q17,0)-D17 -> 59 | F17: =IF(COUNTA(D17:E17)=0,"",SUM(D17:E17)) -> 94 | G17: =IF(OR(F17="",F17=0),"",D17/F17) -> 0.37234043 | H17: =IF(OR(F17="",F17=0),"",E17/F17) -> 0.62765957 | I17: random forest | J17: 3.4531761 | K17: =IF(G17="","",MAX(0,G17-J17/100)) -> 0.33780866 | L17: =IF(G17="","",MIN(1,G17+J17/100)) -> 0.40687219 | M17: =ROUND(Q17*S17,0) -> 6 | N17: =ROUND(SQRT((F17*J17/100)^2+(G17*M17)^2),0) -> 4 | P17: -15.019764 | Q17: 94 | R17: =MAX(0,MIN(1,P17/100+$D$5)) -> 0.3750208 | S17: 0.061040569 | T17: Small
A18: Carbon | B18: FRANKLIN TOWNSHIP | C18: FRANKLIN TOWNSHIP-HARRITY | D18: =ROUND(Q18*R18,0) -> 263 | E18: =ROUND(Q18,0)-D18 -> 576 | F18: =IF(COUNTA(D18:E18)=0,"",SUM(D18:E18)) -> 839 | G18: =IF(OR(F18="",F18=0),"",D18/F18) -> 0.31346841 | H18: =IF(OR(F18="",F18=0),"",E18/F18) -> 0.68653159 | I18: random forest | J18: 2.0502504 | K18: =IF(G18="","",MAX(0,G18-J18/100)) -> 0.29296591 | L18: =IF(G18="","",MIN(1,G18+J18/100)) -> 0.33397092 | M18: =ROUND(Q18*S18,0) -> 42 | N18: =ROUND(SQRT((F18*J18/100)^2+(G18*M18)^2),0) -> 22 | P18: -21.14341 | Q18: 839 | R18: =MAX(0,MIN(1,P18/100+$D$5)) -> 0.31378434 | S18: 0.050032131 | T18: Medium
A19: Carbon | B19: FRANKLIN TOWNSHIP | C19: FRANKLIN TOWNSHIP-IND DIST | D19: =ROUND(Q19*R19,0) -> 138 | E19: =ROUND(Q19,0)-D19 -> 316 | F19: =IF(COUNTA(D19:E19)=0,"",SUM(D19:E19)) -> 454 | G19: =IF(OR(F19="",F19=0),"",D19/F19) -> 0.30396476 | H19: =IF(OR(F19="",F19=0),"",E19/F19) -> 0.69603524 | I19: random forest | J19: 3.4531761 | K19: =IF(G19="","",MAX(0,G19-J19/100)) -> 0.269433 | L19: =IF(G19="","",MIN(1,G19+J19/100)) -> 0.33849652 | M19: =ROUND(Q19*S19,0) -> 28 | N19: =ROUND(SQRT((F19*J19/100)^2+(G19*M19)^2),0) -> 18 | P19: -22.22272 | Q19: 454 | R19: =MAX(0,MIN(1,P19/100+$D$5)) -> 0.30299125 | S19: 0.061040569 | T19: Small
A20: Carbon | B20: FRANKLIN TOWNSHIP | C20: FRANKLIN TOWNSHIP-LONG RUN | D20: =ROUND(Q20*R20,0) -> 201 | E20: =ROUND(Q20,0)-D20 -> 464 | F20: =IF(COUNTA(D20:E20)=0,"",SUM(D20:E20)) -> 665 | G20: =IF(OR(F20="",F20=0),"",D20/F20) -> 0.30225564 | H20: =IF(OR(F20="",F20=0),"",E20/F20) -> 0.69774436 | I20: random forest | J20: 3.4531761 | K20: =IF(G20="","",MAX(0,G20-J20/100)) -> 0.26772388 | L20: =IF(G20="","",MIN(1,G20+J20/100)) -> 0.3367874 | M20: =ROUND(Q20*S20,0) -> 41 | N20: =ROUND(SQRT((F20*J20/100)^2+(G20*M20)^2),0) -> 26 | P20: -22.35058 | Q20: 665 | R20: =MAX(0,MIN(1,P20/100+$D$5)) -> 0.30171265 | S20: 0.061040569 | T20: Small
A21: Carbon | B21: JIM THORPE BOROUGH | C21: JIM THORPE BOROUGH-1ST | D21: =ROUND(Q21*R21,0) -> 215 | E21: =ROUND(Q21,0)-D21 -> 225 | F21: =IF(COUNTA(D21:E21)=0,"",SUM(D21:E21)) -> 440 | G21: =IF(OR(F21="",F21=0),"",D21/F21) -> 0.48863636 | H21: =IF(OR(F21="",F21=0),"",E21/F21) -> 0.51136364 | I21: random forest | J21: 3.4531761 | K21: =IF(G21="","",MAX(0,G21-J21/100)) -> 0.4541046 | L21: =IF(G21="","",MIN(1,G21+J21/100)) -> 0.52316812 | M21: =ROUND(Q21*S21,0) -> 27 | N21: =ROUND(SQRT((F21*J21/100)^2+(G21*M21)^2),0) -> 20 | P21: -3.6413148 | Q21: 440 | R21: =MAX(0,MIN(1,P21/100+$D$5)) -> 0.4888053 | S21: 0.061040569 | T21: Small
A22: Carbon | B22: JIM THORPE BOROUGH | C22: JIM THORPE BOROUGH-2ND | D22: =ROUND(Q22*R22,0) -> 140 | E22: =ROUND(Q22,0)-D22 -> 157 | F22: =IF(COUNTA(D22:E22)=0,"",SUM(D22:E22)) -> 297 | G22: =IF(OR(F22="",F22=0),"",D22/F22) -> 0.47138047 | H22: =IF(OR(F22="",F22=0),"",E22/F22) -> 0.52861953 | I22: random forest | J22: 3.4531761 | K22: =IF(G22="","",MAX(0,G22-J22/100)) -> 0.43684871 | L22: =IF(G22="","",MIN(1,G22+J22/100)) -> 0.50591223 | M22: =ROUND(Q22*S22,0) -> 18 | N22: =ROUND(SQRT((F22*J22/100)^2+(G22*M22)^2),0) -> 13 | P22: -5.4457467 | Q22: 297 | R22: =MAX(0,MIN(1,P22/100+$D$5)) -> 0.47076098 | S22: 0.061040569 | T22: Small
A23: Carbon | B23: JIM THORPE BOROUGH | C23: JIM THORPE BOROUGH-3RD | D23: =ROUND(Q23*R23,0) -> 264 | E23: =ROUND(Q23,0)-D23 -> 361 | F23: =IF(COUNTA(D23:E23)=0,"",SUM(D23:E23)) -> 625 | G23: =IF(OR(F23="",F23=0),"",D23/F23) -> 0.4224 | H23: =IF(OR(F23="",F23=0),"",E23/F23) -> 0.5776 | I23: random forest | J23: 3.4531761 | K23: =IF(G23="","",MAX(0,G23-J23/100)) -> 0.38786824 | L23: =IF(G23="","",MIN(1,G23+J23/100)) -> 0.45693176 | M23: =ROUND(Q23*S23,0) -> 38 | N23: =ROUND(SQRT((F23*J23/100)^2+(G23*M23)^2),0) -> 27 | P23: -10.238546 | Q23: 625 | R23: =MAX(0,MIN(1,P23/100+$D$5)) -> 0.42283299 | S23: 0.061040569 | T23: Small
... A381: Northampton | B381: WIND GAP | C381: WIND GAP | D381: =ROUND(Q381*R381,0) -> 521 | E381: =ROUND(Q381,0)-D381 -> 574 | F381: =IF(COUNTA(D381:E381)=0,"",SUM(D381:E381)) -> 1095 | G381: =IF(OR(F381="",F381=0),"",D381/F381) -> 0.47579909 | H381: =IF(OR(F381="",F381=0),"",E381/F381) -> 0.52420091 | I381: random forest | J381: 2.0502504 | K381: =IF(G381="","",MAX(0,G381-J381/100)) -> 0.45529658 | L381: =IF(G381="","",MIN(1,G381+J381/100)) -> 0.49630159 | M381: =ROUND(Q381*S381,0) -> 55 | N381: =ROUND(SQRT((F381*J381/100)^2+(G381*M381)^2),0) -> 34 | P381: -4.9390023 | Q381: 1095 | R381: =MAX(0,MIN(1,P381/100+$D$5)) -> 0.47582842 | S381: 0.050032131 | T381: Medium

Sheet How Forecasts Are Weighted
A1: How the three precinct-level forecasts weigh their inputs (SHAP) — results-only random forests, turnout held at 2022
A3: Forecast A — Full random forest.
A4: Every candidate input goes into one random forest that forecasts each place’s Democratic share relative to the district. Nothing is weighted by hand: each input’s weight is whatever the forest learned, and SHAP measures it afterwards. This is the reference forecast.
A5: Forecast B — SHAP-selected forest.
A6: Uses SHAP to decide which inputs stay. An input is kept only if (1) its mean |SHAP| beat all 10 random columns in at least 18 of 20 refits and (2) it carried at least 2% of the forest’s SHAP total in Forecast A. The forest is refit on the survivors, so weight that was spread thinly over weak inputs is concentrated on the strong ones.
A7: Forecast C — SHAP family-reweighted forest.
A8: Uses SHAP to re-weight Forecast A. Each forecast = starting value + sum of SHAP values; Forecast C multiplies each input family’s SHAP sum by a family weight, chosen by how well it predicts elections the forest did not see (out-of-fold SHAP, leave-one-election-out, fitted within each election). Families under 3% of SHAP are held at ×1; others are limited to ×0.5–×2, a guard given only three training elections.
A9: Turnout (all three).
A10: No turnout model. Every precinct/municipality casts the same number of House votes as in 2022, so the three forecasts differ only in their results model.
A12: Family weights in each forecast (share of SHAP value in votes, 2026 forecast rows)
A13: Input family | B13: Forecast A | C13: Forecast B | D13: Forecast C | E13: Forecast C family weight (×) | F13: C weight used in 2024 backtest (×) | G13: Read
A14: Election type | B14: 0.0037806522 | C14: 0 | D14: 0.0036742793 | E14: 1 | F14: 1 | G14: unchanged (or held at ×1, under 3% of SHAP)
A15: Geography & municipal context | B15: 0.018896003 | C15: 0 | D15: 0.018364343 | E15: 1 | F15: 1 | G15: unchanged (or held at ×1, under 3% of SHAP)
A16: Historical voter data | B16: 0.73601388 | C16: 0.68324545 | D16: 0.77357931 | E16: 1.0814673 | F16: 0.97814171 | G16: amplified
A17: Voter registration data | B17: 0.24130946 | C17: 0.31675455 | D17: 0.20438207 | E17: 0.87149117 | F17: 1.2435075 | G17: damped
A18: Out-of-fold fit of the family weights: pattern error 2.59 → 2.55 pts after re-weighting.
A20: Forecast B — which inputs survived the SHAP selection
A21: Input | B21: Beat random columns (of 20) | C21: Share of forest SHAP in A | D21: Kept in B?
A22: Precinct House lean, last election (t−2) | B22: 20 | C22: 0.29575643 | D22: Yes
A23: Electorate last election: R % of ballots | B23: 20 | C23: 0.19404728 | D23: Yes
A24: Municipality House lean, last election (t−2) | B24: 20 | C24: 0.13112478 | D24: Yes
A25: State registration: R % (as of election) | B25: 20 | C25: 0.11105602 | D25: Yes
A26: Precinct House lean, last same-type election (t−4) | B26: 20 | C26: 0.078463649 | D26: Yes
A27: State registration: D % (as of election) | B27: 20 | C27: 0.072851368 | D27: Yes
A28: State registration: change in D−R margin since t−2 | B28: 20 | C28: 0.01772911 | D28: No
A29: Precinct vs. its municipality, last election (pts) | B29: 20 | C29: 0.013984863 | D29: No
A30: Mail use last election: R voters | B30: 20 | C30: 0.01392582 | D30: No
A31: Turnout last election: R registrants | B31: 20 | C31: 0.00909359 | D31: No
A32: Voter-file party switch gap (today’s R % − state R %) | B32: 20 | C32: 0.0086844797 | D32: No
A33: Mail use last election: D voters | B33: 20 | C33: 0.008026408 | D33: No
... A44: County: Lehigh | B44: 1 | C44: 0.00098970801 | D44: No

Sheet Feature Ranking A
A1: Rank | B1: Feature | C1: Input family | D1: Share of model | E1: Share within its family | F1: SHAP value in votes | G1: Used to forecast | H1: Significance test result | I1: Variable (short name)
A2: 1 | B2: Democratic percent of the two-party House vote, 2024 (certified precinct results), above or below the district average | C2: Historical voter data | D2: 0.28226256 | E2: 0.38350168 | F2: 51.68654 | G2: Democratic percent of the two-party vote | H2: Beat all 10 random comparison columns in 20 of 20 refits in the Democratic percent forest. | I2: Precinct House lean, last election (t−2)
A3: 2 | B3: Registered Republicans as a percent of everyone who voted, 2024 (voter file) | C3: Historical voter data | D3: 0.19158016 | E3: 0.26029423 | F3: 35.081224 | G3: Democratic percent of the two-party vote | H3: Beat all 10 random comparison columns in 20 of 20 refits in the Democratic percent forest. | I3: Electorate last election: R % of ballots
A4: 3 | B4: Democratic percent of the two-party House vote in the precinct’s whole municipality, 2024, above or below the district average | C4: Historical voter data | D4: 0.12941417 | E4: 0.17583116 | F4: 23.697691 | G4: Democratic percent of the two-party vote | H4: Beat all 10 random comparison columns in 20 of 20 refits in the Democratic percent forest. | I4: Municipality House lean, last election (t−2)
A5: 4 | B5: Registered Republicans as a percent of all registered voters, 2026 primary rolls (Department of State) | C5: Voter registration data | D5: 0.11185254 | E5: 0.46352324 | F5: 20.481891 | G5: Democratic percent of the two-party vote | H5: Beat all 10 random comparison columns in 20 of 20 refits in the Democratic percent forest. | I5: State registration: R % (as of election)
A6: 5 | B6: Democratic percent of the two-party House vote, 2022 — the last midterm (certified precinct results), above or below the district average | C6: Historical voter data | D6: 0.080907352 | E6: 0.10992639 | F6: 14.815359 | G6: Democratic percent of the two-party vote | H6: Beat all 10 random comparison columns in 20 of 20 refits in the Democratic percent forest. | I6: Precinct House lean, last same-type election (t−4)
A7: 6 | B7: Registered Democrats as a percent of all registered voters, 2026 primary rolls (Department of State) | C7: Voter registration data | D7: 0.075747965 | E7: 0.31390383 | F7: 13.870597 | G7: Democratic percent of the two-party vote | H7: Beat all 10 random comparison columns in 20 of 20 refits in the Democratic percent forest. | I7: State registration: D % (as of election)
A8: 7 | B8: Change in registered Democrats minus Republicans (percent of registered) from the 2024 general to the 2026 primary (Department of State) | C8: Voter registration data | D8: 0.020998379 | E8: 0.087018462 | F8: 3.8451205 | G8: Democratic percent of the two-party vote | H8: Beat all 10 random comparison columns in 20 of 20 refits in the Democratic percent forest. | I8: State registration: change in D−R margin since t−2
A9: 8 | B9: Percent of Republican voters who voted by mail, 2024 (voter file) | C9: Historical voter data | D9: 0.016421563 | E9: 0.022311486 | F9: 3.0070364 | G9: Democratic percent of the two-party vote | H9: Beat all 10 random comparison columns in 20 of 20 refits in the Democratic percent forest. | I9: Mail use last election: R voters
A10: 9 | B10: Precinct’s 2024 House Democratic percent minus its municipality’s, in points | C10: Geography & municipal context | D10: 0.014306653 | E10: 0.75712586 | F10: 2.6197644 | G10: Democratic percent of the two-party vote | H10: Beat all 10 random comparison columns in 20 of 20 refits in the Democratic percent forest. | I10: Precinct vs. its municipality, last election (pts)
A11: 10 | B11: Percent of registered Republicans who voted, 2024 (voter file) | C11: Historical voter data | D11: 0.011021175 | E11: 0.01497414 | F11: 2.0181437 | G11: Democratic percent of the two-party vote | H11: Beat all 10 random comparison columns in 20 of 20 refits in the Democratic percent forest. | I11: Turnout last election: R registrants
A12: 11 | B12: Republican percent of registered voters in the 2026 voter file minus the Republican percent on the 2026 state rolls (a party-switching signal) | C12: Voter registration data | D12: 0.0097053693 | E12: 0.040219597 | F12: 1.7771998 | G12: Democratic percent of the two-party vote | H12: Beat all 10 random comparison columns in 20 of 20 refits in the Democratic percent forest. | I12: Voter-file party switch gap (today’s R % − state R %)
A13: 12 | B13: Percent of Democratic voters who voted by mail, 2024 (voter file) | C13: Historical voter data | D13: 0.0096390316 | E13: 0.013096263 | F13: 1.7650524 | G13: Democratic percent of the two-party vote | H13: Beat all 10 random comparison columns in 20 of 20 refits in the Democratic percent forest. | I13: Mail use last election: D voters
... A24: 23 | B24: Precinct is in Lehigh County (1/0) | C24: Geography & municipal context | D24: 0.0010032928 | E24: 0.053095501 | F24: 0.18371807 | G24: Democratic percent of the two-party vote | H24: Beat all 10 random comparison columns in 1 of 20 refits in the Democratic percent forest. | I24: County: Lehigh
B26: Historical voter data, total | C26: Historical voter data | D26: =SUMIF(C2:C24,"Historical voter data",D2:D24) -> 0.73601388 | F26: =SUMIF(C2:C24,"Historical voter data",F2:F24) -> 134.77526
B27: Voter registration data, total | C27: Voter registration data | D27: =SUMIF(C2:C24,"Voter registration data",D2:D24) -> 0.24130946 | F27: =SUMIF(C2:C24,"Voter registration data",F2:F24) -> 44.18741
B28: Geography & municipal context, total | C28: Geography & municipal context | D28: =SUMIF(C2:C24,"Geography & municipal context",D2:D24) -> 0.018896003 | F28: =SUMIF(C2:C24,"Geography & municipal context",F2:F24) -> 3.4601438
B29: Election type, total | C29: Election type | D29: =SUMIF(C2:C24,"Election type",D2:D24) -> 0.0037806522 | F29: =SUMIF(C2:C24,"Election type",F2:F24) -> 0.69229455
B30: All features, total | D30: =SUM(D2:D24) -> 1 | F30: =SUM(F2:F24) -> 183.11511
B32: Notes
B33: How to read this table. Each row is one input that this forecast uses. Rows are ranked by SHAP value in votes on the 2026 forecast rows.
B34: SHAP value: for one place, the number of votes that one input added to or took away from that place’s forecast, measured from the model’s starting value, which is the average forecast over the places and years it was trained on (SHAP stands for SHapley Additive exPlanations). Values are exact TreeSHAP over every tree.
B35: SHAP value in votes is the average, over the 370 precincts, of the votes the input added to or took away from the forecast, ignoring whether it added or took away. Brooks votes and Mackenzie votes are counted together (an input that moves 10 votes from Mackenzie to Brooks counts as 20). Votes cast are fixed at 2022 levels, so every vote an input moves is a shift between the two candidates.
B36: Share of model is the input’s SHAP value in votes divided by the total for all inputs. Share within its family divides by the total for its own family instead.
B37: What the model forecasts. One random forest forecasts each place’s Democratic percent of the two-party House vote, measured above or below the district average for that election (so it learns the pattern, not the year’s overall level). Turnout is not modeled: each place casts the same number of House votes as in 2022 (the last midterm). Brooks share = the forecast pattern plus one uniform shift that makes the district total equal the scenario on the Scenario & Comparison tab.
B38: Forecast A weighting: none imposed. Each input’s weight is exactly what the full forest learned; the SHAP values show it after the fact.
B39: How the inputs were tested. Each forest of Forecast A was refit 20 times with a different random seed, each time with 10 extra columns of random numbers added (5 that change from row to row and 5 that keep one value for each place in every year). The significance column counts the refits in which the input’s average absolute SHAP value on the 2026 forecast rows was larger than that of every random column.
B40: Settings: max_features=0.33, min_samples_leaf=1, 500 trees, trained on 977 precinct-elections (2020–2024).
B41: Historical voter data: past election results (any race) and past turnout (how many voted, which registered parties voted, mail use). Voter registration data: who is on the roll and with which party, the number registered, age and sex make-up, and change in registration. Geography & municipal context: county and the precinct’s municipality. Election type: midterm or presidential year.

Sheet Feature Ranking B
A1: Rank | B1: Feature | C1: Input family | D1: Share of model | E1: Share within its family | F1: SHAP value in votes | G1: Used to forecast | H1: Significance test result | I1: Variable (short name)
A2: 1 | B2: Democratic percent of the two-party House vote, 2024 (certified precinct results), above or below the district average | C2: Historical voter data | D2: 0.1781813 | E2: 0.26078666 | F2: 28.467639 | G2: Democratic percent of the two-party vote | H2: Beat all 10 random comparison columns in 20 of 20 refits in the Democratic percent forest. | I2: Precinct House lean, last election (t−2)
A3: 2 | B3: Democratic percent of the two-party House vote, 2022 — the last midterm (certified precinct results), above or below the district average | C3: Historical voter data | D3: 0.17086588 | E3: 0.2500798 | F3: 27.29887 | G3: Democratic percent of the two-party vote | H3: Beat all 10 random comparison columns in 20 of 20 refits in the Democratic percent forest. | I3: Precinct House lean, last same-type election (t−4)
A4: 3 | B4: Registered Republicans as a percent of everyone who voted, 2024 (voter file) | C4: Historical voter data | D4: 0.16852111 | E4: 0.24664798 | F4: 26.924251 | G4: Democratic percent of the two-party vote | H4: Beat all 10 random comparison columns in 20 of 20 refits in the Democratic percent forest. | I4: Electorate last election: R % of ballots
A5: 4 | B5: Democratic percent of the two-party House vote in the precinct’s whole municipality, 2024, above or below the district average | C5: Historical voter data | D5: 0.16567715 | E5: 0.24248556 | F5: 26.469878 | G5: Democratic percent of the two-party vote | H5: Beat all 10 random comparison columns in 20 of 20 refits in the Democratic percent forest. | I5: Municipality House lean, last election (t−2)
A6: 5 | B6: Registered Republicans as a percent of all registered voters, 2026 primary rolls (Department of State) | C6: Voter registration data | D6: 0.16274973 | E6: 0.5138039 | F6: 26.002169 | G6: Democratic percent of the two-party vote | H6: Beat all 10 random comparison columns in 20 of 20 refits in the Democratic percent forest. | I6: State registration: R % (as of election)
A7: 6 | B7: Registered Democrats as a percent of all registered voters, 2026 primary rolls (Department of State) | C7: Voter registration data | D7: 0.15400483 | E7: 0.4861961 | F7: 24.605016 | G7: Democratic percent of the two-party vote | H7: Beat all 10 random comparison columns in 20 of 20 refits in the Democratic percent forest. | I7: State registration: D % (as of election)
