Workbook

Sheet Scenario & Comparison
A1: PA-07 2026 House Forecast — Precinct Level: three results-only random-forest forecasts (fixed baseline)
A2: Candidates: Brooks | Mackenzie | The two yellow cells set the district-wide Brooks share and votes cast; all three forecasts update.
A3: A, B and C weight the same random-forest inputs differently using SHAP (see How Forecasts Are Weighted). Each is backtested on 2024 with its own weights; those errors are the error terms.
A5: SCENARIO INPUTS (defaults are built from the tables below; type over them to run another scenario)
A6: District-wide Brooks share of the two-party vote (input) | C6: =C21 -> 0.49515845 | D6: ← default: registration-adjusted baseline (row 21)
A7: District House votes cast, 2026 (input) | C7: =C26 -> 312191.92 | D7: ← default: 2022 votes × registration growth, summed over precincts (row 26)
A9: HOW THE DEFAULTS ARE BUILT (all current-district precincts, Carbon and Polk included)
A10: Election | C10: Democratic share | D10: Democratic votes | E10: Republican votes | F10: Registered (state rolls) | G10: Dem share of two-party registration
A11: 2018 General | C11: =D11/(D11+E11) -> 0.53299447 | D11: 136421 | E11: 119531 | F11: 483877 | G11: 0.56798799
A12: 2020 General | C12: =D12/(D12+E12) -> 0.49646525 | D12: 188347 | E12: 191029 | F12: 518873 | G12: 0.55685758
A13: 2022 General | C13: =D13/(D13+E13) -> 0.50896572 | D13: 149243 | E13: 143985 | F13: 510119 | G13: 0.54766474
A14: 2024 General | C14: =D14/(D14+E14) -> 0.49424813 | D14: 196561 | E14: 201136 | F14: 535177 | G14: 0.52758258
A15: 2026 Primary rolls | F15: 517956 | G15: 0.52223425
A16: Source: certified precinct House returns and Department of State registration (PA07_Precinct_Data.xlsx). 2018/2020 include Carbon (PA-09 race) and Polk (PA-08) so every year covers the same territory as 2026.
A18: Average Democratic share, 2022 and 2024 | C18: =AVERAGE(C13,C14) -> 0.50160693
A19: Change in Dem share of two-party registration since then (pts) | C19: =(G15-AVERAGE(G13,G14))*100 -> -1.5389407
A20: Registration-to-vote link (k), measured on precinct changes 2018→2022 and 2020→2024 | C20: 0.41902062 | D20: Within-district slope: precincts whose registration moved 1 pt toward a party moved about this many pts in vote share (national swing removed).
A21: Registration-adjusted baseline for 2026 = row 18 + k × row 19 | C21: =C18+C20*C19/100 -> 0.49515845
A23: 2022 House votes in today’s district | C23: =D13+E13 -> 293228
A24: Registration growth, 2022 general → 2026 primary rolls | C24: =F15/F13 -> 1.0153631
A25: District-level check: 2022 votes × growth | C25: =C23*C24 -> 297732.89
A26: Rule applied precinct by precinct and summed (default votes cast) | C26: 312191.92 | D26: Precinct/municipal growth rates differ slightly, so the summed total differs a little from the district-level check.
A28: WHAT WENT WRONG WITH THE BACKTESTS — AND HOW IT WAS FIXED
A29: Problem 1 — the district baseline left out Carbon and Polk.
A30: The old 2024 backtest set the district Democratic share to the 2020 result, 51.4%. That figure dropped Carbon County and Polk Township because they voted in PA-09 and PA-08 in 2020. Both lean Republican, so the baseline overstated the Democratic share by about 2 points (51.4% vs 49.6% with them counted), moving roughly 8,000 votes from Mackenzie to Wild in the backtest.
A31: Problem 2 — turnout was frozen at 2020 levels.
A32: Each place was given its 2020 House votes. About 3% more people voted in 2024, so both columns shrank. For Democrats the two errors offset (+4% and −3%); for Republicans they stacked (−4% and −3%), which is why only the Republican vote looked badly under-counted (about −7%).
A33: Fix 1 — a complete, registration-adjusted baseline.
A34: The district share now comes from every current-district precinct (Carbon and Polk included), averaged over the last two elections so one unusual year (like 2018) does not dominate, and moved by k × the change in registration since then. k is measured from precinct-level changes in earlier elections only (k = 0.48 for the 2024 backtest, 0.42 for 2026) — it is not tuned to the 2024 result. Backtest baseline: 49.1% vs actual 49.4%.
A35: Fix 2 — turnout grows with the voter roll.
A36: Votes cast = the last same-type election’s House votes × that place’s registration growth since then. In the backtests this rule missed 2024 total votes by -1.6% at district level (vs about −3% before). For 2026 it gives about 312,192 votes, inside the expected 300,000–320,000 range. Turnout is still a rule, not a model: there is only one random forest, on the results.
A37: Result.
A38: The Republican vote in the backtests is now within about 1% of the actual count for every forecast, the Democratic vote within about 1%, and the district-wide share miss fell from about 2 points to under half a point. Row-level (pattern) errors are unchanged because the random forests themselves were not changed.
A40: Forecast | B40: Backtest version | C40: District Dem share miss (pts) | D40: Democratic votes miss | E40: Republican votes miss | F40: Total votes miss
A41: Forecast A | B41: Before fix (2020 level without Carbon/Polk; 2020 turnout) | C41: 2.2311014 | D41: 0.014952721 | E41: -0.071718724 | F41: -0.029072653
A42: Forecast A | B42: After fix (registration-adjusted baseline; turnout × registration growth) | C42: -0.12202765 | D42: 0.0003544591 | E42: 0.0052506748 | F42: 0.0028415265
A43: Forecast B | B43: Before fix (2020 level without Carbon/Polk; 2020 turnout) | C43: 2.2335886 | D43: 0.0150018 | E43: -0.071766266 | F43: -0.029072653
A44: Forecast B | B44: After fix (registration-adjusted baseline; turnout × registration growth) | C44: -0.12042228 | D44: 0.0003871784 | E44: 0.0052189806 | F44: 0.0028415265
A45: Forecast C | B45: Before fix (2020 level without Carbon/Polk; 2020 turnout) | C45: 2.2319305 | D45: 0.01496908 | E45: -0.071734572 | F45: -0.029072653
A46: Forecast C | B46: After fix (registration-adjusted baseline; turnout × registration growth) | C46: -0.12122496 | D46: 0.00037081875 | E46: 0.0052348277 | F46: 0.0028415265
...

Sheet 2026 Forecast A
A1: PA-07 2026 House Forecast — Precinct-Level Predictions (Forecast A: full random forest)
A2: Candidates: Brooks | Mackenzie | District totals (yellow) are formulas over the precinct rows.
A3: Only the results are modelled. Votes cast in each row = its 2022 House votes × its registration growth since 2022, scaled to the district votes-cast input. Brooks votes = votes cast × forecast Brooks share. Change the district share or votes cast on the Scenario & Comparison tab.
A4: Model / scenario | B4: Random forest on results — Forecast A (Full random forest), precinct model; turnout = 2022 votes × registration growth | C4: As-of date | D4: 46300 | E4: Prepared by | F4: Max | G4: Version | H4: v3.0 (results only, fixed baseline)
A5: District Brooks share (scenario) | B5: ='Scenario & Comparison'!$C$6 -> 0.49515845 | C5: Uniform shift applied | D5: =B5-SUMPRODUCT(P12:P381,Q12:Q381)/SUM(Q12:Q381)/100 -> 0.49350323 | E5: 2024 backtest district miss (pts) | F5: -0.12202765 | G5: Turnout scale | H5: ='Scenario & Comparison'!$C$7/SUM(T12:T381) -> 1
A6: DISTRICT TOTALS (auto-sum — do not type over)
A7: Geography | B7: (muni) | C7: (precinct) | D7: Brooks votes | E7: Mackenzie votes | F7: Total votes | G7: Brooks share | H7: Mackenzie share | I7: Notes | J7: Error term: Brooks share (± pts) | K7: Brooks share, low | L7: Brooks share, high | M7: Error term: Brooks votes (± votes)
A8: PA-07 District | B8: (all precincts) | D8: =SUM(D12:D381) -> 154595 | E8: =SUM(E12:E381) -> 157594 | F8: =D8+E8 -> 312189 | G8: =IF(F8=0,"",D8/F8) -> 0.49519682 | H8: =IF(F8=0,"",E8/F8) -> 0.50480318 | I8: Headline forecast for the briefing | J8: 0.12202765 | K8: =G8-J8/100 -> 0.49397654 | L8: =G8+J8/100 -> 0.4964171 | M8: =ROUND(F8*J8/100,0) -> 381
A9: Error terms: each row = ±1 root-mean-square miss of this forecast in its 2024 backtest for places of similar size, after removing the district-wide miss. District row = the district-wide miss. Turnout is set by rule (not forecast), so no turnout error is included; the backtest shows that rule missed 2024 votes cast by under 1%.
A10: PRECINCT DETAIL | P10: MODEL INPUTS (from the random forest — do not edit)
A11: County | B11: Municipality | C11: Precinct | D11: Brooks votes | E11: Mackenzie votes | F11: Total votes | G11: Brooks share | H11: Mackenzie share | I11: Notes / source method | J11: Error term: Brooks share (± pts) | K11: Brooks share, low | L11: Brooks share, high | M11: Error term: Brooks votes (± votes) | P11: Model lean vs district (pts) | Q11: Votes cast (scaled rule) | R11: Forecast Brooks share (unrounded) | S11: Size group (backtest error band) | T11: Rule votes: 2022 House votes × registration growth
A12: Carbon | B12: BANKS TOWNSHIP | C12: BANKS TOWNSHIP | D12: =ROUND(Q12*R12,0) -> 150 | E12: =ROUND(Q12,0)-D12 -> 214 | F12: =IF(COUNTA(D12:E12)=0,"",SUM(D12:E12)) -> 364 | G12: =IF(OR(F12="",F12=0),"",D12/F12) -> 0.41208791 | H12: =IF(OR(F12="",F12=0),"",E12/F12) -> 0.58791209 | I12: random forest (results only) | J12: 3.0236301 | K12: =IF(G12="","",MAX(0,G12-J12/100)) -> 0.38185161 | L12: =IF(G12="","",MIN(1,G12+J12/100)) -> 0.44232421 | M12: =IF(F12="","",ROUND(F12*J12/100,0)) -> 11 | P12: -8.3120668 | Q12: =T12*$H$5 -> 364.49096 | R12: =MAX(0,MIN(1,P12/100+$D$5)) -> 0.41038257 | S12: Small | T12: 364.49096
A13: Carbon | B13: BEAVER MEADOWS BOROUGH | C13: BEAVER MEADOWS BOROUGH | D13: =ROUND(Q13*R13,0) -> 96 | E13: =ROUND(Q13,0)-D13 -> 234 | F13: =IF(COUNTA(D13:E13)=0,"",SUM(D13:E13)) -> 330 | G13: =IF(OR(F13="",F13=0),"",D13/F13) -> 0.29090909 | H13: =IF(OR(F13="",F13=0),"",E13/F13) -> 0.70909091 | I13: random forest (results only) | J13: 3.0236301 | K13: =IF(G13="","",MAX(0,G13-J13/100)) -> 0.26067279 | L13: =IF(G13="","",MIN(1,G13+J13/100)) -> 0.32114539 | M13: =IF(F13="","",ROUND(F13*J13/100,0)) -> 10 | P13: -20.225366 | Q13: =T13*$H$5 -> 330.13014 | R13: =MAX(0,MIN(1,P13/100+$D$5)) -> 0.29124958 | S13: Small | T13: 330.13014
A14: Carbon | B14: BOWMANSTOWN BOROUGH | C14: BOWMANSTOWN BOROUGH | D14: =ROUND(Q14*R14,0) -> 116 | E14: =ROUND(Q14,0)-D14 -> 240 | F14: =IF(COUNTA(D14:E14)=0,"",SUM(D14:E14)) -> 356 | G14: =IF(OR(F14="",F14=0),"",D14/F14) -> 0.3258427 | H14: =IF(OR(F14="",F14=0),"",E14/F14) -> 0.6741573 | I14: random forest (results only) | J14: 3.0236301 | K14: =IF(G14="","",MAX(0,G14-J14/100)) -> 0.2956064 | L14: =IF(G14="","",MIN(1,G14+J14/100)) -> 0.356079 | M14: =IF(F14="","",ROUND(F14*J14/100,0)) -> 11 | P14: -16.727513 | Q14: =T14*$H$5 -> 355.63437 | R14: =MAX(0,MIN(1,P14/100+$D$5)) -> 0.3262281 | S14: Small | T14: 355.63437
A15: Carbon | B15: EAST PENN TOWNSHIP | C15: EAST PENN TOWNSHIP-NORTH | D15: =ROUND(Q15*R15,0) -> 187 | E15: =ROUND(Q15,0)-D15 -> 537 | F15: =IF(COUNTA(D15:E15)=0,"",SUM(D15:E15)) -> 724 | G15: =IF(OR(F15="",F15=0),"",D15/F15) -> 0.25828729 | H15: =IF(OR(F15="",F15=0),"",E15/F15) -> 0.74171271 | I15: random forest (results only) | J15: 3.0236301 | K15: =IF(G15="","",MAX(0,G15-J15/100)) -> 0.22805099 | L15: =IF(G15="","",MIN(1,G15+J15/100)) -> 0.28852359 | M15: =IF(F15="","",ROUND(F15*J15/100,0)) -> 22 | P15: -23.506514 | Q15: =T15*$H$5 -> 724.37791 | R15: =MAX(0,MIN(1,P15/100+$D$5)) -> 0.2584381 | S15: Small | T15: 724.37791
A16: Carbon | B16: EAST PENN TOWNSHIP | C16: EAST PENN TOWNSHIP-SOUTH | D16: =ROUND(Q16*R16,0) -> 176 | E16: =ROUND(Q16,0)-D16 -> 435 | F16: =IF(COUNTA(D16:E16)=0,"",SUM(D16:E16)) -> 611 | G16: =IF(OR(F16="",F16=0),"",D16/F16) -> 0.28805237 | H16: =IF(OR(F16="",F16=0),"",E16/F16) -> 0.71194763 | I16: random forest (results only) | J16: 3.0236301 | K16: =IF(G16="","",MAX(0,G16-J16/100)) -> 0.25781607 | L16: =IF(G16="","",MIN(1,G16+J16/100)) -> 0.31828867 | M16: =IF(F16="","",ROUND(F16*J16/100,0)) -> 18 | P16: -20.528255 | Q16: =T16*$H$5 -> 610.89237 | R16: =MAX(0,MIN(1,P16/100+$D$5)) -> 0.28822068 | S16: Small | T16: 610.89237
A17: Carbon | B17: EAST SIDE BOROUGH | C17: EAST SIDE BOROUGH | D17: =ROUND(Q17*R17,0) -> 32 | E17: =ROUND(Q17,0)-D17 -> 61 | F17: =IF(COUNTA(D17:E17)=0,"",SUM(D17:E17)) -> 93 | G17: =IF(OR(F17="",F17=0),"",D17/F17) -> 0.34408602 | H17: =IF(OR(F17="",F17=0),"",E17/F17) -> 0.65591398 | I17: random forest (results only) | J17: 3.0236301 | K17: =IF(G17="","",MAX(0,G17-J17/100)) -> 0.31384972 | L17: =IF(G17="","",MIN(1,G17+J17/100)) -> 0.37432232 | M17: =IF(F17="","",ROUND(F17*J17/100,0)) -> 3 | P17: -14.667941 | Q17: =T17*$H$5 -> 93.426829 | R17: =MAX(0,MIN(1,P17/100+$D$5)) -> 0.34682383 | S17: Small | T17: 93.426829
A18: Carbon | B18: FRANKLIN TOWNSHIP | C18: FRANKLIN TOWNSHIP-HARRITY | D18: =ROUND(Q18*R18,0) -> 247 | E18: =ROUND(Q18,0)-D18 -> 606 | F18: =IF(COUNTA(D18:E18)=0,"",SUM(D18:E18)) -> 853 | G18: =IF(OR(F18="",F18=0),"",D18/F18) -> 0.28956624 | H18: =IF(OR(F18="",F18=0),"",E18/F18) -> 0.71043376 | I18: random forest (results only) | J18: 1.8087742 | K18: =IF(G18="","",MAX(0,G18-J18/100)) -> 0.2714785 | L18: =IF(G18="","",MIN(1,G18+J18/100)) -> 0.30765398 | M18: =IF(F18="","",ROUND(F18*J18/100,0)) -> 15 | P18: -20.377608 | Q18: =T18*$H$5 -> 852.99444 | R18: =MAX(0,MIN(1,P18/100+$D$5)) -> 0.28972715 | S18: Medium | T18: 852.99444
A19: Carbon | B19: FRANKLIN TOWNSHIP | C19: FRANKLIN TOWNSHIP-IND DIST | D19: =ROUND(Q19*R19,0) -> 126 | E19: =ROUND(Q19,0)-D19 -> 322 | F19: =IF(COUNTA(D19:E19)=0,"",SUM(D19:E19)) -> 448 | G19: =IF(OR(F19="",F19=0),"",D19/F19) -> 0.28125 | H19: =IF(OR(F19="",F19=0),"",E19/F19) -> 0.71875 | I19: random forest (results only) | J19: 3.0236301 | K19: =IF(G19="","",MAX(0,G19-J19/100)) -> 0.2510137 | L19: =IF(G19="","",MIN(1,G19+J19/100)) -> 0.3114863 | M19: =IF(F19="","",ROUND(F19*J19/100,0)) -> 14 | P19: -21.320992 | Q19: =T19*$H$5 -> 447.93932 | R19: =MAX(0,MIN(1,P19/100+$D$5)) -> 0.28029332 | S19: Small | T19: 447.93932
A20: Carbon | B20: FRANKLIN TOWNSHIP | C20: FRANKLIN TOWNSHIP-LONG RUN | D20: =ROUND(Q20*R20,0) -> 190 | E20: =ROUND(Q20,0)-D20 -> 493 | F20: =IF(COUNTA(D20:E20)=0,"",SUM(D20:E20)) -> 683 | G20: =IF(OR(F20="",F20=0),"",D20/F20) -> 0.27818448 | H20: =IF(OR(F20="",F20=0),"",E20/F20) -> 0.72181552 | I20: random forest (results only) | J20: 3.0236301 | K20: =IF(G20="","",MAX(0,G20-J20/100)) -> 0.24794818 | L20: =IF(G20="","",MIN(1,G20+J20/100)) -> 0.30842078 | M20: =IF(F20="","",ROUND(F20*J20/100,0)) -> 21 | P20: -21.529878 | Q20: =T20*$H$5 -> 683.32677 | R20: =MAX(0,MIN(1,P20/100+$D$5)) -> 0.27820446 | S20: Small | T20: 683.32677
A21: Carbon | B21: JIM THORPE BOROUGH | C21: JIM THORPE BOROUGH-1ST | D21: =ROUND(Q21*R21,0) -> 200 | E21: =ROUND(Q21,0)-D21 -> 236 | F21: =IF(COUNTA(D21:E21)=0,"",SUM(D21:E21)) -> 436 | G21: =IF(OR(F21="",F21=0),"",D21/F21) -> 0.4587156 | H21: =IF(OR(F21="",F21=0),"",E21/F21) -> 0.5412844 | I21: random forest (results only) | J21: 3.0236301 | K21: =IF(G21="","",MAX(0,G21-J21/100)) -> 0.42847929 | L21: =IF(G21="","",MIN(1,G21+J21/100)) -> 0.4889519 | M21: =IF(F21="","",ROUND(F21*J21/100,0)) -> 13 | P21: -3.6144659 | Q21: =T21*$H$5 -> 436.24467 | R21: =MAX(0,MIN(1,P21/100+$D$5)) -> 0.45735858 | S21: Small | T21: 436.24467
A22: Carbon | B22: JIM THORPE BOROUGH | C22: JIM THORPE BOROUGH-2ND | D22: =ROUND(Q22*R22,0) -> 123 | E22: =ROUND(Q22,0)-D22 -> 157 | F22: =IF(COUNTA(D22:E22)=0,"",SUM(D22:E22)) -> 280 | G22: =IF(OR(F22="",F22=0),"",D22/F22) -> 0.43928571 | H22: =IF(OR(F22="",F22=0),"",E22/F22) -> 0.56071429 | I22: random forest (results only) | J22: 3.0236301 | K22: =IF(G22="","",MAX(0,G22-J22/100)) -> 0.40904941 | L22: =IF(G22="","",MIN(1,G22+J22/100)) -> 0.46952202 | M22: =IF(F22="","",ROUND(F22*J22/100,0)) -> 8 | P22: -5.491426 | Q22: =T22*$H$5 -> 280.5 | R22: =MAX(0,MIN(1,P22/100+$D$5)) -> 0.43858898 | S22: Small | T22: 280.5
A23: Carbon | B23: JIM THORPE BOROUGH | C23: JIM THORPE BOROUGH-3RD | D23: =ROUND(Q23*R23,0) -> 254 | E23: =ROUND(Q23,0)-D23 -> 392 | F23: =IF(COUNTA(D23:E23)=0,"",SUM(D23:E23)) -> 646 | G23: =IF(OR(F23="",F23=0),"",D23/F23) -> 0.39318885 | H23: =IF(OR(F23="",F23=0),"",E23/F23) -> 0.60681115 | I23: random forest (results only) | J23: 3.0236301 | K23: =IF(G23="","",MAX(0,G23-J23/100)) -> 0.36295255 | L23: =IF(G23="","",MIN(1,G23+J23/100)) -> 0.42342516 | M23: =IF(F23="","",ROUND(F23*J23/100,0)) -> 20 | P23: -9.9574664 | Q23: =T23*$H$5 -> 645.69536 | R23: =MAX(0,MIN(1,P23/100+$D$5)) -> 0.39392857 | S23: Small | T23: 645.69536
... A381: Northampton | B381: WIND GAP | C381: WIND GAP | D381: =ROUND(Q381*R381,0) -> 508 | E381: =ROUND(Q381,0)-D381 -> 637 | F381: =IF(COUNTA(D381:E381)=0,"",SUM(D381:E381)) -> 1145 | G381: =IF(OR(F381="",F381=0),"",D381/F381) -> 0.44366812 | H381: =IF(OR(F381="",F381=0),"",E381/F381) -> 0.55633188 | I381: random forest (results only) | J381: 1.8087742 | K381: =IF(G381="","",MAX(0,G381-J381/100)) -> 0.42558038 | L381: =IF(G381="","",MIN(1,G381+J381/100)) -> 0.46175586 | M381: =IF(F381="","",ROUND(F381*J381/100,0)) -> 21 | P381: -4.9958289 | Q381: =T381*$H$5 -> 1145.4806 | R381: =MAX(0,MIN(1,P381/100+$D$5)) -> 0.44354495 | S381: Medium | T381: 1145.4806

Sheet 2026 Forecast B
A1: PA-07 2026 House Forecast — Precinct-Level Predictions (Forecast B: shap-selected forest)
A2: Candidates: Brooks | Mackenzie | District totals (yellow) are formulas over the precinct rows.
A3: Only the results are modelled. Votes cast in each row = its 2022 House votes × its registration growth since 2022, scaled to the district votes-cast input. Brooks votes = votes cast × forecast Brooks share. Change the district share or votes cast on the Scenario & Comparison tab.
A4: Model / scenario | B4: Random forest on results — Forecast B (SHAP-selected forest), precinct model; turnout = 2022 votes × registration growth | C4: As-of date | D4: 46300 | E4: Prepared by | F4: Max | G4: Version | H4: v3.0 (results only, fixed baseline)
A5: District Brooks share (scenario) | B5: ='Scenario & Comparison'!$C$6 -> 0.49515845 | C5: Uniform shift applied | D5: =B5-SUMPRODUCT(P12:P381,Q12:Q381)/SUM(Q12:Q381)/100 -> 0.50265047 | E5: 2024 backtest district miss (pts) | F5: -0.12042228 | G5: Turnout scale | H5: ='Scenario & Comparison'!$C$7/SUM(T12:T381) -> 1
A6: DISTRICT TOTALS (auto-sum — do not type over)
A7: Geography | B7: (muni) | C7: (precinct) | D7: Brooks votes | E7: Mackenzie votes | F7: Total votes | G7: Brooks share | H7: Mackenzie share | I7: Notes | J7: Error term: Brooks share (± pts) | K7: Brooks share, low | L7: Brooks share, high | M7: Error term: Brooks votes (± votes)
A8: PA-07 District | B8: (all precincts) | D8: =SUM(D12:D381) -> 154579 | E8: =SUM(E12:E381) -> 157610 | F8: =D8+E8 -> 312189 | G8: =IF(F8=0,"",D8/F8) -> 0.49514557 | H8: =IF(F8=0,"",E8/F8) -> 0.50485443 | I8: Headline forecast for the briefing | J8: 0.12042228 | K8: =G8-J8/100 -> 0.49394135 | L8: =G8+J8/100 -> 0.49634979 | M8: =ROUND(F8*J8/100,0) -> 376
A9: Error terms: each row = ±1 root-mean-square miss of this forecast in its 2024 backtest for places of similar size, after removing the district-wide miss. District row = the district-wide miss. Turnout is set by rule (not forecast), so no turnout error is included; the backtest shows that rule missed 2024 votes cast by under 1%.
A10: PRECINCT DETAIL | P10: MODEL INPUTS (from the random forest — do not edit)
A11: County | B11: Municipality | C11: Precinct | D11: Brooks votes | E11: Mackenzie votes | F11: Total votes | G11: Brooks share | H11: Mackenzie share | I11: Notes / source method | J11: Error term: Brooks share (± pts) | K11: Brooks share, low | L11: Brooks share, high | M11: Error term: Brooks votes (± votes) | P11: Model lean vs district (pts) | Q11: Votes cast (scaled rule) | R11: Forecast Brooks share (unrounded) | S11: Size group (backtest error band) | T11: Rule votes: 2022 House votes × registration growth
A12: Carbon | B12: BANKS TOWNSHIP | C12: BANKS TOWNSHIP | D12: =ROUND(Q12*R12,0) -> 150 | E12: =ROUND(Q12,0)-D12 -> 214 | F12: =IF(COUNTA(D12:E12)=0,"",SUM(D12:E12)) -> 364 | G12: =IF(OR(F12="",F12=0),"",D12/F12) -> 0.41208791 | H12: =IF(OR(F12="",F12=0),"",E12/F12) -> 0.58791209 | I12: random forest (results only) | J12: 2.8791897 | K12: =IF(G12="","",MAX(0,G12-J12/100)) -> 0.38329602 | L12: =IF(G12="","",MIN(1,G12+J12/100)) -> 0.44087981 | M12: =IF(F12="","",ROUND(F12*J12/100,0)) -> 10 | P12: -9.0537482 | Q12: =T12*$H$5 -> 364.49096 | R12: =MAX(0,MIN(1,P12/100+$D$5)) -> 0.41211299 | S12: Small | T12: 364.49096
A13: Carbon | B13: BEAVER MEADOWS BOROUGH | C13: BEAVER MEADOWS BOROUGH | D13: =ROUND(Q13*R13,0) -> 99 | E13: =ROUND(Q13,0)-D13 -> 231 | F13: =IF(COUNTA(D13:E13)=0,"",SUM(D13:E13)) -> 330 | G13: =IF(OR(F13="",F13=0),"",D13/F13) -> 0.3 | H13: =IF(OR(F13="",F13=0),"",E13/F13) -> 0.7 | I13: random forest (results only) | J13: 2.8791897 | K13: =IF(G13="","",MAX(0,G13-J13/100)) -> 0.2712081 | L13: =IF(G13="","",MIN(1,G13+J13/100)) -> 0.3287919 | M13: =IF(F13="","",ROUND(F13*J13/100,0)) -> 10 | P13: -20.36251 | Q13: =T13*$H$5 -> 330.13014 | R13: =MAX(0,MIN(1,P13/100+$D$5)) -> 0.29902537 | S13: Small | T13: 330.13014
A14: Carbon | B14: BOWMANSTOWN BOROUGH | C14: BOWMANSTOWN BOROUGH | D14: =ROUND(Q14*R14,0) -> 121 | E14: =ROUND(Q14,0)-D14 -> 235 | F14: =IF(COUNTA(D14:E14)=0,"",SUM(D14:E14)) -> 356 | G14: =IF(OR(F14="",F14=0),"",D14/F14) -> 0.33988764 | H14: =IF(OR(F14="",F14=0),"",E14/F14) -> 0.66011236 | I14: random forest (results only) | J14: 2.8791897 | K14: =IF(G14="","",MAX(0,G14-J14/100)) -> 0.31109574 | L14: =IF(G14="","",MIN(1,G14+J14/100)) -> 0.36867954 | M14: =IF(F14="","",ROUND(F14*J14/100,0)) -> 10 | P14: -16.116993 | Q14: =T14*$H$5 -> 355.63437 | R14: =MAX(0,MIN(1,P14/100+$D$5)) -> 0.34148055 | S14: Small | T14: 355.63437
A15: Carbon | B15: EAST PENN TOWNSHIP | C15: EAST PENN TOWNSHIP-NORTH | D15: =ROUND(Q15*R15,0) -> 192 | E15: =ROUND(Q15,0)-D15 -> 532 | F15: =IF(COUNTA(D15:E15)=0,"",SUM(D15:E15)) -> 724 | G15: =IF(OR(F15="",F15=0),"",D15/F15) -> 0.26519337 | H15: =IF(OR(F15="",F15=0),"",E15/F15) -> 0.73480663 | I15: random forest (results only) | J15: 2.8791897 | K15: =IF(G15="","",MAX(0,G15-J15/100)) -> 0.23640147 | L15: =IF(G15="","",MIN(1,G15+J15/100)) -> 0.29398527 | M15: =IF(F15="","",ROUND(F15*J15/100,0)) -> 21 | P15: -23.742058 | Q15: =T15*$H$5 -> 724.37791 | R15: =MAX(0,MIN(1,P15/100+$D$5)) -> 0.26522989 | S15: Small | T15: 724.37791
A16: Carbon | B16: EAST PENN TOWNSHIP | C16: EAST PENN TOWNSHIP-SOUTH | D16: =ROUND(Q16*R16,0) -> 175 | E16: =ROUND(Q16,0)-D16 -> 436 | F16: =IF(COUNTA(D16:E16)=0,"",SUM(D16:E16)) -> 611 | G16: =IF(OR(F16="",F16=0),"",D16/F16) -> 0.28641571 | H16: =IF(OR(F16="",F16=0),"",E16/F16) -> 0.71358429 | I16: random forest (results only) | J16: 2.8791897 | K16: =IF(G16="","",MAX(0,G16-J16/100)) -> 0.25762382 | L16: =IF(G16="","",MIN(1,G16+J16/100)) -> 0.31520761 | M16: =IF(F16="","",ROUND(F16*J16/100,0)) -> 18 | P16: -21.553933 | Q16: =T16*$H$5 -> 610.89237 | R16: =MAX(0,MIN(1,P16/100+$D$5)) -> 0.28711114 | S16: Small | T16: 610.89237
A17: Carbon | B17: EAST SIDE BOROUGH | C17: EAST SIDE BOROUGH | D17: =ROUND(Q17*R17,0) -> 33 | E17: =ROUND(Q17,0)-D17 -> 60 | F17: =IF(COUNTA(D17:E17)=0,"",SUM(D17:E17)) -> 93 | G17: =IF(OR(F17="",F17=0),"",D17/F17) -> 0.35483871 | H17: =IF(OR(F17="",F17=0),"",E17/F17) -> 0.64516129 | I17: random forest (results only) | J17: 2.8791897 | K17: =IF(G17="","",MAX(0,G17-J17/100)) -> 0.32604681 | L17: =IF(G17="","",MIN(1,G17+J17/100)) -> 0.38363061 | M17: =IF(F17="","",ROUND(F17*J17/100,0)) -> 3 | P17: -14.644744 | Q17: =T17*$H$5 -> 93.426829 | R17: =MAX(0,MIN(1,P17/100+$D$5)) -> 0.35620303 | S17: Small | T17: 93.426829
A18: Carbon | B18: FRANKLIN TOWNSHIP | C18: FRANKLIN TOWNSHIP-HARRITY | D18: =ROUND(Q18*R18,0) -> 247 | E18: =ROUND(Q18,0)-D18 -> 606 | F18: =IF(COUNTA(D18:E18)=0,"",SUM(D18:E18)) -> 853 | G18: =IF(OR(F18="",F18=0),"",D18/F18) -> 0.28956624 | H18: =IF(OR(F18="",F18=0),"",E18/F18) -> 0.71043376 | I18: random forest (results only) | J18: 1.9254971 | K18: =IF(G18="","",MAX(0,G18-J18/100)) -> 0.27031127 | L18: =IF(G18="","",MIN(1,G18+J18/100)) -> 0.30882121 | M18: =IF(F18="","",ROUND(F18*J18/100,0)) -> 16 | P18: -21.271718 | Q18: =T18*$H$5 -> 852.99444 | R18: =MAX(0,MIN(1,P18/100+$D$5)) -> 0.28993329 | S18: Medium | T18: 852.99444
A19: Carbon | B19: FRANKLIN TOWNSHIP | C19: FRANKLIN TOWNSHIP-IND DIST | D19: =ROUND(Q19*R19,0) -> 129 | E19: =ROUND(Q19,0)-D19 -> 319 | F19: =IF(COUNTA(D19:E19)=0,"",SUM(D19:E19)) -> 448 | G19: =IF(OR(F19="",F19=0),"",D19/F19) -> 0.28794643 | H19: =IF(OR(F19="",F19=0),"",E19/F19) -> 0.71205357 | I19: random forest (results only) | J19: 2.8791897 | K19: =IF(G19="","",MAX(0,G19-J19/100)) -> 0.25915453 | L19: =IF(G19="","",MIN(1,G19+J19/100)) -> 0.31673833 | M19: =IF(F19="","",ROUND(F19*J19/100,0)) -> 13 | P19: -21.572129 | Q19: =T19*$H$5 -> 447.93932 | R19: =MAX(0,MIN(1,P19/100+$D$5)) -> 0.28692918 | S19: Small | T19: 447.93932
A20: Carbon | B20: FRANKLIN TOWNSHIP | C20: FRANKLIN TOWNSHIP-LONG RUN | D20: =ROUND(Q20*R20,0) -> 190 | E20: =ROUND(Q20,0)-D20 -> 493 | F20: =IF(COUNTA(D20:E20)=0,"",SUM(D20:E20)) -> 683 | G20: =IF(OR(F20="",F20=0),"",D20/F20) -> 0.27818448 | H20: =IF(OR(F20="",F20=0),"",E20/F20) -> 0.72181552 | I20: random forest (results only) | J20: 2.8791897 | K20: =IF(G20="","",MAX(0,G20-J20/100)) -> 0.24939258 | L20: =IF(G20="","",MIN(1,G20+J20/100)) -> 0.30697638 | M20: =IF(F20="","",ROUND(F20*J20/100,0)) -> 20 | P20: -22.407704 | Q20: =T20*$H$5 -> 683.32677 | R20: =MAX(0,MIN(1,P20/100+$D$5)) -> 0.27857343 | S20: Small | T20: 683.32677
A21: Carbon | B21: JIM THORPE BOROUGH | C21: JIM THORPE BOROUGH-1ST | D21: =ROUND(Q21*R21,0) -> 204 | E21: =ROUND(Q21,0)-D21 -> 232 | F21: =IF(COUNTA(D21:E21)=0,"",SUM(D21:E21)) -> 436 | G21: =IF(OR(F21="",F21=0),"",D21/F21) -> 0.46788991 | H21: =IF(OR(F21="",F21=0),"",E21/F21) -> 0.53211009 | I21: random forest (results only) | J21: 2.8791897 | K21: =IF(G21="","",MAX(0,G21-J21/100)) -> 0.43909801 | L21: =IF(G21="","",MIN(1,G21+J21/100)) -> 0.4966818 | M21: =IF(F21="","",ROUND(F21*J21/100,0)) -> 13 | P21: -3.6000118 | Q21: =T21*$H$5 -> 436.24467 | R21: =MAX(0,MIN(1,P21/100+$D$5)) -> 0.46665036 | S21: Small | T21: 436.24467
A22: Carbon | B22: JIM THORPE BOROUGH | C22: JIM THORPE BOROUGH-2ND | D22: =ROUND(Q22*R22,0) -> 129 | E22: =ROUND(Q22,0)-D22 -> 151 | F22: =IF(COUNTA(D22:E22)=0,"",SUM(D22:E22)) -> 280 | G22: =IF(OR(F22="",F22=0),"",D22/F22) -> 0.46071429 | H22: =IF(OR(F22="",F22=0),"",E22/F22) -> 0.53928571 | I22: random forest (results only) | J22: 2.8791897 | K22: =IF(G22="","",MAX(0,G22-J22/100)) -> 0.43192239 | L22: =IF(G22="","",MIN(1,G22+J22/100)) -> 0.48950618 | M22: =IF(F22="","",ROUND(F22*J22/100,0)) -> 8 | P22: -4.288818 | Q22: =T22*$H$5 -> 280.5 | R22: =MAX(0,MIN(1,P22/100+$D$5)) -> 0.45976229 | S22: Small | T22: 280.5
A23: Carbon | B23: JIM THORPE BOROUGH | C23: JIM THORPE BOROUGH-3RD | D23: =ROUND(Q23*R23,0) -> 257 | E23: =ROUND(Q23,0)-D23 -> 389 | F23: =IF(COUNTA(D23:E23)=0,"",SUM(D23:E23)) -> 646 | G23: =IF(OR(F23="",F23=0),"",D23/F23) -> 0.39783282 | H23: =IF(OR(F23="",F23=0),"",E23/F23) -> 0.60216718 | I23: random forest (results only) | J23: 2.8791897 | K23: =IF(G23="","",MAX(0,G23-J23/100)) -> 0.36904092 | L23: =IF(G23="","",MIN(1,G23+J23/100)) -> 0.42662471 | M23: =IF(F23="","",ROUND(F23*J23/100,0)) -> 19 | P23: -10.416499 | Q23: =T23*$H$5 -> 645.69536 | R23: =MAX(0,MIN(1,P23/100+$D$5)) -> 0.39848548 | S23: Small | T23: 645.69536
... A381: Northampton | B381: WIND GAP | C381: WIND GAP | D381: =ROUND(Q381*R381,0) -> 506 | E381: =ROUND(Q381,0)-D381 -> 639 | F381: =IF(COUNTA(D381:E381)=0,"",SUM(D381:E381)) -> 1145 | G381: =IF(OR(F381="",F381=0),"",D381/F381) -> 0.4419214 | H381: =IF(OR(F381="",F381=0),"",E381/F381) -> 0.5580786 | I381: random forest (results only) | J381: 1.9254971 | K381: =IF(G381="","",MAX(0,G381-J381/100)) -> 0.42266643 | L381: =IF(G381="","",MIN(1,G381+J381/100)) -> 0.46117637 | M381: =IF(F381="","",ROUND(F381*J381/100,0)) -> 22 | P381: -6.1239684 | Q381: =T381*$H$5 -> 1145.4806 | R381: =MAX(0,MIN(1,P381/100+$D$5)) -> 0.44141079 | S381: Medium | T381: 1145.4806

Sheet 2026 Forecast C
A1: PA-07 2026 House Forecast — Precinct-Level Predictions (Forecast C: shap family-reweighted forest)
A2: Candidates: Brooks | Mackenzie | District totals (yellow) are formulas over the precinct rows.
A3: Only the results are modelled. Votes cast in each row = its 2022 House votes × its registration growth since 2022, scaled to the district votes-cast input. Brooks votes = votes cast × forecast Brooks share. Change the district share or votes cast on the Scenario & Comparison tab.
A4: Model / scenario | B4: Random forest on results — Forecast C (SHAP family-reweighted forest), precinct model; turnout = 2022 votes × registration growth | C4: As-of date | D4: 46300 | E4: Prepared by | F4: Max | G4: Version | H4: v3.0 (results only, fixed baseline)
A5: District Brooks share (scenario) | B5: ='Scenario & Comparison'!$C$6 -> 0.49515845 | C5: Uniform shift applied | D5: =B5-SUMPRODUCT(P12:P381,Q12:Q381)/SUM(Q12:Q381)/100 -> 0.49221712 | E5: 2024 backtest district miss (pts) | F5: -0.12122496 | G5: Turnout scale | H5: ='Scenario & Comparison'!$C$7/SUM(T12:T381) -> 1
A6: DISTRICT TOTALS (auto-sum — do not type over)
A7: Geography | B7: (muni) | C7: (precinct) | D7: Brooks votes | E7: Mackenzie votes | F7: Total votes | G7: Brooks share | H7: Mackenzie share | I7: Notes | J7: Error term: Brooks share (± pts) | K7: Brooks share, low | L7: Brooks share, high | M7: Error term: Brooks votes (± votes)
A8: PA-07 District | B8: (all precincts) | D8: =SUM(D12:D381) -> 154594 | E8: =SUM(E12:E381) -> 157595 | F8: =D8+E8 -> 312189 | G8: =IF(F8=0,"",D8/F8) -> 0.49519362 | H8: =IF(F8=0,"",E8/F8) -> 0.50480638 | I8: Headline forecast for the briefing | J8: 0.12122496 | K8: =G8-J8/100 -> 0.49398137 | L8: =G8+J8/100 -> 0.49640587 | M8: =ROUND(F8*J8/100,0) -> 378
A9: Error terms: each row = ±1 root-mean-square miss of this forecast in its 2024 backtest for places of similar size, after removing the district-wide miss. District row = the district-wide miss. Turnout is set by rule (not forecast), so no turnout error is included; the backtest shows that rule missed 2024 votes cast by under 1%.
A10: PRECINCT DETAIL | P10: MODEL INPUTS (from the random forest — do not edit)
A11: County | B11: Municipality | C11: Precinct | D11: Brooks votes | E11: Mackenzie votes | F11: Total votes | G11: Brooks share | H11: Mackenzie share | I11: Notes / source method | J11: Error term: Brooks share (± pts) | K11: Brooks share, low | L11: Brooks share, high | M11: Error term: Brooks votes (± votes) | P11: Model lean vs district (pts) | Q11: Votes cast (scaled rule) | R11: Forecast Brooks share (unrounded) | S11: Size group (backtest error band) | T11: Rule votes: 2022 House votes × registration growth
A12: Carbon | B12: BANKS TOWNSHIP | C12: BANKS TOWNSHIP | D12: =ROUND(Q12*R12,0) -> 147 | E12: =ROUND(Q12,0)-D12 -> 217 | F12: =IF(COUNTA(D12:E12)=0,"",SUM(D12:E12)) -> 364 | G12: =IF(OR(F12="",F12=0),"",D12/F12) -> 0.40384615 | H12: =IF(OR(F12="",F12=0),"",E12/F12) -> 0.59615385 | I12: random forest (results only) | J12: 3.1546623 | K12: =IF(G12="","",MAX(0,G12-J12/100)) -> 0.37229953 | L12: =IF(G12="","",MIN(1,G12+J12/100)) -> 0.43539278 | M12: =IF(F12="","",ROUND(F12*J12/100,0)) -> 11 | P12: -8.8015271 | Q12: =T12*$H$5 -> 364.49096 | R12: =MAX(0,MIN(1,P12/100+$D$5)) -> 0.40420185 | S12: Small | T12: 364.49096
A13: Carbon | B13: BEAVER MEADOWS BOROUGH | C13: BEAVER MEADOWS BOROUGH | D13: =ROUND(Q13*R13,0) -> 93 | E13: =ROUND(Q13,0)-D13 -> 237 | F13: =IF(COUNTA(D13:E13)=0,"",SUM(D13:E13)) -> 330 | G13: =IF(OR(F13="",F13=0),"",D13/F13) -> 0.28181818 | H13: =IF(OR(F13="",F13=0),"",E13/F13) -> 0.71818182 | I13: random forest (results only) | J13: 3.1546623 | K13: =IF(G13="","",MAX(0,G13-J13/100)) -> 0.25027156 | L13: =IF(G13="","",MIN(1,G13+J13/100)) -> 0.31336481 | M13: =IF(F13="","",ROUND(F13*J13/100,0)) -> 10 | P13: -21.059919 | Q13: =T13*$H$5 -> 330.13014 | R13: =MAX(0,MIN(1,P13/100+$D$5)) -> 0.28161793 | S13: Small | T13: 330.13014
A14: Carbon | B14: BOWMANSTOWN BOROUGH | C14: BOWMANSTOWN BOROUGH | D14: =ROUND(Q14*R14,0) -> 114 | E14: =ROUND(Q14,0)-D14 -> 242 | F14: =IF(COUNTA(D14:E14)=0,"",SUM(D14:E14)) -> 356 | G14: =IF(OR(F14="",F14=0),"",D14/F14) -> 0.32022472 | H14: =IF(OR(F14="",F14=0),"",E14/F14) -> 0.67977528 | I14: random forest (results only) | J14: 3.1546623 | K14: =IF(G14="","",MAX(0,G14-J14/100)) -> 0.2886781 | L14: =IF(G14="","",MIN(1,G14+J14/100)) -> 0.35177134 | M14: =IF(F14="","",ROUND(F14*J14/100,0)) -> 11 | P14: -17.216509 | Q14: =T14*$H$5 -> 355.63437 | R14: =MAX(0,MIN(1,P14/100+$D$5)) -> 0.32005203 | S14: Small | T14: 355.63437
A15: Carbon | B15: EAST PENN TOWNSHIP | C15: EAST PENN TOWNSHIP-NORTH | D15: =ROUND(Q15*R15,0) -> 180 | E15: =ROUND(Q15,0)-D15 -> 544 | F15: =IF(COUNTA(D15:E15)=0,"",SUM(D15:E15)) -> 724 | G15: =IF(OR(F15="",F15=0),"",D15/F15) -> 0.24861878 | H15: =IF(OR(F15="",F15=0),"",E15/F15) -> 0.75138122 | I15: random forest (results only) | J15: 3.1546623 | K15: =IF(G15="","",MAX(0,G15-J15/100)) -> 0.21707216 | L15: =IF(G15="","",MIN(1,G15+J15/100)) -> 0.28016541 | M15: =IF(F15="","",ROUND(F15*J15/100,0)) -> 23 | P15: -24.369799 | Q15: =T15*$H$5 -> 724.37791 | R15: =MAX(0,MIN(1,P15/100+$D$5)) -> 0.24851913 | S15: Small | T15: 724.37791
A16: Carbon | B16: EAST PENN TOWNSHIP | C16: EAST PENN TOWNSHIP-SOUTH | D16: =ROUND(Q16*R16,0) -> 170 | E16: =ROUND(Q16,0)-D16 -> 441 | F16: =IF(COUNTA(D16:E16)=0,"",SUM(D16:E16)) -> 611 | G16: =IF(OR(F16="",F16=0),"",D16/F16) -> 0.27823241 | H16: =IF(OR(F16="",F16=0),"",E16/F16) -> 0.72176759 | I16: random forest (results only) | J16: 3.1546623 | K16: =IF(G16="","",MAX(0,G16-J16/100)) -> 0.24668578 | L16: =IF(G16="","",MIN(1,G16+J16/100)) -> 0.30977903 | M16: =IF(F16="","",ROUND(F16*J16/100,0)) -> 19 | P16: -21.361117 | Q16: =T16*$H$5 -> 610.89237 | R16: =MAX(0,MIN(1,P16/100+$D$5)) -> 0.27860595 | S16: Small | T16: 610.89237
A17: Carbon | B17: EAST SIDE BOROUGH | C17: EAST SIDE BOROUGH | D17: =ROUND(Q17*R17,0) -> 32 | E17: =ROUND(Q17,0)-D17 -> 61 | F17: =IF(COUNTA(D17:E17)=0,"",SUM(D17:E17)) -> 93 | G17: =IF(OR(F17="",F17=0),"",D17/F17) -> 0.34408602 | H17: =IF(OR(F17="",F17=0),"",E17/F17) -> 0.65591398 | I17: random forest (results only) | J17: 3.1546623 | K17: =IF(G17="","",MAX(0,G17-J17/100)) -> 0.3125394 | L17: =IF(G17="","",MIN(1,G17+J17/100)) -> 0.37563264 | M17: =IF(F17="","",ROUND(F17*J17/100,0)) -> 3 | P17: -15.019764 | Q17: =T17*$H$5 -> 93.426829 | R17: =MAX(0,MIN(1,P17/100+$D$5)) -> 0.34201948 | S17: Small | T17: 93.426829
A18: Carbon | B18: FRANKLIN TOWNSHIP | C18: FRANKLIN TOWNSHIP-HARRITY | D18: =ROUND(Q18*R18,0) -> 240 | E18: =ROUND(Q18,0)-D18 -> 613 | F18: =IF(COUNTA(D18:E18)=0,"",SUM(D18:E18)) -> 853 | G18: =IF(OR(F18="",F18=0),"",D18/F18) -> 0.28135991 | H18: =IF(OR(F18="",F18=0),"",E18/F18) -> 0.71864009 | I18: random forest (results only) | J18: 1.8851096 | K18: =IF(G18="","",MAX(0,G18-J18/100)) -> 0.26250881 | L18: =IF(G18="","",MIN(1,G18+J18/100)) -> 0.300211 | M18: =IF(F18="","",ROUND(F18*J18/100,0)) -> 16 | P18: -21.14341 | Q18: =T18*$H$5 -> 852.99444 | R18: =MAX(0,MIN(1,P18/100+$D$5)) -> 0.28078302 | S18: Medium | T18: 852.99444
A19: Carbon | B19: FRANKLIN TOWNSHIP | C19: FRANKLIN TOWNSHIP-IND DIST | D19: =ROUND(Q19*R19,0) -> 121 | E19: =ROUND(Q19,0)-D19 -> 327 | F19: =IF(COUNTA(D19:E19)=0,"",SUM(D19:E19)) -> 448 | G19: =IF(OR(F19="",F19=0),"",D19/F19) -> 0.27008929 | H19: =IF(OR(F19="",F19=0),"",E19/F19) -> 0.72991071 | I19: random forest (results only) | J19: 3.1546623 | K19: =IF(G19="","",MAX(0,G19-J19/100)) -> 0.23854266 | L19: =IF(G19="","",MIN(1,G19+J19/100)) -> 0.30163591 | M19: =IF(F19="","",ROUND(F19*J19/100,0)) -> 14 | P19: -22.22272 | Q19: =T19*$H$5 -> 447.93932 | R19: =MAX(0,MIN(1,P19/100+$D$5)) -> 0.26998993 | S19: Small | T19: 447.93932
A20: Carbon | B20: FRANKLIN TOWNSHIP | C20: FRANKLIN TOWNSHIP-LONG RUN | D20: =ROUND(Q20*R20,0) -> 184 | E20: =ROUND(Q20,0)-D20 -> 499 | F20: =IF(COUNTA(D20:E20)=0,"",SUM(D20:E20)) -> 683 | G20: =IF(OR(F20="",F20=0),"",D20/F20) -> 0.26939971 | H20: =IF(OR(F20="",F20=0),"",E20/F20) -> 0.73060029 | I20: random forest (results only) | J20: 3.1546623 | K20: =IF(G20="","",MAX(0,G20-J20/100)) -> 0.23785308 | L20: =IF(G20="","",MIN(1,G20+J20/100)) -> 0.30094633 | M20: =IF(F20="","",ROUND(F20*J20/100,0)) -> 22 | P20: -22.35058 | Q20: =T20*$H$5 -> 683.32677 | R20: =MAX(0,MIN(1,P20/100+$D$5)) -> 0.26871133 | S20: Small | T20: 683.32677
A21: Carbon | B21: JIM THORPE BOROUGH | C21: JIM THORPE BOROUGH-1ST | D21: =ROUND(Q21*R21,0) -> 199 | E21: =ROUND(Q21,0)-D21 -> 237 | F21: =IF(COUNTA(D21:E21)=0,"",SUM(D21:E21)) -> 436 | G21: =IF(OR(F21="",F21=0),"",D21/F21) -> 0.45642202 | H21: =IF(OR(F21="",F21=0),"",E21/F21) -> 0.54357798 | I21: random forest (results only) | J21: 3.1546623 | K21: =IF(G21="","",MAX(0,G21-J21/100)) -> 0.42487539 | L21: =IF(G21="","",MIN(1,G21+J21/100)) -> 0.48796864 | M21: =IF(F21="","",ROUND(F21*J21/100,0)) -> 14 | P21: -3.6413148 | Q21: =T21*$H$5 -> 436.24467 | R21: =MAX(0,MIN(1,P21/100+$D$5)) -> 0.45580398 | S21: Small | T21: 436.24467
A22: Carbon | B22: JIM THORPE BOROUGH | C22: JIM THORPE BOROUGH-2ND | D22: =ROUND(Q22*R22,0) -> 123 | E22: =ROUND(Q22,0)-D22 -> 157 | F22: =IF(COUNTA(D22:E22)=0,"",SUM(D22:E22)) -> 280 | G22: =IF(OR(F22="",F22=0),"",D22/F22) -> 0.43928571 | H22: =IF(OR(F22="",F22=0),"",E22/F22) -> 0.56071429 | I22: random forest (results only) | J22: 3.1546623 | K22: =IF(G22="","",MAX(0,G22-J22/100)) -> 0.40773909 | L22: =IF(G22="","",MIN(1,G22+J22/100)) -> 0.47083234 | M22: =IF(F22="","",ROUND(F22*J22/100,0)) -> 9 | P22: -5.4457467 | Q22: =T22*$H$5 -> 280.5 | R22: =MAX(0,MIN(1,P22/100+$D$5)) -> 0.43775966 | S22: Small | T22: 280.5
A23: Carbon | B23: JIM THORPE BOROUGH | C23: JIM THORPE BOROUGH-3RD | D23: =ROUND(Q23*R23,0) -> 252 | E23: =ROUND(Q23,0)-D23 -> 394 | F23: =IF(COUNTA(D23:E23)=0,"",SUM(D23:E23)) -> 646 | G23: =IF(OR(F23="",F23=0),"",D23/F23) -> 0.39009288 | H23: =IF(OR(F23="",F23=0),"",E23/F23) -> 0.60990712 | I23: random forest (results only) | J23: 3.1546623 | K23: =IF(G23="","",MAX(0,G23-J23/100)) -> 0.35854626 | L23: =IF(G23="","",MIN(1,G23+J23/100)) -> 0.4216395 | M23: =IF(F23="","",ROUND(F23*J23/100,0)) -> 20 | P23: -10.238546 | Q23: =T23*$H$5 -> 645.69536 | R23: =MAX(0,MIN(1,P23/100+$D$5)) -> 0.38983167 | S23: Small | T23: 645.69536
... A381: Northampton | B381: WIND GAP | C381: WIND GAP | D381: =ROUND(Q381*R381,0) -> 507 | E381: =ROUND(Q381,0)-D381 -> 638 | F381: =IF(COUNTA(D381:E381)=0,"",SUM(D381:E381)) -> 1145 | G381: =IF(OR(F381="",F381=0),"",D381/F381) -> 0.44279476 | H381: =IF(OR(F381="",F381=0),"",E381/F381) -> 0.55720524 | I381: random forest (results only) | J381: 1.8851096 | K381: =IF(G381="","",MAX(0,G381-J381/100)) -> 0.42394366 | L381: =IF(G381="","",MIN(1,G381+J381/100)) -> 0.46164586 | M381: =IF(F381="","",ROUND(F381*J381/100,0)) -> 22 | P381: -4.9390023 | Q381: =T381*$H$5 -> 1145.4806 | R381: =MAX(0,MIN(1,P381/100+$D$5)) -> 0.4428271 | S381: Medium | T381: 1145.4806

Sheet How Forecasts Are Weighted
A1: How the three precinct-level forecasts weigh their inputs (SHAP) — results-only random forests
A3: Forecast A — Full random forest.
A4: All 23 candidate inputs go into one random forest that forecasts the Democratic share. Nothing is weighted by hand; SHAP measures what the forest learned. This is the reference.
A5: Forecast B — SHAP-selected forest.
A6: Keeps only inputs whose average |SHAP| beat all 10 random columns in at least 18 of 20 refits and that held at least 2% of Forecast A’s SHAP total (6 of 23 kept), then refits the forest on them. Weight that was spread thinly over weak inputs is concentrated on the strong ones.
A7: Forecast C — SHAP family-reweighted forest.
A8: Keeps Forecast A’s forest but multiplies each input family’s SHAP values by a weight fitted to how well that family predicted elections the forest had not seen (leave-one-election-out, fitted within each election). Families under 3% of SHAP stay at ×1; others are limited to ×0.5–×2 because there are only three training elections.
A9: Backtests.
A10: Each 2024 backtest uses its own forecast’s weighting: A’s full input set, B’s selected inputs, and C’s exact family weights — refit only on 2020 and 2022.
A11: Turnout.
A12: Not modelled in any forecast: votes cast = last same-type House votes × registration growth (2022→2026 for the forecast; 2020→2024 in the backtest). All differences between A, B and C come from the results model.
A14: Family share of SHAP value in votes, 2026 forecast rows
A15: Input family | B15: Forecast A | C15: Forecast B | D15: Forecast C | E15: Forecast C weight (×)
A16: Election type | B16: 0.0037796838 | C16: 0 | D16: 0.0036747458 | E16: 1
A17: Geography & municipal context | B17: 0.018762929 | C17: 0 | D17: 0.018242001 | E17: 1
A18: Historical voter data | B18: 0.73421885 | C18: 0.68091321 | D18: 0.77198837 | E18: 1.0814673
A19: Voter registration data | B19: 0.24323854 | C19: 0.31908679 | D19: 0.20609488 | E19: 0.87149117
A20: Out-of-fold pattern error before → after Forecast C’s re-weighting: 2.59 → 2.55 points.
A22: Top inputs in each forecast (share of SHAP value in votes)
A23: # | B23: Forecast A | C23: Share | D23: Forecast B | E23: Share | F23: Forecast C | G23: Share
A24: 1 | B24: Precinct House lean, last election (t−2) | C24: 0.27862482 | D24: Precinct House lean, last election (t−2) | E24: 0.17520361 | F24: Precinct House lean, last election (t−2) | G24: 0.29295778
A25: 2 | B25: Electorate last election: R % of ballots | C25: 0.19334526 | D25: Precinct House lean, last same-type election (t−4) | E25: 0.16945971 | F25: Electorate last election: R % of ballots | G25: 0.20329128
A26: 3 | B26: Municipality House lean, last election (t−2) | C26: 0.13040476 | D26: Electorate last election: R % of ballots | E26: 0.1689257 | F26: Municipality House lean, last election (t−2) | G26: 0.13711301
A27: 4 | B27: State registration: R % (as of election) | C27: 0.1127324 | D27: Municipality House lean, last election (t−2) | E27: 0.1673242 | F27: State registration: R % (as of election) | G27: 0.095517639
A28: 5 | B28: Precinct House lean, last same-type election (t−4) | C28: 0.080463754 | D28: State registration: R % (as of election) | E28: 0.16356276 | F28: Precinct House lean, last same-type election (t−4) | G28: 0.084602952
A29: 6 | B29: State registration: D % (as of election) | C29: 0.076636876 | D29: State registration: D % (as of election) | E29: 0.15552402 | F29: State registration: D % (as of election) | G29: 0.064934068
A30: 7 | B30: State registration: change in D−R margin since t−2 | C30: 0.020865699 | F30: State registration: change in D−R margin since t−2 | G30: 0.01767941
A31: 8 | B31: Mail use last election: R voters | C31: 0.016328199 | F31: Mail use last election: R voters | G31: 0.017168151
A32: 9 | B32: Precinct vs. its municipality, last election (pts) | C32: 0.014196296 | F32: Precinct vs. its municipality, last election (pts) | G32: 0.013802154
A33: 10 | B33: Turnout last election: R registrants | C33: 0.010926934 | F33: Turnout last election: R registrants | G33: 0.011489035
A35: Forecast B — random-column test and selection
A36: Input | B36: Beat random columns (of 20) | C36: Share of SHAP in A | D36: Kept in B?
A37: Precinct House lean, last election (t−2) | B37: 20 | C37: 0.29575643 | D37: Yes
A38: Electorate last election: R % of ballots | B38: 20 | C38: 0.19404728 | D38: Yes
A39: Municipality House lean, last election (t−2) | B39: 20 | C39: 0.13112478 | D39: Yes
A40: State registration: R % (as of election) | B40: 20 | C40: 0.11105602 | D40: Yes
A41: Precinct House lean, last same-type election (t−4) | B41: 20 | C41: 0.078463649 | D41: Yes
A42: State registration: D % (as of election) | B42: 20 | C42: 0.072851368 | D42: Yes
A43: State registration: change in D−R margin since t−2 | B43: 20 | C43: 0.01772911 | D43: No
A44: Precinct vs. its municipality, last election (pts) | B44: 20 | C44: 0.013984863 | D44: No
...

Sheet Feature Ranking A
A1: Rank | B1: Feature | C1: Input family | D1: Share of model | E1: Share within its family | F1: SHAP value in votes | G1: Used to forecast | H1: Significance test result | I1: Variable (short name) | J1: Status in Forecast B
A2: 1 | B2: Democratic percent of the two-party House vote, 2024 (certified precinct results), above or below the district average | C2: Historical voter data | D2: 0.27862482 | E2: 0.37948471 | F2: 53.408418 | G2: Democratic percent of the two-party vote | H2: Beat all 10 random comparison columns in 20 of 20 refits. | I2: Precinct House lean, last election (t−2) | J2: Kept in B
A3: 2 | B3: Registered Republicans as a percent of everyone who voted, 2024 (voter file) | C3: Historical voter data | D3: 0.19334526 | E3: 0.26333464 | F3: 37.061537 | G3: Democratic percent of the two-party vote | H3: Beat all 10 random comparison columns in 20 of 20 refits. | I3: Electorate last election: R % of ballots | J3: Kept in B
A4: 3 | B4: Democratic percent of the two-party House vote in the precinct’s whole municipality, 2024, above or below the district average | C4: Historical voter data | D4: 0.13040476 | E4: 0.1776102 | F4: 24.996738 | G4: Democratic percent of the two-party vote | H4: Beat all 10 random comparison columns in 20 of 20 refits. | I4: Municipality House lean, last election (t−2) | J4: Kept in B
A5: 4 | B5: Registered Republicans as a percent of all registered voters, 2026 primary rolls (Department of State) | C5: Voter registration data | D5: 0.1127324 | E5: 0.46346439 | F5: 21.609199 | G5: Democratic percent of the two-party vote | H5: Beat all 10 random comparison columns in 20 of 20 refits. | I5: State registration: R % (as of election) | J5: Kept in B
A6: 5 | B6: Democratic percent of the two-party House vote, 2022 — the last midterm (certified precinct results), above or below the district average | C6: Historical voter data | D6: 0.080463754 | E6: 0.10959097 | F6: 15.423758 | G6: Democratic percent of the two-party vote | H6: Beat all 10 random comparison columns in 20 of 20 refits. | I6: Precinct House lean, last same-type election (t−4) | J6: Kept in B
A7: 6 | B7: Registered Democrats as a percent of all registered voters, 2026 primary rolls (Department of State) | C7: Voter registration data | D7: 0.076636876 | E7: 0.3150688 | F7: 14.6902 | G7: Democratic percent of the two-party vote | H7: Beat all 10 random comparison columns in 20 of 20 refits. | I7: State registration: D % (as of election) | J7: Kept in B
A8: 7 | B8: Change in registered Democrats minus Republicans (percent of registered) from the 2024 general to the 2026 primary (Department of State) | C8: Voter registration data | D8: 0.020865699 | E8: 0.085782868 | F8: 3.9996579 | G8: Democratic percent of the two-party vote | H8: Beat all 10 random comparison columns in 20 of 20 refits. | I8: State registration: change in D−R margin since t−2 | J8: Dropped from B
A9: 8 | B9: Percent of Republican voters who voted by mail, 2024 (voter file) | C9: Historical voter data | D9: 0.016328199 | E9: 0.022238873 | F9: 3.1298837 | G9: Democratic percent of the two-party vote | H9: Beat all 10 random comparison columns in 20 of 20 refits. | I9: Mail use last election: R voters | J9: Dropped from B
A10: 9 | B10: Precinct’s 2024 House Democratic percent minus its municipality’s, in points | C10: Geography & municipal context | D10: 0.014196296 | E10: 0.75661406 | F10: 2.7212282 | G10: Democratic percent of the two-party vote | H10: Beat all 10 random comparison columns in 20 of 20 refits. | I10: Precinct vs. its municipality, last election (pts) | J10: Dropped from B
A11: 10 | B11: Percent of registered Republicans who voted, 2024 (voter file) | C11: Historical voter data | D11: 0.010926934 | E11: 0.014882394 | F11: 2.0945379 | G11: Democratic percent of the two-party vote | H11: Beat all 10 random comparison columns in 20 of 20 refits. | I11: Turnout last election: R registrants | J11: Dropped from B
A12: 11 | B12: Republican percent of registered voters in the 2026 voter file minus the Republican percent on the 2026 state rolls (a party-switching signal) | C12: Voter registration data | D12: 0.0096814115 | E12: 0.039802128 | F12: 1.8557889 | G12: Democratic percent of the two-party vote | H12: Beat all 10 random comparison columns in 20 of 20 refits. | I12: Voter-file party switch gap (today’s R % − state R %) | J12: Dropped from B
A13: 12 | B13: Percent of Democratic voters who voted by mail, 2024 (voter file) | C13: Historical voter data | D13: 0.0093961225 | E13: 0.012797441 | F13: 1.8011031 | G13: Democratic percent of the two-party vote | H13: Beat all 10 random comparison columns in 20 of 20 refits. | I13: Mail use last election: D voters | J13: Dropped from B
... A24: 23 | B24: Precinct is in Lehigh County (1/0) | C24: Geography & municipal context | D24: 0.0010024291 | E24: 0.053426044 | F24: 0.19215141 | G24: Democratic percent of the two-party vote | H24: Beat all 10 random comparison columns in 1 of 20 refits. | I24: County: Lehigh | J24: Dropped from B
B26: Historical voter data, total | C26: Historical voter data | D26: =SUMIF(C2:C24,"Historical voter data",D2:D24) -> 0.73421885 | F26: =SUMIF(C2:C24,"Historical voter data",F2:F24) -> 140.73931
B27: Voter registration data, total | C27: Voter registration data | D27: =SUMIF(C2:C24,"Voter registration data",D2:D24) -> 0.24323854 | F27: =SUMIF(C2:C24,"Voter registration data",F2:F24) -> 46.62537
B28: Geography & municipal context, total | C28: Geography & municipal context | D28: =SUMIF(C2:C24,"Geography & municipal context",D2:D24) -> 0.018762929 | F28: =SUMIF(C2:C24,"Geography & municipal context",F2:F24) -> 3.5965868
B29: Election type, total | C29: Election type | D29: =SUMIF(C2:C24,"Election type",D2:D24) -> 0.0037796838 | F29: =SUMIF(C2:C24,"Election type",F2:F24) -> 0.72451164
B30: All features, total | D30: =SUM(D2:D24) -> 1 | F30: =SUM(F2:F24) -> 191.68578
B32: Notes
B33: How to read this table. Each row is one input that this forecast uses, ranked by SHAP value in votes on the 2026 forecast rows.
B34: SHAP value: for one place, the number of votes that one input added to or took away from that place’s forecast, measured from the model’s starting value (the average over the places and years it was trained on). Exact TreeSHAP over every tree.
B35: SHAP value in votes is the average over the 370 precincts of the votes the input moved, ignoring direction. Brooks votes and Mackenzie votes are counted together (moving 10 votes from Mackenzie to Brooks counts as 20). Votes cast are each place’s 2022 House votes × its registration growth since 2022.
B36: Share of model = the input’s SHAP value in votes ÷ the total for all inputs. Share within its family divides by its family’s total instead.
B37: What the model forecasts. One random forest forecasts each place’s Democratic percent of the two-party House vote, above or below the district average for that election. Turnout is not forecast: each place casts its 2022 House votes × its registration growth since 2022. Brooks share = forecast pattern + one uniform shift so the district total equals the scenario (default: registration-adjusted baseline).
B38: Forecast A weighting: none imposed. Each input’s weight is exactly what the full forest learned; SHAP shows it after the fact.
B39: Significance test. The full forest was refit 20 times with 10 extra columns of random numbers (5 that change row to row, 5 that keep one value per place). The column counts the refits in which the input’s average |SHAP| on the 2026 rows beat every random column.
B40: Settings: max_features=0.33, min_samples_leaf=1, 500 trees, trained on 977 precinct-elections (2020, 2022, 2024).

Sheet Feature Ranking B
A1: Rank | B1: Feature | C1: Input family | D1: Share of model | E1: Share within its family | F1: SHAP value in votes | G1: Used to forecast | H1: Significance test result | I1: Variable (short name) | J1: Status in Forecast B
A2: 1 | B2: Democratic percent of the two-party House vote, 2024 (certified precinct results), above or below the district average | C2: Historical voter data | D2: 0.17520361 | E2: 0.25730681 | F2: 29.370437 | G2: Democratic percent of the two-party vote | H2: Beat all 10 random comparison columns in 20 of 20 refits. | I2: Precinct House lean, last election (t−2) | J2: Kept in B
A3: 2 | B3: Democratic percent of the two-party House vote, 2022 — the last midterm (certified precinct results), above or below the district average | C3: Historical voter data | D3: 0.16945971 | E3: 0.24887123 | F3: 28.407553 | G3: Democratic percent of the two-party vote | H3: Beat all 10 random comparison columns in 20 of 20 refits. | I3: Precinct House lean, last same-type election (t−4) | J3: Kept in B
A4: 3 | B4: Registered Republicans as a percent of everyone who voted, 2024 (voter file) | C4: Historical voter data | D4: 0.1689257 | E4: 0.24808697 | F4: 28.318034 | G4: Democratic percent of the two-party vote | H4: Beat all 10 random comparison columns in 20 of 20 refits. | I4: Electorate last election: R % of ballots | J4: Kept in B
A5: 4 | B5: Democratic percent of the two-party House vote in the precinct’s whole municipality, 2024, above or below the district average | C5: Historical voter data | D5: 0.1673242 | E5: 0.24573499 | F5: 28.049565 | G5: Democratic percent of the two-party vote | H5: Beat all 10 random comparison columns in 20 of 20 refits. | I5: Municipality House lean, last election (t−2) | J5: Kept in B
A6: 5 | B6: Registered Republicans as a percent of all registered voters, 2026 primary rolls (Department of State) | C6: Voter registration data | D6: 0.16356276 | E6: 0.51259648 | F6: 27.419013 | G6: Democratic percent of the two-party vote | H6: Beat all 10 random comparison columns in 20 of 20 refits. | I6: State registration: R % (as of election) | J6: Kept in B
A7: 6 | B7: Registered Democrats as a percent of all registered voters, 2026 primary rolls (Department of State) | C7: Voter registration data | D7: 0.15552402 | E7: 0.48740352 | F7: 26.07143 | G7: Democratic percent of the two-party vote | H7: Beat all 10 random comparison columns in 20 of 20 refits. | I7: State registration: D % (as of election) | J7: Kept in B
B9: Historical voter data, total | C9: Historical voter data | D9: =SUMIF(C2:C7,"Historical voter data",D2:D7) -> 0.68091321 | F9: =SUMIF(C2:C7,"Historical voter data",F2:F7) -> 114.14559
B10: Voter registration data, total | C10: Voter registration data | D10: =SUMIF(C2:C7,"Voter registration data",D2:D7) -> 0.31908679 | F10: =SUMIF(C2:C7,"Voter registration data",F2:F7) -> 53.490443
B11: All features, total | D11: =SUM(D2:D7) -> 1 | F11: =SUM(F2:F7) -> 167.63603
B13: Notes
B14: How to read this table. Each row is one input that this forecast uses, ranked by SHAP value in votes on the 2026 forecast rows.
B15: SHAP value: for one place, the number of votes that one input added to or took away from that place’s forecast, measured from the model’s starting value (the average over the places and years it was trained on). Exact TreeSHAP over every tree.
B16: SHAP value in votes is the average over the 370 precincts of the votes the input moved, ignoring direction. Brooks votes and Mackenzie votes are counted together (moving 10 votes from Mackenzie to Brooks counts as 20). Votes cast are each place’s 2022 House votes × its registration growth since 2022.
B17: Share of model = the input’s SHAP value in votes ÷ the total for all inputs. Share within its family divides by its family’s total instead.
B18: What the model forecasts. One random forest forecasts each place’s Democratic percent of the two-party House vote, above or below the district average for that election. Turnout is not forecast: each place casts its 2022 House votes × its registration growth since 2022. Brooks share = forecast pattern + one uniform shift so the district total equals the scenario (default: registration-adjusted baseline).
B19: Forecast B weighting: SHAP-selected. Only inputs that beat all 10 random columns in at least 18 of 20 refits AND held at least 2% of Forecast A’s SHAP total were kept; the forest was refit on those inputs alone, so weight that was spread over weak inputs is concentrated on the strong ones.
B20: Significance test. The full forest was refit 20 times with 10 extra columns of random numbers (5 that change row to row, 5 that keep one value per place). The column counts the refits in which the input’s average |SHAP| on the 2026 rows beat every random column.
B21: Settings: max_features=0.33, min_samples_leaf=3, 500 trees, trained on 977 precinct-elections (2020, 2022, 2024).

Sheet Feature Ranking C
A1: Rank | B1: Feature | C1: Input family | D1: Share of model | E1: Share within its family | F1: SHAP value in votes | G1: Used to forecast | H1: Significance test result | I1: Variable (short name) | J1: Status in Forecast B
A2: 1 | B2: Democratic percent of the two-party House vote, 2024 (certified precinct results), above or below the district average | C2: Historical voter data | D2: 0.29295778 | E2: 0.37948471 | F2: 57.759458 | G2: Democratic percent of the two-party vote | H2: Beat all 10 random comparison columns in 20 of 20 refits. | I2: Precinct House lean, last election (t−2) | J2: Kept in B
A3: 2 | B3: Registered Republicans as a percent of everyone who voted, 2024 (voter file) | C3: Historical voter data | D3: 0.20329128 | E3: 0.26333464 | F3: 40.080841 | G3: Democratic percent of the two-party vote | H3: Beat all 10 random comparison columns in 20 of 20 refits. | I3: Electorate last election: R % of ballots | J3: Kept in B
A4: 3 | B4: Democratic percent of the two-party House vote in the precinct’s whole municipality, 2024, above or below the district average | C4: Historical voter data | D4: 0.13711301 | E4: 0.1776102 | F4: 27.033156 | G4: Democratic percent of the two-party vote | H4: Beat all 10 random comparison columns in 20 of 20 refits. | I4: Municipality House lean, last election (t−2) | J4: Kept in B
A5: 4 | B5: Registered Republicans as a percent of all registered voters, 2026 primary rolls (Department of State) | C5: Voter registration data | D5: 0.095517639 | E5: 0.46346439 | F5: 18.832226 | G5: Democratic percent of the two-party vote | H5: Beat all 10 random comparison columns in 20 of 20 refits. | I5: State registration: R % (as of election) | J5: Kept in B
A6: 5 | B6: Democratic percent of the two-party House vote, 2022 — the last midterm (certified precinct results), above or below the district average | C6: Historical voter data | D6: 0.084602952 | E6: 0.10959097 | F6: 16.68029 | G6: Democratic percent of the two-party vote | H6: Beat all 10 random comparison columns in 20 of 20 refits. | I6: Precinct House lean, last same-type election (t−4) | J6: Kept in B
A7: 6 | B7: Registered Democrats as a percent of all registered voters, 2026 primary rolls (Department of State) | C7: Voter registration data | D7: 0.064934068 | E7: 0.3150688 | F7: 12.802379 | G7: Democratic percent of the two-party vote | H7: Beat all 10 random comparison columns in 20 of 20 refits. | I7: State registration: D % (as of election) | J7: Kept in B
A8: 7 | B8: Change in registered Democrats minus Republicans (percent of registered) from the 2024 general to the 2026 primary (Department of State) | C8: Voter registration data | D8: 0.01767941 | E8: 0.085782868 | F8: 3.4856666 | G8: Democratic percent of the two-party vote | H8: Beat all 10 random comparison columns in 20 of 20 refits. | I8: State registration: change in D−R margin since t−2 | J8: Dropped from B
A9: 8 | B9: Percent of Republican voters who voted by mail, 2024 (voter file) | C9: Historical voter data | D9: 0.017168151 | E9: 0.022238873 | F9: 3.3848669 | G9: Democratic percent of the two-party vote | H9: Beat all 10 random comparison columns in 20 of 20 refits. | I9: Mail use last election: R voters | J9: Dropped from B
