Workbook

Sheet Scenario & Comparison
A1: PA-07 2026 House Forecast — Municipal Level: three results-only random-forest forecasts (fixed baseline)
A2: Candidates: Brooks | Mackenzie | The two yellow cells set the district-wide Brooks share and votes cast; all three forecasts update.
A3: A, B and C weight the same random-forest inputs differently using SHAP (see How Forecasts Are Weighted). Each is backtested on 2024 with its own weights; those errors are the error terms.
A5: SCENARIO INPUTS (defaults are built from the tables below; type over them to run another scenario)
A6: District-wide Brooks share of the two-party vote (input) | C6: =C21 -> 0.49515845 | D6: ← default: registration-adjusted baseline (row 21)
A7: Turnout multiplier (input; 1.00 = each place keeps its 2022 turnout rate) | C7: 1 | D7: ← votes cast = 2022 turnout rate × 2026 registered voters × this multiplier (row 27)
A9: HOW THE DEFAULTS ARE BUILT (today’s map applied to every year — all municipalities and precincts, as if the district had always included them)
A10: Election | C10: Democratic share | D10: Democratic votes | E10: Republican votes | F10: Registered (state rolls) | G10: Dem share of two-party registration
A11: 2018 General | C11: =D11/(D11+E11) -> 0.53259004 | D11: 136790.36 | E11: 120049.52 | F11: 483877 | G11: 0.56798799
A12: 2020 General | C12: =D12/(D12+E12) -> 0.4960879 | D12: 188855.71 | E12: 191834.3 | F12: 518873 | G12: 0.55685758
A13: 2022 General | C13: =D13/(D13+E13) -> 0.50896572 | D13: 149243 | E13: 143985 | F13: 510119 | G13: 0.54766474
A14: 2024 General | C14: =D14/(D14+E14) -> 0.49424813 | D14: 196561 | E14: 201136 | F14: 535177 | G14: 0.52758258
A15: 2026 Primary rolls | F15: 517956 | G15: 0.52223425
A16: Source: certified precinct House returns and Department of State registration (PA07_Precinct_Data.xlsx). 2018/2020 count Carbon (then PA-09) and Polk (then PA-08) as district results and include an estimate for Ross One, so every year covers the same territory as 2026.
A18: Average Democratic share, 2022 and 2024 | C18: =AVERAGE(C13,C14) -> 0.50160693
A19: Change in Dem share of two-party registration since then (pts) | C19: =(G15-AVERAGE(G13,G14))*100 -> -1.5389407
A20: Registration-to-vote link (k), measured on precinct changes 2018→2022 and 2020→2024 | C20: 0.41902062 | D20: Within-district slope: precincts whose registration moved 1 pt toward a party moved about this many pts in vote share (national swing removed).
A21: Registration-adjusted baseline for 2026 = row 18 + k × row 19 | C21: =C18+C20*C19/100 -> 0.49515845
A23: 2022 turnout in today’s district (House votes ÷ registered voters) | C23: 0.56746957
A24: 2026 registered voters (state rolls, summed over municipalities) | C24: 539345
A25: District check: 2022 turnout × 2026 registered | C25: =C23*C24 -> 306061.88
A26: Rule applied municipality by municipality (each place’s own 2022 turnout × its 2026 registered) and summed | C26: 306130.81 | D26: Each place uses its own 2022 turnout rate, so the summed total differs slightly from the district-level check. Registration: Department of State rolls (2026 primary).
A27: Votes cast used in the forecasts (row 26 × turnout multiplier) | C27: =C26*C7 -> 306130.81
A29: DISTRICT TOTALS BY FORECAST, WITH ERROR TERMS (live from each forecast tab)
A30: Forecast | B30: Weighting | C30: Brooks votes | D30: Mackenzie votes | E30: Total votes | F30: Brooks share | G30: Error term, share (± pts) | H30: Brooks share, 95% range | I30: Error term, votes cast (±) | J30: Error term, Brooks votes (±)
A31: Forecast A | B31: Full random forest | C31: ='2026 Forecast A'!D8 -> 151590 | D31: ='2026 Forecast A'!E8 -> 154539 | E31: ='2026 Forecast A'!F8 -> 306129 | F31: ='2026 Forecast A'!G8 -> 0.4951834 | G31: ='2026 Forecast A'!L8 -> 1.8117301 | H31: =TEXT('2026 Forecast A'!M8,"0.0%")&" – "&TEXT('2026 Forecast A'!N8,"0.0%") -> 46.0% – 53.1% | I31: ='2026 Forecast A'!O8 -> 13356 | J31: ='2026 Forecast A'!P8 -> 8631
A32: Forecast B | B32: SHAP-selected forest | C32: ='2026 Forecast B'!D8 -> 151583 | D32: ='2026 Forecast B'!E8 -> 154546 | E32: ='2026 Forecast B'!F8 -> 306129 | F32: ='2026 Forecast B'!G8 -> 0.49516054 | G32: ='2026 Forecast B'!L8 -> 1.8111985 | H32: =TEXT('2026 Forecast B'!M8,"0.0%")&" – "&TEXT('2026 Forecast B'!N8,"0.0%") -> 46.0% – 53.1% | I32: ='2026 Forecast B'!O8 -> 13356 | J32: ='2026 Forecast B'!P8 -> 8630
A33: Forecast C | B33: SHAP family-reweighted forest | C33: ='2026 Forecast C'!D8 -> 151580 | D33: ='2026 Forecast C'!E8 -> 154549 | E33: ='2026 Forecast C'!F8 -> 306129 | F33: ='2026 Forecast C'!G8 -> 0.49515074 | G33: ='2026 Forecast C'!L8 -> 1.8111201 | H33: =TEXT('2026 Forecast C'!M8,"0.0%")&" – "&TEXT('2026 Forecast C'!N8,"0.0%") -> 46.0% – 53.1% | I33: ='2026 Forecast C'!O8 -> 13356 | J33: ='2026 Forecast C'!P8 -> 8630
A34: District error terms = root-mean-square of the district-wide misses in all four backtests (2018, 2020, 2022, 2024). Place pattern error terms come from the 2022 and 2024 forward backtests, which use the same inputs as the 2026 forecast.
A36: BACKTESTS FOR EVERY YEAR, WITH ERROR TERMS (same weights as the forecasts; live from each backtest tab)
A37: Forecast | B37: Backtest | C37: District Dem share miss (pts) | D37: Dem votes miss | E37: Rep votes miss | F37: Votes cast miss | G37: Pattern RMS miss per row (pts) | H37: RMS miss per row (pts) | I37: Avg error term set beforehand (± pts) | J37: Actual inside ±1 error term | K37: Actual inside 95% range | L37: Rows within 3 pts
A38: Forecast A | B38: 2024 — forward backtest | C38: ='Backtest 2024 A'!F99 -> -0.43192073 | D38: ='Backtest 2024 A'!F101 -> -0.014111388 | E38: ='Backtest 2024 A'!F102 -> 0.0030733278 | F38: ='Backtest 2024 A'!F103 -> -0.0054324918 | G38: ='Backtest 2024 A'!F100 -> 1.8079197 | H38: ='Backtest 2024 A'!F98 -> 1.9408966 | I38: ='Backtest 2024 A'!F104 -> 3.4519658 | J38: ='Backtest 2024 A'!F105 -> 0.95505618 | K38: ='Backtest 2024 A'!F106 -> 1 | L38: ='Backtest 2024 A'!F107 -> 0.88764045
A39: Forecast B | B39: 2024 — forward backtest | C39: ='Backtest 2024 B'!F99 -> -0.43217003 | D39: ='Backtest 2024 B'!F101 -> -0.014116398 | E39: ='Backtest 2024 B'!F102 -> 0.0030782373 | F39: ='Backtest 2024 B'!F103 -> -0.0054324918 | G39: ='Backtest 2024 B'!F100 -> 1.8928041 | H39: ='Backtest 2024 B'!F98 -> 2.0080603 | I39: ='Backtest 2024 B'!F104 -> 3.3843934 | J39: ='Backtest 2024 B'!F105 -> 0.93258427 | K39: ='Backtest 2024 B'!F106 -> 1 | L39: ='Backtest 2024 B'!F107 -> 0.85393258
A40: Forecast C | B40: 2024 — forward backtest | C40: ='Backtest 2024 C'!F99 -> -0.43217003 | D40: ='Backtest 2024 C'!F101 -> -0.014116398 | E40: ='Backtest 2024 C'!F102 -> 0.0030782373 | F40: ='Backtest 2024 C'!F103 -> -0.0054324918 | G40: ='Backtest 2024 C'!F100 -> 2.1774044 | H40: ='Backtest 2024 C'!F98 -> 2.3890064 | I40: ='Backtest 2024 C'!F104 -> 3.4443446 | J40: ='Backtest 2024 C'!F105 -> 0.87640449 | K40: ='Backtest 2024 C'!F106 -> 1 | L40: ='Backtest 2024 C'!F107 -> 0.82022472
A41: Forecast A | B41: 2022 — forward backtest | C41: ='Backtest 2022 A'!F99 -> -0.62197042 | D41: ='Backtest 2022 A'!F101 -> -0.071569197 | E41: ='Backtest 2022 A'!F102 -> -0.048176627 | F41: ='Backtest 2022 A'!F103 -> -0.060102866 | G41: ='Backtest 2022 A'!F100 -> 2.3025093 | H41: ='Backtest 2022 A'!F98 -> 2.421165 | I41: ='Backtest 2022 A'!F104 -> 3.3406822 | J41: ='Backtest 2022 A'!F105 -> 0.86516854 | K41: ='Backtest 2022 A'!F106 -> 0.98876404 | L41: ='Backtest 2022 A'!F107 -> 0.82022472
A42: Forecast B | B42: 2022 — forward backtest | C42: ='Backtest 2022 B'!F99 -> -0.6201786 | D42: ='Backtest 2022 B'!F101 -> -0.071536164 | E42: ='Backtest 2022 B'!F102 -> -0.048210985 | F42: ='Backtest 2022 B'!F103 -> -0.060102866 | G42: ='Backtest 2022 B'!F100 -> 2.0522651 | H42: ='Backtest 2022 B'!F98 -> 2.291941 | I42: ='Backtest 2022 B'!F104 -> 3.338336 | J42: ='Backtest 2022 B'!F105 -> 0.80898876 | K42: ='Backtest 2022 B'!F106 -> 1 | L42: ='Backtest 2022 B'!F107 -> 0.82022472
A43: Forecast C | B43: 2022 — forward backtest | C43: ='Backtest 2022 C'!F99 -> -0.6230455 | D43: ='Backtest 2022 C'!F101 -> -0.071589017 | E43: ='Backtest 2022 C'!F102 -> -0.048156012 | F43: ='Backtest 2022 C'!F103 -> -0.060102866 | G43: ='Backtest 2022 C'!F100 -> 2.4168188 | H43: ='Backtest 2022 C'!F98 -> 2.6577183 | I43: ='Backtest 2022 C'!F104 -> 3.3745261 | J43: ='Backtest 2022 C'!F105 -> 0.79775281 | K43: ='Backtest 2022 C'!F106 -> 0.98876404 | L43: ='Backtest 2022 C'!F107 -> 0.70786517
A44: Forecast A | B44: 2020 — hold-out test | C44: ='Backtest 2020 A'!F99 -> 3.0613888 | D44: ='Backtest 2020 A'!F101 -> 0.067733333 | E44: ='Backtest 2020 A'!F102 -> -0.055435561 | F44: ='Backtest 2020 A'!F103 -> 0.0057914313 | G44: ='Backtest 2020 A'!F100 -> 2.704753 | H44: ='Backtest 2020 A'!F98 -> 4.9807309 | I44: ='Backtest 2020 A'!F104 -> 2.7317044 | J44: ='Backtest 2020 A'!F105 -> 0.2247191 | K44: ='Backtest 2020 A'!F106 -> 0.69662921 | L44: ='Backtest 2020 A'!F107 -> 0.3258427
A45: Forecast B | B45: 2020 — hold-out test | C45: ='Backtest 2020 B'!F99 -> 3.060877 | D45: ='Backtest 2020 B'!F101 -> 0.067722977 | E45: ='Backtest 2020 B'!F102 -> -0.055425325 | F45: ='Backtest 2020 B'!F103 -> 0.0057914313 | G45: ='Backtest 2020 B'!F100 -> 2.7920501 | H45: ='Backtest 2020 B'!F98 -> 5.0329107 | I45: ='Backtest 2020 B'!F104 -> 2.6383519 | J45: ='Backtest 2020 B'!F105 -> 0.23595506 | K45: ='Backtest 2020 B'!F106 -> 0.65168539 | L45: ='Backtest 2020 B'!F107 -> 0.33707865
A46: Forecast C | B46: 2020 — hold-out test | C46: ='Backtest 2020 C'!F99 -> 3.0601092 | D46: ='Backtest 2020 C'!F101 -> 0.067707443 | E46: ='Backtest 2020 C'!F102 -> -0.05540997 | F46: ='Backtest 2020 C'!F103 -> 0.0057914313 | G46: ='Backtest 2020 C'!F100 -> 2.3776117 | H46: ='Backtest 2020 C'!F98 -> 4.4766834 | I46: ='Backtest 2020 C'!F104 -> 2.9034255 | J46: ='Backtest 2020 C'!F105 -> 0.29213483 | K46: ='Backtest 2020 C'!F106 -> 0.83146067 | L46: ='Backtest 2020 C'!F107 -> 0.35955056
...

Sheet 2026 Forecast A
A1: PA-07 2026 House Forecast — Municipal-Level Predictions (Forecast A: full random forest)
A2: Candidates: Brooks | Mackenzie | District totals (yellow) are formulas over the municipality rows.
A3: Only the results are modelled (one random forest). Votes cast in each row = its 2022 turnout rate (House votes ÷ registered voters) × its 2026 registered voters. Brooks votes = votes cast × forecast Brooks share. Error terms combine the place’s own pattern error (2022 and 2024 backtests), the district-wide error and turnout error (all four backtest years).
A4: Model / scenario | B4: Random forest on results — Forecast A (Full random forest), municipality model; turnout = 2022 turnout rate × 2026 registered voters | C4: As-of date | D4: 46300 | E4: Prepared by | F4: Max | G4: Version | H4: v7.0 (current map; backtests every year; results only)
A5: District Brooks share (scenario) | B5: ='Scenario & Comparison'!$C$6 -> 0.49515845 | C5: Uniform shift applied | D5: =B5-SUMPRODUCT(R12:R100,S12:S100)/SUM(S12:S100)/100 -> 0.42207825 | E5: Turnout multiplier (1.00 = 2022 turnout) | F5: ='Scenario & Comparison'!$C$7 -> 1
A6: DISTRICT TOTALS (auto-sum — do not type over)
A7: Geography | B7: (muni) | C7: (area) | D7: Brooks votes | E7: Mackenzie votes | F7: Total votes | G7: Brooks share | H7: Mackenzie share | I7: Notes | J7: Error term: place pattern (± pts) | K7: Error term: district-wide (± pts) | L7: Error term: total (± pts) | M7: Brooks share, 95% low | N7: Brooks share, 95% high | O7: Error term: votes cast (± votes) | P7: Error term: Brooks votes (± votes)
A8: PA-07 District | B8: (all municipalities) | D8: =SUM(D12:D100) -> 151590 | E8: =SUM(E12:E100) -> 154539 | F8: =D8+E8 -> 306129 | G8: =IF(F8=0,"",D8/F8) -> 0.4951834 | H8: =IF(F8=0,"",E8/F8) -> 0.5048166 | I8: Headline forecast for the briefing | J8: 0 | K8: 1.8117301 | L8: =SQRT(J8^2+K8^2) -> 1.8117301 | M8: =G8-1.96*L8/100 -> 0.45967349 | N8: =G8+1.96*L8/100 -> 0.53069331 | O8: =ROUND(F8*0.04363,0) -> 13356 | P8: =ROUND(SQRT((F8*L8/100)^2+(G8*O8)^2),0) -> 8631
A9: Error terms are ±1 standard error: place pattern error by place size (2022 and 2024 forward backtests) plus district-wide and turnout error (all four backtest years, 2018–2024). 95% low/high = Brooks share ± 1.96 × total error term.
A10: MUNICIPALITY DETAIL | R10: MODEL INPUTS (from the random forest — do not edit)
A11: County | B11: Municipality | C11: Area | D11: Brooks votes | E11: Mackenzie votes | F11: Total votes | G11: Brooks share | H11: Mackenzie share | I11: Notes / source method | J11: Error term: place pattern (± pts) | K11: Error term: district-wide (± pts) | L11: Error term: total (± pts) | M11: Brooks share, 95% low | N11: Brooks share, 95% high | O11: Error term: votes cast (± votes) | P11: Error term: Brooks votes (± votes) | R11: Model lean vs district (pts) | S11: Votes cast = 2022 turnout × 2026 registered | T11: Forecast Brooks share (unrounded) | U11: 2022 turnout (House votes ÷ registered) | V11: 2026 registered voters | W11: Votes-cast error (% of votes) | X11: Size group (backtest error band) | Y11: Registration source
A12: Carbon | B12: BANKS TOWNSHIP | C12: (whole municipality) | D12: =ROUND(S12*T12,0) -> 138 | E12: =ROUND(S12,0)-D12 -> 226 | F12: =IF(COUNTA(D12:E12)=0,"",SUM(D12:E12)) -> 364 | G12: =IF(OR(F12="",F12=0),"",D12/F12) -> 0.37912088 | H12: =IF(OR(F12="",F12=0),"",E12/F12) -> 0.62087912 | I12: random forest (results only) | J12: 2.8276385 | K12: =$K$8 -> 1.8117301 | L12: =SQRT(J12^2+K12^2) -> 3.3582592 | M12: =IF(G12="","",MAX(0,G12-1.96*L12/100)) -> 0.313299 | N12: =IF(G12="","",MIN(1,G12+1.96*L12/100)) -> 0.44494276 | O12: =ROUND(S12*W12,0) -> 28 | P12: =IF(F12="","",ROUND(SQRT((F12*L12/100)^2+(G12*O12)^2),0)) -> 16 | R12: -4.3644513 | S12: =U12*V12*$F$5 -> 364.49096 | T12: =MAX(0,MIN(1,R12/100+$D$5)) -> 0.37843373 | U12: 0.5813253 | V12: 627 | W12: 0.077704034 | X12: Small | Y12: state rolls, whole municipality
A13: Carbon | B13: BEAVER MEADOWS BOROUGH | C13: (whole municipality) | D13: =ROUND(S13*T13,0) -> 97 | E13: =ROUND(S13,0)-D13 -> 233 | F13: =IF(COUNTA(D13:E13)=0,"",SUM(D13:E13)) -> 330 | G13: =IF(OR(F13="",F13=0),"",D13/F13) -> 0.29393939 | H13: =IF(OR(F13="",F13=0),"",E13/F13) -> 0.70606061 | I13: random forest (results only) | J13: 2.8276385 | K13: =$K$8 -> 1.8117301 | L13: =SQRT(J13^2+K13^2) -> 3.3582592 | M13: =IF(G13="","",MAX(0,G13-1.96*L13/100)) -> 0.22811751 | N13: =IF(G13="","",MIN(1,G13+1.96*L13/100)) -> 0.35976128 | O13: =ROUND(S13*W13,0) -> 26 | P13: =IF(F13="","",ROUND(SQRT((F13*L13/100)^2+(G13*O13)^2),0)) -> 13 | R13: -12.816121 | S13: =U13*V13*$F$5 -> 330.13014 | T13: =MAX(0,MIN(1,R13/100+$D$5)) -> 0.29391703 | U13: 0.53767123 | V13: 614 | W13: 0.077704034 | X13: Small | Y13: state rolls, whole municipality
A14: Carbon | B14: BOWMANSTOWN BOROUGH | C14: (whole municipality) | D14: =ROUND(S14*T14,0) -> 119 | E14: =ROUND(S14,0)-D14 -> 237 | F14: =IF(COUNTA(D14:E14)=0,"",SUM(D14:E14)) -> 356 | G14: =IF(OR(F14="",F14=0),"",D14/F14) -> 0.33426966 | H14: =IF(OR(F14="",F14=0),"",E14/F14) -> 0.66573034 | I14: random forest (results only) | J14: 2.8276385 | K14: =$K$8 -> 1.8117301 | L14: =SQRT(J14^2+K14^2) -> 3.3582592 | M14: =IF(G14="","",MAX(0,G14-1.96*L14/100)) -> 0.26844778 | N14: =IF(G14="","",MIN(1,G14+1.96*L14/100)) -> 0.40009154 | O14: =ROUND(S14*W14,0) -> 28 | P14: =IF(F14="","",ROUND(SQRT((F14*L14/100)^2+(G14*O14)^2),0)) -> 15 | R14: -8.8130031 | S14: =U14*V14*$F$5 -> 355.63437 | T14: =MAX(0,MIN(1,R14/100+$D$5)) -> 0.33394822 | U14: 0.63619744 | V14: 559 | W14: 0.077704034 | X14: Small | Y14: state rolls, whole municipality
A15: Carbon | B15: EAST PENN TOWNSHIP | C15: (whole municipality) | D15: =ROUND(S15*T15,0) -> 371 | E15: =ROUND(S15,0)-D15 -> 964 | F15: =IF(COUNTA(D15:E15)=0,"",SUM(D15:E15)) -> 1335 | G15: =IF(OR(F15="",F15=0),"",D15/F15) -> 0.27790262 | H15: =IF(OR(F15="",F15=0),"",E15/F15) -> 0.72209738 | I15: random forest (results only) | J15: 1.4726368 | K15: =$K$8 -> 1.8117301 | L15: =SQRT(J15^2+K15^2) -> 2.334743 | M15: =IF(G15="","",MAX(0,G15-1.96*L15/100)) -> 0.23214166 | N15: =IF(G15="","",MIN(1,G15+1.96*L15/100)) -> 0.32366358 | O15: =ROUND(S15*W15,0) -> 81 | P15: =IF(F15="","",ROUND(SQRT((F15*L15/100)^2+(G15*O15)^2),0)) -> 38 | R15: -14.415778 | S15: =U15*V15*$F$5 -> 1334.821 | T15: =MAX(0,MIN(1,R15/100+$D$5)) -> 0.27792046 | U15: 0.65208648 | V15: 2047 | W15: 0.060612226 | X15: Medium | Y15: state rolls, whole municipality
A16: Carbon | B16: EAST SIDE BOROUGH | C16: (whole municipality) | D16: =ROUND(S16*T16,0) -> 33 | E16: =ROUND(S16,0)-D16 -> 60 | F16: =IF(COUNTA(D16:E16)=0,"",SUM(D16:E16)) -> 93 | G16: =IF(OR(F16="",F16=0),"",D16/F16) -> 0.35483871 | H16: =IF(OR(F16="",F16=0),"",E16/F16) -> 0.64516129 | I16: random forest (results only) | J16: 2.8276385 | K16: =$K$8 -> 1.8117301 | L16: =SQRT(J16^2+K16^2) -> 3.3582592 | M16: =IF(G16="","",MAX(0,G16-1.96*L16/100)) -> 0.28901683 | N16: =IF(G16="","",MIN(1,G16+1.96*L16/100)) -> 0.42066059 | O16: =ROUND(S16*W16,0) -> 7 | P16: =IF(F16="","",ROUND(SQRT((F16*L16/100)^2+(G16*O16)^2),0)) -> 4 | R16: -7.2742775 | S16: =U16*V16*$F$5 -> 93.426829 | T16: =MAX(0,MIN(1,R16/100+$D$5)) -> 0.34933547 | U16: 0.57317073 | V16: 163 | W16: 0.077704034 | X16: Small | Y16: state rolls, whole municipality
A17: Carbon | B17: FRANKLIN TOWNSHIP | C17: (whole municipality) | D17: =ROUND(S17*T17,0) -> 571 | E17: =ROUND(S17,0)-D17 -> 1411 | F17: =IF(COUNTA(D17:E17)=0,"",SUM(D17:E17)) -> 1982 | G17: =IF(OR(F17="",F17=0),"",D17/F17) -> 0.28809284 | H17: =IF(OR(F17="",F17=0),"",E17/F17) -> 0.71190716 | I17: random forest (results only) | J17: 1.4726368 | K17: =$K$8 -> 1.8117301 | L17: =SQRT(J17^2+K17^2) -> 2.334743 | M17: =IF(G17="","",MAX(0,G17-1.96*L17/100)) -> 0.24233187 | N17: =IF(G17="","",MIN(1,G17+1.96*L17/100)) -> 0.3338538 | O17: =ROUND(S17*W17,0) -> 120 | P17: =IF(F17="","",ROUND(SQRT((F17*L17/100)^2+(G17*O17)^2),0)) -> 58 | R17: -13.40938 | S17: =U17*V17*$F$5 -> 1982.009 | T17: =MAX(0,MIN(1,R17/100+$D$5)) -> 0.28798444 | U17: 0.63181672 | V17: 3137 | W17: 0.060612226 | X17: Medium | Y17: state rolls, whole municipality
A18: Carbon | B18: JIM THORPE BOROUGH | C18: (whole municipality) | D18: =ROUND(S18*T18,0) -> 917 | E18: =ROUND(S18,0)-D18 -> 1191 | F18: =IF(COUNTA(D18:E18)=0,"",SUM(D18:E18)) -> 2108 | G18: =IF(OR(F18="",F18=0),"",D18/F18) -> 0.43500949 | H18: =IF(OR(F18="",F18=0),"",E18/F18) -> 0.56499051 | I18: random forest (results only) | J18: 1.4726368 | K18: =$K$8 -> 1.8117301 | L18: =SQRT(J18^2+K18^2) -> 2.334743 | M18: =IF(G18="","",MAX(0,G18-1.96*L18/100)) -> 0.38924852 | N18: =IF(G18="","",MIN(1,G18+1.96*L18/100)) -> 0.48077045 | O18: =ROUND(S18*W18,0) -> 128 | P18: =IF(F18="","",ROUND(SQRT((F18*L18/100)^2+(G18*O18)^2),0)) -> 74 | R18: 1.2790263 | S18: =U18*V18*$F$5 -> 2107.7256 | T18: =MAX(0,MIN(1,R18/100+$D$5)) -> 0.43486851 | U18: 0.64259928 | V18: 3280 | W18: 0.060612226 | X18: Medium | Y18: state rolls, whole municipality
A19: Carbon | B19: KIDDER TOWNSHIP | C19: (whole municipality) | D19: =ROUND(S19*T19,0) -> 275 | E19: =ROUND(S19,0)-D19 -> 530 | F19: =IF(COUNTA(D19:E19)=0,"",SUM(D19:E19)) -> 805 | G19: =IF(OR(F19="",F19=0),"",D19/F19) -> 0.34161491 | H19: =IF(OR(F19="",F19=0),"",E19/F19) -> 0.65838509 | I19: random forest (results only) | J19: 2.8276385 | K19: =$K$8 -> 1.8117301 | L19: =SQRT(J19^2+K19^2) -> 3.3582592 | M19: =IF(G19="","",MAX(0,G19-1.96*L19/100)) -> 0.27579303 | N19: =IF(G19="","",MIN(1,G19+1.96*L19/100)) -> 0.40743679 | O19: =ROUND(S19*W19,0) -> 63 | P19: =IF(F19="","",ROUND(SQRT((F19*L19/100)^2+(G19*O19)^2),0)) -> 35 | R19: -7.9861949 | S19: =U19*V19*$F$5 -> 804.85033 | T19: =MAX(0,MIN(1,R19/100+$D$5)) -> 0.3422163 | U19: 0.55430464 | V19: 1452 | W19: 0.077704034 | X19: Small | Y19: state rolls, whole municipality
A20: Carbon | B20: LANSFORD BOROUGH | C20: (whole municipality) | D20: =ROUND(S20*T20,0) -> 448 | E20: =ROUND(S20,0)-D20 -> 635 | F20: =IF(COUNTA(D20:E20)=0,"",SUM(D20:E20)) -> 1083 | G20: =IF(OR(F20="",F20=0),"",D20/F20) -> 0.41366574 | H20: =IF(OR(F20="",F20=0),"",E20/F20) -> 0.58633426 | I20: random forest (results only) | J20: 2.8276385 | K20: =$K$8 -> 1.8117301 | L20: =SQRT(J20^2+K20^2) -> 3.3582592 | M20: =IF(G20="","",MAX(0,G20-1.96*L20/100)) -> 0.34784386 | N20: =IF(G20="","",MIN(1,G20+1.96*L20/100)) -> 0.47948762 | O20: =ROUND(S20*W20,0) -> 84 | P20: =IF(F20="","",ROUND(SQRT((F20*L20/100)^2+(G20*O20)^2),0)) -> 50 | R20: -0.85785436 | S20: =U20*V20*$F$5 -> 1083.4829 | T20: =MAX(0,MIN(1,R20/100+$D$5)) -> 0.4134997 | U20: 0.44883303 | V20: 2414 | W20: 0.077704034 | X20: Small | Y20: state rolls, whole municipality
A21: Carbon | B21: LAUSANNE TOWNSHIP | C21: (whole municipality) | D21: =ROUND(S21*T21,0) -> 33 | E21: =ROUND(S21,0)-D21 -> 85 | F21: =IF(COUNTA(D21:E21)=0,"",SUM(D21:E21)) -> 118 | G21: =IF(OR(F21="",F21=0),"",D21/F21) -> 0.27966102 | H21: =IF(OR(F21="",F21=0),"",E21/F21) -> 0.72033898 | I21: random forest (results only) | J21: 2.8276385 | K21: =$K$8 -> 1.8117301 | L21: =SQRT(J21^2+K21^2) -> 3.3582592 | M21: =IF(G21="","",MAX(0,G21-1.96*L21/100)) -> 0.21383914 | N21: =IF(G21="","",MIN(1,G21+1.96*L21/100)) -> 0.3454829 | O21: =ROUND(S21*W21,0) -> 9 | P21: =IF(F21="","",ROUND(SQRT((F21*L21/100)^2+(G21*O21)^2),0)) -> 5 | R21: -14.604771 | S21: =U21*V21*$F$5 -> 118.28571 | T21: =MAX(0,MIN(1,R21/100+$D$5)) -> 0.27603053 | U21: 0.65714286 | V21: 180 | W21: 0.077704034 | X21: Small | Y21: state rolls, whole municipality
A22: Carbon | B22: LEHIGH TOWNSHIP | C22: (whole municipality) | D22: =ROUND(S22*T22,0) -> 49 | E22: =ROUND(S22,0)-D22 -> 188 | F22: =IF(COUNTA(D22:E22)=0,"",SUM(D22:E22)) -> 237 | G22: =IF(OR(F22="",F22=0),"",D22/F22) -> 0.20675105 | H22: =IF(OR(F22="",F22=0),"",E22/F22) -> 0.79324895 | I22: random forest (results only) | J22: 2.8276385 | K22: =$K$8 -> 1.8117301 | L22: =SQRT(J22^2+K22^2) -> 3.3582592 | M22: =IF(G22="","",MAX(0,G22-1.96*L22/100)) -> 0.14092917 | N22: =IF(G22="","",MIN(1,G22+1.96*L22/100)) -> 0.27257294 | O22: =ROUND(S22*W22,0) -> 18 | P22: =IF(F22="","",ROUND(SQRT((F22*L22/100)^2+(G22*O22)^2),0)) -> 9 | R22: -21.320836 | S22: =U22*V22*$F$5 -> 236.84483 | T22: =MAX(0,MIN(1,R22/100+$D$5)) -> 0.20886988 | U22: 0.69252874 | V22: 342 | W22: 0.077704034 | X22: Small | Y22: state rolls, whole municipality
A23: Carbon | B23: LEHIGHTON BOROUGH | C23: (whole municipality) | D23: =ROUND(S23*T23,0) -> 706 | E23: =ROUND(S23,0)-D23 -> 1048 | F23: =IF(COUNTA(D23:E23)=0,"",SUM(D23:E23)) -> 1754 | G23: =IF(OR(F23="",F23=0),"",D23/F23) -> 0.40250855 | H23: =IF(OR(F23="",F23=0),"",E23/F23) -> 0.59749145 | I23: random forest (results only) | J23: 1.4726368 | K23: =$K$8 -> 1.8117301 | L23: =SQRT(J23^2+K23^2) -> 2.334743 | M23: =IF(G23="","",MAX(0,G23-1.96*L23/100)) -> 0.35674759 | N23: =IF(G23="","",MIN(1,G23+1.96*L23/100)) -> 0.44826952 | O23: =ROUND(S23*W23,0) -> 106 | P23: =IF(F23="","",ROUND(SQRT((F23*L23/100)^2+(G23*O23)^2),0)) -> 59 | R23: -1.9367494 | S23: =U23*V23*$F$5 -> 1753.7408 | T23: =MAX(0,MIN(1,R23/100+$D$5)) -> 0.40271075 | U23: 0.52570167 | V23: 3336 | W23: 0.060612226 | X23: Medium | Y23: state rolls, whole municipality
... A100: Northampton | B100: WIND GAP | C100: (whole municipality) | D100: =ROUND(S100*T100,0) -> 494 | E100: =ROUND(S100,0)-D100 -> 651 | F100: =IF(COUNTA(D100:E100)=0,"",SUM(D100:E100)) -> 1145 | G100: =IF(OR(F100="",F100=0),"",D100/F100) -> 0.43144105 | H100: =IF(OR(F100="",F100=0),"",E100/F100) -> 0.56855895 | I100: random forest (results only) | J100: 2.8276385 | K100: =$K$8 -> 1.8117301 | L100: =SQRT(J100^2+K100^2) -> 3.3582592 | M100: =IF(G100="","",MAX(0,G100-1.96*L100/100)) -> 0.36561917 | N100: =IF(G100="","",MIN(1,G100+1.96*L100/100)) -> 0.49726293 | O100: =ROUND(S100*W100,0) -> 89 | P100: =IF(F100="","",ROUND(SQRT((F100*L100/100)^2+(G100*O100)^2),0)) -> 54 | R100: 0.9044477 | S100: =U100*V100*$F$5 -> 1145.4806 | T100: =MAX(0,MIN(1,R100/100+$D$5)) -> 0.43112272 | U100: 0.53702795 | V100: 2133 | W100: 0.077704034 | X100: Small | Y100: state rolls, whole municipality

Sheet 2026 Forecast B
A1: PA-07 2026 House Forecast — Municipal-Level Predictions (Forecast B: shap-selected forest)
A2: Candidates: Brooks | Mackenzie | District totals (yellow) are formulas over the municipality rows.
A3: Only the results are modelled (one random forest). Votes cast in each row = its 2022 turnout rate (House votes ÷ registered voters) × its 2026 registered voters. Brooks votes = votes cast × forecast Brooks share. Error terms combine the place’s own pattern error (2022 and 2024 backtests), the district-wide error and turnout error (all four backtest years).
A4: Model / scenario | B4: Random forest on results — Forecast B (SHAP-selected forest), municipality model; turnout = 2022 turnout rate × 2026 registered voters | C4: As-of date | D4: 46300 | E4: Prepared by | F4: Max | G4: Version | H4: v7.0 (current map; backtests every year; results only)
A5: District Brooks share (scenario) | B5: ='Scenario & Comparison'!$C$6 -> 0.49515845 | C5: Uniform shift applied | D5: =B5-SUMPRODUCT(R12:R100,S12:S100)/SUM(S12:S100)/100 -> 0.42328094 | E5: Turnout multiplier (1.00 = 2022 turnout) | F5: ='Scenario & Comparison'!$C$7 -> 1
A6: DISTRICT TOTALS (auto-sum — do not type over)
A7: Geography | B7: (muni) | C7: (area) | D7: Brooks votes | E7: Mackenzie votes | F7: Total votes | G7: Brooks share | H7: Mackenzie share | I7: Notes | J7: Error term: place pattern (± pts) | K7: Error term: district-wide (± pts) | L7: Error term: total (± pts) | M7: Brooks share, 95% low | N7: Brooks share, 95% high | O7: Error term: votes cast (± votes) | P7: Error term: Brooks votes (± votes)
A8: PA-07 District | B8: (all municipalities) | D8: =SUM(D12:D100) -> 151583 | E8: =SUM(E12:E100) -> 154546 | F8: =D8+E8 -> 306129 | G8: =IF(F8=0,"",D8/F8) -> 0.49516054 | H8: =IF(F8=0,"",E8/F8) -> 0.50483946 | I8: Headline forecast for the briefing | J8: 0 | K8: 1.8111985 | L8: =SQRT(J8^2+K8^2) -> 1.8111985 | M8: =G8-1.96*L8/100 -> 0.45966105 | N8: =G8+1.96*L8/100 -> 0.53066003 | O8: =ROUND(F8*0.04363,0) -> 13356 | P8: =ROUND(SQRT((F8*L8/100)^2+(G8*O8)^2),0) -> 8630
A9: Error terms are ±1 standard error: place pattern error by place size (2022 and 2024 forward backtests) plus district-wide and turnout error (all four backtest years, 2018–2024). 95% low/high = Brooks share ± 1.96 × total error term.
A10: MUNICIPALITY DETAIL | R10: MODEL INPUTS (from the random forest — do not edit)
A11: County | B11: Municipality | C11: Area | D11: Brooks votes | E11: Mackenzie votes | F11: Total votes | G11: Brooks share | H11: Mackenzie share | I11: Notes / source method | J11: Error term: place pattern (± pts) | K11: Error term: district-wide (± pts) | L11: Error term: total (± pts) | M11: Brooks share, 95% low | N11: Brooks share, 95% high | O11: Error term: votes cast (± votes) | P11: Error term: Brooks votes (± votes) | R11: Model lean vs district (pts) | S11: Votes cast = 2022 turnout × 2026 registered | T11: Forecast Brooks share (unrounded) | U11: 2022 turnout (House votes ÷ registered) | V11: 2026 registered voters | W11: Votes-cast error (% of votes) | X11: Size group (backtest error band) | Y11: Registration source
A12: Carbon | B12: BANKS TOWNSHIP | C12: (whole municipality) | D12: =ROUND(S12*T12,0) -> 140 | E12: =ROUND(S12,0)-D12 -> 224 | F12: =IF(COUNTA(D12:E12)=0,"",SUM(D12:E12)) -> 364 | G12: =IF(OR(F12="",F12=0),"",D12/F12) -> 0.38461538 | H12: =IF(OR(F12="",F12=0),"",E12/F12) -> 0.61538462 | I12: random forest (results only) | J12: 2.7365176 | K12: =$K$8 -> 1.8111985 | L12: =SQRT(J12^2+K12^2) -> 3.2816106 | M12: =IF(G12="","",MAX(0,G12-1.96*L12/100)) -> 0.32029582 | N12: =IF(G12="","",MIN(1,G12+1.96*L12/100)) -> 0.44893495 | O12: =ROUND(S12*W12,0) -> 28 | P12: =IF(F12="","",ROUND(SQRT((F12*L12/100)^2+(G12*O12)^2),0)) -> 16 | R12: -3.9438367 | S12: =U12*V12*$F$5 -> 364.49096 | T12: =MAX(0,MIN(1,R12/100+$D$5)) -> 0.38384257 | U12: 0.5813253 | V12: 627 | W12: 0.077704034 | X12: Small | Y12: state rolls, whole municipality
A13: Carbon | B13: BEAVER MEADOWS BOROUGH | C13: (whole municipality) | D13: =ROUND(S13*T13,0) -> 96 | E13: =ROUND(S13,0)-D13 -> 234 | F13: =IF(COUNTA(D13:E13)=0,"",SUM(D13:E13)) -> 330 | G13: =IF(OR(F13="",F13=0),"",D13/F13) -> 0.29090909 | H13: =IF(OR(F13="",F13=0),"",E13/F13) -> 0.70909091 | I13: random forest (results only) | J13: 2.7365176 | K13: =$K$8 -> 1.8111985 | L13: =SQRT(J13^2+K13^2) -> 3.2816106 | M13: =IF(G13="","",MAX(0,G13-1.96*L13/100)) -> 0.22658952 | N13: =IF(G13="","",MIN(1,G13+1.96*L13/100)) -> 0.35522866 | O13: =ROUND(S13*W13,0) -> 26 | P13: =IF(F13="","",ROUND(SQRT((F13*L13/100)^2+(G13*O13)^2),0)) -> 13 | R13: -13.320142 | S13: =U13*V13*$F$5 -> 330.13014 | T13: =MAX(0,MIN(1,R13/100+$D$5)) -> 0.29007952 | U13: 0.53767123 | V13: 614 | W13: 0.077704034 | X13: Small | Y13: state rolls, whole municipality
A14: Carbon | B14: BOWMANSTOWN BOROUGH | C14: (whole municipality) | D14: =ROUND(S14*T14,0) -> 120 | E14: =ROUND(S14,0)-D14 -> 236 | F14: =IF(COUNTA(D14:E14)=0,"",SUM(D14:E14)) -> 356 | G14: =IF(OR(F14="",F14=0),"",D14/F14) -> 0.33707865 | H14: =IF(OR(F14="",F14=0),"",E14/F14) -> 0.66292135 | I14: random forest (results only) | J14: 2.7365176 | K14: =$K$8 -> 1.8111985 | L14: =SQRT(J14^2+K14^2) -> 3.2816106 | M14: =IF(G14="","",MAX(0,G14-1.96*L14/100)) -> 0.27275908 | N14: =IF(G14="","",MIN(1,G14+1.96*L14/100)) -> 0.40139822 | O14: =ROUND(S14*W14,0) -> 28 | P14: =IF(F14="","",ROUND(SQRT((F14*L14/100)^2+(G14*O14)^2),0)) -> 15 | R14: -8.6337062 | S14: =U14*V14*$F$5 -> 355.63437 | T14: =MAX(0,MIN(1,R14/100+$D$5)) -> 0.33694388 | U14: 0.63619744 | V14: 559 | W14: 0.077704034 | X14: Small | Y14: state rolls, whole municipality
A15: Carbon | B15: EAST PENN TOWNSHIP | C15: (whole municipality) | D15: =ROUND(S15*T15,0) -> 368 | E15: =ROUND(S15,0)-D15 -> 967 | F15: =IF(COUNTA(D15:E15)=0,"",SUM(D15:E15)) -> 1335 | G15: =IF(OR(F15="",F15=0),"",D15/F15) -> 0.27565543 | H15: =IF(OR(F15="",F15=0),"",E15/F15) -> 0.72434457 | I15: random forest (results only) | J15: 1.5602358 | K15: =$K$8 -> 1.8111985 | L15: =SQRT(J15^2+K15^2) -> 2.3905597 | M15: =IF(G15="","",MAX(0,G15-1.96*L15/100)) -> 0.22880046 | N15: =IF(G15="","",MIN(1,G15+1.96*L15/100)) -> 0.3225104 | O15: =ROUND(S15*W15,0) -> 81 | P15: =IF(F15="","",ROUND(SQRT((F15*L15/100)^2+(G15*O15)^2),0)) -> 39 | R15: -14.746601 | S15: =U15*V15*$F$5 -> 1334.821 | T15: =MAX(0,MIN(1,R15/100+$D$5)) -> 0.27581493 | U15: 0.65208648 | V15: 2047 | W15: 0.060612226 | X15: Medium | Y15: state rolls, whole municipality
A16: Carbon | B16: EAST SIDE BOROUGH | C16: (whole municipality) | D16: =ROUND(S16*T16,0) -> 33 | E16: =ROUND(S16,0)-D16 -> 60 | F16: =IF(COUNTA(D16:E16)=0,"",SUM(D16:E16)) -> 93 | G16: =IF(OR(F16="",F16=0),"",D16/F16) -> 0.35483871 | H16: =IF(OR(F16="",F16=0),"",E16/F16) -> 0.64516129 | I16: random forest (results only) | J16: 2.7365176 | K16: =$K$8 -> 1.8111985 | L16: =SQRT(J16^2+K16^2) -> 3.2816106 | M16: =IF(G16="","",MAX(0,G16-1.96*L16/100)) -> 0.29051914 | N16: =IF(G16="","",MIN(1,G16+1.96*L16/100)) -> 0.41915828 | O16: =ROUND(S16*W16,0) -> 7 | P16: =IF(F16="","",ROUND(SQRT((F16*L16/100)^2+(G16*O16)^2),0)) -> 4 | R16: -7.385864 | S16: =U16*V16*$F$5 -> 93.426829 | T16: =MAX(0,MIN(1,R16/100+$D$5)) -> 0.3494223 | U16: 0.57317073 | V16: 163 | W16: 0.077704034 | X16: Small | Y16: state rolls, whole municipality
A17: Carbon | B17: FRANKLIN TOWNSHIP | C17: (whole municipality) | D17: =ROUND(S17*T17,0) -> 569 | E17: =ROUND(S17,0)-D17 -> 1413 | F17: =IF(COUNTA(D17:E17)=0,"",SUM(D17:E17)) -> 1982 | G17: =IF(OR(F17="",F17=0),"",D17/F17) -> 0.28708375 | H17: =IF(OR(F17="",F17=0),"",E17/F17) -> 0.71291625 | I17: random forest (results only) | J17: 1.5602358 | K17: =$K$8 -> 1.8111985 | L17: =SQRT(J17^2+K17^2) -> 2.3905597 | M17: =IF(G17="","",MAX(0,G17-1.96*L17/100)) -> 0.24022878 | N17: =IF(G17="","",MIN(1,G17+1.96*L17/100)) -> 0.33393872 | O17: =ROUND(S17*W17,0) -> 120 | P17: =IF(F17="","",ROUND(SQRT((F17*L17/100)^2+(G17*O17)^2),0)) -> 59 | R17: -13.617478 | S17: =U17*V17*$F$5 -> 1982.009 | T17: =MAX(0,MIN(1,R17/100+$D$5)) -> 0.28710616 | U17: 0.63181672 | V17: 3137 | W17: 0.060612226 | X17: Medium | Y17: state rolls, whole municipality
A18: Carbon | B18: JIM THORPE BOROUGH | C18: (whole municipality) | D18: =ROUND(S18*T18,0) -> 914 | E18: =ROUND(S18,0)-D18 -> 1194 | F18: =IF(COUNTA(D18:E18)=0,"",SUM(D18:E18)) -> 2108 | G18: =IF(OR(F18="",F18=0),"",D18/F18) -> 0.43358634 | H18: =IF(OR(F18="",F18=0),"",E18/F18) -> 0.56641366 | I18: random forest (results only) | J18: 1.5602358 | K18: =$K$8 -> 1.8111985 | L18: =SQRT(J18^2+K18^2) -> 2.3905597 | M18: =IF(G18="","",MAX(0,G18-1.96*L18/100)) -> 0.38673137 | N18: =IF(G18="","",MIN(1,G18+1.96*L18/100)) -> 0.48044131 | O18: =ROUND(S18*W18,0) -> 128 | P18: =IF(F18="","",ROUND(SQRT((F18*L18/100)^2+(G18*O18)^2),0)) -> 75 | R18: 1.0586972 | S18: =U18*V18*$F$5 -> 2107.7256 | T18: =MAX(0,MIN(1,R18/100+$D$5)) -> 0.43386791 | U18: 0.64259928 | V18: 3280 | W18: 0.060612226 | X18: Medium | Y18: state rolls, whole municipality
A19: Carbon | B19: KIDDER TOWNSHIP | C19: (whole municipality) | D19: =ROUND(S19*T19,0) -> 279 | E19: =ROUND(S19,0)-D19 -> 526 | F19: =IF(COUNTA(D19:E19)=0,"",SUM(D19:E19)) -> 805 | G19: =IF(OR(F19="",F19=0),"",D19/F19) -> 0.34658385 | H19: =IF(OR(F19="",F19=0),"",E19/F19) -> 0.65341615 | I19: random forest (results only) | J19: 2.7365176 | K19: =$K$8 -> 1.8111985 | L19: =SQRT(J19^2+K19^2) -> 3.2816106 | M19: =IF(G19="","",MAX(0,G19-1.96*L19/100)) -> 0.28226428 | N19: =IF(G19="","",MIN(1,G19+1.96*L19/100)) -> 0.41090342 | O19: =ROUND(S19*W19,0) -> 63 | P19: =IF(F19="","",ROUND(SQRT((F19*L19/100)^2+(G19*O19)^2),0)) -> 34 | R19: -7.6888263 | S19: =U19*V19*$F$5 -> 804.85033 | T19: =MAX(0,MIN(1,R19/100+$D$5)) -> 0.34639268 | U19: 0.55430464 | V19: 1452 | W19: 0.077704034 | X19: Small | Y19: state rolls, whole municipality
A20: Carbon | B20: LANSFORD BOROUGH | C20: (whole municipality) | D20: =ROUND(S20*T20,0) -> 447 | E20: =ROUND(S20,0)-D20 -> 636 | F20: =IF(COUNTA(D20:E20)=0,"",SUM(D20:E20)) -> 1083 | G20: =IF(OR(F20="",F20=0),"",D20/F20) -> 0.41274238 | H20: =IF(OR(F20="",F20=0),"",E20/F20) -> 0.58725762 | I20: random forest (results only) | J20: 2.7365176 | K20: =$K$8 -> 1.8111985 | L20: =SQRT(J20^2+K20^2) -> 3.2816106 | M20: =IF(G20="","",MAX(0,G20-1.96*L20/100)) -> 0.34842281 | N20: =IF(G20="","",MIN(1,G20+1.96*L20/100)) -> 0.47706195 | O20: =ROUND(S20*W20,0) -> 84 | P20: =IF(F20="","",ROUND(SQRT((F20*L20/100)^2+(G20*O20)^2),0)) -> 50 | R20: -1.0822711 | S20: =U20*V20*$F$5 -> 1083.4829 | T20: =MAX(0,MIN(1,R20/100+$D$5)) -> 0.41245823 | U20: 0.44883303 | V20: 2414 | W20: 0.077704034 | X20: Small | Y20: state rolls, whole municipality
A21: Carbon | B21: LAUSANNE TOWNSHIP | C21: (whole municipality) | D21: =ROUND(S21*T21,0) -> 33 | E21: =ROUND(S21,0)-D21 -> 85 | F21: =IF(COUNTA(D21:E21)=0,"",SUM(D21:E21)) -> 118 | G21: =IF(OR(F21="",F21=0),"",D21/F21) -> 0.27966102 | H21: =IF(OR(F21="",F21=0),"",E21/F21) -> 0.72033898 | I21: random forest (results only) | J21: 2.7365176 | K21: =$K$8 -> 1.8111985 | L21: =SQRT(J21^2+K21^2) -> 3.2816106 | M21: =IF(G21="","",MAX(0,G21-1.96*L21/100)) -> 0.21534145 | N21: =IF(G21="","",MIN(1,G21+1.96*L21/100)) -> 0.34398059 | O21: =ROUND(S21*W21,0) -> 9 | P21: =IF(F21="","",ROUND(SQRT((F21*L21/100)^2+(G21*O21)^2),0)) -> 5 | R21: -14.646485 | S21: =U21*V21*$F$5 -> 118.28571 | T21: =MAX(0,MIN(1,R21/100+$D$5)) -> 0.27681609 | U21: 0.65714286 | V21: 180 | W21: 0.077704034 | X21: Small | Y21: state rolls, whole municipality
A22: Carbon | B22: LEHIGH TOWNSHIP | C22: (whole municipality) | D22: =ROUND(S22*T22,0) -> 51 | E22: =ROUND(S22,0)-D22 -> 186 | F22: =IF(COUNTA(D22:E22)=0,"",SUM(D22:E22)) -> 237 | G22: =IF(OR(F22="",F22=0),"",D22/F22) -> 0.21518987 | H22: =IF(OR(F22="",F22=0),"",E22/F22) -> 0.78481013 | I22: random forest (results only) | J22: 2.7365176 | K22: =$K$8 -> 1.8111985 | L22: =SQRT(J22^2+K22^2) -> 3.2816106 | M22: =IF(G22="","",MAX(0,G22-1.96*L22/100)) -> 0.1508703 | N22: =IF(G22="","",MIN(1,G22+1.96*L22/100)) -> 0.27950944 | O22: =ROUND(S22*W22,0) -> 18 | P22: =IF(F22="","",ROUND(SQRT((F22*L22/100)^2+(G22*O22)^2),0)) -> 9 | R22: -20.856066 | S22: =U22*V22*$F$5 -> 236.84483 | T22: =MAX(0,MIN(1,R22/100+$D$5)) -> 0.21472028 | U22: 0.69252874 | V22: 342 | W22: 0.077704034 | X22: Small | Y22: state rolls, whole municipality
A23: Carbon | B23: LEHIGHTON BOROUGH | C23: (whole municipality) | D23: =ROUND(S23*T23,0) -> 705 | E23: =ROUND(S23,0)-D23 -> 1049 | F23: =IF(COUNTA(D23:E23)=0,"",SUM(D23:E23)) -> 1754 | G23: =IF(OR(F23="",F23=0),"",D23/F23) -> 0.40193843 | H23: =IF(OR(F23="",F23=0),"",E23/F23) -> 0.59806157 | I23: random forest (results only) | J23: 1.5602358 | K23: =$K$8 -> 1.8111985 | L23: =SQRT(J23^2+K23^2) -> 2.3905597 | M23: =IF(G23="","",MAX(0,G23-1.96*L23/100)) -> 0.35508346 | N23: =IF(G23="","",MIN(1,G23+1.96*L23/100)) -> 0.4487934 | O23: =ROUND(S23*W23,0) -> 106 | P23: =IF(F23="","",ROUND(SQRT((F23*L23/100)^2+(G23*O23)^2),0)) -> 60 | R23: -2.1542874 | S23: =U23*V23*$F$5 -> 1753.7408 | T23: =MAX(0,MIN(1,R23/100+$D$5)) -> 0.40173807 | U23: 0.52570167 | V23: 3336 | W23: 0.060612226 | X23: Medium | Y23: state rolls, whole municipality
... A100: Northampton | B100: WIND GAP | C100: (whole municipality) | D100: =ROUND(S100*T100,0) -> 496 | E100: =ROUND(S100,0)-D100 -> 649 | F100: =IF(COUNTA(D100:E100)=0,"",SUM(D100:E100)) -> 1145 | G100: =IF(OR(F100="",F100=0),"",D100/F100) -> 0.43318777 | H100: =IF(OR(F100="",F100=0),"",E100/F100) -> 0.56681223 | I100: random forest (results only) | J100: 2.7365176 | K100: =$K$8 -> 1.8111985 | L100: =SQRT(J100^2+K100^2) -> 3.2816106 | M100: =IF(G100="","",MAX(0,G100-1.96*L100/100)) -> 0.3688682 | N100: =IF(G100="","",MIN(1,G100+1.96*L100/100)) -> 0.49750734 | O100: =ROUND(S100*W100,0) -> 89 | P100: =IF(F100="","",ROUND(SQRT((F100*L100/100)^2+(G100*O100)^2),0)) -> 54 | R100: 0.99286003 | S100: =U100*V100*$F$5 -> 1145.4806 | T100: =MAX(0,MIN(1,R100/100+$D$5)) -> 0.43320954 | U100: 0.53702795 | V100: 2133 | W100: 0.077704034 | X100: Small | Y100: state rolls, whole municipality

Sheet 2026 Forecast C
A1: PA-07 2026 House Forecast — Municipal-Level Predictions (Forecast C: shap family-reweighted forest)
A2: Candidates: Brooks | Mackenzie | District totals (yellow) are formulas over the municipality rows.
A3: Only the results are modelled (one random forest). Votes cast in each row = its 2022 turnout rate (House votes ÷ registered voters) × its 2026 registered voters. Brooks votes = votes cast × forecast Brooks share. Error terms combine the place’s own pattern error (2022 and 2024 backtests), the district-wide error and turnout error (all four backtest years).
A4: Model / scenario | B4: Random forest on results — Forecast C (SHAP family-reweighted forest), municipality model; turnout = 2022 turnout rate × 2026 registered voters | C4: As-of date | D4: 46300 | E4: Prepared by | F4: Max | G4: Version | H4: v7.0 (current map; backtests every year; results only)
A5: District Brooks share (scenario) | B5: ='Scenario & Comparison'!$C$6 -> 0.49515845 | C5: Uniform shift applied | D5: =B5-SUMPRODUCT(R12:R100,S12:S100)/SUM(S12:S100)/100 -> 0.41754778 | E5: Turnout multiplier (1.00 = 2022 turnout) | F5: ='Scenario & Comparison'!$C$7 -> 1
A6: DISTRICT TOTALS (auto-sum — do not type over)
A7: Geography | B7: (muni) | C7: (area) | D7: Brooks votes | E7: Mackenzie votes | F7: Total votes | G7: Brooks share | H7: Mackenzie share | I7: Notes | J7: Error term: place pattern (± pts) | K7: Error term: district-wide (± pts) | L7: Error term: total (± pts) | M7: Brooks share, 95% low | N7: Brooks share, 95% high | O7: Error term: votes cast (± votes) | P7: Error term: Brooks votes (± votes)
A8: PA-07 District | B8: (all municipalities) | D8: =SUM(D12:D100) -> 151580 | E8: =SUM(E12:E100) -> 154549 | F8: =D8+E8 -> 306129 | G8: =IF(F8=0,"",D8/F8) -> 0.49515074 | H8: =IF(F8=0,"",E8/F8) -> 0.50484926 | I8: Headline forecast for the briefing | J8: 0 | K8: 1.8111201 | L8: =SQRT(J8^2+K8^2) -> 1.8111201 | M8: =G8-1.96*L8/100 -> 0.45965278 | N8: =G8+1.96*L8/100 -> 0.53064869 | O8: =ROUND(F8*0.04363,0) -> 13356 | P8: =ROUND(SQRT((F8*L8/100)^2+(G8*O8)^2),0) -> 8630
A9: Error terms are ±1 standard error: place pattern error by place size (2022 and 2024 forward backtests) plus district-wide and turnout error (all four backtest years, 2018–2024). 95% low/high = Brooks share ± 1.96 × total error term.
A10: MUNICIPALITY DETAIL | R10: MODEL INPUTS (from the random forest — do not edit)
A11: County | B11: Municipality | C11: Area | D11: Brooks votes | E11: Mackenzie votes | F11: Total votes | G11: Brooks share | H11: Mackenzie share | I11: Notes / source method | J11: Error term: place pattern (± pts) | K11: Error term: district-wide (± pts) | L11: Error term: total (± pts) | M11: Brooks share, 95% low | N11: Brooks share, 95% high | O11: Error term: votes cast (± votes) | P11: Error term: Brooks votes (± votes) | R11: Model lean vs district (pts) | S11: Votes cast = 2022 turnout × 2026 registered | T11: Forecast Brooks share (unrounded) | U11: 2022 turnout (House votes ÷ registered) | V11: 2026 registered voters | W11: Votes-cast error (% of votes) | X11: Size group (backtest error band) | Y11: Registration source
A12: Carbon | B12: BANKS TOWNSHIP | C12: (whole municipality) | D12: =ROUND(S12*T12,0) -> 137 | E12: =ROUND(S12,0)-D12 -> 227 | F12: =IF(COUNTA(D12:E12)=0,"",SUM(D12:E12)) -> 364 | G12: =IF(OR(F12="",F12=0),"",D12/F12) -> 0.37637363 | H12: =IF(OR(F12="",F12=0),"",E12/F12) -> 0.62362637 | I12: random forest (results only) | J12: 3.0127184 | K12: =$K$8 -> 1.8111201 | L12: =SQRT(J12^2+K12^2) -> 3.5151996 | M12: =IF(G12="","",MAX(0,G12-1.96*L12/100)) -> 0.30747571 | N12: =IF(G12="","",MIN(1,G12+1.96*L12/100)) -> 0.44527154 | O12: =ROUND(S12*W12,0) -> 28 | P12: =IF(F12="","",ROUND(SQRT((F12*L12/100)^2+(G12*O12)^2),0)) -> 17 | R12: -4.2602135 | S12: =U12*V12*$F$5 -> 364.49096 | T12: =MAX(0,MIN(1,R12/100+$D$5)) -> 0.37494565 | U12: 0.5813253 | V12: 627 | W12: 0.077704034 | X12: Small | Y12: state rolls, whole municipality
A13: Carbon | B13: BEAVER MEADOWS BOROUGH | C13: (whole municipality) | D13: =ROUND(S13*T13,0) -> 93 | E13: =ROUND(S13,0)-D13 -> 237 | F13: =IF(COUNTA(D13:E13)=0,"",SUM(D13:E13)) -> 330 | G13: =IF(OR(F13="",F13=0),"",D13/F13) -> 0.28181818 | H13: =IF(OR(F13="",F13=0),"",E13/F13) -> 0.71818182 | I13: random forest (results only) | J13: 3.0127184 | K13: =$K$8 -> 1.8111201 | L13: =SQRT(J13^2+K13^2) -> 3.5151996 | M13: =IF(G13="","",MAX(0,G13-1.96*L13/100)) -> 0.21292027 | N13: =IF(G13="","",MIN(1,G13+1.96*L13/100)) -> 0.35071609 | O13: =ROUND(S13*W13,0) -> 26 | P13: =IF(F13="","",ROUND(SQRT((F13*L13/100)^2+(G13*O13)^2),0)) -> 14 | R13: -13.46444 | S13: =U13*V13*$F$5 -> 330.13014 | T13: =MAX(0,MIN(1,R13/100+$D$5)) -> 0.28290338 | U13: 0.53767123 | V13: 614 | W13: 0.077704034 | X13: Small | Y13: state rolls, whole municipality
A14: Carbon | B14: BOWMANSTOWN BOROUGH | C14: (whole municipality) | D14: =ROUND(S14*T14,0) -> 115 | E14: =ROUND(S14,0)-D14 -> 241 | F14: =IF(COUNTA(D14:E14)=0,"",SUM(D14:E14)) -> 356 | G14: =IF(OR(F14="",F14=0),"",D14/F14) -> 0.32303371 | H14: =IF(OR(F14="",F14=0),"",E14/F14) -> 0.67696629 | I14: random forest (results only) | J14: 3.0127184 | K14: =$K$8 -> 1.8111201 | L14: =SQRT(J14^2+K14^2) -> 3.5151996 | M14: =IF(G14="","",MAX(0,G14-1.96*L14/100)) -> 0.2541358 | N14: =IF(G14="","",MIN(1,G14+1.96*L14/100)) -> 0.39193162 | O14: =ROUND(S14*W14,0) -> 28 | P14: =IF(F14="","",ROUND(SQRT((F14*L14/100)^2+(G14*O14)^2),0)) -> 15 | R14: -9.4259223 | S14: =U14*V14*$F$5 -> 355.63437 | T14: =MAX(0,MIN(1,R14/100+$D$5)) -> 0.32328856 | U14: 0.63619744 | V14: 559 | W14: 0.077704034 | X14: Small | Y14: state rolls, whole municipality
A15: Carbon | B15: EAST PENN TOWNSHIP | C15: (whole municipality) | D15: =ROUND(S15*T15,0) -> 355 | E15: =ROUND(S15,0)-D15 -> 980 | F15: =IF(COUNTA(D15:E15)=0,"",SUM(D15:E15)) -> 1335 | G15: =IF(OR(F15="",F15=0),"",D15/F15) -> 0.2659176 | H15: =IF(OR(F15="",F15=0),"",E15/F15) -> 0.7340824 | I15: random forest (results only) | J15: 1.9715334 | K15: =$K$8 -> 1.8111201 | L15: =SQRT(J15^2+K15^2) -> 2.677144 | M15: =IF(G15="","",MAX(0,G15-1.96*L15/100)) -> 0.21344558 | N15: =IF(G15="","",MIN(1,G15+1.96*L15/100)) -> 0.31838963 | O15: =ROUND(S15*W15,0) -> 81 | P15: =IF(F15="","",ROUND(SQRT((F15*L15/100)^2+(G15*O15)^2),0)) -> 42 | R15: -15.185649 | S15: =U15*V15*$F$5 -> 1334.821 | T15: =MAX(0,MIN(1,R15/100+$D$5)) -> 0.26569129 | U15: 0.65208648 | V15: 2047 | W15: 0.060612226 | X15: Medium | Y15: state rolls, whole municipality
A16: Carbon | B16: EAST SIDE BOROUGH | C16: (whole municipality) | D16: =ROUND(S16*T16,0) -> 32 | E16: =ROUND(S16,0)-D16 -> 61 | F16: =IF(COUNTA(D16:E16)=0,"",SUM(D16:E16)) -> 93 | G16: =IF(OR(F16="",F16=0),"",D16/F16) -> 0.34408602 | H16: =IF(OR(F16="",F16=0),"",E16/F16) -> 0.65591398 | I16: random forest (results only) | J16: 3.0127184 | K16: =$K$8 -> 1.8111201 | L16: =SQRT(J16^2+K16^2) -> 3.5151996 | M16: =IF(G16="","",MAX(0,G16-1.96*L16/100)) -> 0.27518811 | N16: =IF(G16="","",MIN(1,G16+1.96*L16/100)) -> 0.41298393 | O16: =ROUND(S16*W16,0) -> 7 | P16: =IF(F16="","",ROUND(SQRT((F16*L16/100)^2+(G16*O16)^2),0)) -> 4 | R16: -7.6615795 | S16: =U16*V16*$F$5 -> 93.426829 | T16: =MAX(0,MIN(1,R16/100+$D$5)) -> 0.34093199 | U16: 0.57317073 | V16: 163 | W16: 0.077704034 | X16: Small | Y16: state rolls, whole municipality
A17: Carbon | B17: FRANKLIN TOWNSHIP | C17: (whole municipality) | D17: =ROUND(S17*T17,0) -> 548 | E17: =ROUND(S17,0)-D17 -> 1434 | F17: =IF(COUNTA(D17:E17)=0,"",SUM(D17:E17)) -> 1982 | G17: =IF(OR(F17="",F17=0),"",D17/F17) -> 0.2764884 | H17: =IF(OR(F17="",F17=0),"",E17/F17) -> 0.7235116 | I17: random forest (results only) | J17: 1.9715334 | K17: =$K$8 -> 1.8111201 | L17: =SQRT(J17^2+K17^2) -> 2.677144 | M17: =IF(G17="","",MAX(0,G17-1.96*L17/100)) -> 0.22401637 | N17: =IF(G17="","",MIN(1,G17+1.96*L17/100)) -> 0.32896042 | O17: =ROUND(S17*W17,0) -> 120 | P17: =IF(F17="","",ROUND(SQRT((F17*L17/100)^2+(G17*O17)^2),0)) -> 63 | R17: -14.113851 | S17: =U17*V17*$F$5 -> 1982.009 | T17: =MAX(0,MIN(1,R17/100+$D$5)) -> 0.27640927 | U17: 0.63181672 | V17: 3137 | W17: 0.060612226 | X17: Medium | Y17: state rolls, whole municipality
A18: Carbon | B18: JIM THORPE BOROUGH | C18: (whole municipality) | D18: =ROUND(S18*T18,0) -> 912 | E18: =ROUND(S18,0)-D18 -> 1196 | F18: =IF(COUNTA(D18:E18)=0,"",SUM(D18:E18)) -> 2108 | G18: =IF(OR(F18="",F18=0),"",D18/F18) -> 0.43263757 | H18: =IF(OR(F18="",F18=0),"",E18/F18) -> 0.56736243 | I18: random forest (results only) | J18: 1.9715334 | K18: =$K$8 -> 1.8111201 | L18: =SQRT(J18^2+K18^2) -> 2.677144 | M18: =IF(G18="","",MAX(0,G18-1.96*L18/100)) -> 0.38016555 | N18: =IF(G18="","",MIN(1,G18+1.96*L18/100)) -> 0.48510959 | O18: =ROUND(S18*W18,0) -> 128 | P18: =IF(F18="","",ROUND(SQRT((F18*L18/100)^2+(G18*O18)^2),0)) -> 79 | R18: 1.5201508 | S18: =U18*V18*$F$5 -> 2107.7256 | T18: =MAX(0,MIN(1,R18/100+$D$5)) -> 0.43274929 | U18: 0.64259928 | V18: 3280 | W18: 0.060612226 | X18: Medium | Y18: state rolls, whole municipality
A19: Carbon | B19: KIDDER TOWNSHIP | C19: (whole municipality) | D19: =ROUND(S19*T19,0) -> 267 | E19: =ROUND(S19,0)-D19 -> 538 | F19: =IF(COUNTA(D19:E19)=0,"",SUM(D19:E19)) -> 805 | G19: =IF(OR(F19="",F19=0),"",D19/F19) -> 0.33167702 | H19: =IF(OR(F19="",F19=0),"",E19/F19) -> 0.66832298 | I19: random forest (results only) | J19: 3.0127184 | K19: =$K$8 -> 1.8111201 | L19: =SQRT(J19^2+K19^2) -> 3.5151996 | M19: =IF(G19="","",MAX(0,G19-1.96*L19/100)) -> 0.26277911 | N19: =IF(G19="","",MIN(1,G19+1.96*L19/100)) -> 0.40057493 | O19: =ROUND(S19*W19,0) -> 63 | P19: =IF(F19="","",ROUND(SQRT((F19*L19/100)^2+(G19*O19)^2),0)) -> 35 | R19: -8.5352194 | S19: =U19*V19*$F$5 -> 804.85033 | T19: =MAX(0,MIN(1,R19/100+$D$5)) -> 0.33219559 | U19: 0.55430464 | V19: 1452 | W19: 0.077704034 | X19: Small | Y19: state rolls, whole municipality
A20: Carbon | B20: LANSFORD BOROUGH | C20: (whole municipality) | D20: =ROUND(S20*T20,0) -> 446 | E20: =ROUND(S20,0)-D20 -> 637 | F20: =IF(COUNTA(D20:E20)=0,"",SUM(D20:E20)) -> 1083 | G20: =IF(OR(F20="",F20=0),"",D20/F20) -> 0.41181902 | H20: =IF(OR(F20="",F20=0),"",E20/F20) -> 0.58818098 | I20: random forest (results only) | J20: 3.0127184 | K20: =$K$8 -> 1.8111201 | L20: =SQRT(J20^2+K20^2) -> 3.5151996 | M20: =IF(G20="","",MAX(0,G20-1.96*L20/100)) -> 0.34292111 | N20: =IF(G20="","",MIN(1,G20+1.96*L20/100)) -> 0.48071693 | O20: =ROUND(S20*W20,0) -> 84 | P20: =IF(F20="","",ROUND(SQRT((F20*L20/100)^2+(G20*O20)^2),0)) -> 51 | R20: -0.6248827 | S20: =U20*V20*$F$5 -> 1083.4829 | T20: =MAX(0,MIN(1,R20/100+$D$5)) -> 0.41129896 | U20: 0.44883303 | V20: 2414 | W20: 0.077704034 | X20: Small | Y20: state rolls, whole municipality
A21: Carbon | B21: LAUSANNE TOWNSHIP | C21: (whole municipality) | D21: =ROUND(S21*T21,0) -> 31 | E21: =ROUND(S21,0)-D21 -> 87 | F21: =IF(COUNTA(D21:E21)=0,"",SUM(D21:E21)) -> 118 | G21: =IF(OR(F21="",F21=0),"",D21/F21) -> 0.26271186 | H21: =IF(OR(F21="",F21=0),"",E21/F21) -> 0.73728814 | I21: random forest (results only) | J21: 3.0127184 | K21: =$K$8 -> 1.8111201 | L21: =SQRT(J21^2+K21^2) -> 3.5151996 | M21: =IF(G21="","",MAX(0,G21-1.96*L21/100)) -> 0.19381395 | N21: =IF(G21="","",MIN(1,G21+1.96*L21/100)) -> 0.33160978 | O21: =ROUND(S21*W21,0) -> 9 | P21: =IF(F21="","",ROUND(SQRT((F21*L21/100)^2+(G21*O21)^2),0)) -> 5 | R21: -15.425189 | S21: =U21*V21*$F$5 -> 118.28571 | T21: =MAX(0,MIN(1,R21/100+$D$5)) -> 0.26329589 | U21: 0.65714286 | V21: 180 | W21: 0.077704034 | X21: Small | Y21: state rolls, whole municipality
A22: Carbon | B22: LEHIGH TOWNSHIP | C22: (whole municipality) | D22: =ROUND(S22*T22,0) -> 45 | E22: =ROUND(S22,0)-D22 -> 192 | F22: =IF(COUNTA(D22:E22)=0,"",SUM(D22:E22)) -> 237 | G22: =IF(OR(F22="",F22=0),"",D22/F22) -> 0.18987342 | H22: =IF(OR(F22="",F22=0),"",E22/F22) -> 0.81012658 | I22: random forest (results only) | J22: 3.0127184 | K22: =$K$8 -> 1.8111201 | L22: =SQRT(J22^2+K22^2) -> 3.5151996 | M22: =IF(G22="","",MAX(0,G22-1.96*L22/100)) -> 0.12097551 | N22: =IF(G22="","",MIN(1,G22+1.96*L22/100)) -> 0.25877133 | O22: =ROUND(S22*W22,0) -> 18 | P22: =IF(F22="","",ROUND(SQRT((F22*L22/100)^2+(G22*O22)^2),0)) -> 9 | R22: -22.786794 | S22: =U22*V22*$F$5 -> 236.84483 | T22: =MAX(0,MIN(1,R22/100+$D$5)) -> 0.18967985 | U22: 0.69252874 | V22: 342 | W22: 0.077704034 | X22: Small | Y22: state rolls, whole municipality
A23: Carbon | B23: LEHIGHTON BOROUGH | C23: (whole municipality) | D23: =ROUND(S23*T23,0) -> 696 | E23: =ROUND(S23,0)-D23 -> 1058 | F23: =IF(COUNTA(D23:E23)=0,"",SUM(D23:E23)) -> 1754 | G23: =IF(OR(F23="",F23=0),"",D23/F23) -> 0.3968073 | H23: =IF(OR(F23="",F23=0),"",E23/F23) -> 0.6031927 | I23: random forest (results only) | J23: 1.9715334 | K23: =$K$8 -> 1.8111201 | L23: =SQRT(J23^2+K23^2) -> 2.677144 | M23: =IF(G23="","",MAX(0,G23-1.96*L23/100)) -> 0.34433527 | N23: =IF(G23="","",MIN(1,G23+1.96*L23/100)) -> 0.44927932 | O23: =ROUND(S23*W23,0) -> 106 | P23: =IF(F23="","",ROUND(SQRT((F23*L23/100)^2+(G23*O23)^2),0)) -> 63 | R23: -2.0664432 | S23: =U23*V23*$F$5 -> 1753.7408 | T23: =MAX(0,MIN(1,R23/100+$D$5)) -> 0.39688335 | U23: 0.52570167 | V23: 3336 | W23: 0.060612226 | X23: Medium | Y23: state rolls, whole municipality
... A100: Northampton | B100: WIND GAP | C100: (whole municipality) | D100: =ROUND(S100*T100,0) -> 490 | E100: =ROUND(S100,0)-D100 -> 655 | F100: =IF(COUNTA(D100:E100)=0,"",SUM(D100:E100)) -> 1145 | G100: =IF(OR(F100="",F100=0),"",D100/F100) -> 0.4279476 | H100: =IF(OR(F100="",F100=0),"",E100/F100) -> 0.5720524 | I100: random forest (results only) | J100: 3.0127184 | K100: =$K$8 -> 1.8111201 | L100: =SQRT(J100^2+K100^2) -> 3.5151996 | M100: =IF(G100="","",MAX(0,G100-1.96*L100/100)) -> 0.35904969 | N100: =IF(G100="","",MIN(1,G100+1.96*L100/100)) -> 0.49684551 | O100: =ROUND(S100*W100,0) -> 89 | P100: =IF(F100="","",ROUND(SQRT((F100*L100/100)^2+(G100*O100)^2),0)) -> 55 | R100: 1.0260455 | S100: =U100*V100*$F$5 -> 1145.4806 | T100: =MAX(0,MIN(1,R100/100+$D$5)) -> 0.42780824 | U100: 0.53702795 | V100: 2133 | W100: 0.077704034 | X100: Small | Y100: state rolls, whole municipality

Sheet How Forecasts Are Weighted
A1: How the three municipality-level forecasts weigh their inputs (SHAP) — results-only random forests
A3: Forecast A — Full random forest.
A4: All 21 candidate inputs go into one random forest that forecasts the Democratic share. Nothing is weighted by hand; SHAP measures what the forest learned. This is the reference.
A5: Forecast B — SHAP-selected forest.
A6: Keeps only inputs whose average |SHAP| beat all 10 random columns in at least 18 of 20 refits and that held at least 2% of Forecast A’s SHAP total (7 of 21 kept), then refits the forest on them. Weight that was spread thinly over weak inputs is concentrated on the strong ones.
A7: Forecast C — SHAP family-reweighted forest.
A8: Keeps Forecast A’s forest but multiplies each input family’s SHAP values by a weight fitted to how well that family predicted elections the forest had not seen (leave-one-election-out, fitted within each election). Families under 3% of SHAP stay at ×1; others are limited to ×0.5–×2 because there are only three training elections.
A9: Backtests.
A10: Each 2024 backtest uses its own forecast’s weighting: A’s full input set, B’s selected inputs, and C’s exact family weights — refit only on 2020 and 2022.
A11: Turnout.
A12: Not modelled in any forecast: votes cast = each place’s 2022 turnout rate × its 2026 registered voters (2020 turnout × 2024 registered in the backtest). All differences between A, B and C come from the results model.
A14: Family share of SHAP value in votes, 2026 forecast rows
A15: Input family | B15: Forecast A | C15: Forecast B | D15: Forecast C | E15: Forecast C weight (×)
A16: Election type | B16: 0.00035844758 | C16: 0 | D16: 0.00033659122 | E16: 1
A17: Historical voter data | B17: 0.77381703 | C17: 0.79909614 | D17: 0.73791335 | E17: 1.0155235
A18: Voter registration data | B18: 0.22582452 | C18: 0.20090386 | D18: 0.26175006 | E18: 1.2343507
A19: Out-of-fold pattern error before → after Forecast C’s re-weighting: 2.37 → 2.29 points.
A21: Top inputs in each forecast (share of SHAP value in votes)
A22: # | B22: Forecast A | C22: Share | D22: Forecast B | E22: Share | F22: Forecast C | G22: Share
A23: 1 | B23: Senate lean, most recent Senate race | C23: 0.25088292 | D23: House lean, last election (t−2) | E23: 0.23881369 | F23: Senate lean, most recent Senate race | G23: 0.23924242
A24: 2 | B24: Top-of-ticket lean, last election (t−2) | C24: 0.20432698 | D24: Senate lean, most recent Senate race | E24: 0.23808094 | F24: Top-of-ticket lean, last election (t−2) | G24: 0.19484659
A25: 3 | B25: House lean, last election (t−2) | C25: 0.2037115 | D25: Top-of-ticket lean, last election (t−2) | E25: 0.22698158 | F25: House lean, last election (t−2) | G25: 0.19425966
A26: 4 | B26: Registration: R % (voter file) | C26: 0.10172285 | D26: Registration: R % (voter file) | E26: 0.12977916 | F26: Registration: R % (voter file) | G26: 0.11790554
A27: 5 | B27: Electorate last election: R % of ballots | C27: 0.075861851 | D27: Electorate last election: R % of ballots | E27: 0.078313179 | F27: Registration: D % (voter file) | G27: 0.087154749
A28: 6 | B28: Registration: D % (voter file) | C28: 0.075192647 | D28: Registration: D % (voter file) | E28: 0.071124699 | F28: Electorate last election: R % of ballots | G28: 0.072342001
A29: 7 | B29: House lean, last same-type election (t−4) | C29: 0.023816276 | D29: House lean, last same-type election (t−4) | E29: 0.01690674 | F29: House lean, last same-type election (t−4) | G29: 0.022711245
A30: 8 | B30: Registered voters (log) | C30: 0.018749702 | F30: Registered voters (log) | G30: 0.021732518
A31: 9 | B31: Registrants: female % (known sex) | C31: 0.010591794 | F31: Registrants: female % (known sex) | G31: 0.012276801
A32: 10 | B32: Registration: unaffiliated/other % | C32: 0.0092191778 | F32: Registration: unaffiliated/other % | G32: 0.01068582
A34: Forecast B — random-column test and selection
A35: Input | B35: Beat random columns (of 20) | C35: Share of SHAP in A | D35: Kept in B?
A36: Senate lean, most recent Senate race | B36: 20 | C36: 0.25063729 | D36: Yes
A37: Top-of-ticket lean, last election (t−2) | B37: 20 | C37: 0.20542462 | D37: Yes
A38: House lean, last election (t−2) | B38: 20 | C38: 0.20290498 | D38: Yes
A39: Registration: R % (voter file) | B39: 20 | C39: 0.098854348 | D39: Yes
A40: Registration: D % (voter file) | B40: 20 | C40: 0.071382716 | D40: Yes
A41: Electorate last election: R % of ballots | B41: 20 | C41: 0.068913111 | D41: Yes
A42: House lean, last same-type election (t−4) | B42: 20 | C42: 0.025784594 | D42: Yes
A43: Registered voters (log) | B43: 19 | C43: 0.015549281 | D43: No
A44: Registrants: female % (known sex) | B44: 17 | C44: 0.013926905 | D44: No
...

Sheet Feature Ranking A
A1: Rank | B1: Feature | C1: Input family | D1: Share of model | E1: Share within its family | F1: SHAP value in votes | G1: Used to forecast | H1: Significance test result | I1: Variable (short name) | J1: Status in Forecast B
A2: 1 | B2: Democratic percent of the two-party U.S. Senate vote, 2024 (most recent Senate race), above or below the district average | C2: Historical voter data | D2: 0.25088292 | E2: 0.32421479 | F2: 199.83114 | G2: Democratic percent of the two-party vote | H2: Beat all 10 random comparison columns in 20 of 20 refits. | I2: Senate lean, most recent Senate race | J2: Kept in B
A3: 2 | B3: Democratic percent of the two-party vote for President, 2024 (the top race on the ballot), above or below the district average | C3: Historical voter data | D3: 0.20432698 | E3: 0.26405077 | F3: 162.7488 | G3: Democratic percent of the two-party vote | H3: Beat all 10 random comparison columns in 20 of 20 refits. | I3: Top-of-ticket lean, last election (t−2) | J3: Kept in B
A4: 3 | B4: Democratic percent of the two-party House vote, 2024 (certified municipal results), above or below the district average for that election | C4: Historical voter data | D4: 0.2037115 | E4: 0.26325538 | F4: 162.25856 | G4: Democratic percent of the two-party vote | H4: Beat all 10 random comparison columns in 20 of 20 refits. | I4: House lean, last election (t−2) | J4: Kept in B
A5: 4 | B5: Registered Republicans as a percent of all registered voters, 2026 (voter file) | C5: Voter registration data | D5: 0.10172285 | E5: 0.45045087 | F5: 81.023426 | G5: Democratic percent of the two-party vote | H5: Beat all 10 random comparison columns in 20 of 20 refits. | I5: Registration: R % (voter file) | J5: Kept in B
A6: 5 | B6: Registered Republicans as a percent of everyone who voted, 2024 (voter file) | C6: Historical voter data | D6: 0.075861851 | E6: 0.098035902 | F6: 60.42484 | G6: Democratic percent of the two-party vote | H6: Beat all 10 random comparison columns in 20 of 20 refits. | I6: Electorate last election: R % of ballots | J6: Kept in B
A7: 6 | B7: Registered Democrats as a percent of all registered voters, 2026 (voter file) | C7: Voter registration data | D7: 0.075192647 | E7: 0.33296936 | F7: 59.891811 | G7: Democratic percent of the two-party vote | H7: Beat all 10 random comparison columns in 20 of 20 refits. | I7: Registration: D % (voter file) | J7: Kept in B
A8: 7 | B8: Democratic percent of the two-party House vote, 2022 — the last midterm (certified municipal results), above or below the district average | C8: Historical voter data | D8: 0.023816276 | E8: 0.030777658 | F8: 18.969939 | G8: Democratic percent of the two-party vote | H8: Beat all 10 random comparison columns in 20 of 20 refits. | I8: House lean, last same-type election (t−4) | J8: Kept in B
A9: 8 | B9: Number of registered voters, 2026, on a log scale (voter file) | C9: Voter registration data | D9: 0.018749702 | E9: 0.08302775 | F9: 14.934354 | G9: Democratic percent of the two-party vote | H9: Beat all 10 random comparison columns in 19 of 20 refits. | I9: Registered voters (log) | J9: Dropped from B
