Workbook

Sheet Scenario & Comparison
A1: PA-07 2026 House Forecast — Precinct Level: three results-only random-forest forecasts (fixed baseline)
A2: Candidates: Brooks | Mackenzie | The two yellow cells set the district-wide Brooks share and votes cast; all three forecasts update.
A3: A, B and C weight the same random-forest inputs differently using SHAP (see How Forecasts Are Weighted). Each is backtested on 2024 with its own weights; those errors are the error terms.
A5: SCENARIO INPUTS (defaults are built from the tables below; type over them to run another scenario)
A6: District-wide Brooks share of the two-party vote (input) | C6: =C21 -> 0.49830982 | D6: ← default: like-for-like baseline (row 21) — last midterm adjusted for the registration shift
A7: Turnout multiplier (input; 1.00 = each place keeps its 2022 turnout rate) | C7: 1 | D7: ← votes cast = 2022 turnout rate × 2026 registered voters × this multiplier (row 27)
A9: HOW THE DEFAULTS ARE BUILT (today’s map applied to every year — all municipalities and precincts, as if the district had always included them)
A10: Election | C10: Democratic share | D10: Democratic votes | E10: Republican votes | F10: Registered (state rolls) | G10: Dem share of two-party registration
A11: 2018 General | C11: =D11/(D11+E11) -> 0.53259004 | D11: 136790.36 | E11: 120049.52 | F11: 483877 | G11: 0.56798799
A12: 2020 General | C12: =D12/(D12+E12) -> 0.4960879 | D12: 188855.71 | E12: 191834.3 | F12: 518873 | G12: 0.55685758
A13: 2022 General | C13: =D13/(D13+E13) -> 0.50896572 | D13: 149243 | E13: 143985 | F13: 510119 | G13: 0.54766474
A14: 2024 General | C14: =D14/(D14+E14) -> 0.49424813 | D14: 196561 | E14: 201136 | F14: 535177 | G14: 0.52758258
A15: 2026 Primary rolls | F15: 517956 | G15: 0.52223425
A16: Source: certified precinct House returns and Department of State registration (PA07_Precinct_Data.xlsx). 2018/2020 count Carbon (then PA-09) and Polk (then PA-08) as district results and include an estimate for Ross One, so every year covers the same territory as 2026.
A18: Democratic share in the last election of the same type (2022 midterm) | C18: =C13 -> 0.50896572
A19: Change in Dem share of two-party registration since 2022 (pts) | C19: =(G15-G13)*100 -> -2.543049
A20: Registration-to-vote link (k), measured on precinct changes 2018→2022 and 2020→2024 | C20: 0.41902062 | D20: Within-district slope: precincts whose registration moved 1 pt toward a party moved about this many pts in vote share (national swing removed).
A21: Like-for-like baseline for 2026 = row 18 + k × row 19 | C21: =C18+C20*C19/100 -> 0.49830982
A22: For comparison — previous rule (average of 2022 and 2024 + k × change since then) | C22: =AVERAGE(C13,C14)+C20*(G15-AVERAGE(G13,G14)) -> 0.49515845
A23: 2022 turnout in today’s district (House votes ÷ registered voters) | C23: 0.56494828
A24: 2026 registered voters (state rolls, summed over precincts) | C24: 538584.71
A25: District check: 2022 turnout × 2026 registered | C25: =C23*C24 -> 304272.51
A26: Rule applied precinct by precinct (each place’s own 2022 turnout × its 2026 registered) and summed | C26: 306117.6 | D26: Each place uses its own 2022 turnout rate, so the summed total differs slightly from the district-level check. Registration: Department of State rolls (2026 primary).
A27: Votes cast used in the forecasts (row 26 × turnout multiplier) | C27: =C26*C7 -> 306117.6
A29: DISTRICT TOTALS BY FORECAST, WITH ERROR TERMS (live from each forecast tab)
A30: Forecast | B30: Weighting | C30: Brooks votes | D30: Mackenzie votes | E30: Total votes | F30: Brooks share | G30: Error term, share (± pts) | H30: Brooks share, 95% range | I30: Error term, votes cast (±) | J30: Error term, Brooks votes (±)
A31: Forecast A | B31: Full random forest | C31: ='2026 Forecast A'!D8 -> 152544 | D31: ='2026 Forecast A'!E8 -> 153569 | E31: ='2026 Forecast A'!F8 -> 306113 | F31: ='2026 Forecast A'!G8 -> 0.49832578 | G31: ='2026 Forecast A'!L8 -> 1.2188879 | H31: =TEXT('2026 Forecast A'!M8,"0.0%")&" – "&TEXT('2026 Forecast A'!N8,"0.0%") -> 47.4% – 52.2% | I31: ='2026 Forecast A'!O8 -> 13264 | J31: ='2026 Forecast A'!P8 -> 7590
A32: Forecast B | B32: SHAP-selected forest | C32: ='2026 Forecast B'!D8 -> 152546 | D32: ='2026 Forecast B'!E8 -> 153567 | E32: ='2026 Forecast B'!F8 -> 306113 | F32: ='2026 Forecast B'!G8 -> 0.49833232 | G32: ='2026 Forecast B'!L8 -> 1.2181759 | H32: =TEXT('2026 Forecast B'!M8,"0.0%")&" – "&TEXT('2026 Forecast B'!N8,"0.0%") -> 47.4% – 52.2% | I32: ='2026 Forecast B'!O8 -> 13264 | J32: ='2026 Forecast B'!P8 -> 7589
A33: Forecast C | B33: SHAP family-reweighted forest | C33: ='2026 Forecast C'!D8 -> 152545 | D33: ='2026 Forecast C'!E8 -> 153568 | E33: ='2026 Forecast C'!F8 -> 306113 | F33: ='2026 Forecast C'!G8 -> 0.49832905 | G33: ='2026 Forecast C'!L8 -> 1.2186289 | H33: =TEXT('2026 Forecast C'!M8,"0.0%")&" – "&TEXT('2026 Forecast C'!N8,"0.0%") -> 47.4% – 52.2% | I33: ='2026 Forecast C'!O8 -> 13264 | J33: ='2026 Forecast C'!P8 -> 7590
A34: District error terms = root-mean-square of the district-wide misses in all four backtests (2018, 2020, 2022, 2024). Place pattern error terms come from the 2022 and 2024 forward backtests, which use the same inputs as the 2026 forecast.
A36: BACKTESTS FOR EVERY YEAR, WITH ERROR TERMS (same weights as the forecasts; live from each backtest tab)
A37: Forecast | B37: Backtest | C37: District Dem share miss (pts) | D37: Dem votes miss | E37: Rep votes miss | F37: Votes cast miss | G37: Pattern RMS miss per row (pts) | H37: RMS miss per row (pts) | I37: Avg error term set beforehand (± pts) | J37: Actual inside ±1 error term | K37: Actual inside 95% range | L37: Rows within 3 pts
A38: Forecast A | B38: 2024 — forward backtest | C38: ='Backtest 2024 A'!F380 -> -1.0017156 | D38: ='Backtest 2024 A'!F382 -> -0.025880967 | E38: ='Backtest 2024 A'!F383 -> 0.013971866 | F38: ='Backtest 2024 A'!F384 -> -0.0056374384 | G38: ='Backtest 2024 A'!F381 -> 2.3262976 | H38: ='Backtest 2024 A'!F379 -> 2.4418874 | I38: ='Backtest 2024 A'!F385 -> 3.4126531 | J38: ='Backtest 2024 A'!F386 -> 0.82163743 | K38: ='Backtest 2024 A'!F387 -> 0.99707602 | L38: ='Backtest 2024 A'!F388 -> 0.78947368
A39: Forecast B | B39: 2024 — forward backtest | C39: ='Backtest 2024 B'!F380 -> -1.0038744 | D39: ='Backtest 2024 B'!F382 -> -0.025924593 | E39: ='Backtest 2024 B'!F383 -> 0.014014125 | F39: ='Backtest 2024 B'!F384 -> -0.0056374384 | G39: ='Backtest 2024 B'!F381 -> 2.3572986 | H39: ='Backtest 2024 B'!F379 -> 2.4647741 | I39: ='Backtest 2024 B'!F385 -> 4.4170332 | J39: ='Backtest 2024 B'!F386 -> 0.93859649 | K39: ='Backtest 2024 B'!F387 -> 0.99707602 | L39: ='Backtest 2024 B'!F388 -> 0.76900585
A40: Forecast C | B40: 2024 — forward backtest | C40: ='Backtest 2024 C'!F380 -> -1.0049537 | D40: ='Backtest 2024 C'!F382 -> -0.025946406 | E40: ='Backtest 2024 C'!F383 -> 0.014035255 | F40: ='Backtest 2024 C'!F384 -> -0.0056374384 | G40: ='Backtest 2024 C'!F381 -> 2.7395426 | H40: ='Backtest 2024 C'!F379 -> 2.8323419 | I40: ='Backtest 2024 C'!F385 -> 4.6011549 | J40: ='Backtest 2024 C'!F386 -> 0.89473684 | K40: ='Backtest 2024 C'!F387 -> 0.99707602 | L40: ='Backtest 2024 C'!F388 -> 0.75438596
A41: Forecast A | B41: 2022 — forward backtest | C41: ='Backtest 2022 A'!F380 -> 1.0226677 | D41: ='Backtest 2022 A'!F382 -> -0.043608175 | E41: ='Backtest 2022 A'!F383 -> -0.081967213 | F41: ='Backtest 2022 A'!F384 -> -0.06249638 | G41: ='Backtest 2022 A'!F381 -> 2.7184855 | H41: ='Backtest 2022 A'!F379 -> 2.6028513 | I41: ='Backtest 2022 A'!F385 -> 3.3124797 | J41: ='Backtest 2022 A'!F386 -> 0.82507289 | K41: ='Backtest 2022 A'!F387 -> 0.97959184 | L41: ='Backtest 2022 A'!F388 -> 0.79300292
A42: Forecast B | B42: 2022 — forward backtest | C42: ='Backtest 2022 B'!F380 -> 1.0242122 | D42: ='Backtest 2022 B'!F382 -> -0.04357965 | E42: ='Backtest 2022 B'!F383 -> -0.081996618 | F42: ='Backtest 2022 B'!F384 -> -0.06249638 | G42: ='Backtest 2022 B'!F381 -> 2.7304654 | H42: ='Backtest 2022 B'!F379 -> 2.7127803 | I42: ='Backtest 2022 B'!F385 -> 4.3398801 | J42: ='Backtest 2022 B'!F386 -> 0.90379009 | K42: ='Backtest 2022 B'!F387 -> 0.99708455 | L42: ='Backtest 2022 B'!F388 -> 0.75218659
A43: Forecast C | B43: 2022 — forward backtest | C43: ='Backtest 2022 C'!F380 -> 1.0222816 | D43: ='Backtest 2022 C'!F382 -> -0.043615307 | E43: ='Backtest 2022 C'!F383 -> -0.081959862 | F43: ='Backtest 2022 C'!F384 -> -0.06249638 | G43: ='Backtest 2022 C'!F381 -> 2.8068132 | H43: ='Backtest 2022 C'!F379 -> 2.704155 | I43: ='Backtest 2022 C'!F385 -> 4.5788446 | J43: ='Backtest 2022 C'!F386 -> 0.9212828 | K43: ='Backtest 2022 C'!F387 -> 1 | L43: ='Backtest 2022 C'!F388 -> 0.77842566
A44: Forecast A | B44: 2020 — hold-out test | C44: ='Backtest 2020 A'!F380 -> 1.1305056 | D44: ='Backtest 2020 A'!F382 -> 0.023864473 | E44: ='Backtest 2020 A'!F383 -> -0.021405912 | F44: ='Backtest 2020 A'!F384 -> 0.0010371281 | G44: ='Backtest 2020 A'!F381 -> 2.7161702 | H44: ='Backtest 2020 A'!F379 -> 3.0996357 | I44: ='Backtest 2020 A'!F385 -> 3.2916731 | J44: ='Backtest 2020 A'!F386 -> 0.74782609 | K44: ='Backtest 2020 A'!F387 -> 0.95942029 | L44: ='Backtest 2020 A'!F388 -> 0.71014493
A45: Forecast B | B45: 2020 — hold-out test | C45: ='Backtest 2020 B'!F380 -> 1.1291352 | D45: ='Backtest 2020 B'!F382 -> 0.023836801 | E45: ='Backtest 2020 B'!F383 -> -0.021378706 | F45: ='Backtest 2020 B'!F384 -> 0.0010371281 | G45: ='Backtest 2020 B'!F381 -> 3.1967328 | H45: ='Backtest 2020 B'!F379 -> 3.5887838 | I45: ='Backtest 2020 B'!F385 -> 4.2314347 | J45: ='Backtest 2020 B'!F386 -> 0.8 | K45: ='Backtest 2020 B'!F387 -> 0.96811594 | L45: ='Backtest 2020 B'!F388 -> 0.65797101
...

Sheet 2026 Forecast A
A1: PA-07 2026 House Forecast — Precinct-Level Predictions (Forecast A: full random forest)
A2: Candidates: Brooks | Mackenzie | District totals (yellow) are formulas over the precinct rows.
A3: Only the results are modelled (one random forest). Votes cast in each row = its 2022 turnout rate (House votes ÷ registered voters) × its 2026 registered voters. Brooks votes = votes cast × forecast Brooks share. Error terms combine the place’s own pattern error (2022 and 2024 backtests), the district-wide error and turnout error (all four backtest years).
A4: Model / scenario | B4: Random forest on results — Forecast A (Full random forest), precinct model; turnout = 2022 turnout rate × 2026 registered voters | C4: As-of date | D4: 46300 | E4: Prepared by | F4: Max | G4: Version | H4: v8.0 (current map; like-for-like baseline; backtests every year)
A5: District Brooks share (scenario) | B5: ='Scenario & Comparison'!$C$6 -> 0.49830982 | C5: Uniform shift applied | D5: =B5-SUMPRODUCT(R12:R381,S12:S381)/SUM(S12:S381)/100 -> 0.51120642 | E5: Turnout multiplier (1.00 = 2022 turnout) | F5: ='Scenario & Comparison'!$C$7 -> 1
A6: DISTRICT TOTALS (auto-sum — do not type over)
A7: Geography | B7: (muni) | C7: (precinct) | D7: Brooks votes | E7: Mackenzie votes | F7: Total votes | G7: Brooks share | H7: Mackenzie share | I7: Notes | J7: Error term: place pattern (± pts) | K7: Error term: district-wide (± pts) | L7: Error term: total (± pts) | M7: Brooks share, 95% low | N7: Brooks share, 95% high | O7: Error term: votes cast (± votes) | P7: Error term: Brooks votes (± votes)
A8: PA-07 District | B8: (all precincts) | D8: =SUM(D12:D381) -> 152544 | E8: =SUM(E12:E381) -> 153569 | F8: =D8+E8 -> 306113 | G8: =IF(F8=0,"",D8/F8) -> 0.49832578 | H8: =IF(F8=0,"",E8/F8) -> 0.50167422 | I8: Headline forecast for the briefing | J8: 0 | K8: 1.2188879 | L8: =SQRT(J8^2+K8^2) -> 1.2188879 | M8: =G8-1.96*L8/100 -> 0.47443558 | N8: =G8+1.96*L8/100 -> 0.52221598 | O8: =ROUND(F8*0.04333,0) -> 13264 | P8: =ROUND(SQRT((F8*L8/100)^2+(G8*O8)^2),0) -> 7590
A9: Error terms are ±1 standard error: place pattern error by place size (2022 and 2024 forward backtests) plus district-wide and turnout error (all four backtest years, 2018–2024). 95% low/high = Brooks share ± 1.96 × total error term.
A10: PRECINCT DETAIL | R10: MODEL INPUTS (from the random forest — do not edit)
A11: County | B11: Municipality | C11: Precinct | D11: Brooks votes | E11: Mackenzie votes | F11: Total votes | G11: Brooks share | H11: Mackenzie share | I11: Notes / source method | J11: Error term: place pattern (± pts) | K11: Error term: district-wide (± pts) | L11: Error term: total (± pts) | M11: Brooks share, 95% low | N11: Brooks share, 95% high | O11: Error term: votes cast (± votes) | P11: Error term: Brooks votes (± votes) | R11: Model lean vs district (pts) | S11: Votes cast = 2022 turnout × 2026 registered | T11: Forecast Brooks share (unrounded) | U11: 2022 turnout (House votes ÷ registered) | V11: 2026 registered voters | W11: Votes-cast error (% of votes) | X11: Size group (backtest error band) | Y11: Registration source
A12: Carbon | B12: BANKS TOWNSHIP | C12: BANKS TOWNSHIP | D12: =ROUND(S12*T12,0) -> 152 | E12: =ROUND(S12,0)-D12 -> 212 | F12: =IF(COUNTA(D12:E12)=0,"",SUM(D12:E12)) -> 364 | G12: =IF(OR(F12="",F12=0),"",D12/F12) -> 0.41758242 | H12: =IF(OR(F12="",F12=0),"",E12/F12) -> 0.58241758 | I12: random forest (results only) | J12: 3.4193192 | K12: =$K$8 -> 1.2188879 | L12: =SQRT(J12^2+K12^2) -> 3.6300732 | M12: =IF(G12="","",MAX(0,G12-1.96*L12/100)) -> 0.34643298 | N12: =IF(G12="","",MIN(1,G12+1.96*L12/100)) -> 0.48873185 | O12: =ROUND(S12*W12,0) -> 54 | P12: =IF(F12="","",ROUND(SQRT((F12*L12/100)^2+(G12*O12)^2),0)) -> 26 | R12: -9.3825015 | S12: =U12*V12*$F$5 -> 364.49096 | T12: =MAX(0,MIN(1,R12/100+$D$5)) -> 0.41738141 | U12: 0.5813253 | V12: 627 | W12: 0.14779328 | X12: Small | Y12: state rolls, precinct
A13: Carbon | B13: BEAVER MEADOWS BOROUGH | C13: BEAVER MEADOWS BOROUGH | D13: =ROUND(S13*T13,0) -> 97 | E13: =ROUND(S13,0)-D13 -> 233 | F13: =IF(COUNTA(D13:E13)=0,"",SUM(D13:E13)) -> 330 | G13: =IF(OR(F13="",F13=0),"",D13/F13) -> 0.29393939 | H13: =IF(OR(F13="",F13=0),"",E13/F13) -> 0.70606061 | I13: random forest (results only) | J13: 3.4193192 | K13: =$K$8 -> 1.2188879 | L13: =SQRT(J13^2+K13^2) -> 3.6300732 | M13: =IF(G13="","",MAX(0,G13-1.96*L13/100)) -> 0.22278996 | N13: =IF(G13="","",MIN(1,G13+1.96*L13/100)) -> 0.36508883 | O13: =ROUND(S13*W13,0) -> 49 | P13: =IF(F13="","",ROUND(SQRT((F13*L13/100)^2+(G13*O13)^2),0)) -> 19 | R13: -21.723744 | S13: =U13*V13*$F$5 -> 330.13014 | T13: =MAX(0,MIN(1,R13/100+$D$5)) -> 0.29396898 | U13: 0.53767123 | V13: 614 | W13: 0.14779328 | X13: Small | Y13: state rolls, precinct
A14: Carbon | B14: BOWMANSTOWN BOROUGH | C14: BOWMANSTOWN BOROUGH | D14: =ROUND(S14*T14,0) -> 116 | E14: =ROUND(S14,0)-D14 -> 240 | F14: =IF(COUNTA(D14:E14)=0,"",SUM(D14:E14)) -> 356 | G14: =IF(OR(F14="",F14=0),"",D14/F14) -> 0.3258427 | H14: =IF(OR(F14="",F14=0),"",E14/F14) -> 0.6741573 | I14: random forest (results only) | J14: 3.4193192 | K14: =$K$8 -> 1.2188879 | L14: =SQRT(J14^2+K14^2) -> 3.6300732 | M14: =IF(G14="","",MAX(0,G14-1.96*L14/100)) -> 0.25469326 | N14: =IF(G14="","",MIN(1,G14+1.96*L14/100)) -> 0.39699213 | O14: =ROUND(S14*W14,0) -> 53 | P14: =IF(F14="","",ROUND(SQRT((F14*L14/100)^2+(G14*O14)^2),0)) -> 22 | R14: -18.412818 | S14: =U14*V14*$F$5 -> 355.63437 | T14: =MAX(0,MIN(1,R14/100+$D$5)) -> 0.32707824 | U14: 0.63619744 | V14: 559 | W14: 0.14779328 | X14: Small | Y14: state rolls, precinct
A15: Carbon | B15: EAST PENN TOWNSHIP | C15: EAST PENN TOWNSHIP-NORTH | D15: =ROUND(S15*T15,0) -> 194 | E15: =ROUND(S15,0)-D15 -> 530 | F15: =IF(COUNTA(D15:E15)=0,"",SUM(D15:E15)) -> 724 | G15: =IF(OR(F15="",F15=0),"",D15/F15) -> 0.2679558 | H15: =IF(OR(F15="",F15=0),"",E15/F15) -> 0.7320442 | I15: random forest (results only) | J15: 2.1171541 | K15: =$K$8 -> 1.2188879 | L15: =SQRT(J15^2+K15^2) -> 2.442955 | M15: =IF(G15="","",MAX(0,G15-1.96*L15/100)) -> 0.22007388 | N15: =IF(G15="","",MIN(1,G15+1.96*L15/100)) -> 0.31583772 | O15: =ROUND(S15*W15,0) -> 64 | P15: =IF(F15="","",ROUND(SQRT((F15*L15/100)^2+(G15*O15)^2),0)) -> 25 | R15: -24.334957 | S15: =U15*V15*$F$5 -> 724.37791 | T15: =MAX(0,MIN(1,R15/100+$D$5)) -> 0.26785685 | U15: 0.67635659 | V15: 1071 | W15: 0.088236166 | X15: Medium | Y15: state rolls, precinct
A16: Carbon | B16: EAST PENN TOWNSHIP | C16: EAST PENN TOWNSHIP-SOUTH | D16: =ROUND(S16*T16,0) -> 177 | E16: =ROUND(S16,0)-D16 -> 434 | F16: =IF(COUNTA(D16:E16)=0,"",SUM(D16:E16)) -> 611 | G16: =IF(OR(F16="",F16=0),"",D16/F16) -> 0.28968903 | H16: =IF(OR(F16="",F16=0),"",E16/F16) -> 0.71031097 | I16: random forest (results only) | J16: 2.1171541 | K16: =$K$8 -> 1.2188879 | L16: =SQRT(J16^2+K16^2) -> 2.442955 | M16: =IF(G16="","",MAX(0,G16-1.96*L16/100)) -> 0.24180712 | N16: =IF(G16="","",MIN(1,G16+1.96*L16/100)) -> 0.33757095 | O16: =ROUND(S16*W16,0) -> 54 | P16: =IF(F16="","",ROUND(SQRT((F16*L16/100)^2+(G16*O16)^2),0)) -> 22 | R16: -22.147157 | S16: =U16*V16*$F$5 -> 610.89237 | T16: =MAX(0,MIN(1,R16/100+$D$5)) -> 0.28973485 | U16: 0.62591432 | V16: 976 | W16: 0.088236166 | X16: Medium | Y16: state rolls, precinct
A17: Carbon | B17: EAST SIDE BOROUGH | C17: EAST SIDE BOROUGH | D17: =ROUND(S17*T17,0) -> 32 | E17: =ROUND(S17,0)-D17 -> 61 | F17: =IF(COUNTA(D17:E17)=0,"",SUM(D17:E17)) -> 93 | G17: =IF(OR(F17="",F17=0),"",D17/F17) -> 0.34408602 | H17: =IF(OR(F17="",F17=0),"",E17/F17) -> 0.65591398 | I17: random forest (results only) | J17: 3.4193192 | K17: =$K$8 -> 1.2188879 | L17: =SQRT(J17^2+K17^2) -> 3.6300732 | M17: =IF(G17="","",MAX(0,G17-1.96*L17/100)) -> 0.27293659 | N17: =IF(G17="","",MIN(1,G17+1.96*L17/100)) -> 0.41523546 | O17: =ROUND(S17*W17,0) -> 14 | P17: =IF(F17="","",ROUND(SQRT((F17*L17/100)^2+(G17*O17)^2),0)) -> 6 | R17: -16.935318 | S17: =U17*V17*$F$5 -> 93.426829 | T17: =MAX(0,MIN(1,R17/100+$D$5)) -> 0.34185324 | U17: 0.57317073 | V17: 163 | W17: 0.14779328 | X17: Small | Y17: state rolls, precinct
A18: Carbon | B18: FRANKLIN TOWNSHIP | C18: FRANKLIN TOWNSHIP-HARRITY | D18: =ROUND(S18*T18,0) -> 246 | E18: =ROUND(S18,0)-D18 -> 607 | F18: =IF(COUNTA(D18:E18)=0,"",SUM(D18:E18)) -> 853 | G18: =IF(OR(F18="",F18=0),"",D18/F18) -> 0.2883939 | H18: =IF(OR(F18="",F18=0),"",E18/F18) -> 0.7116061 | I18: random forest (results only) | J18: 2.1171541 | K18: =$K$8 -> 1.2188879 | L18: =SQRT(J18^2+K18^2) -> 2.442955 | M18: =IF(G18="","",MAX(0,G18-1.96*L18/100)) -> 0.24051199 | N18: =IF(G18="","",MIN(1,G18+1.96*L18/100)) -> 0.33627582 | O18: =ROUND(S18*W18,0) -> 75 | P18: =IF(F18="","",ROUND(SQRT((F18*L18/100)^2+(G18*O18)^2),0)) -> 30 | R18: -22.26495 | S18: =U18*V18*$F$5 -> 852.99444 | T18: =MAX(0,MIN(1,R18/100+$D$5)) -> 0.28855692 | U18: 0.66640191 | V18: 1280 | W18: 0.088236166 | X18: Medium | Y18: state rolls, precinct
A19: Carbon | B19: FRANKLIN TOWNSHIP | C19: FRANKLIN TOWNSHIP-IND DIST | D19: =ROUND(S19*T19,0) -> 126 | E19: =ROUND(S19,0)-D19 -> 322 | F19: =IF(COUNTA(D19:E19)=0,"",SUM(D19:E19)) -> 448 | G19: =IF(OR(F19="",F19=0),"",D19/F19) -> 0.28125 | H19: =IF(OR(F19="",F19=0),"",E19/F19) -> 0.71875 | I19: random forest (results only) | J19: 3.4193192 | K19: =$K$8 -> 1.2188879 | L19: =SQRT(J19^2+K19^2) -> 3.6300732 | M19: =IF(G19="","",MAX(0,G19-1.96*L19/100)) -> 0.21010057 | N19: =IF(G19="","",MIN(1,G19+1.96*L19/100)) -> 0.35239943 | O19: =ROUND(S19*W19,0) -> 66 | P19: =IF(F19="","",ROUND(SQRT((F19*L19/100)^2+(G19*O19)^2),0)) -> 25 | R19: -23.021767 | S19: =U19*V19*$F$5 -> 447.93932 | T19: =MAX(0,MIN(1,R19/100+$D$5)) -> 0.28098875 | U19: 0.55097087 | V19: 813 | W19: 0.14779328 | X19: Small | Y19: state rolls, precinct
A20: Carbon | B20: FRANKLIN TOWNSHIP | C20: FRANKLIN TOWNSHIP-LONG RUN | D20: =ROUND(S20*T20,0) -> 192 | E20: =ROUND(S20,0)-D20 -> 491 | F20: =IF(COUNTA(D20:E20)=0,"",SUM(D20:E20)) -> 683 | G20: =IF(OR(F20="",F20=0),"",D20/F20) -> 0.28111274 | H20: =IF(OR(F20="",F20=0),"",E20/F20) -> 0.71888726 | I20: random forest (results only) | J20: 2.1171541 | K20: =$K$8 -> 1.2188879 | L20: =SQRT(J20^2+K20^2) -> 2.442955 | M20: =IF(G20="","",MAX(0,G20-1.96*L20/100)) -> 0.23323082 | N20: =IF(G20="","",MIN(1,G20+1.96*L20/100)) -> 0.32899466 | O20: =ROUND(S20*W20,0) -> 60 | P20: =IF(F20="","",ROUND(SQRT((F20*L20/100)^2+(G20*O20)^2),0)) -> 24 | R20: -22.998693 | S20: =U20*V20*$F$5 -> 683.32677 | T20: =MAX(0,MIN(1,R20/100+$D$5)) -> 0.28121949 | U20: 0.65452756 | V20: 1044 | W20: 0.088236166 | X20: Medium | Y20: state rolls, precinct
A21: Carbon | B21: JIM THORPE BOROUGH | C21: JIM THORPE BOROUGH-1ST | D21: =ROUND(S21*T21,0) -> 194 | E21: =ROUND(S21,0)-D21 -> 242 | F21: =IF(COUNTA(D21:E21)=0,"",SUM(D21:E21)) -> 436 | G21: =IF(OR(F21="",F21=0),"",D21/F21) -> 0.44495413 | H21: =IF(OR(F21="",F21=0),"",E21/F21) -> 0.55504587 | I21: random forest (results only) | J21: 3.4193192 | K21: =$K$8 -> 1.2188879 | L21: =SQRT(J21^2+K21^2) -> 3.6300732 | M21: =IF(G21="","",MAX(0,G21-1.96*L21/100)) -> 0.37380469 | N21: =IF(G21="","",MIN(1,G21+1.96*L21/100)) -> 0.51610356 | O21: =ROUND(S21*W21,0) -> 64 | P21: =IF(F21="","",ROUND(SQRT((F21*L21/100)^2+(G21*O21)^2),0)) -> 33 | R21: -6.540268 | S21: =U21*V21*$F$5 -> 436.24467 | T21: =MAX(0,MIN(1,R21/100+$D$5)) -> 0.44580374 | U21: 0.62588905 | V21: 697 | W21: 0.14779328 | X21: Small | Y21: state rolls, precinct
A22: Carbon | B22: JIM THORPE BOROUGH | C22: JIM THORPE BOROUGH-2ND | D22: =ROUND(S22*T22,0) -> 120 | E22: =ROUND(S22,0)-D22 -> 160 | F22: =IF(COUNTA(D22:E22)=0,"",SUM(D22:E22)) -> 280 | G22: =IF(OR(F22="",F22=0),"",D22/F22) -> 0.42857143 | H22: =IF(OR(F22="",F22=0),"",E22/F22) -> 0.57142857 | I22: random forest (results only) | J22: 3.4193192 | K22: =$K$8 -> 1.2188879 | L22: =SQRT(J22^2+K22^2) -> 3.6300732 | M22: =IF(G22="","",MAX(0,G22-1.96*L22/100)) -> 0.35742199 | N22: =IF(G22="","",MIN(1,G22+1.96*L22/100)) -> 0.49972086 | O22: =ROUND(S22*W22,0) -> 41 | P22: =IF(F22="","",ROUND(SQRT((F22*L22/100)^2+(G22*O22)^2),0)) -> 20 | R22: -8.5045743 | S22: =U22*V22*$F$5 -> 280.5 | T22: =MAX(0,MIN(1,R22/100+$D$5)) -> 0.42616068 | U22: 0.56896552 | V22: 493 | W22: 0.14779328 | X22: Small | Y22: state rolls, precinct
A23: Carbon | B23: JIM THORPE BOROUGH | C23: JIM THORPE BOROUGH-3RD | D23: =ROUND(S23*T23,0) -> 253 | E23: =ROUND(S23,0)-D23 -> 393 | F23: =IF(COUNTA(D23:E23)=0,"",SUM(D23:E23)) -> 646 | G23: =IF(OR(F23="",F23=0),"",D23/F23) -> 0.39164087 | H23: =IF(OR(F23="",F23=0),"",E23/F23) -> 0.60835913 | I23: random forest (results only) | J23: 2.1171541 | K23: =$K$8 -> 1.2188879 | L23: =SQRT(J23^2+K23^2) -> 2.442955 | M23: =IF(G23="","",MAX(0,G23-1.96*L23/100)) -> 0.34375895 | N23: =IF(G23="","",MIN(1,G23+1.96*L23/100)) -> 0.43952278 | O23: =ROUND(S23*W23,0) -> 57 | P23: =IF(F23="","",ROUND(SQRT((F23*L23/100)^2+(G23*O23)^2),0)) -> 27 | R23: -11.896239 | S23: =U23*V23*$F$5 -> 645.69536 | T23: =MAX(0,MIN(1,R23/100+$D$5)) -> 0.39224403 | U23: 0.68984547 | V23: 936 | W23: 0.088236166 | X23: Medium | Y23: state rolls, precinct
... A381: Northampton | B381: WIND GAP | C381: WIND GAP | D381: =ROUND(S381*T381,0) -> 496 | E381: =ROUND(S381,0)-D381 -> 649 | F381: =IF(COUNTA(D381:E381)=0,"",SUM(D381:E381)) -> 1145 | G381: =IF(OR(F381="",F381=0),"",D381/F381) -> 0.43318777 | H381: =IF(OR(F381="",F381=0),"",E381/F381) -> 0.56681223 | I381: random forest (results only) | J381: 1.7283367 | K381: =$K$8 -> 1.2188879 | L381: =SQRT(J381^2+K381^2) -> 2.1149079 | M381: =IF(G381="","",MAX(0,G381-1.96*L381/100)) -> 0.39173558 | N381: =IF(G381="","",MIN(1,G381+1.96*L381/100)) -> 0.47463997 | O381: =ROUND(S381*W381,0) -> 78 | P381: =IF(F381="","",ROUND(SQRT((F381*L381/100)^2+(G381*O381)^2),0)) -> 42 | R381: -7.8616141 | S381: =U381*V381*$F$5 -> 1145.4806 | T381: =MAX(0,MIN(1,R381/100+$D$5)) -> 0.43259028 | U381: 0.53702795 | V381: 2133 | W381: 0.067815102 | X381: Large | Y381: state rolls, precinct

Sheet 2026 Forecast B
A1: PA-07 2026 House Forecast — Precinct-Level Predictions (Forecast B: shap-selected forest)
A2: Candidates: Brooks | Mackenzie | District totals (yellow) are formulas over the precinct rows.
A3: Only the results are modelled (one random forest). Votes cast in each row = its 2022 turnout rate (House votes ÷ registered voters) × its 2026 registered voters. Brooks votes = votes cast × forecast Brooks share. Error terms combine the place’s own pattern error (2022 and 2024 backtests), the district-wide error and turnout error (all four backtest years).
A4: Model / scenario | B4: Random forest on results — Forecast B (SHAP-selected forest), precinct model; turnout = 2022 turnout rate × 2026 registered voters | C4: As-of date | D4: 46300 | E4: Prepared by | F4: Max | G4: Version | H4: v8.0 (current map; like-for-like baseline; backtests every year)
A5: District Brooks share (scenario) | B5: ='Scenario & Comparison'!$C$6 -> 0.49830982 | C5: Uniform shift applied | D5: =B5-SUMPRODUCT(R12:R381,S12:S381)/SUM(S12:S381)/100 -> 0.51514479 | E5: Turnout multiplier (1.00 = 2022 turnout) | F5: ='Scenario & Comparison'!$C$7 -> 1
A6: DISTRICT TOTALS (auto-sum — do not type over)
A7: Geography | B7: (muni) | C7: (precinct) | D7: Brooks votes | E7: Mackenzie votes | F7: Total votes | G7: Brooks share | H7: Mackenzie share | I7: Notes | J7: Error term: place pattern (± pts) | K7: Error term: district-wide (± pts) | L7: Error term: total (± pts) | M7: Brooks share, 95% low | N7: Brooks share, 95% high | O7: Error term: votes cast (± votes) | P7: Error term: Brooks votes (± votes)
A8: PA-07 District | B8: (all precincts) | D8: =SUM(D12:D381) -> 152546 | E8: =SUM(E12:E381) -> 153567 | F8: =D8+E8 -> 306113 | G8: =IF(F8=0,"",D8/F8) -> 0.49833232 | H8: =IF(F8=0,"",E8/F8) -> 0.50166768 | I8: Headline forecast for the briefing | J8: 0 | K8: 1.2181759 | L8: =SQRT(J8^2+K8^2) -> 1.2181759 | M8: =G8-1.96*L8/100 -> 0.47445607 | N8: =G8+1.96*L8/100 -> 0.52220856 | O8: =ROUND(F8*0.04333,0) -> 13264 | P8: =ROUND(SQRT((F8*L8/100)^2+(G8*O8)^2),0) -> 7589
A9: Error terms are ±1 standard error: place pattern error by place size (2022 and 2024 forward backtests) plus district-wide and turnout error (all four backtest years, 2018–2024). 95% low/high = Brooks share ± 1.96 × total error term.
A10: PRECINCT DETAIL | R10: MODEL INPUTS (from the random forest — do not edit)
A11: County | B11: Municipality | C11: Precinct | D11: Brooks votes | E11: Mackenzie votes | F11: Total votes | G11: Brooks share | H11: Mackenzie share | I11: Notes / source method | J11: Error term: place pattern (± pts) | K11: Error term: district-wide (± pts) | L11: Error term: total (± pts) | M11: Brooks share, 95% low | N11: Brooks share, 95% high | O11: Error term: votes cast (± votes) | P11: Error term: Brooks votes (± votes) | R11: Model lean vs district (pts) | S11: Votes cast = 2022 turnout × 2026 registered | T11: Forecast Brooks share (unrounded) | U11: 2022 turnout (House votes ÷ registered) | V11: 2026 registered voters | W11: Votes-cast error (% of votes) | X11: Size group (backtest error band) | Y11: Registration source
A12: Carbon | B12: BANKS TOWNSHIP | C12: BANKS TOWNSHIP | D12: =ROUND(S12*T12,0) -> 155 | E12: =ROUND(S12,0)-D12 -> 209 | F12: =IF(COUNTA(D12:E12)=0,"",SUM(D12:E12)) -> 364 | G12: =IF(OR(F12="",F12=0),"",D12/F12) -> 0.42582418 | H12: =IF(OR(F12="",F12=0),"",E12/F12) -> 0.57417582 | I12: random forest (results only) | J12: 3.1979633 | K12: =$K$8 -> 1.2181759 | L12: =SQRT(J12^2+K12^2) -> 3.4221224 | M12: =IF(G12="","",MAX(0,G12-1.96*L12/100)) -> 0.35875058 | N12: =IF(G12="","",MIN(1,G12+1.96*L12/100)) -> 0.49289778 | O12: =ROUND(S12*W12,0) -> 54 | P12: =IF(F12="","",ROUND(SQRT((F12*L12/100)^2+(G12*O12)^2),0)) -> 26 | R12: -8.9602389 | S12: =U12*V12*$F$5 -> 364.49096 | T12: =MAX(0,MIN(1,R12/100+$D$5)) -> 0.4255424 | U12: 0.5813253 | V12: 627 | W12: 0.14779328 | X12: Small | Y12: state rolls, precinct
A13: Carbon | B13: BEAVER MEADOWS BOROUGH | C13: BEAVER MEADOWS BOROUGH | D13: =ROUND(S13*T13,0) -> 98 | E13: =ROUND(S13,0)-D13 -> 232 | F13: =IF(COUNTA(D13:E13)=0,"",SUM(D13:E13)) -> 330 | G13: =IF(OR(F13="",F13=0),"",D13/F13) -> 0.2969697 | H13: =IF(OR(F13="",F13=0),"",E13/F13) -> 0.7030303 | I13: random forest (results only) | J13: 3.1979633 | K13: =$K$8 -> 1.2181759 | L13: =SQRT(J13^2+K13^2) -> 3.4221224 | M13: =IF(G13="","",MAX(0,G13-1.96*L13/100)) -> 0.2298961 | N13: =IF(G13="","",MIN(1,G13+1.96*L13/100)) -> 0.3640433 | O13: =ROUND(S13*W13,0) -> 49 | P13: =IF(F13="","",ROUND(SQRT((F13*L13/100)^2+(G13*O13)^2),0)) -> 18 | R13: -21.892882 | S13: =U13*V13*$F$5 -> 330.13014 | T13: =MAX(0,MIN(1,R13/100+$D$5)) -> 0.29621597 | U13: 0.53767123 | V13: 614 | W13: 0.14779328 | X13: Small | Y13: state rolls, precinct
A14: Carbon | B14: BOWMANSTOWN BOROUGH | C14: BOWMANSTOWN BOROUGH | D14: =ROUND(S14*T14,0) -> 122 | E14: =ROUND(S14,0)-D14 -> 234 | F14: =IF(COUNTA(D14:E14)=0,"",SUM(D14:E14)) -> 356 | G14: =IF(OR(F14="",F14=0),"",D14/F14) -> 0.34269663 | H14: =IF(OR(F14="",F14=0),"",E14/F14) -> 0.65730337 | I14: random forest (results only) | J14: 3.1979633 | K14: =$K$8 -> 1.2181759 | L14: =SQRT(J14^2+K14^2) -> 3.4221224 | M14: =IF(G14="","",MAX(0,G14-1.96*L14/100)) -> 0.27562303 | N14: =IF(G14="","",MIN(1,G14+1.96*L14/100)) -> 0.40977023 | O14: =ROUND(S14*W14,0) -> 53 | P14: =IF(F14="","",ROUND(SQRT((F14*L14/100)^2+(G14*O14)^2),0)) -> 22 | R14: -17.273159 | S14: =U14*V14*$F$5 -> 355.63437 | T14: =MAX(0,MIN(1,R14/100+$D$5)) -> 0.3424132 | U14: 0.63619744 | V14: 559 | W14: 0.14779328 | X14: Small | Y14: state rolls, precinct
A15: Carbon | B15: EAST PENN TOWNSHIP | C15: EAST PENN TOWNSHIP-NORTH | D15: =ROUND(S15*T15,0) -> 195 | E15: =ROUND(S15,0)-D15 -> 529 | F15: =IF(COUNTA(D15:E15)=0,"",SUM(D15:E15)) -> 724 | G15: =IF(OR(F15="",F15=0),"",D15/F15) -> 0.26933702 | H15: =IF(OR(F15="",F15=0),"",E15/F15) -> 0.73066298 | I15: random forest (results only) | J15: 2.2249159 | K15: =$K$8 -> 1.2181759 | L15: =SQRT(J15^2+K15^2) -> 2.5365731 | M15: =IF(G15="","",MAX(0,G15-1.96*L15/100)) -> 0.21962018 | N15: =IF(G15="","",MIN(1,G15+1.96*L15/100)) -> 0.31905385 | O15: =ROUND(S15*W15,0) -> 64 | P15: =IF(F15="","",ROUND(SQRT((F15*L15/100)^2+(G15*O15)^2),0)) -> 25 | R15: -24.642821 | S15: =U15*V15*$F$5 -> 724.37791 | T15: =MAX(0,MIN(1,R15/100+$D$5)) -> 0.26871658 | U15: 0.67635659 | V15: 1071 | W15: 0.088236166 | X15: Medium | Y15: state rolls, precinct
A16: Carbon | B16: EAST PENN TOWNSHIP | C16: EAST PENN TOWNSHIP-SOUTH | D16: =ROUND(S16*T16,0) -> 176 | E16: =ROUND(S16,0)-D16 -> 435 | F16: =IF(COUNTA(D16:E16)=0,"",SUM(D16:E16)) -> 611 | G16: =IF(OR(F16="",F16=0),"",D16/F16) -> 0.28805237 | H16: =IF(OR(F16="",F16=0),"",E16/F16) -> 0.71194763 | I16: random forest (results only) | J16: 2.2249159 | K16: =$K$8 -> 1.2181759 | L16: =SQRT(J16^2+K16^2) -> 2.5365731 | M16: =IF(G16="","",MAX(0,G16-1.96*L16/100)) -> 0.23833554 | N16: =IF(G16="","",MIN(1,G16+1.96*L16/100)) -> 0.33776921 | O16: =ROUND(S16*W16,0) -> 54 | P16: =IF(F16="","",ROUND(SQRT((F16*L16/100)^2+(G16*O16)^2),0)) -> 22 | R16: -22.755724 | S16: =U16*V16*$F$5 -> 610.89237 | T16: =MAX(0,MIN(1,R16/100+$D$5)) -> 0.28758755 | U16: 0.62591432 | V16: 976 | W16: 0.088236166 | X16: Medium | Y16: state rolls, precinct
A17: Carbon | B17: EAST SIDE BOROUGH | C17: EAST SIDE BOROUGH | D17: =ROUND(S17*T17,0) -> 33 | E17: =ROUND(S17,0)-D17 -> 60 | F17: =IF(COUNTA(D17:E17)=0,"",SUM(D17:E17)) -> 93 | G17: =IF(OR(F17="",F17=0),"",D17/F17) -> 0.35483871 | H17: =IF(OR(F17="",F17=0),"",E17/F17) -> 0.64516129 | I17: random forest (results only) | J17: 3.1979633 | K17: =$K$8 -> 1.2181759 | L17: =SQRT(J17^2+K17^2) -> 3.4221224 | M17: =IF(G17="","",MAX(0,G17-1.96*L17/100)) -> 0.28776511 | N17: =IF(G17="","",MIN(1,G17+1.96*L17/100)) -> 0.42191231 | O17: =ROUND(S17*W17,0) -> 14 | P17: =IF(F17="","",ROUND(SQRT((F17*L17/100)^2+(G17*O17)^2),0)) -> 6 | R17: -15.909605 | S17: =U17*V17*$F$5 -> 93.426829 | T17: =MAX(0,MIN(1,R17/100+$D$5)) -> 0.35604873 | U17: 0.57317073 | V17: 163 | W17: 0.14779328 | X17: Small | Y17: state rolls, precinct
A18: Carbon | B18: FRANKLIN TOWNSHIP | C18: FRANKLIN TOWNSHIP-HARRITY | D18: =ROUND(S18*T18,0) -> 247 | E18: =ROUND(S18,0)-D18 -> 606 | F18: =IF(COUNTA(D18:E18)=0,"",SUM(D18:E18)) -> 853 | G18: =IF(OR(F18="",F18=0),"",D18/F18) -> 0.28956624 | H18: =IF(OR(F18="",F18=0),"",E18/F18) -> 0.71043376 | I18: random forest (results only) | J18: 2.2249159 | K18: =$K$8 -> 1.2181759 | L18: =SQRT(J18^2+K18^2) -> 2.5365731 | M18: =IF(G18="","",MAX(0,G18-1.96*L18/100)) -> 0.2398494 | N18: =IF(G18="","",MIN(1,G18+1.96*L18/100)) -> 0.33928307 | O18: =ROUND(S18*W18,0) -> 75 | P18: =IF(F18="","",ROUND(SQRT((F18*L18/100)^2+(G18*O18)^2),0)) -> 31 | R18: -22.505631 | S18: =U18*V18*$F$5 -> 852.99444 | T18: =MAX(0,MIN(1,R18/100+$D$5)) -> 0.29008848 | U18: 0.66640191 | V18: 1280 | W18: 0.088236166 | X18: Medium | Y18: state rolls, precinct
A19: Carbon | B19: FRANKLIN TOWNSHIP | C19: FRANKLIN TOWNSHIP-IND DIST | D19: =ROUND(S19*T19,0) -> 127 | E19: =ROUND(S19,0)-D19 -> 321 | F19: =IF(COUNTA(D19:E19)=0,"",SUM(D19:E19)) -> 448 | G19: =IF(OR(F19="",F19=0),"",D19/F19) -> 0.28348214 | H19: =IF(OR(F19="",F19=0),"",E19/F19) -> 0.71651786 | I19: random forest (results only) | J19: 3.1979633 | K19: =$K$8 -> 1.2181759 | L19: =SQRT(J19^2+K19^2) -> 3.4221224 | M19: =IF(G19="","",MAX(0,G19-1.96*L19/100)) -> 0.21640854 | N19: =IF(G19="","",MIN(1,G19+1.96*L19/100)) -> 0.35055574 | O19: =ROUND(S19*W19,0) -> 66 | P19: =IF(F19="","",ROUND(SQRT((F19*L19/100)^2+(G19*O19)^2),0)) -> 24 | R19: -23.193736 | S19: =U19*V19*$F$5 -> 447.93932 | T19: =MAX(0,MIN(1,R19/100+$D$5)) -> 0.28320743 | U19: 0.55097087 | V19: 813 | W19: 0.14779328 | X19: Small | Y19: state rolls, precinct
A20: Carbon | B20: FRANKLIN TOWNSHIP | C20: FRANKLIN TOWNSHIP-LONG RUN | D20: =ROUND(S20*T20,0) -> 190 | E20: =ROUND(S20,0)-D20 -> 493 | F20: =IF(COUNTA(D20:E20)=0,"",SUM(D20:E20)) -> 683 | G20: =IF(OR(F20="",F20=0),"",D20/F20) -> 0.27818448 | H20: =IF(OR(F20="",F20=0),"",E20/F20) -> 0.72181552 | I20: random forest (results only) | J20: 2.2249159 | K20: =$K$8 -> 1.2181759 | L20: =SQRT(J20^2+K20^2) -> 2.5365731 | M20: =IF(G20="","",MAX(0,G20-1.96*L20/100)) -> 0.22846765 | N20: =IF(G20="","",MIN(1,G20+1.96*L20/100)) -> 0.32790131 | O20: =ROUND(S20*W20,0) -> 60 | P20: =IF(F20="","",ROUND(SQRT((F20*L20/100)^2+(G20*O20)^2),0)) -> 24 | R20: -23.639155 | S20: =U20*V20*$F$5 -> 683.32677 | T20: =MAX(0,MIN(1,R20/100+$D$5)) -> 0.27875323 | U20: 0.65452756 | V20: 1044 | W20: 0.088236166 | X20: Medium | Y20: state rolls, precinct
A21: Carbon | B21: JIM THORPE BOROUGH | C21: JIM THORPE BOROUGH-1ST | D21: =ROUND(S21*T21,0) -> 197 | E21: =ROUND(S21,0)-D21 -> 239 | F21: =IF(COUNTA(D21:E21)=0,"",SUM(D21:E21)) -> 436 | G21: =IF(OR(F21="",F21=0),"",D21/F21) -> 0.45183486 | H21: =IF(OR(F21="",F21=0),"",E21/F21) -> 0.54816514 | I21: random forest (results only) | J21: 3.1979633 | K21: =$K$8 -> 1.2181759 | L21: =SQRT(J21^2+K21^2) -> 3.4221224 | M21: =IF(G21="","",MAX(0,G21-1.96*L21/100)) -> 0.38476126 | N21: =IF(G21="","",MIN(1,G21+1.96*L21/100)) -> 0.51890846 | O21: =ROUND(S21*W21,0) -> 64 | P21: =IF(F21="","",ROUND(SQRT((F21*L21/100)^2+(G21*O21)^2),0)) -> 33 | R21: -6.2977772 | S21: =U21*V21*$F$5 -> 436.24467 | T21: =MAX(0,MIN(1,R21/100+$D$5)) -> 0.45216701 | U21: 0.62588905 | V21: 697 | W21: 0.14779328 | X21: Small | Y21: state rolls, precinct
A22: Carbon | B22: JIM THORPE BOROUGH | C22: JIM THORPE BOROUGH-2ND | D22: =ROUND(S22*T22,0) -> 123 | E22: =ROUND(S22,0)-D22 -> 157 | F22: =IF(COUNTA(D22:E22)=0,"",SUM(D22:E22)) -> 280 | G22: =IF(OR(F22="",F22=0),"",D22/F22) -> 0.43928571 | H22: =IF(OR(F22="",F22=0),"",E22/F22) -> 0.56071429 | I22: random forest (results only) | J22: 3.1979633 | K22: =$K$8 -> 1.2181759 | L22: =SQRT(J22^2+K22^2) -> 3.4221224 | M22: =IF(G22="","",MAX(0,G22-1.96*L22/100)) -> 0.37221211 | N22: =IF(G22="","",MIN(1,G22+1.96*L22/100)) -> 0.50635931 | O22: =ROUND(S22*W22,0) -> 41 | P22: =IF(F22="","",ROUND(SQRT((F22*L22/100)^2+(G22*O22)^2),0)) -> 20 | R22: -7.6322666 | S22: =U22*V22*$F$5 -> 280.5 | T22: =MAX(0,MIN(1,R22/100+$D$5)) -> 0.43882212 | U22: 0.56896552 | V22: 493 | W22: 0.14779328 | X22: Small | Y22: state rolls, precinct
A23: Carbon | B23: JIM THORPE BOROUGH | C23: JIM THORPE BOROUGH-3RD | D23: =ROUND(S23*T23,0) -> 253 | E23: =ROUND(S23,0)-D23 -> 393 | F23: =IF(COUNTA(D23:E23)=0,"",SUM(D23:E23)) -> 646 | G23: =IF(OR(F23="",F23=0),"",D23/F23) -> 0.39164087 | H23: =IF(OR(F23="",F23=0),"",E23/F23) -> 0.60835913 | I23: random forest (results only) | J23: 2.2249159 | K23: =$K$8 -> 1.2181759 | L23: =SQRT(J23^2+K23^2) -> 2.5365731 | M23: =IF(G23="","",MAX(0,G23-1.96*L23/100)) -> 0.34192403 | N23: =IF(G23="","",MIN(1,G23+1.96*L23/100)) -> 0.4413577 | O23: =ROUND(S23*W23,0) -> 57 | P23: =IF(F23="","",ROUND(SQRT((F23*L23/100)^2+(G23*O23)^2),0)) -> 28 | R23: -12.305978 | S23: =U23*V23*$F$5 -> 645.69536 | T23: =MAX(0,MIN(1,R23/100+$D$5)) -> 0.39208501 | U23: 0.68984547 | V23: 936 | W23: 0.088236166 | X23: Medium | Y23: state rolls, precinct
... A381: Northampton | B381: WIND GAP | C381: WIND GAP | D381: =ROUND(S381*T381,0) -> 490 | E381: =ROUND(S381,0)-D381 -> 655 | F381: =IF(COUNTA(D381:E381)=0,"",SUM(D381:E381)) -> 1145 | G381: =IF(OR(F381="",F381=0),"",D381/F381) -> 0.4279476 | H381: =IF(OR(F381="",F381=0),"",E381/F381) -> 0.5720524 | I381: random forest (results only) | J381: 2.0829171 | K381: =$K$8 -> 1.2181759 | L381: =SQRT(J381^2+K381^2) -> 2.412985 | M381: =IF(G381="","",MAX(0,G381-1.96*L381/100)) -> 0.38065309 | N381: =IF(G381="","",MIN(1,G381+1.96*L381/100)) -> 0.4752421 | O381: =ROUND(S381*W381,0) -> 78 | P381: =IF(F381="","",ROUND(SQRT((F381*L381/100)^2+(G381*O381)^2),0)) -> 43 | R381: -8.7138028 | S381: =U381*V381*$F$5 -> 1145.4806 | T381: =MAX(0,MIN(1,R381/100+$D$5)) -> 0.42800676 | U381: 0.53702795 | V381: 2133 | W381: 0.067815102 | X381: Large | Y381: state rolls, precinct

Sheet 2026 Forecast C
A1: PA-07 2026 House Forecast — Precinct-Level Predictions (Forecast C: shap family-reweighted forest)
A2: Candidates: Brooks | Mackenzie | District totals (yellow) are formulas over the precinct rows.
A3: Only the results are modelled (one random forest). Votes cast in each row = its 2022 turnout rate (House votes ÷ registered voters) × its 2026 registered voters. Brooks votes = votes cast × forecast Brooks share. Error terms combine the place’s own pattern error (2022 and 2024 backtests), the district-wide error and turnout error (all four backtest years).
A4: Model / scenario | B4: Random forest on results — Forecast C (SHAP family-reweighted forest), precinct model; turnout = 2022 turnout rate × 2026 registered voters | C4: As-of date | D4: 46300 | E4: Prepared by | F4: Max | G4: Version | H4: v8.0 (current map; like-for-like baseline; backtests every year)
A5: District Brooks share (scenario) | B5: ='Scenario & Comparison'!$C$6 -> 0.49830982 | C5: Uniform shift applied | D5: =B5-SUMPRODUCT(R12:R381,S12:S381)/SUM(S12:S381)/100 -> 0.51070748 | E5: Turnout multiplier (1.00 = 2022 turnout) | F5: ='Scenario & Comparison'!$C$7 -> 1
A6: DISTRICT TOTALS (auto-sum — do not type over)
A7: Geography | B7: (muni) | C7: (precinct) | D7: Brooks votes | E7: Mackenzie votes | F7: Total votes | G7: Brooks share | H7: Mackenzie share | I7: Notes | J7: Error term: place pattern (± pts) | K7: Error term: district-wide (± pts) | L7: Error term: total (± pts) | M7: Brooks share, 95% low | N7: Brooks share, 95% high | O7: Error term: votes cast (± votes) | P7: Error term: Brooks votes (± votes)
A8: PA-07 District | B8: (all precincts) | D8: =SUM(D12:D381) -> 152545 | E8: =SUM(E12:E381) -> 153568 | F8: =D8+E8 -> 306113 | G8: =IF(F8=0,"",D8/F8) -> 0.49832905 | H8: =IF(F8=0,"",E8/F8) -> 0.50167095 | I8: Headline forecast for the briefing | J8: 0 | K8: 1.2186289 | L8: =SQRT(J8^2+K8^2) -> 1.2186289 | M8: =G8-1.96*L8/100 -> 0.47444392 | N8: =G8+1.96*L8/100 -> 0.52221417 | O8: =ROUND(F8*0.04333,0) -> 13264 | P8: =ROUND(SQRT((F8*L8/100)^2+(G8*O8)^2),0) -> 7590
A9: Error terms are ±1 standard error: place pattern error by place size (2022 and 2024 forward backtests) plus district-wide and turnout error (all four backtest years, 2018–2024). 95% low/high = Brooks share ± 1.96 × total error term.
A10: PRECINCT DETAIL | R10: MODEL INPUTS (from the random forest — do not edit)
A11: County | B11: Municipality | C11: Precinct | D11: Brooks votes | E11: Mackenzie votes | F11: Total votes | G11: Brooks share | H11: Mackenzie share | I11: Notes / source method | J11: Error term: place pattern (± pts) | K11: Error term: district-wide (± pts) | L11: Error term: total (± pts) | M11: Brooks share, 95% low | N11: Brooks share, 95% high | O11: Error term: votes cast (± votes) | P11: Error term: Brooks votes (± votes) | R11: Model lean vs district (pts) | S11: Votes cast = 2022 turnout × 2026 registered | T11: Forecast Brooks share (unrounded) | U11: 2022 turnout (House votes ÷ registered) | V11: 2026 registered voters | W11: Votes-cast error (% of votes) | X11: Size group (backtest error band) | Y11: Registration source
A12: Carbon | B12: BANKS TOWNSHIP | C12: BANKS TOWNSHIP | D12: =ROUND(S12*T12,0) -> 148 | E12: =ROUND(S12,0)-D12 -> 216 | F12: =IF(COUNTA(D12:E12)=0,"",SUM(D12:E12)) -> 364 | G12: =IF(OR(F12="",F12=0),"",D12/F12) -> 0.40659341 | H12: =IF(OR(F12="",F12=0),"",E12/F12) -> 0.59340659 | I12: random forest (results only) | J12: 3.7104392 | K12: =$K$8 -> 1.2186289 | L12: =SQRT(J12^2+K12^2) -> 3.9054341 | M12: =IF(G12="","",MAX(0,G12-1.96*L12/100)) -> 0.3300469 | N12: =IF(G12="","",MIN(1,G12+1.96*L12/100)) -> 0.48313992 | O12: =ROUND(S12*W12,0) -> 54 | P12: =IF(F12="","",ROUND(SQRT((F12*L12/100)^2+(G12*O12)^2),0)) -> 26 | R12: -10.472152 | S12: =U12*V12*$F$5 -> 364.49096 | T12: =MAX(0,MIN(1,R12/100+$D$5)) -> 0.40598595 | U12: 0.5813253 | V12: 627 | W12: 0.14779328 | X12: Small | Y12: state rolls, precinct
A13: Carbon | B13: BEAVER MEADOWS BOROUGH | C13: BEAVER MEADOWS BOROUGH | D13: =ROUND(S13*T13,0) -> 91 | E13: =ROUND(S13,0)-D13 -> 239 | F13: =IF(COUNTA(D13:E13)=0,"",SUM(D13:E13)) -> 330 | G13: =IF(OR(F13="",F13=0),"",D13/F13) -> 0.27575758 | H13: =IF(OR(F13="",F13=0),"",E13/F13) -> 0.72424242 | I13: random forest (results only) | J13: 3.7104392 | K13: =$K$8 -> 1.2186289 | L13: =SQRT(J13^2+K13^2) -> 3.9054341 | M13: =IF(G13="","",MAX(0,G13-1.96*L13/100)) -> 0.19921107 | N13: =IF(G13="","",MIN(1,G13+1.96*L13/100)) -> 0.35230408 | O13: =ROUND(S13*W13,0) -> 49 | P13: =IF(F13="","",ROUND(SQRT((F13*L13/100)^2+(G13*O13)^2),0)) -> 19 | R13: -23.559984 | S13: =U13*V13*$F$5 -> 330.13014 | T13: =MAX(0,MIN(1,R13/100+$D$5)) -> 0.27510764 | U13: 0.53767123 | V13: 614 | W13: 0.14779328 | X13: Small | Y13: state rolls, precinct
A14: Carbon | B14: BOWMANSTOWN BOROUGH | C14: BOWMANSTOWN BOROUGH | D14: =ROUND(S14*T14,0) -> 112 | E14: =ROUND(S14,0)-D14 -> 244 | F14: =IF(COUNTA(D14:E14)=0,"",SUM(D14:E14)) -> 356 | G14: =IF(OR(F14="",F14=0),"",D14/F14) -> 0.31460674 | H14: =IF(OR(F14="",F14=0),"",E14/F14) -> 0.68539326 | I14: random forest (results only) | J14: 3.7104392 | K14: =$K$8 -> 1.2186289 | L14: =SQRT(J14^2+K14^2) -> 3.9054341 | M14: =IF(G14="","",MAX(0,G14-1.96*L14/100)) -> 0.23806023 | N14: =IF(G14="","",MIN(1,G14+1.96*L14/100)) -> 0.39115325 | O14: =ROUND(S14*W14,0) -> 53 | P14: =IF(F14="","",ROUND(SQRT((F14*L14/100)^2+(G14*O14)^2),0)) -> 22 | R14: -19.445609 | S14: =U14*V14*$F$5 -> 355.63437 | T14: =MAX(0,MIN(1,R14/100+$D$5)) -> 0.31625139 | U14: 0.63619744 | V14: 559 | W14: 0.14779328 | X14: Small | Y14: state rolls, precinct
A15: Carbon | B15: EAST PENN TOWNSHIP | C15: EAST PENN TOWNSHIP-NORTH | D15: =ROUND(S15*T15,0) -> 180 | E15: =ROUND(S15,0)-D15 -> 544 | F15: =IF(COUNTA(D15:E15)=0,"",SUM(D15:E15)) -> 724 | G15: =IF(OR(F15="",F15=0),"",D15/F15) -> 0.24861878 | H15: =IF(OR(F15="",F15=0),"",E15/F15) -> 0.75138122 | I15: random forest (results only) | J15: 2.3729594 | K15: =$K$8 -> 1.2186289 | L15: =SQRT(J15^2+K15^2) -> 2.6675818 | M15: =IF(G15="","",MAX(0,G15-1.96*L15/100)) -> 0.19633418 | N15: =IF(G15="","",MIN(1,G15+1.96*L15/100)) -> 0.30090339 | O15: =ROUND(S15*W15,0) -> 64 | P15: =IF(F15="","",ROUND(SQRT((F15*L15/100)^2+(G15*O15)^2),0)) -> 25 | R15: -26.255514 | S15: =U15*V15*$F$5 -> 724.37791 | T15: =MAX(0,MIN(1,R15/100+$D$5)) -> 0.24815234 | U15: 0.67635659 | V15: 1071 | W15: 0.088236166 | X15: Medium | Y15: state rolls, precinct
A16: Carbon | B16: EAST PENN TOWNSHIP | C16: EAST PENN TOWNSHIP-SOUTH | D16: =ROUND(S16*T16,0) -> 165 | E16: =ROUND(S16,0)-D16 -> 446 | F16: =IF(COUNTA(D16:E16)=0,"",SUM(D16:E16)) -> 611 | G16: =IF(OR(F16="",F16=0),"",D16/F16) -> 0.2700491 | H16: =IF(OR(F16="",F16=0),"",E16/F16) -> 0.7299509 | I16: random forest (results only) | J16: 2.3729594 | K16: =$K$8 -> 1.2186289 | L16: =SQRT(J16^2+K16^2) -> 2.6675818 | M16: =IF(G16="","",MAX(0,G16-1.96*L16/100)) -> 0.2177645 | N16: =IF(G16="","",MIN(1,G16+1.96*L16/100)) -> 0.3223337 | O16: =ROUND(S16*W16,0) -> 54 | P16: =IF(F16="","",ROUND(SQRT((F16*L16/100)^2+(G16*O16)^2),0)) -> 22 | R16: -24.093993 | S16: =U16*V16*$F$5 -> 610.89237 | T16: =MAX(0,MIN(1,R16/100+$D$5)) -> 0.26976755 | U16: 0.62591432 | V16: 976 | W16: 0.088236166 | X16: Medium | Y16: state rolls, precinct
A17: Carbon | B17: EAST SIDE BOROUGH | C17: EAST SIDE BOROUGH | D17: =ROUND(S17*T17,0) -> 31 | E17: =ROUND(S17,0)-D17 -> 62 | F17: =IF(COUNTA(D17:E17)=0,"",SUM(D17:E17)) -> 93 | G17: =IF(OR(F17="",F17=0),"",D17/F17) -> 0.33333333 | H17: =IF(OR(F17="",F17=0),"",E17/F17) -> 0.66666667 | I17: random forest (results only) | J17: 3.7104392 | K17: =$K$8 -> 1.2186289 | L17: =SQRT(J17^2+K17^2) -> 3.9054341 | M17: =IF(G17="","",MAX(0,G17-1.96*L17/100)) -> 0.25678682 | N17: =IF(G17="","",MIN(1,G17+1.96*L17/100)) -> 0.40987984 | O17: =ROUND(S17*W17,0) -> 14 | P17: =IF(F17="","",ROUND(SQRT((F17*L17/100)^2+(G17*O17)^2),0)) -> 6 | R17: -17.924857 | S17: =U17*V17*$F$5 -> 93.426829 | T17: =MAX(0,MIN(1,R17/100+$D$5)) -> 0.33145891 | U17: 0.57317073 | V17: 163 | W17: 0.14779328 | X17: Small | Y17: state rolls, precinct
A18: Carbon | B18: FRANKLIN TOWNSHIP | C18: FRANKLIN TOWNSHIP-HARRITY | D18: =ROUND(S18*T18,0) -> 229 | E18: =ROUND(S18,0)-D18 -> 624 | F18: =IF(COUNTA(D18:E18)=0,"",SUM(D18:E18)) -> 853 | G18: =IF(OR(F18="",F18=0),"",D18/F18) -> 0.26846424 | H18: =IF(OR(F18="",F18=0),"",E18/F18) -> 0.73153576 | I18: random forest (results only) | J18: 2.3729594 | K18: =$K$8 -> 1.2186289 | L18: =SQRT(J18^2+K18^2) -> 2.6675818 | M18: =IF(G18="","",MAX(0,G18-1.96*L18/100)) -> 0.21617964 | N18: =IF(G18="","",MIN(1,G18+1.96*L18/100)) -> 0.32074885 | O18: =ROUND(S18*W18,0) -> 75 | P18: =IF(F18="","",ROUND(SQRT((F18*L18/100)^2+(G18*O18)^2),0)) -> 30 | R18: -24.166982 | S18: =U18*V18*$F$5 -> 852.99444 | T18: =MAX(0,MIN(1,R18/100+$D$5)) -> 0.26903765 | U18: 0.66640191 | V18: 1280 | W18: 0.088236166 | X18: Medium | Y18: state rolls, precinct
A19: Carbon | B19: FRANKLIN TOWNSHIP | C19: FRANKLIN TOWNSHIP-IND DIST | D19: =ROUND(S19*T19,0) -> 116 | E19: =ROUND(S19,0)-D19 -> 332 | F19: =IF(COUNTA(D19:E19)=0,"",SUM(D19:E19)) -> 448 | G19: =IF(OR(F19="",F19=0),"",D19/F19) -> 0.25892857 | H19: =IF(OR(F19="",F19=0),"",E19/F19) -> 0.74107143 | I19: random forest (results only) | J19: 3.7104392 | K19: =$K$8 -> 1.2186289 | L19: =SQRT(J19^2+K19^2) -> 3.9054341 | M19: =IF(G19="","",MAX(0,G19-1.96*L19/100)) -> 0.18238206 | N19: =IF(G19="","",MIN(1,G19+1.96*L19/100)) -> 0.33547508 | O19: =ROUND(S19*W19,0) -> 66 | P19: =IF(F19="","",ROUND(SQRT((F19*L19/100)^2+(G19*O19)^2),0)) -> 24 | R19: -25.0896 | S19: =U19*V19*$F$5 -> 447.93932 | T19: =MAX(0,MIN(1,R19/100+$D$5)) -> 0.25981148 | U19: 0.55097087 | V19: 813 | W19: 0.14779328 | X19: Small | Y19: state rolls, precinct
A20: Carbon | B20: FRANKLIN TOWNSHIP | C20: FRANKLIN TOWNSHIP-LONG RUN | D20: =ROUND(S20*T20,0) -> 179 | E20: =ROUND(S20,0)-D20 -> 504 | F20: =IF(COUNTA(D20:E20)=0,"",SUM(D20:E20)) -> 683 | G20: =IF(OR(F20="",F20=0),"",D20/F20) -> 0.26207906 | H20: =IF(OR(F20="",F20=0),"",E20/F20) -> 0.73792094 | I20: random forest (results only) | J20: 2.3729594 | K20: =$K$8 -> 1.2186289 | L20: =SQRT(J20^2+K20^2) -> 2.6675818 | M20: =IF(G20="","",MAX(0,G20-1.96*L20/100)) -> 0.20979446 | N20: =IF(G20="","",MIN(1,G20+1.96*L20/100)) -> 0.31436367 | O20: =ROUND(S20*W20,0) -> 60 | P20: =IF(F20="","",ROUND(SQRT((F20*L20/100)^2+(G20*O20)^2),0)) -> 24 | R20: -24.90423 | S20: =U20*V20*$F$5 -> 683.32677 | T20: =MAX(0,MIN(1,R20/100+$D$5)) -> 0.26166518 | U20: 0.65452756 | V20: 1044 | W20: 0.088236166 | X20: Medium | Y20: state rolls, precinct
A21: Carbon | B21: JIM THORPE BOROUGH | C21: JIM THORPE BOROUGH-1ST | D21: =ROUND(S21*T21,0) -> 193 | E21: =ROUND(S21,0)-D21 -> 243 | F21: =IF(COUNTA(D21:E21)=0,"",SUM(D21:E21)) -> 436 | G21: =IF(OR(F21="",F21=0),"",D21/F21) -> 0.44266055 | H21: =IF(OR(F21="",F21=0),"",E21/F21) -> 0.55733945 | I21: random forest (results only) | J21: 3.7104392 | K21: =$K$8 -> 1.2186289 | L21: =SQRT(J21^2+K21^2) -> 3.9054341 | M21: =IF(G21="","",MAX(0,G21-1.96*L21/100)) -> 0.36611404 | N21: =IF(G21="","",MIN(1,G21+1.96*L21/100)) -> 0.51920706 | O21: =ROUND(S21*W21,0) -> 64 | P21: =IF(F21="","",ROUND(SQRT((F21*L21/100)^2+(G21*O21)^2),0)) -> 33 | R21: -6.8428827 | S21: =U21*V21*$F$5 -> 436.24467 | T21: =MAX(0,MIN(1,R21/100+$D$5)) -> 0.44227865 | U21: 0.62588905 | V21: 697 | W21: 0.14779328 | X21: Small | Y21: state rolls, precinct
A22: Carbon | B22: JIM THORPE BOROUGH | C22: JIM THORPE BOROUGH-2ND | D22: =ROUND(S22*T22,0) -> 119 | E22: =ROUND(S22,0)-D22 -> 161 | F22: =IF(COUNTA(D22:E22)=0,"",SUM(D22:E22)) -> 280 | G22: =IF(OR(F22="",F22=0),"",D22/F22) -> 0.425 | H22: =IF(OR(F22="",F22=0),"",E22/F22) -> 0.575 | I22: random forest (results only) | J22: 3.7104392 | K22: =$K$8 -> 1.2186289 | L22: =SQRT(J22^2+K22^2) -> 3.9054341 | M22: =IF(G22="","",MAX(0,G22-1.96*L22/100)) -> 0.34845349 | N22: =IF(G22="","",MIN(1,G22+1.96*L22/100)) -> 0.50154651 | O22: =ROUND(S22*W22,0) -> 41 | P22: =IF(F22="","",ROUND(SQRT((F22*L22/100)^2+(G22*O22)^2),0)) -> 21 | R22: -8.7745582 | S22: =U22*V22*$F$5 -> 280.5 | T22: =MAX(0,MIN(1,R22/100+$D$5)) -> 0.4229619 | U22: 0.56896552 | V22: 493 | W22: 0.14779328 | X22: Small | Y22: state rolls, precinct
A23: Carbon | B23: JIM THORPE BOROUGH | C23: JIM THORPE BOROUGH-3RD | D23: =ROUND(S23*T23,0) -> 248 | E23: =ROUND(S23,0)-D23 -> 398 | F23: =IF(COUNTA(D23:E23)=0,"",SUM(D23:E23)) -> 646 | G23: =IF(OR(F23="",F23=0),"",D23/F23) -> 0.38390093 | H23: =IF(OR(F23="",F23=0),"",E23/F23) -> 0.61609907 | I23: random forest (results only) | J23: 2.3729594 | K23: =$K$8 -> 1.2186289 | L23: =SQRT(J23^2+K23^2) -> 2.6675818 | M23: =IF(G23="","",MAX(0,G23-1.96*L23/100)) -> 0.33161632 | N23: =IF(G23="","",MIN(1,G23+1.96*L23/100)) -> 0.43618553 | O23: =ROUND(S23*W23,0) -> 57 | P23: =IF(F23="","",ROUND(SQRT((F23*L23/100)^2+(G23*O23)^2),0)) -> 28 | R23: -12.665571 | S23: =U23*V23*$F$5 -> 645.69536 | T23: =MAX(0,MIN(1,R23/100+$D$5)) -> 0.38405177 | U23: 0.68984547 | V23: 936 | W23: 0.088236166 | X23: Medium | Y23: state rolls, precinct
... A381: Northampton | B381: WIND GAP | C381: WIND GAP | D381: =ROUND(S381*T381,0) -> 490 | E381: =ROUND(S381,0)-D381 -> 655 | F381: =IF(COUNTA(D381:E381)=0,"",SUM(D381:E381)) -> 1145 | G381: =IF(OR(F381="",F381=0),"",D381/F381) -> 0.4279476 | H381: =IF(OR(F381="",F381=0),"",E381/F381) -> 0.5720524 | I381: random forest (results only) | J381: 1.8855282 | K381: =$K$8 -> 1.2186289 | L381: =SQRT(J381^2+K381^2) -> 2.2450552 | M381: =IF(G381="","",MAX(0,G381-1.96*L381/100)) -> 0.38394452 | N381: =IF(G381="","",MIN(1,G381+1.96*L381/100)) -> 0.47195068 | O381: =ROUND(S381*W381,0) -> 78 | P381: =IF(F381="","",ROUND(SQRT((F381*L381/100)^2+(G381*O381)^2),0)) -> 42 | R381: -8.3179097 | S381: =U381*V381*$F$5 -> 1145.4806 | T381: =MAX(0,MIN(1,R381/100+$D$5)) -> 0.42752838 | U381: 0.53702795 | V381: 2133 | W381: 0.067815102 | X381: Large | Y381: state rolls, precinct

Sheet How Forecasts Are Weighted
A1: How the three precinct-level forecasts weigh their inputs (SHAP) — results-only random forests
A3: Forecast A — Full random forest.
A4: All 23 candidate inputs go into one random forest that forecasts the Democratic share. Nothing is weighted by hand; SHAP measures what the forest learned. This is the reference.
A5: Forecast B — SHAP-selected forest.
A6: Keeps only inputs whose average |SHAP| beat all 10 random columns in at least 18 of 20 refits and that held at least 2% of Forecast A’s SHAP total (6 of 23 kept), then refits the forest on them. Weight that was spread thinly over weak inputs is concentrated on the strong ones.
A7: Forecast C — SHAP family-reweighted forest.
A8: Keeps Forecast A’s forest but multiplies each input family’s SHAP values by a weight fitted to how well that family predicted elections the forest had not seen (leave-one-election-out, fitted within each election). Families under 3% of SHAP stay at ×1; others are limited to ×0.5–×2 because there are only three training elections.
A9: Backtests.
A10: Each 2024 backtest uses its own forecast’s weighting: A’s full input set, B’s selected inputs, and C’s exact family weights — refit only on 2020 and 2022.
A11: Turnout.
A12: Not modelled in any forecast: votes cast = each place’s 2022 turnout rate × its 2026 registered voters (2020 turnout × 2024 registered in the backtest). All differences between A, B and C come from the results model.
A14: Family share of SHAP value in votes, 2026 forecast rows
A15: Input family | B15: Forecast A | C15: Forecast B | D15: Forecast C | E15: Forecast C weight (×)
A16: Election type | B16: 0.0012953602 | C16: 0 | D16: 0.0012389737 | E16: 1
A17: Geography & municipal context | B17: 0.030777014 | C17: 0 | D17: 0.029437303 | E17: 1
A18: Historical voter data | B18: 0.73043895 | C18: 0.70204884 | D18: 0.81714939 | E18: 1.1696232
A19: Voter registration data | B19: 0.23748868 | C19: 0.29795116 | D19: 0.15217433 | E19: 0.66992619
A20: Out-of-fold pattern error before → after Forecast C’s re-weighting: 3.20 → 3.08 points.
A22: Top inputs in each forecast (share of SHAP value in votes)
A23: # | B23: Forecast A | C23: Share | D23: Forecast B | E23: Share | F23: Forecast C | G23: Share
A24: 1 | B24: Precinct House lean, last election (t−2) | C24: 0.32339513 | D24: Precinct House lean, last election (t−2) | E24: 0.21105414 | F24: Precinct House lean, last election (t−2) | G24: 0.36178538
A25: 2 | B25: Electorate last election: R % of ballots | C25: 0.19395967 | D25: Municipality House lean, last election (t−2) | E25: 0.18802891 | F25: Electorate last election: R % of ballots | G25: 0.21698463
A26: 3 | B26: Municipality House lean, last election (t−2) | C26: 0.15495316 | D26: Electorate last election: R % of ballots | E26: 0.16872764 | F26: Municipality House lean, last election (t−2) | G26: 0.17334765
A27: 4 | B27: State registration: R % (as of election) | C27: 0.10710037 | D27: State registration: R % (as of election) | E27: 0.15795358 | F27: State registration: R % (as of election) | G27: 0.068626125
A28: 5 | B28: State registration: D % (as of election) | C28: 0.069696116 | D28: State registration: D % (as of election) | E28: 0.13999758 | F28: Precinct House lean, last same-type election (t−4) | G28: 0.051334404
A29: 6 | B29: Precinct House lean, last same-type election (t−4) | C29: 0.04588714 | D29: Precinct House lean, last same-type election (t−4) | E29: 0.13423815 | F29: State registration: D % (as of election) | G29: 0.044658803
A30: 7 | B30: State registration: change in D−R margin since t−2 | C30: 0.023030423 | F30: State registration: change in D−R margin since t−2 | G30: 0.01475708
A31: 8 | B31: County: Carbon | C31: 0.013975294 | F31: County: Carbon | G31: 0.013366955
A32: 9 | B32: Precinct vs. its municipality, last election (pts) | C32: 0.012367595 | F32: Precinct vs. its municipality, last election (pts) | G32: 0.011829239
A33: 10 | B33: Voter-file party switch gap (today’s R % − state R %) | C33: 0.01173328 | F33: Voter-file party switch gap (today’s R % − state R %) | G33: 0.0075182702
A35: Forecast B — random-column test and selection
A36: Input | B36: Beat random columns (of 20) | C36: Share of SHAP in A | D36: Kept in B?
A37: Precinct House lean, last election (t−2) | B37: 20 | C37: 0.33256994 | D37: Yes
A38: Electorate last election: R % of ballots | B38: 20 | C38: 0.19581568 | D38: Yes
A39: Municipality House lean, last election (t−2) | B39: 20 | C39: 0.15379393 | D39: Yes
A40: State registration: R % (as of election) | B40: 20 | C40: 0.10618256 | D40: Yes
A41: State registration: D % (as of election) | B41: 20 | C41: 0.066351754 | D41: Yes
A42: Precinct House lean, last same-type election (t−4) | B42: 20 | C42: 0.045028211 | D42: Yes
A43: State registration: change in D−R margin since t−2 | B43: 20 | C43: 0.019772857 | D43: No
A44: County: Carbon | B44: 20 | C44: 0.013690227 | D44: No
...

Sheet Feature Ranking A
A1: Rank | B1: Feature | C1: Input family | D1: Share of model | E1: Share within its family | F1: SHAP value in votes | G1: Used to forecast | H1: Significance test result | I1: Variable (short name) | J1: Status in Forecast B
A2: 1 | B2: Democratic percent of the two-party House vote, 2024 (certified precinct results), above or below the district average | C2: Historical voter data | D2: 0.32339513 | E2: 0.4427408 | F2: 58.969595 | G2: Democratic percent of the two-party vote | H2: Beat all 10 random comparison columns in 20 of 20 refits. | I2: Precinct House lean, last election (t−2) | J2: Kept in B
A3: 2 | B3: Registered Republicans as a percent of everyone who voted, 2024 (voter file) | C3: Historical voter data | D3: 0.19395967 | E3: 0.26553851 | F3: 35.367642 | G3: Democratic percent of the two-party vote | H3: Beat all 10 random comparison columns in 20 of 20 refits. | I3: Electorate last election: R % of ballots | J3: Kept in B
A4: 3 | B4: Democratic percent of the two-party House vote in the precinct’s whole municipality, 2024, above or below the district average | C4: Historical voter data | D4: 0.15495316 | E4: 0.21213704 | F4: 28.254986 | G4: Democratic percent of the two-party vote | H4: Beat all 10 random comparison columns in 20 of 20 refits. | I4: Municipality House lean, last election (t−2) | J4: Kept in B
A5: 4 | B5: Registered Republicans as a percent of all registered voters, 2026 primary rolls (Department of State) | C5: Voter registration data | D5: 0.10710037 | E5: 0.45097043 | F5: 19.529253 | G5: Democratic percent of the two-party vote | H5: Beat all 10 random comparison columns in 20 of 20 refits. | I5: State registration: R % (as of election) | J5: Kept in B
A6: 5 | B6: Registered Democrats as a percent of all registered voters, 2026 primary rolls (Department of State) | C6: Voter registration data | D6: 0.069696116 | E6: 0.29347133 | F6: 12.708762 | G6: Democratic percent of the two-party vote | H6: Beat all 10 random comparison columns in 20 of 20 refits. | I6: State registration: D % (as of election) | J6: Kept in B
A7: 6 | B7: Democratic percent of the two-party House vote, 2022 — the last midterm (certified precinct results), above or below the district average | C7: Historical voter data | D7: 0.04588714 | E7: 0.062821321 | F7: 8.3673061 | G7: Democratic percent of the two-party vote | H7: Beat all 10 random comparison columns in 20 of 20 refits. | I7: Precinct House lean, last same-type election (t−4) | J7: Kept in B
A8: 7 | B8: Change in registered Democrats minus Republicans (percent of registered) from the 2024 general to the 2026 primary (Department of State) | C8: Voter registration data | D8: 0.023030423 | E8: 0.096974828 | F8: 4.1994904 | G8: Democratic percent of the two-party vote | H8: Beat all 10 random comparison columns in 20 of 20 refits. | I8: State registration: change in D−R margin since t−2 | J8: Dropped from B
A9: 8 | B9: Precinct is in Carbon County (1/0) | C9: Geography & municipal context | D9: 0.013975294 | E9: 0.4540822 | F9: 2.5483297 | G9: Democratic percent of the two-party vote | H9: Beat all 10 random comparison columns in 20 of 20 refits. | I9: County: Carbon | J9: Dropped from B
A10: 9 | B10: Precinct’s 2024 House Democratic percent minus its municipality’s, in points | C10: Geography & municipal context | D10: 0.012367595 | E10: 0.4018452 | F10: 2.2551734 | G10: Democratic percent of the two-party vote | H10: Beat all 10 random comparison columns in 20 of 20 refits. | I10: Precinct vs. its municipality, last election (pts) | J10: Dropped from B
