Workbook

Sheet Scenario & Comparison
A1: PA-07 2026 House Forecast — Precinct Level: three results-only random-forest forecasts (fixed baseline)
A2: Candidates: Brooks | Mackenzie | The two yellow cells set the district-wide Brooks share and votes cast; all three forecasts update.
A3: A, B and C weight the same random-forest inputs differently using SHAP (see How Forecasts Are Weighted). Each is backtested on 2024 with its own weights; those errors are the error terms.
A5: SCENARIO INPUTS (defaults are built from the tables below; type over them to run another scenario)
A6: District-wide Brooks share of the two-party vote (input) | C6: =C21 -> 0.49515845 | D6: ← default: registration-adjusted baseline (row 21)
A7: Turnout multiplier (input; 1.00 = each place keeps its 2022 turnout rate) | C7: 1 | D7: ← votes cast = 2022 turnout rate × 2026 registered voters × this multiplier (row 27)
A9: HOW THE DEFAULTS ARE BUILT (today’s map applied to every year — all municipalities and precincts, as if the district had always included them)
A10: Election | C10: Democratic share | D10: Democratic votes | E10: Republican votes | F10: Registered (state rolls) | G10: Dem share of two-party registration
A11: 2018 General | C11: =D11/(D11+E11) -> 0.53259004 | D11: 136790.36 | E11: 120049.52 | F11: 483877 | G11: 0.56798799
A12: 2020 General | C12: =D12/(D12+E12) -> 0.4960879 | D12: 188855.71 | E12: 191834.3 | F12: 518873 | G12: 0.55685758
A13: 2022 General | C13: =D13/(D13+E13) -> 0.50896572 | D13: 149243 | E13: 143985 | F13: 510119 | G13: 0.54766474
A14: 2024 General | C14: =D14/(D14+E14) -> 0.49424813 | D14: 196561 | E14: 201136 | F14: 535177 | G14: 0.52758258
A15: 2026 Primary rolls | F15: 517956 | G15: 0.52223425
A16: Source: certified precinct House returns and Department of State registration (PA07_Precinct_Data.xlsx). 2018/2020 count Carbon (then PA-09) and Polk (then PA-08) as district results and include an estimate for Ross One, so every year covers the same territory as 2026.
A18: Average Democratic share, 2022 and 2024 | C18: =AVERAGE(C13,C14) -> 0.50160693
A19: Change in Dem share of two-party registration since then (pts) | C19: =(G15-AVERAGE(G13,G14))*100 -> -1.5389407
A20: Registration-to-vote link (k), measured on precinct changes 2018→2022 and 2020→2024 | C20: 0.41902062 | D20: Within-district slope: precincts whose registration moved 1 pt toward a party moved about this many pts in vote share (national swing removed).
A21: Registration-adjusted baseline for 2026 = row 18 + k × row 19 | C21: =C18+C20*C19/100 -> 0.49515845
A23: 2022 turnout in today’s district (House votes ÷ registered voters) | C23: 0.56494828
A24: 2026 registered voters (state rolls, summed over precincts) | C24: 538584.71
A25: District check: 2022 turnout × 2026 registered | C25: =C23*C24 -> 304272.51
A26: Rule applied precinct by precinct (each place’s own 2022 turnout × its 2026 registered) and summed | C26: 306117.6 | D26: Each place uses its own 2022 turnout rate, so the summed total differs slightly from the district-level check. Registration: Department of State rolls (2026 primary).
A27: Votes cast used in the forecasts (row 26 × turnout multiplier) | C27: =C26*C7 -> 306117.6
A29: DISTRICT TOTALS BY FORECAST, WITH ERROR TERMS (live from each forecast tab)
A30: Forecast | B30: Weighting | C30: Brooks votes | D30: Mackenzie votes | E30: Total votes | F30: Brooks share | G30: Error term, share (± pts) | H30: Brooks share, 95% range | I30: Error term, votes cast (±) | J30: Error term, Brooks votes (±)
A31: Forecast A | B31: Full random forest | C31: ='2026 Forecast A'!D8 -> 151580 | D31: ='2026 Forecast A'!E8 -> 154533 | E31: ='2026 Forecast A'!F8 -> 306113 | F31: ='2026 Forecast A'!G8 -> 0.49517662 | G31: ='2026 Forecast A'!L8 -> 0.29703023 | H31: =TEXT('2026 Forecast A'!M8,"0.0%")&" – "&TEXT('2026 Forecast A'!N8,"0.0%") -> 48.9% – 50.1% | I31: ='2026 Forecast A'!O8 -> 13579 | J31: ='2026 Forecast A'!P8 -> 6785
A32: Forecast B | B32: SHAP-selected forest | C32: ='2026 Forecast B'!D8 -> 151578 | D32: ='2026 Forecast B'!E8 -> 154535 | E32: ='2026 Forecast B'!F8 -> 306113 | F32: ='2026 Forecast B'!G8 -> 0.49517008 | G32: ='2026 Forecast B'!L8 -> 0.29793824 | H32: =TEXT('2026 Forecast B'!M8,"0.0%")&" – "&TEXT('2026 Forecast B'!N8,"0.0%") -> 48.9% – 50.1% | I32: ='2026 Forecast B'!O8 -> 13579 | J32: ='2026 Forecast B'!P8 -> 6785
A33: Forecast C | B33: SHAP family-reweighted forest | C33: ='2026 Forecast C'!D8 -> 151570 | D33: ='2026 Forecast C'!E8 -> 154543 | E33: ='2026 Forecast C'!F8 -> 306113 | F33: ='2026 Forecast C'!G8 -> 0.49514395 | G33: ='2026 Forecast C'!L8 -> 0.29619762 | H33: =TEXT('2026 Forecast C'!M8,"0.0%")&" – "&TEXT('2026 Forecast C'!N8,"0.0%") -> 48.9% – 50.1% | I33: ='2026 Forecast C'!O8 -> 13579 | J33: ='2026 Forecast C'!P8 -> 6784
A34: District error terms = root-mean-square of the district-wide misses in the 2022 and 2024 backtests. With only two test elections this understates real election-environment risk (a national swing of several points is plausible); treat the 95% range as a floor on uncertainty.
A36: ERROR TERMS IN THE BACKTESTS (same weights as the forecasts)
A37: Forecast | B37: Backtest | C37: District Dem share miss (pts) | D37: Dem votes miss | E37: Rep votes miss | F37: Votes cast miss | G37: Pattern RMS miss per row (pts) | H37: RMS miss per row (pts) | I37: Avg error term set beforehand (± pts) | J37: Actual inside ±1 error term | K37: Actual inside 95% range | L37: Rows within 3 pts
A38: Forecast A | B38: 2022 (trained on 2020 only) | C38: -0.39591437 | D38: -0.069808737 | E38: -0.054958465 | F38: -0.062480511 | G38: 2.712939 | H38: 2.8567118 | I38: — | J38: — | K38: — | L38: 0.73469388
A39: Forecast A | B39: 2024 (trained on 2020–2022) | C39: ='2024 Backtest A'!F380 -> -0.14037708 | D39: ='2024 Backtest A'!F382 -> -0.008474299 | E39: ='2024 Backtest A'!F383 -> -0.0028894559 | F39: ='2024 Backtest A'!F384 -> -0.0056374384 | G39: ='2024 Backtest A'!F381 -> 2.3303597 | H39: ='2024 Backtest A'!F379 -> 2.3210184 | I39: ='2024 Backtest A'!F385 -> 2.6598299 | J39: ='2024 Backtest A'!F386 -> 0.80701754 | K39: ='2024 Backtest A'!F387 -> 0.97076023 | L39: ='2024 Backtest A'!F388 -> 0.84795322
A40: Forecast B | B40: 2022 (trained on 2020 only) | C40: -0.39784494 | D40: -0.069844394 | E40: -0.054921708 | F40: -0.062480511 | G40: 2.7310093 | H40: 2.8393922 | I40: — | J40: — | K40: — | L40: 0.73469388
A41: Forecast B | B41: 2024 (trained on 2020–2022) | C41: ='2024 Backtest B'!F380 -> -0.13875803 | D41: ='2024 Backtest B'!F382 -> -0.0084415797 | E41: ='2024 Backtest B'!F383 -> -0.0029211501 | F41: ='2024 Backtest B'!F384 -> -0.0056374384 | G41: ='2024 Backtest B'!F381 -> 2.3564449 | H41: ='2024 Backtest B'!F379 -> 2.3461602 | I41: ='2024 Backtest B'!F385 -> 2.733822 | J41: ='2024 Backtest B'!F386 -> 0.80116959 | K41: ='2024 Backtest B'!F387 -> 0.97368421 | L41: ='2024 Backtest B'!F388 -> 0.83918129
A42: Forecast C | B42: 2022 (trained on 2020 only) | C42: -0.39514215 | D42: -0.069794475 | E42: -0.054973168 | F42: -0.062480511 | G42: 2.8010244 | H42: 2.9365813 | I42: — | J42: — | K42: — | L42: 0.73469388
A43: Forecast C | B43: 2024 (trained on 2020–2022) | C43: ='2024 Backtest C'!F380 -> -0.13902787 | D43: ='2024 Backtest C'!F382 -> -0.0084470329 | E43: ='2024 Backtest C'!F383 -> -0.0029158677 | F43: ='2024 Backtest C'!F384 -> -0.0056374384 | G43: ='2024 Backtest C'!F381 -> 2.7382631 | H43: ='2024 Backtest C'!F379 -> 2.729161 | I43: ='2024 Backtest C'!F385 -> 2.7511955 | J43: ='2024 Backtest C'!F386 -> 0.76023392 | K43: ='2024 Backtest C'!F387 -> 0.95321637 | L43: ='2024 Backtest C'!F388 -> 0.78070175
A44: The 2024 error terms were fixed before looking at 2024 (built from the 2022 backtest). Coverage above the ≈68% / ≈95% targets means the error terms are, if anything, conservative. The 2022 backtest had only one training election (2020), so its pattern errors are larger. 2026 error terms pool both backtests.
A46: WHY THE WEIGHTS DIFFER BUT THE FORECASTS LOOK THE SAME
A47: 1. District totals are identical by design.
...

Sheet 2026 Forecast A
A1: PA-07 2026 House Forecast — Precinct-Level Predictions (Forecast A: full random forest)
A2: Candidates: Brooks | Mackenzie | District totals (yellow) are formulas over the precinct rows.
A3: Only the results are modelled (one random forest). Votes cast in each row = its 2022 turnout rate (House votes ÷ registered voters) × its 2026 registered voters. Brooks votes = votes cast × forecast Brooks share. Error terms combine the place’s own pattern error, the district-wide error and turnout error, measured on the 2022 and 2024 backtests.
A4: Model / scenario | B4: Random forest on results — Forecast A (Full random forest), precinct model; turnout = 2022 turnout rate × 2026 registered voters | C4: As-of date | D4: 46300 | E4: Prepared by | F4: Max | G4: Version | H4: v6.0 (current map, all years; results only; 2022 turnout × 2026 registration)
A5: District Brooks share (scenario) | B5: ='Scenario & Comparison'!$C$6 -> 0.49515845 | C5: Uniform shift applied | D5: =B5-SUMPRODUCT(R12:R381,S12:S381)/SUM(S12:S381)/100 -> 0.50805505 | E5: Turnout multiplier (1.00 = 2022 turnout) | F5: ='Scenario & Comparison'!$C$7 -> 1
A6: DISTRICT TOTALS (auto-sum — do not type over)
A7: Geography | B7: (muni) | C7: (precinct) | D7: Brooks votes | E7: Mackenzie votes | F7: Total votes | G7: Brooks share | H7: Mackenzie share | I7: Notes | J7: Error term: place pattern (± pts) | K7: Error term: district-wide (± pts) | L7: Error term: total (± pts) | M7: Brooks share, 95% low | N7: Brooks share, 95% high | O7: Error term: votes cast (± votes) | P7: Error term: Brooks votes (± votes)
A8: PA-07 District | B8: (all precincts) | D8: =SUM(D12:D381) -> 151580 | E8: =SUM(E12:E381) -> 154533 | F8: =D8+E8 -> 306113 | G8: =IF(F8=0,"",D8/F8) -> 0.49517662 | H8: =IF(F8=0,"",E8/F8) -> 0.50482338 | I8: Headline forecast for the briefing | J8: 0 | K8: 0.29703023 | L8: =SQRT(J8^2+K8^2) -> 0.29703023 | M8: =G8-1.96*L8/100 -> 0.48935483 | N8: =G8+1.96*L8/100 -> 0.50099841 | O8: =ROUND(F8*0.04436,0) -> 13579 | P8: =ROUND(SQRT((F8*L8/100)^2+(G8*O8)^2),0) -> 6785
A9: Error terms are ±1 standard error built from the 2022 and 2024 backtests (pattern error by place size; district-wide error; turnout error). 95% low/high = Brooks share ± 1.96 × total error term. Only two test elections — the district-wide term understates real election-environment risk.
A10: PRECINCT DETAIL | R10: MODEL INPUTS (from the random forest — do not edit)
A11: County | B11: Municipality | C11: Precinct | D11: Brooks votes | E11: Mackenzie votes | F11: Total votes | G11: Brooks share | H11: Mackenzie share | I11: Notes / source method | J11: Error term: place pattern (± pts) | K11: Error term: district-wide (± pts) | L11: Error term: total (± pts) | M11: Brooks share, 95% low | N11: Brooks share, 95% high | O11: Error term: votes cast (± votes) | P11: Error term: Brooks votes (± votes) | R11: Model lean vs district (pts) | S11: Votes cast = 2022 turnout × 2026 registered | T11: Forecast Brooks share (unrounded) | U11: 2022 turnout (House votes ÷ registered) | V11: 2026 registered voters | W11: Votes-cast error (% of votes) | X11: Size group (backtest error band) | Y11: Registration source
A12: Carbon | B12: BANKS TOWNSHIP | C12: BANKS TOWNSHIP | D12: =ROUND(S12*T12,0) -> 151 | E12: =ROUND(S12,0)-D12 -> 213 | F12: =IF(COUNTA(D12:E12)=0,"",SUM(D12:E12)) -> 364 | G12: =IF(OR(F12="",F12=0),"",D12/F12) -> 0.41483516 | H12: =IF(OR(F12="",F12=0),"",E12/F12) -> 0.58516484 | I12: random forest (results only) | J12: 3.4204608 | K12: =$K$8 -> 0.29703023 | L12: =SQRT(J12^2+K12^2) -> 3.4333335 | M12: =IF(G12="","",MAX(0,G12-1.96*L12/100)) -> 0.34754183 | N12: =IF(G12="","",MIN(1,G12+1.96*L12/100)) -> 0.4821285 | O12: =ROUND(S12*W12,0) -> 54 | P12: =IF(F12="","",ROUND(SQRT((F12*L12/100)^2+(G12*O12)^2),0)) -> 26 | R12: -9.3825015 | S12: =U12*V12*$F$5 -> 364.49096 | T12: =MAX(0,MIN(1,R12/100+$D$5)) -> 0.41423003 | U12: 0.5813253 | V12: 627 | W12: 0.14809733 | X12: Small | Y12: state rolls, precinct
A13: Carbon | B13: BEAVER MEADOWS BOROUGH | C13: BEAVER MEADOWS BOROUGH | D13: =ROUND(S13*T13,0) -> 96 | E13: =ROUND(S13,0)-D13 -> 234 | F13: =IF(COUNTA(D13:E13)=0,"",SUM(D13:E13)) -> 330 | G13: =IF(OR(F13="",F13=0),"",D13/F13) -> 0.29090909 | H13: =IF(OR(F13="",F13=0),"",E13/F13) -> 0.70909091 | I13: random forest (results only) | J13: 3.4204608 | K13: =$K$8 -> 0.29703023 | L13: =SQRT(J13^2+K13^2) -> 3.4333335 | M13: =IF(G13="","",MAX(0,G13-1.96*L13/100)) -> 0.22361575 | N13: =IF(G13="","",MIN(1,G13+1.96*L13/100)) -> 0.35820243 | O13: =ROUND(S13*W13,0) -> 49 | P13: =IF(F13="","",ROUND(SQRT((F13*L13/100)^2+(G13*O13)^2),0)) -> 18 | R13: -21.723744 | S13: =U13*V13*$F$5 -> 330.13014 | T13: =MAX(0,MIN(1,R13/100+$D$5)) -> 0.29081761 | U13: 0.53767123 | V13: 614 | W13: 0.14809733 | X13: Small | Y13: state rolls, precinct
A14: Carbon | B14: BOWMANSTOWN BOROUGH | C14: BOWMANSTOWN BOROUGH | D14: =ROUND(S14*T14,0) -> 115 | E14: =ROUND(S14,0)-D14 -> 241 | F14: =IF(COUNTA(D14:E14)=0,"",SUM(D14:E14)) -> 356 | G14: =IF(OR(F14="",F14=0),"",D14/F14) -> 0.32303371 | H14: =IF(OR(F14="",F14=0),"",E14/F14) -> 0.67696629 | I14: random forest (results only) | J14: 3.4204608 | K14: =$K$8 -> 0.29703023 | L14: =SQRT(J14^2+K14^2) -> 3.4333335 | M14: =IF(G14="","",MAX(0,G14-1.96*L14/100)) -> 0.25574037 | N14: =IF(G14="","",MIN(1,G14+1.96*L14/100)) -> 0.39032704 | O14: =ROUND(S14*W14,0) -> 53 | P14: =IF(F14="","",ROUND(SQRT((F14*L14/100)^2+(G14*O14)^2),0)) -> 21 | R14: -18.412818 | S14: =U14*V14*$F$5 -> 355.63437 | T14: =MAX(0,MIN(1,R14/100+$D$5)) -> 0.32392687 | U14: 0.63619744 | V14: 559 | W14: 0.14809733 | X14: Small | Y14: state rolls, precinct
A15: Carbon | B15: EAST PENN TOWNSHIP | C15: EAST PENN TOWNSHIP-NORTH | D15: =ROUND(S15*T15,0) -> 192 | E15: =ROUND(S15,0)-D15 -> 532 | F15: =IF(COUNTA(D15:E15)=0,"",SUM(D15:E15)) -> 724 | G15: =IF(OR(F15="",F15=0),"",D15/F15) -> 0.26519337 | H15: =IF(OR(F15="",F15=0),"",E15/F15) -> 0.73480663 | I15: random forest (results only) | J15: 2.1171612 | K15: =$K$8 -> 0.29703023 | L15: =SQRT(J15^2+K15^2) -> 2.1378958 | M15: =IF(G15="","",MAX(0,G15-1.96*L15/100)) -> 0.22329061 | N15: =IF(G15="","",MIN(1,G15+1.96*L15/100)) -> 0.30709613 | O15: =ROUND(S15*W15,0) -> 64 | P15: =IF(F15="","",ROUND(SQRT((F15*L15/100)^2+(G15*O15)^2),0)) -> 23 | R15: -24.334957 | S15: =U15*V15*$F$5 -> 724.37791 | T15: =MAX(0,MIN(1,R15/100+$D$5)) -> 0.26470548 | U15: 0.67635659 | V15: 1071 | W15: 0.08874451 | X15: Medium | Y15: state rolls, precinct
A16: Carbon | B16: EAST PENN TOWNSHIP | C16: EAST PENN TOWNSHIP-SOUTH | D16: =ROUND(S16*T16,0) -> 175 | E16: =ROUND(S16,0)-D16 -> 436 | F16: =IF(COUNTA(D16:E16)=0,"",SUM(D16:E16)) -> 611 | G16: =IF(OR(F16="",F16=0),"",D16/F16) -> 0.28641571 | H16: =IF(OR(F16="",F16=0),"",E16/F16) -> 0.71358429 | I16: random forest (results only) | J16: 2.1171612 | K16: =$K$8 -> 0.29703023 | L16: =SQRT(J16^2+K16^2) -> 2.1378958 | M16: =IF(G16="","",MAX(0,G16-1.96*L16/100)) -> 0.24451295 | N16: =IF(G16="","",MIN(1,G16+1.96*L16/100)) -> 0.32831847 | O16: =ROUND(S16*W16,0) -> 54 | P16: =IF(F16="","",ROUND(SQRT((F16*L16/100)^2+(G16*O16)^2),0)) -> 20 | R16: -22.147157 | S16: =U16*V16*$F$5 -> 610.89237 | T16: =MAX(0,MIN(1,R16/100+$D$5)) -> 0.28658348 | U16: 0.62591432 | V16: 976 | W16: 0.08874451 | X16: Medium | Y16: state rolls, precinct
A17: Carbon | B17: EAST SIDE BOROUGH | C17: EAST SIDE BOROUGH | D17: =ROUND(S17*T17,0) -> 32 | E17: =ROUND(S17,0)-D17 -> 61 | F17: =IF(COUNTA(D17:E17)=0,"",SUM(D17:E17)) -> 93 | G17: =IF(OR(F17="",F17=0),"",D17/F17) -> 0.34408602 | H17: =IF(OR(F17="",F17=0),"",E17/F17) -> 0.65591398 | I17: random forest (results only) | J17: 3.4204608 | K17: =$K$8 -> 0.29703023 | L17: =SQRT(J17^2+K17^2) -> 3.4333335 | M17: =IF(G17="","",MAX(0,G17-1.96*L17/100)) -> 0.27679268 | N17: =IF(G17="","",MIN(1,G17+1.96*L17/100)) -> 0.41137936 | O17: =ROUND(S17*W17,0) -> 14 | P17: =IF(F17="","",ROUND(SQRT((F17*L17/100)^2+(G17*O17)^2),0)) -> 6 | R17: -16.935318 | S17: =U17*V17*$F$5 -> 93.426829 | T17: =MAX(0,MIN(1,R17/100+$D$5)) -> 0.33870187 | U17: 0.57317073 | V17: 163 | W17: 0.14809733 | X17: Small | Y17: state rolls, precinct
A18: Carbon | B18: FRANKLIN TOWNSHIP | C18: FRANKLIN TOWNSHIP-HARRITY | D18: =ROUND(S18*T18,0) -> 243 | E18: =ROUND(S18,0)-D18 -> 610 | F18: =IF(COUNTA(D18:E18)=0,"",SUM(D18:E18)) -> 853 | G18: =IF(OR(F18="",F18=0),"",D18/F18) -> 0.28487691 | H18: =IF(OR(F18="",F18=0),"",E18/F18) -> 0.71512309 | I18: random forest (results only) | J18: 2.1171612 | K18: =$K$8 -> 0.29703023 | L18: =SQRT(J18^2+K18^2) -> 2.1378958 | M18: =IF(G18="","",MAX(0,G18-1.96*L18/100)) -> 0.24297415 | N18: =IF(G18="","",MIN(1,G18+1.96*L18/100)) -> 0.32677966 | O18: =ROUND(S18*W18,0) -> 76 | P18: =IF(F18="","",ROUND(SQRT((F18*L18/100)^2+(G18*O18)^2),0)) -> 28 | R18: -22.26495 | S18: =U18*V18*$F$5 -> 852.99444 | T18: =MAX(0,MIN(1,R18/100+$D$5)) -> 0.28540555 | U18: 0.66640191 | V18: 1280 | W18: 0.08874451 | X18: Medium | Y18: state rolls, precinct
A19: Carbon | B19: FRANKLIN TOWNSHIP | C19: FRANKLIN TOWNSHIP-IND DIST | D19: =ROUND(S19*T19,0) -> 124 | E19: =ROUND(S19,0)-D19 -> 324 | F19: =IF(COUNTA(D19:E19)=0,"",SUM(D19:E19)) -> 448 | G19: =IF(OR(F19="",F19=0),"",D19/F19) -> 0.27678571 | H19: =IF(OR(F19="",F19=0),"",E19/F19) -> 0.72321429 | I19: random forest (results only) | J19: 3.4204608 | K19: =$K$8 -> 0.29703023 | L19: =SQRT(J19^2+K19^2) -> 3.4333335 | M19: =IF(G19="","",MAX(0,G19-1.96*L19/100)) -> 0.20949238 | N19: =IF(G19="","",MIN(1,G19+1.96*L19/100)) -> 0.34407905 | O19: =ROUND(S19*W19,0) -> 66 | P19: =IF(F19="","",ROUND(SQRT((F19*L19/100)^2+(G19*O19)^2),0)) -> 24 | R19: -23.021767 | S19: =U19*V19*$F$5 -> 447.93932 | T19: =MAX(0,MIN(1,R19/100+$D$5)) -> 0.27783738 | U19: 0.55097087 | V19: 813 | W19: 0.14809733 | X19: Small | Y19: state rolls, precinct
A20: Carbon | B20: FRANKLIN TOWNSHIP | C20: FRANKLIN TOWNSHIP-LONG RUN | D20: =ROUND(S20*T20,0) -> 190 | E20: =ROUND(S20,0)-D20 -> 493 | F20: =IF(COUNTA(D20:E20)=0,"",SUM(D20:E20)) -> 683 | G20: =IF(OR(F20="",F20=0),"",D20/F20) -> 0.27818448 | H20: =IF(OR(F20="",F20=0),"",E20/F20) -> 0.72181552 | I20: random forest (results only) | J20: 2.1171612 | K20: =$K$8 -> 0.29703023 | L20: =SQRT(J20^2+K20^2) -> 2.1378958 | M20: =IF(G20="","",MAX(0,G20-1.96*L20/100)) -> 0.23628172 | N20: =IF(G20="","",MIN(1,G20+1.96*L20/100)) -> 0.32008724 | O20: =ROUND(S20*W20,0) -> 61 | P20: =IF(F20="","",ROUND(SQRT((F20*L20/100)^2+(G20*O20)^2),0)) -> 22 | R20: -22.998693 | S20: =U20*V20*$F$5 -> 683.32677 | T20: =MAX(0,MIN(1,R20/100+$D$5)) -> 0.27806812 | U20: 0.65452756 | V20: 1044 | W20: 0.08874451 | X20: Medium | Y20: state rolls, precinct
A21: Carbon | B21: JIM THORPE BOROUGH | C21: JIM THORPE BOROUGH-1ST | D21: =ROUND(S21*T21,0) -> 193 | E21: =ROUND(S21,0)-D21 -> 243 | F21: =IF(COUNTA(D21:E21)=0,"",SUM(D21:E21)) -> 436 | G21: =IF(OR(F21="",F21=0),"",D21/F21) -> 0.44266055 | H21: =IF(OR(F21="",F21=0),"",E21/F21) -> 0.55733945 | I21: random forest (results only) | J21: 3.4204608 | K21: =$K$8 -> 0.29703023 | L21: =SQRT(J21^2+K21^2) -> 3.4333335 | M21: =IF(G21="","",MAX(0,G21-1.96*L21/100)) -> 0.37536721 | N21: =IF(G21="","",MIN(1,G21+1.96*L21/100)) -> 0.50995389 | O21: =ROUND(S21*W21,0) -> 65 | P21: =IF(F21="","",ROUND(SQRT((F21*L21/100)^2+(G21*O21)^2),0)) -> 32 | R21: -6.540268 | S21: =U21*V21*$F$5 -> 436.24467 | T21: =MAX(0,MIN(1,R21/100+$D$5)) -> 0.44265237 | U21: 0.62588905 | V21: 697 | W21: 0.14809733 | X21: Small | Y21: state rolls, precinct
A22: Carbon | B22: JIM THORPE BOROUGH | C22: JIM THORPE BOROUGH-2ND | D22: =ROUND(S22*T22,0) -> 119 | E22: =ROUND(S22,0)-D22 -> 161 | F22: =IF(COUNTA(D22:E22)=0,"",SUM(D22:E22)) -> 280 | G22: =IF(OR(F22="",F22=0),"",D22/F22) -> 0.425 | H22: =IF(OR(F22="",F22=0),"",E22/F22) -> 0.575 | I22: random forest (results only) | J22: 3.4204608 | K22: =$K$8 -> 0.29703023 | L22: =SQRT(J22^2+K22^2) -> 3.4333335 | M22: =IF(G22="","",MAX(0,G22-1.96*L22/100)) -> 0.35770666 | N22: =IF(G22="","",MIN(1,G22+1.96*L22/100)) -> 0.49229334 | O22: =ROUND(S22*W22,0) -> 42 | P22: =IF(F22="","",ROUND(SQRT((F22*L22/100)^2+(G22*O22)^2),0)) -> 20 | R22: -8.5045743 | S22: =U22*V22*$F$5 -> 280.5 | T22: =MAX(0,MIN(1,R22/100+$D$5)) -> 0.42300931 | U22: 0.56896552 | V22: 493 | W22: 0.14809733 | X22: Small | Y22: state rolls, precinct
A23: Carbon | B23: JIM THORPE BOROUGH | C23: JIM THORPE BOROUGH-3RD | D23: =ROUND(S23*T23,0) -> 251 | E23: =ROUND(S23,0)-D23 -> 395 | F23: =IF(COUNTA(D23:E23)=0,"",SUM(D23:E23)) -> 646 | G23: =IF(OR(F23="",F23=0),"",D23/F23) -> 0.38854489 | H23: =IF(OR(F23="",F23=0),"",E23/F23) -> 0.61145511 | I23: random forest (results only) | J23: 2.1171612 | K23: =$K$8 -> 0.29703023 | L23: =SQRT(J23^2+K23^2) -> 2.1378958 | M23: =IF(G23="","",MAX(0,G23-1.96*L23/100)) -> 0.34664213 | N23: =IF(G23="","",MIN(1,G23+1.96*L23/100)) -> 0.43044765 | O23: =ROUND(S23*W23,0) -> 57 | P23: =IF(F23="","",ROUND(SQRT((F23*L23/100)^2+(G23*O23)^2),0)) -> 26 | R23: -11.896239 | S23: =U23*V23*$F$5 -> 645.69536 | T23: =MAX(0,MIN(1,R23/100+$D$5)) -> 0.38909266 | U23: 0.68984547 | V23: 936 | W23: 0.08874451 | X23: Medium | Y23: state rolls, precinct
... A381: Northampton | B381: WIND GAP | C381: WIND GAP | D381: =ROUND(S381*T381,0) -> 492 | E381: =ROUND(S381,0)-D381 -> 653 | F381: =IF(COUNTA(D381:E381)=0,"",SUM(D381:E381)) -> 1145 | G381: =IF(OR(F381="",F381=0),"",D381/F381) -> 0.42969432 | H381: =IF(OR(F381="",F381=0),"",E381/F381) -> 0.57030568 | I381: random forest (results only) | J381: 1.7283555 | K381: =$K$8 -> 0.29703023 | L381: =SQRT(J381^2+K381^2) -> 1.7536931 | M381: =IF(G381="","",MAX(0,G381-1.96*L381/100)) -> 0.39532194 | N381: =IF(G381="","",MIN(1,G381+1.96*L381/100)) -> 0.46406671 | O381: =ROUND(S381*W381,0) -> 78 | P381: =IF(F381="","",ROUND(SQRT((F381*L381/100)^2+(G381*O381)^2),0)) -> 39 | R381: -7.8616141 | S381: =U381*V381*$F$5 -> 1145.4806 | T381: =MAX(0,MIN(1,R381/100+$D$5)) -> 0.42943891 | U381: 0.53702795 | V381: 2133 | W381: 0.068475215 | X381: Large | Y381: state rolls, precinct

Sheet 2026 Forecast B
A1: PA-07 2026 House Forecast — Precinct-Level Predictions (Forecast B: shap-selected forest)
A2: Candidates: Brooks | Mackenzie | District totals (yellow) are formulas over the precinct rows.
A3: Only the results are modelled (one random forest). Votes cast in each row = its 2022 turnout rate (House votes ÷ registered voters) × its 2026 registered voters. Brooks votes = votes cast × forecast Brooks share. Error terms combine the place’s own pattern error, the district-wide error and turnout error, measured on the 2022 and 2024 backtests.
A4: Model / scenario | B4: Random forest on results — Forecast B (SHAP-selected forest), precinct model; turnout = 2022 turnout rate × 2026 registered voters | C4: As-of date | D4: 46300 | E4: Prepared by | F4: Max | G4: Version | H4: v6.0 (current map, all years; results only; 2022 turnout × 2026 registration)
A5: District Brooks share (scenario) | B5: ='Scenario & Comparison'!$C$6 -> 0.49515845 | C5: Uniform shift applied | D5: =B5-SUMPRODUCT(R12:R381,S12:S381)/SUM(S12:S381)/100 -> 0.51199341 | E5: Turnout multiplier (1.00 = 2022 turnout) | F5: ='Scenario & Comparison'!$C$7 -> 1
A6: DISTRICT TOTALS (auto-sum — do not type over)
A7: Geography | B7: (muni) | C7: (precinct) | D7: Brooks votes | E7: Mackenzie votes | F7: Total votes | G7: Brooks share | H7: Mackenzie share | I7: Notes | J7: Error term: place pattern (± pts) | K7: Error term: district-wide (± pts) | L7: Error term: total (± pts) | M7: Brooks share, 95% low | N7: Brooks share, 95% high | O7: Error term: votes cast (± votes) | P7: Error term: Brooks votes (± votes)
A8: PA-07 District | B8: (all precincts) | D8: =SUM(D12:D381) -> 151578 | E8: =SUM(E12:E381) -> 154535 | F8: =D8+E8 -> 306113 | G8: =IF(F8=0,"",D8/F8) -> 0.49517008 | H8: =IF(F8=0,"",E8/F8) -> 0.50482992 | I8: Headline forecast for the briefing | J8: 0 | K8: 0.29793824 | L8: =SQRT(J8^2+K8^2) -> 0.29793824 | M8: =G8-1.96*L8/100 -> 0.48933049 | N8: =G8+1.96*L8/100 -> 0.50100967 | O8: =ROUND(F8*0.04436,0) -> 13579 | P8: =ROUND(SQRT((F8*L8/100)^2+(G8*O8)^2),0) -> 6785
A9: Error terms are ±1 standard error built from the 2022 and 2024 backtests (pattern error by place size; district-wide error; turnout error). 95% low/high = Brooks share ± 1.96 × total error term. Only two test elections — the district-wide term understates real election-environment risk.
A10: PRECINCT DETAIL | R10: MODEL INPUTS (from the random forest — do not edit)
A11: County | B11: Municipality | C11: Precinct | D11: Brooks votes | E11: Mackenzie votes | F11: Total votes | G11: Brooks share | H11: Mackenzie share | I11: Notes / source method | J11: Error term: place pattern (± pts) | K11: Error term: district-wide (± pts) | L11: Error term: total (± pts) | M11: Brooks share, 95% low | N11: Brooks share, 95% high | O11: Error term: votes cast (± votes) | P11: Error term: Brooks votes (± votes) | R11: Model lean vs district (pts) | S11: Votes cast = 2022 turnout × 2026 registered | T11: Forecast Brooks share (unrounded) | U11: 2022 turnout (House votes ÷ registered) | V11: 2026 registered voters | W11: Votes-cast error (% of votes) | X11: Size group (backtest error band) | Y11: Registration source
A12: Carbon | B12: BANKS TOWNSHIP | C12: BANKS TOWNSHIP | D12: =ROUND(S12*T12,0) -> 154 | E12: =ROUND(S12,0)-D12 -> 210 | F12: =IF(COUNTA(D12:E12)=0,"",SUM(D12:E12)) -> 364 | G12: =IF(OR(F12="",F12=0),"",D12/F12) -> 0.42307692 | H12: =IF(OR(F12="",F12=0),"",E12/F12) -> 0.57692308 | I12: random forest (results only) | J12: 3.1978282 | K12: =$K$8 -> 0.29793824 | L12: =SQRT(J12^2+K12^2) -> 3.2116775 | M12: =IF(G12="","",MAX(0,G12-1.96*L12/100)) -> 0.36012804 | N12: =IF(G12="","",MIN(1,G12+1.96*L12/100)) -> 0.4860258 | O12: =ROUND(S12*W12,0) -> 54 | P12: =IF(F12="","",ROUND(SQRT((F12*L12/100)^2+(G12*O12)^2),0)) -> 26 | R12: -8.9602389 | S12: =U12*V12*$F$5 -> 364.49096 | T12: =MAX(0,MIN(1,R12/100+$D$5)) -> 0.42239103 | U12: 0.5813253 | V12: 627 | W12: 0.14809733 | X12: Small | Y12: state rolls, precinct
A13: Carbon | B13: BEAVER MEADOWS BOROUGH | C13: BEAVER MEADOWS BOROUGH | D13: =ROUND(S13*T13,0) -> 97 | E13: =ROUND(S13,0)-D13 -> 233 | F13: =IF(COUNTA(D13:E13)=0,"",SUM(D13:E13)) -> 330 | G13: =IF(OR(F13="",F13=0),"",D13/F13) -> 0.29393939 | H13: =IF(OR(F13="",F13=0),"",E13/F13) -> 0.70606061 | I13: random forest (results only) | J13: 3.1978282 | K13: =$K$8 -> 0.29793824 | L13: =SQRT(J13^2+K13^2) -> 3.2116775 | M13: =IF(G13="","",MAX(0,G13-1.96*L13/100)) -> 0.23099052 | N13: =IF(G13="","",MIN(1,G13+1.96*L13/100)) -> 0.35688827 | O13: =ROUND(S13*W13,0) -> 49 | P13: =IF(F13="","",ROUND(SQRT((F13*L13/100)^2+(G13*O13)^2),0)) -> 18 | R13: -21.892882 | S13: =U13*V13*$F$5 -> 330.13014 | T13: =MAX(0,MIN(1,R13/100+$D$5)) -> 0.2930646 | U13: 0.53767123 | V13: 614 | W13: 0.14809733 | X13: Small | Y13: state rolls, precinct
A14: Carbon | B14: BOWMANSTOWN BOROUGH | C14: BOWMANSTOWN BOROUGH | D14: =ROUND(S14*T14,0) -> 121 | E14: =ROUND(S14,0)-D14 -> 235 | F14: =IF(COUNTA(D14:E14)=0,"",SUM(D14:E14)) -> 356 | G14: =IF(OR(F14="",F14=0),"",D14/F14) -> 0.33988764 | H14: =IF(OR(F14="",F14=0),"",E14/F14) -> 0.66011236 | I14: random forest (results only) | J14: 3.1978282 | K14: =$K$8 -> 0.29793824 | L14: =SQRT(J14^2+K14^2) -> 3.2116775 | M14: =IF(G14="","",MAX(0,G14-1.96*L14/100)) -> 0.27693876 | N14: =IF(G14="","",MIN(1,G14+1.96*L14/100)) -> 0.40283652 | O14: =ROUND(S14*W14,0) -> 53 | P14: =IF(F14="","",ROUND(SQRT((F14*L14/100)^2+(G14*O14)^2),0)) -> 21 | R14: -17.273159 | S14: =U14*V14*$F$5 -> 355.63437 | T14: =MAX(0,MIN(1,R14/100+$D$5)) -> 0.33926183 | U14: 0.63619744 | V14: 559 | W14: 0.14809733 | X14: Small | Y14: state rolls, precinct
A15: Carbon | B15: EAST PENN TOWNSHIP | C15: EAST PENN TOWNSHIP-NORTH | D15: =ROUND(S15*T15,0) -> 192 | E15: =ROUND(S15,0)-D15 -> 532 | F15: =IF(COUNTA(D15:E15)=0,"",SUM(D15:E15)) -> 724 | G15: =IF(OR(F15="",F15=0),"",D15/F15) -> 0.26519337 | H15: =IF(OR(F15="",F15=0),"",E15/F15) -> 0.73480663 | I15: random forest (results only) | J15: 2.2248997 | K15: =$K$8 -> 0.29793824 | L15: =SQRT(J15^2+K15^2) -> 2.2447597 | M15: =IF(G15="","",MAX(0,G15-1.96*L15/100)) -> 0.22119608 | N15: =IF(G15="","",MIN(1,G15+1.96*L15/100)) -> 0.30919066 | O15: =ROUND(S15*W15,0) -> 64 | P15: =IF(F15="","",ROUND(SQRT((F15*L15/100)^2+(G15*O15)^2),0)) -> 23 | R15: -24.642821 | S15: =U15*V15*$F$5 -> 724.37791 | T15: =MAX(0,MIN(1,R15/100+$D$5)) -> 0.2655652 | U15: 0.67635659 | V15: 1071 | W15: 0.08874451 | X15: Medium | Y15: state rolls, precinct
A16: Carbon | B16: EAST PENN TOWNSHIP | C16: EAST PENN TOWNSHIP-SOUTH | D16: =ROUND(S16*T16,0) -> 174 | E16: =ROUND(S16,0)-D16 -> 437 | F16: =IF(COUNTA(D16:E16)=0,"",SUM(D16:E16)) -> 611 | G16: =IF(OR(F16="",F16=0),"",D16/F16) -> 0.28477905 | H16: =IF(OR(F16="",F16=0),"",E16/F16) -> 0.71522095 | I16: random forest (results only) | J16: 2.2248997 | K16: =$K$8 -> 0.29793824 | L16: =SQRT(J16^2+K16^2) -> 2.2447597 | M16: =IF(G16="","",MAX(0,G16-1.96*L16/100)) -> 0.24078176 | N16: =IF(G16="","",MIN(1,G16+1.96*L16/100)) -> 0.32877634 | O16: =ROUND(S16*W16,0) -> 54 | P16: =IF(F16="","",ROUND(SQRT((F16*L16/100)^2+(G16*O16)^2),0)) -> 21 | R16: -22.755724 | S16: =U16*V16*$F$5 -> 610.89237 | T16: =MAX(0,MIN(1,R16/100+$D$5)) -> 0.28443618 | U16: 0.62591432 | V16: 976 | W16: 0.08874451 | X16: Medium | Y16: state rolls, precinct
A17: Carbon | B17: EAST SIDE BOROUGH | C17: EAST SIDE BOROUGH | D17: =ROUND(S17*T17,0) -> 33 | E17: =ROUND(S17,0)-D17 -> 60 | F17: =IF(COUNTA(D17:E17)=0,"",SUM(D17:E17)) -> 93 | G17: =IF(OR(F17="",F17=0),"",D17/F17) -> 0.35483871 | H17: =IF(OR(F17="",F17=0),"",E17/F17) -> 0.64516129 | I17: random forest (results only) | J17: 3.1978282 | K17: =$K$8 -> 0.29793824 | L17: =SQRT(J17^2+K17^2) -> 3.2116775 | M17: =IF(G17="","",MAX(0,G17-1.96*L17/100)) -> 0.29188983 | N17: =IF(G17="","",MIN(1,G17+1.96*L17/100)) -> 0.41778759 | O17: =ROUND(S17*W17,0) -> 14 | P17: =IF(F17="","",ROUND(SQRT((F17*L17/100)^2+(G17*O17)^2),0)) -> 6 | R17: -15.909605 | S17: =U17*V17*$F$5 -> 93.426829 | T17: =MAX(0,MIN(1,R17/100+$D$5)) -> 0.35289736 | U17: 0.57317073 | V17: 163 | W17: 0.14809733 | X17: Small | Y17: state rolls, precinct
A18: Carbon | B18: FRANKLIN TOWNSHIP | C18: FRANKLIN TOWNSHIP-HARRITY | D18: =ROUND(S18*T18,0) -> 245 | E18: =ROUND(S18,0)-D18 -> 608 | F18: =IF(COUNTA(D18:E18)=0,"",SUM(D18:E18)) -> 853 | G18: =IF(OR(F18="",F18=0),"",D18/F18) -> 0.28722157 | H18: =IF(OR(F18="",F18=0),"",E18/F18) -> 0.71277843 | I18: random forest (results only) | J18: 2.2248997 | K18: =$K$8 -> 0.29793824 | L18: =SQRT(J18^2+K18^2) -> 2.2447597 | M18: =IF(G18="","",MAX(0,G18-1.96*L18/100)) -> 0.24322428 | N18: =IF(G18="","",MIN(1,G18+1.96*L18/100)) -> 0.33121886 | O18: =ROUND(S18*W18,0) -> 76 | P18: =IF(F18="","",ROUND(SQRT((F18*L18/100)^2+(G18*O18)^2),0)) -> 29 | R18: -22.505631 | S18: =U18*V18*$F$5 -> 852.99444 | T18: =MAX(0,MIN(1,R18/100+$D$5)) -> 0.2869371 | U18: 0.66640191 | V18: 1280 | W18: 0.08874451 | X18: Medium | Y18: state rolls, precinct
A19: Carbon | B19: FRANKLIN TOWNSHIP | C19: FRANKLIN TOWNSHIP-IND DIST | D19: =ROUND(S19*T19,0) -> 125 | E19: =ROUND(S19,0)-D19 -> 323 | F19: =IF(COUNTA(D19:E19)=0,"",SUM(D19:E19)) -> 448 | G19: =IF(OR(F19="",F19=0),"",D19/F19) -> 0.27901786 | H19: =IF(OR(F19="",F19=0),"",E19/F19) -> 0.72098214 | I19: random forest (results only) | J19: 3.1978282 | K19: =$K$8 -> 0.29793824 | L19: =SQRT(J19^2+K19^2) -> 3.2116775 | M19: =IF(G19="","",MAX(0,G19-1.96*L19/100)) -> 0.21606898 | N19: =IF(G19="","",MIN(1,G19+1.96*L19/100)) -> 0.34196674 | O19: =ROUND(S19*W19,0) -> 66 | P19: =IF(F19="","",ROUND(SQRT((F19*L19/100)^2+(G19*O19)^2),0)) -> 23 | R19: -23.193736 | S19: =U19*V19*$F$5 -> 447.93932 | T19: =MAX(0,MIN(1,R19/100+$D$5)) -> 0.28005606 | U19: 0.55097087 | V19: 813 | W19: 0.14809733 | X19: Small | Y19: state rolls, precinct
A20: Carbon | B20: FRANKLIN TOWNSHIP | C20: FRANKLIN TOWNSHIP-LONG RUN | D20: =ROUND(S20*T20,0) -> 188 | E20: =ROUND(S20,0)-D20 -> 495 | F20: =IF(COUNTA(D20:E20)=0,"",SUM(D20:E20)) -> 683 | G20: =IF(OR(F20="",F20=0),"",D20/F20) -> 0.27525622 | H20: =IF(OR(F20="",F20=0),"",E20/F20) -> 0.72474378 | I20: random forest (results only) | J20: 2.2248997 | K20: =$K$8 -> 0.29793824 | L20: =SQRT(J20^2+K20^2) -> 2.2447597 | M20: =IF(G20="","",MAX(0,G20-1.96*L20/100)) -> 0.23125893 | N20: =IF(G20="","",MIN(1,G20+1.96*L20/100)) -> 0.31925351 | O20: =ROUND(S20*W20,0) -> 61 | P20: =IF(F20="","",ROUND(SQRT((F20*L20/100)^2+(G20*O20)^2),0)) -> 23 | R20: -23.639155 | S20: =U20*V20*$F$5 -> 683.32677 | T20: =MAX(0,MIN(1,R20/100+$D$5)) -> 0.27560186 | U20: 0.65452756 | V20: 1044 | W20: 0.08874451 | X20: Medium | Y20: state rolls, precinct
A21: Carbon | B21: JIM THORPE BOROUGH | C21: JIM THORPE BOROUGH-1ST | D21: =ROUND(S21*T21,0) -> 196 | E21: =ROUND(S21,0)-D21 -> 240 | F21: =IF(COUNTA(D21:E21)=0,"",SUM(D21:E21)) -> 436 | G21: =IF(OR(F21="",F21=0),"",D21/F21) -> 0.44954128 | H21: =IF(OR(F21="",F21=0),"",E21/F21) -> 0.55045872 | I21: random forest (results only) | J21: 3.1978282 | K21: =$K$8 -> 0.29793824 | L21: =SQRT(J21^2+K21^2) -> 3.2116775 | M21: =IF(G21="","",MAX(0,G21-1.96*L21/100)) -> 0.38659241 | N21: =IF(G21="","",MIN(1,G21+1.96*L21/100)) -> 0.51249016 | O21: =ROUND(S21*W21,0) -> 65 | P21: =IF(F21="","",ROUND(SQRT((F21*L21/100)^2+(G21*O21)^2),0)) -> 32 | R21: -6.2977772 | S21: =U21*V21*$F$5 -> 436.24467 | T21: =MAX(0,MIN(1,R21/100+$D$5)) -> 0.44901564 | U21: 0.62588905 | V21: 697 | W21: 0.14809733 | X21: Small | Y21: state rolls, precinct
A22: Carbon | B22: JIM THORPE BOROUGH | C22: JIM THORPE BOROUGH-2ND | D22: =ROUND(S22*T22,0) -> 122 | E22: =ROUND(S22,0)-D22 -> 158 | F22: =IF(COUNTA(D22:E22)=0,"",SUM(D22:E22)) -> 280 | G22: =IF(OR(F22="",F22=0),"",D22/F22) -> 0.43571429 | H22: =IF(OR(F22="",F22=0),"",E22/F22) -> 0.56428571 | I22: random forest (results only) | J22: 3.1978282 | K22: =$K$8 -> 0.29793824 | L22: =SQRT(J22^2+K22^2) -> 3.2116775 | M22: =IF(G22="","",MAX(0,G22-1.96*L22/100)) -> 0.37276541 | N22: =IF(G22="","",MIN(1,G22+1.96*L22/100)) -> 0.49866316 | O22: =ROUND(S22*W22,0) -> 42 | P22: =IF(F22="","",ROUND(SQRT((F22*L22/100)^2+(G22*O22)^2),0)) -> 20 | R22: -7.6322666 | S22: =U22*V22*$F$5 -> 280.5 | T22: =MAX(0,MIN(1,R22/100+$D$5)) -> 0.43567075 | U22: 0.56896552 | V22: 493 | W22: 0.14809733 | X22: Small | Y22: state rolls, precinct
A23: Carbon | B23: JIM THORPE BOROUGH | C23: JIM THORPE BOROUGH-3RD | D23: =ROUND(S23*T23,0) -> 251 | E23: =ROUND(S23,0)-D23 -> 395 | F23: =IF(COUNTA(D23:E23)=0,"",SUM(D23:E23)) -> 646 | G23: =IF(OR(F23="",F23=0),"",D23/F23) -> 0.38854489 | H23: =IF(OR(F23="",F23=0),"",E23/F23) -> 0.61145511 | I23: random forest (results only) | J23: 2.2248997 | K23: =$K$8 -> 0.29793824 | L23: =SQRT(J23^2+K23^2) -> 2.2447597 | M23: =IF(G23="","",MAX(0,G23-1.96*L23/100)) -> 0.3445476 | N23: =IF(G23="","",MIN(1,G23+1.96*L23/100)) -> 0.43254218 | O23: =ROUND(S23*W23,0) -> 57 | P23: =IF(F23="","",ROUND(SQRT((F23*L23/100)^2+(G23*O23)^2),0)) -> 26 | R23: -12.305978 | S23: =U23*V23*$F$5 -> 645.69536 | T23: =MAX(0,MIN(1,R23/100+$D$5)) -> 0.38893364 | U23: 0.68984547 | V23: 936 | W23: 0.08874451 | X23: Medium | Y23: state rolls, precinct
... A381: Northampton | B381: WIND GAP | C381: WIND GAP | D381: =ROUND(S381*T381,0) -> 487 | E381: =ROUND(S381,0)-D381 -> 658 | F381: =IF(COUNTA(D381:E381)=0,"",SUM(D381:E381)) -> 1145 | G381: =IF(OR(F381="",F381=0),"",D381/F381) -> 0.42532751 | H381: =IF(OR(F381="",F381=0),"",E381/F381) -> 0.57467249 | I381: random forest (results only) | J381: 2.0826259 | K381: =$K$8 -> 0.29793824 | L381: =SQRT(J381^2+K381^2) -> 2.1038293 | M381: =IF(G381="","",MAX(0,G381-1.96*L381/100)) -> 0.38409246 | N381: =IF(G381="","",MIN(1,G381+1.96*L381/100)) -> 0.46656257 | O381: =ROUND(S381*W381,0) -> 78 | P381: =IF(F381="","",ROUND(SQRT((F381*L381/100)^2+(G381*O381)^2),0)) -> 41 | R381: -8.7138028 | S381: =U381*V381*$F$5 -> 1145.4806 | T381: =MAX(0,MIN(1,R381/100+$D$5)) -> 0.42485539 | U381: 0.53702795 | V381: 2133 | W381: 0.068475215 | X381: Large | Y381: state rolls, precinct

Sheet 2026 Forecast C
A1: PA-07 2026 House Forecast — Precinct-Level Predictions (Forecast C: shap family-reweighted forest)
A2: Candidates: Brooks | Mackenzie | District totals (yellow) are formulas over the precinct rows.
A3: Only the results are modelled (one random forest). Votes cast in each row = its 2022 turnout rate (House votes ÷ registered voters) × its 2026 registered voters. Brooks votes = votes cast × forecast Brooks share. Error terms combine the place’s own pattern error, the district-wide error and turnout error, measured on the 2022 and 2024 backtests.
A4: Model / scenario | B4: Random forest on results — Forecast C (SHAP family-reweighted forest), precinct model; turnout = 2022 turnout rate × 2026 registered voters | C4: As-of date | D4: 46300 | E4: Prepared by | F4: Max | G4: Version | H4: v6.0 (current map, all years; results only; 2022 turnout × 2026 registration)
A5: District Brooks share (scenario) | B5: ='Scenario & Comparison'!$C$6 -> 0.49515845 | C5: Uniform shift applied | D5: =B5-SUMPRODUCT(R12:R381,S12:S381)/SUM(S12:S381)/100 -> 0.50755611 | E5: Turnout multiplier (1.00 = 2022 turnout) | F5: ='Scenario & Comparison'!$C$7 -> 1
A6: DISTRICT TOTALS (auto-sum — do not type over)
A7: Geography | B7: (muni) | C7: (precinct) | D7: Brooks votes | E7: Mackenzie votes | F7: Total votes | G7: Brooks share | H7: Mackenzie share | I7: Notes | J7: Error term: place pattern (± pts) | K7: Error term: district-wide (± pts) | L7: Error term: total (± pts) | M7: Brooks share, 95% low | N7: Brooks share, 95% high | O7: Error term: votes cast (± votes) | P7: Error term: Brooks votes (± votes)
A8: PA-07 District | B8: (all precincts) | D8: =SUM(D12:D381) -> 151570 | E8: =SUM(E12:E381) -> 154543 | F8: =D8+E8 -> 306113 | G8: =IF(F8=0,"",D8/F8) -> 0.49514395 | H8: =IF(F8=0,"",E8/F8) -> 0.50485605 | I8: Headline forecast for the briefing | J8: 0 | K8: 0.29619762 | L8: =SQRT(J8^2+K8^2) -> 0.29619762 | M8: =G8-1.96*L8/100 -> 0.48933848 | N8: =G8+1.96*L8/100 -> 0.50094942 | O8: =ROUND(F8*0.04436,0) -> 13579 | P8: =ROUND(SQRT((F8*L8/100)^2+(G8*O8)^2),0) -> 6784
A9: Error terms are ±1 standard error built from the 2022 and 2024 backtests (pattern error by place size; district-wide error; turnout error). 95% low/high = Brooks share ± 1.96 × total error term. Only two test elections — the district-wide term understates real election-environment risk.
A10: PRECINCT DETAIL | R10: MODEL INPUTS (from the random forest — do not edit)
A11: County | B11: Municipality | C11: Precinct | D11: Brooks votes | E11: Mackenzie votes | F11: Total votes | G11: Brooks share | H11: Mackenzie share | I11: Notes / source method | J11: Error term: place pattern (± pts) | K11: Error term: district-wide (± pts) | L11: Error term: total (± pts) | M11: Brooks share, 95% low | N11: Brooks share, 95% high | O11: Error term: votes cast (± votes) | P11: Error term: Brooks votes (± votes) | R11: Model lean vs district (pts) | S11: Votes cast = 2022 turnout × 2026 registered | T11: Forecast Brooks share (unrounded) | U11: 2022 turnout (House votes ÷ registered) | V11: 2026 registered voters | W11: Votes-cast error (% of votes) | X11: Size group (backtest error band) | Y11: Registration source
A12: Carbon | B12: BANKS TOWNSHIP | C12: BANKS TOWNSHIP | D12: =ROUND(S12*T12,0) -> 147 | E12: =ROUND(S12,0)-D12 -> 217 | F12: =IF(COUNTA(D12:E12)=0,"",SUM(D12:E12)) -> 364 | G12: =IF(OR(F12="",F12=0),"",D12/F12) -> 0.40384615 | H12: =IF(OR(F12="",F12=0),"",E12/F12) -> 0.59615385 | I12: random forest (results only) | J12: 3.711035 | K12: =$K$8 -> 0.29619762 | L12: =SQRT(J12^2+K12^2) -> 3.7228368 | M12: =IF(G12="","",MAX(0,G12-1.96*L12/100)) -> 0.33087855 | N12: =IF(G12="","",MIN(1,G12+1.96*L12/100)) -> 0.47681375 | O12: =ROUND(S12*W12,0) -> 54 | P12: =IF(F12="","",ROUND(SQRT((F12*L12/100)^2+(G12*O12)^2),0)) -> 26 | R12: -10.472152 | S12: =U12*V12*$F$5 -> 364.49096 | T12: =MAX(0,MIN(1,R12/100+$D$5)) -> 0.40283458 | U12: 0.5813253 | V12: 627 | W12: 0.14809733 | X12: Small | Y12: state rolls, precinct
A13: Carbon | B13: BEAVER MEADOWS BOROUGH | C13: BEAVER MEADOWS BOROUGH | D13: =ROUND(S13*T13,0) -> 90 | E13: =ROUND(S13,0)-D13 -> 240 | F13: =IF(COUNTA(D13:E13)=0,"",SUM(D13:E13)) -> 330 | G13: =IF(OR(F13="",F13=0),"",D13/F13) -> 0.27272727 | H13: =IF(OR(F13="",F13=0),"",E13/F13) -> 0.72727273 | I13: random forest (results only) | J13: 3.711035 | K13: =$K$8 -> 0.29619762 | L13: =SQRT(J13^2+K13^2) -> 3.7228368 | M13: =IF(G13="","",MAX(0,G13-1.96*L13/100)) -> 0.19975967 | N13: =IF(G13="","",MIN(1,G13+1.96*L13/100)) -> 0.34569487 | O13: =ROUND(S13*W13,0) -> 49 | P13: =IF(F13="","",ROUND(SQRT((F13*L13/100)^2+(G13*O13)^2),0)) -> 18 | R13: -23.559984 | S13: =U13*V13*$F$5 -> 330.13014 | T13: =MAX(0,MIN(1,R13/100+$D$5)) -> 0.27195627 | U13: 0.53767123 | V13: 614 | W13: 0.14809733 | X13: Small | Y13: state rolls, precinct
A14: Carbon | B14: BOWMANSTOWN BOROUGH | C14: BOWMANSTOWN BOROUGH | D14: =ROUND(S14*T14,0) -> 111 | E14: =ROUND(S14,0)-D14 -> 245 | F14: =IF(COUNTA(D14:E14)=0,"",SUM(D14:E14)) -> 356 | G14: =IF(OR(F14="",F14=0),"",D14/F14) -> 0.31179775 | H14: =IF(OR(F14="",F14=0),"",E14/F14) -> 0.68820225 | I14: random forest (results only) | J14: 3.711035 | K14: =$K$8 -> 0.29619762 | L14: =SQRT(J14^2+K14^2) -> 3.7228368 | M14: =IF(G14="","",MAX(0,G14-1.96*L14/100)) -> 0.23883015 | N14: =IF(G14="","",MIN(1,G14+1.96*L14/100)) -> 0.38476535 | O14: =ROUND(S14*W14,0) -> 53 | P14: =IF(F14="","",ROUND(SQRT((F14*L14/100)^2+(G14*O14)^2),0)) -> 21 | R14: -19.445609 | S14: =U14*V14*$F$5 -> 355.63437 | T14: =MAX(0,MIN(1,R14/100+$D$5)) -> 0.31310002 | U14: 0.63619744 | V14: 559 | W14: 0.14809733 | X14: Small | Y14: state rolls, precinct
A15: Carbon | B15: EAST PENN TOWNSHIP | C15: EAST PENN TOWNSHIP-NORTH | D15: =ROUND(S15*T15,0) -> 177 | E15: =ROUND(S15,0)-D15 -> 547 | F15: =IF(COUNTA(D15:E15)=0,"",SUM(D15:E15)) -> 724 | G15: =IF(OR(F15="",F15=0),"",D15/F15) -> 0.24447514 | H15: =IF(OR(F15="",F15=0),"",E15/F15) -> 0.75552486 | I15: random forest (results only) | J15: 2.3731091 | K15: =$K$8 -> 0.29619762 | L15: =SQRT(J15^2+K15^2) -> 2.3915225 | M15: =IF(G15="","",MAX(0,G15-1.96*L15/100)) -> 0.1976013 | N15: =IF(G15="","",MIN(1,G15+1.96*L15/100)) -> 0.29134898 | O15: =ROUND(S15*W15,0) -> 64 | P15: =IF(F15="","",ROUND(SQRT((F15*L15/100)^2+(G15*O15)^2),0)) -> 23 | R15: -26.255514 | S15: =U15*V15*$F$5 -> 724.37791 | T15: =MAX(0,MIN(1,R15/100+$D$5)) -> 0.24500097 | U15: 0.67635659 | V15: 1071 | W15: 0.08874451 | X15: Medium | Y15: state rolls, precinct
A16: Carbon | B16: EAST PENN TOWNSHIP | C16: EAST PENN TOWNSHIP-SOUTH | D16: =ROUND(S16*T16,0) -> 163 | E16: =ROUND(S16,0)-D16 -> 448 | F16: =IF(COUNTA(D16:E16)=0,"",SUM(D16:E16)) -> 611 | G16: =IF(OR(F16="",F16=0),"",D16/F16) -> 0.26677578 | H16: =IF(OR(F16="",F16=0),"",E16/F16) -> 0.73322422 | I16: random forest (results only) | J16: 2.3731091 | K16: =$K$8 -> 0.29619762 | L16: =SQRT(J16^2+K16^2) -> 2.3915225 | M16: =IF(G16="","",MAX(0,G16-1.96*L16/100)) -> 0.21990194 | N16: =IF(G16="","",MIN(1,G16+1.96*L16/100)) -> 0.31364962 | O16: =ROUND(S16*W16,0) -> 54 | P16: =IF(F16="","",ROUND(SQRT((F16*L16/100)^2+(G16*O16)^2),0)) -> 21 | R16: -24.093993 | S16: =U16*V16*$F$5 -> 610.89237 | T16: =MAX(0,MIN(1,R16/100+$D$5)) -> 0.26661618 | U16: 0.62591432 | V16: 976 | W16: 0.08874451 | X16: Medium | Y16: state rolls, precinct
A17: Carbon | B17: EAST SIDE BOROUGH | C17: EAST SIDE BOROUGH | D17: =ROUND(S17*T17,0) -> 31 | E17: =ROUND(S17,0)-D17 -> 62 | F17: =IF(COUNTA(D17:E17)=0,"",SUM(D17:E17)) -> 93 | G17: =IF(OR(F17="",F17=0),"",D17/F17) -> 0.33333333 | H17: =IF(OR(F17="",F17=0),"",E17/F17) -> 0.66666667 | I17: random forest (results only) | J17: 3.711035 | K17: =$K$8 -> 0.29619762 | L17: =SQRT(J17^2+K17^2) -> 3.7228368 | M17: =IF(G17="","",MAX(0,G17-1.96*L17/100)) -> 0.26036573 | N17: =IF(G17="","",MIN(1,G17+1.96*L17/100)) -> 0.40630093 | O17: =ROUND(S17*W17,0) -> 14 | P17: =IF(F17="","",ROUND(SQRT((F17*L17/100)^2+(G17*O17)^2),0)) -> 6 | R17: -17.924857 | S17: =U17*V17*$F$5 -> 93.426829 | T17: =MAX(0,MIN(1,R17/100+$D$5)) -> 0.32830754 | U17: 0.57317073 | V17: 163 | W17: 0.14809733 | X17: Small | Y17: state rolls, precinct
A18: Carbon | B18: FRANKLIN TOWNSHIP | C18: FRANKLIN TOWNSHIP-HARRITY | D18: =ROUND(S18*T18,0) -> 227 | E18: =ROUND(S18,0)-D18 -> 626 | F18: =IF(COUNTA(D18:E18)=0,"",SUM(D18:E18)) -> 853 | G18: =IF(OR(F18="",F18=0),"",D18/F18) -> 0.26611958 | H18: =IF(OR(F18="",F18=0),"",E18/F18) -> 0.73388042 | I18: random forest (results only) | J18: 2.3731091 | K18: =$K$8 -> 0.29619762 | L18: =SQRT(J18^2+K18^2) -> 2.3915225 | M18: =IF(G18="","",MAX(0,G18-1.96*L18/100)) -> 0.21924574 | N18: =IF(G18="","",MIN(1,G18+1.96*L18/100)) -> 0.31299342 | O18: =ROUND(S18*W18,0) -> 76 | P18: =IF(F18="","",ROUND(SQRT((F18*L18/100)^2+(G18*O18)^2),0)) -> 29 | R18: -24.166982 | S18: =U18*V18*$F$5 -> 852.99444 | T18: =MAX(0,MIN(1,R18/100+$D$5)) -> 0.26588628 | U18: 0.66640191 | V18: 1280 | W18: 0.08874451 | X18: Medium | Y18: state rolls, precinct
A19: Carbon | B19: FRANKLIN TOWNSHIP | C19: FRANKLIN TOWNSHIP-IND DIST | D19: =ROUND(S19*T19,0) -> 115 | E19: =ROUND(S19,0)-D19 -> 333 | F19: =IF(COUNTA(D19:E19)=0,"",SUM(D19:E19)) -> 448 | G19: =IF(OR(F19="",F19=0),"",D19/F19) -> 0.25669643 | H19: =IF(OR(F19="",F19=0),"",E19/F19) -> 0.74330357 | I19: random forest (results only) | J19: 3.711035 | K19: =$K$8 -> 0.29619762 | L19: =SQRT(J19^2+K19^2) -> 3.7228368 | M19: =IF(G19="","",MAX(0,G19-1.96*L19/100)) -> 0.18372883 | N19: =IF(G19="","",MIN(1,G19+1.96*L19/100)) -> 0.32966403 | O19: =ROUND(S19*W19,0) -> 66 | P19: =IF(F19="","",ROUND(SQRT((F19*L19/100)^2+(G19*O19)^2),0)) -> 24 | R19: -25.0896 | S19: =U19*V19*$F$5 -> 447.93932 | T19: =MAX(0,MIN(1,R19/100+$D$5)) -> 0.25666011 | U19: 0.55097087 | V19: 813 | W19: 0.14809733 | X19: Small | Y19: state rolls, precinct
A20: Carbon | B20: FRANKLIN TOWNSHIP | C20: FRANKLIN TOWNSHIP-LONG RUN | D20: =ROUND(S20*T20,0) -> 177 | E20: =ROUND(S20,0)-D20 -> 506 | F20: =IF(COUNTA(D20:E20)=0,"",SUM(D20:E20)) -> 683 | G20: =IF(OR(F20="",F20=0),"",D20/F20) -> 0.25915081 | H20: =IF(OR(F20="",F20=0),"",E20/F20) -> 0.74084919 | I20: random forest (results only) | J20: 2.3731091 | K20: =$K$8 -> 0.29619762 | L20: =SQRT(J20^2+K20^2) -> 2.3915225 | M20: =IF(G20="","",MAX(0,G20-1.96*L20/100)) -> 0.21227696 | N20: =IF(G20="","",MIN(1,G20+1.96*L20/100)) -> 0.30602465 | O20: =ROUND(S20*W20,0) -> 61 | P20: =IF(F20="","",ROUND(SQRT((F20*L20/100)^2+(G20*O20)^2),0)) -> 23 | R20: -24.90423 | S20: =U20*V20*$F$5 -> 683.32677 | T20: =MAX(0,MIN(1,R20/100+$D$5)) -> 0.25851381 | U20: 0.65452756 | V20: 1044 | W20: 0.08874451 | X20: Medium | Y20: state rolls, precinct
A21: Carbon | B21: JIM THORPE BOROUGH | C21: JIM THORPE BOROUGH-1ST | D21: =ROUND(S21*T21,0) -> 192 | E21: =ROUND(S21,0)-D21 -> 244 | F21: =IF(COUNTA(D21:E21)=0,"",SUM(D21:E21)) -> 436 | G21: =IF(OR(F21="",F21=0),"",D21/F21) -> 0.44036697 | H21: =IF(OR(F21="",F21=0),"",E21/F21) -> 0.55963303 | I21: random forest (results only) | J21: 3.711035 | K21: =$K$8 -> 0.29619762 | L21: =SQRT(J21^2+K21^2) -> 3.7228368 | M21: =IF(G21="","",MAX(0,G21-1.96*L21/100)) -> 0.36739937 | N21: =IF(G21="","",MIN(1,G21+1.96*L21/100)) -> 0.51333457 | O21: =ROUND(S21*W21,0) -> 65 | P21: =IF(F21="","",ROUND(SQRT((F21*L21/100)^2+(G21*O21)^2),0)) -> 33 | R21: -6.8428827 | S21: =U21*V21*$F$5 -> 436.24467 | T21: =MAX(0,MIN(1,R21/100+$D$5)) -> 0.43912728 | U21: 0.62588905 | V21: 697 | W21: 0.14809733 | X21: Small | Y21: state rolls, precinct
A22: Carbon | B22: JIM THORPE BOROUGH | C22: JIM THORPE BOROUGH-2ND | D22: =ROUND(S22*T22,0) -> 118 | E22: =ROUND(S22,0)-D22 -> 162 | F22: =IF(COUNTA(D22:E22)=0,"",SUM(D22:E22)) -> 280 | G22: =IF(OR(F22="",F22=0),"",D22/F22) -> 0.42142857 | H22: =IF(OR(F22="",F22=0),"",E22/F22) -> 0.57857143 | I22: random forest (results only) | J22: 3.711035 | K22: =$K$8 -> 0.29619762 | L22: =SQRT(J22^2+K22^2) -> 3.7228368 | M22: =IF(G22="","",MAX(0,G22-1.96*L22/100)) -> 0.34846097 | N22: =IF(G22="","",MIN(1,G22+1.96*L22/100)) -> 0.49439617 | O22: =ROUND(S22*W22,0) -> 42 | P22: =IF(F22="","",ROUND(SQRT((F22*L22/100)^2+(G22*O22)^2),0)) -> 21 | R22: -8.7745582 | S22: =U22*V22*$F$5 -> 280.5 | T22: =MAX(0,MIN(1,R22/100+$D$5)) -> 0.41981053 | U22: 0.56896552 | V22: 493 | W22: 0.14809733 | X22: Small | Y22: state rolls, precinct
A23: Carbon | B23: JIM THORPE BOROUGH | C23: JIM THORPE BOROUGH-3RD | D23: =ROUND(S23*T23,0) -> 246 | E23: =ROUND(S23,0)-D23 -> 400 | F23: =IF(COUNTA(D23:E23)=0,"",SUM(D23:E23)) -> 646 | G23: =IF(OR(F23="",F23=0),"",D23/F23) -> 0.38080495 | H23: =IF(OR(F23="",F23=0),"",E23/F23) -> 0.61919505 | I23: random forest (results only) | J23: 2.3731091 | K23: =$K$8 -> 0.29619762 | L23: =SQRT(J23^2+K23^2) -> 2.3915225 | M23: =IF(G23="","",MAX(0,G23-1.96*L23/100)) -> 0.33393111 | N23: =IF(G23="","",MIN(1,G23+1.96*L23/100)) -> 0.4276788 | O23: =ROUND(S23*W23,0) -> 57 | P23: =IF(F23="","",ROUND(SQRT((F23*L23/100)^2+(G23*O23)^2),0)) -> 27 | R23: -12.665571 | S23: =U23*V23*$F$5 -> 645.69536 | T23: =MAX(0,MIN(1,R23/100+$D$5)) -> 0.3809004 | U23: 0.68984547 | V23: 936 | W23: 0.08874451 | X23: Medium | Y23: state rolls, precinct
... A381: Northampton | B381: WIND GAP | C381: WIND GAP | D381: =ROUND(S381*T381,0) -> 486 | E381: =ROUND(S381,0)-D381 -> 659 | F381: =IF(COUNTA(D381:E381)=0,"",SUM(D381:E381)) -> 1145 | G381: =IF(OR(F381="",F381=0),"",D381/F381) -> 0.42445415 | H381: =IF(OR(F381="",F381=0),"",E381/F381) -> 0.57554585 | I381: random forest (results only) | J381: 1.8861273 | K381: =$K$8 -> 0.29619762 | L381: =SQRT(J381^2+K381^2) -> 1.9092431 | M381: =IF(G381="","",MAX(0,G381-1.96*L381/100)) -> 0.38703298 | N381: =IF(G381="","",MIN(1,G381+1.96*L381/100)) -> 0.46187531 | O381: =ROUND(S381*W381,0) -> 78 | P381: =IF(F381="","",ROUND(SQRT((F381*L381/100)^2+(G381*O381)^2),0)) -> 40 | R381: -8.3179097 | S381: =U381*V381*$F$5 -> 1145.4806 | T381: =MAX(0,MIN(1,R381/100+$D$5)) -> 0.42437701 | U381: 0.53702795 | V381: 2133 | W381: 0.068475215 | X381: Large | Y381: state rolls, precinct

Sheet How Forecasts Are Weighted
A1: How the three precinct-level forecasts weigh their inputs (SHAP) — results-only random forests
A3: Forecast A — Full random forest.
A4: All 23 candidate inputs go into one random forest that forecasts the Democratic share. Nothing is weighted by hand; SHAP measures what the forest learned. This is the reference.
A5: Forecast B — SHAP-selected forest.
A6: Keeps only inputs whose average |SHAP| beat all 10 random columns in at least 18 of 20 refits and that held at least 2% of Forecast A’s SHAP total (6 of 23 kept), then refits the forest on them. Weight that was spread thinly over weak inputs is concentrated on the strong ones.
A7: Forecast C — SHAP family-reweighted forest.
A8: Keeps Forecast A’s forest but multiplies each input family’s SHAP values by a weight fitted to how well that family predicted elections the forest had not seen (leave-one-election-out, fitted within each election). Families under 3% of SHAP stay at ×1; others are limited to ×0.5–×2 because there are only three training elections.
A9: Backtests.
A10: Each 2024 backtest uses its own forecast’s weighting: A’s full input set, B’s selected inputs, and C’s exact family weights — refit only on 2020 and 2022.
A11: Turnout.
A12: Not modelled in any forecast: votes cast = each place’s 2022 turnout rate × its 2026 registered voters (2020 turnout × 2024 registered in the backtest). All differences between A, B and C come from the results model.
A14: Family share of SHAP value in votes, 2026 forecast rows
A15: Input family | B15: Forecast A | C15: Forecast B | D15: Forecast C | E15: Forecast C weight (×)
A16: Election type | B16: 0.0012953602 | C16: 0 | D16: 0.0012389737 | E16: 1
A17: Geography & municipal context | B17: 0.030777014 | C17: 0 | D17: 0.029437303 | E17: 1
A18: Historical voter data | B18: 0.73043895 | C18: 0.70204884 | D18: 0.81714939 | E18: 1.1696232
A19: Voter registration data | B19: 0.23748868 | C19: 0.29795116 | D19: 0.15217433 | E19: 0.66992619
A20: Out-of-fold pattern error before → after Forecast C’s re-weighting: 3.20 → 3.08 points.
A22: Top inputs in each forecast (share of SHAP value in votes)
A23: # | B23: Forecast A | C23: Share | D23: Forecast B | E23: Share | F23: Forecast C | G23: Share
A24: 1 | B24: Precinct House lean, last election (t−2) | C24: 0.32339513 | D24: Precinct House lean, last election (t−2) | E24: 0.21105414 | F24: Precinct House lean, last election (t−2) | G24: 0.36178538
A25: 2 | B25: Electorate last election: R % of ballots | C25: 0.19395967 | D25: Municipality House lean, last election (t−2) | E25: 0.18802891 | F25: Electorate last election: R % of ballots | G25: 0.21698463
A26: 3 | B26: Municipality House lean, last election (t−2) | C26: 0.15495316 | D26: Electorate last election: R % of ballots | E26: 0.16872764 | F26: Municipality House lean, last election (t−2) | G26: 0.17334765
A27: 4 | B27: State registration: R % (as of election) | C27: 0.10710037 | D27: State registration: R % (as of election) | E27: 0.15795358 | F27: State registration: R % (as of election) | G27: 0.068626125
A28: 5 | B28: State registration: D % (as of election) | C28: 0.069696116 | D28: State registration: D % (as of election) | E28: 0.13999758 | F28: Precinct House lean, last same-type election (t−4) | G28: 0.051334404
A29: 6 | B29: Precinct House lean, last same-type election (t−4) | C29: 0.04588714 | D29: Precinct House lean, last same-type election (t−4) | E29: 0.13423815 | F29: State registration: D % (as of election) | G29: 0.044658803
A30: 7 | B30: State registration: change in D−R margin since t−2 | C30: 0.023030423 | F30: State registration: change in D−R margin since t−2 | G30: 0.01475708
A31: 8 | B31: County: Carbon | C31: 0.013975294 | F31: County: Carbon | G31: 0.013366955
A32: 9 | B32: Precinct vs. its municipality, last election (pts) | C32: 0.012367595 | F32: Precinct vs. its municipality, last election (pts) | G32: 0.011829239
A33: 10 | B33: Voter-file party switch gap (today’s R % − state R %) | C33: 0.01173328 | F33: Voter-file party switch gap (today’s R % − state R %) | G33: 0.0075182702
A35: Forecast B — random-column test and selection
A36: Input | B36: Beat random columns (of 20) | C36: Share of SHAP in A | D36: Kept in B?
A37: Precinct House lean, last election (t−2) | B37: 20 | C37: 0.33256994 | D37: Yes
A38: Electorate last election: R % of ballots | B38: 20 | C38: 0.19581568 | D38: Yes
A39: Municipality House lean, last election (t−2) | B39: 20 | C39: 0.15379393 | D39: Yes
A40: State registration: R % (as of election) | B40: 20 | C40: 0.10618256 | D40: Yes
A41: State registration: D % (as of election) | B41: 20 | C41: 0.066351754 | D41: Yes
A42: Precinct House lean, last same-type election (t−4) | B42: 20 | C42: 0.045028211 | D42: Yes
A43: State registration: change in D−R margin since t−2 | B43: 20 | C43: 0.019772857 | D43: No
A44: County: Carbon | B44: 20 | C44: 0.013690227 | D44: No
...

Sheet Feature Ranking A
A1: Rank | B1: Feature | C1: Input family | D1: Share of model | E1: Share within its family | F1: SHAP value in votes | G1: Used to forecast | H1: Significance test result | I1: Variable (short name) | J1: Status in Forecast B
A2: 1 | B2: Democratic percent of the two-party House vote, 2024 (certified precinct results), above or below the district average | C2: Historical voter data | D2: 0.32339513 | E2: 0.4427408 | F2: 58.969595 | G2: Democratic percent of the two-party vote | H2: Beat all 10 random comparison columns in 20 of 20 refits. | I2: Precinct House lean, last election (t−2) | J2: Kept in B
A3: 2 | B3: Registered Republicans as a percent of everyone who voted, 2024 (voter file) | C3: Historical voter data | D3: 0.19395967 | E3: 0.26553851 | F3: 35.367642 | G3: Democratic percent of the two-party vote | H3: Beat all 10 random comparison columns in 20 of 20 refits. | I3: Electorate last election: R % of ballots | J3: Kept in B
A4: 3 | B4: Democratic percent of the two-party House vote in the precinct’s whole municipality, 2024, above or below the district average | C4: Historical voter data | D4: 0.15495316 | E4: 0.21213704 | F4: 28.254986 | G4: Democratic percent of the two-party vote | H4: Beat all 10 random comparison columns in 20 of 20 refits. | I4: Municipality House lean, last election (t−2) | J4: Kept in B
A5: 4 | B5: Registered Republicans as a percent of all registered voters, 2026 primary rolls (Department of State) | C5: Voter registration data | D5: 0.10710037 | E5: 0.45097043 | F5: 19.529253 | G5: Democratic percent of the two-party vote | H5: Beat all 10 random comparison columns in 20 of 20 refits. | I5: State registration: R % (as of election) | J5: Kept in B
A6: 5 | B6: Registered Democrats as a percent of all registered voters, 2026 primary rolls (Department of State) | C6: Voter registration data | D6: 0.069696116 | E6: 0.29347133 | F6: 12.708762 | G6: Democratic percent of the two-party vote | H6: Beat all 10 random comparison columns in 20 of 20 refits. | I6: State registration: D % (as of election) | J6: Kept in B
A7: 6 | B7: Democratic percent of the two-party House vote, 2022 — the last midterm (certified precinct results), above or below the district average | C7: Historical voter data | D7: 0.04588714 | E7: 0.062821321 | F7: 8.3673061 | G7: Democratic percent of the two-party vote | H7: Beat all 10 random comparison columns in 20 of 20 refits. | I7: Precinct House lean, last same-type election (t−4) | J7: Kept in B
A8: 7 | B8: Change in registered Democrats minus Republicans (percent of registered) from the 2024 general to the 2026 primary (Department of State) | C8: Voter registration data | D8: 0.023030423 | E8: 0.096974828 | F8: 4.1994904 | G8: Democratic percent of the two-party vote | H8: Beat all 10 random comparison columns in 20 of 20 refits. | I8: State registration: change in D−R margin since t−2 | J8: Dropped from B
A9: 8 | B9: Precinct is in Carbon County (1/0) | C9: Geography & municipal context | D9: 0.013975294 | E9: 0.4540822 | F9: 2.5483297 | G9: Democratic percent of the two-party vote | H9: Beat all 10 random comparison columns in 20 of 20 refits. | I9: County: Carbon | J9: Dropped from B
A10: 9 | B10: Precinct’s 2024 House Democratic percent minus its municipality’s, in points | C10: Geography & municipal context | D10: 0.012367595 | E10: 0.4018452 | F10: 2.2551734 | G10: Democratic percent of the two-party vote | H10: Beat all 10 random comparison columns in 20 of 20 refits. | I10: Precinct vs. its municipality, last election (pts) | J10: Dropped from B
A11: 10 | B11: Republican percent of registered voters in the 2026 voter file minus the Republican percent on the 2026 state rolls (a party-switching signal) | C11: Voter registration data | D11: 0.01173328 | E11: 0.049405639 | F11: 2.1395089 | G11: Democratic percent of the two-party vote | H11: Beat all 10 random comparison columns in 20 of 20 refits. | I11: Voter-file party switch gap (today’s R % − state R %) | J11: Dropped from B
A12: 11 | B12: Number of registered voters, 2026 primary rolls, on a log scale (Department of State) | C12: Voter registration data | D12: 0.0069734462 | E12: 0.029363279 | F12: 1.2715754 | G12: Democratic percent of the two-party vote | H12: Beat all 10 random comparison columns in 20 of 20 refits. | I12: Registered voters (log, state) | J12: Dropped from B
A13: 12 | B13: Registered voters born 1964 or earlier, as a percent of all registered voters, 2026 (voter file) | C13: Voter registration data | D13: 0.0062749133 | E13: 0.026421948 | F13: 1.1442012 | G13: Democratic percent of the two-party vote | H13: Beat all 10 random comparison columns in 20 of 20 refits. | I13: Registrants: Boomer + Silent % | J13: Dropped from B
... A24: 23 | B24: Election type: 1 for a midterm year (2026), 0 for a presidential year | C24: Election type | D24: 0.0012953602 | E24: 1 | F24: 0.23620289 | G24: Democratic percent of the two-party vote | H24: Beat all 10 random comparison columns in 0 of 20 refits. | I24: Midterm year (1/0) | J24: Dropped from B
