Workbook

Sheet Intro
A1: PA-07 2026 House Forecasts: Every Forecast, Compiled
A2: Kiley Meringer · PSTD 400: Senior Seminar Congressional Forecasting Project · Compiled Oct. 26, 2026
A4: Bottom line
A5: Of 19 forecasts, 14 predict that Rep. Ryan Mackenzie (R) wins, including every forecast that came within half a point of the real 2024 result. The margin is narrow: the best-tested forecasts put Bob Brooks (D) between 49.5% and 50.0% of the two-party vote. Best description: Lean Republican.
A7: What is in this workbook
A8: How to Read | B8: Definitions, how strict each backtest is, and what the ratings mean. Start here if any term is unfamiliar.
A9: Summary | B9: Headline numbers, a chart of every forecast, and how the project developed.
A10: Results | B10: One row per forecast: predicted winner, margin, 2024 backtest accuracy, rating and a one-sentence verdict.
A11: F01 Trend v2 | B11: F01–F19: one tab per forecast with its methodology, 2026 forecast, 2024 backtest and a plain-language summary on one page, followed by the town- or precinct-level detail.
A12: Bellwether Tests | B12: Every bellwether test: selection rule, stability, registration, demographics, comparison with Professor Crain’s precincts, and whether bellwethers improve the baseline.
A13: Backtest-Only Tests | B13: Twelve methods tested on 2024 but never used for a 2026 forecast.
A14: Final Assessment | B14: Ranking by backtest accuracy, how often each candidate is predicted, an accuracy-weighted forecast, and the conclusion.
A15: Data & Caveats | B15: How the data improved over the project and the main limitations.
A16: Sources | B16: Where every number comes from.
A18: Suggested reading order
A19: Summary → Results → Final Assessment, then open any forecast tab from Results for detail. Use How to Read for definitions.
A21: Conventions
A22: • All shares are Brooks’s (D) share of the two-party vote; above 50% means Brooks wins.
A23: • A “miss” is forecast minus actual, in percentage points: negative = too Republican, positive = too Democratic.
A24: • Blue numbers are typed in from source files; black numbers are formulas.

Sheet How to Read
A1: How to read this workbook
A3: The question
A4: Every forecast here answers the same question: what share of the two-party vote will Bob Brooks (D) win against Rep. Ryan Mackenzie (R) in Pennsylvania’s 7th District on Nov. 3, 2026? Above 50% means Brooks wins; below 50% means Mackenzie wins.
A6: Key terms
A7: Term | B7: Meaning
A8: Two-party share | B8: Votes for one major-party candidate divided by votes for both major-party candidates. Third-party and write-in votes are left out.
A9: Margin | B9: Brooks’s share minus Mackenzie’s share, in percentage points. A margin of −2.0 means Mackenzie leads by 2 points.
A10: Backtest | B10: A test of the method on an election that already happened. The method is run using only data from before that election, and its prediction is compared with the real result.
A11: Out of sample | B11: The election being predicted was not used to build or tune the method. This is what makes a backtest fair.
A12: In sample | B12: The method was fitted and scored on the same data. In-sample results look better than the method would do on a new election.
A13: Miss | B13: Forecast minus actual result, in percentage points. Negative = the forecast was too Republican; positive = too Democratic.
A14: Average miss per town or precinct | B14: The typical size of the error for individual towns or precincts. Good for judging the map, but towns of very different sizes count equally, so it is not comparable across levels.
A15: District result miss | B15: How far the forecast’s district-wide total was from the real district result. This is the fairest single comparison across all forecasts, and the one used to rank them.
A16: Municipal / precinct | B16: Municipal forecasts predict each of the 89 towns; precinct forecasts predict each of roughly 370 voting precincts. District totals add up those rows.
A17: Beta | B17: How strongly a town moves when the whole district moves. A beta of 1.5 means a town shifts 1.5 points for every 1 point the district shifts.
A18: Bellwether precinct | B18: A precinct whose vote has closely matched the district’s. Reading a set of bellwethers gives an estimate of the district result.
... A21: Random forest | B21: A machine-learning model that averages the predictions of hundreds of decision trees.
A23: How strict each backtest is
A24: Level | B24: Forecasts | C24: What it means
A25: Strongest | B25: F18, F19, group baseline v11 | C25: Tested on two elections (2022 and 2024). Only earlier elections were used, and turnout was projected rather than taken from the real result.
A26: Standard | B26: F04–F15 | C26: Tested on 2024 only. Trained on 2018–2022; nothing from 2024 was used.
A27: Limited | B27: F01, F16, F17, group baseline v0.1 | C27: F01 covers only Lehigh and Northampton. F16 and F17 rest on v0.1, whose 2024 backtest used actual 2024 turnout; F17’s precinct selection data are not available.
A28: Not available | B28: F02, F03 | C28: Only town-by-town accuracy was saved; the district-level check cannot be computed.
A30: What the ratings mean
A31: Rating | B31: Meaning
A32: Strongest | B32: Passed the strictest backtests. Most reliable evidence, though only two elections.
A33: Good | B33: District result miss under half a point in a standard backtest.
A34: Fair | B34: Miss between half a point and 1.5 points, or a caveat about the test.
A35: Weak | B35: Miss larger than 1.5 points. Kept for completeness; should carry little weight.
A36: Superseded | B36: Built on early data that was later corrected. Replaced by a newer version.
A38: Cell colors and formulas
A39: Blue numbers are values typed in from source files; black numbers are formulas. The Results, Final Assessment and Summary tabs recalculate automatically if a forecast tab changes.

Sheet Summary
A1: Summary
A3: Forecasts compiled | C3: =COUNTA(Results!A5:A23) -> 19
A4: Predict Mackenzie | C4: =COUNTIF(Results!H5:H23,"Mackenzie") -> 14
A5: Predict Brooks | C5: =COUNTIF(Results!H5:H23,"Brooks") -> 5
A6: Average Brooks share across forecasts | C6: =AVERAGE(Results!E5:E23) -> 0.48812613
A7: Range of Brooks share | C7: =TEXT(MIN(Results!E5:E23),"0.0%")&" to "&TEXT(MAX(Results!E5:E23),"0.0%") -> 46.0% to 51.2%
A8: Accuracy-weighted Brooks share | C8: ='Final Assessment'!F37 -> 0.48351408
A9: Accuracy-weighted winner | C9: ='Final Assessment'!F39 -> Mackenzie
A10: Best 2024 district-level backtest | C10: ='Final Assessment'!B7&": "&'Final Assessment'!C7&" ("&TEXT('Final Assessment'!E7,"+0.00;-0.00")&" pts)" -> F16: Bellwether reading, 10-precinct set, on the v0.1 baseline (-0.15 pts)
A11: Methods tested on 2024 only (no 2026 forecast) | C11: 8 new methods, plus a calibration check
A13: Story of the project
A14: • Sept. 14: three municipal methods (Trend, Beta-Adjusted, Regression) on early data with Carbon estimated and Monroe missing. Two of three favored Mackenzie.
A15: • Sept. 16–17: rebuilt on certified returns for all 89 towns, then repeated at the precinct level. Correcting the 2020 result reversed the method ranking: Beta-Adjusted became the best backtest and Regression the worst.
A16: • Sept. 24: the same methods entered in the class template; four new adjustments tested (Cycle-Type Beta adopted).
A17: • Sept. 27: five more methods backtested (Stacking and Uniform Swing best on average miss per town); no 2026 forecasts were run for these.
A18: • Oct. 21–26: bellwether precincts selected by a fixed rule, compared with Professor Crain’s set, and combined with the group baseline. Adding bellwethers did not improve the honest v11 backtests.
A20: Bottom line
A21: Most forecasts, and all of the best-backtested ones, predict a narrow Mackenzie win. The race is best described as Lean Republican with a small margin; the newest and most rigorously tested forecasts put Brooks between 49.5% and 50.0%.
A23: Brooks share by forecast (50% line = tie)
A46: Reading the chart: bars to the right of 50% predict Brooks. Most bars sit between 46% and 50%; the bars above 50% are mostly regression versions (F03, F06, F09, F15) and the v11 bellwether reading (F18).

Sheet Results
A1: Results: every forecast at a glance
A2: Each row is one 2026 forecast. “Brooks share” is Bob Brooks’s (D) share of the two-party House vote; above 50% means Brooks wins. A “miss” is the forecast minus the actual result, in percentage points: negative means the forecast was too Republican, positive too Democratic. Click a forecast name to open its full tab.
A4: ID | B4: Forecast (click to open) | C4: Date run | D4: Level of detail | E4: Brooks (D) share | F4: Mackenzie (R) share | G4: Margin, Brooks − Mackenzie (pts) | H4: Predicted winner | I4: 2024 backtest: average miss per town or precinct (pts) | J4: 2024 backtest: winners called correctly | K4: 2024 backtest: district result miss (pts) | L4: 2022 backtest: district result miss (pts) | M4: How strict the backtest was | N4: Built on superseded data? | O4: Rating | P4: Verdict in brief
A5: F01 | B5: =HYPERLINK("#'F01 Trend v2'!A1","Simple Trend (municipal, v2)") -> Simple Trend (municipal, v2) | C5: Sept. 14 | D5: Municipality (86) | E5: ='F01 Trend v2'!C14 -> 0.49372 | F5: ='F01 Trend v2'!C15 -> 0.50628 | G5: ='F01 Trend v2'!C16 -> -1.256 | H5: ='F01 Trend v2'!C17 -> Mackenzie | I5: =IF(ISNUMBER('F01 Trend v2'!C22),'F01 Trend v2'!C22,"") -> 2.18 | J5: ='F01 Trend v2'!C23 -> 57 of 63 towns | K5: =IF(ISNUMBER('F01 Trend v2'!C24),'F01 Trend v2'!C24,"") -> 1.7409974 | L5: =IF(ISNUMBER('F01 Trend v2'!C25),'F01 Trend v2'!C25,"") | M5: Out of sample (unit-level); district miss is for Lehigh + Northampton only | N5: Yes | O5: Superseded | P5: The first forecast of the project. It predicted a narrow Mackenzie win (49.4% Brooks).
A6: F02 | B6: =HYPERLINK("#'F02 Beta v2'!A1","Beta-Adjusted (municipal, v2)") -> Beta-Adjusted (municipal, v2) | C6: Sept. 14 | D6: Municipality (86) | E6: ='F02 Beta v2'!C14 -> 0.48763 | F6: ='F02 Beta v2'!C15 -> 0.51237 | G6: ='F02 Beta v2'!C16 -> -2.474 | H6: ='F02 Beta v2'!C17 -> Mackenzie | I6: =IF(ISNUMBER('F02 Beta v2'!C22),'F02 Beta v2'!C22,"") -> 1.57 | J6: ='F02 Beta v2'!C23 -> 59 of 63 towns | K6: =IF(ISNUMBER('F02 Beta v2'!C24),'F02 Beta v2'!C24,"") | L6: =IF(ISNUMBER('F02 Beta v2'!C25),'F02 Beta v2'!C25,"") | M6: Out of sample (unit-level); town-by-town backtest predictions not saved in the source file | N6: Yes | O6: Superseded | P6: Predicted Mackenzie (48.8% Brooks). Replaced by F05, which uses the same method on corrected data.
A7: F03 | B7: =HYPERLINK("#'F03 Regression v2'!A1","Multi-Variable Regression (municipal, v2)") -> Multi-Variable Regression (municipal, v2) | C7: Sept. 14 | D7: Municipality (86) | E7: ='F03 Regression v2'!C14 -> 0.51198 | F7: ='F03 Regression v2'!C15 -> 0.48802 | G7: ='F03 Regression v2'!C16 -> 2.396 | H7: ='F03 Regression v2'!C17 -> Brooks | I7: =IF(ISNUMBER('F03 Regression v2'!C22),'F03 Regression v2'!C22,"") -> 1.13 | J7: ='F03 Regression v2'!C23 -> 61 of 63 towns | K7: =IF(ISNUMBER('F03 Regression v2'!C24),'F03 Regression v2'!C24,"") | L7: =IF(ISNUMBER('F03 Regression v2'!C25),'F03 Regression v2'!C25,"") | M7: Out of sample (unit-level); town-by-town backtest predictions not saved in the source file | N7: Yes | O7: Superseded | P7: Predicted a Brooks win (51.2%). Its strong-looking backtest did not survive the switch to complete, corrected data.
A8: F04 | B8: =HYPERLINK("#'F04 Trend v3'!A1","Simple Trend (municipal, v3)") -> Simple Trend (municipal, v3) | C8: Sept. 16 | D8: Municipality (89) | E8: ='F04 Trend v3'!C14 -> 0.47727 | F8: ='F04 Trend v3'!C15 -> 0.52273 | G8: ='F04 Trend v3'!C16 -> -4.546 | H8: ='F04 Trend v3'!C17 -> Mackenzie | I8: =IF(ISNUMBER('F04 Trend v3'!C22),'F04 Trend v3'!C22,"") -> 1.99 | J8: ='F04 Trend v3'!C23 -> 86 of 89 towns | K8: =IF(ISNUMBER('F04 Trend v3'!C24),'F04 Trend v3'!C24,"") -> 0.26874283 | L8: =IF(ISNUMBER('F04 Trend v3'!C25),'F04 Trend v3'!C25,"") | M8: Out of sample | N8: No | O8: Good | P8: Predicts Mackenzie (47.7% Brooks). In 2024 it came within about a quarter point of the district result, one of the best simple-method backtests.
A9: F05 | B9: =HYPERLINK("#'F05 Beta v3'!A1","Beta-Adjusted (municipal, v3)") -> Beta-Adjusted (municipal, v3) | C9: Sept. 16 | D9: Municipality (89) | E9: ='F05 Beta v3'!C14 -> 0.46765 | F9: ='F05 Beta v3'!C15 -> 0.53235 | G9: ='F05 Beta v3'!C16 -> -6.47 | H9: ='F05 Beta v3'!C17 -> Mackenzie | I9: =IF(ISNUMBER('F05 Beta v3'!C22),'F05 Beta v3'!C22,"") -> 1.81 | J9: ='F05 Beta v3'!C23 -> 86 of 89 towns | K9: =IF(ISNUMBER('F05 Beta v3'!C24),'F05 Beta v3'!C24,"") -> 1.2854274 | L9: =IF(ISNUMBER('F05 Beta v3'!C25),'F05 Beta v3'!C25,"") | M9: Out of sample | N9: No | O9: Fair | P9: Predicts a clear Mackenzie win (46.8% Brooks). It placed individual towns well, but the town-level errors leaned in the same direction, so the district total missed by 1.3 points.
A10: F06 | B10: =HYPERLINK("#'F06 Regression v3'!A1","Multi-Variable Regression (municipal, v3)") -> Multi-Variable Regression (municipal, v3) | C10: Sept. 16 | D10: Municipality (89) | E10: ='F06 Regression v3'!C14 -> 0.50644 | F10: ='F06 Regression v3'!C15 -> 0.49356 | G10: ='F06 Regression v3'!C16 -> 1.288 | H10: ='F06 Regression v3'!C17 -> Brooks | I10: =IF(ISNUMBER('F06 Regression v3'!C22),'F06 Regression v3'!C22,"") -> 3.09 | J10: ='F06 Regression v3'!C23 -> 82 of 89 towns | K10: =IF(ISNUMBER('F06 Regression v3'!C24),'F06 Regression v3'!C24,"") -> -2.2876796 | L10: =IF(ISNUMBER('F06 Regression v3'!C25),'F06 Regression v3'!C25,"") | M10: Out of sample | N10: No | O10: Weak | P10: Predicts a Brooks win (50.6%), but it had the worst backtest of the municipal methods: it missed the 2024 district result by about 2.3 points, predicting it too Republican. Treat with caution.
A11: F07 | B11: =HYPERLINK("#'F07 Precinct Trend'!A1","Simple Trend (precinct)") -> Simple Trend (precinct) | C11: Sept. 17 | D11: Precinct (408) | E11: ='F07 Precinct Trend'!C14 -> 0.48313 | F11: ='F07 Precinct Trend'!C15 -> 0.51687 | G11: ='F07 Precinct Trend'!C16 -> -3.374 | H11: ='F07 Precinct Trend'!C17 -> Mackenzie | I11: =IF(ISNUMBER('F07 Precinct Trend'!C22),'F07 Precinct Trend'!C22,"") -> 2.24 | J11: ='F07 Precinct Trend'!C23 -> 387 of 408 precincts | K11: =IF(ISNUMBER('F07 Precinct Trend'!C24),'F07 Precinct Trend'!C24,"") -> 0.38745946 | L11: =IF(ISNUMBER('F07 Precinct Trend'!C25),'F07 Precinct Trend'!C25,"") | M11: Out of sample | N11: No | O11: Good | P11: Predicts Mackenzie (48.3% Brooks). Its 2024 backtest came within about 0.4 points of the district result.
A12: F08 | B12: =HYPERLINK("#'F08 Precinct Beta'!A1","Beta-Adjusted (precinct)") -> Beta-Adjusted (precinct) | C12: Sept. 17 | D12: Precinct (408) | E12: ='F08 Precinct Beta'!C14 -> 0.47277 | F12: ='F08 Precinct Beta'!C15 -> 0.52723 | G12: ='F08 Precinct Beta'!C16 -> -5.446 | H12: ='F08 Precinct Beta'!C17 -> Mackenzie | I12: =IF(ISNUMBER('F08 Precinct Beta'!C22),'F08 Precinct Beta'!C22,"") -> 2.09 | J12: ='F08 Precinct Beta'!C23 -> 390 of 408 precincts | K12: =IF(ISNUMBER('F08 Precinct Beta'!C24),'F08 Precinct Beta'!C24,"") -> 0.20996571 | L12: =IF(ISNUMBER('F08 Precinct Beta'!C25),'F08 Precinct Beta'!C25,"") | M12: Out of sample | N12: No | O12: Good | P12: Predicts Mackenzie (47.3% Brooks). Best district-level backtest of any town- or precinct-level method: it missed 2024 by only 0.21 points.
A13: F09 | B13: =HYPERLINK("#'F09 Precinct Regression'!A1","Multi-Variable Regression (precinct)") -> Multi-Variable Regression (precinct) | C13: Sept. 17 | D13: Precinct (408) | E13: ='F09 Precinct Regression'!C14 -> 0.50897 | F13: ='F09 Precinct Regression'!C15 -> 0.49103 | G13: ='F09 Precinct Regression'!C16 -> 1.794 | H13: ='F09 Precinct Regression'!C17 -> Brooks | I13: =IF(ISNUMBER('F09 Precinct Regression'!C22),'F09 Precinct Regression'!C22,"") -> 2.46 | J13: ='F09 Precinct Regression'!C23 -> 366 of 408 precincts | K13: =IF(ISNUMBER('F09 Precinct Regression'!C24),'F09 Precinct Regression'!C24,"") -> -1.8266567 | L13: =IF(ISNUMBER('F09 Precinct Regression'!C25),'F09 Precinct Regression'!C25,"") | M13: Out of sample | N13: No | O13: Weak | P13: Predicts a narrow Brooks win (50.9%), but like F06 it had the weakest backtest at its level, missing 2024 by about 1.8 points. Treat with caution.
A14: F10 | B14: =HYPERLINK("#'F10 Muni Template Trend'!A1","Simple Trend (municipal template)") -> Simple Trend (municipal template) | C14: Sept. 24 | D14: Municipality (89) | E14: ='F10 Muni Template Trend'!C14 -> 0.46939 | F14: ='F10 Muni Template Trend'!C15 -> 0.53061 | G14: ='F10 Muni Template Trend'!C16 -> -6.122 | H14: ='F10 Muni Template Trend'!C17 -> Mackenzie | I14: =IF(ISNUMBER('F10 Muni Template Trend'!C22),'F10 Muni Template Trend'!C22,"") -> 1.99 | J14: ='F10 Muni Template Trend'!C23 -> 86 of 89 towns | K14: =IF(ISNUMBER('F10 Muni Template Trend'!C24),'F10 Muni Template Trend'!C24,"") -> 0.26874283 | L14: =IF(ISNUMBER('F10 Muni Template Trend'!C25),'F10 Muni Template Trend'!C25,"") | M14: Out of sample (same backtest as F04) | N14: No | O14: Good | P14: Predicts Mackenzie (46.9% Brooks). The template version of F04; same strong backtest.
A15: F11 | B15: =HYPERLINK("#'F11 Muni Template Beta'!A1","Beta-Adjusted (municipal template)") -> Beta-Adjusted (municipal template) | C15: Sept. 24 | D15: Municipality (89) | E15: ='F11 Muni Template Beta'!C14 -> 0.4597 | F15: ='F11 Muni Template Beta'!C15 -> 0.5403 | G15: ='F11 Muni Template Beta'!C16 -> -8.06 | H15: ='F11 Muni Template Beta'!C17 -> Mackenzie | I15: =IF(ISNUMBER('F11 Muni Template Beta'!C22),'F11 Muni Template Beta'!C22,"") -> 1.81 | J15: ='F11 Muni Template Beta'!C23 -> 86 of 89 towns | K15: =IF(ISNUMBER('F11 Muni Template Beta'!C24),'F11 Muni Template Beta'!C24,"") -> 1.2854274 | L15: =IF(ISNUMBER('F11 Muni Template Beta'!C25),'F11 Muni Template Beta'!C25,"") | M15: Out of sample (same backtest as F05) | N15: No | O15: Fair | P15: Predicts Mackenzie (46.0% Brooks), the lowest Brooks share of any forecast. The template version of F05.
A16: F12 | B16: =HYPERLINK("#'F12 Muni Template Reg'!A1","Regression (municipal template)") -> Regression (municipal template) | C16: Sept. 24 | D16: Municipality (89) | E16: ='F12 Muni Template Reg'!C14 -> 0.49935 | F16: ='F12 Muni Template Reg'!C15 -> 0.50065 | G16: ='F12 Muni Template Reg'!C16 -> -0.13 | H16: ='F12 Muni Template Reg'!C17 -> Mackenzie | I16: =IF(ISNUMBER('F12 Muni Template Reg'!C22),'F12 Muni Template Reg'!C22,"") -> 3.09 | J16: ='F12 Muni Template Reg'!C23 -> 82 of 89 towns | K16: =IF(ISNUMBER('F12 Muni Template Reg'!C24),'F12 Muni Template Reg'!C24,"") -> -2.2876796 | L16: =IF(ISNUMBER('F12 Muni Template Reg'!C25),'F12 Muni Template Reg'!C25,"") | M16: Out of sample (same backtest as F06) | N16: No | O16: Weak | P16: Essentially a tie (49.9% Brooks), tipping to Mackenzie. The template version of F06, which had the worst municipal backtest.
A17: F13 | B17: =HYPERLINK("#'F13 Pct Template Trend'!A1","Simple Trend (precinct template)") -> Simple Trend (precinct template) | C17: Sept. 24 | D17: Precinct (370) | E17: ='F13 Pct Template Trend'!C14 -> 0.4763 | F17: ='F13 Pct Template Trend'!C15 -> 0.5237 | G17: ='F13 Pct Template Trend'!C16 -> -4.74 | H17: ='F13 Pct Template Trend'!C17 -> Mackenzie | I17: =IF(ISNUMBER('F13 Pct Template Trend'!C22),'F13 Pct Template Trend'!C22,"") -> 2.24 | J17: ='F13 Pct Template Trend'!C23 -> 387 of 408 precincts | K17: =IF(ISNUMBER('F13 Pct Template Trend'!C24),'F13 Pct Template Trend'!C24,"") -> 0.38745946 | L17: =IF(ISNUMBER('F13 Pct Template Trend'!C25),'F13 Pct Template Trend'!C25,"") | M17: Out of sample (same backtest as F07) | N17: No | O17: Good | P17: Predicts Mackenzie (47.6% Brooks). The template version of F07.
A18: F14 | B18: =HYPERLINK("#'F14 Pct Template Beta'!A1","Beta-Adjusted (precinct template)") -> Beta-Adjusted (precinct template) | C18: Sept. 24 | D18: Precinct (370) | E18: ='F14 Pct Template Beta'!C14 -> 0.46573 | F18: ='F14 Pct Template Beta'!C15 -> 0.53427 | G18: ='F14 Pct Template Beta'!C16 -> -6.854 | H18: ='F14 Pct Template Beta'!C17 -> Mackenzie | I18: =IF(ISNUMBER('F14 Pct Template Beta'!C22),'F14 Pct Template Beta'!C22,"") -> 2.09 | J18: ='F14 Pct Template Beta'!C23 -> 390 of 408 precincts | K18: =IF(ISNUMBER('F14 Pct Template Beta'!C24),'F14 Pct Template Beta'!C24,"") -> 0.20996571 | L18: =IF(ISNUMBER('F14 Pct Template Beta'!C25),'F14 Pct Template Beta'!C25,"") | M18: Out of sample (same backtest as F08) | N18: No | O18: Good | P18: Predicts Mackenzie (46.6% Brooks). The template version of F08, which had the best unit-level backtest.
A19: F15 | B19: =HYPERLINK("#'F15 Pct Template Reg'!A1","Regression (precinct template)") -> Regression (precinct template) | C19: Sept. 24 | D19: Precinct (370) | E19: ='F15 Pct Template Reg'!C14 -> 0.50487 | F19: ='F15 Pct Template Reg'!C15 -> 0.49513 | G19: ='F15 Pct Template Reg'!C16 -> 0.974 | H19: ='F15 Pct Template Reg'!C17 -> Brooks | I19: =IF(ISNUMBER('F15 Pct Template Reg'!C22),'F15 Pct Template Reg'!C22,"") -> 2.46 | J19: ='F15 Pct Template Reg'!C23 -> 366 of 408 precincts | K19: =IF(ISNUMBER('F15 Pct Template Reg'!C24),'F15 Pct Template Reg'!C24,"") -> -1.8266567 | L19: =IF(ISNUMBER('F15 Pct Template Reg'!C25),'F15 Pct Template Reg'!C25,"") | M19: Out of sample (same backtest as F09) | N19: No | O19: Weak | P19: Predicts a narrow Brooks win (50.5%). The template version of F09, which had a weak backtest.
A20: F16 | B20: =HYPERLINK("#'F16 Bellwether (v0.1)'!A1","Bellwether reading, 10-precinct set, on the v0.1 baseline") -> Bellwether reading, 10-precinct set, on the v0.1 baseline | C20: Oct. 21–22 | D20: 10 precincts | E20: ='F16 Bellwether (v0.1)'!C14 -> 0.49968331 | F20: ='F16 Bellwether (v0.1)'!C15 -> 0.50031669 | G20: ='F16 Bellwether (v0.1)'!C16 -> -0.063337901 | H20: ='F16 Bellwether (v0.1)'!C17 -> Mackenzie | I20: =IF(ISNUMBER('F16 Bellwether (v0.1)'!C22),'F16 Bellwether (v0.1)'!C22,"") | J20: ='F16 Bellwether (v0.1)'!C23 -> — | K20: =IF(ISNUMBER('F16 Bellwether (v0.1)'!C24),'F16 Bellwether (v0.1)'!C24,"") -> -0.14586132 | L20: =IF(ISNUMBER('F16 Bellwether (v0.1)'!C25),'F16 Bellwether (v0.1)'!C25,"") | M20: Out of sample selection; baseline backtest used actual turnout | N20: No | O20: Good (with caveat) | P20: Essentially a tie (49.97% Brooks), tipping to Mackenzie. Best 2024 backtest in the workbook (0.15 pts), though that test is less strict than F18’s.
A21: F17 | B21: =HYPERLINK("#'F17 Bellwether Crain 6'!A1","Bellwether reading, Professor Crain’s 6 precincts, on the v0.1 baseline") -> Bellwether reading, Professor Crain’s 6 precincts, on the v0.1 baseline | C21: Oct. 22 | D21: 6 precincts | E21: ='F17 Bellwether Crain 6'!C14 -> 0.49217551 | F21: ='F17 Bellwether Crain 6'!C15 -> 0.50782449 | G21: ='F17 Bellwether Crain 6'!C16 -> -1.5648982 | H21: ='F17 Bellwether Crain 6'!C17 -> Mackenzie | I21: =IF(ISNUMBER('F17 Bellwether Crain 6'!C22),'F17 Bellwether Crain 6'!C22,"") | J21: ='F17 Bellwether Crain 6'!C23 -> — | K21: =IF(ISNUMBER('F17 Bellwether Crain 6'!C24),'F17 Bellwether Crain 6'!C24,"") -> -0.62822898 | L21: =IF(ISNUMBER('F17 Bellwether Crain 6'!C25),'F17 Bellwether Crain 6'!C25,"") | M21: Selection data unknown; baseline backtest used actual turnout | N21: No | O21: Fair (with caveat) | P21: Predicts Mackenzie (49.2% Brooks). Its backtest missed by about 0.6 points.
A22: F18 | B22: =HYPERLINK("#'F18 Bellwether (v11)'!A1","Bellwether reading on the v11 baseline (honest rule)") -> Bellwether reading on the v11 baseline (honest rule) | C22: Oct. 26 | D22: 10 precincts | E22: ='F18 Bellwether (v11)'!C14 -> 0.50011074 | F22: ='F18 Bellwether (v11)'!C15 -> 0.49988926 | G22: ='F18 Bellwether (v11)'!C16 -> 0.022148892 | H22: ='F18 Bellwether (v11)'!C17 -> Brooks | I22: =IF(ISNUMBER('F18 Bellwether (v11)'!C22),'F18 Bellwether (v11)'!C22,"") | J22: ='F18 Bellwether (v11)'!C23 -> — | K22: =IF(ISNUMBER('F18 Bellwether (v11)'!C24),'F18 Bellwether (v11)'!C24,"") -> -0.51046282 | L22: =IF(ISNUMBER('F18 Bellwether (v11)'!C25),'F18 Bellwether (v11)'!C25,"") -> 0.2670494 | M22: Fully out of sample (2022 and 2024) | N22: No | O22: Strongest | P22: A dead heat (50.01% Brooks). The most rigorous bellwether test, but it missed both backtests by more than the v11 baseline alone (0.27 pts in 2022, 0.51 in 2024), because bellwethers chosen from earlier elections drifted away from the district.
A23: F19 | B23: =HYPERLINK("#'F19 Baseline+Bellwether'!A1","Baseline + bellwether blend (50/50, v11)") -> Baseline + bellwether blend (50/50, v11) | C23: Oct. 26 | D23: District | E23: ='F19 Baseline+Bellwether'!C14 -> 0.49752688 | F23: ='F19 Baseline+Bellwether'!C15 -> 0.50247312 | G23: ='F19 Baseline+Bellwether'!C16 -> -0.49462402 | H23: ='F19 Baseline+Bellwether'!C17 -> Mackenzie | I23: =IF(ISNUMBER('F19 Baseline+Bellwether'!C22),'F19 Baseline+Bellwether'!C22,"") | J23: ='F19 Baseline+Bellwether'!C23 -> — | K23: =IF(ISNUMBER('F19 Baseline+Bellwether'!C24),'F19 Baseline+Bellwether'!C24,"") -> -0.34444009 | L23: =IF(ISNUMBER('F19 Baseline+Bellwether'!C25),'F19 Baseline+Bellwether'!C25,"") -> 0.14387802 | M23: Fully out of sample (2022 and 2024) | N23: No | O23: Strongest | P23: Predicts a narrow Mackenzie win (49.75% Brooks). In both backtests the blend was further from the result than the v11 baseline alone (0.14 vs 0.02 pts in 2022; 0.34 vs 0.18 in 2024).
A25: Group baselines (for reference; these are the group’s models, not Kiley’s forecasts, and are not counted in any tally)
A26: G1 | B26: Group baseline v0.1 (precinct random forest, Oct. 4) | E26: 0.48727 | F26: =1-E26 -> 0.51273 | G26: =(E26-F26)*100 -> -2.546 | H26: =IF(E26>0.5,"Brooks","Mackenzie") -> Mackenzie | K26: -0.1 | M26: 2024 backtest used actual 2024 turnout
A27: G2 | B27: Group baseline v11, Forecast A (Oct. 6) | E27: 0.49496 | F27: =1-E27 -> 0.50504 | G27: =(E27-F27)*100 -> -1.008 | H27: =IF(E27>0.5,"Brooks","Mackenzie") -> Mackenzie | K27: -0.18 | L27: 0.02 | M27: Fully out of sample (2022 and 2024), projected turnout
A30: Note on F10–F15: these repeat the methods of F04–F09 in the class template and share their backtests. They differ only in projected turnout, which changes how much each town or precinct counts.

Sheet F01 Trend v2
A1: F01 · Simple Trend (municipal, v2)
A2: Run Sept. 14, 2026 · Level: Municipality (86) · Source: PA07_Analysis.xlsx (tracker: "Analysis Workbook," Sept. 14)
A3: ← Back to Results
A5: Methodology
A6: What it does: extends each town’s Democratic share along a straight line drawn through its 2018–2024 House results.
A7: Data: the first municipal file. Carbon County votes were not reported, so they were estimated from voter registration; Monroe was missing.
A8: Votes: turnout projected from the two most recent midterms (2018 and 2022).
A9: Backtest: the same straight line drawn through 2018–2022 only, used to predict 2024.
A10: Why it is superseded: this source also reported the 2020 race wrongly (as a Democratic win). F04 repeats this method on corrected data.
A13: 2026 forecast | E13: In plain terms
A14: Brooks (D) share of the two-party vote | C14: 0.49372 | E14: The first forecast of the project. It predicted a narrow Mackenzie win (49.4% Brooks). Its backtest was the weakest of the trend forecasts and it rests on incomplete data, so it is kept only to show where the project started. Read F04 instead.
A15: Mackenzie (R) share of the two-party vote | C15: =1-C14 -> 0.50628
A16: Margin: Brooks minus Mackenzie (points) | C16: =(C14-C15)*100 -> -1.256
A17: Predicted winner | C17: =IF(C14>0.5,"Brooks","Mackenzie") -> Mackenzie
A18: Brooks votes
A19: Mackenzie votes
A21: 2024 backtest | E21: Rating
A22: Average miss per town or precinct (points) | C22: 2.18 | E22: Superseded | F22: See “How to Read” for what the ratings mean.
A23: Towns or precincts where the winner was called correctly | C23: 57 of 63 towns
A24: District result miss, 2024 (points; negative = too Republican) | C24: 1.7409974
A25: District result miss, 2022 (points) | C25: not available
A26: How strict the backtest was | C26: Out of sample (unit-level); district miss is for Lehigh + Northampton only
A29: 2026 forecast detail | J29: 2024 backtest detail
A30: Municipality | B30: County | C30: Source | D30: Projected Total Votes 2026 | E30: Projected Dem Share 2026 | F30: Projected Dem Votes 2026 | G30: Projected Rep Votes 2026 | H30: Projected Winner | J30: Municipality | K30: Predicted Dem Share | L30: Actual Dem Share | M30: Error (pts) | N30: Winner Correct? (Trend)
A31: Alburtis | B31: Lehigh | C31: Actual-based | D31: 1130 | E31: 0.43013086 | F31: 486 | G31: 644 | H31: Republican | J31: Alburtis | K31: 0.46808463 | L31: 0.43964887 | M31: 2.843576 | N31: 1
A32: Allentown | B32: Lehigh | C32: Actual-based | D32: 21769 | E32: 0.63099348 | F32: 13736 | G32: 8033 | H32: Democrat | J32: Allentown | K32: 0.66255702 | L32: 0.64562222 | M32: 1.6934795 | N32: 1
A33: Bethlehem | B33: Lehigh | C33: Actual-based | D33: 8404 | E33: 0.64305726 | F33: 5404 | G33: 3000 | H33: Democrat | J33: Bethlehem | K33: 0.66197092 | L33: 0.63296956 | M33: 2.9001364 | N33: 1
A34: Catasauqua | B34: Lehigh | C34: Actual-based | D34: 2160 | E34: 0.50429424 | F34: 1089 | G34: 1071 | H34: Democrat | J34: Catasauqua | K34: 0.52058179 | L34: 0.51130777 | M34: 0.92740264 | N34: 1
A35: Coopersburg | B35: Lehigh | C35: Actual-based | D35: 1433 | E35: 0.47707595 | F35: 684 | G35: 749 | H35: Republican | J35: Coopersburg | K35: 0.49591445 | L35: 0.47758285 | M35: 1.83316 | N35: 1
A36: Coplay | B36: Lehigh | C36: Actual-based | D36: 1365 | E36: 0.49815122 | F36: 680 | G36: 685 | H36: Republican | J36: Coplay | K36: 0.51977203 | L36: 0.50027824 | M36: 1.949379 | N36: 1
A37: Emmaus | B37: Lehigh | C37: Actual-based | D37: 5598 | E37: 0.54336209 | F37: 3042 | G37: 2556 | H37: Democrat | J37: Emmaus | K37: 0.56295728 | L37: 0.53094651 | M37: 3.2010768 | N37: 1
A38: Fountain Hill | B38: Lehigh | C38: Actual-based | D38: 1480 | E38: 0.65632144 | F38: 971 | G38: 509 | H38: Democrat | J38: Fountain Hill | K38: 0.69983948 | L38: 0.64375562 | M38: 5.6083864 | N38: 1
A39: Hanover | B39: Lehigh | C39: Actual-based | D39: 431 | E39: 0.52282311 | F39: 225 | G39: 206 | H39: Democrat | J39: Hanover | K39: 0.54878412 | L39: 0.53455571 | M39: 1.4228403 | N39: 1
A40: Heidelberg | B40: Lehigh | C40: Actual-based | D40: 1774 | E40: 0.30410583 | F40: 539 | G40: 1235 | H40: Republican | J40: Heidelberg | K40: 0.31389739 | L40: 0.31247014 | M40: 0.14272563 | N40: 1
A41: Lower Macungie | B41: Lehigh | C41: Actual-based | D41: 17421 | E41: 0.50777979 | F41: 8846 | G41: 8575 | H41: Democrat | J41: Lower Macungie | K41: 0.53023123 | L41: 0.49559842 | M41: 3.4632816 | N41: 0
A42: Lower Milford | B42: Lehigh | C42: Actual-based | D42: 2422 | E42: 0.38557709 | F42: 934 | G42: 1488 | H42: Republican | J42: Lower Milford | K42: 0.38738778 | L42: 0.38311941 | M42: 0.4268373 | N42: 1
... A93: Wind Gap | B93: Northampton | C93: Actual-based | D93: 1361 | E93: 0.43273879 | F93: 589 | G93: 772 | H93: Republican | J93: Wind Gap | K93: 0.44076496 | L93: 0.42550336 | M93: 1.5261607 | N93: 1
A94: Banks Township | B94: Carbon | C94: Estimated | D94: 382 | E94: 0.5165016 | F94: 197 | G94: 185 | H94: Democrat | J94: Trend model MAE (pts) | K94: 2.1746586
A95: Beaver Meadows Borough | B95: Carbon | C95: Estimated | D95: 339 | E95: 0.3741537 | F95: 127 | G95: 212 | H95: Republican | J95: Naive model MAE (pts) | K95: 2.2487813
A96: Bowmanstown Borough | B96: Carbon | C96: Estimated | D96: 398 | E96: 0.3574788 | F96: 142 | G96: 256 | H96: Republican
...

Sheet F02 Beta v2
A1: F02 · Beta-Adjusted (municipal, v2)
A2: Run Sept. 14, 2026 · Level: Municipality (86) · Source: PA07_Analysis.xlsx (tracker: "Analysis Workbook," Sept. 14)
A3: ← Back to Results
A5: Methodology
A6: What it does: measures each town’s “beta,” how strongly it moves when the district as a whole moves (an idea borrowed from finance).
A7: Forecast: each town’s 2024 result plus its beta times the district’s projected shift from 2024 to 2026.
A8: Data: the same early file as F01 (Carbon estimated, Monroe missing, 2020 misreported).
A9: Backtest: town-level accuracy only. The town-by-town backtest predictions were not saved, so a district-level check is not possible.
A13: 2026 forecast | E13: In plain terms
A14: Brooks (D) share of the two-party vote | C14: 0.48763 | E14: Predicted Mackenzie (48.8% Brooks). Replaced by F05, which uses the same method on corrected data.
A15: Mackenzie (R) share of the two-party vote | C15: =1-C14 -> 0.51237
A16: Margin: Brooks minus Mackenzie (points) | C16: =(C14-C15)*100 -> -2.474
A17: Predicted winner | C17: =IF(C14>0.5,"Brooks","Mackenzie") -> Mackenzie
A18: Brooks votes
A19: Mackenzie votes
A21: 2024 backtest | E21: Rating
A22: Average miss per town or precinct (points) | C22: 1.57 | E22: Superseded | F22: See “How to Read” for what the ratings mean.
A23: Towns or precincts where the winner was called correctly | C23: 59 of 63 towns
A24: District result miss, 2024 (points; negative = too Republican) | C24: not available
A25: District result miss, 2022 (points) | C25: not available
A26: How strict the backtest was | C26: Out of sample (unit-level); town-by-town backtest predictions not saved in the source file
A29: 2026 forecast detail | J29: 2024 backtest detail
A30: Municipality | B30: County | C30: Method | D30: Projected Total Votes | E30: Projected Dem Share | F30: Projected Dem Votes | G30: Projected Rep Votes | H30: Projected Winner | J30: Town-by-town backtest predictions for this method were not saved in the source file; the summary metrics above come from its Model Comparison sheet.
A31: Alburtis | B31: Lehigh | C31: Beta-Adjusted | D31: 1130 | E31: 0.42583526 | F31: 481 | G31: 649 | H31: Republican
A32: Allentown | B32: Lehigh | C32: Beta-Adjusted | D32: 21769 | E32: 0.63378379 | F32: 13797 | G32: 7972 | H32: Democrat
A33: Bethlehem | B33: Lehigh | C33: Beta-Adjusted | D33: 8404 | E33: 0.63126609 | F33: 5305 | G33: 3099 | H33: Democrat
A34: Catasauqua | B34: Lehigh | C34: Beta-Adjusted | D34: 2160 | E34: 0.5014158 | F34: 1083 | G34: 1077 | H34: Democrat
A35: Coopersburg | B35: Lehigh | C35: Beta-Adjusted | D35: 1433 | E35: 0.46835255 | F35: 671 | G35: 762 | H35: Republican
A36: Coplay | B36: Lehigh | C36: Beta-Adjusted | D36: 1365 | E36: 0.491101 | F36: 670 | G36: 695 | H36: Republican
A37: Emmaus | B37: Lehigh | C37: Beta-Adjusted | D37: 5598 | E37: 0.52921819 | F37: 2963 | G37: 2635 | H37: Democrat
A38: Fountain Hill | B38: Lehigh | C38: Beta-Adjusted | D38: 1480 | E38: 0.64025327 | F38: 948 | G38: 532 | H38: Democrat
A39: Hanover | B39: Lehigh | C39: Beta-Adjusted | D39: 431 | E39: 0.52631866 | F39: 227 | G39: 204 | H39: Democrat
A40: Heidelberg | B40: Lehigh | C40: Beta-Adjusted | D40: 1774 | E40: 0.30307598 | F40: 538 | G40: 1236 | H40: Republican
A41: Lower Macungie | B41: Lehigh | C41: Beta-Adjusted | D41: 17421 | E41: 0.49387002 | F41: 8604 | G41: 8817 | H41: Republican
A42: Lower Milford | B42: Lehigh | C42: Beta-Adjusted | D42: 2422 | E42: 0.37966284 | F42: 920 | G42: 1502 | H42: Republican
... A116: Weissport Borough | B116: Carbon | C116: Registration Calibration | D116: 128 | E116: 0.403347 | F116: 52 | G116: 76 | H116: Republican

Sheet F03 Regression v2
A1: F03 · Multi-Variable Regression (municipal, v2)
A2: Run Sept. 14, 2026 · Level: Municipality (86) · Source: PA07_Analysis.xlsx (tracker: "Analysis Workbook," Sept. 14)
A3: ← Back to Results
A5: Methodology
A6: What it does: a regression that predicts each town’s Democratic share from four things: party registration, share of adults with a bachelor’s degree, whether it is a presidential year, and the town’s previous result.
A7: Equation: Dem share = 16.63 + 18.07 × (registration D−R) + 7.62 × (% bachelor’s) − 3.67 × (presidential year) + 0.656 × (previous Dem share).
A8: Data: the same early file as F01. On this incomplete data the regression looked like the best method; on corrected data (F06) it became the worst.
A9: Backtest: town-level accuracy only; a district-level check is not possible.
A13: 2026 forecast | E13: In plain terms
A14: Brooks (D) share of the two-party vote | C14: 0.51198 | E14: Predicted a Brooks win (51.2%). Its strong-looking backtest did not survive the switch to complete, corrected data. Read F06 instead.
A15: Mackenzie (R) share of the two-party vote | C15: =1-C14 -> 0.48802
A16: Margin: Brooks minus Mackenzie (points) | C16: =(C14-C15)*100 -> 2.396
A17: Predicted winner | C17: =IF(C14>0.5,"Brooks","Mackenzie") -> Brooks
A18: Brooks votes
A19: Mackenzie votes
A21: 2024 backtest | E21: Rating
A22: Average miss per town or precinct (points) | C22: 1.13 | E22: Superseded | F22: See “How to Read” for what the ratings mean.
A23: Towns or precincts where the winner was called correctly | C23: 61 of 63 towns
A24: District result miss, 2024 (points; negative = too Republican) | C24: not available
A25: District result miss, 2022 (points) | C25: not available
A26: How strict the backtest was | C26: Out of sample (unit-level); town-by-town backtest predictions not saved in the source file
A29: 2026 forecast detail | J29: 2024 backtest detail
A30: Municipality | B30: County | C30: Method | D30: Projected Total Votes | E30: Projected Dem Share | F30: Projected Dem Votes | G30: Projected Rep Votes | H30: Projected Winner | J30: Town-by-town backtest predictions for this method were not saved in the source file; the summary metrics above come from its Model Comparison sheet.
A31: Alburtis | B31: Lehigh | C31: Regression | D31: 1130 | E31: 0.47577554 | F31: 538 | G31: 592 | H31: Republican
A32: Allentown | B32: Lehigh | C32: Regression | D32: 21769 | E32: 0.66458249 | F32: 14467 | G32: 7302 | H32: Democrat
A33: Bethlehem | B33: Lehigh | C33: Regression | D33: 8404 | E33: 0.65763423 | F33: 5527 | G33: 2877 | H33: Democrat
A34: Catasauqua | B34: Lehigh | C34: Regression | D34: 2160 | E34: 0.54232395 | F34: 1171 | G34: 989 | H34: Democrat
A35: Coopersburg | B35: Lehigh | C35: Regression | D35: 1433 | E35: 0.49255005 | F35: 706 | G35: 727 | H35: Republican
A36: Coplay | B36: Lehigh | C36: Regression | D36: 1365 | E36: 0.5274993 | F36: 720 | G36: 645 | H36: Democrat
A37: Emmaus | B37: Lehigh | C37: Regression | D37: 5598 | E37: 0.55161 | F37: 3088 | G37: 2510 | H37: Democrat
A38: Fountain Hill | B38: Lehigh | C38: Regression | D38: 1480 | E38: 0.66861305 | F38: 990 | G38: 490 | H38: Democrat
A39: Hanover | B39: Lehigh | C39: Regression | D39: 431 | E39: 0.56391389 | F39: 243 | G39: 188 | H39: Democrat
A40: Heidelberg | B40: Lehigh | C40: Regression | D40: 1774 | E40: 0.3298394 | F40: 585 | G40: 1189 | H40: Republican
A41: Lower Macungie | B41: Lehigh | C41: Regression | D41: 17421 | E41: 0.52624106 | F41: 9168 | G41: 8253 | H41: Democrat
A42: Lower Milford | B42: Lehigh | C42: Regression | D42: 2422 | E42: 0.3989437 | F42: 966 | G42: 1456 | H42: Republican
... A116: Weissport Borough | B116: Carbon | C116: Registration Calibration | D116: 128 | E116: 0.403347 | F116: 52 | G116: 76 | H116: Republican

Sheet F04 Trend v3
A1: F04 · Simple Trend (municipal, v3)
A2: Run Sept. 16, 2026 · Level: Municipality (89) · Source: PA07_Analysis (2).xlsx (tracker: "Backtest & Forecast Analysis Update," Sept. 16)
A3: ← Back to Results
A5: Methodology
A6: What it does: extends each town’s Democratic share along a straight line drawn through its 2018–2024 House results.
A7: Data: certified returns for all 89 towns in the current district (Carbon and Monroe now real data). The 2020 result was corrected: Republicans won it, so the district has alternated D-R-D-R.
A8: Backtest: the line drawn through 2018–2022 only, used to predict 2024. Nothing from 2024 was used.
A13: 2026 forecast | E13: In plain terms
A14: Brooks (D) share of the two-party vote | C14: 0.47727 | E14: Predicts Mackenzie (47.7% Brooks). In 2024 it came within about a quarter point of the district result, one of the best simple-method backtests. A reliable, easy-to-explain reference forecast.
A15: Mackenzie (R) share of the two-party vote | C15: =1-C14 -> 0.52273
A16: Margin: Brooks minus Mackenzie (points) | C16: =(C14-C15)*100 -> -4.546
A17: Predicted winner | C17: =IF(C14>0.5,"Brooks","Mackenzie") -> Mackenzie
A18: Brooks votes
A19: Mackenzie votes
A21: 2024 backtest | E21: Rating
A22: Average miss per town or precinct (points) | C22: 1.99 | E22: Good | F22: See “How to Read” for what the ratings mean.
A23: Towns or precincts where the winner was called correctly | C23: 86 of 89 towns
A24: District result miss, 2024 (points; negative = too Republican) | C24: 0.26874283
A25: District result miss, 2022 (points) | C25: not available
A26: How strict the backtest was | C26: Out of sample
A29: 2026 forecast detail | I29: 2024 backtest detail
A30: Municipality | B30: County | C30: Projected Total Votes | D30: Projected Dem Share | E30: Projected Dem Votes | F30: Projected Rep Votes | G30: Projected Winner | I30: Municipality | J30: Predicted Dem Share (Trend) | K30: Actual Dem Share | L30: Trend Error (pts) | M30: Trend Winner Correct?
A31: Banks Township | B31: Carbon | C31: 391 | D31: 0.3558994 | E31: 139 | F31: 252 | G31: Republican | I31: Banks Township | J31: 0.30658478 | K31: 0.38841202 | L31: -8.1827236 | M31: 1
A32: Beaver Meadows Borough | B32: Carbon | C32: 341 | D32: 0.25054939 | E32: 85 | F32: 256 | G32: Republican | I32: Beaver Meadows Borough | J32: 0.21872725 | K32: 0.28229665 | L32: -6.3569402 | M32: 1
A33: Bowmanstown Borough | B33: Carbon | C33: 411 | D33: 0.30379586 | E33: 125 | F33: 286 | G33: Republican | I33: Bowmanstown Borough | J33: 0.30806586 | K33: 0.31718062 | L33: -0.91147571 | M33: 1
A34: East Penn Township | B34: Carbon | C34: 1483 | D34: 0.23635959 | E34: 351 | F34: 1132 | G34: Republican | I34: East Penn Township | J34: 0.24380138 | K34: 0.25901833 | L34: -1.5216955 | M34: 1
A35: East Side Borough | B35: Carbon | C35: 111 | D35: 0.2823389 | E35: 31 | F35: 80 | G35: Republican | I35: East Side Borough | J35: 0.3031894 | K35: 0.32758621 | L35: -2.4396811 | M35: 1
A36: Franklin Township | B36: Carbon | C36: 2258 | D36: 0.25857475 | E36: 584 | F36: 1674 | G36: Republican | I36: Franklin Township | J36: 0.25135692 | K36: 0.27721222 | L36: -2.5855293 | M36: 1
A37: Jim Thorpe Borough | B37: Carbon | C37: 2411 | D37: 0.41121642 | E37: 991 | F37: 1420 | G37: Republican | I37: Jim Thorpe Borough | J37: 0.42151537 | K37: 0.4270793 | L37: -0.55639296 | M37: 1
A38: Kidder Township | B38: Carbon | C38: 912 | D38: 0.32519874 | E38: 297 | F38: 615 | G38: Republican | I38: Kidder Township | J38: 0.30908561 | K38: 0.33492366 | L38: -2.5838053 | M38: 1
A39: Lansford Borough | B39: Carbon | C39: 1078 | D39: 0.3584428 | E39: 386 | F39: 692 | G39: Republican | I39: Lansford Borough | J39: 0.37118771 | K39: 0.395189 | L39: -2.4001294 | M39: 1
A40: Lausanne Township | B40: Carbon | C40: 142 | D40: 0.25381798 | E40: 36 | F40: 106 | G40: Republican | I40: Lausanne Township | J40: 0.29698511 | K40: 0.26206897 | L40: 3.4916149 | M40: 1
A41: Lehigh Township | B41: Carbon | C41: 278 | D41: 0.21907245 | E41: 61 | F41: 217 | G41: Republican | I41: Lehigh Township | J41: 0.21574705 | K41: 0.21167883 | L41: 0.40682152 | M41: 1
A42: Lehighton Borough | B42: Carbon | C42: 1900 | D42: 0.37121931 | E42: 705 | F42: 1195 | G42: Republican | I42: Lehighton Borough | J42: 0.38906899 | K42: 0.38847737 | L42: 0.05916284 | M42: 1
... A119: Wind Gap | B119: Northampton | C119: 1391 | D119: 0.42454097 | E119: 591 | F119: 800 | G119: Republican | I119: Wind Gap | J119: 0.42983453 | K119: 0.42550336 | L119: 0.4331177 | M119: 1

Sheet F05 Beta v3
A1: F05 · Beta-Adjusted (municipal, v3)
A2: Run Sept. 16, 2026 · Level: Municipality (89) · Source: PA07_Analysis (2).xlsx (tracker: "Backtest & Forecast Analysis Update," Sept. 16)
A3: ← Back to Results
A5: Methodology
A6: What it does: each town’s 2024 result plus its beta (how strongly it swings with the district) times the district’s projected 2024→2026 shift.
A7: Data: certified returns for all 89 towns. Betas are measured over 2018–2024; the backtest betas use 2018–2022 only.
A8: Backtest: best town-by-town accuracy of the Sept. 16 methods (1.81 pts), but the town errors added up to a district miss of about 1.3 points.
A13: 2026 forecast | E13: In plain terms
A14: Brooks (D) share of the two-party vote | C14: 0.46765 | E14: Predicts a clear Mackenzie win (46.8% Brooks). It placed individual towns well, but the town-level errors leaned in the same direction, so the district total missed by 1.3 points. Its Brooks share is among the lowest of all forecasts.
A15: Mackenzie (R) share of the two-party vote | C15: =1-C14 -> 0.53235
A16: Margin: Brooks minus Mackenzie (points) | C16: =(C14-C15)*100 -> -6.47
A17: Predicted winner | C17: =IF(C14>0.5,"Brooks","Mackenzie") -> Mackenzie
A18: Brooks votes
A19: Mackenzie votes
A21: 2024 backtest | E21: Rating
A22: Average miss per town or precinct (points) | C22: 1.81 | E22: Fair | F22: See “How to Read” for what the ratings mean.
A23: Towns or precincts where the winner was called correctly | C23: 86 of 89 towns
A24: District result miss, 2024 (points; negative = too Republican) | C24: 1.2854274
A25: District result miss, 2022 (points) | C25: not available
A26: How strict the backtest was | C26: Out of sample
A29: 2026 forecast detail | I29: 2024 backtest detail
A30: Municipality | B30: County | C30: Projected Total Votes | D30: Projected Dem Share | E30: Projected Dem Votes | F30: Projected Rep Votes | G30: Projected Winner | I30: Municipality | J30: Beta-Adj Predicted Share | K30: Actual Dem Share | L30: Beta-Adj Error (pts) | M30: Beta-Adj Winner Correct?
A31: Banks Township | B31: Carbon | C31: 391 | D31: 0.36354873 | E31: 142 | F31: 249 | G31: Republican | I31: Banks Township | J31: 0.34217727 | K31: 0.38841202 | L31: -4.6234743 | M31: 1
A32: Beaver Meadows Borough | B32: Carbon | C32: 341 | D32: 0.25230594 | E32: 86 | F32: 255 | G32: Republican | I32: Beaver Meadows Borough | J32: 0.25367759 | K32: 0.28229665 | L32: -2.8619061 | M32: 1
A33: Bowmanstown Borough | B33: Carbon | C33: 411 | D33: 0.27130024 | E33: 112 | F33: 299 | G33: Republican | I33: Bowmanstown Borough | J33: 0.32656465 | K33: 0.31718062 | L33: 0.93840325 | M33: 1
A34: East Penn Township | B34: Carbon | C34: 1483 | D34: 0.2221331 | E34: 329 | F34: 1154 | G34: Republican | I34: East Penn Township | J34: 0.2697552 | K34: 0.25901833 | L34: 1.0736871 | M34: 1
A35: East Side Borough | B35: Carbon | C35: 111 | D35: 0.28804306 | E35: 32 | F35: 79 | G35: Republican | I35: East Side Borough | J35: 0.35033421 | K35: 0.32758621 | L35: 2.2747999 | M35: 1
A36: Franklin Township | B36: Carbon | C36: 2258 | D36: 0.25100756 | E36: 567 | F36: 1691 | G36: Republican | I36: Franklin Township | J36: 0.27261462 | K36: 0.27721222 | L36: -0.45975927 | M36: 1
A37: Jim Thorpe Borough | B37: Carbon | C37: 2411 | D37: 0.39365254 | E37: 949 | F37: 1462 | G37: Republican | I37: Jim Thorpe Borough | J37: 0.44051077 | K37: 0.4270793 | L37: 1.3431469 | M37: 1
A38: Kidder Township | B38: Carbon | C38: 912 | D38: 0.32089831 | E38: 293 | F38: 619 | G38: Republican | I38: Kidder Township | J38: 0.3206431 | K38: 0.33492366 | L38: -1.4280567 | M38: 1
A39: Lansford Borough | B39: Carbon | C39: 1078 | D39: 0.35484185 | E39: 383 | F39: 695 | G39: Republican | I39: Lansford Borough | J39: 0.41069815 | K39: 0.395189 | L39: 1.5509146 | M39: 1
A40: Lausanne Township | B40: Carbon | C40: 142 | D40: 0.23780742 | E40: 34 | F40: 108 | G40: Republican | I40: Lausanne Township | J40: 0.30648463 | K40: 0.26206897 | L40: 4.4415667 | M40: 1
A41: Lehigh Township | B41: Carbon | C41: 278 | D41: 0.21076248 | E41: 59 | F41: 219 | G41: Republican | I41: Lehigh Township | J41: 0.20900933 | K41: 0.21167883 | L41: -0.26695065 | M41: 1
A42: Lehighton Borough | B42: Carbon | C42: 1900 | D42: 0.34833996 | E42: 662 | F42: 1238 | G42: Republican | I42: Lehighton Borough | J42: 0.4100046 | K42: 0.38847737 | L42: 2.1527237 | M42: 1
... A119: Wind Gap | B119: Northampton | C119: 1391 | D119: 0.40437863 | E119: 562 | F119: 829 | G119: Republican | I119: Wind Gap | J119: 0.43333593 | K119: 0.42550336 | L119: 0.78325749 | M119: 1

Sheet F06 Regression v3
A1: F06 · Multi-Variable Regression (municipal, v3)
A2: Run Sept. 16, 2026 · Level: Municipality (89) · Source: PA07_Analysis (2).xlsx (tracker: "Backtest & Forecast Analysis Update," Sept. 16)
A3: ← Back to Results
A5: Methodology
A6: What it does: a regression on party registration, % bachelor’s degree, presidential year and the previous result.
A7: Equation: Dem share = 9.61 + 0.0975 × (registration D−R, pts) + 10.539 × (% bachelor’s) − 4.688 × (presidential year) + 0.767 × (previous Dem share).
A8: Backtest: trained on 2020–2022 only, used to predict 2024. It had the worst backtest of the three methods, likely because it relies on “last result plus a change,” which fails in a district that alternates parties.
A13: 2026 forecast | E13: In plain terms
A14: Brooks (D) share of the two-party vote | C14: 0.50644 | E14: Predicts a Brooks win (50.6%), but it had the worst backtest of the municipal methods: it missed the 2024 district result by about 2.3 points, predicting it too Republican. Treat with caution.
A15: Mackenzie (R) share of the two-party vote | C15: =1-C14 -> 0.49356
A16: Margin: Brooks minus Mackenzie (points) | C16: =(C14-C15)*100 -> 1.288
A17: Predicted winner | C17: =IF(C14>0.5,"Brooks","Mackenzie") -> Brooks
A18: Brooks votes
A19: Mackenzie votes
A21: 2024 backtest | E21: Rating
A22: Average miss per town or precinct (points) | C22: 3.09 | E22: Weak | F22: See “How to Read” for what the ratings mean.
A23: Towns or precincts where the winner was called correctly | C23: 82 of 89 towns
A24: District result miss, 2024 (points; negative = too Republican) | C24: -2.2876796
A25: District result miss, 2022 (points) | C25: not available
A26: How strict the backtest was | C26: Out of sample
A29: 2026 forecast detail | I29: 2024 backtest detail
A30: Municipality | B30: County | C30: Projected Total Votes | D30: Projected Dem Share | E30: Projected Dem Votes | F30: Projected Rep Votes | G30: Projected Winner | I30: Municipality | J30: Reg. Predicted Share | K30: Actual Dem Share | L30: Reg. Error (pts) | M30: Reg. Winner Correct?
A31: Banks Township | B31: Carbon | C31: 391 | D31: 0.40803849 | E31: 160 | F31: 231 | G31: Republican | I31: Banks Township | J31: 0.31908422 | K31: 0.38841202 | L31: -6.9327796 | M31: 1
A32: Beaver Meadows Borough | B32: Carbon | C32: 341 | D32: 0.30210975 | E32: 103 | F32: 238 | G32: Republican | I32: Beaver Meadows Borough | J32: 0.22278668 | K32: 0.28229665 | L32: -5.9509975 | M32: 1
A33: Bowmanstown Borough | B33: Carbon | C33: 411 | D33: 0.34649276 | E33: 142 | F33: 269 | G33: Republican | I33: Bowmanstown Borough | J33: 0.31367265 | K33: 0.31718062 | L33: -0.35079667 | M33: 1
A34: East Penn Township | B34: Carbon | C34: 1483 | D34: 0.28076953 | E34: 416 | F34: 1067 | G34: Republican | I34: East Penn Township | J34: 0.23340984 | K34: 0.25901833 | L34: -2.560849 | M34: 1
A35: East Side Borough | B35: Carbon | C35: 111 | D35: 0.34821671 | E35: 39 | F35: 72 | G35: Republican | I35: East Side Borough | J35: 0.30071708 | K35: 0.32758621 | L35: -2.686913 | M35: 1
A36: Franklin Township | B36: Carbon | C36: 2258 | D36: 0.3014448 | E36: 681 | F36: 1577 | G36: Republican | I36: Franklin Township | J36: 0.24035086 | K36: 0.27721222 | L36: -3.6861353 | M36: 1
A37: Jim Thorpe Borough | B37: Carbon | C37: 2411 | D37: 0.45039431 | E37: 1086 | F37: 1325 | G37: Republican | I37: Jim Thorpe Borough | J37: 0.41312678 | K37: 0.4270793 | L37: -1.3952527 | M37: 1
A38: Kidder Township | B38: Carbon | C38: 912 | D38: 0.36018189 | E38: 328 | F38: 584 | G38: Republican | I38: Kidder Township | J38: 0.29159561 | K38: 0.33492366 | L38: -4.3328058 | M38: 1
A39: Lansford Borough | B39: Carbon | C39: 1078 | D39: 0.41157552 | E39: 444 | F39: 634 | G39: Republican | I39: Lansford Borough | J39: 0.36738246 | K39: 0.395189 | L39: -2.7806541 | M39: 1
A40: Lausanne Township | B40: Carbon | C40: 142 | D40: 0.27654167 | E40: 39 | F40: 103 | G40: Republican | I40: Lausanne Township | J40: 0.24647011 | K40: 0.26206897 | L40: -1.5598859 | M40: 1
A41: Lehigh Township | B41: Carbon | C41: 278 | D41: 0.21887815 | E41: 61 | F41: 217 | G41: Republican | I41: Lehigh Township | J41: 0.148859 | K41: 0.21167883 | L41: -6.2819836 | M41: 1
A42: Lehighton Borough | B42: Carbon | C42: 1900 | D42: 0.39809846 | E42: 756 | F42: 1144 | G42: Republican | I42: Lehighton Borough | J42: 0.36640698 | K42: 0.38847737 | L42: -2.2070388 | M42: 1
... A119: Wind Gap | B119: Northampton | C119: 1391 | D119: 0.44142103 | E119: 614 | F119: 777 | G119: Republican | I119: Wind Gap | J119: 0.39863344 | K119: 0.42550336 | L119: -2.6869913 | M119: 1

Sheet F07 Precinct Trend
A1: F07 · Simple Trend (precinct)
A2: Run Sept. 17, 2026 · Level: Precinct (408) · Source: Precinct Backtest & Forecast Analysis.xlsx (tracker, Sept. 17)
A3: ← Back to Results
A5: Methodology
A6: What it does: the straight-line trend method from F04, applied to each precinct instead of each town.
A7: Data: certified precinct House results for 2018–2024 from the Department of State precinct summary, which keeps precinct codes stable across years.
A8: Backtest: line drawn through 2018–2022, used to predict 2024. District-level miss is measured over in-district precincts only.
A13: 2026 forecast | E13: In plain terms
A14: Brooks (D) share of the two-party vote | C14: 0.48313 | E14: Predicts Mackenzie (48.3% Brooks). Its 2024 backtest came within about 0.4 points of the district result. Confirms F04 at a finer level of detail.
A15: Mackenzie (R) share of the two-party vote | C15: =1-C14 -> 0.51687
A16: Margin: Brooks minus Mackenzie (points) | C16: =(C14-C15)*100 -> -3.374
A17: Predicted winner | C17: =IF(C14>0.5,"Brooks","Mackenzie") -> Mackenzie
A18: Brooks votes
A19: Mackenzie votes
A21: 2024 backtest | E21: Rating
A22: Average miss per town or precinct (points) | C22: 2.24 | E22: Good | F22: See “How to Read” for what the ratings mean.
A23: Towns or precincts where the winner was called correctly | C23: 387 of 408 precincts
A24: District result miss, 2024 (points; negative = too Republican) | C24: 0.38745946
A25: District result miss, 2022 (points) | C25: not available
A26: How strict the backtest was | C26: Out of sample
A29: 2026 forecast detail | J29: 2024 backtest detail
A30: County | B30: Municipality | C30: Precinct | D30: Projected Total Votes | E30: Projected Dem Share | F30: Projected Dem Votes | G30: Projected Rep Votes | H30: Projected Winner | J30: County | K30: Municipality | L30: Precinct | M30: Trend Predicted | N30: Actual Dem Share | O30: Trend Error | P30: Trend Correct?
A31: Carbon | B31: BANKS | C31: 10 | D31: 391 | E31: 0.3558994 | F31: 139 | G31: 252 | H31: Republican | J31: Carbon | K31: BANKS | L31: 10 | M31: 0.30658478 | N31: 0.38841202 | O31: -8.1827236 | P31: 1
A32: Carbon | B32: BEAVER MEADOWS | C32: 40 | D32: 341 | E32: 0.25054939 | F32: 85 | G32: 256 | H32: Republican | J32: Carbon | K32: BEAVER MEADOWS | L32: 40 | M32: 0.21872725 | N32: 0.28229665 | O32: -6.3569402 | P32: 1
A33: Carbon | B33: BOWMANSTOWN | C33: 50 | D33: 411 | E33: 0.30379586 | F33: 125 | G33: 286 | H33: Republican | J33: Carbon | K33: BOWMANSTOWN | L33: 50 | M33: 0.30806586 | N33: 0.31718062 | O33: -0.91147571 | P33: 1
A34: Carbon | B34: EAST PENN | C34: 60 | D34: 786 | E34: 0.21578077 | F34: 170 | G34: 616 | H34: Republican | J34: Carbon | K34: EAST PENN | L34: 60 | M34: 0.23626047 | N34: 0.24085006 | O34: -0.45895919 | P34: 1
A35: Carbon | B35: EAST PENN | C35: 65 | D35: 697 | E35: 0.25733276 | F35: 179 | G35: 518 | H35: Republican | J35: Carbon | K35: EAST PENN | L35: 65 | M35: 0.25260566 | N35: 0.27725118 | O35: -2.4645523 | P35: 1
A36: Carbon | B36: EAST SIDE | C36: 70 | D36: 111 | E36: 0.2823389 | F36: 31 | G36: 80 | H36: Republican | J36: Carbon | K36: EAST SIDE | L36: 70 | M36: 0.3031894 | N36: 0.32758621 | O36: -2.4396811 | P36: 1
A37: Carbon | B37: FRANKLIN | C37: 80 | D37: 522 | E37: 0.24215798 | F37: 126 | G37: 396 | H37: Republican | J37: Carbon | K37: FRANKLIN | L37: 80 | M37: 0.25228175 | N37: 0.26666667 | O37: -1.438492 | P37: 1
A38: Carbon | B38: FRANKLIN | C38: 90 | D38: 960 | E38: 0.26608357 | F38: 255 | G38: 705 | H38: Republican | J38: Carbon | K38: FRANKLIN | L38: 90 | M38: 0.25731054 | N38: 0.2877095 | O38: -3.0398958 | P38: 1
A39: Carbon | B39: FRANKLIN | C39: 100 | D39: 776 | E39: 0.2612572 | F39: 203 | G39: 573 | H39: Republican | J39: Carbon | K39: FRANKLIN | L39: 100 | M39: 0.24367968 | N39: 0.2716763 | O39: -2.7996617 | P39: 1
A40: Carbon | B40: JIM THORPE | C40: 110 | D40: 480 | E40: 0.39462235 | F40: 189 | G40: 291 | H40: Republican | J40: Carbon | K40: JIM THORPE | L40: 110 | M40: 0.38427139 | N40: 0.43984962 | O40: -5.5578234 | P40: 1
A41: Carbon | B41: JIM THORPE | C41: 120 | D41: 338 | E41: 0.43354982 | F41: 147 | G41: 191 | H41: Republican | J41: Carbon | K41: JIM THORPE | L41: 120 | M41: 0.44973264 | N41: 0.41943734 | O41: 3.0295296 | P41: 1
A42: Carbon | B42: JIM THORPE | C42: 130 | D42: 690 | E42: 0.34762431 | F42: 240 | G42: 450 | H42: Republican | J42: Carbon | K42: JIM THORPE | L42: 130 | M42: 0.33993793 | N42: 0.38278146 | O42: -4.2843525 | P42: 1
... A438: Northampton | B438: WIND GAP | C438: 1360 | D438: 1391 | E438: 0.42454097 | F438: 591 | G438: 800 | H438: Republican | J438: Northampton | K438: WIND GAP | L438: 1360 | M438: 0.42983453 | N438: 0.42550336 | O438: 0.4331177 | P438: 1

Sheet F08 Precinct Beta
A1: F08 · Beta-Adjusted (precinct)
A2: Run Sept. 17, 2026 · Level: Precinct (408) · Source: Precinct Backtest & Forecast Analysis.xlsx (tracker, Sept. 17)
A3: ← Back to Results
A5: Methodology
A6: What it does: the beta method from F05, applied to each precinct.
A7: Data: the same precinct file as F07.
A8: Backtest: betas measured on 2018–2022 only, used to predict 2024.
A13: 2026 forecast | E13: In plain terms
A14: Brooks (D) share of the two-party vote | C14: 0.47277 | E14: Predicts Mackenzie (47.3% Brooks). Best district-level backtest of any town- or precinct-level method: it missed 2024 by only 0.21 points. One of the most credible forecasts in this workbook.
A15: Mackenzie (R) share of the two-party vote | C15: =1-C14 -> 0.52723
A16: Margin: Brooks minus Mackenzie (points) | C16: =(C14-C15)*100 -> -5.446
A17: Predicted winner | C17: =IF(C14>0.5,"Brooks","Mackenzie") -> Mackenzie
A18: Brooks votes
A19: Mackenzie votes
A21: 2024 backtest | E21: Rating
A22: Average miss per town or precinct (points) | C22: 2.09 | E22: Good | F22: See “How to Read” for what the ratings mean.
A23: Towns or precincts where the winner was called correctly | C23: 390 of 408 precincts
A24: District result miss, 2024 (points; negative = too Republican) | C24: 0.20996571
A25: District result miss, 2022 (points) | C25: not available
A26: How strict the backtest was | C26: Out of sample
A29: 2026 forecast detail | J29: 2024 backtest detail
A30: County | B30: Municipality | C30: Precinct | D30: Projected Total Votes | E30: Projected Dem Share | F30: Projected Dem Votes | G30: Projected Rep Votes | H30: Projected Winner | J30: County | K30: Municipality | L30: Precinct | M30: Beta-Adj Predicted | N30: Actual Dem Share | O30: Beta-Adj Error | P30: Beta-Adj Correct?
A31: Carbon | B31: BANKS | C31: 10 | D31: 391 | E31: 0.36102331 | F31: 141 | G31: 250 | H31: Republican | J31: Carbon | K31: BANKS | L31: 10 | M31: 0.30751194 | N31: 0.38841202 | O31: -8.0900074 | P31: 1
A32: Carbon | B32: BEAVER MEADOWS | C32: 40 | D32: 341 | E32: 0.24892555 | F32: 85 | G32: 256 | H32: Republican | J32: Carbon | K32: BEAVER MEADOWS | L32: 40 | M32: 0.21906598 | N32: 0.28229665 | O32: -6.3230675 | P32: 1
A33: Carbon | B33: BOWMANSTOWN | C33: 50 | D33: 411 | E33: 0.26896879 | F33: 111 | G33: 300 | H33: Republican | J33: Carbon | K33: BOWMANSTOWN | L33: 50 | M33: 0.29731179 | N33: 0.31718062 | O33: -1.9868823 | P33: 1
