Workbook

Sheet Read Me
A1: PA-07 2026 Forecast: Baseline vs. Baseline + Bellwether
A2: Kiley Meringer · PSTD 400 · October 2026
A4: What this workbook does
A5: It compares two ways of forecasting the district’s Democratic share of the two-party House vote, and backtests both on 2022 and 2024:
A6: Baseline: the group’s precinct random forest (v11, Forecast A: full random forest), summed over all precincts.
A7: Bellwether reading: the same model’s prediction for 10 bellwether precincts only, minus the set’s usual lean (offset).
A8: Baseline + bellwether: a weighted average of the two. The weight is an input on the Summary sheet (default 50/50).
A10: Why v11 is the baseline here
A11: v11 is the only group model with honest forward backtests for both 2022 and 2024: each backtest forest was trained only on elections before the target, and turnout was projected rather than taken from actual results. The earlier v0.1 baseline (48.7%) has a 2024 backtest only, built with actual turnout; it is shown for reference on the Reference v0.1 sheet.
A13: Bellwether selection rule (same for every election; applied by formula in Precinct Data)
A14: 1. Use the two most recent general elections before the target: 2018 and 2020 for the 2022 backtest; 2020 and 2022 for 2024; 2022 and 2024 for the 2026 forecast.
A15: 2. Eligible: at least 300 two-party House votes in both of those elections; the precinct still exists on the 2026 lines; and it has a comparable result in the target backtest.
... A30: Sources: data citations.

Sheet Summary
A1: Summary: baseline vs. baseline + bellwether
A2: Democratic (Brooks) share of the two-party House vote. Misses are estimate minus actual, in points.
A5: Weight on the baseline (input; 1 = baseline only, 0 = bellwethers only) | C5: 0.5
A7: Election | B7: Actual | C7: Baseline | D7: Bellwether reading | E7: Baseline + bellwether | F7: Miss: baseline | G7: Miss: bellwether | H7: Miss: combined | I7: Winner called correctly by combined?
A8: 2022 backtest | B8: ='Backtest 2022'!C26 -> 0.507753 | C8: ='Backtest 2022'!C23 -> 0.50796007 | D8: ='Backtest 2022'!C22 -> 0.51042349 | E8: ='Backtest 2022'!C25 -> 0.50919178 | F8: ='Backtest 2022'!C27 -> 0.02070664 | G8: ='Backtest 2022'!C28 -> 0.2670494 | H8: ='Backtest 2022'!C29 -> 0.14387802 | I8: =IF((E8>0.5)=(B8>0.5),"Yes","No") -> Yes
A9: 2024 backtest | B9: ='Backtest 2024'!C26 -> 0.49262491 | C9: ='Backtest 2024'!C23 -> 0.49084073 | D9: ='Backtest 2024'!C22 -> 0.48752028 | E9: ='Backtest 2024'!C25 -> 0.48918051 | F9: ='Backtest 2024'!C27 -> -0.17841735 | G9: ='Backtest 2024'!C28 -> -0.51046282 | H9: ='Backtest 2024'!C29 -> -0.34444009 | I9: =IF((E9>0.5)=(B9>0.5),"Yes","No") -> Yes
A10: Average absolute miss, 2022 and 2024 | F10: =AVERAGE(ABS(F8),ABS(F9)) -> 0.099561997 | G10: =AVERAGE(ABS(G8),ABS(G9)) -> 0.38875611 | H10: =AVERAGE(ABS(H8),ABS(H9)) -> 0.24415905
A11: 2026 forecast | C11: ='Forecast 2026'!C23 -> 0.49494302 | D11: ='Forecast 2026'!C22 -> 0.50011074 | E11: ='Forecast 2026'!C25 -> 0.49752688 | I11: =IF(E11>0.5,"Brooks","Mackenzie") -> Mackenzie
A12: 2026 margin, Brooks minus Mackenzie (pts) | C12: =(2*C11-1)*100 -> -1.0113969 | D12: =(2*D11-1)*100 -> 0.022148892 | E12: =(2*E11-1)*100 -> -0.49462402
A14: Weight sensitivity (fixed weights, independent of the input above)
A15: Weight on baseline | B15: 2022 miss | C15: 2024 miss | D15: Average absolute miss | E15: 2026 Brooks share
A16: 1 | B16: =(A16*'Backtest 2022'!C23+(1-A16)*'Backtest 2022'!C22-'Backtest 2022'!C26)*100 -> 0.02070664 | C16: =(A16*'Backtest 2024'!C23+(1-A16)*'Backtest 2024'!C22-'Backtest 2024'!C26)*100 -> -0.17841735 | D16: =AVERAGE(ABS(B16),ABS(C16)) -> 0.099561997 | E16: =A16*'Forecast 2026'!C23+(1-A16)*'Forecast 2026'!C22 -> 0.49494302
A17: 0.75 | B17: =(A17*'Backtest 2022'!C23+(1-A17)*'Backtest 2022'!C22-'Backtest 2022'!C26)*100 -> 0.082292329 | C17: =(A17*'Backtest 2024'!C23+(1-A17)*'Backtest 2024'!C22-'Backtest 2024'!C26)*100 -> -0.26142872 | D17: =AVERAGE(ABS(B17),ABS(C17)) -> 0.17186052 | E17: =A17*'Forecast 2026'!C23+(1-A17)*'Forecast 2026'!C22 -> 0.49623495
A18: 0.5 | B18: =(A18*'Backtest 2022'!C23+(1-A18)*'Backtest 2022'!C22-'Backtest 2022'!C26)*100 -> 0.14387802 | C18: =(A18*'Backtest 2024'!C23+(1-A18)*'Backtest 2024'!C22-'Backtest 2024'!C26)*100 -> -0.34444009 | D18: =AVERAGE(ABS(B18),ABS(C18)) -> 0.24415905 | E18: =A18*'Forecast 2026'!C23+(1-A18)*'Forecast 2026'!C22 -> 0.49752688
A19: 0.25 | B19: =(A19*'Backtest 2022'!C23+(1-A19)*'Backtest 2022'!C22-'Backtest 2022'!C26)*100 -> 0.20546371 | C19: =(A19*'Backtest 2024'!C23+(1-A19)*'Backtest 2024'!C22-'Backtest 2024'!C26)*100 -> -0.42745145 | D19: =AVERAGE(ABS(B19),ABS(C19)) -> 0.31645758 | E19: =A19*'Forecast 2026'!C23+(1-A19)*'Forecast 2026'!C22 -> 0.49881881
A20: 0 | B20: =(A20*'Backtest 2022'!C23+(1-A20)*'Backtest 2022'!C22-'Backtest 2022'!C26)*100 -> 0.2670494 | C20: =(A20*'Backtest 2024'!C23+(1-A20)*'Backtest 2024'!C22-'Backtest 2024'!C26)*100 -> -0.51046282 | D20: =AVERAGE(ABS(B20),ABS(C20)) -> 0.38875611 | E20: =A20*'Forecast 2026'!C23+(1-A20)*'Forecast 2026'!C22 -> 0.50011074
A22: Reading the results
A23: In both backtests the baseline alone was closest to the actual result; adding the bellwether reading moved the estimate further away. The sensitivity table shows the miss growing as weight shifts to the bellwethers.
A24: The bellwethers chosen from earlier elections drifted from the district in the target year (Backtest sheets, “did the bellwethers stay bellwethers?”), and the baseline’s error on those 10 precincts did not cancel that drift.
A25: For 2026 the bellwether reading (about 50.0%) is more Democratic than the baseline (about 49.5%), so any weight on the bellwethers moves the forecast toward Brooks. The backtests do not support doing so; the bellwethers are better used as an election-night check.
A26: Two backtests are a small sample. Treat these as evidence, not proof.

Sheet Backtest 2022
A1: 2022 backtest: 10 bellwethers chosen from 2018 and 2020 results
A2: 2022 results were not used to choose these precincts. The baseline forecast for 2022 comes from the v11 backtest forest trained only on earlier elections.
A4: Rank | B4: Data row | C4: Precinct | D4: County | E4: Gap 2018 | F4: Gap 2020 | G4: D votes 2018 | H4: Two-party votes 2018 | I4: D votes 2020 | J4: Two-party votes 2020 | K4: Baseline pred D | L4: Baseline pred R | M4: Baseline pred D share | N4: Actual D | O4: Actual R | P4: Actual D share
A5: 1 | B5: =MATCH(A5,'Precinct Data'!$Z$1:$Z$379,0) -> 133 | C5: {=INDEX('Precinct Data'!$F$1:$F$379,$B5)} -> EMMAUS 5TH DISTRICT | D5: {=INDEX('Precinct Data'!$B$1:$B$379,$B5)} -> Lehigh | E5: {=INDEX('Precinct Data'!$U$1:$U$379,$B5)} -> -0.55509077 | F5: {=INDEX('Precinct Data'!$V$1:$V$379,$B5)} -> -0.43282439 | G5: {=INDEX('Precinct Data'!$I$1:$I$379,$B5)} -> 259 | H5: {=INDEX('Precinct Data'!$Q$1:$Q$379,$B5)} -> 490 | I5: {=INDEX('Precinct Data'!$K$1:$K$379,$B5)} -> 325 | J5: {=INDEX('Precinct Data'!$R$1:$R$379,$B5)} -> 659 | K5: {=INDEX('Baseline Rows'!$D$1:$D$366,MATCH($C5,'Baseline Rows'!$C$1:$C$366,0))} -> 261 | L5: {=INDEX('Baseline Rows'!$E$1:$E$366,MATCH($C5,'Baseline Rows'!$C$1:$C$366,0))} -> 247 | M5: =K5/(K5+L5) -> 0.51377953 | N5: {=INDEX('Baseline Rows'!$F$1:$F$366,MATCH($C5,'Baseline Rows'!$C$1:$C$366,0))} -> 294 | O5: {=INDEX('Baseline Rows'!$G$1:$G$366,MATCH($C5,'Baseline Rows'!$C$1:$C$366,0))} -> 260 | P5: =N5/(N5+O5) -> 0.53068592
A6: 2 | B6: =MATCH(A6,'Precinct Data'!$Z$1:$Z$379,0) -> 180 | C6: {=INDEX('Precinct Data'!$F$1:$F$379,$B6)} -> SOUTH WHITEHALL 8TH DISTRICT | D6: {=INDEX('Precinct Data'!$B$1:$B$379,$B6)} -> Lehigh | E6: {=INDEX('Precinct Data'!$U$1:$U$379,$B6)} -> -0.59399423 | F6: {=INDEX('Precinct Data'!$V$1:$V$379,$B6)} -> -0.71473669 | G6: {=INDEX('Precinct Data'!$I$1:$I$379,$B6)} -> 834 | H6: {=INDEX('Precinct Data'!$Q$1:$Q$379,$B6)} -> 1579 | I6: {=INDEX('Precinct Data'!$K$1:$K$379,$B6)} -> 1169 | J6: {=INDEX('Precinct Data'!$R$1:$R$379,$B6)} -> 2384 | K6: {=INDEX('Baseline Rows'!$D$1:$D$366,MATCH($C6,'Baseline Rows'!$C$1:$C$366,0))} -> 920 | L6: {=INDEX('Baseline Rows'!$E$1:$E$366,MATCH($C6,'Baseline Rows'!$C$1:$C$366,0))} -> 920 | M6: =K6/(K6+L6) -> 0.5 | N6: {=INDEX('Baseline Rows'!$F$1:$F$366,MATCH($C6,'Baseline Rows'!$C$1:$C$366,0))} -> 1062 | O6: {=INDEX('Baseline Rows'!$G$1:$G$366,MATCH($C6,'Baseline Rows'!$C$1:$C$366,0))} -> 971 | P6: =N6/(N6+O6) -> 0.52238072
A7: 3 | B7: =MATCH(A7,'Precinct Data'!$Z$1:$Z$379,0) -> 162 | C7: {=INDEX('Precinct Data'!$F$1:$F$379,$B7)} -> SALISBURY 1ST WARD | D7: {=INDEX('Precinct Data'!$B$1:$B$379,$B7)} -> Lehigh | E7: {=INDEX('Precinct Data'!$U$1:$U$379,$B7)} -> 0.88884164 | F7: {=INDEX('Precinct Data'!$V$1:$V$379,$B7)} -> 0.57353668 | G7: {=INDEX('Precinct Data'!$I$1:$I$379,$B7)} -> 505 | H7: {=INDEX('Precinct Data'!$Q$1:$Q$379,$B7)} -> 930 | I7: {=INDEX('Precinct Data'!$K$1:$K$379,$B7)} -> 700 | J7: {=INDEX('Precinct Data'!$R$1:$R$379,$B7)} -> 1391 | K7: {=INDEX('Baseline Rows'!$D$1:$D$366,MATCH($C7,'Baseline Rows'!$C$1:$C$366,0))} -> 505 | L7: {=INDEX('Baseline Rows'!$E$1:$E$366,MATCH($C7,'Baseline Rows'!$C$1:$C$366,0))} -> 460 | M7: =K7/(K7+L7) -> 0.52331606 | N7: {=INDEX('Baseline Rows'!$F$1:$F$366,MATCH($C7,'Baseline Rows'!$C$1:$C$366,0))} -> 504 | O7: {=INDEX('Baseline Rows'!$G$1:$G$366,MATCH($C7,'Baseline Rows'!$C$1:$C$366,0))} -> 501 | P7: =N7/(N7+O7) -> 0.50149254
A8: 4 | B8: =MATCH(A8,'Precinct Data'!$Z$1:$Z$379,0) -> 163 | C8: {=INDEX('Precinct Data'!$F$1:$F$379,$B8)} -> SALISBURY 2ND WARD | D8: {=INDEX('Precinct Data'!$B$1:$B$379,$B8)} -> Lehigh | E8: {=INDEX('Precinct Data'!$U$1:$U$379,$B8)} -> 0.91468945 | F8: {=INDEX('Precinct Data'!$V$1:$V$379,$B8)} -> 0.43918352 | G8: {=INDEX('Precinct Data'!$I$1:$I$379,$B8)} -> 565 | H8: {=INDEX('Precinct Data'!$Q$1:$Q$379,$B8)} -> 1040 | I8: {=INDEX('Precinct Data'!$K$1:$K$379,$B8)} -> 796 | J8: {=INDEX('Precinct Data'!$R$1:$R$379,$B8)} -> 1586 | K8: {=INDEX('Baseline Rows'!$D$1:$D$366,MATCH($C8,'Baseline Rows'!$C$1:$C$366,0))} -> 568 | L8: {=INDEX('Baseline Rows'!$E$1:$E$366,MATCH($C8,'Baseline Rows'!$C$1:$C$366,0))} -> 526 | M8: =K8/(K8+L8) -> 0.51919561 | N8: {=INDEX('Baseline Rows'!$F$1:$F$366,MATCH($C8,'Baseline Rows'!$C$1:$C$366,0))} -> 602 | O8: {=INDEX('Baseline Rows'!$G$1:$G$366,MATCH($C8,'Baseline Rows'!$C$1:$C$366,0))} -> 577 | P8: =N8/(N8+O8) -> 0.51060221
A9: 5 | B9: =MATCH(A9,'Precinct Data'!$Z$1:$Z$379,0) -> 254 | C9: {=INDEX('Precinct Data'!$F$1:$F$379,$B9)} -> BETHLEHEM TWSP 2ND WARD 3RD DISTRICT | D9: {=INDEX('Precinct Data'!$B$1:$B$379,$B9)} -> Northampton | E9: {=INDEX('Precinct Data'!$U$1:$U$379,$B9)} -> 1.0455977 | F9: {=INDEX('Precinct Data'!$V$1:$V$379,$B9)} -> 0.96318214 | G9: {=INDEX('Precinct Data'!$I$1:$I$379,$B9)} -> 226 | H9: {=INDEX('Precinct Data'!$Q$1:$Q$379,$B9)} -> 415 | I9: {=INDEX('Precinct Data'!$K$1:$K$379,$B9)} -> 320 | J9: {=INDEX('Precinct Data'!$R$1:$R$379,$B9)} -> 631 | K9: {=INDEX('Baseline Rows'!$D$1:$D$366,MATCH($C9,'Baseline Rows'!$C$1:$C$366,0))} -> 227 | L9: {=INDEX('Baseline Rows'!$E$1:$E$366,MATCH($C9,'Baseline Rows'!$C$1:$C$366,0))} -> 210 | M9: =K9/(K9+L9) -> 0.5194508 | N9: {=INDEX('Baseline Rows'!$F$1:$F$366,MATCH($C9,'Baseline Rows'!$C$1:$C$366,0))} -> 279 | O9: {=INDEX('Baseline Rows'!$G$1:$G$366,MATCH($C9,'Baseline Rows'!$C$1:$C$366,0))} -> 214 | P9: =N9/(N9+O9) -> 0.56592292
A10: 6 | B10: =MATCH(A10,'Precinct Data'!$Z$1:$Z$379,0) -> 173 | C10: {=INDEX('Precinct Data'!$F$1:$F$379,$B10)} -> SOUTH WHITEHALL 1ST DISTRICT | D10: {=INDEX('Precinct Data'!$B$1:$B$379,$B10)} -> Lehigh | E10: {=INDEX('Precinct Data'!$U$1:$U$379,$B10)} -> 1.3328644 | F10: {=INDEX('Precinct Data'!$V$1:$V$379,$B10)} -> -0.99997159 | G10: {=INDEX('Precinct Data'!$I$1:$I$379,$B10)} -> 698 | H10: {=INDEX('Precinct Data'!$Q$1:$Q$379,$B10)} -> 1275 | I10: {=INDEX('Precinct Data'!$K$1:$K$379,$B10)} -> 897 | J10: {=INDEX('Precinct Data'!$R$1:$R$379,$B10)} -> 1840 | K10: {=INDEX('Baseline Rows'!$D$1:$D$366,MATCH($C10,'Baseline Rows'!$C$1:$C$366,0))} -> 679 | L10: {=INDEX('Baseline Rows'!$E$1:$E$366,MATCH($C10,'Baseline Rows'!$C$1:$C$366,0))} -> 662 | M10: =K10/(K10+L10) -> 0.50633855 | N10: {=INDEX('Baseline Rows'!$F$1:$F$366,MATCH($C10,'Baseline Rows'!$C$1:$C$366,0))} -> 745 | O10: {=INDEX('Baseline Rows'!$G$1:$G$366,MATCH($C10,'Baseline Rows'!$C$1:$C$366,0))} -> 675 | P10: =N10/(N10+O10) -> 0.52464789
A11: 7 | B11: =MATCH(A11,'Precinct Data'!$Z$1:$Z$379,0) -> 165 | C11: {=INDEX('Precinct Data'!$F$1:$F$379,$B11)} -> SALISBURY 3RD WARD 2ND DIST | D11: {=INDEX('Precinct Data'!$B$1:$B$379,$B11)} -> Lehigh | E11: {=INDEX('Precinct Data'!$U$1:$U$379,$B11)} -> -1.0492847 | F11: {=INDEX('Precinct Data'!$V$1:$V$379,$B11)} -> 1.3835297 | G11: {=INDEX('Precinct Data'!$I$1:$I$379,$B11)} -> 277 | H11: {=INDEX('Precinct Data'!$Q$1:$Q$379,$B11)} -> 529 | I11: {=INDEX('Precinct Data'!$K$1:$K$379,$B11)} -> 406 | J11: {=INDEX('Precinct Data'!$R$1:$R$379,$B11)} -> 794 | K11: {=INDEX('Baseline Rows'!$D$1:$D$366,MATCH($C11,'Baseline Rows'!$C$1:$C$366,0))} -> 279 | L11: {=INDEX('Baseline Rows'!$E$1:$E$366,MATCH($C11,'Baseline Rows'!$C$1:$C$366,0))} -> 272 | M11: =K11/(K11+L11) -> 0.50635209 | N11: {=INDEX('Baseline Rows'!$F$1:$F$366,MATCH($C11,'Baseline Rows'!$C$1:$C$366,0))} -> 331 | O11: {=INDEX('Baseline Rows'!$G$1:$G$366,MATCH($C11,'Baseline Rows'!$C$1:$C$366,0))} -> 297 | P11: =N11/(N11+O11) -> 0.52707006
A12: 8 | B12: =MATCH(A12,'Precinct Data'!$Z$1:$Z$379,0) -> 299 | C12: {=INDEX('Precinct Data'!$F$1:$F$379,$B12)} -> HANOVER #4 | D12: {=INDEX('Precinct Data'!$B$1:$B$379,$B12)} -> Northampton | E12: {=INDEX('Precinct Data'!$U$1:$U$379,$B12)} -> -1.4948295 | F12: {=INDEX('Precinct Data'!$V$1:$V$379,$B12)} -> 1.4712426 | G12: {=INDEX('Precinct Data'!$I$1:$I$379,$B12)} -> 528 | H12: {=INDEX('Precinct Data'!$Q$1:$Q$379,$B12)} -> 1017 | I12: {=INDEX('Precinct Data'!$K$1:$K$379,$B12)} -> 734 | J12: {=INDEX('Precinct Data'!$R$1:$R$379,$B12)} -> 1433 | K12: {=INDEX('Baseline Rows'!$D$1:$D$366,MATCH($C12,'Baseline Rows'!$C$1:$C$366,0))} -> 521 | L12: {=INDEX('Baseline Rows'!$E$1:$E$366,MATCH($C12,'Baseline Rows'!$C$1:$C$366,0))} -> 497 | M12: =K12/(K12+L12) -> 0.51178782 | N12: {=INDEX('Baseline Rows'!$F$1:$F$366,MATCH($C12,'Baseline Rows'!$C$1:$C$366,0))} -> 603 | O12: {=INDEX('Baseline Rows'!$G$1:$G$366,MATCH($C12,'Baseline Rows'!$C$1:$C$366,0))} -> 543 | P12: =N12/(N12+O12) -> 0.52617801
A13: 9 | B13: =MATCH(A13,'Precinct Data'!$Z$1:$Z$379,0) -> 181 | C13: {=INDEX('Precinct Data'!$F$1:$F$379,$B13)} -> UPPER MACUNGIE 1ST DISTRICT | D13: {=INDEX('Precinct Data'!$B$1:$B$379,$B13)} -> Lehigh | E13: {=INDEX('Precinct Data'!$U$1:$U$379,$B13)} -> -1.5153116 | F13: {=INDEX('Precinct Data'!$V$1:$V$379,$B13)} -> 0.60790162 | G13: {=INDEX('Precinct Data'!$I$1:$I$379,$B13)} -> 725 | H13: {=INDEX('Precinct Data'!$Q$1:$Q$379,$B13)} -> 1397 | I13: {=INDEX('Precinct Data'!$K$1:$K$379,$B13)} -> 985 | J13: {=INDEX('Precinct Data'!$R$1:$R$379,$B13)} -> 1956 | K13: {=INDEX('Baseline Rows'!$D$1:$D$366,MATCH($C13,'Baseline Rows'!$C$1:$C$366,0))} -> 754 | L13: {=INDEX('Baseline Rows'!$E$1:$E$366,MATCH($C13,'Baseline Rows'!$C$1:$C$366,0))} -> 723 | M13: =K13/(K13+L13) -> 0.51049425 | N13: {=INDEX('Baseline Rows'!$F$1:$F$366,MATCH($C13,'Baseline Rows'!$C$1:$C$366,0))} -> 812 | O13: {=INDEX('Baseline Rows'!$G$1:$G$366,MATCH($C13,'Baseline Rows'!$C$1:$C$366,0))} -> 703 | P13: =N13/(N13+O13) -> 0.5359736
A14: 10 | B14: =MATCH(A14,'Precinct Data'!$Z$1:$Z$379,0) -> 164 | C14: {=INDEX('Precinct Data'!$F$1:$F$379,$B14)} -> SALISBURY 3RD WARD 1ST DIST | D14: {=INDEX('Precinct Data'!$B$1:$B$379,$B14)} -> Lehigh | E14: {=INDEX('Precinct Data'!$U$1:$U$379,$B14)} -> -1.6668537 | F14: {=INDEX('Precinct Data'!$V$1:$V$379,$B14)} -> -0.70105854 | G14: {=INDEX('Precinct Data'!$I$1:$I$379,$B14)} -> 252 | H14: {=INDEX('Precinct Data'!$Q$1:$Q$379,$B14)} -> 487 | I14: {=INDEX('Precinct Data'!$K$1:$K$379,$B14)} -> 361 | J14: {=INDEX('Precinct Data'!$R$1:$R$379,$B14)} -> 736 | K14: {=INDEX('Baseline Rows'!$D$1:$D$366,MATCH($C14,'Baseline Rows'!$C$1:$C$366,0))} -> 248 | L14: {=INDEX('Baseline Rows'!$E$1:$E$366,MATCH($C14,'Baseline Rows'!$C$1:$C$366,0))} -> 251 | M14: =K14/(K14+L14) -> 0.49699399 | N14: {=INDEX('Baseline Rows'!$F$1:$F$366,MATCH($C14,'Baseline Rows'!$C$1:$C$366,0))} -> 292 | O14: {=INDEX('Baseline Rows'!$G$1:$G$366,MATCH($C14,'Baseline Rows'!$C$1:$C$366,0))} -> 268 | P14: =N14/(N14+O14) -> 0.52142857
C15: Set combined | G15: =SUM(G5:G14) -> 4869 | H15: =SUM(H5:H14) -> 9159 | I15: =SUM(I5:I14) -> 6693 | J15: =SUM(J5:J14) -> 13410 | K15: =SUM(K5:K14) -> 4962 | L15: =SUM(L5:L14) -> 4768 | M15: =K15/(K15+L15) -> 0.50996917 | N15: =SUM(N5:N14) -> 5524 | O15: =SUM(O5:O14) -> 5009 | P15: =N15/(N15+O15) -> 0.52444698
A18: Set gap, 2018 (pts) | C18: =(G15/H15-District!B4)*100 -> -0.25140821
A19: Set gap, 2020 (pts) | C19: =(I15/J15-District!B5)*100 -> 0.16054295
A20: Offset: average of the two gaps (pts) | C20: =AVERAGE(C18:C19) -> -0.045432627
A21: Baseline prediction for the set | C21: =M15 -> 0.50996917
A22: Bellwether reading of the district (set prediction − offset) | C22: =C21-C20/100 -> 0.51042349
A23: Baseline district prediction (all precincts) | C23: =SUMIFS('Baseline Rows'!$D$2:$D$366,'Baseline Rows'!$H$2:$H$366,TRUE())/(SUMIFS('Baseline Rows'!$D$2:$D$366,'Baseline Rows'!$H$2:$H$366,TRUE())+SUMIFS('Baseline Rows'!$E$2:$E$366,'Baseline Rows'!$H$2:$H$366,TRUE())) -> 0.50796007
A24: Weight on baseline (from Summary) | C24: =Summary!$C$5 -> 0.5
A25: Baseline + bellwether | C25: =C24*C23+(1-C24)*C22 -> 0.50919178
A26: Actual district result (comparable precincts) | C26: =SUMIFS('Baseline Rows'!$F$2:$F$366,'Baseline Rows'!$H$2:$H$366,TRUE())/(SUMIFS('Baseline Rows'!$F$2:$F$366,'Baseline Rows'!$H$2:$H$366,TRUE())+SUMIFS('Baseline Rows'!$G$2:$G$366,'Baseline Rows'!$H$2:$H$366,TRUE())) -> 0.507753
A27: Miss: baseline (pts) | C27: =(C23-C26)*100 -> 0.02070664
A28: Miss: bellwether reading (pts) | C28: =(C22-C26)*100 -> 0.2670494
A29: Miss: baseline + bellwether (pts) | C29: =(C25-C26)*100 -> 0.14387802
A30: Set actual vs. district actual (pts): did the bellwethers stay bellwethers? | C30: =(P15-C26)*100 -> 1.6693976
A31: Baseline miss on the set itself (pts) | C31: =(M15-P15)*100 -> -1.4477809

Sheet Backtest 2024
A1: 2024 backtest: 10 bellwethers chosen from 2020 and 2022 results
A2: 2024 results were not used to choose these precincts. The baseline forecast for 2024 comes from the v11 backtest forest trained only on earlier elections.
A4: Rank | B4: Data row | C4: Precinct | D4: County | E4: Gap 2020 | F4: Gap 2022 | G4: D votes 2020 | H4: Two-party votes 2020 | I4: D votes 2022 | J4: Two-party votes 2022 | K4: Baseline pred D | L4: Baseline pred R | M4: Baseline pred D share | N4: Actual D | O4: Actual R | P4: Actual D share
A5: 1 | B5: =MATCH(A5,'Precinct Data'!$AB$1:$AB$379,0) -> 163 | C5: {=INDEX('Precinct Data'!$G$1:$G$379,$B5)} -> SALISBURY 2ND WARD | D5: {=INDEX('Precinct Data'!$B$1:$B$379,$B5)} -> Lehigh | E5: {=INDEX('Precinct Data'!$V$1:$V$379,$B5)} -> 0.43918352 | F5: {=INDEX('Precinct Data'!$W$1:$W$379,$B5)} -> 0.077199821 | G5: {=INDEX('Precinct Data'!$K$1:$K$379,$B5)} -> 796 | H5: {=INDEX('Precinct Data'!$R$1:$R$379,$B5)} -> 1586 | I5: {=INDEX('Precinct Data'!$M$1:$M$379,$B5)} -> 602 | J5: {=INDEX('Precinct Data'!$S$1:$S$379,$B5)} -> 1179 | K5: {=INDEX('Baseline Rows'!$I$1:$I$366,MATCH($C5,'Baseline Rows'!$C$1:$C$366,0))} -> 802 | L5: {=INDEX('Baseline Rows'!$J$1:$J$366,MATCH($C5,'Baseline Rows'!$C$1:$C$366,0))} -> 820 | M5: =K5/(K5+L5) -> 0.49445129 | N5: {=INDEX('Baseline Rows'!$K$1:$K$366,MATCH($C5,'Baseline Rows'!$C$1:$C$366,0))} -> 803 | O5: {=INDEX('Baseline Rows'!$L$1:$L$366,MATCH($C5,'Baseline Rows'!$C$1:$C$366,0))} -> 818 | P5: =N5/(N5+O5) -> 0.49537323
A6: 2 | B6: =MATCH(A6,'Precinct Data'!$AB$1:$AB$379,0) -> 141 | C6: {=INDEX('Precinct Data'!$G$1:$G$379,$B6)} -> LOWER MACUNGIE 2ND DISTRICT | D6: {=INDEX('Precinct Data'!$B$1:$B$379,$B6)} -> Lehigh | E6: {=INDEX('Precinct Data'!$V$1:$V$379,$B6)} -> -0.31815341 | F6: {=INDEX('Precinct Data'!$W$1:$W$379,$B6)} -> 0.57735921 | G6: {=INDEX('Precinct Data'!$K$1:$K$379,$B6)} -> 1827 | H6: {=INDEX('Precinct Data'!$R$1:$R$379,$B6)} -> 3696 | I6: {=INDEX('Precinct Data'!$M$1:$M$379,$B6)} -> 1520 | J6: {=INDEX('Precinct Data'!$S$1:$S$379,$B6)} -> 2948 | K6: {=INDEX('Baseline Rows'!$I$1:$I$366,MATCH($C6,'Baseline Rows'!$C$1:$C$366,0))} -> 1819 | L6: {=INDEX('Baseline Rows'!$J$1:$J$366,MATCH($C6,'Baseline Rows'!$C$1:$C$366,0))} -> 1896 | M6: =K6/(K6+L6) -> 0.48963661 | N6: {=INDEX('Baseline Rows'!$K$1:$K$366,MATCH($C6,'Baseline Rows'!$C$1:$C$366,0))} -> 1799 | O6: {=INDEX('Baseline Rows'!$L$1:$L$366,MATCH($C6,'Baseline Rows'!$C$1:$C$366,0))} -> 1810 | P6: =N6/(N6+O6) -> 0.49847603
A7: 3 | B7: =MATCH(A7,'Precinct Data'!$AB$1:$AB$379,0) -> 162 | C7: {=INDEX('Precinct Data'!$G$1:$G$379,$B7)} -> SALISBURY 1ST WARD | D7: {=INDEX('Precinct Data'!$B$1:$B$379,$B7)} -> Lehigh | E7: {=INDEX('Precinct Data'!$V$1:$V$379,$B7)} -> 0.57353668 | F7: {=INDEX('Precinct Data'!$W$1:$W$379,$B7)} -> -0.83376697 | G7: {=INDEX('Precinct Data'!$K$1:$K$379,$B7)} -> 700 | H7: {=INDEX('Precinct Data'!$R$1:$R$379,$B7)} -> 1391 | I7: {=INDEX('Precinct Data'!$M$1:$M$379,$B7)} -> 504 | J7: {=INDEX('Precinct Data'!$S$1:$S$379,$B7)} -> 1005 | K7: {=INDEX('Baseline Rows'!$I$1:$I$366,MATCH($C7,'Baseline Rows'!$C$1:$C$366,0))} -> 678 | L7: {=INDEX('Baseline Rows'!$J$1:$J$366,MATCH($C7,'Baseline Rows'!$C$1:$C$366,0))} -> 711 | M7: =K7/(K7+L7) -> 0.48812095 | N7: {=INDEX('Baseline Rows'!$K$1:$K$366,MATCH($C7,'Baseline Rows'!$C$1:$C$366,0))} -> 668 | O7: {=INDEX('Baseline Rows'!$L$1:$L$366,MATCH($C7,'Baseline Rows'!$C$1:$C$366,0))} -> 693 | P7: =N7/(N7+O7) -> 0.49081558
A8: 4 | B8: =MATCH(A8,'Precinct Data'!$AB$1:$AB$379,0) -> 260 | C8: {=INDEX('Precinct Data'!$G$1:$G$379,$B8)} -> BETHLEHEM TWSP 3RD WARD 5TH DISTRICT | D8: {=INDEX('Precinct Data'!$B$1:$B$379,$B8)} -> Northampton | E8: {=INDEX('Precinct Data'!$V$1:$V$379,$B8)} -> -0.20143886 | F8: {=INDEX('Precinct Data'!$W$1:$W$379,$B8)} -> 0.91202303 | G8: {=INDEX('Precinct Data'!$K$1:$K$379,$B8)} -> 439 | H8: {=INDEX('Precinct Data'!$R$1:$R$379,$B8)} -> 886 | I8: {=INDEX('Precinct Data'!$M$1:$M$379,$B8)} -> 356 | J8: {=INDEX('Precinct Data'!$S$1:$S$379,$B8)} -> 686 | K8: {=INDEX('Baseline Rows'!$I$1:$I$366,MATCH($C8,'Baseline Rows'!$C$1:$C$366,0))} -> 415 | L8: {=INDEX('Baseline Rows'!$J$1:$J$366,MATCH($C8,'Baseline Rows'!$C$1:$C$366,0))} -> 452 | M8: =K8/(K8+L8) -> 0.47866205 | N8: {=INDEX('Baseline Rows'!$K$1:$K$366,MATCH($C8,'Baseline Rows'!$C$1:$C$366,0))} -> 436 | O8: {=INDEX('Baseline Rows'!$L$1:$L$366,MATCH($C8,'Baseline Rows'!$C$1:$C$366,0))} -> 423 | P8: =N8/(N8+O8) -> 0.50756694
A9: 5 | B9: =MATCH(A9,'Precinct Data'!$AB$1:$AB$379,0) -> 257 | C9: {=INDEX('Precinct Data'!$G$1:$G$379,$B9)} -> BETHLEHEM TWSP 3RD WARD 2ND DISTRICT | D9: {=INDEX('Precinct Data'!$B$1:$B$379,$B9)} -> Northampton | E9: {=INDEX('Precinct Data'!$V$1:$V$379,$B9)} -> -0.96948378 | F9: {=INDEX('Precinct Data'!$W$1:$W$379,$B9)} -> -0.9830207 | G9: {=INDEX('Precinct Data'!$K$1:$K$379,$B9)} -> 340 | H9: {=INDEX('Precinct Data'!$R$1:$R$379,$B9)} -> 697 | I9: {=INDEX('Precinct Data'!$M$1:$M$379,$B9)} -> 276 | J9: {=INDEX('Precinct Data'!$S$1:$S$379,$B9)} -> 552 | K9: {=INDEX('Baseline Rows'!$I$1:$I$366,MATCH($C9,'Baseline Rows'!$C$1:$C$366,0))} -> 325 | L9: {=INDEX('Baseline Rows'!$J$1:$J$366,MATCH($C9,'Baseline Rows'!$C$1:$C$366,0))} -> 363 | M9: =K9/(K9+L9) -> 0.47238372 | N9: {=INDEX('Baseline Rows'!$K$1:$K$366,MATCH($C9,'Baseline Rows'!$C$1:$C$366,0))} -> 352 | O9: {=INDEX('Baseline Rows'!$L$1:$L$366,MATCH($C9,'Baseline Rows'!$C$1:$C$366,0))} -> 326 | P9: =N9/(N9+O9) -> 0.51917404
A10: 6 | B10: =MATCH(A10,'Precinct Data'!$AB$1:$AB$379,0) -> 182 | C10: {=INDEX('Precinct Data'!$G$1:$G$379,$B10)} -> UPPER MACUNGIE 2ND DISTRICT | D10: {=INDEX('Precinct Data'!$B$1:$B$379,$B10)} -> Lehigh | E10: {=INDEX('Precinct Data'!$V$1:$V$379,$B10)} -> -0.23540848 | F10: {=INDEX('Precinct Data'!$W$1:$W$379,$B10)} -> 1.0724286 | G10: {=INDEX('Precinct Data'!$K$1:$K$379,$B10)} -> 1275 | H10: {=INDEX('Precinct Data'!$R$1:$R$379,$B10)} -> 2575 | I10: {=INDEX('Precinct Data'!$M$1:$M$379,$B10)} -> 1089 | J10: {=INDEX('Precinct Data'!$S$1:$S$379,$B10)} -> 2092 | K10: {=INDEX('Baseline Rows'!$I$1:$I$366,MATCH($C10,'Baseline Rows'!$C$1:$C$366,0))} -> 1276 | L10: {=INDEX('Baseline Rows'!$J$1:$J$366,MATCH($C10,'Baseline Rows'!$C$1:$C$366,0))} -> 1287 | M10: =K10/(K10+L10) -> 0.49785408 | N10: {=INDEX('Baseline Rows'!$K$1:$K$366,MATCH($C10,'Baseline Rows'!$C$1:$C$366,0))} -> 1311 | O10: {=INDEX('Baseline Rows'!$L$1:$L$366,MATCH($C10,'Baseline Rows'!$C$1:$C$366,0))} -> 1258 | P10: =N10/(N10+O10) -> 0.5103153
A11: 7 | B11: =MATCH(A11,'Precinct Data'!$AB$1:$AB$379,0) -> 140 | C11: {=INDEX('Precinct Data'!$G$1:$G$379,$B11)} -> LOWER MACUNGIE 1ST DISTRICT | D11: {=INDEX('Precinct Data'!$B$1:$B$379,$B11)} -> Lehigh | E11: {=INDEX('Precinct Data'!$V$1:$V$379,$B11)} -> -0.2944362 | F11: {=INDEX('Precinct Data'!$W$1:$W$379,$B11)} -> 1.090439 | G11: {=INDEX('Precinct Data'!$K$1:$K$379,$B11)} -> 1090 | H11: {=INDEX('Precinct Data'!$R$1:$R$379,$B11)} -> 2204 | I11: {=INDEX('Precinct Data'!$M$1:$M$379,$B11)} -> 879 | J11: {=INDEX('Precinct Data'!$S$1:$S$379,$B11)} -> 1688 | K11: {=INDEX('Baseline Rows'!$I$1:$I$366,MATCH($C11,'Baseline Rows'!$C$1:$C$366,0))} -> 1115 | L11: {=INDEX('Baseline Rows'!$J$1:$J$366,MATCH($C11,'Baseline Rows'!$C$1:$C$366,0))} -> 1140 | M11: =K11/(K11+L11) -> 0.49445676 | N11: {=INDEX('Baseline Rows'!$K$1:$K$366,MATCH($C11,'Baseline Rows'!$C$1:$C$366,0))} -> 1082 | O11: {=INDEX('Baseline Rows'!$L$1:$L$366,MATCH($C11,'Baseline Rows'!$C$1:$C$366,0))} -> 1101 | P11: =N11/(N11+O11) -> 0.49564819
A12: 8 | B12: =MATCH(A12,'Precinct Data'!$AB$1:$AB$379,0) -> 333 | C12: {=INDEX('Precinct Data'!$G$1:$G$379,$B12)} -> NORTH CATASAUQUA 2ND WARD | D12: {=INDEX('Precinct Data'!$B$1:$B$379,$B12)} -> Northampton | E12: {=INDEX('Precinct Data'!$V$1:$V$379,$B12)} -> -1.1414373 | F12: {=INDEX('Precinct Data'!$W$1:$W$379,$B12)} -> 0.9820448 | G12: {=INDEX('Precinct Data'!$K$1:$K$379,$B12)} -> 524 | H12: {=INDEX('Precinct Data'!$R$1:$R$379,$B12)} -> 1078 | I12: {=INDEX('Precinct Data'!$M$1:$M$379,$B12)} -> 476 | J12: {=INDEX('Precinct Data'!$S$1:$S$379,$B12)} -> 916 | K12: {=INDEX('Baseline Rows'!$I$1:$I$366,MATCH($C12,'Baseline Rows'!$C$1:$C$366,0))} -> 605 | L12: {=INDEX('Baseline Rows'!$J$1:$J$366,MATCH($C12,'Baseline Rows'!$C$1:$C$366,0))} -> 644 | M12: =K12/(K12+L12) -> 0.48438751 | N12: {=INDEX('Baseline Rows'!$K$1:$K$366,MATCH($C12,'Baseline Rows'!$C$1:$C$366,0))} -> 625 | O12: {=INDEX('Baseline Rows'!$L$1:$L$366,MATCH($C12,'Baseline Rows'!$C$1:$C$366,0))} -> 613 | P12: =N12/(N12+O12) -> 0.50484653
A13: 9 | B13: =MATCH(A13,'Precinct Data'!$AB$1:$AB$379,0) -> 144 | C13: {=INDEX('Precinct Data'!$G$1:$G$379,$B13)} -> LOWER MACUNGIE 5TH DISTRICT | D13: {=INDEX('Precinct Data'!$B$1:$B$379,$B13)} -> Lehigh | E13: {=INDEX('Precinct Data'!$V$1:$V$379,$B13)} -> -1.1429335 | F13: {=INDEX('Precinct Data'!$W$1:$W$379,$B13)} -> 1.0899478 | G13: {=INDEX('Precinct Data'!$K$1:$K$379,$B13)} -> 663 | H13: {=INDEX('Precinct Data'!$R$1:$R$379,$B13)} -> 1364 | I13: {=INDEX('Precinct Data'!$M$1:$M$379,$B13)} -> 628 | J13: {=INDEX('Precinct Data'!$S$1:$S$379,$B13)} -> 1206 | K13: {=INDEX('Baseline Rows'!$I$1:$I$366,MATCH($C13,'Baseline Rows'!$C$1:$C$366,0))} -> 668 | L13: {=INDEX('Baseline Rows'!$J$1:$J$366,MATCH($C13,'Baseline Rows'!$C$1:$C$366,0))} -> 721 | M13: =K13/(K13+L13) -> 0.48092153 | N13: {=INDEX('Baseline Rows'!$K$1:$K$366,MATCH($C13,'Baseline Rows'!$C$1:$C$366,0))} -> 715 | O13: {=INDEX('Baseline Rows'!$L$1:$L$366,MATCH($C13,'Baseline Rows'!$C$1:$C$366,0))} -> 677 | P13: =N13/(N13+O13) -> 0.51364943
A14: 10 | B14: =MATCH(A14,'Precinct Data'!$AB$1:$AB$379,0) -> 329 | C14: {=INDEX('Precinct Data'!$G$1:$G$379,$B14)} -> NAZARETH BORO 1ST WARD | D14: {=INDEX('Precinct Data'!$B$1:$B$379,$B14)} -> Northampton | E14: {=INDEX('Precinct Data'!$V$1:$V$379,$B14)} -> -1.1494627 | F14: {=INDEX('Precinct Data'!$W$1:$W$379,$B14)} -> -0.93055481 | G14: {=INDEX('Precinct Data'!$K$1:$K$379,$B14)} -> 573 | H14: {=INDEX('Precinct Data'!$R$1:$R$379,$B14)} -> 1179 | I14: {=INDEX('Precinct Data'!$M$1:$M$379,$B14)} -> 477 | J14: {=INDEX('Precinct Data'!$S$1:$S$379,$B14)} -> 953 | K14: {=INDEX('Baseline Rows'!$I$1:$I$366,MATCH($C14,'Baseline Rows'!$C$1:$C$366,0))} -> 555 | L14: {=INDEX('Baseline Rows'!$J$1:$J$366,MATCH($C14,'Baseline Rows'!$C$1:$C$366,0))} -> 624 | M14: =K14/(K14+L14) -> 0.47073791 | N14: {=INDEX('Baseline Rows'!$K$1:$K$366,MATCH($C14,'Baseline Rows'!$C$1:$C$366,0))} -> 601 | O14: {=INDEX('Baseline Rows'!$L$1:$L$366,MATCH($C14,'Baseline Rows'!$C$1:$C$366,0))} -> 605 | P14: =N14/(N14+O14) -> 0.49834163
C15: Set combined | G15: =SUM(G5:G14) -> 8227 | H15: =SUM(H5:H14) -> 16656 | I15: =SUM(I5:I14) -> 6807 | J15: =SUM(J5:J14) -> 13225 | K15: =SUM(K5:K14) -> 8258 | L15: =SUM(L5:L14) -> 8658 | M15: =K15/(K15+L15) -> 0.48817687 | N15: =SUM(N5:N14) -> 8392 | O15: =SUM(O5:O14) -> 8324 | P15: =N15/(N15+O15) -> 0.50203398
A18: Set gap, 2020 (pts) | C18: =(G15/H15-District!B5)*100 -> -0.35635968
A19: Set gap, 2022 (pts) | C19: =(I15/J15-District!B6)*100 -> 0.48767873
A20: Offset: average of the two gaps (pts) | C20: =AVERAGE(C18:C19) -> 0.065659526
A21: Baseline prediction for the set | C21: =M15 -> 0.48817687
A22: Bellwether reading of the district (set prediction − offset) | C22: =C21-C20/100 -> 0.48752028
A23: Baseline district prediction (all precincts) | C23: =SUMIFS('Baseline Rows'!$I$2:$I$366,'Baseline Rows'!$M$2:$M$366,TRUE())/(SUMIFS('Baseline Rows'!$I$2:$I$366,'Baseline Rows'!$M$2:$M$366,TRUE())+SUMIFS('Baseline Rows'!$J$2:$J$366,'Baseline Rows'!$M$2:$M$366,TRUE())) -> 0.49084073
A24: Weight on baseline (from Summary) | C24: =Summary!$C$5 -> 0.5
A25: Baseline + bellwether | C25: =C24*C23+(1-C24)*C22 -> 0.48918051
A26: Actual district result (comparable precincts) | C26: =SUMIFS('Baseline Rows'!$K$2:$K$366,'Baseline Rows'!$M$2:$M$366,TRUE())/(SUMIFS('Baseline Rows'!$K$2:$K$366,'Baseline Rows'!$M$2:$M$366,TRUE())+SUMIFS('Baseline Rows'!$L$2:$L$366,'Baseline Rows'!$M$2:$M$366,TRUE())) -> 0.49262491
A27: Miss: baseline (pts) | C27: =(C23-C26)*100 -> -0.17841735
A28: Miss: bellwether reading (pts) | C28: =(C22-C26)*100 -> -0.51046282
A29: Miss: baseline + bellwether (pts) | C29: =(C25-C26)*100 -> -0.34444009
A30: Set actual vs. district actual (pts): did the bellwethers stay bellwethers? | C30: =(P15-C26)*100 -> 0.94090725
A31: Baseline miss on the set itself (pts) | C31: =(M15-P15)*100 -> -1.3857105

Sheet Forecast 2026
A1: 2026 forecast: 10 bellwethers chosen from 2022 and 2024 results
A2: Bellwether reading = baseline’s predicted share for these 10 precincts − the set’s usual lean (offset).
A4: Rank | B4: Data row | C4: Precinct | D4: County | E4: Gap 2022 | F4: Gap 2024 | G4: D votes 2022 | H4: Two-party votes 2022 | I4: D votes 2024 | J4: Two-party votes 2024 | K4: Baseline Brooks | L4: Baseline Mackenzie | M4: Baseline pred D share
A5: 1 | B5: =MATCH(A5,'Precinct Data'!$AD$1:$AD$379,0) -> 163 | C5: {=INDEX('Precinct Data'!$H$1:$H$379,$B5)} -> SALISBURY 2ND WARD | D5: {=INDEX('Precinct Data'!$B$1:$B$379,$B5)} -> Lehigh | E5: {=INDEX('Precinct Data'!$W$1:$W$379,$B5)} -> 0.077199821 | F5: {=INDEX('Precinct Data'!$X$1:$X$379,$B5)} -> 0.040900498 | G5: {=INDEX('Precinct Data'!$M$1:$M$379,$B5)} -> 602 | H5: {=INDEX('Precinct Data'!$S$1:$S$379,$B5)} -> 1179 | I5: {=INDEX('Precinct Data'!$O$1:$O$379,$B5)} -> 803 | J5: {=INDEX('Precinct Data'!$T$1:$T$379,$B5)} -> 1621 | K5: {=INDEX('Baseline Rows'!$N$1:$N$366,MATCH($C5,'Baseline Rows'!$C$1:$C$366,0))} -> 618 | L5: {=INDEX('Baseline Rows'!$O$1:$O$366,MATCH($C5,'Baseline Rows'!$C$1:$C$366,0))} -> 613 | M5: =K5/(K5+L5) -> 0.50203087
A6: 2 | B6: =MATCH(A6,'Precinct Data'!$AD$1:$AD$379,0) -> 169 | C6: {=INDEX('Precinct Data'!$H$1:$H$379,$B6)} -> SALISBURY 5TH WARD 2ND DIST | D6: {=INDEX('Precinct Data'!$B$1:$B$379,$B6)} -> Lehigh | E6: {=INDEX('Precinct Data'!$W$1:$W$379,$B6)} -> 0.36541511 | F6: {=INDEX('Precinct Data'!$X$1:$X$379,$B6)} -> 0.4099449 | G6: {=INDEX('Precinct Data'!$M$1:$M$379,$B6)} -> 476 | H6: {=INDEX('Precinct Data'!$S$1:$S$379,$B6)} -> 927 | I6: {=INDEX('Precinct Data'!$O$1:$O$379,$B6)} -> 533 | J6: {=INDEX('Precinct Data'!$T$1:$T$379,$B6)} -> 1068 | K6: {=INDEX('Baseline Rows'!$N$1:$N$366,MATCH($C6,'Baseline Rows'!$C$1:$C$366,0))} -> 461 | L6: {=INDEX('Baseline Rows'!$O$1:$O$366,MATCH($C6,'Baseline Rows'!$C$1:$C$366,0))} -> 439 | M6: =K6/(K6+L6) -> 0.51222222
A7: 3 | B7: =MATCH(A7,'Precinct Data'!$AD$1:$AD$379,0) -> 141 | C7: {=INDEX('Precinct Data'!$H$1:$H$379,$B7)} -> LOWER MACUNGIE 2ND DISTRICT | D7: {=INDEX('Precinct Data'!$B$1:$B$379,$B7)} -> Lehigh | E7: {=INDEX('Precinct Data'!$W$1:$W$379,$B7)} -> 0.57735921 | F7: {=INDEX('Precinct Data'!$X$1:$X$379,$B7)} -> 0.35118107 | G7: {=INDEX('Precinct Data'!$M$1:$M$379,$B7)} -> 1520 | H7: {=INDEX('Precinct Data'!$S$1:$S$379,$B7)} -> 2948 | I7: {=INDEX('Precinct Data'!$O$1:$O$379,$B7)} -> 1799 | J7: {=INDEX('Precinct Data'!$T$1:$T$379,$B7)} -> 3609 | K7: {=INDEX('Baseline Rows'!$N$1:$N$366,MATCH($C7,'Baseline Rows'!$C$1:$C$366,0))} -> 1504 | L7: {=INDEX('Baseline Rows'!$O$1:$O$366,MATCH($C7,'Baseline Rows'!$C$1:$C$366,0))} -> 1461 | M7: =K7/(K7+L7) -> 0.50725126
A8: 4 | B8: =MATCH(A8,'Precinct Data'!$AD$1:$AD$379,0) -> 162 | C8: {=INDEX('Precinct Data'!$H$1:$H$379,$B8)} -> SALISBURY 1ST WARD | D8: {=INDEX('Precinct Data'!$B$1:$B$379,$B8)} -> Lehigh | E8: {=INDEX('Precinct Data'!$W$1:$W$379,$B8)} -> -0.83376697 | F8: {=INDEX('Precinct Data'!$X$1:$X$379,$B8)} -> -0.41486446 | G8: {=INDEX('Precinct Data'!$M$1:$M$379,$B8)} -> 504 | H8: {=INDEX('Precinct Data'!$S$1:$S$379,$B8)} -> 1005 | I8: {=INDEX('Precinct Data'!$O$1:$O$379,$B8)} -> 668 | J8: {=INDEX('Precinct Data'!$T$1:$T$379,$B8)} -> 1361 | K8: {=INDEX('Baseline Rows'!$N$1:$N$366,MATCH($C8,'Baseline Rows'!$C$1:$C$366,0))} -> 508 | L8: {=INDEX('Baseline Rows'!$O$1:$O$366,MATCH($C8,'Baseline Rows'!$C$1:$C$366,0))} -> 511 | M8: =K8/(K8+L8) -> 0.49852797
A9: 5 | B9: =MATCH(A9,'Precinct Data'!$AD$1:$AD$379,0) -> 191 | C9: {=INDEX('Precinct Data'!$H$1:$H$379,$B9)} -> UPPER SAUCON 1ST DISTRICT | D9: {=INDEX('Precinct Data'!$B$1:$B$379,$B9)} -> Lehigh | E9: {=INDEX('Precinct Data'!$W$1:$W$379,$B9)} -> -0.15302643 | F9: {=INDEX('Precinct Data'!$X$1:$X$379,$B9)} -> -0.85940636 | G9: {=INDEX('Precinct Data'!$M$1:$M$379,$B9)} -> 888 | H9: {=INDEX('Precinct Data'!$S$1:$S$379,$B9)} -> 1747 | I9: {=INDEX('Precinct Data'!$O$1:$O$379,$B9)} -> 1017 | J9: {=INDEX('Precinct Data'!$T$1:$T$379,$B9)} -> 2091 | K9: {=INDEX('Baseline Rows'!$N$1:$N$366,MATCH($C9,'Baseline Rows'!$C$1:$C$366,0))} -> 864 | L9: {=INDEX('Baseline Rows'!$O$1:$O$366,MATCH($C9,'Baseline Rows'!$C$1:$C$366,0))} -> 905 | M9: =K9/(K9+L9) -> 0.48841153
A10: 6 | B10: =MATCH(A10,'Precinct Data'!$AD$1:$AD$379,0) -> 329 | C10: {=INDEX('Precinct Data'!$H$1:$H$379,$B10)} -> NAZARETH BORO 1ST WARD | D10: {=INDEX('Precinct Data'!$B$1:$B$379,$B10)} -> Northampton | E10: {=INDEX('Precinct Data'!$W$1:$W$379,$B10)} -> -0.93055481 | F10: {=INDEX('Precinct Data'!$X$1:$X$379,$B10)} -> 0.33774038 | G10: {=INDEX('Precinct Data'!$M$1:$M$379,$B10)} -> 477 | H10: {=INDEX('Precinct Data'!$S$1:$S$379,$B10)} -> 953 | I10: {=INDEX('Precinct Data'!$O$1:$O$379,$B10)} -> 601 | J10: {=INDEX('Precinct Data'!$T$1:$T$379,$B10)} -> 1206 | K10: {=INDEX('Baseline Rows'!$N$1:$N$366,MATCH($C10,'Baseline Rows'!$C$1:$C$366,0))} -> 490 | L10: {=INDEX('Baseline Rows'!$O$1:$O$366,MATCH($C10,'Baseline Rows'!$C$1:$C$366,0))} -> 488 | M10: =K10/(K10+L10) -> 0.50102249
A11: 7 | B11: =MATCH(A11,'Precinct Data'!$AD$1:$AD$379,0) -> 333 | C11: {=INDEX('Precinct Data'!$H$1:$H$379,$B11)} -> NORTH CATASAUQUA 2ND WARD | D11: {=INDEX('Precinct Data'!$B$1:$B$379,$B11)} -> Northampton | E11: {=INDEX('Precinct Data'!$W$1:$W$379,$B11)} -> 0.9820448 | F11: {=INDEX('Precinct Data'!$X$1:$X$379,$B11)} -> 0.98823052 | G11: {=INDEX('Precinct Data'!$M$1:$M$379,$B11)} -> 476 | H11: {=INDEX('Precinct Data'!$S$1:$S$379,$B11)} -> 916 | I11: {=INDEX('Precinct Data'!$O$1:$O$379,$B11)} -> 625 | J11: {=INDEX('Precinct Data'!$T$1:$T$379,$B11)} -> 1238 | K11: {=INDEX('Baseline Rows'!$N$1:$N$366,MATCH($C11,'Baseline Rows'!$C$1:$C$366,0))} -> 530 | L11: {=INDEX('Baseline Rows'!$O$1:$O$366,MATCH($C11,'Baseline Rows'!$C$1:$C$366,0))} -> 519 | M11: =K11/(K11+L11) -> 0.50524309
A12: 8 | B12: =MATCH(A12,'Precinct Data'!$AD$1:$AD$379,0) -> 149 | C12: {=INDEX('Precinct Data'!$H$1:$H$379,$B12)} -> LOWER MACUNGIE 10TH DISTRICT | D12: {=INDEX('Precinct Data'!$B$1:$B$379,$B12)} -> Lehigh | E12: {=INDEX('Precinct Data'!$W$1:$W$379,$B12)} -> -0.28719565 | F12: {=INDEX('Precinct Data'!$X$1:$X$379,$B12)} -> -1.0621841 | G12: {=INDEX('Precinct Data'!$M$1:$M$379,$B12)} -> 765 | H12: {=INDEX('Precinct Data'!$S$1:$S$379,$B12)} -> 1509 | I12: {=INDEX('Precinct Data'!$O$1:$O$379,$B12)} -> 928 | J12: {=INDEX('Precinct Data'!$T$1:$T$379,$B12)} -> 1916 | K12: {=INDEX('Baseline Rows'!$N$1:$N$366,MATCH($C12,'Baseline Rows'!$C$1:$C$366,0))} -> 757 | L12: {=INDEX('Baseline Rows'!$O$1:$O$366,MATCH($C12,'Baseline Rows'!$C$1:$C$366,0))} -> 783 | M12: =K12/(K12+L12) -> 0.49155844
A13: 9 | B13: =MATCH(A13,'Precinct Data'!$AD$1:$AD$379,0) -> 140 | C13: {=INDEX('Precinct Data'!$H$1:$H$379,$B13)} -> LOWER MACUNGIE 1ST DISTRICT | D13: {=INDEX('Precinct Data'!$B$1:$B$379,$B13)} -> Lehigh | E13: {=INDEX('Precinct Data'!$W$1:$W$379,$B13)} -> 1.090439 | F13: {=INDEX('Precinct Data'!$X$1:$X$379,$B13)} -> 0.068396914 | G13: {=INDEX('Precinct Data'!$M$1:$M$379,$B13)} -> 879 | H13: {=INDEX('Precinct Data'!$S$1:$S$379,$B13)} -> 1688 | I13: {=INDEX('Precinct Data'!$O$1:$O$379,$B13)} -> 1082 | J13: {=INDEX('Precinct Data'!$T$1:$T$379,$B13)} -> 2183 | K13: {=INDEX('Baseline Rows'!$N$1:$N$366,MATCH($C13,'Baseline Rows'!$C$1:$C$366,0))} -> 860 | L13: {=INDEX('Baseline Rows'!$O$1:$O$366,MATCH($C13,'Baseline Rows'!$C$1:$C$366,0))} -> 835 | M13: =K13/(K13+L13) -> 0.50737463
A14: 10 | B14: =MATCH(A14,'Precinct Data'!$AD$1:$AD$379,0) -> 335 | C14: {=INDEX('Precinct Data'!$H$1:$H$379,$B14)} -> NORTHAMPTON BORO 2ND WARD | D14: {=INDEX('Precinct Data'!$B$1:$B$379,$B14)} -> Northampton | E14: {=INDEX('Precinct Data'!$W$1:$W$379,$B14)} -> -0.26359624 | F14: {=INDEX('Precinct Data'!$X$1:$X$379,$B14)} -> -1.141159 | G14: {=INDEX('Precinct Data'!$M$1:$M$379,$B14)} -> 423 | H14: {=INDEX('Precinct Data'!$S$1:$S$379,$B14)} -> 834 | I14: {=INDEX('Precinct Data'!$O$1:$O$379,$B14)} -> 588 | J14: {=INDEX('Precinct Data'!$T$1:$T$379,$B14)} -> 1216 | K14: {=INDEX('Baseline Rows'!$N$1:$N$366,MATCH($C14,'Baseline Rows'!$C$1:$C$366,0))} -> 419 | L14: {=INDEX('Baseline Rows'!$O$1:$O$366,MATCH($C14,'Baseline Rows'!$C$1:$C$366,0))} -> 449 | M14: =K14/(K14+L14) -> 0.48271889
C15: Set combined | G15: =SUM(G5:G14) -> 7010 | H15: =SUM(H5:H14) -> 13706 | I15: =SUM(I5:I14) -> 8644 | J15: =SUM(J5:J14) -> 17509 | K15: =SUM(K5:K14) -> 7011 | L15: =SUM(L5:L14) -> 7003 | M15: =K15/(K15+L15) -> 0.50028543
A18: Set gap, 2022 (pts) | C18: =(G15/H15-District!B6)*100 -> 0.16246303
A19: Set gap, 2024 (pts) | C19: =(I15/J15-District!B7)*100 -> -0.12752615
A20: Offset: average of the two gaps (pts) | C20: =AVERAGE(C18:C19) -> 0.017468439
A21: Baseline prediction for the set | C21: =M15 -> 0.50028543
A22: Bellwether reading of the district (set prediction − offset) | C22: =C21-C20/100 -> 0.50011074
A23: Baseline district prediction (all precincts) | C23: =SUM('Baseline Rows'!$N$2:$N$366)/(SUM('Baseline Rows'!$N$2:$N$366)+SUM('Baseline Rows'!$O$2:$O$366)) -> 0.49494302
A24: Weight on baseline (from Summary) | C24: =Summary!$C$5 -> 0.5
A25: Baseline + bellwether | C25: =C24*C23+(1-C24)*C22 -> 0.49752688

Sheet Precinct Data
A1: Precinct key | B1: County | C1: Municipality | D1: DOS code | E1: Exists on 2026 lines | F1: Name in 2022 backtest | G1: Name in 2024 backtest | H1: Name in 2026 forecast | I1: House D 2018 | J1: House R 2018 | K1: House D 2020 | L1: House R 2020 | M1: House D 2022 | N1: House R 2022 | O1: House D 2024 | P1: House R 2024 | Q1: Votes 2018 | R1: Votes 2020 | S1: Votes 2022 | T1: Votes 2024 | U1: Gap 2018 | V1: Gap 2020 | W1: Gap 2022 | X1: Gap 2024 | Y1: Score for 2022 (2018+2020) | Z1: Rank for 2022 | AA1: Score for 2024 (2020+2022) | AB1: Rank for 2024 | AC1: Score for 2026 (2022+2024) | AD1: Rank for 2026
A2: Carbon | BANKS | 10 | B2: Carbon | C2: BANKS | D2: 10 | E2: Yes | F2: BANKS TOWNSHIP | H2: BANKS TOWNSHIP | I2: 160 | J2: 221 | K2: 171 | L2: 332 | M2: 137 | N2: 249 | O2: 181 | P2: 285 | Q2: =IF(COUNT(I2:J2)=2,I2+J2,0) -> 381 | R2: =IF(COUNT(K2:L2)=2,K2+L2,0) -> 503 | S2: =IF(COUNT(M2:N2)=2,M2+N2,0) -> 386 | T2: =IF(COUNT(O2:P2)=2,O2+P2,0) -> 466 | U2: =IF(Q2>0,(I2/Q2-District!$B$4)*100,"") -> -11.417483 | V2: =IF(R2>0,(K2/R2-District!$B$5)*100,"") -> -15.753948 | W2: =IF(S2>0,(M2/S2-District!$B$6)*100,"") -> -15.490793 | X2: =IF(T2>0,(O2/T2-District!$B$7)*100,"") -> -10.65522 | Y2: =IF(AND(E2="Yes",Q2>=300,R2>=300,F2<>""),MAX(ABS(U2),ABS(V2))-R2/1000000000,"") -> 15.753947 | Z2: =IF(ISNUMBER(Y2),SUMPRODUCT(ISNUMBER($Y$2:$Y$379)*($Y$2:$Y$379<Y2))+1,"") -> 190 | AA2: =IF(AND(E2="Yes",R2>=300,S2>=300,G2<>""),MAX(ABS(V2),ABS(W2))-S2/1000000000,"") | AB2: =IF(ISNUMBER(AA2),SUMPRODUCT(ISNUMBER($AA$2:$AA$379)*($AA$2:$AA$379<AA2))+1,"") | AC2: =IF(AND(E2="Yes",S2>=300,T2>=300,H2<>""),MAX(ABS(W2),ABS(X2))-T2/1000000000,"") -> 15.490792 | AD2: =IF(ISNUMBER(AC2),SUMPRODUCT(ISNUMBER($AC$2:$AC$379)*($AC$2:$AC$379<AC2))+1,"") -> 195
A3: Carbon | BEAVER MEADOWS | 40 | B3: Carbon | C3: BEAVER MEADOWS | D3: 40 | E3: Yes | F3: BEAVER MEADOWS BOROUGH | H3: BEAVER MEADOWS BOROUGH | I3: 95 | J3: 192 | K3: 100 | L3: 303 | M3: 84 | N3: 230 | O3: 118 | P3: 300 | Q3: =IF(COUNT(I3:J3)=2,I3+J3,0) -> 287 | R3: =IF(COUNT(K3:L3)=2,K3+L3,0) -> 403 | S3: =IF(COUNT(M3:N3)=2,M3+N3,0) -> 314 | T3: =IF(COUNT(O3:P3)=2,O3+P3,0) -> 418 | U3: =IF(Q3>0,(I3/Q3-District!$B$4)*100,"") -> -20.311188 | V3: =IF(R3>0,(K3/R3-District!$B$5)*100,"") -> -24.936076 | W3: =IF(S3>0,(M3/S3-District!$B$6)*100,"") -> -24.231428 | X3: =IF(T3>0,(O3/T3-District!$B$7)*100,"") -> -21.266757 | Y3: =IF(AND(E3="Yes",Q3>=300,R3>=300,F3<>""),MAX(ABS(U3),ABS(V3))-R3/1000000000,"") | Z3: =IF(ISNUMBER(Y3),SUMPRODUCT(ISNUMBER($Y$2:$Y$379)*($Y$2:$Y$379<Y3))+1,"") | AA3: =IF(AND(E3="Yes",R3>=300,S3>=300,G3<>""),MAX(ABS(V3),ABS(W3))-S3/1000000000,"") | AB3: =IF(ISNUMBER(AA3),SUMPRODUCT(ISNUMBER($AA$2:$AA$379)*($AA$2:$AA$379<AA3))+1,"") | AC3: =IF(AND(E3="Yes",S3>=300,T3>=300,H3<>""),MAX(ABS(W3),ABS(X3))-T3/1000000000,"") -> 24.231428 | AD3: =IF(ISNUMBER(AC3),SUMPRODUCT(ISNUMBER($AC$2:$AC$379)*($AC$2:$AC$379<AC3))+1,"") -> 270
A4: Carbon | BOWMANSTOWN | 50 | B4: Carbon | C4: BOWMANSTOWN | D4: 50 | E4: Yes | F4: BOWMANSTOWN BOROUGH | H4: BOWMANSTOWN BOROUGH | I4: 110 | J4: 175 | K4: 111 | L4: 317 | M4: 125 | N4: 223 | O4: 144 | P4: 310 | Q4: =IF(COUNT(I4:J4)=2,I4+J4,0) -> 285 | R4: =IF(COUNT(K4:L4)=2,K4+L4,0) -> 428 | S4: =IF(COUNT(M4:N4)=2,M4+N4,0) -> 348 | T4: =IF(COUNT(O4:P4)=2,O4+P4,0) -> 454 | U4: =IF(Q4>0,(I4/Q4-District!$B$4)*100,"") -> -14.815742 | V4: =IF(R4>0,(K4/R4-District!$B$5)*100,"") -> -23.815392 | W4: =IF(S4>0,(M4/S4-District!$B$6)*100,"") -> -15.06348 | X4: =IF(T4>0,(O4/T4-District!$B$7)*100,"") -> -17.77836 | Y4: =IF(AND(E4="Yes",Q4>=300,R4>=300,F4<>""),MAX(ABS(U4),ABS(V4))-R4/1000000000,"") | Z4: =IF(ISNUMBER(Y4),SUMPRODUCT(ISNUMBER($Y$2:$Y$379)*($Y$2:$Y$379<Y4))+1,"") | AA4: =IF(AND(E4="Yes",R4>=300,S4>=300,G4<>""),MAX(ABS(V4),ABS(W4))-S4/1000000000,"") | AB4: =IF(ISNUMBER(AA4),SUMPRODUCT(ISNUMBER($AA$2:$AA$379)*($AA$2:$AA$379<AA4))+1,"") | AC4: =IF(AND(E4="Yes",S4>=300,T4>=300,H4<>""),MAX(ABS(W4),ABS(X4))-T4/1000000000,"") -> 17.77836 | AD4: =IF(ISNUMBER(AC4),SUMPRODUCT(ISNUMBER($AC$2:$AC$379)*($AC$2:$AC$379<AC4))+1,"") -> 220
A5: Carbon | EAST PENN | 60 | B5: Carbon | C5: EAST PENN | D5: 60 | E5: Yes | F5: EAST PENN TOWNSHIP-NORTH | H5: EAST PENN TOWNSHIP-NORTH | I5: 201 | J5: 409 | K5: 196 | L5: 587 | M5: 195 | N5: 503 | O5: 204 | P5: 643 | Q5: =IF(COUNT(I5:J5)=2,I5+J5,0) -> 610 | R5: =IF(COUNT(K5:L5)=2,K5+L5,0) -> 783 | S5: =IF(COUNT(M5:N5)=2,M5+N5,0) -> 698 | T5: =IF(COUNT(O5:P5)=2,O5+P5,0) -> 847 | U5: =IF(Q5>0,(I5/Q5-District!$B$4)*100,"") -> -20.461414 | V5: =IF(R5>0,(K5/R5-District!$B$5)*100,"") -> -24.718043 | W5: =IF(S5>0,(M5/S5-District!$B$6)*100,"") -> -23.046058 | X5: =IF(T5>0,(O5/T5-District!$B$7)*100,"") -> -25.411416 | Y5: =IF(AND(E5="Yes",Q5>=300,R5>=300,F5<>""),MAX(ABS(U5),ABS(V5))-R5/1000000000,"") -> 24.718042 | Z5: =IF(ISNUMBER(Y5),SUMPRODUCT(ISNUMBER($Y$2:$Y$379)*($Y$2:$Y$379<Y5))+1,"") -> 262 | AA5: =IF(AND(E5="Yes",R5>=300,S5>=300,G5<>""),MAX(ABS(V5),ABS(W5))-S5/1000000000,"") | AB5: =IF(ISNUMBER(AA5),SUMPRODUCT(ISNUMBER($AA$2:$AA$379)*($AA$2:$AA$379<AA5))+1,"") | AC5: =IF(AND(E5="Yes",S5>=300,T5>=300,H5<>""),MAX(ABS(W5),ABS(X5))-T5/1000000000,"") -> 25.411415 | AD5: =IF(ISNUMBER(AC5),SUMPRODUCT(ISNUMBER($AC$2:$AC$379)*($AC$2:$AC$379<AC5))+1,"") -> 276
A6: Carbon | EAST PENN | 65 | B6: Carbon | C6: EAST PENN | D6: 65 | E6: Yes | F6: EAST PENN TOWNSHIP-SOUTH | H6: EAST PENN TOWNSHIP-SOUTH | I6: 168 | J6: 333 | K6: 194 | L6: 593 | M6: 177 | N6: 422 | O6: 234 | P6: 610 | Q6: =IF(COUNT(I6:J6)=2,I6+J6,0) -> 501 | R6: =IF(COUNT(K6:L6)=2,K6+L6,0) -> 787 | S6: =IF(COUNT(M6:N6)=2,M6+N6,0) -> 599 | T6: =IF(COUNT(O6:P6)=2,O6+P6,0) -> 844 | U6: =IF(Q6>0,(I6/Q6-District!$B$4)*100,"") -> -19.879299 | V6: =IF(R6>0,(K6/R6-District!$B$5)*100,"") -> -25.0994 | W6: =IF(S6>0,(M6/S6-District!$B$6)*100,"") -> -21.433772 | X6: =IF(T6>0,(O6/T6-District!$B$7)*100,"") -> -21.771304 | Y6: =IF(AND(E6="Yes",Q6>=300,R6>=300,F6<>""),MAX(ABS(U6),ABS(V6))-R6/1000000000,"") -> 25.099399 | Z6: =IF(ISNUMBER(Y6),SUMPRODUCT(ISNUMBER($Y$2:$Y$379)*($Y$2:$Y$379<Y6))+1,"") -> 264 | AA6: =IF(AND(E6="Yes",R6>=300,S6>=300,G6<>""),MAX(ABS(V6),ABS(W6))-S6/1000000000,"") | AB6: =IF(ISNUMBER(AA6),SUMPRODUCT(ISNUMBER($AA$2:$AA$379)*($AA$2:$AA$379<AA6))+1,"") | AC6: =IF(AND(E6="Yes",S6>=300,T6>=300,H6<>""),MAX(ABS(W6),ABS(X6))-T6/1000000000,"") -> 21.771303 | AD6: =IF(ISNUMBER(AC6),SUMPRODUCT(ISNUMBER($AC$2:$AC$379)*($AC$2:$AC$379<AC6))+1,"") -> 254
A7: Carbon | EAST SIDE | 70 | B7: Carbon | C7: EAST SIDE | D7: 70 | E7: Yes | F7: EAST SIDE BOROUGH | G7: EAST SIDE BOROUGH | H7: EAST SIDE BOROUGH | I7: 34 | J7: 43 | K7: 47 | L7: 74 | M7: 33 | N7: 61 | O7: 38 | P7: 78 | Q7: =IF(COUNT(I7:J7)=2,I7+J7,0) -> 77 | R7: =IF(COUNT(K7:L7)=2,K7+L7,0) -> 121 | S7: =IF(COUNT(M7:N7)=2,M7+N7,0) -> 94 | T7: =IF(COUNT(O7:P7)=2,O7+P7,0) -> 116 | U7: =IF(Q7>0,(I7/Q7-District!$B$4)*100,"") -> -9.2563895 | V7: =IF(R7>0,(K7/R7-District!$B$5)*100,"") -> -10.906996 | W7: =IF(S7>0,(M7/S7-District!$B$6)*100,"") -> -15.876638 | X7: =IF(T7>0,(O7/T7-District!$B$7)*100,"") -> -16.737801 | Y7: =IF(AND(E7="Yes",Q7>=300,R7>=300,F7<>""),MAX(ABS(U7),ABS(V7))-R7/1000000000,"") | Z7: =IF(ISNUMBER(Y7),SUMPRODUCT(ISNUMBER($Y$2:$Y$379)*($Y$2:$Y$379<Y7))+1,"") | AA7: =IF(AND(E7="Yes",R7>=300,S7>=300,G7<>""),MAX(ABS(V7),ABS(W7))-S7/1000000000,"") | AB7: =IF(ISNUMBER(AA7),SUMPRODUCT(ISNUMBER($AA$2:$AA$379)*($AA$2:$AA$379<AA7))+1,"") | AC7: =IF(AND(E7="Yes",S7>=300,T7>=300,H7<>""),MAX(ABS(W7),ABS(X7))-T7/1000000000,"") | AD7: =IF(ISNUMBER(AC7),SUMPRODUCT(ISNUMBER($AC$2:$AC$379)*($AC$2:$AC$379<AC7))+1,"")
A8: Carbon | FRANKLIN | 80 | B8: Carbon | C8: FRANKLIN | D8: 80 | E8: Yes | F8: FRANKLIN TOWNSHIP-IND DIST | H8: FRANKLIN TOWNSHIP-IND DIST | I8: 132 | J8: 254 | K8: 163 | L8: 443 | M8: 133 | N8: 321 | O8: 164 | P8: 451 | Q8: =IF(COUNT(I8:J8)=2,I8+J8,0) -> 386 | R8: =IF(COUNT(K8:L8)=2,K8+L8,0) -> 606 | S8: =IF(COUNT(M8:N8)=2,M8+N8,0) -> 454 | T8: =IF(COUNT(O8:P8)=2,O8+P8,0) -> 615 | U8: =IF(Q8>0,(I8/Q8-District!$B$4)*100,"") -> -19.215342 | V8: =IF(R8>0,(K8/R8-District!$B$5)*100,"") -> -22.852282 | W8: =IF(S8>0,(M8/S8-District!$B$6)*100,"") -> -21.687867 | X8: =IF(T8>0,(O8/T8-District!$B$7)*100,"") -> -22.829755 | Y8: =IF(AND(E8="Yes",Q8>=300,R8>=300,F8<>""),MAX(ABS(U8),ABS(V8))-R8/1000000000,"") -> 22.852281 | Z8: =IF(ISNUMBER(Y8),SUMPRODUCT(ISNUMBER($Y$2:$Y$379)*($Y$2:$Y$379<Y8))+1,"") -> 250 | AA8: =IF(AND(E8="Yes",R8>=300,S8>=300,G8<>""),MAX(ABS(V8),ABS(W8))-S8/1000000000,"") | AB8: =IF(ISNUMBER(AA8),SUMPRODUCT(ISNUMBER($AA$2:$AA$379)*($AA$2:$AA$379<AA8))+1,"") | AC8: =IF(AND(E8="Yes",S8>=300,T8>=300,H8<>""),MAX(ABS(W8),ABS(X8))-T8/1000000000,"") -> 22.829755 | AD8: =IF(ISNUMBER(AC8),SUMPRODUCT(ISNUMBER($AC$2:$AC$379)*($AC$2:$AC$379<AC8))+1,"") -> 261
A9: Carbon | FRANKLIN | 90 | B9: Carbon | C9: FRANKLIN | D9: 90 | E9: Yes | F9: FRANKLIN TOWNSHIP-HARRITY | H9: FRANKLIN TOWNSHIP-HARRITY | I9: 245 | J9: 473 | K9: 268 | L9: 753 | M9: 250 | N9: 589 | O9: 309 | P9: 765 | Q9: =IF(COUNT(I9:J9)=2,I9+J9,0) -> 718 | R9: =IF(COUNT(K9:L9)=2,K9+L9,0) -> 1021 | S9: =IF(COUNT(M9:N9)=2,M9+N9,0) -> 839 | T9: =IF(COUNT(O9:P9)=2,O9+P9,0) -> 1074 | U9: =IF(Q9>0,(I9/Q9-District!$B$4)*100,"") -> -19.289671 | V9: =IF(R9>0,(K9/R9-District!$B$5)*100,"") -> -23.501196 | W9: =IF(S9>0,(M9/S9-District!$B$6)*100,"") -> -21.185643 | X9: =IF(T9>0,(O9/T9-District!$B$7)*100,"") -> -20.725472 | Y9: =IF(AND(E9="Yes",Q9>=300,R9>=300,F9<>""),MAX(ABS(U9),ABS(V9))-R9/1000000000,"") -> 23.501195 | Z9: =IF(ISNUMBER(Y9),SUMPRODUCT(ISNUMBER($Y$2:$Y$379)*($Y$2:$Y$379<Y9))+1,"") -> 257 | AA9: =IF(AND(E9="Yes",R9>=300,S9>=300,G9<>""),MAX(ABS(V9),ABS(W9))-S9/1000000000,"") | AB9: =IF(ISNUMBER(AA9),SUMPRODUCT(ISNUMBER($AA$2:$AA$379)*($AA$2:$AA$379<AA9))+1,"") | AC9: =IF(AND(E9="Yes",S9>=300,T9>=300,H9<>""),MAX(ABS(W9),ABS(X9))-T9/1000000000,"") -> 21.185642 | AD9: =IF(ISNUMBER(AC9),SUMPRODUCT(ISNUMBER($AC$2:$AC$379)*($AC$2:$AC$379<AC9))+1,"") -> 251
A10: Carbon | FRANKLIN | 100 | B10: Carbon | C10: FRANKLIN | D10: 100 | E10: Yes | F10: FRANKLIN TOWNSHIP-LONG RUN | H10: FRANKLIN TOWNSHIP-LONG RUN | I10: 159 | J10: 395 | K10: 200 | L10: 632 | M10: 177 | N10: 488 | O10: 235 | P10: 630 | Q10: =IF(COUNT(I10:J10)=2,I10+J10,0) -> 554 | R10: =IF(COUNT(K10:L10)=2,K10+L10,0) -> 832 | S10: =IF(COUNT(M10:N10)=2,M10+N10,0) -> 665 | T10: =IF(COUNT(O10:P10)=2,O10+P10,0) -> 865 | U10: =IF(Q10>0,(I10/Q10-District!$B$4)*100,"") -> -24.711873 | V10: =IF(R10>0,(K10/R10-District!$B$5)*100,"") -> -25.71151 | W10: =IF(S10>0,(M10/S10-District!$B$6)*100,"") -> -24.366479 | X10: =IF(T10>0,(O10/T10-District!$B$7)*100,"") -> -22.328792 | Y10: =IF(AND(E10="Yes",Q10>=300,R10>=300,F10<>""),MAX(ABS(U10),ABS(V10))-R10/1000000000,"") -> 25.711509 | Z10: =IF(ISNUMBER(Y10),SUMPRODUCT(ISNUMBER($Y$2:$Y$379)*($Y$2:$Y$379<Y10))+1,"") -> 267 | AA10: =IF(AND(E10="Yes",R10>=300,S10>=300,G10<>""),MAX(ABS(V10),ABS(W10))-S10/1000000000,"") | AB10: =IF(ISNUMBER(AA10),SUMPRODUCT(ISNUMBER($AA$2:$AA$379)*($AA$2:$AA$379<AA10))+1,"") | AC10: =IF(AND(E10="Yes",S10>=300,T10>=300,H10<>""),MAX(ABS(W10),ABS(X10))-T10/1000000000,"") -> 24.366478 | AD10: =IF(ISNUMBER(AC10),SUMPRODUCT(ISNUMBER($AC$2:$AC$379)*($AC$2:$AC$379<AC10))+1,"") -> 271
A11: Carbon | JIM THORPE | 110 | B11: Carbon | C11: JIM THORPE | D11: 110 | E11: Yes | F11: JIM THORPE BOROUGH-1ST | H11: JIM THORPE BOROUGH-1ST | I11: 218 | J11: 182 | K11: 231 | L11: 313 | M11: 200 | N11: 240 | O11: 234 | P11: 298 | Q11: =IF(COUNT(I11:J11)=2,I11+J11,0) -> 400 | R11: =IF(COUNT(K11:L11)=2,K11+L11,0) -> 544 | S11: =IF(COUNT(M11:N11)=2,M11+N11,0) -> 440 | T11: =IF(COUNT(O11:P11)=2,O11+P11,0) -> 532 | U11: =IF(Q11>0,(I11/Q11-District!$B$4)*100,"") -> 1.0877664 | V11: =IF(R11>0,(K11/R11-District!$B$5)*100,"") -> -7.2867363 | W11: =IF(S11>0,(M11/S11-District!$B$6)*100,"") -> -5.5284752 | X11: =IF(T11>0,(O11/T11-District!$B$7)*100,"") -> -5.5114597 | Y11: =IF(AND(E11="Yes",Q11>=300,R11>=300,F11<>""),MAX(ABS(U11),ABS(V11))-R11/1000000000,"") -> 7.2867358 | Z11: =IF(ISNUMBER(Y11),SUMPRODUCT(ISNUMBER($Y$2:$Y$379)*($Y$2:$Y$379<Y11))+1,"") -> 101 | AA11: =IF(AND(E11="Yes",R11>=300,S11>=300,G11<>""),MAX(ABS(V11),ABS(W11))-S11/1000000000,"") | AB11: =IF(ISNUMBER(AA11),SUMPRODUCT(ISNUMBER($AA$2:$AA$379)*($AA$2:$AA$379<AA11))+1,"") | AC11: =IF(AND(E11="Yes",S11>=300,T11>=300,H11<>""),MAX(ABS(W11),ABS(X11))-T11/1000000000,"") -> 5.5284747 | AD11: =IF(ISNUMBER(AC11),SUMPRODUCT(ISNUMBER($AC$2:$AC$379)*($AC$2:$AC$379<AC11))+1,"") -> 86
A12: Carbon | JIM THORPE | 120 | B12: Carbon | C12: JIM THORPE | D12: 120 | E12: Yes | F12: JIM THORPE BOROUGH-2ND | H12: JIM THORPE BOROUGH-2ND | I12: 110 | J12: 146 | K12: 147 | L12: 243 | M12: 136 | N12: 161 | O12: 164 | P12: 227 | Q12: =IF(COUNT(I12:J12)=2,I12+J12,0) -> 256 | R12: =IF(COUNT(K12:L12)=2,K12+L12,0) -> 390 | S12: =IF(COUNT(M12:N12)=2,M12+N12,0) -> 297 | T12: =IF(COUNT(O12:P12)=2,O12+P12,0) -> 391 | U12: =IF(Q12>0,(I12/Q12-District!$B$4)*100,"") -> -10.443484 | V12: =IF(R12>0,(K12/R12-District!$B$5)*100,"") -> -12.057664 | W12: =IF(S12>0,(M12/S12-District!$B$6)*100,"") -> -5.1917749 | X12: =IF(T12>0,(O12/T12-District!$B$7)*100,"") -> -7.5526881 | Y12: =IF(AND(E12="Yes",Q12>=300,R12>=300,F12<>""),MAX(ABS(U12),ABS(V12))-R12/1000000000,"") | Z12: =IF(ISNUMBER(Y12),SUMPRODUCT(ISNUMBER($Y$2:$Y$379)*($Y$2:$Y$379<Y12))+1,"") | AA12: =IF(AND(E12="Yes",R12>=300,S12>=300,G12<>""),MAX(ABS(V12),ABS(W12))-S12/1000000000,"") | AB12: =IF(ISNUMBER(AA12),SUMPRODUCT(ISNUMBER($AA$2:$AA$379)*($AA$2:$AA$379<AA12))+1,"") | AC12: =IF(AND(E12="Yes",S12>=300,T12>=300,H12<>""),MAX(ABS(W12),ABS(X12))-T12/1000000000,"") | AD12: =IF(ISNUMBER(AC12),SUMPRODUCT(ISNUMBER($AC$2:$AC$379)*($AC$2:$AC$379<AC12))+1,"")
A13: Carbon | JIM THORPE | 130 | B13: Carbon | C13: JIM THORPE | D13: 130 | E13: Yes | F13: JIM THORPE BOROUGH-3RD | H13: JIM THORPE BOROUGH-3RD | I13: 258 | J13: 302 | K13: 276 | L13: 451 | M13: 244 | N13: 381 | O13: 289 | P13: 466 | Q13: =IF(COUNT(I13:J13)=2,I13+J13,0) -> 560 | R13: =IF(COUNT(K13:L13)=2,K13+L13,0) -> 727 | S13: =IF(COUNT(M13:N13)=2,M13+N13,0) -> 625 | T13: =IF(COUNT(O13:P13)=2,O13+P13,0) -> 755 | U13: =IF(Q13>0,(I13/Q13-District!$B$4)*100,"") -> -7.3408051 | V13: =IF(R13>0,(K13/R13-District!$B$5)*100,"") -> -11.785735 | W13: =IF(S13>0,(M13/S13-District!$B$6)*100,"") -> -11.943021 | X13: =IF(T13>0,(O13/T13-District!$B$7)*100,"") -> -11.218276 | Y13: =IF(AND(E13="Yes",Q13>=300,R13>=300,F13<>""),MAX(ABS(U13),ABS(V13))-R13/1000000000,"") -> 11.785734 | Z13: =IF(ISNUMBER(Y13),SUMPRODUCT(ISNUMBER($Y$2:$Y$379)*($Y$2:$Y$379<Y13))+1,"") -> 143 | AA13: =IF(AND(E13="Yes",R13>=300,S13>=300,G13<>""),MAX(ABS(V13),ABS(W13))-S13/1000000000,"") | AB13: =IF(ISNUMBER(AA13),SUMPRODUCT(ISNUMBER($AA$2:$AA$379)*($AA$2:$AA$379<AA13))+1,"") | AC13: =IF(AND(E13="Yes",S13>=300,T13>=300,H13<>""),MAX(ABS(W13),ABS(X13))-T13/1000000000,"") -> 11.94302 | AD13: =IF(ISNUMBER(AC13),SUMPRODUCT(ISNUMBER($AC$2:$AC$379)*($AC$2:$AC$379<AC13))+1,"") -> 159
A14: Carbon | JIM THORPE | 140 | B14: Carbon | C14: JIM THORPE | D14: 140 | E14: Yes | F14: JIM THORPE BOROUGH-4TH | H14: JIM THORPE BOROUGH-4TH | I14: 133 | J14: 94 | K14: 158 | L14: 142 | M14: 141 | N14: 108 | O14: 139 | P14: 135 | Q14: =IF(COUNT(I14:J14)=2,I14+J14,0) -> 227 | R14: =IF(COUNT(K14:L14)=2,K14+L14,0) -> 300 | S14: =IF(COUNT(M14:N14)=2,M14+N14,0) -> 249 | T14: =IF(COUNT(O14:P14)=2,O14+P14,0) -> 274 | U14: =IF(Q14>0,(I14/Q14-District!$B$4)*100,"") -> 5.1780747 | V14: =IF(R14>0,(K14/R14-District!$B$5)*100,"") -> 2.9166951 | W14: =IF(S14>0,(M14/S14-District!$B$6)*100,"") -> 5.6434853 | X14: =IF(T14>0,(O14/T14-District!$B$7)*100,"") -> 1.2335049 | Y14: =IF(AND(E14="Yes",Q14>=300,R14>=300,F14<>""),MAX(ABS(U14),ABS(V14))-R14/1000000000,"") | Z14: =IF(ISNUMBER(Y14),SUMPRODUCT(ISNUMBER($Y$2:$Y$379)*($Y$2:$Y$379<Y14))+1,"") | AA14: =IF(AND(E14="Yes",R14>=300,S14>=300,G14<>""),MAX(ABS(V14),ABS(W14))-S14/1000000000,"") | AB14: =IF(ISNUMBER(AA14),SUMPRODUCT(ISNUMBER($AA$2:$AA$379)*($AA$2:$AA$379<AA14))+1,"") | AC14: =IF(AND(E14="Yes",S14>=300,T14>=300,H14<>""),MAX(ABS(W14),ABS(X14))-T14/1000000000,"") | AD14: =IF(ISNUMBER(AC14),SUMPRODUCT(ISNUMBER($AC$2:$AC$379)*($AC$2:$AC$379<AC14))+1,"")
A15: Carbon | JIM THORPE | 150 | B15: Carbon | C15: JIM THORPE | D15: 150 | E15: Yes | F15: JIM THORPE BOROUGH-5TH | H15: JIM THORPE BOROUGH-5TH | I15: 193 | J15: 225 | K15: 248 | L15: 368 | M15: 258 | N15: 267 | O15: 278 | P15: 355 | Q15: =IF(COUNT(I15:J15)=2,I15+J15,0) -> 418 | R15: =IF(COUNT(K15:L15)=2,K15+L15,0) -> 616 | S15: =IF(COUNT(M15:N15)=2,M15+N15,0) -> 525 | T15: =IF(COUNT(O15:P15)=2,O15+P15,0) -> 633 | U15: =IF(Q15>0,(I15/Q15-District!$B$4)*100,"") -> -7.2399848 | V15: =IF(R15>0,(K15/R15-District!$B$5)*100,"") -> -9.4902313 | W15: =IF(S15>0,(M15/S15-District!$B$6)*100,"") -> -1.8401636 | X15: =IF(T15>0,(O15/T15-District!$B$7)*100,"") -> -5.5785706 | Y15: =IF(AND(E15="Yes",Q15>=300,R15>=300,F15<>""),MAX(ABS(U15),ABS(V15))-R15/1000000000,"") -> 9.4902307 | Z15: =IF(ISNUMBER(Y15),SUMPRODUCT(ISNUMBER($Y$2:$Y$379)*($Y$2:$Y$379<Y15))+1,"") -> 121 | AA15: =IF(AND(E15="Yes",R15>=300,S15>=300,G15<>""),MAX(ABS(V15),ABS(W15))-S15/1000000000,"") | AB15: =IF(ISNUMBER(AA15),SUMPRODUCT(ISNUMBER($AA$2:$AA$379)*($AA$2:$AA$379<AA15))+1,"") | AC15: =IF(AND(E15="Yes",S15>=300,T15>=300,H15<>""),MAX(ABS(W15),ABS(X15))-T15/1000000000,"") -> 5.57857 | AD15: =IF(ISNUMBER(AC15),SUMPRODUCT(ISNUMBER($AC$2:$AC$379)*($AC$2:$AC$379<AC15))+1,"") -> 88
A16: Carbon | KIDDER | 160 | B16: Carbon | C16: KIDDER | D16: 160 | E16: Yes | F16: KIDDER TOWNSHIP-NORTH | H16: KIDDER TOWNSHIP-NORTH | I16: 82 | J16: 131 | K16: 98 | L16: 208 | M16: 89 | N16: 161 | O16: 121 | P16: 204 | Q16: =IF(COUNT(I16:J16)=2,I16+J16,0) -> 213 | R16: =IF(COUNT(K16:L16)=2,K16+L16,0) -> 306 | S16: =IF(COUNT(M16:N16)=2,M16+N16,0) -> 250 | T16: =IF(COUNT(O16:P16)=2,O16+P16,0) -> 325 | U16: =IF(Q16>0,(I16/Q16-District!$B$4)*100,"") -> -14.914581 | V16: =IF(R16>0,(K16/R16-District!$B$5)*100,"") -> -17.723828 | W16: =IF(S16>0,(M16/S16-District!$B$6)*100,"") -> -15.383021 | X16: =IF(T16>0,(O16/T16-District!$B$7)*100,"") -> -12.265653 | Y16: =IF(AND(E16="Yes",Q16>=300,R16>=300,F16<>""),MAX(ABS(U16),ABS(V16))-R16/1000000000,"") | Z16: =IF(ISNUMBER(Y16),SUMPRODUCT(ISNUMBER($Y$2:$Y$379)*($Y$2:$Y$379<Y16))+1,"") | AA16: =IF(AND(E16="Yes",R16>=300,S16>=300,G16<>""),MAX(ABS(V16),ABS(W16))-S16/1000000000,"") | AB16: =IF(ISNUMBER(AA16),SUMPRODUCT(ISNUMBER($AA$2:$AA$379)*($AA$2:$AA$379<AA16))+1,"") | AC16: =IF(AND(E16="Yes",S16>=300,T16>=300,H16<>""),MAX(ABS(W16),ABS(X16))-T16/1000000000,"") | AD16: =IF(ISNUMBER(AC16),SUMPRODUCT(ISNUMBER($AC$2:$AC$379)*($AC$2:$AC$379<AC16))+1,"")
A17: Carbon | KIDDER | 170 | B17: Carbon | C17: KIDDER | D17: 170 | E17: Yes | F17: KIDDER TOWNSHIP-SOUTH | H17: KIDDER TOWNSHIP-SOUTH | I17: 185 | J17: 364 | K17: 237 | L17: 558 | M17: 188 | N17: 399 | O17: 230 | P17: 493 | Q17: =IF(COUNT(I17:J17)=2,I17+J17,0) -> 549 | R17: =IF(COUNT(K17:L17)=2,K17+L17,0) -> 795 | S17: =IF(COUNT(M17:N17)=2,M17+N17,0) -> 587 | T17: =IF(COUNT(O17:P17)=2,O17+P17,0) -> 723 | U17: =IF(Q17>0,(I17/Q17-District!$B$4)*100,"") -> -19.714602 | V17: =IF(R17>0,(K17/R17-District!$B$5)*100,"") -> -19.938651 | W17: =IF(S17>0,(M17/S17-District!$B$6)*100,"") -> -18.955763 | X17: =IF(T17>0,(O17/T17-District!$B$7)*100,"") -> -17.684527 | Y17: =IF(AND(E17="Yes",Q17>=300,R17>=300,F17<>""),MAX(ABS(U17),ABS(V17))-R17/1000000000,"") -> 19.93865 | Z17: =IF(ISNUMBER(Y17),SUMPRODUCT(ISNUMBER($Y$2:$Y$379)*($Y$2:$Y$379<Y17))+1,"") -> 222 | AA17: =IF(AND(E17="Yes",R17>=300,S17>=300,G17<>""),MAX(ABS(V17),ABS(W17))-S17/1000000000,"") | AB17: =IF(ISNUMBER(AA17),SUMPRODUCT(ISNUMBER($AA$2:$AA$379)*($AA$2:$AA$379<AA17))+1,"") | AC17: =IF(AND(E17="Yes",S17>=300,T17>=300,H17<>""),MAX(ABS(W17),ABS(X17))-T17/1000000000,"") -> 18.955763 | AD17: =IF(ISNUMBER(AC17),SUMPRODUCT(ISNUMBER($AC$2:$AC$379)*($AC$2:$AC$379<AC17))+1,"") -> 230
