Workbook

Sheet Beta Coefficient
A1: Two beta coefficients: national (1,099 races) and PA-07-specific (4 elections)
B3: National | C3: PA-07
A4: Beta (Dem money share coefficient) | B4: =INDEX(LINEST('National Races Data'!$J$4:$J$1102,'National Races Data'!$K$4:$L$1102,TRUE(),TRUE()),1,2) -> 0.33011163 | C4: ='Beta Coefficient'!$F$25 -> 0.010572695
A5: Gamma (incumbency coefficient) | B5: =INDEX(LINEST('National Races Data'!$J$4:$J$1102,'National Races Data'!$K$4:$L$1102,TRUE(),TRUE()),1,1) -> 0.03961089
A6: Intercept | B6: =INDEX(LINEST('National Races Data'!$J$4:$J$1102,'National Races Data'!$K$4:$L$1102,TRUE(),TRUE()),1,3) -> 0.33588718
A7: Sample | B7: 1,099 contested U.S. House races, 2018/2020/2022 (your uploaded workbook's training set) | C7: 4 PA-07 general elections, 2018-2024 (this workbook)
A8: Money definition | B8: Candidate committee spending + outside spending for the Dem / against the Rep (your workbook's definition) | C8: Candidate committee spending only -- outside/PAC spending not separately gathered for PA-07 (see note below)
A9: Statistical validity | B9: n=1,099, real inference (your workbook reports SE, t-stat, p-value, R²) | C9: n=4, 2 degrees of freedom -- not a valid inferential estimate, see note below
A13: PA-07 data (candidate-committee spending only)
A15: Year | B15: Dem $ (blended '18/'20) | C15: Rep $ (blended '18/'20) | D15: Total $ | E15: Dem money share | F15: House Dem vote share
A16: 2018 | B16: 3133499 | C16: 1079430 | D16: =B16+C16 -> 4212929 | E16: =B16/D16 -> 0.74378158 | F16: =SUMIFS('District Rollup'!$D$4:$D$7,'District Rollup'!$A$4:$A$7,A16) -> 0.53327586
A17: 2020 | B17: 4164240 | C17: 3404792 | D17: =B17+C17 -> 7569032 | E17: =B17/D17 -> 0.55016811 | F17: =SUMIFS('District Rollup'!$D$4:$D$7,'District Rollup'!$A$4:$A$7,A17) -> 0.49666572
A18: 2022 | B18: 7027026 | C18: 4301277 | D18: =B18+C18 -> 11328303 | E18: =B18/D18 -> 0.62030703 | F18: =SUMIFS('District Rollup'!$D$4:$D$7,'District Rollup'!$A$4:$A$7,A18) -> 0.50983021
A19: 2024 | B19: 7540355 | C19: 1229151 | D19: =B19+C19 -> 8769506 | E19: =B19/D19 -> 0.85983806 | F19: =SUMIFS('District Rollup'!$D$4:$D$7,'District Rollup'!$A$4:$A$7,A19) -> 0.49496422
A20: 2018: Blend: 90.57% old-PA07 (Wild $3,294,280 + Nothstein $958,874, FEC cycle totals) / 9.43% old-PA09 (Meuser $2,237,302 + Wolff $1,589,287). Weights = each area's exact share of 2018 real House votes.
A21: 2020: Blend: 90.54%/9.46%, same method. Old-PA07: Wild $4,591,501 + Scheller $3,661,738. Old-PA09: Meuser $945,604 + Wegman (~$75,000 assumed, not found in available sources).
A22: 2022: No blending -- single race. Wild $7,027,026 (FEC cycle total). Scheller ~$4,301,277 reconstructed from ProPublica FEC-mirror period filings -- least reliable figure here.
A23: 2024: No blending. Wild $7,540,355, Mackenzie $1,229,151, both Oct. 16, 2024 pre-general FEC reports. NOTE: your national workbook's own PA-07 2024 row uses $23,477,453 / $13,473,092 -- it includes outside spending, which this candidate-only figure does not. See note below the table.
A25: PA-07's own beta (this table, OLS, n=4) | F25: =SLOPE(F16:F19,E16:E19) -> 0.010572695
A27: A discovery worth flagging
A29: Your national workbook's own 15-race Pennsylvania 2024 holdout set includes PA-07 (row for Wild vs. Mackenzie) -- and it defines Democratic/Republican money as candidate committee spending PLUS outside spending, giving $23,477,453 (D) / $13,473,092 (R) for that race, a Dem money share of 63.5%. The PA-07 table above, using FEC candidate-committee totals only (no outside spending gathered), gives $7,540,355 (D) / $1,229,151 (R) for the same race -- an 86.0% Dem money share. Same election, two different numbers, because they're measuring different things. The PA-07 beta above uses the narrower (candidate-only) definition throughout for consistency across all 4 cycles, since outside-spending totals for 2018/2020/2022 weren't gathered here. That means the PA-07 beta and the national beta aren't a fully apples-to-apples comparison -- flagging it rather than quietly reconciling it, since fixing it properly would mean re-collecting outside-spending totals for all four PA-07 cycles, which hasn't been done.
A31: Using YOUR workbook's own money definition for PA-07 2024 as a spot check
A32: Definition | B32: Dem money share | C32: National-model predicted | D32: Actual | E32: Error (pts)
A33: Candidate-committee only (this workbook) | B33: =E19 -> 0.85983806 | C33: =$B$6+$B$4*B33+$B$5*1 -> 0.65934061 | D33: =F19 -> 0.49496422 | E33: =(D33-C33)*100 -> -16.437639
A34: Candidate + outside spending (your workbook's own PA-07 2024 row) | B34: ='National Races Data'!K1107 -> 0.63537501 | C34: ='National Races Data'!M1107 -> 0.58524275 | D34: ='National Races Data'!J1107 -> 0.49496422 | E34: ='National Races Data'!N1107 -> -9.0278529
A36: Even with the fuller (candidate+outside) money share, the national model still overpredicts PA-07 2024 -- by 9.0 points instead of 16.4. The gap shrinks a lot, but doesn't close, once outside spending is counted properly. That's a real result, not an artifact of which money definition was used.
A37: Regression chart: national fit vs. PA-07 fit
A39: PA-07 intercept (OLS, n=4) | F39: =INTERCEPT(F16:F19,E16:E19) -> 0.50135159
A41: Chart helper: fitted-line endpoints (National line assumes a Democratic incumbent, gamma x 1, matching PA-07's typical case)
B42: Dem money share (x) | C42: National fitted vote share | D42: PA-07 fitted vote share
B43: 0 | C43: =$B$6+$B$4*B43+$B$5*1 -> 0.37549807 | D43: =$F$39+$C$4*B43 -> 0.50135159
B44: 1 | C44: =$B$6+$B$4*B44+$B$5*1 -> 0.7056097 | D44: =$F$39+$C$4*B44 -> 0.51192428

Sheet Municipal Master Data
A1: Year | B1: Municipality Name | C1: County | D1: Municipality ID | E1: Party of the Incumbent - President | F1: Party that won the municpality - President | G1: Votes (Democrat) - President | H1: Votes (Republican) - President | I1: Votes (R+D) - President | J1: Party of the Incumbent - Governor | K1: Party that won the municpality - Governor | L1: Votes (Democrat) - Governor | M1: Votes (Republican) - Governor | N1: Votes (R+D) - Governor | O1: Party of the Incumbent - Senate | P1: Party that won the municpality- Senate | Q1: Votes (Democrat) - Senate | R1: Votes (Republican) - Senate | S1: Votes (R+D)- Senate | T1: Party of the Incumbent - House | U1: Party that won the municpality- House | V1: Votes (Democrat) - House | W1: Votes (Republican) - House | X1: Votes (R+D) - House | Y1: Voter Turnout (% of Registered Voters) | Z1: Dem Share - President | AA1: Dem Share - Governor | AB1: Dem Share - Senate | AC1: Dem Share - House | AD1: House Margin (R-D, votes)
A2: 2018 | B2: Banks Township | C2: Carbon | D2: 1 | E2: Republican | J2: Democrat | K2: Republican | L2: 174 | M2: 208 | N2: 382 | O2: Democrat | P2: Republican | Q2: 132 | R2: 260 | S2: 392 | U2: Republican | V2: 160 | W2: 221 | X2: 381 | Y2: 52 | Z2: =IFERROR(G2/(G2+H2),"") | AA2: =IFERROR(L2/(L2+M2),"") -> 0.45549738 | AB2: =IFERROR(Q2/(Q2+R2),"") -> 0.33673469 | AC2: =IFERROR(V2/(V2+W2),"") -> 0.41994751 | AD2: =W2-V2 -> 61
A3: 2018 | B3: Beaver Meadows Borough | C3: Carbon | D3: 2 | E3: Republican | J3: Democrat | K3: Republican | L3: 112 | M3: 168 | N3: 280 | O3: Democrat | P3: Republican | Q3: 83 | R3: 196 | S3: 279 | U3: Republican | V3: 95 | W3: 192 | X3: 287 | Y3: 47.7 | Z3: =IFERROR(G3/(G3+H3),"") | AA3: =IFERROR(L3/(L3+M3),"") -> 0.4 | AB3: =IFERROR(Q3/(Q3+R3),"") -> 0.29749104 | AC3: =IFERROR(V3/(V3+W3),"") -> 0.33101045 | AD3: =W3-V3 -> 97
A4: 2018 | B4: Bowmanstown Borough | C4: Carbon | D4: 3 | E4: Republican | J4: Democrat | K4: Republican | L4: 121 | M4: 160 | N4: 281 | O4: Democrat | P4: Republican | Q4: 123 | R4: 162 | S4: 285 | U4: Republican | V4: 110 | W4: 175 | X4: 285 | Y4: 52.6 | Z4: =IFERROR(G4/(G4+H4),"") | AA4: =IFERROR(L4/(L4+M4),"") -> 0.43060498 | AB4: =IFERROR(Q4/(Q4+R4),"") -> 0.43157895 | AC4: =IFERROR(V4/(V4+W4),"") -> 0.38596491 | AD4: =W4-V4 -> 65
A5: 2018 | B5: East Penn Township | C5: Carbon | D5: 4 | E5: Republican | J5: Democrat | K5: Republican | L5: 443 | M5: 665 | N5: 1108 | O5: Democrat | P5: Republican | Q5: 369 | R5: 740 | S5: 1109 | U5: Republican | V5: 369 | W5: 742 | X5: 1111 | Y5: 56.9 | Z5: =IFERROR(G5/(G5+H5),"") | AA5: =IFERROR(L5/(L5+M5),"") -> 0.39981949 | AB5: =IFERROR(Q5/(Q5+R5),"") -> 0.33273219 | AC5: =IFERROR(V5/(V5+W5),"") -> 0.33213321 | AD5: =W5-V5 -> 373
A6: 2018 | B6: East Side Borough | C6: Carbon | D6: 5 | E6: Republican | J6: Democrat | K6: Republican | L6: 36 | M6: 40 | N6: 76 | O6: Democrat | P6: Republican | Q6: 31 | R6: 45 | S6: 76 | U6: Republican | V6: 34 | W6: 43 | X6: 77 | Y6: 46.1 | Z6: =IFERROR(G6/(G6+H6),"") | AA6: =IFERROR(L6/(L6+M6),"") -> 0.47368421 | AB6: =IFERROR(Q6/(Q6+R6),"") -> 0.40789474 | AC6: =IFERROR(V6/(V6+W6),"") -> 0.44155844 | AD6: =W6-V6 -> 9
A7: 2018 | B7: Franklin Township | C7: Carbon | D7: 6 | E7: Republican | J7: Democrat | K7: Republican | L7: 581 | M7: 1055 | N7: 1636 | O7: Democrat | P7: Republican | Q7: 540 | R7: 1110 | S7: 1650 | U7: Republican | V7: 536 | W7: 1122 | X7: 1658 | Y7: 55.8 | Z7: =IFERROR(G7/(G7+H7),"") | AA7: =IFERROR(L7/(L7+M7),"") -> 0.35513447 | AB7: =IFERROR(Q7/(Q7+R7),"") -> 0.32727273 | AC7: =IFERROR(V7/(V7+W7),"") -> 0.32328106 | AD7: =W7-V7 -> 586
A8: 2018 | B8: Jim Thorpe Borough | C8: Carbon | D8: 7 | E8: Republican | J8: Democrat | K8: Democrat | L8: 971 | M8: 862 | N8: 1833 | O8: Democrat | P8: Republican | Q8: 887 | R8: 974 | S8: 1861 | U8: Republican | V8: 912 | W8: 949 | X8: 1861 | Y8: 55.7 | Z8: =IFERROR(G8/(G8+H8),"") | AA8: =IFERROR(L8/(L8+M8),"") -> 0.52973268 | AB8: =IFERROR(Q8/(Q8+R8),"") -> 0.47662547 | AC8: =IFERROR(V8/(V8+W8),"") -> 0.49005911 | AD8: =W8-V8 -> 37
A9: 2018 | B9: Kidder Township | C9: Carbon | D9: 8 | E9: Republican | J9: Democrat | K9: Republican | L9: 303 | M9: 453 | N9: 756 | O9: Democrat | P9: Republican | Q9: 261 | R9: 500 | S9: 761 | U9: Republican | V9: 267 | W9: 495 | X9: 762 | Y9: 53.5 | Z9: =IFERROR(G9/(G9+H9),"") | AA9: =IFERROR(L9/(L9+M9),"") -> 0.40079365 | AB9: =IFERROR(Q9/(Q9+R9),"") -> 0.34296978 | AC9: =IFERROR(V9/(V9+W9),"") -> 0.3503937 | AD9: =W9-V9 -> 228
A10: 2018 | B10: Lansford Borough | C10: Carbon | D10: 9 | E10: Republican | J10: Democrat | K10: Democrat | L10: 482 | M10: 429 | N10: 911 | O10: Democrat | P10: Republican | Q10: 428 | R10: 492 | S10: 920 | U10: Republican | V10: 455 | W10: 467 | X10: 922 | Y10: 40.9 | Z10: =IFERROR(G10/(G10+H10),"") | AA10: =IFERROR(L10/(L10+M10),"") -> 0.52908891 | AB10: =IFERROR(Q10/(Q10+R10),"") -> 0.46521739 | AC10: =IFERROR(V10/(V10+W10),"") -> 0.49349241 | AD10: =W10-V10 -> 12
A11: 2018 | B11: Lausanne Township | C11: Carbon | D11: 10 | E11: Republican | J11: Democrat | K11: Republican | L11: 33 | M11: 58 | N11: 91 | O11: Democrat | P11: Republican | Q11: 30 | R11: 61 | S11: 91 | U11: Republican | V11: 29 | W11: 59 | X11: 88 | Y11: 52.1 | Z11: =IFERROR(G11/(G11+H11),"") | AA11: =IFERROR(L11/(L11+M11),"") -> 0.36263736 | AB11: =IFERROR(Q11/(Q11+R11),"") -> 0.32967033 | AC11: =IFERROR(V11/(V11+W11),"") -> 0.32954545 | AD11: =W11-V11 -> 30
A12: 2018 | B12: Lehigh Township | C12: Carbon | D12: 11 | E12: Republican | J12: Democrat | K12: Republican | L12: 55 | M12: 143 | N12: 198 | O12: Democrat | P12: Republican | Q12: 39 | R12: 161 | S12: 200 | U12: Republican | V12: 41 | W12: 163 | X12: 204 | Y12: 57.3 | Z12: =IFERROR(G12/(G12+H12),"") | AA12: =IFERROR(L12/(L12+M12),"") -> 0.27777778 | AB12: =IFERROR(Q12/(Q12+R12),"") -> 0.195 | AC12: =IFERROR(V12/(V12+W12),"") -> 0.20098039 | AD12: =W12-V12 -> 122
A13: 2018 | B13: Lehighton Borough | C13: Carbon | D13: 12 | E13: Republican | J13: Democrat | K13: Democrat | L13: 713 | M13: 711 | N13: 1424 | O13: Democrat | P13: Republican | Q13: 677 | R13: 752 | S13: 1429 | U13: Republican | V13: 668 | W13: 766 | X13: 1434 | Y13: 46.4 | Z13: =IFERROR(G13/(G13+H13),"") | AA13: =IFERROR(L13/(L13+M13),"") -> 0.50070225 | AB13: =IFERROR(Q13/(Q13+R13),"") -> 0.47375787 | AC13: =IFERROR(V13/(V13+W13),"") -> 0.46582985 | AD13: =W13-V13 -> 98
... A90: 2018 | B90: Wind Gap | C90: Northampton | D90: 89 | E90: Republican | J90: Democrat | K90: Democrat | L90: 424 | M90: 401 | N90: 825 | O90: Democrat | P90: Republican | Q90: 391 | R90: 426 | S90: 817 | U90: Republican | V90: 362 | W90: 437 | X90: 799 | Y90: 50.9 | Z90: =IFERROR(G90/(G90+H90),"") | AA90: =IFERROR(L90/(L90+M90),"") -> 0.51393939 | AB90: =IFERROR(Q90/(Q90+R90),"") -> 0.47858017 | AC90: =IFERROR(V90/(V90+W90),"") -> 0.45306633 | AD90: =W90-V90 -> 75
A91: 2020 | B91: Banks Township | C91: Carbon | D91: 1 | E91: Republican | F91: Republican | G91: 148 | H91: 364 | I91: 512 | J91: Democrat | O91: N/A | T91: Democrat | U91: Republican | V91: 171 | W91: 332 | X91: 503 | Y91: 67.3 | Z91: =IFERROR(G91/(G91+H91),"") -> 0.2890625 | AA91: =IFERROR(L91/(L91+M91),"") | AB91: =IFERROR(Q91/(Q91+R91),"") | AC91: =IFERROR(V91/(V91+W91),"") -> 0.33996024 | AD91: =W91-V91 -> 161
A92: 2020 | B92: Beaver Meadows Borough | C92: Carbon | D92: 2 | E92: Republican | F92: Republican | G92: 98 | H92: 307 | I92: 405 | J92: Democrat | O92: N/A | T92: Democrat | U92: Republican | V92: 100 | W92: 303 | X92: 403 | Y92: 65.4 | Z92: =IFERROR(G92/(G92+H92),"") -> 0.24197531 | AA92: =IFERROR(L92/(L92+M92),"") | AB92: =IFERROR(Q92/(Q92+R92),"") | AC92: =IFERROR(V92/(V92+W92),"") -> 0.24813896 | AD92: =W92-V92 -> 203
A93: 2020 | B93: Bowmanstown Borough | C93: Carbon | D93: 3 | E93: Republican | F93: Republican | G93: 120 | H93: 304 | I93: 424 | J93: Democrat | O93: N/A | T93: Democrat | U93: Republican | V93: 111 | W93: 317 | X93: 428 | Y93: 71.6 | Z93: =IFERROR(G93/(G93+H93),"") -> 0.28301887 | AA93: =IFERROR(L93/(L93+M93),"") | AB93: =IFERROR(Q93/(Q93+R93),"") | AC93: =IFERROR(V93/(V93+W93),"") -> 0.25934579 | AD93: =W93-V93 -> 206
A94: 2020 | B94: East Penn Township | C94: Carbon | D94: 4 | E94: Republican | F94: Republican | G94: 422 | H94: 1155 | I94: 1577 | J94: Democrat | O94: N/A | T94: Democrat | U94: Republican | V94: 390 | W94: 1180 | X94: 1570 | Y94: 74.8 | Z94: =IFERROR(G94/(G94+H94),"") -> 0.2675967 | AA94: =IFERROR(L94/(L94+M94),"") | AB94: =IFERROR(Q94/(Q94+R94),"") | AC94: =IFERROR(V94/(V94+W94),"") -> 0.24840764 | AD94: =W94-V94 -> 790
A95: 2020 | B95: East Side Borough | C95: Carbon | D95: 5 | E95: Republican | F95: Republican | G95: 51 | H95: 72 | I95: 123 | J95: Democrat | O95: N/A | T95: Democrat | U95: Republican | V95: 47 | W95: 74 | X95: 121 | Y95: 65.8 | Z95: =IFERROR(G95/(G95+H95),"") -> 0.41463415 | AA95: =IFERROR(L95/(L95+M95),"") | AB95: =IFERROR(Q95/(Q95+R95),"") | AC95: =IFERROR(V95/(V95+W95),"") -> 0.38842975 | AD95: =W95-V95 -> 27
A96: 2020 | B96: Franklin Township | C96: Carbon | D96: 6 | E96: Republican | F96: Republican | G96: 673 | H96: 1811 | I96: 2484 | J96: Democrat | O96: N/A | T96: Democrat | U96: Republican | V96: 631 | W96: 1828 | X96: 2459 | Y96: 75.7 | Z96: =IFERROR(G96/(G96+H96),"") -> 0.27093398 | AA96: =IFERROR(L96/(L96+M96),"") | AB96: =IFERROR(Q96/(Q96+R96),"") | AC96: =IFERROR(V96/(V96+W96),"") -> 0.25660838 | AD96: =W96-V96 -> 1197
A97: 2020 | B97: Jim Thorpe Borough | C97: Carbon | D97: 7 | E97: Republican | F97: Republican | G97: 1116 | H97: 1508 | I97: 2624 | J97: Democrat | O97: N/A | T97: Democrat | U97: Republican | V97: 1060 | W97: 1517 | X97: 2577 | Y97: 72.1 | Z97: =IFERROR(G97/(G97+H97),"") -> 0.42530488 | AA97: =IFERROR(L97/(L97+M97),"") | AB97: =IFERROR(Q97/(Q97+R97),"") | AC97: =IFERROR(V97/(V97+W97),"") -> 0.41133101 | AD97: =W97-V97 -> 457
A98: 2020 | B98: Kidder Township | C98: Carbon | D98: 8 | E98: Republican | F98: Republican | G98: 360 | H98: 740 | I98: 1100 | J98: Democrat | O98: N/A | T98: Democrat | U98: Republican | V98: 335 | W98: 766 | X98: 1101 | Y98: 68.3 | Z98: =IFERROR(G98/(G98+H98),"") -> 0.32727273 | AA98: =IFERROR(L98/(L98+M98),"") | AB98: =IFERROR(Q98/(Q98+R98),"") | AC98: =IFERROR(V98/(V98+W98),"") -> 0.30426885 | AD98: =W98-V98 -> 431
A99: 2020 | B99: Lansford Borough | C99: Carbon | D99: 9 | E99: Republican | F99: Republican | G99: 603 | H99: 856 | I99: 1459 | J99: Democrat | O99: N/A | T99: Democrat | U99: Republican | V99: 614 | W99: 846 | X99: 1460 | Y99: 59.8 | Z99: =IFERROR(G99/(G99+H99),"") -> 0.41329678 | AA99: =IFERROR(L99/(L99+M99),"") | AB99: =IFERROR(Q99/(Q99+R99),"") | AC99: =IFERROR(V99/(V99+W99),"") -> 0.42054795 | AD99: =W99-V99 -> 232
A100: 2020 | B100: Lausanne Township | C100: Carbon | D100: 10 | E100: Republican | F100: Republican | G100: 43 | H100: 97 | I100: 140 | J100: Democrat | O100: N/A | T100: Democrat | U100: Republican | V100: 42 | W100: 99 | X100: 141 | Y100: 76.6 | Z100: =IFERROR(G100/(G100+H100),"") -> 0.30714286 | AA100: =IFERROR(L100/(L100+M100),"") | AB100: =IFERROR(Q100/(Q100+R100),"") | AC100: =IFERROR(V100/(V100+W100),"") -> 0.29787234 | AD100: =W100-V100 -> 57
A101: 2020 | B101: Lehigh Township | C101: Carbon | D101: 11 | E101: Republican | F101: Republican | G101: 61 | H101: 217 | I101: 278 | J101: Democrat | O101: N/A | T101: Democrat | U101: Republican | V101: 51 | W101: 223 | X101: 274 | Y101: 75.3 | Z101: =IFERROR(G101/(G101+H101),"") -> 0.21942446 | AA101: =IFERROR(L101/(L101+M101),"") | AB101: =IFERROR(Q101/(Q101+R101),"") | AC101: =IFERROR(V101/(V101+W101),"") -> 0.18613139 | AD101: =W101-V101 -> 172
A102: 2020 | B102: Lehighton Borough | C102: Carbon | D102: 12 | E102: Republican | F102: Republican | G102: 898 | H102: 1376 | I102: 2274 | J102: Democrat | O102: N/A | T102: Democrat | U102: Republican | V102: 841 | W102: 1410 | X102: 2251 | Y102: 67.3 | Z102: =IFERROR(G102/(G102+H102),"") -> 0.39489886 | AA102: =IFERROR(L102/(L102+M102),"") | AB102: =IFERROR(Q102/(Q102+R102),"") | AC102: =IFERROR(V102/(V102+W102),"") -> 0.37361173 | AD102: =W102-V102 -> 569
... A179: 2020 | B179: Wind Gap | C179: Northampton | D179: 89 | E179: Republican | F179: Republican | G179: 531 | H179: 793 | I179: 1324 | J179: Democrat | O179: N/A | T179: Democrat | U179: Republican | V179: 508 | W179: 791 | X179: 1299 | Y179: 72.8 | Z179: =IFERROR(G179/(G179+H179),"") -> 0.4010574 | AA179: =IFERROR(L179/(L179+M179),"") | AB179: =IFERROR(Q179/(Q179+R179),"") | AC179: =IFERROR(V179/(V179+W179),"") -> 0.39107005 | AD179: =W179-V179 -> 283
A180: 2022 | B180: Banks Township | C180: Carbon | D180: 1 | E180: Democrat | J180: Democrat | K180: Republican | L180: 151 | M180: 227 | N180: 378 | O180: Republican | P180: Republican | Q180: 141 | R180: 233 | S180: 374 | T180: Democrat | U180: Republican | V180: 137 | W180: 249 | X180: 386 | Y180: 58.89 | Z180: =IFERROR(G180/(G180+H180),"") | AA180: =IFERROR(L180/(L180+M180),"") -> 0.3994709 | AB180: =IFERROR(Q180/(Q180+R180),"") -> 0.37700535 | AC180: =IFERROR(V180/(V180+W180),"") -> 0.35492228 | AD180: =W180-V180 -> 112
A181: 2022 | B181: Beaver Meadows Borough | C181: Carbon | D181: 2 | E181: Democrat | J181: Democrat | K181: Republican | L181: 108 | M181: 196 | N181: 304 | O181: Republican | P181: Republican | Q181: 87 | R181: 216 | S181: 303 | T181: Democrat | U181: Republican | V181: 84 | W181: 230 | X181: 314 | Y181: 54.62 | Z181: =IFERROR(G181/(G181+H181),"") | AA181: =IFERROR(L181/(L181+M181),"") -> 0.35526316 | AB181: =IFERROR(Q181/(Q181+R181),"") -> 0.28712871 | AC181: =IFERROR(V181/(V181+W181),"") -> 0.26751592 | AD181: =W181-V181 -> 146
A182: 2022 | B182: Bowmanstown Borough | C182: Carbon | D182: 3 | E182: Democrat | J182: Democrat | K182: Republican | L182: 145 | M182: 199 | N182: 344 | O182: Republican | P182: Republican | Q182: 135 | R182: 201 | S182: 336 | T182: Democrat | U182: Republican | V182: 125 | W182: 223 | X182: 348 | Y182: 65.27 | Z182: =IFERROR(G182/(G182+H182),"") | AA182: =IFERROR(L182/(L182+M182),"") -> 0.42151163 | AB182: =IFERROR(Q182/(Q182+R182),"") -> 0.40178571 | AC182: =IFERROR(V182/(V182+W182),"") -> 0.3591954 | AD182: =W182-V182 -> 98
A183: 2022 | B183: East Penn Township | C183: Carbon | D183: 4 | E183: Democrat | J183: Democrat | K183: Republican | L183: 449 | M183: 830 | N183: 1279 | O183: Republican | P183: Republican | Q183: 378 | R183: 872 | S183: 1250 | T183: Democrat | U183: Republican | V183: 372 | W183: 925 | X183: 1297 | Y183: 66.05 | Z183: =IFERROR(G183/(G183+H183),"") | AA183: =IFERROR(L183/(L183+M183),"") -> 0.35105551 | AB183: =IFERROR(Q183/(Q183+R183),"") -> 0.3024 | AC183: =IFERROR(V183/(V183+W183),"") -> 0.28681573 | AD183: =W183-V183 -> 553
A184: 2022 | B184: East Side Borough | C184: Carbon | D184: 5 | E184: Democrat | J184: Democrat | K184: Republican | L184: 38 | M184: 52 | N184: 90 | O184: Republican | P184: Republican | Q184: 36 | R184: 54 | S184: 90 | T184: Democrat | U184: Republican | V184: 33 | W184: 61 | X184: 94 | Y184: 58.28 | Z184: =IFERROR(G184/(G184+H184),"") | AA184: =IFERROR(L184/(L184+M184),"") -> 0.42222222 | AB184: =IFERROR(Q184/(Q184+R184),"") -> 0.4 | AC184: =IFERROR(V184/(V184+W184),"") -> 0.35106383 | AD184: =W184-V184 -> 28
A185: 2022 | B185: Franklin Township | C185: Carbon | D185: 6 | E185: Democrat | J185: Democrat | K185: Republican | L185: 680 | M185: 1232 | N185: 1912 | O185: Republican | P185: Republican | Q185: 588 | R185: 1309 | S185: 1897 | T185: Democrat | U185: Republican | V185: 560 | W185: 1398 | X185: 1958 | Y185: 63.11 | Z185: =IFERROR(G185/(G185+H185),"") | AA185: =IFERROR(L185/(L185+M185),"") -> 0.35564854 | AB185: =IFERROR(Q185/(Q185+R185),"") -> 0.3099631 | AC185: =IFERROR(V185/(V185+W185),"") -> 0.28600613 | AD185: =W185-V185 -> 838
A186: 2022 | B186: Jim Thorpe Borough | C186: Carbon | D186: 7 | E186: Democrat | J186: Democrat | K186: Democrat | L186: 1107 | M186: 992 | N186: 2099 | O186: Republican | P186: Democrat | Q186: 1049 | R186: 1031 | S186: 2080 | T186: Democrat | U186: Republican | V186: 979 | W186: 1157 | X186: 2136 | Y186: 64.88 | Z186: =IFERROR(G186/(G186+H186),"") | AA186: =IFERROR(L186/(L186+M186),"") -> 0.527394 | AB186: =IFERROR(Q186/(Q186+R186),"") -> 0.50432692 | AC186: =IFERROR(V186/(V186+W186),"") -> 0.45833333 | AD186: =W186-V186 -> 178
A187: 2022 | B187: Kidder Township | C187: Carbon | D187: 8 | E187: Democrat | J187: Democrat | K187: Republican | L187: 347 | M187: 482 | N187: 829 | O187: Republican | P187: Republican | Q187: 299 | R187: 526 | S187: 825 | T187: Democrat | U187: Republican | V187: 277 | W187: 560 | X187: 837 | Y187: 58.79 | Z187: =IFERROR(G187/(G187+H187),"") | AA187: =IFERROR(L187/(L187+M187),"") -> 0.4185766 | AB187: =IFERROR(Q187/(Q187+R187),"") -> 0.36242424 | AC187: =IFERROR(V187/(V187+W187),"") -> 0.33094385 | AD187: =W187-V187 -> 283
A188: 2022 | B188: Lansford Borough | C188: Carbon | D188: 9 | E188: Democrat | J188: Democrat | K188: Republican | L188: 493 | M188: 506 | N188: 999 | O188: Republican | P188: Republican | Q188: 455 | R188: 525 | S188: 980 | T188: Democrat | U188: Republican | V188: 420 | W188: 580 | X188: 1000 | Y188: 45.83 | Z188: =IFERROR(G188/(G188+H188),"") | AA188: =IFERROR(L188/(L188+M188),"") -> 0.49349349 | AB188: =IFERROR(Q188/(Q188+R188),"") -> 0.46428571 | AC188: =IFERROR(V188/(V188+W188),"") -> 0.42 | AD188: =W188-V188 -> 160
A189: 2022 | B189: Lausanne Township | C189: Carbon | D189: 10 | E189: Democrat | J189: Democrat | K189: Republican | L189: 45 | M189: 70 | N189: 115 | O189: Republican | P189: Republican | Q189: 41 | R189: 72 | S189: 113 | T189: Democrat | U189: Republican | V189: 36 | W189: 79 | X189: 115 | Y189: 66.86 | Z189: =IFERROR(G189/(G189+H189),"") | AA189: =IFERROR(L189/(L189+M189),"") -> 0.39130435 | AB189: =IFERROR(Q189/(Q189+R189),"") -> 0.36283186 | AC189: =IFERROR(V189/(V189+W189),"") -> 0.31304348 | AD189: =W189-V189 -> 43
A190: 2022 | B190: Lehigh Township | C190: Carbon | D190: 11 | E190: Democrat | J190: Democrat | K190: Republican | L190: 68 | M190: 173 | N190: 241 | O190: Republican | P190: Republican | Q190: 56 | R190: 181 | S190: 237 | T190: Democrat | U190: Republican | V190: 52 | W190: 189 | X190: 241 | Y190: 70.98 | Z190: =IFERROR(G190/(G190+H190),"") | AA190: =IFERROR(L190/(L190+M190),"") -> 0.28215768 | AB190: =IFERROR(Q190/(Q190+R190),"") -> 0.23628692 | AC190: =IFERROR(V190/(V190+W190),"") -> 0.21576763 | AD190: =W190-V190 -> 137
A191: 2022 | B191: Lehighton Borough | C191: Carbon | D191: 12 | E191: Democrat | J191: Democrat | K191: Republican | L191: 803 | M191: 846 | N191: 1649 | O191: Republican | P191: Republican | Q191: 744 | R191: 878 | S191: 1622 | T191: Democrat | U191: Republican | V191: 719 | W191: 948 | X191: 1667 | Y191: 53.84 | Z191: =IFERROR(G191/(G191+H191),"") | AA191: =IFERROR(L191/(L191+M191),"") -> 0.4869618 | AB191: =IFERROR(Q191/(Q191+R191),"") -> 0.45869297 | AC191: =IFERROR(V191/(V191+W191),"") -> 0.43131374 | AD191: =W191-V191 -> 229
... A268: 2022 | B268: Wind Gap | C268: Northampton | D268: 89 | E268: Democrat | J268: Democrat | K268: Democrat | L268: 557 | M268: 527 | N268: 1084 | O268: Republican | P268: Republican | Q268: 506 | R268: 562 | S268: 1068 | T268: Democrat | U268: Republican | V268: 494 | W268: 601 | X268: 1095 | Y268: 53.5 | Z268: =IFERROR(G268/(G268+H268),"") | AA268: =IFERROR(L268/(L268+M268),"") -> 0.51383764 | AB268: =IFERROR(Q268/(Q268+R268),"") -> 0.47378277 | AC268: =IFERROR(V268/(V268+W268),"") -> 0.45114155 | AD268: =W268-V268 -> 107
...

Sheet District Rollup
A1: PA-07 House race totals by year, summed live from Municipal Master Data (all 89 municipalities). House only -- the only race campaign spending in this workbook maps to.
A3: Year | B3: House D votes | C3: House R votes | D3: House Dem vote share
A4: 2018 | B4: =SUMIFS('Municipal Master Data'!$V$2:$V$357,'Municipal Master Data'!$A$2:$A$357,$A4) -> 140419 | C4: =SUMIFS('Municipal Master Data'!$W$2:$W$357,'Municipal Master Data'!$A$2:$A$357,$A4) -> 122895 | D4: =B4/(B4+C4) -> 0.53327586
A5: 2020 | B5: =SUMIFS('Municipal Master Data'!$V$2:$V$357,'Municipal Master Data'!$A$2:$A$357,$A5) -> 193719 | C5: =SUMIFS('Municipal Master Data'!$W$2:$W$357,'Municipal Master Data'!$A$2:$A$357,$A5) -> 196320 | D5: =B5/(B5+C5) -> 0.49666572
A6: 2022 | B6: =SUMIFS('Municipal Master Data'!$V$2:$V$357,'Municipal Master Data'!$A$2:$A$357,$A6) -> 151364 | C6: =SUMIFS('Municipal Master Data'!$W$2:$W$357,'Municipal Master Data'!$A$2:$A$357,$A6) -> 145527 | D6: =B6/(B6+C6) -> 0.50983021
A7: 2024 | B7: =SUMIFS('Municipal Master Data'!$V$2:$V$357,'Municipal Master Data'!$A$2:$A$357,$A7) -> 199626 | C7: =SUMIFS('Municipal Master Data'!$W$2:$W$357,'Municipal Master Data'!$A$2:$A$357,$A7) -> 203688 | D7: =B7/(B7+C7) -> 0.49496422

Sheet Registration & Turnout
A1: Registration and turnout by municipality and election (party = current 31 Aug 2026 registration snapshot — see Summary tab)
A3: Election Year | B3: Municipality | C3: County | D3: Municipality ID | E3: Registered D | F3: Registered R | G3: Registered Other | H3: Voted D | I3: Voted R | J3: Voted Other | K3: Mail D | L3: Mail R | M3: Mail Other | N3: Voted Dem share
A4: 2026 | B4: Banks Township | C4: Carbon | D4: 1 | E4: 277 | F4: 246 | G4: 94 | H4: 89 | I4: 57 | J4: 0 | K4: 23 | L4: 11 | M4: 0 | N4: =IFERROR(G4/(G4+H4),"") -> 0.5136612
A5: 2026 | B5: Beaver Meadows Borough | C5: Carbon | D5: 2 | E5: 168 | F5: 316 | G5: 118 | H5: 23 | I5: 52 | J5: 0 | K5: 2 | L5: 3 | M5: 0 | N5: =IFERROR(G5/(G5+H5),"") -> 0.83687943
A6: 2026 | B6: Bowmanstown Borough | C6: Carbon | D6: 3 | E6: 158 | F6: 311 | G6: 89 | H6: 59 | I6: 75 | J6: 1 | K6: 20 | L6: 5 | M6: 0 | N6: =IFERROR(G6/(G6+H6),"") -> 0.60135135
A7: 2026 | B7: East Penn Township | C7: Carbon | D7: 4 | E7: 516 | F7: 1250 | G7: 285 | H7: 174 | I7: 308 | J7: 0 | K7: 69 | L7: 44 | M7: 0 | N7: =IFERROR(G7/(G7+H7),"") -> 0.62091503
A8: 2026 | B8: East Side Borough | C8: Carbon | D8: 5 | E8: 52 | F8: 79 | G8: 30 | H8: 20 | I8: 22 | J8: 0 | K8: 13 | L8: 5 | M8: 0 | N8: =IFERROR(G8/(G8+H8),"") -> 0.6
A9: 2026 | B9: Franklin Township | C9: Carbon | D9: 6 | E9: 801 | F9: 1859 | G9: 427 | H9: 275 | I9: 478 | J9: 0 | K9: 107 | L9: 39 | M9: 0 | N9: =IFERROR(G9/(G9+H9),"") -> 0.60826211
A10: 2026 | B10: Jim Thorpe Borough | C10: Carbon | D10: 7 | E10: 1291 | F10: 1460 | G10: 482 | H10: 512 | I10: 361 | J10: 0 | K10: 171 | L10: 54 | M10: 0 | N10: =IFERROR(G10/(G10+H10),"") -> 0.48490946
A11: 2026 | B11: Kidder Township | C11: Carbon | D11: 8 | E11: 363 | F11: 769 | G11: 286 | H11: 118 | I11: 182 | J11: 2 | K11: 49 | L11: 25 | M11: 0 | N11: =IFERROR(G11/(G11+H11),"") -> 0.70792079
A12: 2026 | B12: Lansford Borough | C12: Carbon | D12: 9 | E12: 884 | F12: 975 | G12: 513 | H12: 220 | I12: 188 | J12: 0 | K12: 81 | L12: 30 | M12: 0 | N12: =IFERROR(G12/(G12+H12),"") -> 0.69986357
A13: 2026 | B13: Lausanne Township | C13: Carbon | D13: 10 | E13: 43 | F13: 111 | G13: 26 | H13: 15 | I13: 15 | J13: 1 | K13: 10 | L13: 4 | M13: 1 | N13: =IFERROR(G13/(G13+H13),"") -> 0.63414634
A14: 2026 | B14: Lehigh Township | C14: Carbon | D14: 11 | E14: 56 | F14: 237 | G14: 38 | H14: 15 | I14: 62 | J14: 0 | K14: 4 | L14: 12 | M14: 0 | N14: =IFERROR(G14/(G14+H14),"") -> 0.71698113
A15: 2026 | B15: Lehighton Borough | C15: Carbon | D15: 12 | E15: 1126 | F15: 1635 | G15: 530 | H15: 343 | I15: 312 | J15: 0 | K15: 141 | L15: 50 | M15: 0 | N15: =IFERROR(G15/(G15+H15),"") -> 0.60710195
... A359: 2020 | B359: Wind Gap | C359: Northampton | D359: 89 | E359: 624 | F359: 770 | G359: 285 | H359: 462 | I359: 579 | J359: 170 | K359: 231 | L359: 91 | M359: 50 | N359: =IFERROR(G359/(G359+H359),"") -> 0.3815261
A360: 2018 | B360: Banks Township | C360: Carbon | D360: 1 | E360: 235 | F360: 188 | G360: 61 | H360: 151 | I360: 118 | J360: 21 | N360: =IFERROR(G360/(G360+H360),"") -> 0.28773585
A361: 2018 | B361: Beaver Meadows Borough | C361: Carbon | D361: 2 | E361: 130 | F361: 224 | G361: 55 | H361: 65 | I361: 130 | J361: 20 | N361: =IFERROR(G361/(G361+H361),"") -> 0.45833333
A362: 2018 | B362: Bowmanstown Borough | C362: Carbon | D362: 3 | E362: 133 | F362: 236 | G362: 56 | H362: 85 | I362: 137 | J362: 20 | N362: =IFERROR(G362/(G362+H362),"") -> 0.39716312
A363: 2018 | B363: East Penn Township | C363: Carbon | D363: 4 | E363: 428 | F363: 977 | G363: 196 | H363: 256 | I363: 592 | J363: 69 | N363: =IFERROR(G363/(G363+H363),"") -> 0.43362832
A364: 2018 | B364: East Side Borough | C364: Carbon | D364: 5 | E364: 43 | F364: 62 | G364: 19 | H364: 28 | I364: 32 | J364: 5 | N364: =IFERROR(G364/(G364+H364),"") -> 0.40425532
A365: 2018 | B365: Franklin Township | C365: Carbon | D365: 6 | E365: 663 | F365: 1436 | G365: 272 | H365: 384 | I365: 849 | J365: 105 | N365: =IFERROR(G365/(G365+H365),"") -> 0.41463415
A366: 2018 | B366: Jim Thorpe Borough | C366: Carbon | D366: 7 | E366: 1077 | F366: 1151 | G366: 303 | H366: 673 | I366: 696 | J366: 118 | N366: =IFERROR(G366/(G366+H366),"") -> 0.31045082
A367: 2018 | B367: Kidder Township | C367: Carbon | D367: 8 | E367: 266 | F367: 545 | G367: 159 | H367: 123 | I367: 283 | J367: 65 | N367: =IFERROR(G367/(G367+H367),"") -> 0.56382979
A368: 2018 | B368: Lansford Borough | C368: Carbon | D368: 9 | E368: 662 | F368: 683 | G368: 282 | H368: 298 | I368: 304 | J368: 74 | N368: =IFERROR(G368/(G368+H368),"") -> 0.4862069
A369: 2018 | B369: Lausanne Township | C369: Carbon | D369: 10 | E369: 36 | F369: 81 | G369: 13 | H369: 16 | I369: 45 | J369: 6 | N369: =IFERROR(G369/(G369+H369),"") -> 0.44827586
A370: 2018 | B370: Lehigh Township | C370: Carbon | D370: 11 | E370: 52 | F370: 200 | G370: 30 | H370: 26 | I370: 140 | J370: 13 | N370: =IFERROR(G370/(G370+H370),"") -> 0.53571429
A371: 2018 | B371: Lehighton Borough | C371: Carbon | D371: 12 | E371: 906 | F371: 1214 | G371: 296 | H371: 470 | I371: 614 | J371: 79 | N371: =IFERROR(G371/(G371+H371),"") -> 0.38642298
... A448: 2018 | B448: Wind Gap | C448: Northampton | D448: 89 | E448: 560 | F448: 663 | G448: 239 | H448: 296 | I448: 343 | J448: 74 | N448: =IFERROR(G448/(G448+H448),"") -> 0.44672897

Sheet National Races Data
A1: Source: your uploaded House_Money_Beta_Backtests.xlsx, "Races" sheet, values only. 1,099 contested U.S. House races (2018/2020/2022) used to train the national beta, plus 15 Pennsylvania 2024 races your workbook held out as a fresh test -- PA-07 among them (row with Wild/Mackenzie).
A3: Election year | B3: State | C3: District | D3: Democratic candidate | E3: Republican candidate | F3: Democratic votes | G3: Republican votes | H3: Democratic side money ($) (candidate committee plus outside spending for the Democrat or against the Republican) | I3: Republican side money ($) | J3: Democratic share of the two-party vote | K3: Democratic share of the two-party money | L3: Incumbency (+1 Democratic incumbent, -1 Republican incumbent, 0 open) | M3: Predicted Democratic vote share (final beta, trained on 2018-2022) | N3: Prediction error (percentage points, actual minus predicted) | O3: Winner called correctly (1 = yes) | P3: Vote source | Q3: In training sample (2018/20/22)?
A4: 2018 | B4: AL | C4: 1 | D4: Kennedy, Robert, Jr. | E4: Byrne, Bradley | F4: 89226 | G4: 153228 | H4: 167707.07 | I4: 834780.43 | J4: 0.36801208 | K4: 0.16729093 | L4: -1 | M4: 0.35150097 | N4: 1.6511103 | O4: 1 | P4: FEC Federal Elections; FEC filings | Q4: =IF(A4=2024,"No -- held out","Yes") -> Yes
A5: 2018 | B5: AL | C5: 2 | D5: Isner, Tabitha | E5: Roby, Martha | F5: 86931 | G5: 138879 | H5: 526541.43 | I5: 2648797.9 | J5: 0.38497409 | K5: 0.1658221 | L5: -1 | M5: 0.35101609 | N5: 3.3958 | O5: 1 | P5: FEC Federal Elections; FEC filings | Q5: =IF(A5=2024,"No -- held out","Yes") -> Yes
A6: 2018 | B6: AL | C6: 3 | D6: Hagan, Mallory | E6: Rogers, Mike | F6: 83996 | G6: 147770 | H6: 464511.8 | I6: 1348278.3 | J6: 0.36241727 | K6: 0.25624136 | L6: -1 | M6: 0.38086454 | N6: -1.8447277 | O6: 1 | P6: FEC Federal Elections; FEC filings | Q6: =IF(A6=2024,"No -- held out","Yes") -> Yes
A7: 2018 | B7: AL | C7: 4 | D7: Auman, Lee | E7: Aderholt, Robert | F7: 46492 | G7: 184255 | H7: 78413.55 | I7: 1300365 | J7: 0.20148474 | K7: 0.05687175 | L7: -1 | M7: 0.31505032 | N7: -11.356557 | O7: 1 | P7: FEC Federal Elections; FEC filings | Q7: =IF(A7=2024,"No -- held out","Yes") -> Yes
A8: 2018 | B8: AL | C8: 5 | D8: Joffrion, Peter | E8: Brooks, Mo | F8: 101388 | G8: 159063 | H8: 587237.93 | I8: 2010714.1 | J8: 0.3892786 | K8: 0.22603879 | L8: -1 | M8: 0.37089432 | N8: 1.8384273 | O8: 1 | P8: FEC Federal Elections; FEC filings | Q8: =IF(A8=2024,"No -- held out","Yes") -> Yes
A9: 2018 | B9: AL | C9: 6 | D9: Kline, Danner | E9: Palmer, Gary | F9: 85644 | G9: 192542 | H9: 288294.09 | I9: 1500555.4 | J9: 0.30786596 | K9: 0.16116174 | L9: -1 | M9: 0.34947765 | N9: -4.1611694 | O9: 1 | P9: FEC Federal Elections; FEC filings | Q9: =IF(A9=2024,"No -- held out","Yes") -> Yes
A10: 2018 | B10: AR | C10: 1 | D10: Desai, Chintan | E10: Crawford, Rick | F10: 57907 | G10: 138757 | H10: 137153.22 | I10: 966616.64 | J10: 0.29444637 | K10: 0.12425889 | L10: -1 | M10: 0.3372956 | N10: -4.284923 | O10: 1 | P10: FEC Federal Elections; FEC filings | Q10: =IF(A10=2024,"No -- held out","Yes") -> Yes
A11: 2018 | B11: AR | C11: 2 | D11: Tucker, Clarke | E11: Hill, French | F11: 116135 | G11: 132125 | H11: 3251897.9 | I11: 4310765.1 | J11: 0.46779586 | K11: 0.42999376 | L11: -1 | M11: 0.43822223 | N11: 2.9573629 | O11: 1 | P11: FEC Federal Elections; FEC filings | Q11: =IF(A11=2024,"No -- held out","Yes") -> Yes
A12: 2018 | B12: AR | C12: 3 | D12: Mahony, Josh | E12: Womack, Steve | F12: 74952 | G12: 148717 | H12: 266794.84 | I12: 1218424 | J12: 0.33510232 | K12: 0.17963335 | L12: -1 | M12: 0.35557535 | N12: -2.0473032 | O12: 1 | P12: FEC Federal Elections; FEC filings | Q12: =IF(A12=2024,"No -- held out","Yes") -> Yes
A13: 2018 | B13: AR | C13: 4 | D13: Shamel, Hayden Catherine | E13: Westerman, Bruce | F13: 63984 | G13: 136740 | H13: 155911.8 | I13: 1297141.1 | J13: 0.31876607 | K13: 0.10729947 | L13: -1 | M13: 0.33169709 | N13: -1.2931025 | O13: 1 | P13: FEC Federal Elections; FEC filings | Q13: =IF(A13=2024,"No -- held out","Yes") -> Yes
A14: 2018 | B14: AS | C14: 0 | D14: Suitonu-Chapman, Meleagi | E14: Amata, Aumua | F14: 637 | G14: 7194 | H14: 0 | I14: 168373.19 | J14: 0.081343379 | K14: 0 | L14: -1 | M14: 0.29627629 | N14: -21.493291 | O14: 1 | P14: FEC Federal Elections; FEC filings | Q14: =IF(A14=2024,"No -- held out","Yes") -> Yes
A15: 2018 | B15: AZ | C15: 1 | D15: O'Halleran, Tom | E15: Rogers, Wendy | F15: 143240 | G15: 122784 | H15: 4781453.2 | I15: 1895065.5 | J15: 0.53844766 | K15: 0.71615963 | L15: 1 | M15: 0.61191069 | N15: -7.3463036 | O15: 1 | P15: FEC Federal Elections; FEC filings | Q15: =IF(A15=2024,"No -- held out","Yes") -> Yes
... A1117: 2024 | B1117: PA | C1117: 17 | D1117: Deluzio, Christopher | E1117: Mercuri, Robert | F1117: 242838 | G1117: 207900 | H1117: 5493682.1 | I1117: 2160748 | J1117: 0.53875644 | K1117: 0.71771275 | L1117: 1 | M1117: 0.6124234 | N1117: -7.3666956 | O1117: 1 | P1117: PA Dept. of State precinct returns; FEC filings | Q1117: =IF(A1117=2024,"No -- held out","Yes") -> No -- held out
